Workbook

Sheet Raw Data
B11: C1 | C11: C2 | D11: C3 | E11: C4 | F11: C5 | G11: C6 | H11: C7 | I11: C8 | J11: C9 | K11: C10 | L11: C11 | M11: C12 | N11: C13 | O11: C14 | P11: C15 | Q11: C16 | R11: C17 | S11: C18 | T11: C19 | U11: C20 | V11: C21 | W11: C22 | X11: C23
B12: Main Contract | C12: Payment for Advance | D12: N/A | M12: 0 | T12: 0 | U12: THB | V12: 35.7 | W12: 0
B13: Main Contract | C13: Payment No.01 | D13: Kick off Meeting (KOM) and Submission of APPROVED PROJECT Execution plan and Organization Chart. | E13: 45595 | F13: 45597 | G13: 10142810 | M13: 0 | T13: 0 | U13: THB | W13: 0
B14: Main Contract | C14: Payment No.02 | D14: Procurement of Bulk Material. ** Note | E14: 45656 | F14: 45658 | G14: 10142810 | M14: 0 | T14: 0 | U14: THB | W14: 0
B15: Main Contract | C15: Payment No.03 | D15: Completion of Civil Work ** Note | E15: 45658 | F15: 45689 | G15: 11157091 | M15: 0 | T15: 0 | U15: THB | W15: 0
B16: Main Contract | C16: Payment No.04 | D16: Construction & Mechanical Completion. ** Note | E16: 45716 | F16: 45717 | G16: 1014281 | M16: 0 | T16: 0 | U16: THB | W16: 0
B17: Main Contract | C17: Payment No.05 | D17: Procurement of Bulk Material. ** Note Construction & Mechanical Completion. ** Note | E17: 45747 | F17: 45748 | G17: 4057124 | M17: 0 | T17: 0 | U17: THB | W17: 0
B18: Main Contract | C18: Payment No.06 | D18: Construction & Mechanical Completion. ** Note | E18: 45777 | F18: 45778 | G18: 32710562 | M18: 0 | T18: 0 | U18: THB | W18: 0
B19: Main Contract | C19: Payment No.07 | D19: Construction & Mechanical Completion ** Note | E19: 45807 | F19: 45809 | G19: 8874958.8 | M19: 0 | T19: 0 | U19: THB | W19: 0
B20: Main Contract | C20: Payment No.08 | D20: Construction & Mechanical Completion ** Note | E20: 45838 | F20: 45839 | G20: 3042843 | M20: 0 | T20: 0 | U20: THB | W20: 0
B21: Main Contract | C21: Payment No.09 | D21: Commissioning Work, Testing and PLANT Startup | E21: 45961 | F21: 45962 | G21: 15214215 | M21: 0 | T21: 0 | U21: THB | W21: 0
B22: Main Contract | C22: Payment No.10 | D22: Final payment Milestone | E22: 46022 | F22: 46023 | G22: 5071405 | M22: 0 | T22: 0 | U22: THB | W22: 0
B23: Main Contract | C23: Payment No.11 | M23: 0 | T23: 0 | U23: THB | W23: 0
B24: Main Contract | C24: Payment No.12 | M24: 0 | T24: 0 | U24: THB | W24: 0
B25: Main Contract | C25: Payment No.13 | M25: 0 | T25: 0 | U25: THB | W25: 0
B26: Main Contract | C26: Payment No.14 | M26: 0 | T26: 0 | U26: THB | W26: 0
B27: Main Contract | C27: Payment No.15 | M27: 0 | T27: 0 | U27: THB | W27: 0
B28: Main Contract | C28: Payment No.16 | M28: 0 | T28: 0 | U28: THB | W28: 0
B29: Main Contract | C29: Payment No.17 | M29: 0 | T29: 0 | U29: THB | W29: 0
B30: Main Contract | C30: Payment No.18 | M30: 0 | T30: 0 | U30: THB | W30: 0
B31: Main Contract | C31: Payment No.19 | M31: 0 | T31: 0 | U31: THB | W31: 0
B32: Main Contract | C32: Payment No.20 | M32: 0 | T32: 0 | U32: THB | W32: 0
B33: Main Contract | C33: Payment No.21 | M33: 0 | T33: 0 | U33: THB | W33: 0
B34: Main Contract | C34: Payment No.22 | M34: 0 | T34: 0 | U34: THB | W34: 0
... B39: Change Order | C39: CO Payment No.03 | M39: 0 | T39: 0 | U39: THB | W39: 0
B40: Change Order | C40: CO Payment No.04 | M40: 0 | T40: 0
B41: Change Order | C41: CO Payment No.05 | M41: 0 | T41: 0

Sheet Validate_Empty
B10: FALSE | C10: FALSE | D10: FALSE | E10: FALSE | F10: FALSE | G10: FALSE | H10: FALSE | I10: FALSE | J10: FALSE | K10: FALSE | L10: FALSE | M10: FALSE | N10: FALSE | O10: FALSE | P10: FALSE | Q10: FALSE | R10: FALSE | S10: FALSE | T10: FALSE | U10: FALSE | V10: FALSE | W10: FALSE | X10: FALSE
B11: C1 | C11: C2 | D11: C3 | E11: C4 | F11: C5 | G11: C6 | H11: C7 | I11: C8 | J11: C9 | K11: C10 | L11: C11 | M11: C12 | N11: C13 | O11: C14 | P11: C15 | Q11: C16 | R11: C17 | S11: C18 | T11: C19 | U11: C20 | V11: C21 | W11: C22 | X11: C23

Sheet Validate_Value
B10: NVARCHAR(50) | C10: NVARCHAR(50) | D10: NVARCHAR(255) | E10: DATE | F10: NVARCHAR(20) | G10: DECIMAL(13,2) | H10: DECIMAL(13,2) | I10: NVARCHAR(50) | J10: DATE | K10: DECIMAL(13,2) | L10: DECIMAL(13,2) | M10: DECIMAL(13,2) | N10: DECIMAL(13,2) | O10: DECIMAL(13,2) | P10: DATE | Q10: DATE | R10: DECIMAL(13,2) | S10: DECIMAL(13,2) | T10: DECIMAL(13,2) | U10: NVARCHAR(5) | V10: DECIMAL(13,2) | W10: DECIMAL(13,2) | X10: NVARCHAR(MAX)
B11: C1 | C11: C2 | D11: C3 | E11: C4 | F11: C5 | G11: C6 | H11: C7 | I11: C8 | J11: C9 | K11: C10 | L11: C11 | M11: C12 | N11: C13 | O11: C14 | P11: C15 | Q11: C16 | R11: C17 | S11: C18 | T11: C19 | U11: C20 | V11: C21 | W11: C22 | X11: C23
B12: {=IFERROR(IF(OR('Raw Data'!B12="",LEN(TRIM('Raw Data'!B12))=0),"",IF(AND(LEN('Raw Data'!B12) <= 50,LEN('Raw Data'!B12)> 0),"",_xlfn.REGEXEXTRACT(CELL("address",'Raw Data'!B12),"\$([A-Z]+)\$[0-9]+"))),_xlfn.REGEXEXTRACT(CELL("address",'Raw Data'!B12),"\$([A-Z]+)\$[0-9]+"))} | C12: {=IFERROR(IF(OR('Raw Data'!C12="",LEN(TRIM('Raw Data'!C12))=0),"",IF(AND(LEN('Raw Data'!C12) <= 50,LEN('Raw Data'!C12)> 0),"",_xlfn.REGEXEXTRACT(CELL("address",'Raw Data'!C12),"\$([A-Z]+)\$[0-9]+"))),_xlfn.REGEXEXTRACT(CELL("address",'Raw Data'!C12),"\$([A-Z]+)\$[0-9]+"))} | D12: {=IFERROR(IF(OR('Raw Data'!D12="",LEN(TRIM('Raw Data'!D12))=0),"",IF(AND(LEN('Raw Data'!D12) <= 255,LEN('Raw Data'!D12)> 0),"",_xlfn.REGEXEXTRACT(CELL("address",'Raw Data'!D12),"\$([A-Z]+)\$[0-9]+"))),_xlfn.REGEXEXTRACT(CELL("address",'Raw Data'!D12),"\$([A-Z]+)\$[0-9]+"))} | E12: {=IFERROR(IF(OR('Raw Data'!E12="",LEN(TRIM('Raw Data'!E12))=0),"",IF(AND(ISNUMBER('Raw Data'!E12),'Raw Data'!E12>=Configuration!$D$2),"",_xlfn.REGEXEXTRACT(CELL("address",'Raw Data'!E12),"\$([A-Z]+)\$[0-9]+"))),_xlfn.REGEXEXTRACT(CELL("address",E12), "\$([A-Z]+)\$[0-9]+"))} | F12: {=IFERROR(IF(OR('Raw Data'!F12="",LEN(TRIM('Raw Data'!F12))=0),"",IF(AND(LEN('Raw Data'!F12) <= 20,LEN('Raw Data'!F12)> 0),"",_xlfn.REGEXEXTRACT(CELL("address",'Raw Data'!F12),"\$([A-Z]+)\$[0-9]+"))),_xlfn.REGEXEXTRACT(CELL("address",'Raw Data'!F12),"\$([A-Z]+)\$[0-9]+"))} | G12: {=IFERROR(IF(OR('Raw Data'!G12="",LEN(TRIM('Raw Data'!G12))=0),"",IF(AND(ISNUMBER('Raw Data'!G12), IFERROR('Raw Data'!G12 = ROUND('Raw Data'!G12, 2),FALSE)),"",_xlfn.REGEXEXTRACT(CELL("address",G12), "\$([A-Z]+)\$[0-9]+"))),_xlfn.REGEXEXTRACT(CELL("address",G12), "\$([A-Z]+)\$[0-9]+"))} | H12: {=IFERROR(IF(OR('Raw Data'!H12="",LEN(TRIM('Raw Data'!H12))=0),"",IF(AND(ISNUMBER('Raw Data'!H12), IFERROR('Raw Data'!H12 = ROUND('Raw Data'!H12, 2),FALSE)),"",_xlfn.REGEXEXTRACT(CELL("address",H12), "\$([A-Z]+)\$[0-9]+"))),_xlfn.REGEXEXTRACT(CELL("address",H12), "\$([A-Z]+)\$[0-9]+"))} | I12: {=IFERROR(IF(OR('Raw Data'!I12="",LEN(TRIM('Raw Data'!I12))=0),"",IF(AND(LEN('Raw Data'!I12) <= 50,LEN('Raw Data'!I12)> 0),"",_xlfn.REGEXEXTRACT(CELL("address",'Raw Data'!I12),"\$([A-Z]+)\$[0-9]+"))),_xlfn.REGEXEXTRACT(CELL("address",'Raw Data'!I12),"\$([A-Z]+)\$[0-9]+"))} | J12: {=IFERROR(IF(OR('Raw Data'!J12="",LEN(TRIM('Raw Data'!J12))=0),"",IF(AND(ISNUMBER('Raw Data'!J12),'Raw Data'!J12>=Configuration!$D$2),"",_xlfn.REGEXEXTRACT(CELL("address",'Raw Data'!J12),"\$([A-Z]+)\$[0-9]+"))),_xlfn.REGEXEXTRACT(CELL("address",J12), "\$([A-Z]+)\$[0-9]+"))} | K12: {=IFERROR(IF(OR('Raw Data'!K12="",LEN(TRIM('Raw Data'!K12))=0),"",IF(AND(ISNUMBER('Raw Data'!K12), IFERROR('Raw Data'!K12 = ROUND('Raw Data'!K12, 2),FALSE)),"",_xlfn.REGEXEXTRACT(CELL("address",K12), "\$([A-Z]+)\$[0-9]+"))),_xlfn.REGEXEXTRACT(CELL("address",K12), "\$([A-Z]+)\$[0-9]+"))} | L12: {=IFERROR(IF(OR('Raw Data'!L12="",LEN(TRIM('Raw Data'!L12))=0),"",IF(AND(ISNUMBER('Raw Data'!L12), IFERROR('Raw Data'!L12 = ROUND('Raw Data'!L12, 2),FALSE)),"",_xlfn.REGEXEXTRACT(CELL("address",L12), "\$([A-Z]+)\$[0-9]+"))),_xlfn.REGEXEXTRACT(CELL("address",L12), "\$([A-Z]+)\$[0-9]+"))} | M12: {=IFERROR(IF(OR('Raw Data'!M12="",LEN(TRIM('Raw Data'!M12))=0),"",IF(AND(ISNUMBER('Raw Data'!M12), IFERROR('Raw Data'!M12 = ROUND('Raw Data'!M12, 2),FALSE)),"",_xlfn.REGEXEXTRACT(CELL("address",M12), "\$([A-Z]+)\$[0-9]+"))),_xlfn.REGEXEXTRACT(CELL("address",M12), "\$([A-Z]+)\$[0-9]+"))} | N12: {=IFERROR(IF(OR('Raw Data'!N12="",LEN(TRIM('Raw Data'!N12))=0),"",IF(AND(ISNUMBER('Raw Data'!N12), IFERROR('Raw Data'!N12 = ROUND('Raw Data'!N12, 2),FALSE)),"",_xlfn.REGEXEXTRACT(CELL("address",N12), "\$([A-Z]+)\$[0-9]+"))),_xlfn.REGEXEXTRACT(CELL("address",N12), "\$([A-Z]+)\$[0-9]+"))} | O12: {=IFERROR(IF(OR('Raw Data'!O12="",LEN(TRIM('Raw Data'!O12))=0),"",IF(AND(ISNUMBER('Raw Data'!O12), IFERROR('Raw Data'!O12 = ROUND('Raw Data'!O12, 2),FALSE)),"",_xlfn.REGEXEXTRACT(CELL("address",O12), "\$([A-Z]+)\$[0-9]+"))),_xlfn.REGEXEXTRACT(CELL("address",O12), "\$([A-Z]+)\$[0-9]+"))} | P12: {=IFERROR(IF(OR('Raw Data'!P12="",LEN(TRIM('Raw Data'!P12))=0),"",IF(AND(ISNUMBER('Raw Data'!P12),'Raw Data'!P12>=Configuration!$D$2),"",_xlfn.REGEXEXTRACT(CELL("address",'Raw Data'!P12),"\$([A-Z]+)\$[0-9]+"))),_xlfn.REGEXEXTRACT(CELL("address",P12), "\$([A-Z]+)\$[0-9]+"))} | Q12: {=IFERROR(IF(OR('Raw Data'!Q12="",LEN(TRIM('Raw Data'!Q12))=0),"",IF(AND(ISNUMBER('Raw Data'!Q12),'Raw Data'!Q12>=Configuration!$D$2),"",_xlfn.REGEXEXTRACT(CELL("address",'Raw Data'!Q12),"\$([A-Z]+)\$[0-9]+"))),_xlfn.REGEXEXTRACT(CELL("address",Q12), "\$([A-Z]+)\$[0-9]+"))} | R12: {=IFERROR(IF(OR('Raw Data'!R12="",LEN(TRIM('Raw Data'!R12))=0),"",IF(AND(ISNUMBER('Raw Data'!R12), IFERROR('Raw Data'!R12 = ROUND('Raw Data'!R12, 2),FALSE)),"",_xlfn.REGEXEXTRACT(CELL("address",R12), "\$([A-Z]+)\$[0-9]+"))),_xlfn.REGEXEXTRACT(CELL("address",R12), "\$([A-Z]+)\$[0-9]+"))} | S12: {=IFERROR(IF(OR('Raw Data'!S12="",LEN(TRIM('Raw Data'!S12))=0),"",IF(AND(ISNUMBER('Raw Data'!S12), IFERROR('Raw Data'!S12 = ROUND('Raw Data'!S12, 2),FALSE)),"",_xlfn.REGEXEXTRACT(CELL("address",S12), "\$([A-Z]+)\$[0-9]+"))),_xlfn.REGEXEXTRACT(CELL("address",S12), "\$([A-Z]+)\$[0-9]+"))} | T12: {=IFERROR(IF(OR('Raw Data'!T12="",LEN(TRIM('Raw Data'!T12))=0),"",IF(AND(ISNUMBER('Raw Data'!T12), IFERROR('Raw Data'!T12 = ROUND('Raw Data'!T12, 2),FALSE)),"",_xlfn.REGEXEXTRACT(CELL("address",T12), "\$([A-Z]+)\$[0-9]+"))),_xlfn.REGEXEXTRACT(CELL("address",T12), "\$([A-Z]+)\$[0-9]+"))} | U12: {=IFERROR(IF(OR('Raw Data'!U12="",LEN(TRIM('Raw Data'!U12))=0),"",IF(AND(LEN('Raw Data'!U12) <= 5,LEN('Raw Data'!U12)> 0),"",_xlfn.REGEXEXTRACT(CELL("address",'Raw Data'!U12),"\$([A-Z]+)\$[0-9]+"))),_xlfn.REGEXEXTRACT(CELL("address",'Raw Data'!U12),"\$([A-Z]+)\$[0-9]+"))} | V12: {=IFERROR(IF(OR('Raw Data'!V12="",LEN(TRIM('Raw Data'!V12))=0),"",IF(AND(ISNUMBER('Raw Data'!V12), IFERROR('Raw Data'!V12 = ROUND('Raw Data'!V12, 2),FALSE)),"",_xlfn.REGEXEXTRACT(CELL("address",V12), "\$([A-Z]+)\$[0-9]+"))),_xlfn.REGEXEXTRACT(CELL("address",V12), "\$([A-Z]+)\$[0-9]+"))} | W12: {=IFERROR(IF(OR('Raw Data'!W12="",LEN(TRIM('Raw Data'!W12))=0),"",IF(AND(ISNUMBER('Raw Data'!W12), IFERROR('Raw Data'!W12 = ROUND('Raw Data'!W12, 2),FALSE)),"",_xlfn.REGEXEXTRACT(CELL("address",W12), "\$([A-Z]+)\$[0-9]+"))),_xlfn.REGEXEXTRACT(CELL("address",W12), "\$([A-Z]+)\$[0-9]+"))} | X12: {=IFERROR(IF(OR('Raw Data'!X12="",LEN(TRIM('Raw Data'!X12))=0),"",IF(AND(LEN('Raw Data'!X12)> 0),"",_xlfn.REGEXEXTRACT(CELL("address",'Raw Data'!X12),"\$([A-Z]+)\$[0-9]+"))),_xlfn.REGEXEXTRACT(CELL("address",'Raw Data'!X12),"\$([A-Z]+)\$[0-9]+"))}
B13: {=IFERROR(IF(OR('Raw Data'!B13="",LEN(TRIM('Raw Data'!B13))=0),"",IF(AND(LEN('Raw Data'!B13) <= 50,LEN('Raw Data'!B13)> 0),"",_xlfn.REGEXEXTRACT(CELL("address",'Raw Data'!B13),"\$([A-Z]+)\$[0-9]+"))),_xlfn.REGEXEXTRACT(CELL("address",'Raw Data'!B13),"\$([A-Z]+)\$[0-9]+"))} | C13: {=IFERROR(IF(OR('Raw Data'!C13="",LEN(TRIM('Raw Data'!C13))=0),"",IF(AND(LEN('Raw Data'!C13) <= 50,LEN('Raw Data'!C13)> 0),"",_xlfn.REGEXEXTRACT(CELL("address",'Raw Data'!C13),"\$([A-Z]+)\$[0-9]+"))),_xlfn.REGEXEXTRACT(CELL("address",'Raw Data'!C13),"\$([A-Z]+)\$[0-9]+"))} | D13: {=IFERROR(IF(OR('Raw Data'!D13="",LEN(TRIM('Raw Data'!D13))=0),"",IF(AND(LEN('Raw Data'!D13) <= 255,LEN('Raw Data'!D13)> 0),"",_xlfn.REGEXEXTRACT(CELL("address",'Raw Data'!D13),"\$([A-Z]+)\$[0-9]+"))),_xlfn.REGEXEXTRACT(CELL("address",'Raw Data'!D13),"\$([A-Z]+)\$[0-9]+"))} | E13: {=IFERROR(IF(OR('Raw Data'!E13="",LEN(TRIM('Raw Data'!E13))=0),"",IF(AND(ISNUMBER('Raw Data'!E13),'Raw Data'!E13>=Configuration!$D$2),"",_xlfn.REGEXEXTRACT(CELL("address",'Raw Data'!E13),"\$([A-Z]+)\$[0-9]+"))),_xlfn.REGEXEXTRACT(CELL("address",E13), "\$([A-Z]+)\$[0-9]+"))} | F13: {=IFERROR(IF(OR('Raw Data'!F13="",LEN(TRIM('Raw Data'!F13))=0),"",IF(AND(LEN('Raw Data'!F13) <= 20,LEN('Raw Data'!F13)> 0),"",_xlfn.REGEXEXTRACT(CELL("address",'Raw Data'!F13),"\$([A-Z]+)\$[0-9]+"))),_xlfn.REGEXEXTRACT(CELL("address",'Raw Data'!F13),"\$([A-Z]+)\$[0-9]+"))} | G13: {=IFERROR(IF(OR('Raw Data'!G13="",LEN(TRIM('Raw Data'!G13))=0),"",IF(AND(ISNUMBER('Raw Data'!G13), IFERROR('Raw Data'!G13 = ROUND('Raw Data'!G13, 2),FALSE)),"",_xlfn.REGEXEXTRACT(CELL("address",G13), "\$([A-Z]+)\$[0-9]+"))),_xlfn.REGEXEXTRACT(CELL("address",G13), "\$([A-Z]+)\$[0-9]+"))} | H13: {=IFERROR(IF(OR('Raw Data'!H13="",LEN(TRIM('Raw Data'!H13))=0),"",IF(AND(ISNUMBER('Raw Data'!H13), IFERROR('Raw Data'!H13 = ROUND('Raw Data'!H13, 2),FALSE)),"",_xlfn.REGEXEXTRACT(CELL("address",H13), "\$([A-Z]+)\$[0-9]+"))),_xlfn.REGEXEXTRACT(CELL("address",H13), "\$([A-Z]+)\$[0-9]+"))} | I13: {=IFERROR(IF(OR('Raw Data'!I13="",LEN(TRIM('Raw Data'!I13))=0),"",IF(AND(LEN('Raw Data'!I13) <= 50,LEN('Raw Data'!I13)> 0),"",_xlfn.REGEXEXTRACT(CELL("address",'Raw Data'!I13),"\$([A-Z]+)\$[0-9]+"))),_xlfn.REGEXEXTRACT(CELL("address",'Raw Data'!I13),"\$([A-Z]+)\$[0-9]+"))} | J13: {=IFERROR(IF(OR('Raw Data'!J13="",LEN(TRIM('Raw Data'!J13))=0),"",IF(AND(ISNUMBER('Raw Data'!J13),'Raw Data'!J13>=Configuration!$D$2),"",_xlfn.REGEXEXTRACT(CELL("address",'Raw Data'!J13),"\$([A-Z]+)\$[0-9]+"))),_xlfn.REGEXEXTRACT(CELL("address",J13), "\$([A-Z]+)\$[0-9]+"))} | K13: {=IFERROR(IF(OR('Raw Data'!K13="",LEN(TRIM('Raw Data'!K13))=0),"",IF(AND(ISNUMBER('Raw Data'!K13), IFERROR('Raw Data'!K13 = ROUND('Raw Data'!K13, 2),FALSE)),"",_xlfn.REGEXEXTRACT(CELL("address",K13), "\$([A-Z]+)\$[0-9]+"))),_xlfn.REGEXEXTRACT(CELL("address",K13), "\$([A-Z]+)\$[0-9]+"))} | L13: {=IFERROR(IF(OR('Raw Data'!L13="",LEN(TRIM('Raw Data'!L13))=0),"",IF(AND(ISNUMBER('Raw Data'!L13), IFERROR('Raw Data'!L13 = ROUND('Raw Data'!L13, 2),FALSE)),"",_xlfn.REGEXEXTRACT(CELL("address",L13), "\$([A-Z]+)\$[0-9]+"))),_xlfn.REGEXEXTRACT(CELL("address",L13), "\$([A-Z]+)\$[0-9]+"))} | M13: {=IFERROR(IF(OR('Raw Data'!M13="",LEN(TRIM('Raw Data'!M13))=0),"",IF(AND(ISNUMBER('Raw Data'!M13), IFERROR('Raw Data'!M13 = ROUND('Raw Data'!M13, 2),FALSE)),"",_xlfn.REGEXEXTRACT(CELL("address",M13), "\$([A-Z]+)\$[0-9]+"))),_xlfn.REGEXEXTRACT(CELL("address",M13), "\$([A-Z]+)\$[0-9]+"))} | N13: {=IFERROR(IF(OR('Raw Data'!N13="",LEN(TRIM('Raw Data'!N13))=0),"",IF(AND(ISNUMBER('Raw Data'!N13), IFERROR('Raw Data'!N13 = ROUND('Raw Data'!N13, 2),FALSE)),"",_xlfn.REGEXEXTRACT(CELL("address",N13), "\$([A-Z]+)\$[0-9]+"))),_xlfn.REGEXEXTRACT(CELL("address",N13), "\$([A-Z]+)\$[0-9]+"))} | O13: {=IFERROR(IF(OR('Raw Data'!O13="",LEN(TRIM('Raw Data'!O13))=0),"",IF(AND(ISNUMBER('Raw Data'!O13), IFERROR('Raw Data'!O13 = ROUND('Raw Data'!O13, 2),FALSE)),"",_xlfn.REGEXEXTRACT(CELL("address",O13), "\$([A-Z]+)\$[0-9]+"))),_xlfn.REGEXEXTRACT(CELL("address",O13), "\$([A-Z]+)\$[0-9]+"))} | P13: {=IFERROR(IF(OR('Raw Data'!P13="",LEN(TRIM('Raw Data'!P13))=0),"",IF(AND(ISNUMBER('Raw Data'!P13),'Raw Data'!P13>=Configuration!$D$2),"",_xlfn.REGEXEXTRACT(CELL("address",'Raw Data'!P13),"\$([A-Z]+)\$[0-9]+"))),_xlfn.REGEXEXTRACT(CELL("address",P13), "\$([A-Z]+)\$[0-9]+"))} | Q13: {=IFERROR(IF(OR('Raw Data'!Q13="",LEN(TRIM('Raw Data'!Q13))=0),"",IF(AND(ISNUMBER('Raw Data'!Q13),'Raw Data'!Q13>=Configuration!$D$2),"",_xlfn.REGEXEXTRACT(CELL("address",'Raw Data'!Q13),"\$([A-Z]+)\$[0-9]+"))),_xlfn.REGEXEXTRACT(CELL("address",Q13), "\$([A-Z]+)\$[0-9]+"))} | R13: {=IFERROR(IF(OR('Raw Data'!R13="",LEN(TRIM('Raw Data'!R13))=0),"",IF(AND(ISNUMBER('Raw Data'!R13), IFERROR('Raw Data'!R13 = ROUND('Raw Data'!R13, 2),FALSE)),"",_xlfn.REGEXEXTRACT(CELL("address",R13), "\$([A-Z]+)\$[0-9]+"))),_xlfn.REGEXEXTRACT(CELL("address",R13), "\$([A-Z]+)\$[0-9]+"))} | S13: {=IFERROR(IF(OR('Raw Data'!S13="",LEN(TRIM('Raw Data'!S13))=0),"",IF(AND(ISNUMBER('Raw Data'!S13), IFERROR('Raw Data'!S13 = ROUND('Raw Data'!S13, 2),FALSE)),"",_xlfn.REGEXEXTRACT(CELL("address",S13), "\$([A-Z]+)\$[0-9]+"))),_xlfn.REGEXEXTRACT(CELL("address",S13), "\$([A-Z]+)\$[0-9]+"))} | T13: {=IFERROR(IF(OR('Raw Data'!T13="",LEN(TRIM('Raw Data'!T13))=0),"",IF(AND(ISNUMBER('Raw Data'!T13), IFERROR('Raw Data'!T13 = ROUND('Raw Data'!T13, 2),FALSE)),"",_xlfn.REGEXEXTRACT(CELL("address",T13), "\$([A-Z]+)\$[0-9]+"))),_xlfn.REGEXEXTRACT(CELL("address",T13), "\$([A-Z]+)\$[0-9]+"))} | U13: {=IFERROR(IF(OR('Raw Data'!U13="",LEN(TRIM('Raw Data'!U13))=0),"",IF(AND(LEN('Raw Data'!U13) <= 5,LEN('Raw Data'!U13)> 0),"",_xlfn.REGEXEXTRACT(CELL("address",'Raw Data'!U13),"\$([A-Z]+)\$[0-9]+"))),_xlfn.REGEXEXTRACT(CELL("address",'Raw Data'!U13),"\$([A-Z]+)\$[0-9]+"))} | V13: {=IFERROR(IF(OR('Raw Data'!V13="",LEN(TRIM('Raw Data'!V13))=0),"",IF(AND(ISNUMBER('Raw Data'!V13), IFERROR('Raw Data'!V13 = ROUND('Raw Data'!V13, 2),FALSE)),"",_xlfn.REGEXEXTRACT(CELL("address",V13), "\$([A-Z]+)\$[0-9]+"))),_xlfn.REGEXEXTRACT(CELL("address",V13), "\$([A-Z]+)\$[0-9]+"))} | W13: {=IFERROR(IF(OR('Raw Data'!W13="",LEN(TRIM('Raw Data'!W13))=0),"",IF(AND(ISNUMBER('Raw Data'!W13), IFERROR('Raw Data'!W13 = ROUND('Raw Data'!W13, 2),FALSE)),"",_xlfn.REGEXEXTRACT(CELL("address",W13), "\$([A-Z]+)\$[0-9]+"))),_xlfn.REGEXEXTRACT(CELL("address",W13), "\$([A-Z]+)\$[0-9]+"))} | X13: {=IFERROR(IF(OR('Raw Data'!X13="",LEN(TRIM('Raw Data'!X13))=0),"",IF(AND(ISNUMBER('Raw Data'!X13), IFERROR('Raw Data'!X13 = ROUND('Raw Data'!X13, 2),FALSE)),"",_xlfn.REGEXEXTRACT(CELL("address",X13), "\$([A-Z]+)\$[0-9]+"))),_xlfn.REGEXEXTRACT(CELL("address",X13), "\$([A-Z]+)\$[0-9]+"))}
B14: {=IFERROR(IF(OR('Raw Data'!B14="",LEN(TRIM('Raw Data'!B14))=0),"",IF(AND(LEN('Raw Data'!B14) <= 50,LEN('Raw Data'!B14)> 0),"",_xlfn.REGEXEXTRACT(CELL("address",'Raw Data'!B14),"\$([A-Z]+)\$[0-9]+"))),_xlfn.REGEXEXTRACT(CELL("address",'Raw Data'!B14),"\$([A-Z]+)\$[0-9]+"))} | C14: {=IFERROR(IF(OR('Raw Data'!C14="",LEN(TRIM('Raw Data'!C14))=0),"",IF(AND(LEN('Raw Data'!C14) <= 50,LEN('Raw Data'!C14)> 0),"",_xlfn.REGEXEXTRACT(CELL("address",'Raw Data'!C14),"\$([A-Z]+)\$[0-9]+"))),_xlfn.REGEXEXTRACT(CELL("address",'Raw Data'!C14),"\$([A-Z]+)\$[0-9]+"))} | D14: {=IFERROR(IF(OR('Raw Data'!D14="",LEN(TRIM('Raw Data'!D14))=0),"",IF(AND(LEN('Raw Data'!D14) <= 255,LEN('Raw Data'!D14)> 0),"",_xlfn.REGEXEXTRACT(CELL("address",'Raw Data'!D14),"\$([A-Z]+)\$[0-9]+"))),_xlfn.REGEXEXTRACT(CELL("address",'Raw Data'!D14),"\$([A-Z]+)\$[0-9]+"))} | E14: {=IFERROR(IF(OR('Raw Data'!E14="",LEN(TRIM('Raw Data'!E14))=0),"",IF(AND(ISNUMBER('Raw Data'!E14),'Raw Data'!E14>=Configuration!$D$2),"",_xlfn.REGEXEXTRACT(CELL("address",'Raw Data'!E14),"\$([A-Z]+)\$[0-9]+"))),_xlfn.REGEXEXTRACT(CELL("address",E14), "\$([A-Z]+)\$[0-9]+"))} | F14: {=IFERROR(IF(OR('Raw Data'!F14="",LEN(TRIM('Raw Data'!F14))=0),"",IF(AND(LEN('Raw Data'!F14) <= 20,LEN('Raw Data'!F14)> 0),"",_xlfn.REGEXEXTRACT(CELL("address",'Raw Data'!F14),"\$([A-Z]+)\$[0-9]+"))),_xlfn.REGEXEXTRACT(CELL("address",'Raw Data'!F14),"\$([A-Z]+)\$[0-9]+"))} | G14: {=IFERROR(IF(OR('Raw Data'!G14="",LEN(TRIM('Raw Data'!G14))=0),"",IF(AND(ISNUMBER('Raw Data'!G14), IFERROR('Raw Data'!G14 = ROUND('Raw Data'!G14, 2),FALSE)),"",_xlfn.REGEXEXTRACT(CELL("address",G14), "\$([A-Z]+)\$[0-9]+"))),_xlfn.REGEXEXTRACT(CELL("address",G14), "\$([A-Z]+)\$[0-9]+"))} | H14: {=IFERROR(IF(OR('Raw Data'!H14="",LEN(TRIM('Raw Data'!H14))=0),"",IF(AND(ISNUMBER('Raw Data'!H14), IFERROR('Raw Data'!H14 = ROUND('Raw Data'!H14, 2),FALSE)),"",_xlfn.REGEXEXTRACT(CELL("address",H14), "\$([A-Z]+)\$[0-9]+"))),_xlfn.REGEXEXTRACT(CELL("address",H14), "\$([A-Z]+)\$[0-9]+"))} | I14: {=IFERROR(IF(OR('Raw Data'!I14="",LEN(TRIM('Raw Data'!I14))=0),"",IF(AND(LEN('Raw Data'!I14) <= 50,LEN('Raw Data'!I14)> 0),"",_xlfn.REGEXEXTRACT(CELL("address",'Raw Data'!I14),"\$([A-Z]+)\$[0-9]+"))),_xlfn.REGEXEXTRACT(CELL("address",'Raw Data'!I14),"\$([A-Z]+)\$[0-9]+"))} | J14: {=IFERROR(IF(OR('Raw Data'!J14="",LEN(TRIM('Raw Data'!J14))=0),"",IF(AND(ISNUMBER('Raw Data'!J14),'Raw Data'!J14>=Configuration!$D$2),"",_xlfn.REGEXEXTRACT(CELL("address",'Raw Data'!J14),"\$([A-Z]+)\$[0-9]+"))),_xlfn.REGEXEXTRACT(CELL("address",J14), "\$([A-Z]+)\$[0-9]+"))} | K14: {=IFERROR(IF(OR('Raw Data'!K14="",LEN(TRIM('Raw Data'!K14))=0),"",IF(AND(ISNUMBER('Raw Data'!K14), IFERROR('Raw Data'!K14 = ROUND('Raw Data'!K14, 2),FALSE)),"",_xlfn.REGEXEXTRACT(CELL("address",K14), "\$([A-Z]+)\$[0-9]+"))),_xlfn.REGEXEXTRACT(CELL("address",K14), "\$([A-Z]+)\$[0-9]+"))} | L14: {=IFERROR(IF(OR('Raw Data'!L14="",LEN(TRIM('Raw Data'!L14))=0),"",IF(AND(ISNUMBER('Raw Data'!L14), IFERROR('Raw Data'!L14 = ROUND('Raw Data'!L14, 2),FALSE)),"",_xlfn.REGEXEXTRACT(CELL("address",L14), "\$([A-Z]+)\$[0-9]+"))),_xlfn.REGEXEXTRACT(CELL("address",L14), "\$([A-Z]+)\$[0-9]+"))} | M14: {=IFERROR(IF(OR('Raw Data'!M14="",LEN(TRIM('Raw Data'!M14))=0),"",IF(AND(ISNUMBER('Raw Data'!M14), IFERROR('Raw Data'!M14 = ROUND('Raw Data'!M14, 2),FALSE)),"",_xlfn.REGEXEXTRACT(CELL("address",M14), "\$([A-Z]+)\$[0-9]+"))),_xlfn.REGEXEXTRACT(CELL("address",M14), "\$([A-Z]+)\$[0-9]+"))} | N14: {=IFERROR(IF(OR('Raw Data'!N14="",LEN(TRIM('Raw Data'!N14))=0),"",IF(AND(ISNUMBER('Raw Data'!N14), IFERROR('Raw Data'!N14 = ROUND('Raw Data'!N14, 2),FALSE)),"",_xlfn.REGEXEXTRACT(CELL("address",N14), "\$([A-Z]+)\$[0-9]+"))),_xlfn.REGEXEXTRACT(CELL("address",N14), "\$([A-Z]+)\$[0-9]+"))} | O14: {=IFERROR(IF(OR('Raw Data'!O14="",LEN(TRIM('Raw Data'!O14))=0),"",IF(AND(ISNUMBER('Raw Data'!O14), IFERROR('Raw Data'!O14 = ROUND('Raw Data'!O14, 2),FALSE)),"",_xlfn.REGEXEXTRACT(CELL("address",O14), "\$([A-Z]+)\$[0-9]+"))),_xlfn.REGEXEXTRACT(CELL("address",O14), "\$([A-Z]+)\$[0-9]+"))} | P14: {=IFERROR(IF(OR('Raw Data'!P14="",LEN(TRIM('Raw Data'!P14))=0),"",IF(AND(ISNUMBER('Raw Data'!P14),'Raw Data'!P14>=Configuration!$D$2),"",_xlfn.REGEXEXTRACT(CELL("address",'Raw Data'!P14),"\$([A-Z]+)\$[0-9]+"))),_xlfn.REGEXEXTRACT(CELL("address",P14), "\$([A-Z]+)\$[0-9]+"))} | Q14: {=IFERROR(IF(OR('Raw Data'!Q14="",LEN(TRIM('Raw Data'!Q14))=0),"",IF(AND(ISNUMBER('Raw Data'!Q14),'Raw Data'!Q14>=Configuration!$D$2),"",_xlfn.REGEXEXTRACT(CELL("address",'Raw Data'!Q14),"\$([A-Z]+)\$[0-9]+"))),_xlfn.REGEXEXTRACT(CELL("address",Q14), "\$([A-Z]+)\$[0-9]+"))} | R14: {=IFERROR(IF(OR('Raw Data'!R14="",LEN(TRIM('Raw Data'!R14))=0),"",IF(AND(ISNUMBER('Raw Data'!R14), IFERROR('Raw Data'!R14 = ROUND('Raw Data'!R14, 2),FALSE)),"",_xlfn.REGEXEXTRACT(CELL("address",R14), "\$([A-Z]+)\$[0-9]+"))),_xlfn.REGEXEXTRACT(CELL("address",R14), "\$([A-Z]+)\$[0-9]+"))} | S14: {=IFERROR(IF(OR('Raw Data'!S14="",LEN(TRIM('Raw Data'!S14))=0),"",IF(AND(ISNUMBER('Raw Data'!S14), IFERROR('Raw Data'!S14 = ROUND('Raw Data'!S14, 2),FALSE)),"",_xlfn.REGEXEXTRACT(CELL("address",S14), "\$([A-Z]+)\$[0-9]+"))),_xlfn.REGEXEXTRACT(CELL("address",S14), "\$([A-Z]+)\$[0-9]+"))} | T14: {=IFERROR(IF(OR('Raw Data'!T14="",LEN(TRIM('Raw Data'!T14))=0),"",IF(AND(ISNUMBER('Raw Data'!T14), IFERROR('Raw Data'!T14 = ROUND('Raw Data'!T14, 2),FALSE)),"",_xlfn.REGEXEXTRACT(CELL("address",T14), "\$([A-Z]+)\$[0-9]+"))),_xlfn.REGEXEXTRACT(CELL("address",T14), "\$([A-Z]+)\$[0-9]+"))} | U14: {=IFERROR(IF(OR('Raw Data'!U14="",LEN(TRIM('Raw Data'!U14))=0),"",IF(AND(LEN('Raw Data'!U14) <= 5,LEN('Raw Data'!U14)> 0),"",_xlfn.REGEXEXTRACT(CELL("address",'Raw Data'!U14),"\$([A-Z]+)\$[0-9]+"))),_xlfn.REGEXEXTRACT(CELL("address",'Raw Data'!U14),"\$([A-Z]+)\$[0-9]+"))} | V14: {=IFERROR(IF(OR('Raw Data'!V14="",LEN(TRIM('Raw Data'!V14))=0),"",IF(AND(ISNUMBER('Raw Data'!V14), IFERROR('Raw Data'!V14 = ROUND('Raw Data'!V14, 2),FALSE)),"",_xlfn.REGEXEXTRACT(CELL("address",V14), "\$([A-Z]+)\$[0-9]+"))),_xlfn.REGEXEXTRACT(CELL("address",V14), "\$([A-Z]+)\$[0-9]+"))} | W14: {=IFERROR(IF(OR('Raw Data'!W14="",LEN(TRIM('Raw Data'!W14))=0),"",IF(AND(ISNUMBER('Raw Data'!W14), IFERROR('Raw Data'!W14 = ROUND('Raw Data'!W14, 2),FALSE)),"",_xlfn.REGEXEXTRACT(CELL("address",W14), "\$([A-Z]+)\$[0-9]+"))),_xlfn.REGEXEXTRACT(CELL("address",W14), "\$([A-Z]+)\$[0-9]+"))} | X14: {=IFERROR(IF(OR('Raw Data'!X14="",LEN(TRIM('Raw Data'!X14))=0),"",IF(AND(ISNUMBER('Raw Data'!X14), IFERROR('Raw Data'!X14 = ROUND('Raw Data'!X14, 2),FALSE)),"",_xlfn.REGEXEXTRACT(CELL("address",X14), "\$([A-Z]+)\$[0-9]+"))),_xlfn.REGEXEXTRACT(CELL("address",X14), "\$([A-Z]+)\$[0-9]+"))}
B15: {=IFERROR(IF(OR('Raw Data'!B15="",LEN(TRIM('Raw Data'!B15))=0),"",IF(AND(LEN('Raw Data'!B15) <= 50,LEN('Raw Data'!B15)> 0),"",_xlfn.REGEXEXTRACT(CELL("address",'Raw Data'!B15),"\$([A-Z]+)\$[0-9]+"))),_xlfn.REGEXEXTRACT(CELL("address",'Raw Data'!B15),"\$([A-Z]+)\$[0-9]+"))} | C15: {=IFERROR(IF(OR('Raw Data'!C15="",LEN(TRIM('Raw Data'!C15))=0),"",IF(AND(LEN('Raw Data'!C15) <= 50,LEN('Raw Data'!C15)> 0),"",_xlfn.REGEXEXTRACT(CELL("address",'Raw Data'!C15),"\$([A-Z]+)\$[0-9]+"))),_xlfn.REGEXEXTRACT(CELL("address",'Raw Data'!C15),"\$([A-Z]+)\$[0-9]+"))} | D15: {=IFERROR(IF(OR('Raw Data'!D15="",LEN(TRIM('Raw Data'!D15))=0),"",IF(AND(LEN('Raw Data'!D15) <= 255,LEN('Raw Data'!D15)> 0),"",_xlfn.REGEXEXTRACT(CELL("address",'Raw Data'!D15),"\$([A-Z]+)\$[0-9]+"))),_xlfn.REGEXEXTRACT(CELL("address",'Raw Data'!D15),"\$([A-Z]+)\$[0-9]+"))} | E15: {=IFERROR(IF(OR('Raw Data'!E15="",LEN(TRIM('Raw Data'!E15))=0),"",IF(AND(ISNUMBER('Raw Data'!E15),'Raw Data'!E15>=Configuration!$D$2),"",_xlfn.REGEXEXTRACT(CELL("address",'Raw Data'!E15),"\$([A-Z]+)\$[0-9]+"))),_xlfn.REGEXEXTRACT(CELL("address",E15), "\$([A-Z]+)\$[0-9]+"))} | F15: {=IFERROR(IF(OR('Raw Data'!F15="",LEN(TRIM('Raw Data'!F15))=0),"",IF(AND(LEN('Raw Data'!F15) <= 20,LEN('Raw Data'!F15)> 0),"",_xlfn.REGEXEXTRACT(CELL("address",'Raw Data'!F15),"\$([A-Z]+)\$[0-9]+"))),_xlfn.REGEXEXTRACT(CELL("address",'Raw Data'!F15),"\$([A-Z]+)\$[0-9]+"))} | G15: {=IFERROR(IF(OR('Raw Data'!G15="",LEN(TRIM('Raw Data'!G15))=0),"",IF(AND(ISNUMBER('Raw Data'!G15), IFERROR('Raw Data'!G15 = ROUND('Raw Data'!G15, 2),FALSE)),"",_xlfn.REGEXEXTRACT(CELL("address",G15), "\$([A-Z]+)\$[0-9]+"))),_xlfn.REGEXEXTRACT(CELL("address",G15), "\$([A-Z]+)\$[0-9]+"))} | H15: {=IFERROR(IF(OR('Raw Data'!H15="",LEN(TRIM('Raw Data'!H15))=0),"",IF(AND(ISNUMBER('Raw Data'!H15), IFERROR('Raw Data'!H15 = ROUND('Raw Data'!H15, 2),FALSE)),"",_xlfn.REGEXEXTRACT(CELL("address",H15), "\$([A-Z]+)\$[0-9]+"))),_xlfn.REGEXEXTRACT(CELL("address",H15), "\$([A-Z]+)\$[0-9]+"))} | I15: {=IFERROR(IF(OR('Raw Data'!I15="",LEN(TRIM('Raw Data'!I15))=0),"",IF(AND(LEN('Raw Data'!I15) <= 50,LEN('Raw Data'!I15)> 0),"",_xlfn.REGEXEXTRACT(CELL("address",'Raw Data'!I15),"\$([A-Z]+)\$[0-9]+"))),_xlfn.REGEXEXTRACT(CELL("address",'Raw Data'!I15),"\$([A-Z]+)\$[0-9]+"))} | J15: {=IFERROR(IF(OR('Raw Data'!J15="",LEN(TRIM('Raw Data'!J15))=0),"",IF(AND(ISNUMBER('Raw Data'!J15),'Raw Data'!J15>=Configuration!$D$2),"",_xlfn.REGEXEXTRACT(CELL("address",'Raw Data'!J15),"\$([A-Z]+)\$[0-9]+"))),_xlfn.REGEXEXTRACT(CELL("address",J15), "\$([A-Z]+)\$[0-9]+"))} | K15: {=IFERROR(IF(OR('Raw Data'!K15="",LEN(TRIM('Raw Data'!K15))=0),"",IF(AND(ISNUMBER('Raw Data'!K15), IFERROR('Raw Data'!K15 = ROUND('Raw Data'!K15, 2),FALSE)),"",_xlfn.REGEXEXTRACT(CELL("address",K15), "\$([A-Z]+)\$[0-9]+"))),_xlfn.REGEXEXTRACT(CELL("address",K15), "\$([A-Z]+)\$[0-9]+"))} | L15: {=IFERROR(IF(OR('Raw Data'!L15="",LEN(TRIM('Raw Data'!L15))=0),"",IF(AND(ISNUMBER('Raw Data'!L15), IFERROR('Raw Data'!L15 = ROUND('Raw Data'!L15, 2),FALSE)),"",_xlfn.REGEXEXTRACT(CELL("address",L15), "\$([A-Z]+)\$[0-9]+"))),_xlfn.REGEXEXTRACT(CELL("address",L15), "\$([A-Z]+)\$[0-9]+"))} | M15: {=IFERROR(IF(OR('Raw Data'!M15="",LEN(TRIM('Raw Data'!M15))=0),"",IF(AND(ISNUMBER('Raw Data'!M15), IFERROR('Raw Data'!M15 = ROUND('Raw Data'!M15, 2),FALSE)),"",_xlfn.REGEXEXTRACT(CELL("address",M15), "\$([A-Z]+)\$[0-9]+"))),_xlfn.REGEXEXTRACT(CELL("address",M15), "\$([A-Z]+)\$[0-9]+"))} | N15: {=IFERROR(IF(OR('Raw Data'!N15="",LEN(TRIM('Raw Data'!N15))=0),"",IF(AND(ISNUMBER('Raw Data'!N15), IFERROR('Raw Data'!N15 = ROUND('Raw Data'!N15, 2),FALSE)),"",_xlfn.REGEXEXTRACT(CELL("address",N15), "\$([A-Z]+)\$[0-9]+"))),_xlfn.REGEXEXTRACT(CELL("address",N15), "\$([A-Z]+)\$[0-9]+"))} | O15: {=IFERROR(IF(OR('Raw Data'!O15="",LEN(TRIM('Raw Data'!O15))=0),"",IF(AND(ISNUMBER('Raw Data'!O15), IFERROR('Raw Data'!O15 = ROUND('Raw Data'!O15, 2),FALSE)),"",_xlfn.REGEXEXTRACT(CELL("address",O15), "\$([A-Z]+)\$[0-9]+"))),_xlfn.REGEXEXTRACT(CELL("address",O15), "\$([A-Z]+)\$[0-9]+"))} | P15: {=IFERROR(IF(OR('Raw Data'!P15="",LEN(TRIM('Raw Data'!P15))=0),"",IF(AND(ISNUMBER('Raw Data'!P15),'Raw Data'!P15>=Configuration!$D$2),"",_xlfn.REGEXEXTRACT(CELL("address",'Raw Data'!P15),"\$([A-Z]+)\$[0-9]+"))),_xlfn.REGEXEXTRACT(CELL("address",P15), "\$([A-Z]+)\$[0-9]+"))} | Q15: {=IFERROR(IF(OR('Raw Data'!Q15="",LEN(TRIM('Raw Data'!Q15))=0),"",IF(AND(ISNUMBER('Raw Data'!Q15),'Raw Data'!Q15>=Configuration!$D$2),"",_xlfn.REGEXEXTRACT(CELL("address",'Raw Data'!Q15),"\$([A-Z]+)\$[0-9]+"))),_xlfn.REGEXEXTRACT(CELL("address",Q15), "\$([A-Z]+)\$[0-9]+"))} | R15: {=IFERROR(IF(OR('Raw Data'!R15="",LEN(TRIM('Raw Data'!R15))=0),"",IF(AND(ISNUMBER('Raw Data'!R15), IFERROR('Raw Data'!R15 = ROUND('Raw Data'!R15, 2),FALSE)),"",_xlfn.REGEXEXTRACT(CELL("address",R15), "\$([A-Z]+)\$[0-9]+"))),_xlfn.REGEXEXTRACT(CELL("address",R15), "\$([A-Z]+)\$[0-9]+"))} | S15: {=IFERROR(IF(OR('Raw Data'!S15="",LEN(TRIM('Raw Data'!S15))=0),"",IF(AND(ISNUMBER('Raw Data'!S15), IFERROR('Raw Data'!S15 = ROUND('Raw Data'!S15, 2),FALSE)),"",_xlfn.REGEXEXTRACT(CELL("address",S15), "\$([A-Z]+)\$[0-9]+"))),_xlfn.REGEXEXTRACT(CELL("address",S15), "\$([A-Z]+)\$[0-9]+"))} | T15: {=IFERROR(IF(OR('Raw Data'!T15="",LEN(TRIM('Raw Data'!T15))=0),"",IF(AND(ISNUMBER('Raw Data'!T15), IFERROR('Raw Data'!T15 = ROUND('Raw Data'!T15, 2),FALSE)),"",_xlfn.REGEXEXTRACT(CELL("address",T15), "\$([A-Z]+)\$[0-9]+"))),_xlfn.REGEXEXTRACT(CELL("address",T15), "\$([A-Z]+)\$[0-9]+"))} | U15: {=IFERROR(IF(OR('Raw Data'!U15="",LEN(TRIM('Raw Data'!U15))=0),"",IF(AND(LEN('Raw Data'!U15) <= 5,LEN('Raw Data'!U15)> 0),"",_xlfn.REGEXEXTRACT(CELL("address",'Raw Data'!U15),"\$([A-Z]+)\$[0-9]+"))),_xlfn.REGEXEXTRACT(CELL("address",'Raw Data'!U15),"\$([A-Z]+)\$[0-9]+"))} | V15: {=IFERROR(IF(OR('Raw Data'!V15="",LEN(TRIM('Raw Data'!V15))=0),"",IF(AND(ISNUMBER('Raw Data'!V15), IFERROR('Raw Data'!V15 = ROUND('Raw Data'!V15, 2),FALSE)),"",_xlfn.REGEXEXTRACT(CELL("address",V15), "\$([A-Z]+)\$[0-9]+"))),_xlfn.REGEXEXTRACT(CELL("address",V15), "\$([A-Z]+)\$[0-9]+"))} | W15: {=IFERROR(IF(OR('Raw Data'!W15="",LEN(TRIM('Raw Data'!W15))=0),"",IF(AND(ISNUMBER('Raw Data'!W15), IFERROR('Raw Data'!W15 = ROUND('Raw Data'!W15, 2),FALSE)),"",_xlfn.REGEXEXTRACT(CELL("address",W15), "\$([A-Z]+)\$[0-9]+"))),_xlfn.REGEXEXTRACT(CELL("address",W15), "\$([A-Z]+)\$[0-9]+"))} | X15: {=IFERROR(IF(OR('Raw Data'!X15="",LEN(TRIM('Raw Data'!X15))=0),"",IF(AND(ISNUMBER('Raw Data'!X15), IFERROR('Raw Data'!X15 = ROUND('Raw Data'!X15, 2),FALSE)),"",_xlfn.REGEXEXTRACT(CELL("address",X15), "\$([A-Z]+)\$[0-9]+"))),_xlfn.REGEXEXTRACT(CELL("address",X15), "\$([A-Z]+)\$[0-9]+"))}
B16: {=IFERROR(IF(OR('Raw Data'!B16="",LEN(TRIM('Raw Data'!B16))=0),"",IF(AND(LEN('Raw Data'!B16) <= 50,LEN('Raw Data'!B16)> 0),"",_xlfn.REGEXEXTRACT(CELL("address",'Raw Data'!B16),"\$([A-Z]+)\$[0-9]+"))),_xlfn.REGEXEXTRACT(CELL("address",'Raw Data'!B16),"\$([A-Z]+)\$[0-9]+"))} | C16: {=IFERROR(IF(OR('Raw Data'!C16="",LEN(TRIM('Raw Data'!C16))=0),"",IF(AND(LEN('Raw Data'!C16) <= 50,LEN('Raw Data'!C16)> 0),"",_xlfn.REGEXEXTRACT(CELL("address",'Raw Data'!C16),"\$([A-Z]+)\$[0-9]+"))),_xlfn.REGEXEXTRACT(CELL("address",'Raw Data'!C16),"\$([A-Z]+)\$[0-9]+"))} | D16: {=IFERROR(IF(OR('Raw Data'!D16="",LEN(TRIM('Raw Data'!D16))=0),"",IF(AND(LEN('Raw Data'!D16) <= 255,LEN('Raw Data'!D16)> 0),"",_xlfn.REGEXEXTRACT(CELL("address",'Raw Data'!D16),"\$([A-Z]+)\$[0-9]+"))),_xlfn.REGEXEXTRACT(CELL("address",'Raw Data'!D16),"\$([A-Z]+)\$[0-9]+"))} | E16: {=IFERROR(IF(OR('Raw Data'!E16="",LEN(TRIM('Raw Data'!E16))=0),"",IF(AND(ISNUMBER('Raw Data'!E16),'Raw Data'!E16>=Configuration!$D$2),"",_xlfn.REGEXEXTRACT(CELL("address",'Raw Data'!E16),"\$([A-Z]+)\$[0-9]+"))),_xlfn.REGEXEXTRACT(CELL("address",E16), "\$([A-Z]+)\$[0-9]+"))} | F16: {=IFERROR(IF(OR('Raw Data'!F16="",LEN(TRIM('Raw Data'!F16))=0),"",IF(AND(LEN('Raw Data'!F16) <= 20,LEN('Raw Data'!F16)> 0),"",_xlfn.REGEXEXTRACT(CELL("address",'Raw Data'!F16),"\$([A-Z]+)\$[0-9]+"))),_xlfn.REGEXEXTRACT(CELL("address",'Raw Data'!F16),"\$([A-Z]+)\$[0-9]+"))} | G16: {=IFERROR(IF(OR('Raw Data'!G16="",LEN(TRIM('Raw Data'!G16))=0),"",IF(AND(ISNUMBER('Raw Data'!G16), IFERROR('Raw Data'!G16 = ROUND('Raw Data'!G16, 2),FALSE)),"",_xlfn.REGEXEXTRACT(CELL("address",G16), "\$([A-Z]+)\$[0-9]+"))),_xlfn.REGEXEXTRACT(CELL("address",G16), "\$([A-Z]+)\$[0-9]+"))} | H16: {=IFERROR(IF(OR('Raw Data'!H16="",LEN(TRIM('Raw Data'!H16))=0),"",IF(AND(ISNUMBER('Raw Data'!H16), IFERROR('Raw Data'!H16 = ROUND('Raw Data'!H16, 2),FALSE)),"",_xlfn.REGEXEXTRACT(CELL("address",H16), "\$([A-Z]+)\$[0-9]+"))),_xlfn.REGEXEXTRACT(CELL("address",H16), "\$([A-Z]+)\$[0-9]+"))} | I16: {=IFERROR(IF(OR('Raw Data'!I16="",LEN(TRIM('Raw Data'!I16))=0),"",IF(AND(LEN('Raw Data'!I16) <= 50,LEN('Raw Data'!I16)> 0),"",_xlfn.REGEXEXTRACT(CELL("address",'Raw Data'!I16),"\$([A-Z]+)\$[0-9]+"))),_xlfn.REGEXEXTRACT(CELL("address",'Raw Data'!I16),"\$([A-Z]+)\$[0-9]+"))} | J16: {=IFERROR(IF(OR('Raw Data'!J16="",LEN(TRIM('Raw Data'!J16))=0),"",IF(AND(ISNUMBER('Raw Data'!J16),'Raw Data'!J16>=Configuration!$D$2),"",_xlfn.REGEXEXTRACT(CELL("address",'Raw Data'!J16),"\$([A-Z]+)\$[0-9]+"))),_xlfn.REGEXEXTRACT(CELL("address",J16), "\$([A-Z]+)\$[0-9]+"))} | K16: {=IFERROR(IF(OR('Raw Data'!K16="",LEN(TRIM('Raw Data'!K16))=0),"",IF(AND(ISNUMBER('Raw Data'!K16), IFERROR('Raw Data'!K16 = ROUND('Raw Data'!K16, 2),FALSE)),"",_xlfn.REGEXEXTRACT(CELL("address",K16), "\$([A-Z]+)\$[0-9]+"))),_xlfn.REGEXEXTRACT(CELL("address",K16), "\$([A-Z]+)\$[0-9]+"))} | L16: {=IFERROR(IF(OR('Raw Data'!L16="",LEN(TRIM('Raw Data'!L16))=0),"",IF(AND(ISNUMBER('Raw Data'!L16), IFERROR('Raw Data'!L16 = ROUND('Raw Data'!L16, 2),FALSE)),"",_xlfn.REGEXEXTRACT(CELL("address",L16), "\$([A-Z]+)\$[0-9]+"))),_xlfn.REGEXEXTRACT(CELL("address",L16), "\$([A-Z]+)\$[0-9]+"))} | M16: {=IFERROR(IF(OR('Raw Data'!M16="",LEN(TRIM('Raw Data'!M16))=0),"",IF(AND(ISNUMBER('Raw Data'!M16), IFERROR('Raw Data'!M16 = ROUND('Raw Data'!M16, 2),FALSE)),"",_xlfn.REGEXEXTRACT(CELL("address",M16), "\$([A-Z]+)\$[0-9]+"))),_xlfn.REGEXEXTRACT(CELL("address",M16), "\$([A-Z]+)\$[0-9]+"))} | N16: {=IFERROR(IF(OR('Raw Data'!N16="",LEN(TRIM('Raw Data'!N16))=0),"",IF(AND(ISNUMBER('Raw Data'!N16), IFERROR('Raw Data'!N16 = ROUND('Raw Data'!N16, 2),FALSE)),"",_xlfn.REGEXEXTRACT(CELL("address",N16), "\$([A-Z]+)\$[0-9]+"))),_xlfn.REGEXEXTRACT(CELL("address",N16), "\$([A-Z]+)\$[0-9]+"))} | O16: {=IFERROR(IF(OR('Raw Data'!O16="",LEN(TRIM('Raw Data'!O16))=0),"",IF(AND(ISNUMBER('Raw Data'!O16), IFERROR('Raw Data'!O16 = ROUND('Raw Data'!O16, 2),FALSE)),"",_xlfn.REGEXEXTRACT(CELL("address",O16), "\$([A-Z]+)\$[0-9]+"))),_xlfn.REGEXEXTRACT(CELL("address",O16), "\$([A-Z]+)\$[0-9]+"))} | P16: {=IFERROR(IF(OR('Raw Data'!P16="",LEN(TRIM('Raw Data'!P16))=0),"",IF(AND(ISNUMBER('Raw Data'!P16),'Raw Data'!P16>=Configuration!$D$2),"",_xlfn.REGEXEXTRACT(CELL("address",'Raw Data'!P16),"\$([A-Z]+)\$[0-9]+"))),_xlfn.REGEXEXTRACT(CELL("address",P16), "\$([A-Z]+)\$[0-9]+"))} | Q16: {=IFERROR(IF(OR('Raw Data'!Q16="",LEN(TRIM('Raw Data'!Q16))=0),"",IF(AND(ISNUMBER('Raw Data'!Q16),'Raw Data'!Q16>=Configuration!$D$2),"",_xlfn.REGEXEXTRACT(CELL("address",'Raw Data'!Q16),"\$([A-Z]+)\$[0-9]+"))),_xlfn.REGEXEXTRACT(CELL("address",Q16), "\$([A-Z]+)\$[0-9]+"))} | R16: {=IFERROR(IF(OR('Raw Data'!R16="",LEN(TRIM('Raw Data'!R16))=0),"",IF(AND(ISNUMBER('Raw Data'!R16), IFERROR('Raw Data'!R16 = ROUND('Raw Data'!R16, 2),FALSE)),"",_xlfn.REGEXEXTRACT(CELL("address",R16), "\$([A-Z]+)\$[0-9]+"))),_xlfn.REGEXEXTRACT(CELL("address",R16), "\$([A-Z]+)\$[0-9]+"))} | S16: {=IFERROR(IF(OR('Raw Data'!S16="",LEN(TRIM('Raw Data'!S16))=0),"",IF(AND(ISNUMBER('Raw Data'!S16), IFERROR('Raw Data'!S16 = ROUND('Raw Data'!S16, 2),FALSE)),"",_xlfn.REGEXEXTRACT(CELL("address",S16), "\$([A-Z]+)\$[0-9]+"))),_xlfn.REGEXEXTRACT(CELL("address",S16), "\$([A-Z]+)\$[0-9]+"))} | T16: {=IFERROR(IF(OR('Raw Data'!T16="",LEN(TRIM('Raw Data'!T16))=0),"",IF(AND(ISNUMBER('Raw Data'!T16), IFERROR('Raw Data'!T16 = ROUND('Raw Data'!T16, 2),FALSE)),"",_xlfn.REGEXEXTRACT(CELL("address",T16), "\$([A-Z]+)\$[0-9]+"))),_xlfn.REGEXEXTRACT(CELL("address",T16), "\$([A-Z]+)\$[0-9]+"))} | U16: {=IFERROR(IF(OR('Raw Data'!U16="",LEN(TRIM('Raw Data'!U16))=0),"",IF(AND(LEN('Raw Data'!U16) <= 5,LEN('Raw Data'!U16)> 0),"",_xlfn.REGEXEXTRACT(CELL("address",'Raw Data'!U16),"\$([A-Z]+)\$[0-9]+"))),_xlfn.REGEXEXTRACT(CELL("address",'Raw Data'!U16),"\$([A-Z]+)\$[0-9]+"))} | V16: {=IFERROR(IF(OR('Raw Data'!V16="",LEN(TRIM('Raw Data'!V16))=0),"",IF(AND(ISNUMBER('Raw Data'!V16), IFERROR('Raw Data'!V16 = ROUND('Raw Data'!V16, 2),FALSE)),"",_xlfn.REGEXEXTRACT(CELL("address",V16), "\$([A-Z]+)\$[0-9]+"))),_xlfn.REGEXEXTRACT(CELL("address",V16), "\$([A-Z]+)\$[0-9]+"))} | W16: {=IFERROR(IF(OR('Raw Data'!W16="",LEN(TRIM('Raw Data'!W16))=0),"",IF(AND(ISNUMBER('Raw Data'!W16), IFERROR('Raw Data'!W16 = ROUND('Raw Data'!W16, 2),FALSE)),"",_xlfn.REGEXEXTRACT(CELL("address",W16), "\$([A-Z]+)\$[0-9]+"))),_xlfn.REGEXEXTRACT(CELL("address",W16), "\$([A-Z]+)\$[0-9]+"))} | X16: {=IFERROR(IF(OR('Raw Data'!X16="",LEN(TRIM('Raw Data'!X16))=0),"",IF(AND(ISNUMBER('Raw Data'!X16), IFERROR('Raw Data'!X16 = ROUND('Raw Data'!X16, 2),FALSE)),"",_xlfn.REGEXEXTRACT(CELL("address",X16), "\$([A-Z]+)\$[0-9]+"))),_xlfn.REGEXEXTRACT(CELL("address",X16), "\$([A-Z]+)\$[0-9]+"))}
B17: {=IFERROR(IF(OR('Raw Data'!B17="",LEN(TRIM('Raw Data'!B17))=0),"",IF(AND(LEN('Raw Data'!B17) <= 50,LEN('Raw Data'!B17)> 0),"",_xlfn.REGEXEXTRACT(CELL("address",'Raw Data'!B17),"\$([A-Z]+)\$[0-9]+"))),_xlfn.REGEXEXTRACT(CELL("address",'Raw Data'!B17),"\$([A-Z]+)\$[0-9]+"))} | C17: {=IFERROR(IF(OR('Raw Data'!C17="",LEN(TRIM('Raw Data'!C17))=0),"",IF(AND(LEN('Raw Data'!C17) <= 50,LEN('Raw Data'!C17)> 0),"",_xlfn.REGEXEXTRACT(CELL("address",'Raw Data'!C17),"\$([A-Z]+)\$[0-9]+"))),_xlfn.REGEXEXTRACT(CELL("address",'Raw Data'!C17),"\$([A-Z]+)\$[0-9]+"))} | D17: {=IFERROR(IF(OR('Raw Data'!D17="",LEN(TRIM('Raw Data'!D17))=0),"",IF(AND(LEN('Raw Data'!D17) <= 255,LEN('Raw Data'!D17)> 0),"",_xlfn.REGEXEXTRACT(CELL("address",'Raw Data'!D17),"\$([A-Z]+)\$[0-9]+"))),_xlfn.REGEXEXTRACT(CELL("address",'Raw Data'!D17),"\$([A-Z]+)\$[0-9]+"))} | E17: {=IFERROR(IF(OR('Raw Data'!E17="",LEN(TRIM('Raw Data'!E17))=0),"",IF(AND(ISNUMBER('Raw Data'!E17),'Raw Data'!E17>=Configuration!$D$2),"",_xlfn.REGEXEXTRACT(CELL("address",'Raw Data'!E17),"\$([A-Z]+)\$[0-9]+"))),_xlfn.REGEXEXTRACT(CELL("address",E17), "\$([A-Z]+)\$[0-9]+"))} | F17: {=IFERROR(IF(OR('Raw Data'!F17="",LEN(TRIM('Raw Data'!F17))=0),"",IF(AND(LEN('Raw Data'!F17) <= 20,LEN('Raw Data'!F17)> 0),"",_xlfn.REGEXEXTRACT(CELL("address",'Raw Data'!F17),"\$([A-Z]+)\$[0-9]+"))),_xlfn.REGEXEXTRACT(CELL("address",'Raw Data'!F17),"\$([A-Z]+)\$[0-9]+"))} | G17: {=IFERROR(IF(OR('Raw Data'!G17="",LEN(TRIM('Raw Data'!G17))=0),"",IF(AND(ISNUMBER('Raw Data'!G17), IFERROR('Raw Data'!G17 = ROUND('Raw Data'!G17, 2),FALSE)),"",_xlfn.REGEXEXTRACT(CELL("address",G17), "\$([A-Z]+)\$[0-9]+"))),_xlfn.REGEXEXTRACT(CELL("address",G17), "\$([A-Z]+)\$[0-9]+"))} | H17: {=IFERROR(IF(OR('Raw Data'!H17="",LEN(TRIM('Raw Data'!H17))=0),"",IF(AND(ISNUMBER('Raw Data'!H17), IFERROR('Raw Data'!H17 = ROUND('Raw Data'!H17, 2),FALSE)),"",_xlfn.REGEXEXTRACT(CELL("address",H17), "\$([A-Z]+)\$[0-9]+"))),_xlfn.REGEXEXTRACT(CELL("address",H17), "\$([A-Z]+)\$[0-9]+"))} | I17: {=IFERROR(IF(OR('Raw Data'!I17="",LEN(TRIM('Raw Data'!I17))=0),"",IF(AND(LEN('Raw Data'!I17) <= 50,LEN('Raw Data'!I17)> 0),"",_xlfn.REGEXEXTRACT(CELL("address",'Raw Data'!I17),"\$([A-Z]+)\$[0-9]+"))),_xlfn.REGEXEXTRACT(CELL("address",'Raw Data'!I17),"\$([A-Z]+)\$[0-9]+"))} | J17: {=IFERROR(IF(OR('Raw Data'!J17="",LEN(TRIM('Raw Data'!J17))=0),"",IF(AND(ISNUMBER('Raw Data'!J17),'Raw Data'!J17>=Configuration!$D$2),"",_xlfn.REGEXEXTRACT(CELL("address",'Raw Data'!J17),"\$([A-Z]+)\$[0-9]+"))),_xlfn.REGEXEXTRACT(CELL("address",J17), "\$([A-Z]+)\$[0-9]+"))} | K17: {=IFERROR(IF(OR('Raw Data'!K17="",LEN(TRIM('Raw Data'!K17))=0),"",IF(AND(ISNUMBER('Raw Data'!K17), IFERROR('Raw Data'!K17 = ROUND('Raw Data'!K17, 2),FALSE)),"",_xlfn.REGEXEXTRACT(CELL("address",K17), "\$([A-Z]+)\$[0-9]+"))),_xlfn.REGEXEXTRACT(CELL("address",K17), "\$([A-Z]+)\$[0-9]+"))} | L17: {=IFERROR(IF(OR('Raw Data'!L17="",LEN(TRIM('Raw Data'!L17))=0),"",IF(AND(ISNUMBER('Raw Data'!L17), IFERROR('Raw Data'!L17 = ROUND('Raw Data'!L17, 2),FALSE)),"",_xlfn.REGEXEXTRACT(CELL("address",L17), "\$([A-Z]+)\$[0-9]+"))),_xlfn.REGEXEXTRACT(CELL("address",L17), "\$([A-Z]+)\$[0-9]+"))} | M17: {=IFERROR(IF(OR('Raw Data'!M17="",LEN(TRIM('Raw Data'!M17))=0),"",IF(AND(ISNUMBER('Raw Data'!M17), IFERROR('Raw Data'!M17 = ROUND('Raw Data'!M17, 2),FALSE)),"",_xlfn.REGEXEXTRACT(CELL("address",M17), "\$([A-Z]+)\$[0-9]+"))),_xlfn.REGEXEXTRACT(CELL("address",M17), "\$([A-Z]+)\$[0-9]+"))} | N17: {=IFERROR(IF(OR('Raw Data'!N17="",LEN(TRIM('Raw Data'!N17))=0),"",IF(AND(ISNUMBER('Raw Data'!N17), IFERROR('Raw Data'!N17 = ROUND('Raw Data'!N17, 2),FALSE)),"",_xlfn.REGEXEXTRACT(CELL("address",N17), "\$([A-Z]+)\$[0-9]+"))),_xlfn.REGEXEXTRACT(CELL("address",N17), "\$([A-Z]+)\$[0-9]+"))} | O17: {=IFERROR(IF(OR('Raw Data'!O17="",LEN(TRIM('Raw Data'!O17))=0),"",IF(AND(ISNUMBER('Raw Data'!O17), IFERROR('Raw Data'!O17 = ROUND('Raw Data'!O17, 2),FALSE)),"",_xlfn.REGEXEXTRACT(CELL("address",O17), "\$([A-Z]+)\$[0-9]+"))),_xlfn.REGEXEXTRACT(CELL("address",O17), "\$([A-Z]+)\$[0-9]+"))} | P17: {=IFERROR(IF(OR('Raw Data'!P17="",LEN(TRIM('Raw Data'!P17))=0),"",IF(AND(ISNUMBER('Raw Data'!P17),'Raw Data'!P17>=Configuration!$D$2),"",_xlfn.REGEXEXTRACT(CELL("address",'Raw Data'!P17),"\$([A-Z]+)\$[0-9]+"))),_xlfn.REGEXEXTRACT(CELL("address",P17), "\$([A-Z]+)\$[0-9]+"))} | Q17: {=IFERROR(IF(OR('Raw Data'!Q17="",LEN(TRIM('Raw Data'!Q17))=0),"",IF(AND(ISNUMBER('Raw Data'!Q17),'Raw Data'!Q17>=Configuration!$D$2),"",_xlfn.REGEXEXTRACT(CELL("address",'Raw Data'!Q17),"\$([A-Z]+)\$[0-9]+"))),_xlfn.REGEXEXTRACT(CELL("address",Q17), "\$([A-Z]+)\$[0-9]+"))} | R17: {=IFERROR(IF(OR('Raw Data'!R17="",LEN(TRIM('Raw Data'!R17))=0),"",IF(AND(ISNUMBER('Raw Data'!R17), IFERROR('Raw Data'!R17 = ROUND('Raw Data'!R17, 2),FALSE)),"",_xlfn.REGEXEXTRACT(CELL("address",R17), "\$([A-Z]+)\$[0-9]+"))),_xlfn.REGEXEXTRACT(CELL("address",R17), "\$([A-Z]+)\$[0-9]+"))} | S17: {=IFERROR(IF(OR('Raw Data'!S17="",LEN(TRIM('Raw Data'!S17))=0),"",IF(AND(ISNUMBER('Raw Data'!S17), IFERROR('Raw Data'!S17 = ROUND('Raw Data'!S17, 2),FALSE)),"",_xlfn.REGEXEXTRACT(CELL("address",S17), "\$([A-Z]+)\$[0-9]+"))),_xlfn.REGEXEXTRACT(CELL("address",S17), "\$([A-Z]+)\$[0-9]+"))} | T17: {=IFERROR(IF(OR('Raw Data'!T17="",LEN(TRIM('Raw Data'!T17))=0),"",IF(AND(ISNUMBER('Raw Data'!T17), IFERROR('Raw Data'!T17 = ROUND('Raw Data'!T17, 2),FALSE)),"",_xlfn.REGEXEXTRACT(CELL("address",T17), "\$([A-Z]+)\$[0-9]+"))),_xlfn.REGEXEXTRACT(CELL("address",T17), "\$([A-Z]+)\$[0-9]+"))} | U17: {=IFERROR(IF(OR('Raw Data'!U17="",LEN(TRIM('Raw Data'!U17))=0),"",IF(AND(LEN('Raw Data'!U17) <= 5,LEN('Raw Data'!U17)> 0),"",_xlfn.REGEXEXTRACT(CELL("address",'Raw Data'!U17),"\$([A-Z]+)\$[0-9]+"))),_xlfn.REGEXEXTRACT(CELL("address",'Raw Data'!U17),"\$([A-Z]+)\$[0-9]+"))} | V17: {=IFERROR(IF(OR('Raw Data'!V17="",LEN(TRIM('Raw Data'!V17))=0),"",IF(AND(ISNUMBER('Raw Data'!V17), IFERROR('Raw Data'!V17 = ROUND('Raw Data'!V17, 2),FALSE)),"",_xlfn.REGEXEXTRACT(CELL("address",V17), "\$([A-Z]+)\$[0-9]+"))),_xlfn.REGEXEXTRACT(CELL("address",V17), "\$([A-Z]+)\$[0-9]+"))} | W17: {=IFERROR(IF(OR('Raw Data'!W17="",LEN(TRIM('Raw Data'!W17))=0),"",IF(AND(ISNUMBER('Raw Data'!W17), IFERROR('Raw Data'!W17 = ROUND('Raw Data'!W17, 2),FALSE)),"",_xlfn.REGEXEXTRACT(CELL("address",W17), "\$([A-Z]+)\$[0-9]+"))),_xlfn.REGEXEXTRACT(CELL("address",W17), "\$([A-Z]+)\$[0-9]+"))} | X17: {=IFERROR(IF(OR('Raw Data'!X17="",LEN(TRIM('Raw Data'!X17))=0),"",IF(AND(ISNUMBER('Raw Data'!X17), IFERROR('Raw Data'!X17 = ROUND('Raw Data'!X17, 2),FALSE)),"",_xlfn.REGEXEXTRACT(CELL("address",X17), "\$([A-Z]+)\$[0-9]+"))),_xlfn.REGEXEXTRACT(CELL("address",X17), "\$([A-Z]+)\$[0-9]+"))}
B18: {=IFERROR(IF(OR('Raw Data'!B18="",LEN(TRIM('Raw Data'!B18))=0),"",IF(AND(LEN('Raw Data'!B18) <= 50,LEN('Raw Data'!B18)> 0),"",_xlfn.REGEXEXTRACT(CELL("address",'Raw Data'!B18),"\$([A-Z]+)\$[0-9]+"))),_xlfn.REGEXEXTRACT(CELL("address",'Raw Data'!B18),"\$([A-Z]+)\$[0-9]+"))} | C18: {=IFERROR(IF(OR('Raw Data'!C18="",LEN(TRIM('Raw Data'!C18))=0),"",IF(AND(LEN('Raw Data'!C18) <= 50,LEN('Raw Data'!C18)> 0),"",_xlfn.REGEXEXTRACT(CELL("address",'Raw Data'!C18),"\$([A-Z]+)\$[0-9]+"))),_xlfn.REGEXEXTRACT(CELL("address",'Raw Data'!C18),"\$([A-Z]+)\$[0-9]+"))} | D18: {=IFERROR(IF(OR('Raw Data'!D18="",LEN(TRIM('Raw Data'!D18))=0),"",IF(AND(LEN('Raw Data'!D18) <= 255,LEN('Raw Data'!D18)> 0),"",_xlfn.REGEXEXTRACT(CELL("address",'Raw Data'!D18),"\$([A-Z]+)\$[0-9]+"))),_xlfn.REGEXEXTRACT(CELL("address",'Raw Data'!D18),"\$([A-Z]+)\$[0-9]+"))} | E18: {=IFERROR(IF(OR('Raw Data'!E18="",LEN(TRIM('Raw Data'!E18))=0),"",IF(AND(ISNUMBER('Raw Data'!E18),'Raw Data'!E18>=Configuration!$D$2),"",_xlfn.REGEXEXTRACT(CELL("address",'Raw Data'!E18),"\$([A-Z]+)\$[0-9]+"))),_xlfn.REGEXEXTRACT(CELL("address",E18), "\$([A-Z]+)\$[0-9]+"))} | F18: {=IFERROR(IF(OR('Raw Data'!F18="",LEN(TRIM('Raw Data'!F18))=0),"",IF(AND(LEN('Raw Data'!F18) <= 20,LEN('Raw Data'!F18)> 0),"",_xlfn.REGEXEXTRACT(CELL("address",'Raw Data'!F18),"\$([A-Z]+)\$[0-9]+"))),_xlfn.REGEXEXTRACT(CELL("address",'Raw Data'!F18),"\$([A-Z]+)\$[0-9]+"))} | G18: {=IFERROR(IF(OR('Raw Data'!G18="",LEN(TRIM('Raw Data'!G18))=0),"",IF(AND(ISNUMBER('Raw Data'!G18), IFERROR('Raw Data'!G18 = ROUND('Raw Data'!G18, 2),FALSE)),"",_xlfn.REGEXEXTRACT(CELL("address",G18), "\$([A-Z]+)\$[0-9]+"))),_xlfn.REGEXEXTRACT(CELL("address",G18), "\$([A-Z]+)\$[0-9]+"))} | H18: {=IFERROR(IF(OR('Raw Data'!H18="",LEN(TRIM('Raw Data'!H18))=0),"",IF(AND(ISNUMBER('Raw Data'!H18), IFERROR('Raw Data'!H18 = ROUND('Raw Data'!H18, 2),FALSE)),"",_xlfn.REGEXEXTRACT(CELL("address",H18), "\$([A-Z]+)\$[0-9]+"))),_xlfn.REGEXEXTRACT(CELL("address",H18), "\$([A-Z]+)\$[0-9]+"))} | I18: {=IFERROR(IF(OR('Raw Data'!I18="",LEN(TRIM('Raw Data'!I18))=0),"",IF(AND(LEN('Raw Data'!I18) <= 50,LEN('Raw Data'!I18)> 0),"",_xlfn.REGEXEXTRACT(CELL("address",'Raw Data'!I18),"\$([A-Z]+)\$[0-9]+"))),_xlfn.REGEXEXTRACT(CELL("address",'Raw Data'!I18),"\$([A-Z]+)\$[0-9]+"))} | J18: {=IFERROR(IF(OR('Raw Data'!J18="",LEN(TRIM('Raw Data'!J18))=0),"",IF(AND(ISNUMBER('Raw Data'!J18),'Raw Data'!J18>=Configuration!$D$2),"",_xlfn.REGEXEXTRACT(CELL("address",'Raw Data'!J18),"\$([A-Z]+)\$[0-9]+"))),_xlfn.REGEXEXTRACT(CELL("address",J18), "\$([A-Z]+)\$[0-9]+"))} | K18: {=IFERROR(IF(OR('Raw Data'!K18="",LEN(TRIM('Raw Data'!K18))=0),"",IF(AND(ISNUMBER('Raw Data'!K18), IFERROR('Raw Data'!K18 = ROUND('Raw Data'!K18, 2),FALSE)),"",_xlfn.REGEXEXTRACT(CELL("address",K18), "\$([A-Z]+)\$[0-9]+"))),_xlfn.REGEXEXTRACT(CELL("address",K18), "\$([A-Z]+)\$[0-9]+"))} | L18: {=IFERROR(IF(OR('Raw Data'!L18="",LEN(TRIM('Raw Data'!L18))=0),"",IF(AND(ISNUMBER('Raw Data'!L18), IFERROR('Raw Data'!L18 = ROUND('Raw Data'!L18, 2),FALSE)),"",_xlfn.REGEXEXTRACT(CELL("address",L18), "\$([A-Z]+)\$[0-9]+"))),_xlfn.REGEXEXTRACT(CELL("address",L18), "\$([A-Z]+)\$[0-9]+"))} | M18: {=IFERROR(IF(OR('Raw Data'!M18="",LEN(TRIM('Raw Data'!M18))=0),"",IF(AND(ISNUMBER('Raw Data'!M18), IFERROR('Raw Data'!M18 = ROUND('Raw Data'!M18, 2),FALSE)),"",_xlfn.REGEXEXTRACT(CELL("address",M18), "\$([A-Z]+)\$[0-9]+"))),_xlfn.REGEXEXTRACT(CELL("address",M18), "\$([A-Z]+)\$[0-9]+"))} | N18: {=IFERROR(IF(OR('Raw Data'!N18="",LEN(TRIM('Raw Data'!N18))=0),"",IF(AND(ISNUMBER('Raw Data'!N18), IFERROR('Raw Data'!N18 = ROUND('Raw Data'!N18, 2),FALSE)),"",_xlfn.REGEXEXTRACT(CELL("address",N18), "\$([A-Z]+)\$[0-9]+"))),_xlfn.REGEXEXTRACT(CELL("address",N18), "\$([A-Z]+)\$[0-9]+"))} | O18: {=IFERROR(IF(OR('Raw Data'!O18="",LEN(TRIM('Raw Data'!O18))=0),"",IF(AND(ISNUMBER('Raw Data'!O18), IFERROR('Raw Data'!O18 = ROUND('Raw Data'!O18, 2),FALSE)),"",_xlfn.REGEXEXTRACT(CELL("address",O18), "\$([A-Z]+)\$[0-9]+"))),_xlfn.REGEXEXTRACT(CELL("address",O18), "\$([A-Z]+)\$[0-9]+"))} | P18: {=IFERROR(IF(OR('Raw Data'!P18="",LEN(TRIM('Raw Data'!P18))=0),"",IF(AND(ISNUMBER('Raw Data'!P18),'Raw Data'!P18>=Configuration!$D$2),"",_xlfn.REGEXEXTRACT(CELL("address",'Raw Data'!P18),"\$([A-Z]+)\$[0-9]+"))),_xlfn.REGEXEXTRACT(CELL("address",P18), "\$([A-Z]+)\$[0-9]+"))} | Q18: {=IFERROR(IF(OR('Raw Data'!Q18="",LEN(TRIM('Raw Data'!Q18))=0),"",IF(AND(ISNUMBER('Raw Data'!Q18),'Raw Data'!Q18>=Configuration!$D$2),"",_xlfn.REGEXEXTRACT(CELL("address",'Raw Data'!Q18),"\$([A-Z]+)\$[0-9]+"))),_xlfn.REGEXEXTRACT(CELL("address",Q18), "\$([A-Z]+)\$[0-9]+"))} | R18: {=IFERROR(IF(OR('Raw Data'!R18="",LEN(TRIM('Raw Data'!R18))=0),"",IF(AND(ISNUMBER('Raw Data'!R18), IFERROR('Raw Data'!R18 = ROUND('Raw Data'!R18, 2),FALSE)),"",_xlfn.REGEXEXTRACT(CELL("address",R18), "\$([A-Z]+)\$[0-9]+"))),_xlfn.REGEXEXTRACT(CELL("address",R18), "\$([A-Z]+)\$[0-9]+"))} | S18: {=IFERROR(IF(OR('Raw Data'!S18="",LEN(TRIM('Raw Data'!S18))=0),"",IF(AND(ISNUMBER('Raw Data'!S18), IFERROR('Raw Data'!S18 = ROUND('Raw Data'!S18, 2),FALSE)),"",_xlfn.REGEXEXTRACT(CELL("address",S18), "\$([A-Z]+)\$[0-9]+"))),_xlfn.REGEXEXTRACT(CELL("address",S18), "\$([A-Z]+)\$[0-9]+"))} | T18: {=IFERROR(IF(OR('Raw Data'!T18="",LEN(TRIM('Raw Data'!T18))=0),"",IF(AND(ISNUMBER('Raw Data'!T18), IFERROR('Raw Data'!T18 = ROUND('Raw Data'!T18, 2),FALSE)),"",_xlfn.REGEXEXTRACT(CELL("address",T18), "\$([A-Z]+)\$[0-9]+"))),_xlfn.REGEXEXTRACT(CELL("address",T18), "\$([A-Z]+)\$[0-9]+"))} | U18: {=IFERROR(IF(OR('Raw Data'!U18="",LEN(TRIM('Raw Data'!U18))=0),"",IF(AND(LEN('Raw Data'!U18) <= 5,LEN('Raw Data'!U18)> 0),"",_xlfn.REGEXEXTRACT(CELL("address",'Raw Data'!U18),"\$([A-Z]+)\$[0-9]+"))),_xlfn.REGEXEXTRACT(CELL("address",'Raw Data'!U18),"\$([A-Z]+)\$[0-9]+"))} | V18: {=IFERROR(IF(OR('Raw Data'!V18="",LEN(TRIM('Raw Data'!V18))=0),"",IF(AND(ISNUMBER('Raw Data'!V18), IFERROR('Raw Data'!V18 = ROUND('Raw Data'!V18, 2),FALSE)),"",_xlfn.REGEXEXTRACT(CELL("address",V18), "\$([A-Z]+)\$[0-9]+"))),_xlfn.REGEXEXTRACT(CELL("address",V18), "\$([A-Z]+)\$[0-9]+"))} | W18: {=IFERROR(IF(OR('Raw Data'!W18="",LEN(TRIM('Raw Data'!W18))=0),"",IF(AND(ISNUMBER('Raw Data'!W18), IFERROR('Raw Data'!W18 = ROUND('Raw Data'!W18, 2),FALSE)),"",_xlfn.REGEXEXTRACT(CELL("address",W18), "\$([A-Z]+)\$[0-9]+"))),_xlfn.REGEXEXTRACT(CELL("address",W18), "\$([A-Z]+)\$[0-9]+"))} | X18: {=IFERROR(IF(OR('Raw Data'!X18="",LEN(TRIM('Raw Data'!X18))=0),"",IF(AND(ISNUMBER('Raw Data'!X18), IFERROR('Raw Data'!X18 = ROUND('Raw Data'!X18, 2),FALSE)),"",_xlfn.REGEXEXTRACT(CELL("address",X18), "\$([A-Z]+)\$[0-9]+"))),_xlfn.REGEXEXTRACT(CELL("address",X18), "\$([A-Z]+)\$[0-9]+"))}
B19: {=IFERROR(IF(OR('Raw Data'!B19="",LEN(TRIM('Raw Data'!B19))=0),"",IF(AND(LEN('Raw Data'!B19) <= 50,LEN('Raw Data'!B19)> 0),"",_xlfn.REGEXEXTRACT(CELL("address",'Raw Data'!B19),"\$([A-Z]+)\$[0-9]+"))),_xlfn.REGEXEXTRACT(CELL("address",'Raw Data'!B19),"\$([A-Z]+)\$[0-9]+"))} | C19: {=IFERROR(IF(OR('Raw Data'!C19="",LEN(TRIM('Raw Data'!C19))=0),"",IF(AND(LEN('Raw Data'!C19) <= 50,LEN('Raw Data'!C19)> 0),"",_xlfn.REGEXEXTRACT(CELL("address",'Raw Data'!C19),"\$([A-Z]+)\$[0-9]+"))),_xlfn.REGEXEXTRACT(CELL("address",'Raw Data'!C19),"\$([A-Z]+)\$[0-9]+"))} | D19: {=IFERROR(IF(OR('Raw Data'!D19="",LEN(TRIM('Raw Data'!D19))=0),"",IF(AND(LEN('Raw Data'!D19) <= 255,LEN('Raw Data'!D19)> 0),"",_xlfn.REGEXEXTRACT(CELL("address",'Raw Data'!D19),"\$([A-Z]+)\$[0-9]+"))),_xlfn.REGEXEXTRACT(CELL("address",'Raw Data'!D19),"\$([A-Z]+)\$[0-9]+"))} | E19: {=IFERROR(IF(OR('Raw Data'!E19="",LEN(TRIM('Raw Data'!E19))=0),"",IF(AND(ISNUMBER('Raw Data'!E19),'Raw Data'!E19>=Configuration!$D$2),"",_xlfn.REGEXEXTRACT(CELL("address",'Raw Data'!E19),"\$([A-Z]+)\$[0-9]+"))),_xlfn.REGEXEXTRACT(CELL("address",E19), "\$([A-Z]+)\$[0-9]+"))} | F19: {=IFERROR(IF(OR('Raw Data'!F19="",LEN(TRIM('Raw Data'!F19))=0),"",IF(AND(LEN('Raw Data'!F19) <= 20,LEN('Raw Data'!F19)> 0),"",_xlfn.REGEXEXTRACT(CELL("address",'Raw Data'!F19),"\$([A-Z]+)\$[0-9]+"))),_xlfn.REGEXEXTRACT(CELL("address",'Raw Data'!F19),"\$([A-Z]+)\$[0-9]+"))} | G19: {=IFERROR(IF(OR('Raw Data'!G19="",LEN(TRIM('Raw Data'!G19))=0),"",IF(AND(ISNUMBER('Raw Data'!G19), IFERROR('Raw Data'!G19 = ROUND('Raw Data'!G19, 2),FALSE)),"",_xlfn.REGEXEXTRACT(CELL("address",G19), "\$([A-Z]+)\$[0-9]+"))),_xlfn.REGEXEXTRACT(CELL("address",G19), "\$([A-Z]+)\$[0-9]+"))} | H19: {=IFERROR(IF(OR('Raw Data'!H19="",LEN(TRIM('Raw Data'!H19))=0),"",IF(AND(ISNUMBER('Raw Data'!H19), IFERROR('Raw Data'!H19 = ROUND('Raw Data'!H19, 2),FALSE)),"",_xlfn.REGEXEXTRACT(CELL("address",H19), "\$([A-Z]+)\$[0-9]+"))),_xlfn.REGEXEXTRACT(CELL("address",H19), "\$([A-Z]+)\$[0-9]+"))} | I19: {=IFERROR(IF(OR('Raw Data'!I19="",LEN(TRIM('Raw Data'!I19))=0),"",IF(AND(LEN('Raw Data'!I19) <= 50,LEN('Raw Data'!I19)> 0),"",_xlfn.REGEXEXTRACT(CELL("address",'Raw Data'!I19),"\$([A-Z]+)\$[0-9]+"))),_xlfn.REGEXEXTRACT(CELL("address",'Raw Data'!I19),"\$([A-Z]+)\$[0-9]+"))} | J19: {=IFERROR(IF(OR('Raw Data'!J19="",LEN(TRIM('Raw Data'!J19))=0),"",IF(AND(ISNUMBER('Raw Data'!J19),'Raw Data'!J19>=Configuration!$D$2),"",_xlfn.REGEXEXTRACT(CELL("address",'Raw Data'!J19),"\$([A-Z]+)\$[0-9]+"))),_xlfn.REGEXEXTRACT(CELL("address",J19), "\$([A-Z]+)\$[0-9]+"))} | K19: {=IFERROR(IF(OR('Raw Data'!K19="",LEN(TRIM('Raw Data'!K19))=0),"",IF(AND(ISNUMBER('Raw Data'!K19), IFERROR('Raw Data'!K19 = ROUND('Raw Data'!K19, 2),FALSE)),"",_xlfn.REGEXEXTRACT(CELL("address",K19), "\$([A-Z]+)\$[0-9]+"))),_xlfn.REGEXEXTRACT(CELL("address",K19), "\$([A-Z]+)\$[0-9]+"))} | L19: {=IFERROR(IF(OR('Raw Data'!L19="",LEN(TRIM('Raw Data'!L19))=0),"",IF(AND(ISNUMBER('Raw Data'!L19), IFERROR('Raw Data'!L19 = ROUND('Raw Data'!L19, 2),FALSE)),"",_xlfn.REGEXEXTRACT(CELL("address",L19), "\$([A-Z]+)\$[0-9]+"))),_xlfn.REGEXEXTRACT(CELL("address",L19), "\$([A-Z]+)\$[0-9]+"))} | M19: {=IFERROR(IF(OR('Raw Data'!M19="",LEN(TRIM('Raw Data'!M19))=0),"",IF(AND(ISNUMBER('Raw Data'!M19), IFERROR('Raw Data'!M19 = ROUND('Raw Data'!M19, 2),FALSE)),"",_xlfn.REGEXEXTRACT(CELL("address",M19), "\$([A-Z]+)\$[0-9]+"))),_xlfn.REGEXEXTRACT(CELL("address",M19), "\$([A-Z]+)\$[0-9]+"))} | N19: {=IFERROR(IF(OR('Raw Data'!N19="",LEN(TRIM('Raw Data'!N19))=0),"",IF(AND(ISNUMBER('Raw Data'!N19), IFERROR('Raw Data'!N19 = ROUND('Raw Data'!N19, 2),FALSE)),"",_xlfn.REGEXEXTRACT(CELL("address",N19), "\$([A-Z]+)\$[0-9]+"))),_xlfn.REGEXEXTRACT(CELL("address",N19), "\$([A-Z]+)\$[0-9]+"))} | O19: {=IFERROR(IF(OR('Raw Data'!O19="",LEN(TRIM('Raw Data'!O19))=0),"",IF(AND(ISNUMBER('Raw Data'!O19), IFERROR('Raw Data'!O19 = ROUND('Raw Data'!O19, 2),FALSE)),"",_xlfn.REGEXEXTRACT(CELL("address",O19), "\$([A-Z]+)\$[0-9]+"))),_xlfn.REGEXEXTRACT(CELL("address",O19), "\$([A-Z]+)\$[0-9]+"))} | P19: {=IFERROR(IF(OR('Raw Data'!P19="",LEN(TRIM('Raw Data'!P19))=0),"",IF(AND(ISNUMBER('Raw Data'!P19),'Raw Data'!P19>=Configuration!$D$2),"",_xlfn.REGEXEXTRACT(CELL("address",'Raw Data'!P19),"\$([A-Z]+)\$[0-9]+"))),_xlfn.REGEXEXTRACT(CELL("address",P19), "\$([A-Z]+)\$[0-9]+"))} | Q19: {=IFERROR(IF(OR('Raw Data'!Q19="",LEN(TRIM('Raw Data'!Q19))=0),"",IF(AND(ISNUMBER('Raw Data'!Q19),'Raw Data'!Q19>=Configuration!$D$2),"",_xlfn.REGEXEXTRACT(CELL("address",'Raw Data'!Q19),"\$([A-Z]+)\$[0-9]+"))),_xlfn.REGEXEXTRACT(CELL("address",Q19), "\$([A-Z]+)\$[0-9]+"))} | R19: {=IFERROR(IF(OR('Raw Data'!R19="",LEN(TRIM('Raw Data'!R19))=0),"",IF(AND(ISNUMBER('Raw Data'!R19), IFERROR('Raw Data'!R19 = ROUND('Raw Data'!R19, 2),FALSE)),"",_xlfn.REGEXEXTRACT(CELL("address",R19), "\$([A-Z]+)\$[0-9]+"))),_xlfn.REGEXEXTRACT(CELL("address",R19), "\$([A-Z]+)\$[0-9]+"))} | S19: {=IFERROR(IF(OR('Raw Data'!S19="",LEN(TRIM('Raw Data'!S19))=0),"",IF(AND(ISNUMBER('Raw Data'!S19), IFERROR('Raw Data'!S19 = ROUND('Raw Data'!S19, 2),FALSE)),"",_xlfn.REGEXEXTRACT(CELL("address",S19), "\$([A-Z]+)\$[0-9]+"))),_xlfn.REGEXEXTRACT(CELL("address",S19), "\$([A-Z]+)\$[0-9]+"))} | T19: {=IFERROR(IF(OR('Raw Data'!T19="",LEN(TRIM('Raw Data'!T19))=0),"",IF(AND(ISNUMBER('Raw Data'!T19), IFERROR('Raw Data'!T19 = ROUND('Raw Data'!T19, 2),FALSE)),"",_xlfn.REGEXEXTRACT(CELL("address",T19), "\$([A-Z]+)\$[0-9]+"))),_xlfn.REGEXEXTRACT(CELL("address",T19), "\$([A-Z]+)\$[0-9]+"))} | U19: {=IFERROR(IF(OR('Raw Data'!U19="",LEN(TRIM('Raw Data'!U19))=0),"",IF(AND(LEN('Raw Data'!U19) <= 5,LEN('Raw Data'!U19)> 0),"",_xlfn.REGEXEXTRACT(CELL("address",'Raw Data'!U19),"\$([A-Z]+)\$[0-9]+"))),_xlfn.REGEXEXTRACT(CELL("address",'Raw Data'!U19),"\$([A-Z]+)\$[0-9]+"))} | V19: {=IFERROR(IF(OR('Raw Data'!V19="",LEN(TRIM('Raw Data'!V19))=0),"",IF(AND(ISNUMBER('Raw Data'!V19), IFERROR('Raw Data'!V19 = ROUND('Raw Data'!V19, 2),FALSE)),"",_xlfn.REGEXEXTRACT(CELL("address",V19), "\$([A-Z]+)\$[0-9]+"))),_xlfn.REGEXEXTRACT(CELL("address",V19), "\$([A-Z]+)\$[0-9]+"))} | W19: {=IFERROR(IF(OR('Raw Data'!W19="",LEN(TRIM('Raw Data'!W19))=0),"",IF(AND(ISNUMBER('Raw Data'!W19), IFERROR('Raw Data'!W19 = ROUND('Raw Data'!W19, 2),FALSE)),"",_xlfn.REGEXEXTRACT(CELL("address",W19), "\$([A-Z]+)\$[0-9]+"))),_xlfn.REGEXEXTRACT(CELL("address",W19), "\$([A-Z]+)\$[0-9]+"))} | X19: {=IFERROR(IF(OR('Raw Data'!X19="",LEN(TRIM('Raw Data'!X19))=0),"",IF(AND(ISNUMBER('Raw Data'!X19), IFERROR('Raw Data'!X19 = ROUND('Raw Data'!X19, 2),FALSE)),"",_xlfn.REGEXEXTRACT(CELL("address",X19), "\$([A-Z]+)\$[0-9]+"))),_xlfn.REGEXEXTRACT(CELL("address",X19), "\$([A-Z]+)\$[0-9]+"))}
