Workbook

Sheet Raw Data
B9: C1 | C9: C2 | D9: C3 | E9: C4 | F9: C5 | G9: C6 | H9: C7 | I9: C8 | J9: C9 | K9: C10 | L9: C11 | M9: C12 | N9: C13 | O9: C14 | P9: C15 | Q9: C16 | R9: C17 | S9: C18 | T9: C19 | U9: C20
B10: Month # 1 | C10: 45536 | D10: 0 | E10: 0 | F10: 0 | G10: 0 | H10: 0 | I10: 0 | J10: 0 | K10: 0 | L10: 0 | M10: 0 | N10: 0 | O10: 0 | P10: 0 | Q10: 0 | R10: 0 | S10: 0 | T10: 402109.02 | U10: None Data | W10: 45292
B11: Month # 2 | C11: 45566 | D11: 0 | E11: 0 | F11: 0 | G11: 0 | H11: 0 | I11: 0 | J11: 0 | K11: 0 | L11: 0 | M11: 0 | N11: 0 | O11: 0 | P11: 0 | Q11: 0 | R11: 0 | S11: 0 | T11: 1261280.3 | U11: None Data
B12: Month # 3 | C12: 45597 | D12: 10142810 | E12: 0 | F12: 10142810 | G12: 0 | H12: 0 | I12: 0 | J12: 0 | K12: 0 | L12: 0 | M12: 0 | N12: 0 | O12: 0 | P12: 10142810 | Q12: 0 | R12: 0 | S12: 0 | T12: 0 | U12: None Data
B13: Month # 4 | C13: 45627 | D13: 0 | E13: 0 | F13: 0 | G13: 0 | H13: 0 | I13: 0 | J13: 0 | K13: 0 | L13: 0 | M13: 0 | N13: 0 | O13: 0 | P13: 10142810 | Q13: 0 | R13: 0 | S13: 0 | T13: 0 | U13: None Data
B14: Month # 5 | C14: 45658 | D14: 10142810 | E14: 0 | F14: 10142810 | G14: 0 | H14: 0 | I14: 0 | J14: 0 | K14: 0 | L14: 0 | M14: 0 | N14: 0 | O14: 0 | P14: 20285620 | Q14: 0 | R14: 0 | S14: 0 | T14: 0 | U14: None Data
B15: Month # 6 | C15: 45689 | D15: 11157091 | E15: 0 | F15: 11157091 | G15: 0 | H15: 0 | I15: 0 | J15: 0 | K15: 0 | L15: 0 | M15: 0 | N15: 0 | O15: 0 | P15: 31442711 | Q15: 0 | R15: 0 | S15: 0 | T15: 0 | U15: None Data
B16: Month # 7 | C16: 45717 | D16: 1014281 | E16: 0 | F16: 1014281 | G16: 0 | H16: 0 | I16: 0 | J16: 0 | K16: 0 | L16: 0 | M16: 0 | N16: 0 | O16: 0 | P16: 32456992 | Q16: 0 | R16: 0 | S16: 0 | T16: 0 | U16: None Data
B17: Month # 8 | C17: 45748 | D17: 4057124 | E17: 0 | F17: 4057124 | G17: 0 | H17: 0 | I17: 0 | J17: 0 | K17: 0 | L17: 0 | M17: 0 | N17: 0 | O17: 0 | P17: 36514116 | Q17: 0 | R17: 0 | S17: 0 | T17: 0 | U17: None Data
B18: Month # 9 | C18: 45778 | D18: 32710562 | E18: 0 | F18: 32710562 | G18: 0 | H18: 0 | I18: 0 | J18: 0 | K18: 0 | L18: 0 | M18: 0 | N18: 0 | O18: 0 | P18: 69224678 | Q18: 0 | R18: 0 | S18: 0 | T18: 0 | U18: None Data
B19: Month # 10 | C19: 45809 | D19: 8874958.8 | E19: 0 | F19: 8874958.8 | G19: 0 | H19: 0 | I19: 0 | J19: 0 | K19: 0 | L19: 0 | M19: 0 | N19: 0 | O19: 0 | P19: 78099637 | Q19: 0 | R19: 0 | S19: 0 | T19: 0 | U19: None Data
B20: Month # 11 | C20: 45839 | D20: 3042843 | E20: 0 | F20: 3042843 | G20: 0 | H20: 0 | I20: 0 | J20: 0 | K20: 0 | L20: 0 | M20: 0 | N20: 0 | O20: 0 | P20: 81142480 | Q20: 0 | R20: 0 | S20: 0 | T20: 0 | U20: None Data
B21: Month # 12 | C21: 45870 | D21: 0 | E21: 0 | F21: 0 | G21: 0 | H21: 0 | I21: 0 | J21: 0 | K21: 0 | L21: 0 | M21: 0 | N21: 0 | O21: 0 | P21: 81142480 | Q21: 0 | R21: 0 | S21: 0 | T21: 0 | U21: None Data
B22: Month # 13 | C22: 45901 | D22: 0 | E22: 0 | F22: 0 | G22: 0 | H22: 0 | I22: 0 | J22: 0 | K22: 0 | L22: 0 | M22: 0 | N22: 0 | O22: 0 | P22: 81142480 | Q22: 0 | R22: 0 | S22: 0 | T22: 0 | U22: None Data
... B25: Month # 16 | C25: 45992 | D25: 0 | E25: 0 | F25: 0 | G25: 0 | H25: 0 | I25: 0 | J25: 0 | K25: 0 | L25: 0 | M25: 0 | N25: 0 | O25: 0 | P25: 96356695 | Q25: 0 | R25: 0 | S25: 0 | T25: 0 | U25: None Data
B26: Month # 17 | C26: 46023 | D26: 5071405 | E26: 0 | F26: 5071405 | G26: 0 | H26: 0 | I26: 0 | J26: 0 | K26: 0 | L26: 0 | M26: 0 | N26: 0 | O26: 0 | P26: 101428100 | Q26: 0 | R26: 0 | S26: 0 | T26: 0
B27: Month # 18 | C27: 46054 | D27: 0 | E27: 0 | F27: 0 | G27: 0 | H27: 0 | I27: 0 | J27: 0 | K27: 0 | L27: 0 | M27: 0 | N27: 0 | O27: 0 | P27: 101428100 | Q27: 0 | R27: 0 | S27: 0 | T27: 0
B28: Month # 19 | C28: 46082 | D28: 0 | E28: 0 | F28: 0 | G28: 0 | H28: 0 | I28: 0 | J28: 0 | K28: 0 | L28: 0 | M28: 0 | N28: 0 | O28: 0 | P28: 101428100 | Q28: 0 | R28: 0 | S28: 0 | T28: 0
B29: Month # 20 | C29: 46113 | D29: 0 | E29: 0 | F29: 0 | G29: 0 | H29: 0 | I29: 0 | J29: 0 | K29: 0 | L29: 0 | M29: 0 | N29: 0 | O29: 0 | P29: 101428100 | Q29: 0 | R29: 0 | S29: 0 | T29: 0
B30: Month # 21 | C30: 46143 | D30: 0 | E30: 0 | F30: 0 | G30: 0 | H30: 0 | I30: 0 | J30: 0 | K30: 0 | L30: 0 | M30: 0 | N30: 0 | O30: 0 | P30: 101428100 | Q30: 0 | R30: 0 | S30: 0 | T30: 0
B31: Month # 22 | C31: 46174 | D31: 0 | E31: 0 | F31: 0 | G31: 0 | H31: 0 | I31: 0 | J31: 0 | K31: 0 | L31: 0 | M31: 0 | N31: 0 | O31: 0 | P31: 101428100 | Q31: 0 | R31: 0 | S31: 0 | T31: 0
B32: Month # 23 | C32: 46204 | D32: 0 | E32: 0 | F32: 0 | G32: 0 | H32: 0 | I32: 0 | J32: 0 | K32: 0 | L32: 0 | M32: 0 | N32: 0 | O32: 0 | P32: 101428100 | Q32: 0 | R32: 0 | S32: 0 | T32: 0
B33: Month # 24 | C33: 46235 | D33: 0 | E33: 0 | F33: 0 | G33: 0 | H33: 0 | I33: 0 | J33: 0 | K33: 0 | L33: 0 | M33: 0 | N33: 0 | O33: 0 | P33: 101428100 | Q33: 0 | R33: 0 | S33: 0 | T33: 0

Sheet Validate_Empty
B8: TRUE | C8: TRUE | D8: FALSE | E8: FALSE | F8: FALSE | G8: FALSE | H8: FALSE | I8: FALSE | J8: FALSE | K8: FALSE | L8: FALSE | M8: FALSE | N8: FALSE | O8: FALSE | P8: FALSE | Q8: FALSE | R8: FALSE | S8: FALSE | T8: FALSE | U8: FALSE
B9: C1 | C9: C2 | D9: C3 | E9: C4 | F9: C5 | G9: C6 | H9: C7 | I9: C8 | J9: C9 | K9: C10 | L9: C11 | M9: C12 | N9: C13 | O9: C14 | P9: C15 | Q9: C16 | R9: C17 | S9: C18 | T9: C19 | U9: C20
B10: {=IFERROR(IF(OR('Raw Data'!B10="",LEN(TRIM('Raw Data'!B10))=0),_xlfn.REGEXEXTRACT(CELL("address",'Raw Data'!B10),"\$([A-Z]+)\$[0-9]+"),""),"")} | C10: {=IFERROR(IF(OR('Raw Data'!C10="",LEN(TRIM('Raw Data'!C10))=0),_xlfn.REGEXEXTRACT(CELL("address",'Raw Data'!C10),"\$([A-Z]+)\$[0-9]+"),""),"")}
B11: {=IFERROR(IF(OR('Raw Data'!B11="",LEN(TRIM('Raw Data'!B11))=0),_xlfn.REGEXEXTRACT(CELL("address",'Raw Data'!B11),"\$([A-Z]+)\$[0-9]+"),""),"")} | C11: {=IFERROR(IF(OR('Raw Data'!C11="",LEN(TRIM('Raw Data'!C11))=0),_xlfn.REGEXEXTRACT(CELL("address",'Raw Data'!C11),"\$([A-Z]+)\$[0-9]+"),""),"")}
B12: {=IFERROR(IF(OR('Raw Data'!B12="",LEN(TRIM('Raw Data'!B12))=0),_xlfn.REGEXEXTRACT(CELL("address",'Raw Data'!B12),"\$([A-Z]+)\$[0-9]+"),""),"")} | C12: {=IFERROR(IF(OR('Raw Data'!C12="",LEN(TRIM('Raw Data'!C12))=0),_xlfn.REGEXEXTRACT(CELL("address",'Raw Data'!C12),"\$([A-Z]+)\$[0-9]+"),""),"")}
B13: {=IFERROR(IF(OR('Raw Data'!B13="",LEN(TRIM('Raw Data'!B13))=0),_xlfn.REGEXEXTRACT(CELL("address",'Raw Data'!B13),"\$([A-Z]+)\$[0-9]+"),""),"")} | C13: {=IFERROR(IF(OR('Raw Data'!C13="",LEN(TRIM('Raw Data'!C13))=0),_xlfn.REGEXEXTRACT(CELL("address",'Raw Data'!C13),"\$([A-Z]+)\$[0-9]+"),""),"")}
B14: {=IFERROR(IF(OR('Raw Data'!B14="",LEN(TRIM('Raw Data'!B14))=0),_xlfn.REGEXEXTRACT(CELL("address",'Raw Data'!B14),"\$([A-Z]+)\$[0-9]+"),""),"")} | C14: {=IFERROR(IF(OR('Raw Data'!C14="",LEN(TRIM('Raw Data'!C14))=0),_xlfn.REGEXEXTRACT(CELL("address",'Raw Data'!C14),"\$([A-Z]+)\$[0-9]+"),""),"")}
B15: {=IFERROR(IF(OR('Raw Data'!B15="",LEN(TRIM('Raw Data'!B15))=0),_xlfn.REGEXEXTRACT(CELL("address",'Raw Data'!B15),"\$([A-Z]+)\$[0-9]+"),""),"")} | C15: {=IFERROR(IF(OR('Raw Data'!C15="",LEN(TRIM('Raw Data'!C15))=0),_xlfn.REGEXEXTRACT(CELL("address",'Raw Data'!C15),"\$([A-Z]+)\$[0-9]+"),""),"")}
B16: {=IFERROR(IF(OR('Raw Data'!B16="",LEN(TRIM('Raw Data'!B16))=0),_xlfn.REGEXEXTRACT(CELL("address",'Raw Data'!B16),"\$([A-Z]+)\$[0-9]+"),""),"")} | C16: {=IFERROR(IF(OR('Raw Data'!C16="",LEN(TRIM('Raw Data'!C16))=0),_xlfn.REGEXEXTRACT(CELL("address",'Raw Data'!C16),"\$([A-Z]+)\$[0-9]+"),""),"")}
B17: {=IFERROR(IF(OR('Raw Data'!B17="",LEN(TRIM('Raw Data'!B17))=0),_xlfn.REGEXEXTRACT(CELL("address",'Raw Data'!B17),"\$([A-Z]+)\$[0-9]+"),""),"")} | C17: {=IFERROR(IF(OR('Raw Data'!C17="",LEN(TRIM('Raw Data'!C17))=0),_xlfn.REGEXEXTRACT(CELL("address",'Raw Data'!C17),"\$([A-Z]+)\$[0-9]+"),""),"")}
B18: {=IFERROR(IF(OR('Raw Data'!B18="",LEN(TRIM('Raw Data'!B18))=0),_xlfn.REGEXEXTRACT(CELL("address",'Raw Data'!B18),"\$([A-Z]+)\$[0-9]+"),""),"")} | C18: {=IFERROR(IF(OR('Raw Data'!C18="",LEN(TRIM('Raw Data'!C18))=0),_xlfn.REGEXEXTRACT(CELL("address",'Raw Data'!C18),"\$([A-Z]+)\$[0-9]+"),""),"")}
B19: {=IFERROR(IF(OR('Raw Data'!B19="",LEN(TRIM('Raw Data'!B19))=0),_xlfn.REGEXEXTRACT(CELL("address",'Raw Data'!B19),"\$([A-Z]+)\$[0-9]+"),""),"")} | C19: {=IFERROR(IF(OR('Raw Data'!C19="",LEN(TRIM('Raw Data'!C19))=0),_xlfn.REGEXEXTRACT(CELL("address",'Raw Data'!C19),"\$([A-Z]+)\$[0-9]+"),""),"")}
B20: {=IFERROR(IF(OR('Raw Data'!B20="",LEN(TRIM('Raw Data'!B20))=0),_xlfn.REGEXEXTRACT(CELL("address",'Raw Data'!B20),"\$([A-Z]+)\$[0-9]+"),""),"")} | C20: {=IFERROR(IF(OR('Raw Data'!C20="",LEN(TRIM('Raw Data'!C20))=0),_xlfn.REGEXEXTRACT(CELL("address",'Raw Data'!C20),"\$([A-Z]+)\$[0-9]+"),""),"")}
B21: {=IFERROR(IF(OR('Raw Data'!B21="",LEN(TRIM('Raw Data'!B21))=0),_xlfn.REGEXEXTRACT(CELL("address",'Raw Data'!B21),"\$([A-Z]+)\$[0-9]+"),""),"")} | C21: {=IFERROR(IF(OR('Raw Data'!C21="",LEN(TRIM('Raw Data'!C21))=0),_xlfn.REGEXEXTRACT(CELL("address",'Raw Data'!C21),"\$([A-Z]+)\$[0-9]+"),""),"")}
... B295: {=IFERROR(IF(OR('Raw Data'!B295="",LEN(TRIM('Raw Data'!B295))=0),_xlfn.REGEXEXTRACT(CELL("address",'Raw Data'!B295),"\$([A-Z]+)\$[0-9]+"),""),"")} -> $B$295 | C295: {=IFERROR(IF(OR('Raw Data'!C295="",LEN(TRIM('Raw Data'!C295))=0),_xlfn.REGEXEXTRACT(CELL("address",'Raw Data'!C295),"\$([A-Z]+)\$[0-9]+"),""),"")} -> $C$295

Sheet Validate_Value
B8: NVARCHAR(20) | C8: DATE | D8: DECIMAL(13,2) | E8: DECIMAL(13,2) | F8: DECIMAL(13,2) | G8: DECIMAL(13,2) | H8: DECIMAL(13,2) | I8: DECIMAL(13,2) | J8: DECIMAL(13,2) | K8: DECIMAL(13,2) | L8: DECIMAL(13,2) | M8: DECIMAL(13,2) | N8: DECIMAL(13,2) | O8: DECIMAL(13,2) | P8: DECIMAL(13,2) | Q8: DECIMAL(13,2) | R8: DECIMAL(13,2) | S8: DECIMAL(13,2) | T8: DECIMAL(13,2) | U8: NVARCHAR(255)
B9: C1 | C9: C2 | D9: C3 | E9: C4 | F9: C5 | G9: C6 | H9: C7 | I9: C8 | J9: C9 | K9: C10 | L9: C11 | M9: C12 | N9: C13 | O9: C14 | P9: C15 | Q9: C16 | R9: C17 | S9: C18 | T9: C19 | U9: C20
B10: {=IFERROR(IF(OR('Raw Data'!B10="",LEN(TRIM('Raw Data'!B10))=0),"",IF(AND(LEN('Raw Data'!B10) <= 20,LEN('Raw Data'!B10)> 0),"",_xlfn.REGEXEXTRACT(CELL("address",'Raw Data'!B10),"\$([A-Z]+)\$[0-9]+"))),_xlfn.REGEXEXTRACT(CELL("address",'Raw Data'!B10),"\$([A-Z]+)\$[0-9]+"))} | C10: {=IFERROR(IF(OR('Raw Data'!C10="",LEN(TRIM('Raw Data'!C10))=0),"",IF(AND(ISNUMBER('Raw Data'!C10),'Raw Data'!C10>=Configuration!$D$2),"",_xlfn.REGEXEXTRACT(CELL("address",'Raw Data'!C10),"\$([A-Z]+)\$[0-9]+"))),_xlfn.REGEXEXTRACT(CELL("address",C10), "\$([A-Z]+)\$[0-9]+"))} | D10: {=IFERROR(IF(OR('Raw Data'!D10="",LEN(TRIM('Raw Data'!D10))=0),"",IF(AND(ISNUMBER('Raw Data'!D10), IFERROR('Raw Data'!D10 = ROUND('Raw Data'!D10, 2),FALSE)),"",_xlfn.REGEXEXTRACT(CELL("address",D10), "\$([A-Z]+)\$[0-9]+"))),_xlfn.REGEXEXTRACT(CELL("address",D10), "\$([A-Z]+)\$[0-9]+"))} | E10: {=IFERROR(IF(OR('Raw Data'!E10="",LEN(TRIM('Raw Data'!E10))=0),"",IF(AND(ISNUMBER('Raw Data'!E10), IFERROR('Raw Data'!E10 = ROUND('Raw Data'!E10, 2),FALSE)),"",_xlfn.REGEXEXTRACT(CELL("address",E10), "\$([A-Z]+)\$[0-9]+"))),_xlfn.REGEXEXTRACT(CELL("address",E10), "\$([A-Z]+)\$[0-9]+"))} | F10: {=IFERROR(IF(OR('Raw Data'!F10="",LEN(TRIM('Raw Data'!F10))=0),"",IF(AND(ISNUMBER('Raw Data'!F10), IFERROR('Raw Data'!F10 = ROUND('Raw Data'!F10, 2),FALSE)),"",_xlfn.REGEXEXTRACT(CELL("address",F10), "\$([A-Z]+)\$[0-9]+"))),_xlfn.REGEXEXTRACT(CELL("address",F10), "\$([A-Z]+)\$[0-9]+"))} | G10: {=IFERROR(IF(OR('Raw Data'!G10="",LEN(TRIM('Raw Data'!G10))=0),"",IF(AND(ISNUMBER('Raw Data'!G10), IFERROR('Raw Data'!G10 = ROUND('Raw Data'!G10, 2),FALSE)),"",_xlfn.REGEXEXTRACT(CELL("address",G10), "\$([A-Z]+)\$[0-9]+"))),_xlfn.REGEXEXTRACT(CELL("address",G10), "\$([A-Z]+)\$[0-9]+"))} | H10: {=IFERROR(IF(OR('Raw Data'!H10="",LEN(TRIM('Raw Data'!H10))=0),"",IF(AND(ISNUMBER('Raw Data'!H10), IFERROR('Raw Data'!H10 = ROUND('Raw Data'!H10, 2),FALSE)),"",_xlfn.REGEXEXTRACT(CELL("address",H10), "\$([A-Z]+)\$[0-9]+"))),_xlfn.REGEXEXTRACT(CELL("address",H10), "\$([A-Z]+)\$[0-9]+"))} | I10: {=IFERROR(IF(OR('Raw Data'!I10="",LEN(TRIM('Raw Data'!I10))=0),"",IF(AND(ISNUMBER('Raw Data'!I10), IFERROR('Raw Data'!I10 = ROUND('Raw Data'!I10, 2),FALSE)),"",_xlfn.REGEXEXTRACT(CELL("address",I10), "\$([A-Z]+)\$[0-9]+"))),_xlfn.REGEXEXTRACT(CELL("address",I10), "\$([A-Z]+)\$[0-9]+"))} | J10: {=IFERROR(IF(OR('Raw Data'!J10="",LEN(TRIM('Raw Data'!J10))=0),"",IF(AND(ISNUMBER('Raw Data'!J10), IFERROR('Raw Data'!J10 = ROUND('Raw Data'!J10, 2),FALSE)),"",_xlfn.REGEXEXTRACT(CELL("address",J10), "\$([A-Z]+)\$[0-9]+"))),_xlfn.REGEXEXTRACT(CELL("address",J10), "\$([A-Z]+)\$[0-9]+"))} | K10: {=IFERROR(IF(OR('Raw Data'!K10="",LEN(TRIM('Raw Data'!K10))=0),"",IF(AND(ISNUMBER('Raw Data'!K10), IFERROR('Raw Data'!K10 = ROUND('Raw Data'!K10, 2),FALSE)),"",_xlfn.REGEXEXTRACT(CELL("address",K10), "\$([A-Z]+)\$[0-9]+"))),_xlfn.REGEXEXTRACT(CELL("address",K10), "\$([A-Z]+)\$[0-9]+"))} | ... T10: {=IFERROR(IF(OR('Raw Data'!T10="",LEN(TRIM('Raw Data'!T10))=0),"",IF(AND(ISNUMBER('Raw Data'!T10), IFERROR('Raw Data'!T10 = ROUND('Raw Data'!T10, 2),FALSE)),"",_xlfn.REGEXEXTRACT(CELL("address",T10), "\$([A-Z]+)\$[0-9]+"))),_xlfn.REGEXEXTRACT(CELL("address",T10), "\$([A-Z]+)\$[0-9]+"))} | U10: {=IFERROR(IF(OR('Raw Data'!U10="",LEN(TRIM('Raw Data'!U10))=0),"",IF(AND(LEN('Raw Data'!B10) <= 255,LEN('Raw Data'!U10)> 0),"",_xlfn.REGEXEXTRACT(CELL("address",'Raw Data'!U10),"\$([A-Z]+)\$[0-9]+"))),_xlfn.REGEXEXTRACT(CELL("address",'Raw Data'!U10),"\$([A-Z]+)\$[0-9]+"))}
B11: {=IFERROR(IF(OR('Raw Data'!B11="",LEN(TRIM('Raw Data'!B11))=0),"",IF(AND(LEN('Raw Data'!B11) <= 20,LEN('Raw Data'!B11)> 0),"",_xlfn.REGEXEXTRACT(CELL("address",'Raw Data'!B11),"\$([A-Z]+)\$[0-9]+"))),_xlfn.REGEXEXTRACT(CELL("address",'Raw Data'!B11),"\$([A-Z]+)\$[0-9]+"))} | C11: {=IFERROR(IF(OR('Raw Data'!C11="",LEN(TRIM('Raw Data'!C11))=0),"",IF(AND(ISNUMBER('Raw Data'!C11),'Raw Data'!C11>=Configuration!$D$2),"",_xlfn.REGEXEXTRACT(CELL("address",'Raw Data'!C11),"\$([A-Z]+)\$[0-9]+"))),_xlfn.REGEXEXTRACT(CELL("address",C11), "\$([A-Z]+)\$[0-9]+"))} | D11: {=IFERROR(IF(OR('Raw Data'!D11="",LEN(TRIM('Raw Data'!D11))=0),"",IF(AND(ISNUMBER('Raw Data'!D11), IFERROR('Raw Data'!D11 = ROUND('Raw Data'!D11, 2),FALSE)),"",_xlfn.REGEXEXTRACT(CELL("address",D11), "\$([A-Z]+)\$[0-9]+"))),_xlfn.REGEXEXTRACT(CELL("address",D11), "\$([A-Z]+)\$[0-9]+"))} | E11: {=IFERROR(IF(OR('Raw Data'!E11="",LEN(TRIM('Raw Data'!E11))=0),"",IF(AND(ISNUMBER('Raw Data'!E11), IFERROR('Raw Data'!E11 = ROUND('Raw Data'!E11, 2),FALSE)),"",_xlfn.REGEXEXTRACT(CELL("address",E11), "\$([A-Z]+)\$[0-9]+"))),_xlfn.REGEXEXTRACT(CELL("address",E11), "\$([A-Z]+)\$[0-9]+"))} | F11: {=IFERROR(IF(OR('Raw Data'!F11="",LEN(TRIM('Raw Data'!F11))=0),"",IF(AND(ISNUMBER('Raw Data'!F11), IFERROR('Raw Data'!F11 = ROUND('Raw Data'!F11, 2),FALSE)),"",_xlfn.REGEXEXTRACT(CELL("address",F11), "\$([A-Z]+)\$[0-9]+"))),_xlfn.REGEXEXTRACT(CELL("address",F11), "\$([A-Z]+)\$[0-9]+"))} | G11: {=IFERROR(IF(OR('Raw Data'!G11="",LEN(TRIM('Raw Data'!G11))=0),"",IF(AND(ISNUMBER('Raw Data'!G11), IFERROR('Raw Data'!G11 = ROUND('Raw Data'!G11, 2),FALSE)),"",_xlfn.REGEXEXTRACT(CELL("address",G11), "\$([A-Z]+)\$[0-9]+"))),_xlfn.REGEXEXTRACT(CELL("address",G11), "\$([A-Z]+)\$[0-9]+"))} | H11: {=IFERROR(IF(OR('Raw Data'!H11="",LEN(TRIM('Raw Data'!H11))=0),"",IF(AND(ISNUMBER('Raw Data'!H11), IFERROR('Raw Data'!H11 = ROUND('Raw Data'!H11, 2),FALSE)),"",_xlfn.REGEXEXTRACT(CELL("address",H11), "\$([A-Z]+)\$[0-9]+"))),_xlfn.REGEXEXTRACT(CELL("address",H11), "\$([A-Z]+)\$[0-9]+"))} | I11: {=IFERROR(IF(OR('Raw Data'!I11="",LEN(TRIM('Raw Data'!I11))=0),"",IF(AND(ISNUMBER('Raw Data'!I11), IFERROR('Raw Data'!I11 = ROUND('Raw Data'!I11, 2),FALSE)),"",_xlfn.REGEXEXTRACT(CELL("address",I11), "\$([A-Z]+)\$[0-9]+"))),_xlfn.REGEXEXTRACT(CELL("address",I11), "\$([A-Z]+)\$[0-9]+"))} | J11: {=IFERROR(IF(OR('Raw Data'!J11="",LEN(TRIM('Raw Data'!J11))=0),"",IF(AND(ISNUMBER('Raw Data'!J11), IFERROR('Raw Data'!J11 = ROUND('Raw Data'!J11, 2),FALSE)),"",_xlfn.REGEXEXTRACT(CELL("address",J11), "\$([A-Z]+)\$[0-9]+"))),_xlfn.REGEXEXTRACT(CELL("address",J11), "\$([A-Z]+)\$[0-9]+"))} | K11: {=IFERROR(IF(OR('Raw Data'!K11="",LEN(TRIM('Raw Data'!K11))=0),"",IF(AND(ISNUMBER('Raw Data'!K11), IFERROR('Raw Data'!K11 = ROUND('Raw Data'!K11, 2),FALSE)),"",_xlfn.REGEXEXTRACT(CELL("address",K11), "\$([A-Z]+)\$[0-9]+"))),_xlfn.REGEXEXTRACT(CELL("address",K11), "\$([A-Z]+)\$[0-9]+"))} | ... T11: {=IFERROR(IF(OR('Raw Data'!T11="",LEN(TRIM('Raw Data'!T11))=0),"",IF(AND(ISNUMBER('Raw Data'!T11), IFERROR('Raw Data'!T11 = ROUND('Raw Data'!T11, 2),FALSE)),"",_xlfn.REGEXEXTRACT(CELL("address",T11), "\$([A-Z]+)\$[0-9]+"))),_xlfn.REGEXEXTRACT(CELL("address",T11), "\$([A-Z]+)\$[0-9]+"))} | U11: {=IFERROR(IF(OR('Raw Data'!U11="",LEN(TRIM('Raw Data'!U11))=0),"",IF(AND(LEN('Raw Data'!B11) <= 255,LEN('Raw Data'!U11)> 0),"",_xlfn.REGEXEXTRACT(CELL("address",'Raw Data'!U11),"\$([A-Z]+)\$[0-9]+"))),_xlfn.REGEXEXTRACT(CELL("address",'Raw Data'!U11),"\$([A-Z]+)\$[0-9]+"))}
B12: {=IFERROR(IF(OR('Raw Data'!B12="",LEN(TRIM('Raw Data'!B12))=0),"",IF(AND(LEN('Raw Data'!B12) <= 20,LEN('Raw Data'!B12)> 0),"",_xlfn.REGEXEXTRACT(CELL("address",'Raw Data'!B12),"\$([A-Z]+)\$[0-9]+"))),_xlfn.REGEXEXTRACT(CELL("address",'Raw Data'!B12),"\$([A-Z]+)\$[0-9]+"))} | C12: {=IFERROR(IF(OR('Raw Data'!C12="",LEN(TRIM('Raw Data'!C12))=0),"",IF(AND(ISNUMBER('Raw Data'!C12),'Raw Data'!C12>=Configuration!$D$2),"",_xlfn.REGEXEXTRACT(CELL("address",'Raw Data'!C12),"\$([A-Z]+)\$[0-9]+"))),_xlfn.REGEXEXTRACT(CELL("address",C12), "\$([A-Z]+)\$[0-9]+"))} | D12: {=IFERROR(IF(OR('Raw Data'!D12="",LEN(TRIM('Raw Data'!D12))=0),"",IF(AND(ISNUMBER('Raw Data'!D12), IFERROR('Raw Data'!D12 = ROUND('Raw Data'!D12, 2),FALSE)),"",_xlfn.REGEXEXTRACT(CELL("address",D12), "\$([A-Z]+)\$[0-9]+"))),_xlfn.REGEXEXTRACT(CELL("address",D12), "\$([A-Z]+)\$[0-9]+"))} | E12: {=IFERROR(IF(OR('Raw Data'!E12="",LEN(TRIM('Raw Data'!E12))=0),"",IF(AND(ISNUMBER('Raw Data'!E12), IFERROR('Raw Data'!E12 = ROUND('Raw Data'!E12, 2),FALSE)),"",_xlfn.REGEXEXTRACT(CELL("address",E12), "\$([A-Z]+)\$[0-9]+"))),_xlfn.REGEXEXTRACT(CELL("address",E12), "\$([A-Z]+)\$[0-9]+"))} | F12: {=IFERROR(IF(OR('Raw Data'!F12="",LEN(TRIM('Raw Data'!F12))=0),"",IF(AND(ISNUMBER('Raw Data'!F12), IFERROR('Raw Data'!F12 = ROUND('Raw Data'!F12, 2),FALSE)),"",_xlfn.REGEXEXTRACT(CELL("address",F12), "\$([A-Z]+)\$[0-9]+"))),_xlfn.REGEXEXTRACT(CELL("address",F12), "\$([A-Z]+)\$[0-9]+"))} | G12: {=IFERROR(IF(OR('Raw Data'!G12="",LEN(TRIM('Raw Data'!G12))=0),"",IF(AND(ISNUMBER('Raw Data'!G12), IFERROR('Raw Data'!G12 = ROUND('Raw Data'!G12, 2),FALSE)),"",_xlfn.REGEXEXTRACT(CELL("address",G12), "\$([A-Z]+)\$[0-9]+"))),_xlfn.REGEXEXTRACT(CELL("address",G12), "\$([A-Z]+)\$[0-9]+"))} | H12: {=IFERROR(IF(OR('Raw Data'!H12="",LEN(TRIM('Raw Data'!H12))=0),"",IF(AND(ISNUMBER('Raw Data'!H12), IFERROR('Raw Data'!H12 = ROUND('Raw Data'!H12, 2),FALSE)),"",_xlfn.REGEXEXTRACT(CELL("address",H12), "\$([A-Z]+)\$[0-9]+"))),_xlfn.REGEXEXTRACT(CELL("address",H12), "\$([A-Z]+)\$[0-9]+"))} | I12: {=IFERROR(IF(OR('Raw Data'!I12="",LEN(TRIM('Raw Data'!I12))=0),"",IF(AND(ISNUMBER('Raw Data'!I12), IFERROR('Raw Data'!I12 = ROUND('Raw Data'!I12, 2),FALSE)),"",_xlfn.REGEXEXTRACT(CELL("address",I12), "\$([A-Z]+)\$[0-9]+"))),_xlfn.REGEXEXTRACT(CELL("address",I12), "\$([A-Z]+)\$[0-9]+"))} | J12: {=IFERROR(IF(OR('Raw Data'!J12="",LEN(TRIM('Raw Data'!J12))=0),"",IF(AND(ISNUMBER('Raw Data'!J12), IFERROR('Raw Data'!J12 = ROUND('Raw Data'!J12, 2),FALSE)),"",_xlfn.REGEXEXTRACT(CELL("address",J12), "\$([A-Z]+)\$[0-9]+"))),_xlfn.REGEXEXTRACT(CELL("address",J12), "\$([A-Z]+)\$[0-9]+"))} | K12: {=IFERROR(IF(OR('Raw Data'!K12="",LEN(TRIM('Raw Data'!K12))=0),"",IF(AND(ISNUMBER('Raw Data'!K12), IFERROR('Raw Data'!K12 = ROUND('Raw Data'!K12, 2),FALSE)),"",_xlfn.REGEXEXTRACT(CELL("address",K12), "\$([A-Z]+)\$[0-9]+"))),_xlfn.REGEXEXTRACT(CELL("address",K12), "\$([A-Z]+)\$[0-9]+"))} | ... T12: {=IFERROR(IF(OR('Raw Data'!T12="",LEN(TRIM('Raw Data'!T12))=0),"",IF(AND(ISNUMBER('Raw Data'!T12), IFERROR('Raw Data'!T12 = ROUND('Raw Data'!T12, 2),FALSE)),"",_xlfn.REGEXEXTRACT(CELL("address",T12), "\$([A-Z]+)\$[0-9]+"))),_xlfn.REGEXEXTRACT(CELL("address",T12), "\$([A-Z]+)\$[0-9]+"))} | U12: {=IFERROR(IF(OR('Raw Data'!U12="",LEN(TRIM('Raw Data'!U12))=0),"",IF(AND(LEN('Raw Data'!B12) <= 255,LEN('Raw Data'!U12)> 0),"",_xlfn.REGEXEXTRACT(CELL("address",'Raw Data'!U12),"\$([A-Z]+)\$[0-9]+"))),_xlfn.REGEXEXTRACT(CELL("address",'Raw Data'!U12),"\$([A-Z]+)\$[0-9]+"))}
B13: {=IFERROR(IF(OR('Raw Data'!B13="",LEN(TRIM('Raw Data'!B13))=0),"",IF(AND(LEN('Raw Data'!B13) <= 20,LEN('Raw Data'!B13)> 0),"",_xlfn.REGEXEXTRACT(CELL("address",'Raw Data'!B13),"\$([A-Z]+)\$[0-9]+"))),_xlfn.REGEXEXTRACT(CELL("address",'Raw Data'!B13),"\$([A-Z]+)\$[0-9]+"))} | C13: {=IFERROR(IF(OR('Raw Data'!C13="",LEN(TRIM('Raw Data'!C13))=0),"",IF(AND(ISNUMBER('Raw Data'!C13),'Raw Data'!C13>=Configuration!$D$2),"",_xlfn.REGEXEXTRACT(CELL("address",'Raw Data'!C13),"\$([A-Z]+)\$[0-9]+"))),_xlfn.REGEXEXTRACT(CELL("address",C13), "\$([A-Z]+)\$[0-9]+"))} | D13: {=IFERROR(IF(OR('Raw Data'!D13="",LEN(TRIM('Raw Data'!D13))=0),"",IF(AND(ISNUMBER('Raw Data'!D13), IFERROR('Raw Data'!D13 = ROUND('Raw Data'!D13, 2),FALSE)),"",_xlfn.REGEXEXTRACT(CELL("address",D13), "\$([A-Z]+)\$[0-9]+"))),_xlfn.REGEXEXTRACT(CELL("address",D13), "\$([A-Z]+)\$[0-9]+"))} | E13: {=IFERROR(IF(OR('Raw Data'!E13="",LEN(TRIM('Raw Data'!E13))=0),"",IF(AND(ISNUMBER('Raw Data'!E13), IFERROR('Raw Data'!E13 = ROUND('Raw Data'!E13, 2),FALSE)),"",_xlfn.REGEXEXTRACT(CELL("address",E13), "\$([A-Z]+)\$[0-9]+"))),_xlfn.REGEXEXTRACT(CELL("address",E13), "\$([A-Z]+)\$[0-9]+"))} | F13: {=IFERROR(IF(OR('Raw Data'!F13="",LEN(TRIM('Raw Data'!F13))=0),"",IF(AND(ISNUMBER('Raw Data'!F13), IFERROR('Raw Data'!F13 = ROUND('Raw Data'!F13, 2),FALSE)),"",_xlfn.REGEXEXTRACT(CELL("address",F13), "\$([A-Z]+)\$[0-9]+"))),_xlfn.REGEXEXTRACT(CELL("address",F13), "\$([A-Z]+)\$[0-9]+"))} | G13: {=IFERROR(IF(OR('Raw Data'!G13="",LEN(TRIM('Raw Data'!G13))=0),"",IF(AND(ISNUMBER('Raw Data'!G13), IFERROR('Raw Data'!G13 = ROUND('Raw Data'!G13, 2),FALSE)),"",_xlfn.REGEXEXTRACT(CELL("address",G13), "\$([A-Z]+)\$[0-9]+"))),_xlfn.REGEXEXTRACT(CELL("address",G13), "\$([A-Z]+)\$[0-9]+"))} | H13: {=IFERROR(IF(OR('Raw Data'!H13="",LEN(TRIM('Raw Data'!H13))=0),"",IF(AND(ISNUMBER('Raw Data'!H13), IFERROR('Raw Data'!H13 = ROUND('Raw Data'!H13, 2),FALSE)),"",_xlfn.REGEXEXTRACT(CELL("address",H13), "\$([A-Z]+)\$[0-9]+"))),_xlfn.REGEXEXTRACT(CELL("address",H13), "\$([A-Z]+)\$[0-9]+"))} | I13: {=IFERROR(IF(OR('Raw Data'!I13="",LEN(TRIM('Raw Data'!I13))=0),"",IF(AND(ISNUMBER('Raw Data'!I13), IFERROR('Raw Data'!I13 = ROUND('Raw Data'!I13, 2),FALSE)),"",_xlfn.REGEXEXTRACT(CELL("address",I13), "\$([A-Z]+)\$[0-9]+"))),_xlfn.REGEXEXTRACT(CELL("address",I13), "\$([A-Z]+)\$[0-9]+"))} | J13: {=IFERROR(IF(OR('Raw Data'!J13="",LEN(TRIM('Raw Data'!J13))=0),"",IF(AND(ISNUMBER('Raw Data'!J13), IFERROR('Raw Data'!J13 = ROUND('Raw Data'!J13, 2),FALSE)),"",_xlfn.REGEXEXTRACT(CELL("address",J13), "\$([A-Z]+)\$[0-9]+"))),_xlfn.REGEXEXTRACT(CELL("address",J13), "\$([A-Z]+)\$[0-9]+"))} | K13: {=IFERROR(IF(OR('Raw Data'!K13="",LEN(TRIM('Raw Data'!K13))=0),"",IF(AND(ISNUMBER('Raw Data'!K13), IFERROR('Raw Data'!K13 = ROUND('Raw Data'!K13, 2),FALSE)),"",_xlfn.REGEXEXTRACT(CELL("address",K13), "\$([A-Z]+)\$[0-9]+"))),_xlfn.REGEXEXTRACT(CELL("address",K13), "\$([A-Z]+)\$[0-9]+"))} | ... T13: {=IFERROR(IF(OR('Raw Data'!T13="",LEN(TRIM('Raw Data'!T13))=0),"",IF(AND(ISNUMBER('Raw Data'!T13), IFERROR('Raw Data'!T13 = ROUND('Raw Data'!T13, 2),FALSE)),"",_xlfn.REGEXEXTRACT(CELL("address",T13), "\$([A-Z]+)\$[0-9]+"))),_xlfn.REGEXEXTRACT(CELL("address",T13), "\$([A-Z]+)\$[0-9]+"))} | U13: {=IFERROR(IF(OR('Raw Data'!U13="",LEN(TRIM('Raw Data'!U13))=0),"",IF(AND(LEN('Raw Data'!B13) <= 255,LEN('Raw Data'!U13)> 0),"",_xlfn.REGEXEXTRACT(CELL("address",'Raw Data'!U13),"\$([A-Z]+)\$[0-9]+"))),_xlfn.REGEXEXTRACT(CELL("address",'Raw Data'!U13),"\$([A-Z]+)\$[0-9]+"))}
B14: {=IFERROR(IF(OR('Raw Data'!B14="",LEN(TRIM('Raw Data'!B14))=0),"",IF(AND(LEN('Raw Data'!B14) <= 20,LEN('Raw Data'!B14)> 0),"",_xlfn.REGEXEXTRACT(CELL("address",'Raw Data'!B14),"\$([A-Z]+)\$[0-9]+"))),_xlfn.REGEXEXTRACT(CELL("address",'Raw Data'!B14),"\$([A-Z]+)\$[0-9]+"))} | C14: {=IFERROR(IF(OR('Raw Data'!C14="",LEN(TRIM('Raw Data'!C14))=0),"",IF(AND(ISNUMBER('Raw Data'!C14),'Raw Data'!C14>=Configuration!$D$2),"",_xlfn.REGEXEXTRACT(CELL("address",'Raw Data'!C14),"\$([A-Z]+)\$[0-9]+"))),_xlfn.REGEXEXTRACT(CELL("address",C14), "\$([A-Z]+)\$[0-9]+"))} | D14: {=IFERROR(IF(OR('Raw Data'!D14="",LEN(TRIM('Raw Data'!D14))=0),"",IF(AND(ISNUMBER('Raw Data'!D14), IFERROR('Raw Data'!D14 = ROUND('Raw Data'!D14, 2),FALSE)),"",_xlfn.REGEXEXTRACT(CELL("address",D14), "\$([A-Z]+)\$[0-9]+"))),_xlfn.REGEXEXTRACT(CELL("address",D14), "\$([A-Z]+)\$[0-9]+"))} | E14: {=IFERROR(IF(OR('Raw Data'!E14="",LEN(TRIM('Raw Data'!E14))=0),"",IF(AND(ISNUMBER('Raw Data'!E14), IFERROR('Raw Data'!E14 = ROUND('Raw Data'!E14, 2),FALSE)),"",_xlfn.REGEXEXTRACT(CELL("address",E14), "\$([A-Z]+)\$[0-9]+"))),_xlfn.REGEXEXTRACT(CELL("address",E14), "\$([A-Z]+)\$[0-9]+"))} | F14: {=IFERROR(IF(OR('Raw Data'!F14="",LEN(TRIM('Raw Data'!F14))=0),"",IF(AND(ISNUMBER('Raw Data'!F14), IFERROR('Raw Data'!F14 = ROUND('Raw Data'!F14, 2),FALSE)),"",_xlfn.REGEXEXTRACT(CELL("address",F14), "\$([A-Z]+)\$[0-9]+"))),_xlfn.REGEXEXTRACT(CELL("address",F14), "\$([A-Z]+)\$[0-9]+"))} | G14: {=IFERROR(IF(OR('Raw Data'!G14="",LEN(TRIM('Raw Data'!G14))=0),"",IF(AND(ISNUMBER('Raw Data'!G14), IFERROR('Raw Data'!G14 = ROUND('Raw Data'!G14, 2),FALSE)),"",_xlfn.REGEXEXTRACT(CELL("address",G14), "\$([A-Z]+)\$[0-9]+"))),_xlfn.REGEXEXTRACT(CELL("address",G14), "\$([A-Z]+)\$[0-9]+"))} | H14: {=IFERROR(IF(OR('Raw Data'!H14="",LEN(TRIM('Raw Data'!H14))=0),"",IF(AND(ISNUMBER('Raw Data'!H14), IFERROR('Raw Data'!H14 = ROUND('Raw Data'!H14, 2),FALSE)),"",_xlfn.REGEXEXTRACT(CELL("address",H14), "\$([A-Z]+)\$[0-9]+"))),_xlfn.REGEXEXTRACT(CELL("address",H14), "\$([A-Z]+)\$[0-9]+"))} | I14: {=IFERROR(IF(OR('Raw Data'!I14="",LEN(TRIM('Raw Data'!I14))=0),"",IF(AND(ISNUMBER('Raw Data'!I14), IFERROR('Raw Data'!I14 = ROUND('Raw Data'!I14, 2),FALSE)),"",_xlfn.REGEXEXTRACT(CELL("address",I14), "\$([A-Z]+)\$[0-9]+"))),_xlfn.REGEXEXTRACT(CELL("address",I14), "\$([A-Z]+)\$[0-9]+"))} | J14: {=IFERROR(IF(OR('Raw Data'!J14="",LEN(TRIM('Raw Data'!J14))=0),"",IF(AND(ISNUMBER('Raw Data'!J14), IFERROR('Raw Data'!J14 = ROUND('Raw Data'!J14, 2),FALSE)),"",_xlfn.REGEXEXTRACT(CELL("address",J14), "\$([A-Z]+)\$[0-9]+"))),_xlfn.REGEXEXTRACT(CELL("address",J14), "\$([A-Z]+)\$[0-9]+"))} | K14: {=IFERROR(IF(OR('Raw Data'!K14="",LEN(TRIM('Raw Data'!K14))=0),"",IF(AND(ISNUMBER('Raw Data'!K14), IFERROR('Raw Data'!K14 = ROUND('Raw Data'!K14, 2),FALSE)),"",_xlfn.REGEXEXTRACT(CELL("address",K14), "\$([A-Z]+)\$[0-9]+"))),_xlfn.REGEXEXTRACT(CELL("address",K14), "\$([A-Z]+)\$[0-9]+"))} | ... T14: {=IFERROR(IF(OR('Raw Data'!T14="",LEN(TRIM('Raw Data'!T14))=0),"",IF(AND(ISNUMBER('Raw Data'!T14), IFERROR('Raw Data'!T14 = ROUND('Raw Data'!T14, 2),FALSE)),"",_xlfn.REGEXEXTRACT(CELL("address",T14), "\$([A-Z]+)\$[0-9]+"))),_xlfn.REGEXEXTRACT(CELL("address",T14), "\$([A-Z]+)\$[0-9]+"))} | U14: {=IFERROR(IF(OR('Raw Data'!U14="",LEN(TRIM('Raw Data'!U14))=0),"",IF(AND(LEN('Raw Data'!B14) <= 255,LEN('Raw Data'!U14)> 0),"",_xlfn.REGEXEXTRACT(CELL("address",'Raw Data'!U14),"\$([A-Z]+)\$[0-9]+"))),_xlfn.REGEXEXTRACT(CELL("address",'Raw Data'!U14),"\$([A-Z]+)\$[0-9]+"))}
B15: {=IFERROR(IF(OR('Raw Data'!B15="",LEN(TRIM('Raw Data'!B15))=0),"",IF(AND(LEN('Raw Data'!B15) <= 20,LEN('Raw Data'!B15)> 0),"",_xlfn.REGEXEXTRACT(CELL("address",'Raw Data'!B15),"\$([A-Z]+)\$[0-9]+"))),_xlfn.REGEXEXTRACT(CELL("address",'Raw Data'!B15),"\$([A-Z]+)\$[0-9]+"))} | C15: {=IFERROR(IF(OR('Raw Data'!C15="",LEN(TRIM('Raw Data'!C15))=0),"",IF(AND(ISNUMBER('Raw Data'!C15),'Raw Data'!C15>=Configuration!$D$2),"",_xlfn.REGEXEXTRACT(CELL("address",'Raw Data'!C15),"\$([A-Z]+)\$[0-9]+"))),_xlfn.REGEXEXTRACT(CELL("address",C15), "\$([A-Z]+)\$[0-9]+"))} | D15: {=IFERROR(IF(OR('Raw Data'!D15="",LEN(TRIM('Raw Data'!D15))=0),"",IF(AND(ISNUMBER('Raw Data'!D15), IFERROR('Raw Data'!D15 = ROUND('Raw Data'!D15, 2),FALSE)),"",_xlfn.REGEXEXTRACT(CELL("address",D15), "\$([A-Z]+)\$[0-9]+"))),_xlfn.REGEXEXTRACT(CELL("address",D15), "\$([A-Z]+)\$[0-9]+"))} | E15: {=IFERROR(IF(OR('Raw Data'!E15="",LEN(TRIM('Raw Data'!E15))=0),"",IF(AND(ISNUMBER('Raw Data'!E15), IFERROR('Raw Data'!E15 = ROUND('Raw Data'!E15, 2),FALSE)),"",_xlfn.REGEXEXTRACT(CELL("address",E15), "\$([A-Z]+)\$[0-9]+"))),_xlfn.REGEXEXTRACT(CELL("address",E15), "\$([A-Z]+)\$[0-9]+"))} | F15: {=IFERROR(IF(OR('Raw Data'!F15="",LEN(TRIM('Raw Data'!F15))=0),"",IF(AND(ISNUMBER('Raw Data'!F15), IFERROR('Raw Data'!F15 = ROUND('Raw Data'!F15, 2),FALSE)),"",_xlfn.REGEXEXTRACT(CELL("address",F15), "\$([A-Z]+)\$[0-9]+"))),_xlfn.REGEXEXTRACT(CELL("address",F15), "\$([A-Z]+)\$[0-9]+"))} | G15: {=IFERROR(IF(OR('Raw Data'!G15="",LEN(TRIM('Raw Data'!G15))=0),"",IF(AND(ISNUMBER('Raw Data'!G15), IFERROR('Raw Data'!G15 = ROUND('Raw Data'!G15, 2),FALSE)),"",_xlfn.REGEXEXTRACT(CELL("address",G15), "\$([A-Z]+)\$[0-9]+"))),_xlfn.REGEXEXTRACT(CELL("address",G15), "\$([A-Z]+)\$[0-9]+"))} | H15: {=IFERROR(IF(OR('Raw Data'!H15="",LEN(TRIM('Raw Data'!H15))=0),"",IF(AND(ISNUMBER('Raw Data'!H15), IFERROR('Raw Data'!H15 = ROUND('Raw Data'!H15, 2),FALSE)),"",_xlfn.REGEXEXTRACT(CELL("address",H15), "\$([A-Z]+)\$[0-9]+"))),_xlfn.REGEXEXTRACT(CELL("address",H15), "\$([A-Z]+)\$[0-9]+"))} | I15: {=IFERROR(IF(OR('Raw Data'!I15="",LEN(TRIM('Raw Data'!I15))=0),"",IF(AND(ISNUMBER('Raw Data'!I15), IFERROR('Raw Data'!I15 = ROUND('Raw Data'!I15, 2),FALSE)),"",_xlfn.REGEXEXTRACT(CELL("address",I15), "\$([A-Z]+)\$[0-9]+"))),_xlfn.REGEXEXTRACT(CELL("address",I15), "\$([A-Z]+)\$[0-9]+"))} | J15: {=IFERROR(IF(OR('Raw Data'!J15="",LEN(TRIM('Raw Data'!J15))=0),"",IF(AND(ISNUMBER('Raw Data'!J15), IFERROR('Raw Data'!J15 = ROUND('Raw Data'!J15, 2),FALSE)),"",_xlfn.REGEXEXTRACT(CELL("address",J15), "\$([A-Z]+)\$[0-9]+"))),_xlfn.REGEXEXTRACT(CELL("address",J15), "\$([A-Z]+)\$[0-9]+"))} | K15: {=IFERROR(IF(OR('Raw Data'!K15="",LEN(TRIM('Raw Data'!K15))=0),"",IF(AND(ISNUMBER('Raw Data'!K15), IFERROR('Raw Data'!K15 = ROUND('Raw Data'!K15, 2),FALSE)),"",_xlfn.REGEXEXTRACT(CELL("address",K15), "\$([A-Z]+)\$[0-9]+"))),_xlfn.REGEXEXTRACT(CELL("address",K15), "\$([A-Z]+)\$[0-9]+"))} | ... T15: {=IFERROR(IF(OR('Raw Data'!T15="",LEN(TRIM('Raw Data'!T15))=0),"",IF(AND(ISNUMBER('Raw Data'!T15), IFERROR('Raw Data'!T15 = ROUND('Raw Data'!T15, 2),FALSE)),"",_xlfn.REGEXEXTRACT(CELL("address",T15), "\$([A-Z]+)\$[0-9]+"))),_xlfn.REGEXEXTRACT(CELL("address",T15), "\$([A-Z]+)\$[0-9]+"))} | U15: {=IFERROR(IF(OR('Raw Data'!U15="",LEN(TRIM('Raw Data'!U15))=0),"",IF(AND(LEN('Raw Data'!B15) <= 255,LEN('Raw Data'!U15)> 0),"",_xlfn.REGEXEXTRACT(CELL("address",'Raw Data'!U15),"\$([A-Z]+)\$[0-9]+"))),_xlfn.REGEXEXTRACT(CELL("address",'Raw Data'!U15),"\$([A-Z]+)\$[0-9]+"))}
B16: {=IFERROR(IF(OR('Raw Data'!B16="",LEN(TRIM('Raw Data'!B16))=0),"",IF(AND(LEN('Raw Data'!B16) <= 20,LEN('Raw Data'!B16)> 0),"",_xlfn.REGEXEXTRACT(CELL("address",'Raw Data'!B16),"\$([A-Z]+)\$[0-9]+"))),_xlfn.REGEXEXTRACT(CELL("address",'Raw Data'!B16),"\$([A-Z]+)\$[0-9]+"))} | C16: {=IFERROR(IF(OR('Raw Data'!C16="",LEN(TRIM('Raw Data'!C16))=0),"",IF(AND(ISNUMBER('Raw Data'!C16),'Raw Data'!C16>=Configuration!$D$2),"",_xlfn.REGEXEXTRACT(CELL("address",'Raw Data'!C16),"\$([A-Z]+)\$[0-9]+"))),_xlfn.REGEXEXTRACT(CELL("address",C16), "\$([A-Z]+)\$[0-9]+"))} | D16: {=IFERROR(IF(OR('Raw Data'!D16="",LEN(TRIM('Raw Data'!D16))=0),"",IF(AND(ISNUMBER('Raw Data'!D16), IFERROR('Raw Data'!D16 = ROUND('Raw Data'!D16, 2),FALSE)),"",_xlfn.REGEXEXTRACT(CELL("address",D16), "\$([A-Z]+)\$[0-9]+"))),_xlfn.REGEXEXTRACT(CELL("address",D16), "\$([A-Z]+)\$[0-9]+"))} | E16: {=IFERROR(IF(OR('Raw Data'!E16="",LEN(TRIM('Raw Data'!E16))=0),"",IF(AND(ISNUMBER('Raw Data'!E16), IFERROR('Raw Data'!E16 = ROUND('Raw Data'!E16, 2),FALSE)),"",_xlfn.REGEXEXTRACT(CELL("address",E16), "\$([A-Z]+)\$[0-9]+"))),_xlfn.REGEXEXTRACT(CELL("address",E16), "\$([A-Z]+)\$[0-9]+"))} | F16: {=IFERROR(IF(OR('Raw Data'!F16="",LEN(TRIM('Raw Data'!F16))=0),"",IF(AND(ISNUMBER('Raw Data'!F16), IFERROR('Raw Data'!F16 = ROUND('Raw Data'!F16, 2),FALSE)),"",_xlfn.REGEXEXTRACT(CELL("address",F16), "\$([A-Z]+)\$[0-9]+"))),_xlfn.REGEXEXTRACT(CELL("address",F16), "\$([A-Z]+)\$[0-9]+"))} | G16: {=IFERROR(IF(OR('Raw Data'!G16="",LEN(TRIM('Raw Data'!G16))=0),"",IF(AND(ISNUMBER('Raw Data'!G16), IFERROR('Raw Data'!G16 = ROUND('Raw Data'!G16, 2),FALSE)),"",_xlfn.REGEXEXTRACT(CELL("address",G16), "\$([A-Z]+)\$[0-9]+"))),_xlfn.REGEXEXTRACT(CELL("address",G16), "\$([A-Z]+)\$[0-9]+"))} | H16: {=IFERROR(IF(OR('Raw Data'!H16="",LEN(TRIM('Raw Data'!H16))=0),"",IF(AND(ISNUMBER('Raw Data'!H16), IFERROR('Raw Data'!H16 = ROUND('Raw Data'!H16, 2),FALSE)),"",_xlfn.REGEXEXTRACT(CELL("address",H16), "\$([A-Z]+)\$[0-9]+"))),_xlfn.REGEXEXTRACT(CELL("address",H16), "\$([A-Z]+)\$[0-9]+"))} | I16: {=IFERROR(IF(OR('Raw Data'!I16="",LEN(TRIM('Raw Data'!I16))=0),"",IF(AND(ISNUMBER('Raw Data'!I16), IFERROR('Raw Data'!I16 = ROUND('Raw Data'!I16, 2),FALSE)),"",_xlfn.REGEXEXTRACT(CELL("address",I16), "\$([A-Z]+)\$[0-9]+"))),_xlfn.REGEXEXTRACT(CELL("address",I16), "\$([A-Z]+)\$[0-9]+"))} | J16: {=IFERROR(IF(OR('Raw Data'!J16="",LEN(TRIM('Raw Data'!J16))=0),"",IF(AND(ISNUMBER('Raw Data'!J16), IFERROR('Raw Data'!J16 = ROUND('Raw Data'!J16, 2),FALSE)),"",_xlfn.REGEXEXTRACT(CELL("address",J16), "\$([A-Z]+)\$[0-9]+"))),_xlfn.REGEXEXTRACT(CELL("address",J16), "\$([A-Z]+)\$[0-9]+"))} | K16: {=IFERROR(IF(OR('Raw Data'!K16="",LEN(TRIM('Raw Data'!K16))=0),"",IF(AND(ISNUMBER('Raw Data'!K16), IFERROR('Raw Data'!K16 = ROUND('Raw Data'!K16, 2),FALSE)),"",_xlfn.REGEXEXTRACT(CELL("address",K16), "\$([A-Z]+)\$[0-9]+"))),_xlfn.REGEXEXTRACT(CELL("address",K16), "\$([A-Z]+)\$[0-9]+"))} | ... T16: {=IFERROR(IF(OR('Raw Data'!T16="",LEN(TRIM('Raw Data'!T16))=0),"",IF(AND(ISNUMBER('Raw Data'!T16), IFERROR('Raw Data'!T16 = ROUND('Raw Data'!T16, 2),FALSE)),"",_xlfn.REGEXEXTRACT(CELL("address",T16), "\$([A-Z]+)\$[0-9]+"))),_xlfn.REGEXEXTRACT(CELL("address",T16), "\$([A-Z]+)\$[0-9]+"))} | U16: {=IFERROR(IF(OR('Raw Data'!U16="",LEN(TRIM('Raw Data'!U16))=0),"",IF(AND(LEN('Raw Data'!B16) <= 255,LEN('Raw Data'!U16)> 0),"",_xlfn.REGEXEXTRACT(CELL("address",'Raw Data'!U16),"\$([A-Z]+)\$[0-9]+"))),_xlfn.REGEXEXTRACT(CELL("address",'Raw Data'!U16),"\$([A-Z]+)\$[0-9]+"))}
B17: {=IFERROR(IF(OR('Raw Data'!B17="",LEN(TRIM('Raw Data'!B17))=0),"",IF(AND(LEN('Raw Data'!B17) <= 20,LEN('Raw Data'!B17)> 0),"",_xlfn.REGEXEXTRACT(CELL("address",'Raw Data'!B17),"\$([A-Z]+)\$[0-9]+"))),_xlfn.REGEXEXTRACT(CELL("address",'Raw Data'!B17),"\$([A-Z]+)\$[0-9]+"))} | C17: {=IFERROR(IF(OR('Raw Data'!C17="",LEN(TRIM('Raw Data'!C17))=0),"",IF(AND(ISNUMBER('Raw Data'!C17),'Raw Data'!C17>=Configuration!$D$2),"",_xlfn.REGEXEXTRACT(CELL("address",'Raw Data'!C17),"\$([A-Z]+)\$[0-9]+"))),_xlfn.REGEXEXTRACT(CELL("address",C17), "\$([A-Z]+)\$[0-9]+"))} | D17: {=IFERROR(IF(OR('Raw Data'!D17="",LEN(TRIM('Raw Data'!D17))=0),"",IF(AND(ISNUMBER('Raw Data'!D17), IFERROR('Raw Data'!D17 = ROUND('Raw Data'!D17, 2),FALSE)),"",_xlfn.REGEXEXTRACT(CELL("address",D17), "\$([A-Z]+)\$[0-9]+"))),_xlfn.REGEXEXTRACT(CELL("address",D17), "\$([A-Z]+)\$[0-9]+"))} | E17: {=IFERROR(IF(OR('Raw Data'!E17="",LEN(TRIM('Raw Data'!E17))=0),"",IF(AND(ISNUMBER('Raw Data'!E17), IFERROR('Raw Data'!E17 = ROUND('Raw Data'!E17, 2),FALSE)),"",_xlfn.REGEXEXTRACT(CELL("address",E17), "\$([A-Z]+)\$[0-9]+"))),_xlfn.REGEXEXTRACT(CELL("address",E17), "\$([A-Z]+)\$[0-9]+"))} | F17: {=IFERROR(IF(OR('Raw Data'!F17="",LEN(TRIM('Raw Data'!F17))=0),"",IF(AND(ISNUMBER('Raw Data'!F17), IFERROR('Raw Data'!F17 = ROUND('Raw Data'!F17, 2),FALSE)),"",_xlfn.REGEXEXTRACT(CELL("address",F17), "\$([A-Z]+)\$[0-9]+"))),_xlfn.REGEXEXTRACT(CELL("address",F17), "\$([A-Z]+)\$[0-9]+"))} | G17: {=IFERROR(IF(OR('Raw Data'!G17="",LEN(TRIM('Raw Data'!G17))=0),"",IF(AND(ISNUMBER('Raw Data'!G17), IFERROR('Raw Data'!G17 = ROUND('Raw Data'!G17, 2),FALSE)),"",_xlfn.REGEXEXTRACT(CELL("address",G17), "\$([A-Z]+)\$[0-9]+"))),_xlfn.REGEXEXTRACT(CELL("address",G17), "\$([A-Z]+)\$[0-9]+"))} | H17: {=IFERROR(IF(OR('Raw Data'!H17="",LEN(TRIM('Raw Data'!H17))=0),"",IF(AND(ISNUMBER('Raw Data'!H17), IFERROR('Raw Data'!H17 = ROUND('Raw Data'!H17, 2),FALSE)),"",_xlfn.REGEXEXTRACT(CELL("address",H17), "\$([A-Z]+)\$[0-9]+"))),_xlfn.REGEXEXTRACT(CELL("address",H17), "\$([A-Z]+)\$[0-9]+"))} | I17: {=IFERROR(IF(OR('Raw Data'!I17="",LEN(TRIM('Raw Data'!I17))=0),"",IF(AND(ISNUMBER('Raw Data'!I17), IFERROR('Raw Data'!I17 = ROUND('Raw Data'!I17, 2),FALSE)),"",_xlfn.REGEXEXTRACT(CELL("address",I17), "\$([A-Z]+)\$[0-9]+"))),_xlfn.REGEXEXTRACT(CELL("address",I17), "\$([A-Z]+)\$[0-9]+"))} | J17: {=IFERROR(IF(OR('Raw Data'!J17="",LEN(TRIM('Raw Data'!J17))=0),"",IF(AND(ISNUMBER('Raw Data'!J17), IFERROR('Raw Data'!J17 = ROUND('Raw Data'!J17, 2),FALSE)),"",_xlfn.REGEXEXTRACT(CELL("address",J17), "\$([A-Z]+)\$[0-9]+"))),_xlfn.REGEXEXTRACT(CELL("address",J17), "\$([A-Z]+)\$[0-9]+"))} | K17: {=IFERROR(IF(OR('Raw Data'!K17="",LEN(TRIM('Raw Data'!K17))=0),"",IF(AND(ISNUMBER('Raw Data'!K17), IFERROR('Raw Data'!K17 = ROUND('Raw Data'!K17, 2),FALSE)),"",_xlfn.REGEXEXTRACT(CELL("address",K17), "\$([A-Z]+)\$[0-9]+"))),_xlfn.REGEXEXTRACT(CELL("address",K17), "\$([A-Z]+)\$[0-9]+"))} | ... T17: {=IFERROR(IF(OR('Raw Data'!T17="",LEN(TRIM('Raw Data'!T17))=0),"",IF(AND(ISNUMBER('Raw Data'!T17), IFERROR('Raw Data'!T17 = ROUND('Raw Data'!T17, 2),FALSE)),"",_xlfn.REGEXEXTRACT(CELL("address",T17), "\$([A-Z]+)\$[0-9]+"))),_xlfn.REGEXEXTRACT(CELL("address",T17), "\$([A-Z]+)\$[0-9]+"))} | U17: {=IFERROR(IF(OR('Raw Data'!U17="",LEN(TRIM('Raw Data'!U17))=0),"",IF(AND(LEN('Raw Data'!B17) <= 255,LEN('Raw Data'!U17)> 0),"",_xlfn.REGEXEXTRACT(CELL("address",'Raw Data'!U17),"\$([A-Z]+)\$[0-9]+"))),_xlfn.REGEXEXTRACT(CELL("address",'Raw Data'!U17),"\$([A-Z]+)\$[0-9]+"))}
B18: {=IFERROR(IF(OR('Raw Data'!B18="",LEN(TRIM('Raw Data'!B18))=0),"",IF(AND(LEN('Raw Data'!B18) <= 20,LEN('Raw Data'!B18)> 0),"",_xlfn.REGEXEXTRACT(CELL("address",'Raw Data'!B18),"\$([A-Z]+)\$[0-9]+"))),_xlfn.REGEXEXTRACT(CELL("address",'Raw Data'!B18),"\$([A-Z]+)\$[0-9]+"))} | C18: {=IFERROR(IF(OR('Raw Data'!C18="",LEN(TRIM('Raw Data'!C18))=0),"",IF(AND(ISNUMBER('Raw Data'!C18),'Raw Data'!C18>=Configuration!$D$2),"",_xlfn.REGEXEXTRACT(CELL("address",'Raw Data'!C18),"\$([A-Z]+)\$[0-9]+"))),_xlfn.REGEXEXTRACT(CELL("address",C18), "\$([A-Z]+)\$[0-9]+"))} | D18: {=IFERROR(IF(OR('Raw Data'!D18="",LEN(TRIM('Raw Data'!D18))=0),"",IF(AND(ISNUMBER('Raw Data'!D18), IFERROR('Raw Data'!D18 = ROUND('Raw Data'!D18, 2),FALSE)),"",_xlfn.REGEXEXTRACT(CELL("address",D18), "\$([A-Z]+)\$[0-9]+"))),_xlfn.REGEXEXTRACT(CELL("address",D18), "\$([A-Z]+)\$[0-9]+"))} | E18: {=IFERROR(IF(OR('Raw Data'!E18="",LEN(TRIM('Raw Data'!E18))=0),"",IF(AND(ISNUMBER('Raw Data'!E18), IFERROR('Raw Data'!E18 = ROUND('Raw Data'!E18, 2),FALSE)),"",_xlfn.REGEXEXTRACT(CELL("address",E18), "\$([A-Z]+)\$[0-9]+"))),_xlfn.REGEXEXTRACT(CELL("address",E18), "\$([A-Z]+)\$[0-9]+"))} | F18: {=IFERROR(IF(OR('Raw Data'!F18="",LEN(TRIM('Raw Data'!F18))=0),"",IF(AND(ISNUMBER('Raw Data'!F18), IFERROR('Raw Data'!F18 = ROUND('Raw Data'!F18, 2),FALSE)),"",_xlfn.REGEXEXTRACT(CELL("address",F18), "\$([A-Z]+)\$[0-9]+"))),_xlfn.REGEXEXTRACT(CELL("address",F18), "\$([A-Z]+)\$[0-9]+"))} | G18: {=IFERROR(IF(OR('Raw Data'!G18="",LEN(TRIM('Raw Data'!G18))=0),"",IF(AND(ISNUMBER('Raw Data'!G18), IFERROR('Raw Data'!G18 = ROUND('Raw Data'!G18, 2),FALSE)),"",_xlfn.REGEXEXTRACT(CELL("address",G18), "\$([A-Z]+)\$[0-9]+"))),_xlfn.REGEXEXTRACT(CELL("address",G18), "\$([A-Z]+)\$[0-9]+"))} | H18: {=IFERROR(IF(OR('Raw Data'!H18="",LEN(TRIM('Raw Data'!H18))=0),"",IF(AND(ISNUMBER('Raw Data'!H18), IFERROR('Raw Data'!H18 = ROUND('Raw Data'!H18, 2),FALSE)),"",_xlfn.REGEXEXTRACT(CELL("address",H18), "\$([A-Z]+)\$[0-9]+"))),_xlfn.REGEXEXTRACT(CELL("address",H18), "\$([A-Z]+)\$[0-9]+"))} | I18: {=IFERROR(IF(OR('Raw Data'!I18="",LEN(TRIM('Raw Data'!I18))=0),"",IF(AND(ISNUMBER('Raw Data'!I18), IFERROR('Raw Data'!I18 = ROUND('Raw Data'!I18, 2),FALSE)),"",_xlfn.REGEXEXTRACT(CELL("address",I18), "\$([A-Z]+)\$[0-9]+"))),_xlfn.REGEXEXTRACT(CELL("address",I18), "\$([A-Z]+)\$[0-9]+"))} | J18: {=IFERROR(IF(OR('Raw Data'!J18="",LEN(TRIM('Raw Data'!J18))=0),"",IF(AND(ISNUMBER('Raw Data'!J18), IFERROR('Raw Data'!J18 = ROUND('Raw Data'!J18, 2),FALSE)),"",_xlfn.REGEXEXTRACT(CELL("address",J18), "\$([A-Z]+)\$[0-9]+"))),_xlfn.REGEXEXTRACT(CELL("address",J18), "\$([A-Z]+)\$[0-9]+"))} | K18: {=IFERROR(IF(OR('Raw Data'!K18="",LEN(TRIM('Raw Data'!K18))=0),"",IF(AND(ISNUMBER('Raw Data'!K18), IFERROR('Raw Data'!K18 = ROUND('Raw Data'!K18, 2),FALSE)),"",_xlfn.REGEXEXTRACT(CELL("address",K18), "\$([A-Z]+)\$[0-9]+"))),_xlfn.REGEXEXTRACT(CELL("address",K18), "\$([A-Z]+)\$[0-9]+"))} | ... T18: {=IFERROR(IF(OR('Raw Data'!T18="",LEN(TRIM('Raw Data'!T18))=0),"",IF(AND(ISNUMBER('Raw Data'!T18), IFERROR('Raw Data'!T18 = ROUND('Raw Data'!T18, 2),FALSE)),"",_xlfn.REGEXEXTRACT(CELL("address",T18), "\$([A-Z]+)\$[0-9]+"))),_xlfn.REGEXEXTRACT(CELL("address",T18), "\$([A-Z]+)\$[0-9]+"))} | U18: {=IFERROR(IF(OR('Raw Data'!U18="",LEN(TRIM('Raw Data'!U18))=0),"",IF(AND(LEN('Raw Data'!B18) <= 255,LEN('Raw Data'!U18)> 0),"",_xlfn.REGEXEXTRACT(CELL("address",'Raw Data'!U18),"\$([A-Z]+)\$[0-9]+"))),_xlfn.REGEXEXTRACT(CELL("address",'Raw Data'!U18),"\$([A-Z]+)\$[0-9]+"))}
B19: {=IFERROR(IF(OR('Raw Data'!B19="",LEN(TRIM('Raw Data'!B19))=0),"",IF(AND(LEN('Raw Data'!B19) <= 20,LEN('Raw Data'!B19)> 0),"",_xlfn.REGEXEXTRACT(CELL("address",'Raw Data'!B19),"\$([A-Z]+)\$[0-9]+"))),_xlfn.REGEXEXTRACT(CELL("address",'Raw Data'!B19),"\$([A-Z]+)\$[0-9]+"))} | C19: {=IFERROR(IF(OR('Raw Data'!C19="",LEN(TRIM('Raw Data'!C19))=0),"",IF(AND(ISNUMBER('Raw Data'!C19),'Raw Data'!C19>=Configuration!$D$2),"",_xlfn.REGEXEXTRACT(CELL("address",'Raw Data'!C19),"\$([A-Z]+)\$[0-9]+"))),_xlfn.REGEXEXTRACT(CELL("address",C19), "\$([A-Z]+)\$[0-9]+"))} | D19: {=IFERROR(IF(OR('Raw Data'!D19="",LEN(TRIM('Raw Data'!D19))=0),"",IF(AND(ISNUMBER('Raw Data'!D19), IFERROR('Raw Data'!D19 = ROUND('Raw Data'!D19, 2),FALSE)),"",_xlfn.REGEXEXTRACT(CELL("address",D19), "\$([A-Z]+)\$[0-9]+"))),_xlfn.REGEXEXTRACT(CELL("address",D19), "\$([A-Z]+)\$[0-9]+"))} | E19: {=IFERROR(IF(OR('Raw Data'!E19="",LEN(TRIM('Raw Data'!E19))=0),"",IF(AND(ISNUMBER('Raw Data'!E19), IFERROR('Raw Data'!E19 = ROUND('Raw Data'!E19, 2),FALSE)),"",_xlfn.REGEXEXTRACT(CELL("address",E19), "\$([A-Z]+)\$[0-9]+"))),_xlfn.REGEXEXTRACT(CELL("address",E19), "\$([A-Z]+)\$[0-9]+"))} | F19: {=IFERROR(IF(OR('Raw Data'!F19="",LEN(TRIM('Raw Data'!F19))=0),"",IF(AND(ISNUMBER('Raw Data'!F19), IFERROR('Raw Data'!F19 = ROUND('Raw Data'!F19, 2),FALSE)),"",_xlfn.REGEXEXTRACT(CELL("address",F19), "\$([A-Z]+)\$[0-9]+"))),_xlfn.REGEXEXTRACT(CELL("address",F19), "\$([A-Z]+)\$[0-9]+"))} | G19: {=IFERROR(IF(OR('Raw Data'!G19="",LEN(TRIM('Raw Data'!G19))=0),"",IF(AND(ISNUMBER('Raw Data'!G19), IFERROR('Raw Data'!G19 = ROUND('Raw Data'!G19, 2),FALSE)),"",_xlfn.REGEXEXTRACT(CELL("address",G19), "\$([A-Z]+)\$[0-9]+"))),_xlfn.REGEXEXTRACT(CELL("address",G19), "\$([A-Z]+)\$[0-9]+"))} | H19: {=IFERROR(IF(OR('Raw Data'!H19="",LEN(TRIM('Raw Data'!H19))=0),"",IF(AND(ISNUMBER('Raw Data'!H19), IFERROR('Raw Data'!H19 = ROUND('Raw Data'!H19, 2),FALSE)),"",_xlfn.REGEXEXTRACT(CELL("address",H19), "\$([A-Z]+)\$[0-9]+"))),_xlfn.REGEXEXTRACT(CELL("address",H19), "\$([A-Z]+)\$[0-9]+"))} | I19: {=IFERROR(IF(OR('Raw Data'!I19="",LEN(TRIM('Raw Data'!I19))=0),"",IF(AND(ISNUMBER('Raw Data'!I19), IFERROR('Raw Data'!I19 = ROUND('Raw Data'!I19, 2),FALSE)),"",_xlfn.REGEXEXTRACT(CELL("address",I19), "\$([A-Z]+)\$[0-9]+"))),_xlfn.REGEXEXTRACT(CELL("address",I19), "\$([A-Z]+)\$[0-9]+"))} | J19: {=IFERROR(IF(OR('Raw Data'!J19="",LEN(TRIM('Raw Data'!J19))=0),"",IF(AND(ISNUMBER('Raw Data'!J19), IFERROR('Raw Data'!J19 = ROUND('Raw Data'!J19, 2),FALSE)),"",_xlfn.REGEXEXTRACT(CELL("address",J19), "\$([A-Z]+)\$[0-9]+"))),_xlfn.REGEXEXTRACT(CELL("address",J19), "\$([A-Z]+)\$[0-9]+"))} | K19: {=IFERROR(IF(OR('Raw Data'!K19="",LEN(TRIM('Raw Data'!K19))=0),"",IF(AND(ISNUMBER('Raw Data'!K19), IFERROR('Raw Data'!K19 = ROUND('Raw Data'!K19, 2),FALSE)),"",_xlfn.REGEXEXTRACT(CELL("address",K19), "\$([A-Z]+)\$[0-9]+"))),_xlfn.REGEXEXTRACT(CELL("address",K19), "\$([A-Z]+)\$[0-9]+"))} | ... T19: {=IFERROR(IF(OR('Raw Data'!T19="",LEN(TRIM('Raw Data'!T19))=0),"",IF(AND(ISNUMBER('Raw Data'!T19), IFERROR('Raw Data'!T19 = ROUND('Raw Data'!T19, 2),FALSE)),"",_xlfn.REGEXEXTRACT(CELL("address",T19), "\$([A-Z]+)\$[0-9]+"))),_xlfn.REGEXEXTRACT(CELL("address",T19), "\$([A-Z]+)\$[0-9]+"))} | U19: {=IFERROR(IF(OR('Raw Data'!U19="",LEN(TRIM('Raw Data'!U19))=0),"",IF(AND(LEN('Raw Data'!B19) <= 255,LEN('Raw Data'!U19)> 0),"",_xlfn.REGEXEXTRACT(CELL("address",'Raw Data'!U19),"\$([A-Z]+)\$[0-9]+"))),_xlfn.REGEXEXTRACT(CELL("address",'Raw Data'!U19),"\$([A-Z]+)\$[0-9]+"))}
B20: {=IFERROR(IF(OR('Raw Data'!B20="",LEN(TRIM('Raw Data'!B20))=0),"",IF(AND(LEN('Raw Data'!B20) <= 20,LEN('Raw Data'!B20)> 0),"",_xlfn.REGEXEXTRACT(CELL("address",'Raw Data'!B20),"\$([A-Z]+)\$[0-9]+"))),_xlfn.REGEXEXTRACT(CELL("address",'Raw Data'!B20),"\$([A-Z]+)\$[0-9]+"))} | C20: {=IFERROR(IF(OR('Raw Data'!C20="",LEN(TRIM('Raw Data'!C20))=0),"",IF(AND(ISNUMBER('Raw Data'!C20),'Raw Data'!C20>=Configuration!$D$2),"",_xlfn.REGEXEXTRACT(CELL("address",'Raw Data'!C20),"\$([A-Z]+)\$[0-9]+"))),_xlfn.REGEXEXTRACT(CELL("address",C20), "\$([A-Z]+)\$[0-9]+"))} | D20: {=IFERROR(IF(OR('Raw Data'!D20="",LEN(TRIM('Raw Data'!D20))=0),"",IF(AND(ISNUMBER('Raw Data'!D20), IFERROR('Raw Data'!D20 = ROUND('Raw Data'!D20, 2),FALSE)),"",_xlfn.REGEXEXTRACT(CELL("address",D20), "\$([A-Z]+)\$[0-9]+"))),_xlfn.REGEXEXTRACT(CELL("address",D20), "\$([A-Z]+)\$[0-9]+"))} | E20: {=IFERROR(IF(OR('Raw Data'!E20="",LEN(TRIM('Raw Data'!E20))=0),"",IF(AND(ISNUMBER('Raw Data'!E20), IFERROR('Raw Data'!E20 = ROUND('Raw Data'!E20, 2),FALSE)),"",_xlfn.REGEXEXTRACT(CELL("address",E20), "\$([A-Z]+)\$[0-9]+"))),_xlfn.REGEXEXTRACT(CELL("address",E20), "\$([A-Z]+)\$[0-9]+"))} | F20: {=IFERROR(IF(OR('Raw Data'!F20="",LEN(TRIM('Raw Data'!F20))=0),"",IF(AND(ISNUMBER('Raw Data'!F20), IFERROR('Raw Data'!F20 = ROUND('Raw Data'!F20, 2),FALSE)),"",_xlfn.REGEXEXTRACT(CELL("address",F20), "\$([A-Z]+)\$[0-9]+"))),_xlfn.REGEXEXTRACT(CELL("address",F20), "\$([A-Z]+)\$[0-9]+"))} | G20: {=IFERROR(IF(OR('Raw Data'!G20="",LEN(TRIM('Raw Data'!G20))=0),"",IF(AND(ISNUMBER('Raw Data'!G20), IFERROR('Raw Data'!G20 = ROUND('Raw Data'!G20, 2),FALSE)),"",_xlfn.REGEXEXTRACT(CELL("address",G20), "\$([A-Z]+)\$[0-9]+"))),_xlfn.REGEXEXTRACT(CELL("address",G20), "\$([A-Z]+)\$[0-9]+"))} | H20: {=IFERROR(IF(OR('Raw Data'!H20="",LEN(TRIM('Raw Data'!H20))=0),"",IF(AND(ISNUMBER('Raw Data'!H20), IFERROR('Raw Data'!H20 = ROUND('Raw Data'!H20, 2),FALSE)),"",_xlfn.REGEXEXTRACT(CELL("address",H20), "\$([A-Z]+)\$[0-9]+"))),_xlfn.REGEXEXTRACT(CELL("address",H20), "\$([A-Z]+)\$[0-9]+"))} | I20: {=IFERROR(IF(OR('Raw Data'!I20="",LEN(TRIM('Raw Data'!I20))=0),"",IF(AND(ISNUMBER('Raw Data'!I20), IFERROR('Raw Data'!I20 = ROUND('Raw Data'!I20, 2),FALSE)),"",_xlfn.REGEXEXTRACT(CELL("address",I20), "\$([A-Z]+)\$[0-9]+"))),_xlfn.REGEXEXTRACT(CELL("address",I20), "\$([A-Z]+)\$[0-9]+"))} | J20: {=IFERROR(IF(OR('Raw Data'!J20="",LEN(TRIM('Raw Data'!J20))=0),"",IF(AND(ISNUMBER('Raw Data'!J20), IFERROR('Raw Data'!J20 = ROUND('Raw Data'!J20, 2),FALSE)),"",_xlfn.REGEXEXTRACT(CELL("address",J20), "\$([A-Z]+)\$[0-9]+"))),_xlfn.REGEXEXTRACT(CELL("address",J20), "\$([A-Z]+)\$[0-9]+"))} | K20: {=IFERROR(IF(OR('Raw Data'!K20="",LEN(TRIM('Raw Data'!K20))=0),"",IF(AND(ISNUMBER('Raw Data'!K20), IFERROR('Raw Data'!K20 = ROUND('Raw Data'!K20, 2),FALSE)),"",_xlfn.REGEXEXTRACT(CELL("address",K20), "\$([A-Z]+)\$[0-9]+"))),_xlfn.REGEXEXTRACT(CELL("address",K20), "\$([A-Z]+)\$[0-9]+"))} | ... T20: {=IFERROR(IF(OR('Raw Data'!T20="",LEN(TRIM('Raw Data'!T20))=0),"",IF(AND(ISNUMBER('Raw Data'!T20), IFERROR('Raw Data'!T20 = ROUND('Raw Data'!T20, 2),FALSE)),"",_xlfn.REGEXEXTRACT(CELL("address",T20), "\$([A-Z]+)\$[0-9]+"))),_xlfn.REGEXEXTRACT(CELL("address",T20), "\$([A-Z]+)\$[0-9]+"))} | U20: {=IFERROR(IF(OR('Raw Data'!U20="",LEN(TRIM('Raw Data'!U20))=0),"",IF(AND(LEN('Raw Data'!B20) <= 255,LEN('Raw Data'!U20)> 0),"",_xlfn.REGEXEXTRACT(CELL("address",'Raw Data'!U20),"\$([A-Z]+)\$[0-9]+"))),_xlfn.REGEXEXTRACT(CELL("address",'Raw Data'!U20),"\$([A-Z]+)\$[0-9]+"))}
B21: {=IFERROR(IF(OR('Raw Data'!B21="",LEN(TRIM('Raw Data'!B21))=0),"",IF(AND(LEN('Raw Data'!B21) <= 20,LEN('Raw Data'!B21)> 0),"",_xlfn.REGEXEXTRACT(CELL("address",'Raw Data'!B21),"\$([A-Z]+)\$[0-9]+"))),_xlfn.REGEXEXTRACT(CELL("address",'Raw Data'!B21),"\$([A-Z]+)\$[0-9]+"))} | C21: {=IFERROR(IF(OR('Raw Data'!C21="",LEN(TRIM('Raw Data'!C21))=0),"",IF(AND(ISNUMBER('Raw Data'!C21),'Raw Data'!C21>=Configuration!$D$2),"",_xlfn.REGEXEXTRACT(CELL("address",'Raw Data'!C21),"\$([A-Z]+)\$[0-9]+"))),_xlfn.REGEXEXTRACT(CELL("address",C21), "\$([A-Z]+)\$[0-9]+"))} | D21: {=IFERROR(IF(OR('Raw Data'!D21="",LEN(TRIM('Raw Data'!D21))=0),"",IF(AND(ISNUMBER('Raw Data'!D21), IFERROR('Raw Data'!D21 = ROUND('Raw Data'!D21, 2),FALSE)),"",_xlfn.REGEXEXTRACT(CELL("address",D21), "\$([A-Z]+)\$[0-9]+"))),_xlfn.REGEXEXTRACT(CELL("address",D21), "\$([A-Z]+)\$[0-9]+"))} | E21: {=IFERROR(IF(OR('Raw Data'!E21="",LEN(TRIM('Raw Data'!E21))=0),"",IF(AND(ISNUMBER('Raw Data'!E21), IFERROR('Raw Data'!E21 = ROUND('Raw Data'!E21, 2),FALSE)),"",_xlfn.REGEXEXTRACT(CELL("address",E21), "\$([A-Z]+)\$[0-9]+"))),_xlfn.REGEXEXTRACT(CELL("address",E21), "\$([A-Z]+)\$[0-9]+"))} | F21: {=IFERROR(IF(OR('Raw Data'!F21="",LEN(TRIM('Raw Data'!F21))=0),"",IF(AND(ISNUMBER('Raw Data'!F21), IFERROR('Raw Data'!F21 = ROUND('Raw Data'!F21, 2),FALSE)),"",_xlfn.REGEXEXTRACT(CELL("address",F21), "\$([A-Z]+)\$[0-9]+"))),_xlfn.REGEXEXTRACT(CELL("address",F21), "\$([A-Z]+)\$[0-9]+"))} | G21: {=IFERROR(IF(OR('Raw Data'!G21="",LEN(TRIM('Raw Data'!G21))=0),"",IF(AND(ISNUMBER('Raw Data'!G21), IFERROR('Raw Data'!G21 = ROUND('Raw Data'!G21, 2),FALSE)),"",_xlfn.REGEXEXTRACT(CELL("address",G21), "\$([A-Z]+)\$[0-9]+"))),_xlfn.REGEXEXTRACT(CELL("address",G21), "\$([A-Z]+)\$[0-9]+"))} | H21: {=IFERROR(IF(OR('Raw Data'!H21="",LEN(TRIM('Raw Data'!H21))=0),"",IF(AND(ISNUMBER('Raw Data'!H21), IFERROR('Raw Data'!H21 = ROUND('Raw Data'!H21, 2),FALSE)),"",_xlfn.REGEXEXTRACT(CELL("address",H21), "\$([A-Z]+)\$[0-9]+"))),_xlfn.REGEXEXTRACT(CELL("address",H21), "\$([A-Z]+)\$[0-9]+"))} | I21: {=IFERROR(IF(OR('Raw Data'!I21="",LEN(TRIM('Raw Data'!I21))=0),"",IF(AND(ISNUMBER('Raw Data'!I21), IFERROR('Raw Data'!I21 = ROUND('Raw Data'!I21, 2),FALSE)),"",_xlfn.REGEXEXTRACT(CELL("address",I21), "\$([A-Z]+)\$[0-9]+"))),_xlfn.REGEXEXTRACT(CELL("address",I21), "\$([A-Z]+)\$[0-9]+"))} | J21: {=IFERROR(IF(OR('Raw Data'!J21="",LEN(TRIM('Raw Data'!J21))=0),"",IF(AND(ISNUMBER('Raw Data'!J21), IFERROR('Raw Data'!J21 = ROUND('Raw Data'!J21, 2),FALSE)),"",_xlfn.REGEXEXTRACT(CELL("address",J21), "\$([A-Z]+)\$[0-9]+"))),_xlfn.REGEXEXTRACT(CELL("address",J21), "\$([A-Z]+)\$[0-9]+"))} | K21: {=IFERROR(IF(OR('Raw Data'!K21="",LEN(TRIM('Raw Data'!K21))=0),"",IF(AND(ISNUMBER('Raw Data'!K21), IFERROR('Raw Data'!K21 = ROUND('Raw Data'!K21, 2),FALSE)),"",_xlfn.REGEXEXTRACT(CELL("address",K21), "\$([A-Z]+)\$[0-9]+"))),_xlfn.REGEXEXTRACT(CELL("address",K21), "\$([A-Z]+)\$[0-9]+"))} | ... T21: {=IFERROR(IF(OR('Raw Data'!T21="",LEN(TRIM('Raw Data'!T21))=0),"",IF(AND(ISNUMBER('Raw Data'!T21), IFERROR('Raw Data'!T21 = ROUND('Raw Data'!T21, 2),FALSE)),"",_xlfn.REGEXEXTRACT(CELL("address",T21), "\$([A-Z]+)\$[0-9]+"))),_xlfn.REGEXEXTRACT(CELL("address",T21), "\$([A-Z]+)\$[0-9]+"))} | U21: {=IFERROR(IF(OR('Raw Data'!U21="",LEN(TRIM('Raw Data'!U21))=0),"",IF(AND(LEN('Raw Data'!B21) <= 255,LEN('Raw Data'!U21)> 0),"",_xlfn.REGEXEXTRACT(CELL("address",'Raw Data'!U21),"\$([A-Z]+)\$[0-9]+"))),_xlfn.REGEXEXTRACT(CELL("address",'Raw Data'!U21),"\$([A-Z]+)\$[0-9]+"))}
... B249: {=IFERROR(IF(OR('Raw Data'!B249="",LEN(TRIM('Raw Data'!B249))=0),"",IF(AND(LEN('Raw Data'!B249) <= 20,LEN('Raw Data'!B249)> 0),"",_xlfn.REGEXEXTRACT(CELL("address",'Raw Data'!B249),"\$([A-Z]+)\$[0-9]+"))),_xlfn.REGEXEXTRACT(CELL("address",'Raw Data'!B249),"\$([A-Z]+)\$[0-9]+"))} | C249: {=IFERROR(IF(OR('Raw Data'!C249="",LEN(TRIM('Raw Data'!C249))=0),"",IF(AND(ISNUMBER('Raw Data'!C249),'Raw Data'!C249>=Configuration!$D$2),"",_xlfn.REGEXEXTRACT(CELL("address",'Raw Data'!C249),"\$([A-Z]+)\$[0-9]+"))),_xlfn.REGEXEXTRACT(CELL("address",C249), "\$([A-Z]+)\$[0-9]+"))} | D249: {=IFERROR(IF(OR('Raw Data'!D249="",LEN(TRIM('Raw Data'!D249))=0),"",IF(AND(ISNUMBER('Raw Data'!D249), IFERROR('Raw Data'!D249 = ROUND('Raw Data'!D249, 2),FALSE)),"",_xlfn.REGEXEXTRACT(CELL("address",D249), "\$([A-Z]+)\$[0-9]+"))),_xlfn.REGEXEXTRACT(CELL("address",D249), "\$([A-Z]+)\$[0-9]+"))} | E249: {=IFERROR(IF(OR('Raw Data'!E249="",LEN(TRIM('Raw Data'!E249))=0),"",IF(AND(ISNUMBER('Raw Data'!E249), IFERROR('Raw Data'!E249 = ROUND('Raw Data'!E249, 2),FALSE)),"",_xlfn.REGEXEXTRACT(CELL("address",E249), "\$([A-Z]+)\$[0-9]+"))),_xlfn.REGEXEXTRACT(CELL("address",E249), "\$([A-Z]+)\$[0-9]+"))} | F249: {=IFERROR(IF(OR('Raw Data'!F249="",LEN(TRIM('Raw Data'!F249))=0),"",IF(AND(ISNUMBER('Raw Data'!F249), IFERROR('Raw Data'!F249 = ROUND('Raw Data'!F249, 2),FALSE)),"",_xlfn.REGEXEXTRACT(CELL("address",F249), "\$([A-Z]+)\$[0-9]+"))),_xlfn.REGEXEXTRACT(CELL("address",F249), "\$([A-Z]+)\$[0-9]+"))} | G249: {=IFERROR(IF(OR('Raw Data'!G249="",LEN(TRIM('Raw Data'!G249))=0),"",IF(AND(ISNUMBER('Raw Data'!G249), IFERROR('Raw Data'!G249 = ROUND('Raw Data'!G249, 2),FALSE)),"",_xlfn.REGEXEXTRACT(CELL("address",G249), "\$([A-Z]+)\$[0-9]+"))),_xlfn.REGEXEXTRACT(CELL("address",G249), "\$([A-Z]+)\$[0-9]+"))} | H249: {=IFERROR(IF(OR('Raw Data'!H249="",LEN(TRIM('Raw Data'!H249))=0),"",IF(AND(ISNUMBER('Raw Data'!H249), IFERROR('Raw Data'!H249 = ROUND('Raw Data'!H249, 2),FALSE)),"",_xlfn.REGEXEXTRACT(CELL("address",H249), "\$([A-Z]+)\$[0-9]+"))),_xlfn.REGEXEXTRACT(CELL("address",H249), "\$([A-Z]+)\$[0-9]+"))} | I249: {=IFERROR(IF(OR('Raw Data'!I249="",LEN(TRIM('Raw Data'!I249))=0),"",IF(AND(ISNUMBER('Raw Data'!I249), IFERROR('Raw Data'!I249 = ROUND('Raw Data'!I249, 2),FALSE)),"",_xlfn.REGEXEXTRACT(CELL("address",I249), "\$([A-Z]+)\$[0-9]+"))),_xlfn.REGEXEXTRACT(CELL("address",I249), "\$([A-Z]+)\$[0-9]+"))} | J249: {=IFERROR(IF(OR('Raw Data'!J249="",LEN(TRIM('Raw Data'!J249))=0),"",IF(AND(ISNUMBER('Raw Data'!J249), IFERROR('Raw Data'!J249 = ROUND('Raw Data'!J249, 2),FALSE)),"",_xlfn.REGEXEXTRACT(CELL("address",J249), "\$([A-Z]+)\$[0-9]+"))),_xlfn.REGEXEXTRACT(CELL("address",J249), "\$([A-Z]+)\$[0-9]+"))} | K249: {=IFERROR(IF(OR('Raw Data'!K249="",LEN(TRIM('Raw Data'!K249))=0),"",IF(AND(ISNUMBER('Raw Data'!K249), IFERROR('Raw Data'!K249 = ROUND('Raw Data'!K249, 2),FALSE)),"",_xlfn.REGEXEXTRACT(CELL("address",K249), "\$([A-Z]+)\$[0-9]+"))),_xlfn.REGEXEXTRACT(CELL("address",K249), "\$([A-Z]+)\$[0-9]+"))} | ... T249: {=IFERROR(IF(OR('Raw Data'!T249="",LEN(TRIM('Raw Data'!T249))=0),"",IF(AND(ISNUMBER('Raw Data'!T249), IFERROR('Raw Data'!T249 = ROUND('Raw Data'!T249, 2),FALSE)),"",_xlfn.REGEXEXTRACT(CELL("address",T249), "\$([A-Z]+)\$[0-9]+"))),_xlfn.REGEXEXTRACT(CELL("address",T249), "\$([A-Z]+)\$[0-9]+"))} | U249: {=IFERROR(IF(OR('Raw Data'!U249="",LEN(TRIM('Raw Data'!U249))=0),"",IF(AND(LEN('Raw Data'!B249) <= 255,LEN('Raw Data'!U249)> 0),"",_xlfn.REGEXEXTRACT(CELL("address",'Raw Data'!U249),"\$([A-Z]+)\$[0-9]+"))),_xlfn.REGEXEXTRACT(CELL("address",'Raw Data'!U249),"\$([A-Z]+)\$[0-9]+"))}

Sheet Configuration
A1: col_number | B1: range_start | C1: range_stop | D1: project_active_start | E1: project_inactive_end | F1: relate_document
A2: 2 | B2: B10 | C2: U? | D2: 45292 | E2: 46388

Sheet Validate_Type
B1: C1 | C1: C2 | D1: C3 | E1: C4 | F1: C5 | G1: C6 | H1: C7 | I1: C8
B2: {=IF('Raw Data'!B2="",_xlfn.REGEXEXTRACT(CELL("address",'Raw Data'!B2),"\$([A-Z]+)\$[0-9]+"),"")} -> $B$2 | C2: {=IF('Raw Data'!C2="",_xlfn.REGEXEXTRACT(CELL("address",'Raw Data'!C2),"\$([A-Z]+)\$[0-9]+"),"")} -> $C$2 | D2: {=IF('Raw Data'!D2="",_xlfn.REGEXEXTRACT(CELL("address",'Raw Data'!D2),"\$([A-Z]+)\$[0-9]+"),"")} -> $D$2 | E2: {=IF('Raw Data'!E2="",_xlfn.REGEXEXTRACT(CELL("address",'Raw Data'!E2),"\$([A-Z]+)\$[0-9]+"),"")} -> $E$2 | F2: {=IF('Raw Data'!F2="",_xlfn.REGEXEXTRACT(CELL("address",'Raw Data'!F2),"\$([A-Z]+)\$[0-9]+"),"")} -> $F$2 | G2: {=IF('Raw Data'!#REF!="",_xlfn.REGEXEXTRACT(CELL("address",'Raw Data'!#REF!),"\$([A-Z]+)\$[0-9]+"),"")} -> #REF! | H2: {=IF('Raw Data'!G2="",_xlfn.REGEXEXTRACT(CELL("address",'Raw Data'!G2),"\$([A-Z]+)\$[0-9]+"),"")} -> $G$2 | I2: {=IF('Raw Data'!H2="",_xlfn.REGEXEXTRACT(CELL("address",'Raw Data'!H2),"\$([A-Z]+)\$[0-9]+"),"")} -> $H$2
B3: {=IF('Raw Data'!B3="",_xlfn.REGEXEXTRACT(CELL("address",'Raw Data'!B3),"\$([A-Z]+)\$[0-9]+"),"")} -> $B$3 | C3: {=IF('Raw Data'!C3="",_xlfn.REGEXEXTRACT(CELL("address",'Raw Data'!C3),"\$([A-Z]+)\$[0-9]+"),"")} -> $C$3 | D3: {=IF('Raw Data'!D3="",_xlfn.REGEXEXTRACT(CELL("address",'Raw Data'!D3),"\$([A-Z]+)\$[0-9]+"),"")} -> $D$3 | E3: {=IF('Raw Data'!E3="",_xlfn.REGEXEXTRACT(CELL("address",'Raw Data'!E3),"\$([A-Z]+)\$[0-9]+"),"")} -> $E$3 | F3: {=IF('Raw Data'!F3="",_xlfn.REGEXEXTRACT(CELL("address",'Raw Data'!F3),"\$([A-Z]+)\$[0-9]+"),"")} -> $F$3 | G3: {=IF('Raw Data'!#REF!="",_xlfn.REGEXEXTRACT(CELL("address",'Raw Data'!#REF!),"\$([A-Z]+)\$[0-9]+"),"")} -> #REF! | H3: {=IF('Raw Data'!G3="",_xlfn.REGEXEXTRACT(CELL("address",'Raw Data'!G3),"\$([A-Z]+)\$[0-9]+"),"")} -> $G$3 | I3: {=IF('Raw Data'!H3="",_xlfn.REGEXEXTRACT(CELL("address",'Raw Data'!H3),"\$([A-Z]+)\$[0-9]+"),"")} -> $H$3
B4: {=IF('Raw Data'!B4="",_xlfn.REGEXEXTRACT(CELL("address",'Raw Data'!B4),"\$([A-Z]+)\$[0-9]+"),"")} -> $B$4 | C4: {=IF('Raw Data'!C4="",_xlfn.REGEXEXTRACT(CELL("address",'Raw Data'!C4),"\$([A-Z]+)\$[0-9]+"),"")} -> $C$4 | D4: {=IF('Raw Data'!D4="",_xlfn.REGEXEXTRACT(CELL("address",'Raw Data'!D4),"\$([A-Z]+)\$[0-9]+"),"")} -> $D$4 | E4: {=IF('Raw Data'!E4="",_xlfn.REGEXEXTRACT(CELL("address",'Raw Data'!E4),"\$([A-Z]+)\$[0-9]+"),"")} -> $E$4 | F4: {=IF('Raw Data'!F4="",_xlfn.REGEXEXTRACT(CELL("address",'Raw Data'!F4),"\$([A-Z]+)\$[0-9]+"),"")} -> $F$4 | G4: {=IF('Raw Data'!#REF!="",_xlfn.REGEXEXTRACT(CELL("address",'Raw Data'!#REF!),"\$([A-Z]+)\$[0-9]+"),"")} -> #REF! | H4: {=IF('Raw Data'!G4="",_xlfn.REGEXEXTRACT(CELL("address",'Raw Data'!G4),"\$([A-Z]+)\$[0-9]+"),"")} -> $G$4 | I4: {=IF('Raw Data'!H4="",_xlfn.REGEXEXTRACT(CELL("address",'Raw Data'!H4),"\$([A-Z]+)\$[0-9]+"),"")} -> $H$4
B5: {=IF('Raw Data'!B5="",_xlfn.REGEXEXTRACT(CELL("address",'Raw Data'!B5),"\$([A-Z]+)\$[0-9]+"),"")} -> $B$5 | C5: {=IF('Raw Data'!C5="",_xlfn.REGEXEXTRACT(CELL("address",'Raw Data'!C5),"\$([A-Z]+)\$[0-9]+"),"")} -> $C$5 | D5: {=IF('Raw Data'!D5="",_xlfn.REGEXEXTRACT(CELL("address",'Raw Data'!D5),"\$([A-Z]+)\$[0-9]+"),"")} -> $D$5 | E5: {=IF('Raw Data'!E5="",_xlfn.REGEXEXTRACT(CELL("address",'Raw Data'!E5),"\$([A-Z]+)\$[0-9]+"),"")} -> $E$5 | F5: {=IF('Raw Data'!F5="",_xlfn.REGEXEXTRACT(CELL("address",'Raw Data'!F5),"\$([A-Z]+)\$[0-9]+"),"")} -> $F$5 | G5: {=IF('Raw Data'!#REF!="",_xlfn.REGEXEXTRACT(CELL("address",'Raw Data'!#REF!),"\$([A-Z]+)\$[0-9]+"),"")} -> #REF! | H5: {=IF('Raw Data'!G5="",_xlfn.REGEXEXTRACT(CELL("address",'Raw Data'!G5),"\$([A-Z]+)\$[0-9]+"),"")} -> $G$5 | I5: {=IF('Raw Data'!H5="",_xlfn.REGEXEXTRACT(CELL("address",'Raw Data'!H5),"\$([A-Z]+)\$[0-9]+"),"")} -> $H$5
