Workbook

Sheet Raw Data
B9: C1 | C9: C2 | D9: C3 | E9: C4 | F9: C5 | G9: C6 | H9: C7 | I9: C8 | J9: C9
B10: Overall Project | C10: Month # 1 | D10: 45536 | E10: 0.03 | F10: 0.03 | G10: 0.03 | H10: 0.03 | I10: 0.03 | J10: 0.03
B11: Overall Project | C11: Month # 2 | D11: 45566 | E11: 0.11 | F11: 0.11 | G11: 0.09 | H11: 0.08 | I11: 0.08 | J11: 0.06
B12: Overall Project | C12: Month # 3 | D12: 45597 | E12: 0.19 | F12: 0.19 | H12: 0.08 | I12: 0.08
B13: Overall Project | C13: Month # 4 | D13: 45627 | E13: 0.24 | F13: 0.24 | H13: 0.05 | I13: 0.05
B14: Overall Project | C14: Month # 5 | D14: 45658 | E14: 0.31 | F14: 0.31 | H14: 0.07 | I14: 0.07
B15: Overall Project | C15: Month # 6 | D15: 45689 | E15: 0.46 | F15: 0.46 | H15: 0.15 | I15: 0.15
B16: Overall Project | C16: Month # 7 | D16: 45717 | E16: 0.62 | F16: 0.62 | H16: 0.16 | I16: 0.16
B17: Overall Project | C17: Month # 8 | D17: 45748 | E17: 0.78 | F17: 0.78 | H17: 0.16 | I17: 0.16
B18: Overall Project | C18: Month # 9 | D18: 45778 | E18: 0.79 | F18: 0.79 | H18: 0.01 | I18: 0.01
B19: Overall Project | C19: Month # 10 | D19: 45809 | E19: 0.82 | F19: 0.82 | H19: 0.03 | I19: 0.03
B20: Overall Project | C20: Month # 11 | D20: 45839 | E20: 0.87 | F20: 0.87 | H20: 0.05 | I20: 0.05
B21: Overall Project | C21: Month # 12 | D21: 45870 | E21: 0.92 | F21: 0.92 | H21: 0.05 | I21: 0.05
B22: Overall Project | C22: Month # 13 | D22: 45901 | E22: 0.94 | F22: 0.94 | H22: 0.02 | I22: 0.02
B23: Overall Project | C23: Month # 14 | D23: 45931 | E23: 0.95 | F23: 0.95 | H23: 0.01 | I23: 0.01
... B33: Overall Project | C33: Month # 24 | D33: 46235 | E33: 1 | F33: 1 | H33: 0 | I33: 0
B34: Engineering | C34: Month # 1 | D34: 45536 | E34: 0.03 | F34: 0.03 | G34: 0.01 | H34: 0.03 | I34: 0.03 | J34: 0.01
B35: Engineering | C35: Month # 2 | D35: 45566 | E35: 0.42 | F35: 0.42 | G35: 0.47 | H35: 0.39 | I35: 0.39 | J35: 0.46
B36: Engineering | C36: Month # 3 | D36: 45597 | E36: 0.86 | F36: 0.86 | H36: 0.44 | I36: 0.44
B37: Engineering | C37: Month # 4 | D37: 45627 | E37: 0.99 | F37: 0.99 | H37: 0.13 | I37: 0.13
B38: Engineering | C38: Month # 5 | D38: 45658 | E38: 1 | F38: 1 | H38: 0.01 | I38: 0.01
B39: Engineering | C39: Month # 6 | D39: 45689 | E39: 1 | F39: 1 | H39: 0 | I39: 0
B40: Engineering | C40: Month # 7 | D40: 45717 | E40: 1 | F40: 1 | H40: 0 | I40: 0
B41: Engineering | C41: Month # 8 | D41: 45748 | E41: 1 | F41: 1 | H41: 0 | I41: 0
B42: Engineering | C42: Month # 9 | D42: 45778 | E42: 1 | F42: 1 | H42: 0 | I42: 0
B43: Engineering | C43: Month # 10 | D43: 45809 | E43: 1 | F43: 1 | H43: 0 | I43: 0
B44: Engineering | C44: Month # 11 | D44: 45839 | E44: 1 | F44: 1 | H44: 0 | I44: 0
B45: Engineering | C45: Month # 12 | D45: 45870 | E45: 1 | F45: 1 | H45: 0 | I45: 0
B46: Engineering | C46: Month # 13 | D46: 45901 | E46: 1 | F46: 1 | H46: 0 | I46: 0
B47: Engineering | C47: Month # 14 | D47: 45931 | E47: 1 | F47: 1 | H47: 0 | I47: 0
... B57: Engineering | C57: Month # 24 | D57: 46235 | E57: 1 | F57: 1 | H57: 0 | I57: 0
B58: Procurement | C58: Month # 1 | D58: 45536 | E58: 0 | F58: 0 | G58: 0 | H58: 0 | I58: 0 | J58: 0
B59: Procurement | C59: Month # 2 | D59: 45566 | E59: 0.2 | F59: 0.2 | G59: 0.13 | H59: 0.2 | I59: 0.2 | J59: 0.13
B60: Procurement | C60: Month # 3 | D60: 45597 | E60: 0.48 | F60: 0.48 | H60: 0.28 | I60: 0.28
B61: Procurement | C61: Month # 4 | D61: 45627 | E61: 0.59 | F61: 0.59 | H61: 0.11 | I61: 0.11
B62: Procurement | C62: Month # 5 | D62: 45658 | E62: 0.75 | F62: 0.75 | H62: 0.16 | I62: 0.16
B63: Procurement | C63: Month # 6 | D63: 45689 | E63: 0.96 | F63: 0.96 | H63: 0.21 | I63: 0.21
B64: Procurement | C64: Month # 7 | D64: 45717 | E64: 1 | F64: 1 | H64: 0.04 | I64: 0.04
B65: Procurement | C65: Month # 8 | D65: 45748 | E65: 1 | F65: 1 | H65: 0 | I65: 0
B66: Procurement | C66: Month # 9 | D66: 45778 | E66: 1 | F66: 1 | H66: 0 | I66: 0
...

Sheet Validate_Empty
B8: TRUE | C8: TRUE | D8: FALSE | E8: TRUE | F8: FALSE | G8: FALSE | H8: TRUE | I8: FALSE | J8: FALSE
B9: C1 | C9: C2 | D9: C3 | E9: C4 | F9: C5 | G9: C6 | H9: C7 | I9: C8 | J9: C9
B10: {=IFERROR(IF(OR('Raw Data'!B10="",LEN(TRIM('Raw Data'!B10))=0),_xlfn.REGEXEXTRACT(CELL("address",'Raw Data'!B10),"\$([A-Z]+)\$[0-9]+"),""),"")} | C10: {=IFERROR(IF(OR('Raw Data'!C10="",LEN(TRIM('Raw Data'!C10))=0),_xlfn.REGEXEXTRACT(CELL("address",'Raw Data'!C10),"\$([A-Z]+)\$[0-9]+"),""),"")} | E10: {=IFERROR(IF(OR('Raw Data'!E10="",LEN(TRIM('Raw Data'!E10))=0),_xlfn.REGEXEXTRACT(CELL("address",'Raw Data'!E10),"\$([A-Z]+)\$[0-9]+"),""),"")} | H10: {=IFERROR(IF(OR('Raw Data'!H10="",LEN(TRIM('Raw Data'!H10))=0),_xlfn.REGEXEXTRACT(CELL("address",'Raw Data'!H10),"\$([A-Z]+)\$[0-9]+"),""),"")}
B11: {=IFERROR(IF(OR('Raw Data'!B11="",LEN(TRIM('Raw Data'!B11))=0),_xlfn.REGEXEXTRACT(CELL("address",'Raw Data'!B11),"\$([A-Z]+)\$[0-9]+"),""),"")} | C11: {=IFERROR(IF(OR('Raw Data'!C11="",LEN(TRIM('Raw Data'!C11))=0),_xlfn.REGEXEXTRACT(CELL("address",'Raw Data'!C11),"\$([A-Z]+)\$[0-9]+"),""),"")} | E11: {=IFERROR(IF(OR('Raw Data'!E11="",LEN(TRIM('Raw Data'!E11))=0),_xlfn.REGEXEXTRACT(CELL("address",'Raw Data'!E11),"\$([A-Z]+)\$[0-9]+"),""),"")} | H11: {=IFERROR(IF(OR('Raw Data'!H11="",LEN(TRIM('Raw Data'!H11))=0),_xlfn.REGEXEXTRACT(CELL("address",'Raw Data'!H11),"\$([A-Z]+)\$[0-9]+"),""),"")}
B12: {=IFERROR(IF(OR('Raw Data'!B12="",LEN(TRIM('Raw Data'!B12))=0),_xlfn.REGEXEXTRACT(CELL("address",'Raw Data'!B12),"\$([A-Z]+)\$[0-9]+"),""),"")} | C12: {=IFERROR(IF(OR('Raw Data'!C12="",LEN(TRIM('Raw Data'!C12))=0),_xlfn.REGEXEXTRACT(CELL("address",'Raw Data'!C12),"\$([A-Z]+)\$[0-9]+"),""),"")} | E12: {=IFERROR(IF(OR('Raw Data'!E12="",LEN(TRIM('Raw Data'!E12))=0),_xlfn.REGEXEXTRACT(CELL("address",'Raw Data'!E12),"\$([A-Z]+)\$[0-9]+"),""),"")} | H12: {=IFERROR(IF(OR('Raw Data'!H12="",LEN(TRIM('Raw Data'!H12))=0),_xlfn.REGEXEXTRACT(CELL("address",'Raw Data'!H12),"\$([A-Z]+)\$[0-9]+"),""),"")}
B13: {=IFERROR(IF(OR('Raw Data'!B13="",LEN(TRIM('Raw Data'!B13))=0),_xlfn.REGEXEXTRACT(CELL("address",'Raw Data'!B13),"\$([A-Z]+)\$[0-9]+"),""),"")} | C13: {=IFERROR(IF(OR('Raw Data'!C13="",LEN(TRIM('Raw Data'!C13))=0),_xlfn.REGEXEXTRACT(CELL("address",'Raw Data'!C13),"\$([A-Z]+)\$[0-9]+"),""),"")} | E13: {=IFERROR(IF(OR('Raw Data'!E13="",LEN(TRIM('Raw Data'!E13))=0),_xlfn.REGEXEXTRACT(CELL("address",'Raw Data'!E13),"\$([A-Z]+)\$[0-9]+"),""),"")} | H13: {=IFERROR(IF(OR('Raw Data'!H13="",LEN(TRIM('Raw Data'!H13))=0),_xlfn.REGEXEXTRACT(CELL("address",'Raw Data'!H13),"\$([A-Z]+)\$[0-9]+"),""),"")}
B14: {=IFERROR(IF(OR('Raw Data'!B14="",LEN(TRIM('Raw Data'!B14))=0),_xlfn.REGEXEXTRACT(CELL("address",'Raw Data'!B14),"\$([A-Z]+)\$[0-9]+"),""),"")} | C14: {=IFERROR(IF(OR('Raw Data'!C14="",LEN(TRIM('Raw Data'!C14))=0),_xlfn.REGEXEXTRACT(CELL("address",'Raw Data'!C14),"\$([A-Z]+)\$[0-9]+"),""),"")} | E14: {=IFERROR(IF(OR('Raw Data'!E14="",LEN(TRIM('Raw Data'!E14))=0),_xlfn.REGEXEXTRACT(CELL("address",'Raw Data'!E14),"\$([A-Z]+)\$[0-9]+"),""),"")} | H14: {=IFERROR(IF(OR('Raw Data'!H14="",LEN(TRIM('Raw Data'!H14))=0),_xlfn.REGEXEXTRACT(CELL("address",'Raw Data'!H14),"\$([A-Z]+)\$[0-9]+"),""),"")}
B15: {=IFERROR(IF(OR('Raw Data'!B15="",LEN(TRIM('Raw Data'!B15))=0),_xlfn.REGEXEXTRACT(CELL("address",'Raw Data'!B15),"\$([A-Z]+)\$[0-9]+"),""),"")} | C15: {=IFERROR(IF(OR('Raw Data'!C15="",LEN(TRIM('Raw Data'!C15))=0),_xlfn.REGEXEXTRACT(CELL("address",'Raw Data'!C15),"\$([A-Z]+)\$[0-9]+"),""),"")} | E15: {=IFERROR(IF(OR('Raw Data'!E15="",LEN(TRIM('Raw Data'!E15))=0),_xlfn.REGEXEXTRACT(CELL("address",'Raw Data'!E15),"\$([A-Z]+)\$[0-9]+"),""),"")} | H15: {=IFERROR(IF(OR('Raw Data'!H15="",LEN(TRIM('Raw Data'!H15))=0),_xlfn.REGEXEXTRACT(CELL("address",'Raw Data'!H15),"\$([A-Z]+)\$[0-9]+"),""),"")}
B16: {=IFERROR(IF(OR('Raw Data'!B16="",LEN(TRIM('Raw Data'!B16))=0),_xlfn.REGEXEXTRACT(CELL("address",'Raw Data'!B16),"\$([A-Z]+)\$[0-9]+"),""),"")} | C16: {=IFERROR(IF(OR('Raw Data'!C16="",LEN(TRIM('Raw Data'!C16))=0),_xlfn.REGEXEXTRACT(CELL("address",'Raw Data'!C16),"\$([A-Z]+)\$[0-9]+"),""),"")} | E16: {=IFERROR(IF(OR('Raw Data'!E16="",LEN(TRIM('Raw Data'!E16))=0),_xlfn.REGEXEXTRACT(CELL("address",'Raw Data'!E16),"\$([A-Z]+)\$[0-9]+"),""),"")} | H16: {=IFERROR(IF(OR('Raw Data'!H16="",LEN(TRIM('Raw Data'!H16))=0),_xlfn.REGEXEXTRACT(CELL("address",'Raw Data'!H16),"\$([A-Z]+)\$[0-9]+"),""),"")}
B17: {=IFERROR(IF(OR('Raw Data'!B17="",LEN(TRIM('Raw Data'!B17))=0),_xlfn.REGEXEXTRACT(CELL("address",'Raw Data'!B17),"\$([A-Z]+)\$[0-9]+"),""),"")} | C17: {=IFERROR(IF(OR('Raw Data'!C17="",LEN(TRIM('Raw Data'!C17))=0),_xlfn.REGEXEXTRACT(CELL("address",'Raw Data'!C17),"\$([A-Z]+)\$[0-9]+"),""),"")} | E17: {=IFERROR(IF(OR('Raw Data'!E17="",LEN(TRIM('Raw Data'!E17))=0),_xlfn.REGEXEXTRACT(CELL("address",'Raw Data'!E17),"\$([A-Z]+)\$[0-9]+"),""),"")} | H17: {=IFERROR(IF(OR('Raw Data'!H17="",LEN(TRIM('Raw Data'!H17))=0),_xlfn.REGEXEXTRACT(CELL("address",'Raw Data'!H17),"\$([A-Z]+)\$[0-9]+"),""),"")}
B18: {=IFERROR(IF(OR('Raw Data'!B18="",LEN(TRIM('Raw Data'!B18))=0),_xlfn.REGEXEXTRACT(CELL("address",'Raw Data'!B18),"\$([A-Z]+)\$[0-9]+"),""),"")} | C18: {=IFERROR(IF(OR('Raw Data'!C18="",LEN(TRIM('Raw Data'!C18))=0),_xlfn.REGEXEXTRACT(CELL("address",'Raw Data'!C18),"\$([A-Z]+)\$[0-9]+"),""),"")} | E18: {=IFERROR(IF(OR('Raw Data'!E18="",LEN(TRIM('Raw Data'!E18))=0),_xlfn.REGEXEXTRACT(CELL("address",'Raw Data'!E18),"\$([A-Z]+)\$[0-9]+"),""),"")} | H18: {=IFERROR(IF(OR('Raw Data'!H18="",LEN(TRIM('Raw Data'!H18))=0),_xlfn.REGEXEXTRACT(CELL("address",'Raw Data'!H18),"\$([A-Z]+)\$[0-9]+"),""),"")}
B19: {=IFERROR(IF(OR('Raw Data'!B19="",LEN(TRIM('Raw Data'!B19))=0),_xlfn.REGEXEXTRACT(CELL("address",'Raw Data'!B19),"\$([A-Z]+)\$[0-9]+"),""),"")} | C19: {=IFERROR(IF(OR('Raw Data'!C19="",LEN(TRIM('Raw Data'!C19))=0),_xlfn.REGEXEXTRACT(CELL("address",'Raw Data'!C19),"\$([A-Z]+)\$[0-9]+"),""),"")} | E19: {=IFERROR(IF(OR('Raw Data'!E19="",LEN(TRIM('Raw Data'!E19))=0),_xlfn.REGEXEXTRACT(CELL("address",'Raw Data'!E19),"\$([A-Z]+)\$[0-9]+"),""),"")} | H19: {=IFERROR(IF(OR('Raw Data'!H19="",LEN(TRIM('Raw Data'!H19))=0),_xlfn.REGEXEXTRACT(CELL("address",'Raw Data'!H19),"\$([A-Z]+)\$[0-9]+"),""),"")}
B20: {=IFERROR(IF(OR('Raw Data'!B20="",LEN(TRIM('Raw Data'!B20))=0),_xlfn.REGEXEXTRACT(CELL("address",'Raw Data'!B20),"\$([A-Z]+)\$[0-9]+"),""),"")} | C20: {=IFERROR(IF(OR('Raw Data'!C20="",LEN(TRIM('Raw Data'!C20))=0),_xlfn.REGEXEXTRACT(CELL("address",'Raw Data'!C20),"\$([A-Z]+)\$[0-9]+"),""),"")} | E20: {=IFERROR(IF(OR('Raw Data'!E20="",LEN(TRIM('Raw Data'!E20))=0),_xlfn.REGEXEXTRACT(CELL("address",'Raw Data'!E20),"\$([A-Z]+)\$[0-9]+"),""),"")} | H20: {=IFERROR(IF(OR('Raw Data'!H20="",LEN(TRIM('Raw Data'!H20))=0),_xlfn.REGEXEXTRACT(CELL("address",'Raw Data'!H20),"\$([A-Z]+)\$[0-9]+"),""),"")}
B21: {=IFERROR(IF(OR('Raw Data'!B21="",LEN(TRIM('Raw Data'!B21))=0),_xlfn.REGEXEXTRACT(CELL("address",'Raw Data'!B21),"\$([A-Z]+)\$[0-9]+"),""),"")} | C21: {=IFERROR(IF(OR('Raw Data'!C21="",LEN(TRIM('Raw Data'!C21))=0),_xlfn.REGEXEXTRACT(CELL("address",'Raw Data'!C21),"\$([A-Z]+)\$[0-9]+"),""),"")} | E21: {=IFERROR(IF(OR('Raw Data'!E21="",LEN(TRIM('Raw Data'!E21))=0),_xlfn.REGEXEXTRACT(CELL("address",'Raw Data'!E21),"\$([A-Z]+)\$[0-9]+"),""),"")} | H21: {=IFERROR(IF(OR('Raw Data'!H21="",LEN(TRIM('Raw Data'!H21))=0),_xlfn.REGEXEXTRACT(CELL("address",'Raw Data'!H21),"\$([A-Z]+)\$[0-9]+"),""),"")}
... B249: {=IFERROR(IF(OR('Raw Data'!B249="",LEN(TRIM('Raw Data'!B249))=0),_xlfn.REGEXEXTRACT(CELL("address",'Raw Data'!B249),"\$([A-Z]+)\$[0-9]+"),""),"")} | C249: {=IFERROR(IF(OR('Raw Data'!C249="",LEN(TRIM('Raw Data'!C249))=0),_xlfn.REGEXEXTRACT(CELL("address",'Raw Data'!C249),"\$([A-Z]+)\$[0-9]+"),""),"")} | E249: {=IFERROR(IF(OR('Raw Data'!E249="",LEN(TRIM('Raw Data'!E249))=0),_xlfn.REGEXEXTRACT(CELL("address",'Raw Data'!E249),"\$([A-Z]+)\$[0-9]+"),""),"")} | H249: {=IFERROR(IF(OR('Raw Data'!H249="",LEN(TRIM('Raw Data'!H249))=0),_xlfn.REGEXEXTRACT(CELL("address",'Raw Data'!H249),"\$([A-Z]+)\$[0-9]+"),""),"")}

Sheet Validate_Value
B8: NVARCHAR(255) | C8: NVARCHAR(20) | D8: DATE | E8: DECIMAL(13,4) [Percentage] | F8: DECIMAL(13,4) [Percentage] | G8: DECIMAL(13,4) [Percentage] | H8: DECIMAL(13,4) [Percentage] | I8: DECIMAL(13,4) [Percentage] | J8: DECIMAL(13,4) [Percentage]
B9: C1 | C9: C2 | D9: C3 | E9: C4 | F9: C5 | G9: C6 | H9: C7 | I9: C8 | J9: C9
B10: {=IFERROR(IF(OR('Raw Data'!B10="",LEN(TRIM('Raw Data'!B10))=0),"",IF(AND(LEN('Raw Data'!B10) <= 255,LEN('Raw Data'!B10)> 0),"",_xlfn.REGEXEXTRACT(CELL("address",'Raw Data'!B10),"\$([A-Z]+)\$[0-9]+"))),_xlfn.REGEXEXTRACT(CELL("address",'Raw Data'!B10),"\$([A-Z]+)\$[0-9]+"))} | C10: {=IFERROR(IF(OR('Raw Data'!C10="",LEN(TRIM('Raw Data'!C10))=0),"",IF(AND(LEN('Raw Data'!C10) <= 20,LEN('Raw Data'!C10)> 0),"",_xlfn.REGEXEXTRACT(CELL("address",'Raw Data'!C10),"\$([A-Z]+)\$[0-9]+"))),_xlfn.REGEXEXTRACT(CELL("address",'Raw Data'!C10),"\$([A-Z]+)\$[0-9]+"))} | D10: {=IFERROR(IF(OR('Raw Data'!D10="",LEN(TRIM('Raw Data'!D10))=0),"",IF(AND(ISNUMBER('Raw Data'!D10),'Raw Data'!D10>=Configuration!$D$2),"",_xlfn.REGEXEXTRACT(CELL("address",'Raw Data'!D10),"\$([A-Z]+)\$[0-9]+"))),_xlfn.REGEXEXTRACT(CELL("address",D10), "\$([A-Z]+)\$[0-9]+"))} | E10: {=IFERROR(IF(OR('Raw Data'!E10="",LEN(TRIM('Raw Data'!E10))=0),"",IF(AND(ISNUMBER('Raw Data'!E10),'Raw Data'!E10=ROUND('Raw Data'!E10,4),IFERROR(ROUND('Raw Data'!E10,4)<=99999999999.99,FALSE))=TRUE,"",_xlfn.REGEXEXTRACT(CELL("address",'Raw Data'!E10), "\$([A-Z]+)\$[0-9]+"))),_xlfn.REGEXEXTRACT(CELL("address",'Raw Data'!E10), "\$([A-Z]+)\$[0-9]+"))} | F10: {=IFERROR(IF(OR('Raw Data'!F10="",LEN(TRIM('Raw Data'!F10))=0),"",IF(AND(ISNUMBER('Raw Data'!F10),'Raw Data'!F10=ROUND('Raw Data'!F10,4),IFERROR(ROUND('Raw Data'!F10,4)<=99999999999.99,FALSE))=TRUE,"",_xlfn.REGEXEXTRACT(CELL("address",'Raw Data'!F10), "\$([A-Z]+)\$[0-9]+"))),_xlfn.REGEXEXTRACT(CELL("address",'Raw Data'!F10), "\$([A-Z]+)\$[0-9]+"))} | G10: {=IFERROR(IF(OR('Raw Data'!G10="",LEN(TRIM('Raw Data'!G10))=0),"",IF(AND(ISNUMBER('Raw Data'!G10),'Raw Data'!G10=ROUND('Raw Data'!G10,4),IFERROR(ROUND('Raw Data'!G10,4)<=99999999999.99,FALSE))=TRUE,"",_xlfn.REGEXEXTRACT(CELL("address",'Raw Data'!G10), "\$([A-Z]+)\$[0-9]+"))),_xlfn.REGEXEXTRACT(CELL("address",'Raw Data'!G10), "\$([A-Z]+)\$[0-9]+"))} | H10: {=IFERROR(IF(OR('Raw Data'!H10="",LEN(TRIM('Raw Data'!H10))=0),"",IF(AND(ISNUMBER('Raw Data'!H10),'Raw Data'!H10=ROUND('Raw Data'!H10,4),IFERROR(ROUND('Raw Data'!H10,4)<=99999999999.99,FALSE))=TRUE,"",_xlfn.REGEXEXTRACT(CELL("address",'Raw Data'!H10), "\$([A-Z]+)\$[0-9]+"))),_xlfn.REGEXEXTRACT(CELL("address",'Raw Data'!H10), "\$([A-Z]+)\$[0-9]+"))} | I10: {=IFERROR(IF(OR('Raw Data'!I10="",LEN(TRIM('Raw Data'!I10))=0),"",IF(AND(ISNUMBER('Raw Data'!I10),'Raw Data'!I10=ROUND('Raw Data'!I10,4),IFERROR(ROUND('Raw Data'!I10,4)<=99999999999.99,FALSE))=TRUE,"",_xlfn.REGEXEXTRACT(CELL("address",'Raw Data'!I10), "\$([A-Z]+)\$[0-9]+"))),_xlfn.REGEXEXTRACT(CELL("address",'Raw Data'!I10), "\$([A-Z]+)\$[0-9]+"))} | J10: {=IFERROR(IF(OR('Raw Data'!J10="",LEN(TRIM('Raw Data'!J10))=0),"",IF(AND(ISNUMBER('Raw Data'!J10),'Raw Data'!J10=ROUND('Raw Data'!J10,4),IFERROR(ROUND('Raw Data'!J10,4)<=99999999999.99,FALSE))=TRUE,"",_xlfn.REGEXEXTRACT(CELL("address",'Raw Data'!J10), "\$([A-Z]+)\$[0-9]+"))),_xlfn.REGEXEXTRACT(CELL("address",'Raw Data'!J10), "\$([A-Z]+)\$[0-9]+"))}
B11: {=IFERROR(IF(OR('Raw Data'!B11="",LEN(TRIM('Raw Data'!B11))=0),"",IF(AND(LEN('Raw Data'!B11) <= 255,LEN('Raw Data'!B11)> 0),"",_xlfn.REGEXEXTRACT(CELL("address",'Raw Data'!B11),"\$([A-Z]+)\$[0-9]+"))),_xlfn.REGEXEXTRACT(CELL("address",'Raw Data'!B11),"\$([A-Z]+)\$[0-9]+"))} | C11: {=IFERROR(IF(OR('Raw Data'!C11="",LEN(TRIM('Raw Data'!C11))=0),"",IF(AND(LEN('Raw Data'!C11) <= 20,LEN('Raw Data'!C11)> 0),"",_xlfn.REGEXEXTRACT(CELL("address",'Raw Data'!C11),"\$([A-Z]+)\$[0-9]+"))),_xlfn.REGEXEXTRACT(CELL("address",'Raw Data'!C11),"\$([A-Z]+)\$[0-9]+"))} | D11: {=IFERROR(IF(OR('Raw Data'!D11="",LEN(TRIM('Raw Data'!D11))=0),"",IF(AND(ISNUMBER('Raw Data'!D11),'Raw Data'!D11>=Configuration!$D$2),"",_xlfn.REGEXEXTRACT(CELL("address",'Raw Data'!D11),"\$([A-Z]+)\$[0-9]+"))),_xlfn.REGEXEXTRACT(CELL("address",D11), "\$([A-Z]+)\$[0-9]+"))} | E11: {=IFERROR(IF(OR('Raw Data'!E11="",LEN(TRIM('Raw Data'!E11))=0),"",IF(AND(ISNUMBER('Raw Data'!E11),'Raw Data'!E11=ROUND('Raw Data'!E11,4),IFERROR(ROUND('Raw Data'!E11,4)<=99999999999.99,FALSE))=TRUE,"",_xlfn.REGEXEXTRACT(CELL("address",'Raw Data'!E11), "\$([A-Z]+)\$[0-9]+"))),_xlfn.REGEXEXTRACT(CELL("address",'Raw Data'!E11), "\$([A-Z]+)\$[0-9]+"))} | F11: {=IFERROR(IF(OR('Raw Data'!F11="",LEN(TRIM('Raw Data'!F11))=0),"",IF(AND(ISNUMBER('Raw Data'!F11),'Raw Data'!F11=ROUND('Raw Data'!F11,4),IFERROR(ROUND('Raw Data'!F11,4)<=99999999999.99,FALSE))=TRUE,"",_xlfn.REGEXEXTRACT(CELL("address",'Raw Data'!F11), "\$([A-Z]+)\$[0-9]+"))),_xlfn.REGEXEXTRACT(CELL("address",'Raw Data'!F11), "\$([A-Z]+)\$[0-9]+"))} | G11: {=IFERROR(IF(OR('Raw Data'!G11="",LEN(TRIM('Raw Data'!G11))=0),"",IF(AND(ISNUMBER('Raw Data'!G11),'Raw Data'!G11=ROUND('Raw Data'!G11,4),IFERROR(ROUND('Raw Data'!G11,4)<=99999999999.99,FALSE))=TRUE,"",_xlfn.REGEXEXTRACT(CELL("address",'Raw Data'!G11), "\$([A-Z]+)\$[0-9]+"))),_xlfn.REGEXEXTRACT(CELL("address",'Raw Data'!G11), "\$([A-Z]+)\$[0-9]+"))} | H11: {=IFERROR(IF(OR('Raw Data'!H11="",LEN(TRIM('Raw Data'!H11))=0),"",IF(AND(ISNUMBER('Raw Data'!H11),'Raw Data'!H11=ROUND('Raw Data'!H11,4),IFERROR(ROUND('Raw Data'!H11,4)<=99999999999.99,FALSE))=TRUE,"",_xlfn.REGEXEXTRACT(CELL("address",'Raw Data'!H11), "\$([A-Z]+)\$[0-9]+"))),_xlfn.REGEXEXTRACT(CELL("address",'Raw Data'!H11), "\$([A-Z]+)\$[0-9]+"))} | I11: {=IFERROR(IF(OR('Raw Data'!I11="",LEN(TRIM('Raw Data'!I11))=0),"",IF(AND(ISNUMBER('Raw Data'!I11),'Raw Data'!I11=ROUND('Raw Data'!I11,4),IFERROR(ROUND('Raw Data'!I11,4)<=99999999999.99,FALSE))=TRUE,"",_xlfn.REGEXEXTRACT(CELL("address",'Raw Data'!I11), "\$([A-Z]+)\$[0-9]+"))),_xlfn.REGEXEXTRACT(CELL("address",'Raw Data'!I11), "\$([A-Z]+)\$[0-9]+"))} | J11: {=IFERROR(IF(OR('Raw Data'!J11="",LEN(TRIM('Raw Data'!J11))=0),"",IF(AND(ISNUMBER('Raw Data'!J11),'Raw Data'!J11=ROUND('Raw Data'!J11,4),IFERROR(ROUND('Raw Data'!J11,4)<=99999999999.99,FALSE))=TRUE,"",_xlfn.REGEXEXTRACT(CELL("address",'Raw Data'!J11), "\$([A-Z]+)\$[0-9]+"))),_xlfn.REGEXEXTRACT(CELL("address",'Raw Data'!J11), "\$([A-Z]+)\$[0-9]+"))}
B12: {=IFERROR(IF(OR('Raw Data'!B12="",LEN(TRIM('Raw Data'!B12))=0),"",IF(AND(LEN('Raw Data'!B12) <= 255,LEN('Raw Data'!B12)> 0),"",_xlfn.REGEXEXTRACT(CELL("address",'Raw Data'!B12),"\$([A-Z]+)\$[0-9]+"))),_xlfn.REGEXEXTRACT(CELL("address",'Raw Data'!B12),"\$([A-Z]+)\$[0-9]+"))} | C12: {=IFERROR(IF(OR('Raw Data'!C12="",LEN(TRIM('Raw Data'!C12))=0),"",IF(AND(LEN('Raw Data'!C12) <= 20,LEN('Raw Data'!C12)> 0),"",_xlfn.REGEXEXTRACT(CELL("address",'Raw Data'!C12),"\$([A-Z]+)\$[0-9]+"))),_xlfn.REGEXEXTRACT(CELL("address",'Raw Data'!C12),"\$([A-Z]+)\$[0-9]+"))} | D12: {=IFERROR(IF(OR('Raw Data'!D12="",LEN(TRIM('Raw Data'!D12))=0),"",IF(AND(ISNUMBER('Raw Data'!D12),'Raw Data'!D12>=Configuration!$D$2),"",_xlfn.REGEXEXTRACT(CELL("address",'Raw Data'!D12),"\$([A-Z]+)\$[0-9]+"))),_xlfn.REGEXEXTRACT(CELL("address",D12), "\$([A-Z]+)\$[0-9]+"))} | E12: {=IFERROR(IF(OR('Raw Data'!E12="",LEN(TRIM('Raw Data'!E12))=0),"",IF(AND(ISNUMBER('Raw Data'!E12),'Raw Data'!E12=ROUND('Raw Data'!E12,4),IFERROR(ROUND('Raw Data'!E12,4)<=99999999999.99,FALSE))=TRUE,"",_xlfn.REGEXEXTRACT(CELL("address",'Raw Data'!E12), "\$([A-Z]+)\$[0-9]+"))),_xlfn.REGEXEXTRACT(CELL("address",'Raw Data'!E12), "\$([A-Z]+)\$[0-9]+"))} | F12: {=IFERROR(IF(OR('Raw Data'!F12="",LEN(TRIM('Raw Data'!F12))=0),"",IF(AND(ISNUMBER('Raw Data'!F12),'Raw Data'!F12=ROUND('Raw Data'!F12,4),IFERROR(ROUND('Raw Data'!F12,4)<=99999999999.99,FALSE))=TRUE,"",_xlfn.REGEXEXTRACT(CELL("address",'Raw Data'!F12), "\$([A-Z]+)\$[0-9]+"))),_xlfn.REGEXEXTRACT(CELL("address",'Raw Data'!F12), "\$([A-Z]+)\$[0-9]+"))} | G12: {=IFERROR(IF(OR('Raw Data'!G12="",LEN(TRIM('Raw Data'!G12))=0),"",IF(AND(ISNUMBER('Raw Data'!G12),'Raw Data'!G12=ROUND('Raw Data'!G12,4),IFERROR(ROUND('Raw Data'!G12,4)<=99999999999.99,FALSE))=TRUE,"",_xlfn.REGEXEXTRACT(CELL("address",'Raw Data'!G12), "\$([A-Z]+)\$[0-9]+"))),_xlfn.REGEXEXTRACT(CELL("address",'Raw Data'!G12), "\$([A-Z]+)\$[0-9]+"))} | H12: {=IFERROR(IF(OR('Raw Data'!H12="",LEN(TRIM('Raw Data'!H12))=0),"",IF(AND(ISNUMBER('Raw Data'!H12),'Raw Data'!H12=ROUND('Raw Data'!H12,4),IFERROR(ROUND('Raw Data'!H12,4)<=99999999999.99,FALSE))=TRUE,"",_xlfn.REGEXEXTRACT(CELL("address",'Raw Data'!H12), "\$([A-Z]+)\$[0-9]+"))),_xlfn.REGEXEXTRACT(CELL("address",'Raw Data'!H12), "\$([A-Z]+)\$[0-9]+"))} | I12: {=IFERROR(IF(OR('Raw Data'!I12="",LEN(TRIM('Raw Data'!I12))=0),"",IF(AND(ISNUMBER('Raw Data'!I12),'Raw Data'!I12=ROUND('Raw Data'!I12,4),IFERROR(ROUND('Raw Data'!I12,4)<=99999999999.99,FALSE))=TRUE,"",_xlfn.REGEXEXTRACT(CELL("address",'Raw Data'!I12), "\$([A-Z]+)\$[0-9]+"))),_xlfn.REGEXEXTRACT(CELL("address",'Raw Data'!I12), "\$([A-Z]+)\$[0-9]+"))} | J12: {=IFERROR(IF(OR('Raw Data'!J12="",LEN(TRIM('Raw Data'!J12))=0),"",IF(AND(ISNUMBER('Raw Data'!J12),'Raw Data'!J12=ROUND('Raw Data'!J12,4),IFERROR(ROUND('Raw Data'!J12,4)<=99999999999.99,FALSE))=TRUE,"",_xlfn.REGEXEXTRACT(CELL("address",'Raw Data'!J12), "\$([A-Z]+)\$[0-9]+"))),_xlfn.REGEXEXTRACT(CELL("address",'Raw Data'!J12), "\$([A-Z]+)\$[0-9]+"))}
B13: {=IFERROR(IF(OR('Raw Data'!B13="",LEN(TRIM('Raw Data'!B13))=0),"",IF(AND(LEN('Raw Data'!B13) <= 255,LEN('Raw Data'!B13)> 0),"",_xlfn.REGEXEXTRACT(CELL("address",'Raw Data'!B13),"\$([A-Z]+)\$[0-9]+"))),_xlfn.REGEXEXTRACT(CELL("address",'Raw Data'!B13),"\$([A-Z]+)\$[0-9]+"))} | C13: {=IFERROR(IF(OR('Raw Data'!C13="",LEN(TRIM('Raw Data'!C13))=0),"",IF(AND(LEN('Raw Data'!C13) <= 20,LEN('Raw Data'!C13)> 0),"",_xlfn.REGEXEXTRACT(CELL("address",'Raw Data'!C13),"\$([A-Z]+)\$[0-9]+"))),_xlfn.REGEXEXTRACT(CELL("address",'Raw Data'!C13),"\$([A-Z]+)\$[0-9]+"))} | D13: {=IFERROR(IF(OR('Raw Data'!D13="",LEN(TRIM('Raw Data'!D13))=0),"",IF(AND(ISNUMBER('Raw Data'!D13),'Raw Data'!D13>=Configuration!$D$2),"",_xlfn.REGEXEXTRACT(CELL("address",'Raw Data'!D13),"\$([A-Z]+)\$[0-9]+"))),_xlfn.REGEXEXTRACT(CELL("address",D13), "\$([A-Z]+)\$[0-9]+"))} | E13: {=IFERROR(IF(OR('Raw Data'!E13="",LEN(TRIM('Raw Data'!E13))=0),"",IF(AND(ISNUMBER('Raw Data'!E13),'Raw Data'!E13=ROUND('Raw Data'!E13,4),IFERROR(ROUND('Raw Data'!E13,4)<=99999999999.99,FALSE))=TRUE,"",_xlfn.REGEXEXTRACT(CELL("address",'Raw Data'!E13), "\$([A-Z]+)\$[0-9]+"))),_xlfn.REGEXEXTRACT(CELL("address",'Raw Data'!E13), "\$([A-Z]+)\$[0-9]+"))} | F13: {=IFERROR(IF(OR('Raw Data'!F13="",LEN(TRIM('Raw Data'!F13))=0),"",IF(AND(ISNUMBER('Raw Data'!F13),'Raw Data'!F13=ROUND('Raw Data'!F13,4),IFERROR(ROUND('Raw Data'!F13,4)<=99999999999.99,FALSE))=TRUE,"",_xlfn.REGEXEXTRACT(CELL("address",'Raw Data'!F13), "\$([A-Z]+)\$[0-9]+"))),_xlfn.REGEXEXTRACT(CELL("address",'Raw Data'!F13), "\$([A-Z]+)\$[0-9]+"))} | G13: {=IFERROR(IF(OR('Raw Data'!G13="",LEN(TRIM('Raw Data'!G13))=0),"",IF(AND(ISNUMBER('Raw Data'!G13),'Raw Data'!G13=ROUND('Raw Data'!G13,4),IFERROR(ROUND('Raw Data'!G13,4)<=99999999999.99,FALSE))=TRUE,"",_xlfn.REGEXEXTRACT(CELL("address",'Raw Data'!G13), "\$([A-Z]+)\$[0-9]+"))),_xlfn.REGEXEXTRACT(CELL("address",'Raw Data'!G13), "\$([A-Z]+)\$[0-9]+"))} | H13: {=IFERROR(IF(OR('Raw Data'!H13="",LEN(TRIM('Raw Data'!H13))=0),"",IF(AND(ISNUMBER('Raw Data'!H13),'Raw Data'!H13=ROUND('Raw Data'!H13,4),IFERROR(ROUND('Raw Data'!H13,4)<=99999999999.99,FALSE))=TRUE,"",_xlfn.REGEXEXTRACT(CELL("address",'Raw Data'!H13), "\$([A-Z]+)\$[0-9]+"))),_xlfn.REGEXEXTRACT(CELL("address",'Raw Data'!H13), "\$([A-Z]+)\$[0-9]+"))} | I13: {=IFERROR(IF(OR('Raw Data'!I13="",LEN(TRIM('Raw Data'!I13))=0),"",IF(AND(ISNUMBER('Raw Data'!I13),'Raw Data'!I13=ROUND('Raw Data'!I13,4),IFERROR(ROUND('Raw Data'!I13,4)<=99999999999.99,FALSE))=TRUE,"",_xlfn.REGEXEXTRACT(CELL("address",'Raw Data'!I13), "\$([A-Z]+)\$[0-9]+"))),_xlfn.REGEXEXTRACT(CELL("address",'Raw Data'!I13), "\$([A-Z]+)\$[0-9]+"))} | J13: {=IFERROR(IF(OR('Raw Data'!J13="",LEN(TRIM('Raw Data'!J13))=0),"",IF(AND(ISNUMBER('Raw Data'!J13),'Raw Data'!J13=ROUND('Raw Data'!J13,4),IFERROR(ROUND('Raw Data'!J13,4)<=99999999999.99,FALSE))=TRUE,"",_xlfn.REGEXEXTRACT(CELL("address",'Raw Data'!J13), "\$([A-Z]+)\$[0-9]+"))),_xlfn.REGEXEXTRACT(CELL("address",'Raw Data'!J13), "\$([A-Z]+)\$[0-9]+"))}
B14: {=IFERROR(IF(OR('Raw Data'!B14="",LEN(TRIM('Raw Data'!B14))=0),"",IF(AND(LEN('Raw Data'!B14) <= 255,LEN('Raw Data'!B14)> 0),"",_xlfn.REGEXEXTRACT(CELL("address",'Raw Data'!B14),"\$([A-Z]+)\$[0-9]+"))),_xlfn.REGEXEXTRACT(CELL("address",'Raw Data'!B14),"\$([A-Z]+)\$[0-9]+"))} | C14: {=IFERROR(IF(OR('Raw Data'!C14="",LEN(TRIM('Raw Data'!C14))=0),"",IF(AND(LEN('Raw Data'!C14) <= 20,LEN('Raw Data'!C14)> 0),"",_xlfn.REGEXEXTRACT(CELL("address",'Raw Data'!C14),"\$([A-Z]+)\$[0-9]+"))),_xlfn.REGEXEXTRACT(CELL("address",'Raw Data'!C14),"\$([A-Z]+)\$[0-9]+"))} | D14: {=IFERROR(IF(OR('Raw Data'!D14="",LEN(TRIM('Raw Data'!D14))=0),"",IF(AND(ISNUMBER('Raw Data'!D14),'Raw Data'!D14>=Configuration!$D$2),"",_xlfn.REGEXEXTRACT(CELL("address",'Raw Data'!D14),"\$([A-Z]+)\$[0-9]+"))),_xlfn.REGEXEXTRACT(CELL("address",D14), "\$([A-Z]+)\$[0-9]+"))} | E14: {=IFERROR(IF(OR('Raw Data'!E14="",LEN(TRIM('Raw Data'!E14))=0),"",IF(AND(ISNUMBER('Raw Data'!E14),'Raw Data'!E14=ROUND('Raw Data'!E14,4),IFERROR(ROUND('Raw Data'!E14,4)<=99999999999.99,FALSE))=TRUE,"",_xlfn.REGEXEXTRACT(CELL("address",'Raw Data'!E14), "\$([A-Z]+)\$[0-9]+"))),_xlfn.REGEXEXTRACT(CELL("address",'Raw Data'!E14), "\$([A-Z]+)\$[0-9]+"))} | F14: {=IFERROR(IF(OR('Raw Data'!F14="",LEN(TRIM('Raw Data'!F14))=0),"",IF(AND(ISNUMBER('Raw Data'!F14),'Raw Data'!F14=ROUND('Raw Data'!F14,4),IFERROR(ROUND('Raw Data'!F14,4)<=99999999999.99,FALSE))=TRUE,"",_xlfn.REGEXEXTRACT(CELL("address",'Raw Data'!F14), "\$([A-Z]+)\$[0-9]+"))),_xlfn.REGEXEXTRACT(CELL("address",'Raw Data'!F14), "\$([A-Z]+)\$[0-9]+"))} | G14: {=IFERROR(IF(OR('Raw Data'!G14="",LEN(TRIM('Raw Data'!G14))=0),"",IF(AND(ISNUMBER('Raw Data'!G14),'Raw Data'!G14=ROUND('Raw Data'!G14,4),IFERROR(ROUND('Raw Data'!G14,4)<=99999999999.99,FALSE))=TRUE,"",_xlfn.REGEXEXTRACT(CELL("address",'Raw Data'!G14), "\$([A-Z]+)\$[0-9]+"))),_xlfn.REGEXEXTRACT(CELL("address",'Raw Data'!G14), "\$([A-Z]+)\$[0-9]+"))} | H14: {=IFERROR(IF(OR('Raw Data'!H14="",LEN(TRIM('Raw Data'!H14))=0),"",IF(AND(ISNUMBER('Raw Data'!H14),'Raw Data'!H14=ROUND('Raw Data'!H14,4),IFERROR(ROUND('Raw Data'!H14,4)<=99999999999.99,FALSE))=TRUE,"",_xlfn.REGEXEXTRACT(CELL("address",'Raw Data'!H14), "\$([A-Z]+)\$[0-9]+"))),_xlfn.REGEXEXTRACT(CELL("address",'Raw Data'!H14), "\$([A-Z]+)\$[0-9]+"))} | I14: {=IFERROR(IF(OR('Raw Data'!I14="",LEN(TRIM('Raw Data'!I14))=0),"",IF(AND(ISNUMBER('Raw Data'!I14),'Raw Data'!I14=ROUND('Raw Data'!I14,4),IFERROR(ROUND('Raw Data'!I14,4)<=99999999999.99,FALSE))=TRUE,"",_xlfn.REGEXEXTRACT(CELL("address",'Raw Data'!I14), "\$([A-Z]+)\$[0-9]+"))),_xlfn.REGEXEXTRACT(CELL("address",'Raw Data'!I14), "\$([A-Z]+)\$[0-9]+"))} | J14: {=IFERROR(IF(OR('Raw Data'!J14="",LEN(TRIM('Raw Data'!J14))=0),"",IF(AND(ISNUMBER('Raw Data'!J14),'Raw Data'!J14=ROUND('Raw Data'!J14,4),IFERROR(ROUND('Raw Data'!J14,4)<=99999999999.99,FALSE))=TRUE,"",_xlfn.REGEXEXTRACT(CELL("address",'Raw Data'!J14), "\$([A-Z]+)\$[0-9]+"))),_xlfn.REGEXEXTRACT(CELL("address",'Raw Data'!J14), "\$([A-Z]+)\$[0-9]+"))}
B15: {=IFERROR(IF(OR('Raw Data'!B15="",LEN(TRIM('Raw Data'!B15))=0),"",IF(AND(LEN('Raw Data'!B15) <= 255,LEN('Raw Data'!B15)> 0),"",_xlfn.REGEXEXTRACT(CELL("address",'Raw Data'!B15),"\$([A-Z]+)\$[0-9]+"))),_xlfn.REGEXEXTRACT(CELL("address",'Raw Data'!B15),"\$([A-Z]+)\$[0-9]+"))} | C15: {=IFERROR(IF(OR('Raw Data'!C15="",LEN(TRIM('Raw Data'!C15))=0),"",IF(AND(LEN('Raw Data'!C15) <= 20,LEN('Raw Data'!C15)> 0),"",_xlfn.REGEXEXTRACT(CELL("address",'Raw Data'!C15),"\$([A-Z]+)\$[0-9]+"))),_xlfn.REGEXEXTRACT(CELL("address",'Raw Data'!C15),"\$([A-Z]+)\$[0-9]+"))} | D15: {=IFERROR(IF(OR('Raw Data'!D15="",LEN(TRIM('Raw Data'!D15))=0),"",IF(AND(ISNUMBER('Raw Data'!D15),'Raw Data'!D15>=Configuration!$D$2),"",_xlfn.REGEXEXTRACT(CELL("address",'Raw Data'!D15),"\$([A-Z]+)\$[0-9]+"))),_xlfn.REGEXEXTRACT(CELL("address",D15), "\$([A-Z]+)\$[0-9]+"))} | E15: {=IFERROR(IF(OR('Raw Data'!E15="",LEN(TRIM('Raw Data'!E15))=0),"",IF(AND(ISNUMBER('Raw Data'!E15),'Raw Data'!E15=ROUND('Raw Data'!E15,4),IFERROR(ROUND('Raw Data'!E15,4)<=99999999999.99,FALSE))=TRUE,"",_xlfn.REGEXEXTRACT(CELL("address",'Raw Data'!E15), "\$([A-Z]+)\$[0-9]+"))),_xlfn.REGEXEXTRACT(CELL("address",'Raw Data'!E15), "\$([A-Z]+)\$[0-9]+"))} | F15: {=IFERROR(IF(OR('Raw Data'!F15="",LEN(TRIM('Raw Data'!F15))=0),"",IF(AND(ISNUMBER('Raw Data'!F15),'Raw Data'!F15=ROUND('Raw Data'!F15,4),IFERROR(ROUND('Raw Data'!F15,4)<=99999999999.99,FALSE))=TRUE,"",_xlfn.REGEXEXTRACT(CELL("address",'Raw Data'!F15), "\$([A-Z]+)\$[0-9]+"))),_xlfn.REGEXEXTRACT(CELL("address",'Raw Data'!F15), "\$([A-Z]+)\$[0-9]+"))} | G15: {=IFERROR(IF(OR('Raw Data'!G15="",LEN(TRIM('Raw Data'!G15))=0),"",IF(AND(ISNUMBER('Raw Data'!G15),'Raw Data'!G15=ROUND('Raw Data'!G15,4),IFERROR(ROUND('Raw Data'!G15,4)<=99999999999.99,FALSE))=TRUE,"",_xlfn.REGEXEXTRACT(CELL("address",'Raw Data'!G15), "\$([A-Z]+)\$[0-9]+"))),_xlfn.REGEXEXTRACT(CELL("address",'Raw Data'!G15), "\$([A-Z]+)\$[0-9]+"))} | H15: {=IFERROR(IF(OR('Raw Data'!H15="",LEN(TRIM('Raw Data'!H15))=0),"",IF(AND(ISNUMBER('Raw Data'!H15),'Raw Data'!H15=ROUND('Raw Data'!H15,4),IFERROR(ROUND('Raw Data'!H15,4)<=99999999999.99,FALSE))=TRUE,"",_xlfn.REGEXEXTRACT(CELL("address",'Raw Data'!H15), "\$([A-Z]+)\$[0-9]+"))),_xlfn.REGEXEXTRACT(CELL("address",'Raw Data'!H15), "\$([A-Z]+)\$[0-9]+"))} | I15: {=IFERROR(IF(OR('Raw Data'!I15="",LEN(TRIM('Raw Data'!I15))=0),"",IF(AND(ISNUMBER('Raw Data'!I15),'Raw Data'!I15=ROUND('Raw Data'!I15,4),IFERROR(ROUND('Raw Data'!I15,4)<=99999999999.99,FALSE))=TRUE,"",_xlfn.REGEXEXTRACT(CELL("address",'Raw Data'!I15), "\$([A-Z]+)\$[0-9]+"))),_xlfn.REGEXEXTRACT(CELL("address",'Raw Data'!I15), "\$([A-Z]+)\$[0-9]+"))} | J15: {=IFERROR(IF(OR('Raw Data'!J15="",LEN(TRIM('Raw Data'!J15))=0),"",IF(AND(ISNUMBER('Raw Data'!J15),'Raw Data'!J15=ROUND('Raw Data'!J15,4),IFERROR(ROUND('Raw Data'!J15,4)<=99999999999.99,FALSE))=TRUE,"",_xlfn.REGEXEXTRACT(CELL("address",'Raw Data'!J15), "\$([A-Z]+)\$[0-9]+"))),_xlfn.REGEXEXTRACT(CELL("address",'Raw Data'!J15), "\$([A-Z]+)\$[0-9]+"))}
B16: {=IFERROR(IF(OR('Raw Data'!B16="",LEN(TRIM('Raw Data'!B16))=0),"",IF(AND(LEN('Raw Data'!B16) <= 255,LEN('Raw Data'!B16)> 0),"",_xlfn.REGEXEXTRACT(CELL("address",'Raw Data'!B16),"\$([A-Z]+)\$[0-9]+"))),_xlfn.REGEXEXTRACT(CELL("address",'Raw Data'!B16),"\$([A-Z]+)\$[0-9]+"))} | C16: {=IFERROR(IF(OR('Raw Data'!C16="",LEN(TRIM('Raw Data'!C16))=0),"",IF(AND(LEN('Raw Data'!C16) <= 20,LEN('Raw Data'!C16)> 0),"",_xlfn.REGEXEXTRACT(CELL("address",'Raw Data'!C16),"\$([A-Z]+)\$[0-9]+"))),_xlfn.REGEXEXTRACT(CELL("address",'Raw Data'!C16),"\$([A-Z]+)\$[0-9]+"))} | D16: {=IFERROR(IF(OR('Raw Data'!D16="",LEN(TRIM('Raw Data'!D16))=0),"",IF(AND(ISNUMBER('Raw Data'!D16),'Raw Data'!D16>=Configuration!$D$2),"",_xlfn.REGEXEXTRACT(CELL("address",'Raw Data'!D16),"\$([A-Z]+)\$[0-9]+"))),_xlfn.REGEXEXTRACT(CELL("address",D16), "\$([A-Z]+)\$[0-9]+"))} | E16: {=IFERROR(IF(OR('Raw Data'!E16="",LEN(TRIM('Raw Data'!E16))=0),"",IF(AND(ISNUMBER('Raw Data'!E16),'Raw Data'!E16=ROUND('Raw Data'!E16,4),IFERROR(ROUND('Raw Data'!E16,4)<=99999999999.99,FALSE))=TRUE,"",_xlfn.REGEXEXTRACT(CELL("address",'Raw Data'!E16), "\$([A-Z]+)\$[0-9]+"))),_xlfn.REGEXEXTRACT(CELL("address",'Raw Data'!E16), "\$([A-Z]+)\$[0-9]+"))} | F16: {=IFERROR(IF(OR('Raw Data'!F16="",LEN(TRIM('Raw Data'!F16))=0),"",IF(AND(ISNUMBER('Raw Data'!F16),'Raw Data'!F16=ROUND('Raw Data'!F16,4),IFERROR(ROUND('Raw Data'!F16,4)<=99999999999.99,FALSE))=TRUE,"",_xlfn.REGEXEXTRACT(CELL("address",'Raw Data'!F16), "\$([A-Z]+)\$[0-9]+"))),_xlfn.REGEXEXTRACT(CELL("address",'Raw Data'!F16), "\$([A-Z]+)\$[0-9]+"))} | G16: {=IFERROR(IF(OR('Raw Data'!G16="",LEN(TRIM('Raw Data'!G16))=0),"",IF(AND(ISNUMBER('Raw Data'!G16),'Raw Data'!G16=ROUND('Raw Data'!G16,4),IFERROR(ROUND('Raw Data'!G16,4)<=99999999999.99,FALSE))=TRUE,"",_xlfn.REGEXEXTRACT(CELL("address",'Raw Data'!G16), "\$([A-Z]+)\$[0-9]+"))),_xlfn.REGEXEXTRACT(CELL("address",'Raw Data'!G16), "\$([A-Z]+)\$[0-9]+"))} | H16: {=IFERROR(IF(OR('Raw Data'!H16="",LEN(TRIM('Raw Data'!H16))=0),"",IF(AND(ISNUMBER('Raw Data'!H16),'Raw Data'!H16=ROUND('Raw Data'!H16,4),IFERROR(ROUND('Raw Data'!H16,4)<=99999999999.99,FALSE))=TRUE,"",_xlfn.REGEXEXTRACT(CELL("address",'Raw Data'!H16), "\$([A-Z]+)\$[0-9]+"))),_xlfn.REGEXEXTRACT(CELL("address",'Raw Data'!H16), "\$([A-Z]+)\$[0-9]+"))} | I16: {=IFERROR(IF(OR('Raw Data'!I16="",LEN(TRIM('Raw Data'!I16))=0),"",IF(AND(ISNUMBER('Raw Data'!I16),'Raw Data'!I16=ROUND('Raw Data'!I16,4),IFERROR(ROUND('Raw Data'!I16,4)<=99999999999.99,FALSE))=TRUE,"",_xlfn.REGEXEXTRACT(CELL("address",'Raw Data'!I16), "\$([A-Z]+)\$[0-9]+"))),_xlfn.REGEXEXTRACT(CELL("address",'Raw Data'!I16), "\$([A-Z]+)\$[0-9]+"))} | J16: {=IFERROR(IF(OR('Raw Data'!J16="",LEN(TRIM('Raw Data'!J16))=0),"",IF(AND(ISNUMBER('Raw Data'!J16),'Raw Data'!J16=ROUND('Raw Data'!J16,4),IFERROR(ROUND('Raw Data'!J16,4)<=99999999999.99,FALSE))=TRUE,"",_xlfn.REGEXEXTRACT(CELL("address",'Raw Data'!J16), "\$([A-Z]+)\$[0-9]+"))),_xlfn.REGEXEXTRACT(CELL("address",'Raw Data'!J16), "\$([A-Z]+)\$[0-9]+"))}
B17: {=IFERROR(IF(OR('Raw Data'!B17="",LEN(TRIM('Raw Data'!B17))=0),"",IF(AND(LEN('Raw Data'!B17) <= 255,LEN('Raw Data'!B17)> 0),"",_xlfn.REGEXEXTRACT(CELL("address",'Raw Data'!B17),"\$([A-Z]+)\$[0-9]+"))),_xlfn.REGEXEXTRACT(CELL("address",'Raw Data'!B17),"\$([A-Z]+)\$[0-9]+"))} | C17: {=IFERROR(IF(OR('Raw Data'!C17="",LEN(TRIM('Raw Data'!C17))=0),"",IF(AND(LEN('Raw Data'!C17) <= 20,LEN('Raw Data'!C17)> 0),"",_xlfn.REGEXEXTRACT(CELL("address",'Raw Data'!C17),"\$([A-Z]+)\$[0-9]+"))),_xlfn.REGEXEXTRACT(CELL("address",'Raw Data'!C17),"\$([A-Z]+)\$[0-9]+"))} | D17: {=IFERROR(IF(OR('Raw Data'!D17="",LEN(TRIM('Raw Data'!D17))=0),"",IF(AND(ISNUMBER('Raw Data'!D17),'Raw Data'!D17>=Configuration!$D$2),"",_xlfn.REGEXEXTRACT(CELL("address",'Raw Data'!D17),"\$([A-Z]+)\$[0-9]+"))),_xlfn.REGEXEXTRACT(CELL("address",D17), "\$([A-Z]+)\$[0-9]+"))} | E17: {=IFERROR(IF(OR('Raw Data'!E17="",LEN(TRIM('Raw Data'!E17))=0),"",IF(AND(ISNUMBER('Raw Data'!E17),'Raw Data'!E17=ROUND('Raw Data'!E17,4),IFERROR(ROUND('Raw Data'!E17,4)<=99999999999.99,FALSE))=TRUE,"",_xlfn.REGEXEXTRACT(CELL("address",'Raw Data'!E17), "\$([A-Z]+)\$[0-9]+"))),_xlfn.REGEXEXTRACT(CELL("address",'Raw Data'!E17), "\$([A-Z]+)\$[0-9]+"))} | F17: {=IFERROR(IF(OR('Raw Data'!F17="",LEN(TRIM('Raw Data'!F17))=0),"",IF(AND(ISNUMBER('Raw Data'!F17),'Raw Data'!F17=ROUND('Raw Data'!F17,4),IFERROR(ROUND('Raw Data'!F17,4)<=99999999999.99,FALSE))=TRUE,"",_xlfn.REGEXEXTRACT(CELL("address",'Raw Data'!F17), "\$([A-Z]+)\$[0-9]+"))),_xlfn.REGEXEXTRACT(CELL("address",'Raw Data'!F17), "\$([A-Z]+)\$[0-9]+"))} | G17: {=IFERROR(IF(OR('Raw Data'!G17="",LEN(TRIM('Raw Data'!G17))=0),"",IF(AND(ISNUMBER('Raw Data'!G17),'Raw Data'!G17=ROUND('Raw Data'!G17,4),IFERROR(ROUND('Raw Data'!G17,4)<=99999999999.99,FALSE))=TRUE,"",_xlfn.REGEXEXTRACT(CELL("address",'Raw Data'!G17), "\$([A-Z]+)\$[0-9]+"))),_xlfn.REGEXEXTRACT(CELL("address",'Raw Data'!G17), "\$([A-Z]+)\$[0-9]+"))} | H17: {=IFERROR(IF(OR('Raw Data'!H17="",LEN(TRIM('Raw Data'!H17))=0),"",IF(AND(ISNUMBER('Raw Data'!H17),'Raw Data'!H17=ROUND('Raw Data'!H17,4),IFERROR(ROUND('Raw Data'!H17,4)<=99999999999.99,FALSE))=TRUE,"",_xlfn.REGEXEXTRACT(CELL("address",'Raw Data'!H17), "\$([A-Z]+)\$[0-9]+"))),_xlfn.REGEXEXTRACT(CELL("address",'Raw Data'!H17), "\$([A-Z]+)\$[0-9]+"))} | I17: {=IFERROR(IF(OR('Raw Data'!I17="",LEN(TRIM('Raw Data'!I17))=0),"",IF(AND(ISNUMBER('Raw Data'!I17),'Raw Data'!I17=ROUND('Raw Data'!I17,4),IFERROR(ROUND('Raw Data'!I17,4)<=99999999999.99,FALSE))=TRUE,"",_xlfn.REGEXEXTRACT(CELL("address",'Raw Data'!I17), "\$([A-Z]+)\$[0-9]+"))),_xlfn.REGEXEXTRACT(CELL("address",'Raw Data'!I17), "\$([A-Z]+)\$[0-9]+"))} | J17: {=IFERROR(IF(OR('Raw Data'!J17="",LEN(TRIM('Raw Data'!J17))=0),"",IF(AND(ISNUMBER('Raw Data'!J17),'Raw Data'!J17=ROUND('Raw Data'!J17,4),IFERROR(ROUND('Raw Data'!J17,4)<=99999999999.99,FALSE))=TRUE,"",_xlfn.REGEXEXTRACT(CELL("address",'Raw Data'!J17), "\$([A-Z]+)\$[0-9]+"))),_xlfn.REGEXEXTRACT(CELL("address",'Raw Data'!J17), "\$([A-Z]+)\$[0-9]+"))}
B18: {=IFERROR(IF(OR('Raw Data'!B18="",LEN(TRIM('Raw Data'!B18))=0),"",IF(AND(LEN('Raw Data'!B18) <= 255,LEN('Raw Data'!B18)> 0),"",_xlfn.REGEXEXTRACT(CELL("address",'Raw Data'!B18),"\$([A-Z]+)\$[0-9]+"))),_xlfn.REGEXEXTRACT(CELL("address",'Raw Data'!B18),"\$([A-Z]+)\$[0-9]+"))} | C18: {=IFERROR(IF(OR('Raw Data'!C18="",LEN(TRIM('Raw Data'!C18))=0),"",IF(AND(LEN('Raw Data'!C18) <= 20,LEN('Raw Data'!C18)> 0),"",_xlfn.REGEXEXTRACT(CELL("address",'Raw Data'!C18),"\$([A-Z]+)\$[0-9]+"))),_xlfn.REGEXEXTRACT(CELL("address",'Raw Data'!C18),"\$([A-Z]+)\$[0-9]+"))} | D18: {=IFERROR(IF(OR('Raw Data'!D18="",LEN(TRIM('Raw Data'!D18))=0),"",IF(AND(ISNUMBER('Raw Data'!D18),'Raw Data'!D18>=Configuration!$D$2),"",_xlfn.REGEXEXTRACT(CELL("address",'Raw Data'!D18),"\$([A-Z]+)\$[0-9]+"))),_xlfn.REGEXEXTRACT(CELL("address",D18), "\$([A-Z]+)\$[0-9]+"))} | E18: {=IFERROR(IF(OR('Raw Data'!E18="",LEN(TRIM('Raw Data'!E18))=0),"",IF(AND(ISNUMBER('Raw Data'!E18),'Raw Data'!E18=ROUND('Raw Data'!E18,4),IFERROR(ROUND('Raw Data'!E18,4)<=99999999999.99,FALSE))=TRUE,"",_xlfn.REGEXEXTRACT(CELL("address",'Raw Data'!E18), "\$([A-Z]+)\$[0-9]+"))),_xlfn.REGEXEXTRACT(CELL("address",'Raw Data'!E18), "\$([A-Z]+)\$[0-9]+"))} | F18: {=IFERROR(IF(OR('Raw Data'!F18="",LEN(TRIM('Raw Data'!F18))=0),"",IF(AND(ISNUMBER('Raw Data'!F18),'Raw Data'!F18=ROUND('Raw Data'!F18,4),IFERROR(ROUND('Raw Data'!F18,4)<=99999999999.99,FALSE))=TRUE,"",_xlfn.REGEXEXTRACT(CELL("address",'Raw Data'!F18), "\$([A-Z]+)\$[0-9]+"))),_xlfn.REGEXEXTRACT(CELL("address",'Raw Data'!F18), "\$([A-Z]+)\$[0-9]+"))} | G18: {=IFERROR(IF(OR('Raw Data'!G18="",LEN(TRIM('Raw Data'!G18))=0),"",IF(AND(ISNUMBER('Raw Data'!G18),'Raw Data'!G18=ROUND('Raw Data'!G18,4),IFERROR(ROUND('Raw Data'!G18,4)<=99999999999.99,FALSE))=TRUE,"",_xlfn.REGEXEXTRACT(CELL("address",'Raw Data'!G18), "\$([A-Z]+)\$[0-9]+"))),_xlfn.REGEXEXTRACT(CELL("address",'Raw Data'!G18), "\$([A-Z]+)\$[0-9]+"))} | H18: {=IFERROR(IF(OR('Raw Data'!H18="",LEN(TRIM('Raw Data'!H18))=0),"",IF(AND(ISNUMBER('Raw Data'!H18),'Raw Data'!H18=ROUND('Raw Data'!H18,4),IFERROR(ROUND('Raw Data'!H18,4)<=99999999999.99,FALSE))=TRUE,"",_xlfn.REGEXEXTRACT(CELL("address",'Raw Data'!H18), "\$([A-Z]+)\$[0-9]+"))),_xlfn.REGEXEXTRACT(CELL("address",'Raw Data'!H18), "\$([A-Z]+)\$[0-9]+"))} | I18: {=IFERROR(IF(OR('Raw Data'!I18="",LEN(TRIM('Raw Data'!I18))=0),"",IF(AND(ISNUMBER('Raw Data'!I18),'Raw Data'!I18=ROUND('Raw Data'!I18,4),IFERROR(ROUND('Raw Data'!I18,4)<=99999999999.99,FALSE))=TRUE,"",_xlfn.REGEXEXTRACT(CELL("address",'Raw Data'!I18), "\$([A-Z]+)\$[0-9]+"))),_xlfn.REGEXEXTRACT(CELL("address",'Raw Data'!I18), "\$([A-Z]+)\$[0-9]+"))} | J18: {=IFERROR(IF(OR('Raw Data'!J18="",LEN(TRIM('Raw Data'!J18))=0),"",IF(AND(ISNUMBER('Raw Data'!J18),'Raw Data'!J18=ROUND('Raw Data'!J18,4),IFERROR(ROUND('Raw Data'!J18,4)<=99999999999.99,FALSE))=TRUE,"",_xlfn.REGEXEXTRACT(CELL("address",'Raw Data'!J18), "\$([A-Z]+)\$[0-9]+"))),_xlfn.REGEXEXTRACT(CELL("address",'Raw Data'!J18), "\$([A-Z]+)\$[0-9]+"))}
B19: {=IFERROR(IF(OR('Raw Data'!B19="",LEN(TRIM('Raw Data'!B19))=0),"",IF(AND(LEN('Raw Data'!B19) <= 255,LEN('Raw Data'!B19)> 0),"",_xlfn.REGEXEXTRACT(CELL("address",'Raw Data'!B19),"\$([A-Z]+)\$[0-9]+"))),_xlfn.REGEXEXTRACT(CELL("address",'Raw Data'!B19),"\$([A-Z]+)\$[0-9]+"))} | C19: {=IFERROR(IF(OR('Raw Data'!C19="",LEN(TRIM('Raw Data'!C19))=0),"",IF(AND(LEN('Raw Data'!C19) <= 20,LEN('Raw Data'!C19)> 0),"",_xlfn.REGEXEXTRACT(CELL("address",'Raw Data'!C19),"\$([A-Z]+)\$[0-9]+"))),_xlfn.REGEXEXTRACT(CELL("address",'Raw Data'!C19),"\$([A-Z]+)\$[0-9]+"))} | D19: {=IFERROR(IF(OR('Raw Data'!D19="",LEN(TRIM('Raw Data'!D19))=0),"",IF(AND(ISNUMBER('Raw Data'!D19),'Raw Data'!D19>=Configuration!$D$2),"",_xlfn.REGEXEXTRACT(CELL("address",'Raw Data'!D19),"\$([A-Z]+)\$[0-9]+"))),_xlfn.REGEXEXTRACT(CELL("address",D19), "\$([A-Z]+)\$[0-9]+"))} | E19: {=IFERROR(IF(OR('Raw Data'!E19="",LEN(TRIM('Raw Data'!E19))=0),"",IF(AND(ISNUMBER('Raw Data'!E19),'Raw Data'!E19=ROUND('Raw Data'!E19,4),IFERROR(ROUND('Raw Data'!E19,4)<=99999999999.99,FALSE))=TRUE,"",_xlfn.REGEXEXTRACT(CELL("address",'Raw Data'!E19), "\$([A-Z]+)\$[0-9]+"))),_xlfn.REGEXEXTRACT(CELL("address",'Raw Data'!E19), "\$([A-Z]+)\$[0-9]+"))} | F19: {=IFERROR(IF(OR('Raw Data'!F19="",LEN(TRIM('Raw Data'!F19))=0),"",IF(AND(ISNUMBER('Raw Data'!F19),'Raw Data'!F19=ROUND('Raw Data'!F19,4),IFERROR(ROUND('Raw Data'!F19,4)<=99999999999.99,FALSE))=TRUE,"",_xlfn.REGEXEXTRACT(CELL("address",'Raw Data'!F19), "\$([A-Z]+)\$[0-9]+"))),_xlfn.REGEXEXTRACT(CELL("address",'Raw Data'!F19), "\$([A-Z]+)\$[0-9]+"))} | G19: {=IFERROR(IF(OR('Raw Data'!G19="",LEN(TRIM('Raw Data'!G19))=0),"",IF(AND(ISNUMBER('Raw Data'!G19),'Raw Data'!G19=ROUND('Raw Data'!G19,4),IFERROR(ROUND('Raw Data'!G19,4)<=99999999999.99,FALSE))=TRUE,"",_xlfn.REGEXEXTRACT(CELL("address",'Raw Data'!G19), "\$([A-Z]+)\$[0-9]+"))),_xlfn.REGEXEXTRACT(CELL("address",'Raw Data'!G19), "\$([A-Z]+)\$[0-9]+"))} | H19: {=IFERROR(IF(OR('Raw Data'!H19="",LEN(TRIM('Raw Data'!H19))=0),"",IF(AND(ISNUMBER('Raw Data'!H19),'Raw Data'!H19=ROUND('Raw Data'!H19,4),IFERROR(ROUND('Raw Data'!H19,4)<=99999999999.99,FALSE))=TRUE,"",_xlfn.REGEXEXTRACT(CELL("address",'Raw Data'!H19), "\$([A-Z]+)\$[0-9]+"))),_xlfn.REGEXEXTRACT(CELL("address",'Raw Data'!H19), "\$([A-Z]+)\$[0-9]+"))} | I19: {=IFERROR(IF(OR('Raw Data'!I19="",LEN(TRIM('Raw Data'!I19))=0),"",IF(AND(ISNUMBER('Raw Data'!I19),'Raw Data'!I19=ROUND('Raw Data'!I19,4),IFERROR(ROUND('Raw Data'!I19,4)<=99999999999.99,FALSE))=TRUE,"",_xlfn.REGEXEXTRACT(CELL("address",'Raw Data'!I19), "\$([A-Z]+)\$[0-9]+"))),_xlfn.REGEXEXTRACT(CELL("address",'Raw Data'!I19), "\$([A-Z]+)\$[0-9]+"))} | J19: {=IFERROR(IF(OR('Raw Data'!J19="",LEN(TRIM('Raw Data'!J19))=0),"",IF(AND(ISNUMBER('Raw Data'!J19),'Raw Data'!J19=ROUND('Raw Data'!J19,4),IFERROR(ROUND('Raw Data'!J19,4)<=99999999999.99,FALSE))=TRUE,"",_xlfn.REGEXEXTRACT(CELL("address",'Raw Data'!J19), "\$([A-Z]+)\$[0-9]+"))),_xlfn.REGEXEXTRACT(CELL("address",'Raw Data'!J19), "\$([A-Z]+)\$[0-9]+"))}
B20: {=IFERROR(IF(OR('Raw Data'!B20="",LEN(TRIM('Raw Data'!B20))=0),"",IF(AND(LEN('Raw Data'!B20) <= 255,LEN('Raw Data'!B20)> 0),"",_xlfn.REGEXEXTRACT(CELL("address",'Raw Data'!B20),"\$([A-Z]+)\$[0-9]+"))),_xlfn.REGEXEXTRACT(CELL("address",'Raw Data'!B20),"\$([A-Z]+)\$[0-9]+"))} | C20: {=IFERROR(IF(OR('Raw Data'!C20="",LEN(TRIM('Raw Data'!C20))=0),"",IF(AND(LEN('Raw Data'!C20) <= 20,LEN('Raw Data'!C20)> 0),"",_xlfn.REGEXEXTRACT(CELL("address",'Raw Data'!C20),"\$([A-Z]+)\$[0-9]+"))),_xlfn.REGEXEXTRACT(CELL("address",'Raw Data'!C20),"\$([A-Z]+)\$[0-9]+"))} | D20: {=IFERROR(IF(OR('Raw Data'!D20="",LEN(TRIM('Raw Data'!D20))=0),"",IF(AND(ISNUMBER('Raw Data'!D20),'Raw Data'!D20>=Configuration!$D$2),"",_xlfn.REGEXEXTRACT(CELL("address",'Raw Data'!D20),"\$([A-Z]+)\$[0-9]+"))),_xlfn.REGEXEXTRACT(CELL("address",D20), "\$([A-Z]+)\$[0-9]+"))} | E20: {=IFERROR(IF(OR('Raw Data'!E20="",LEN(TRIM('Raw Data'!E20))=0),"",IF(AND(ISNUMBER('Raw Data'!E20),'Raw Data'!E20=ROUND('Raw Data'!E20,4),IFERROR(ROUND('Raw Data'!E20,4)<=99999999999.99,FALSE))=TRUE,"",_xlfn.REGEXEXTRACT(CELL("address",'Raw Data'!E20), "\$([A-Z]+)\$[0-9]+"))),_xlfn.REGEXEXTRACT(CELL("address",'Raw Data'!E20), "\$([A-Z]+)\$[0-9]+"))} | F20: {=IFERROR(IF(OR('Raw Data'!F20="",LEN(TRIM('Raw Data'!F20))=0),"",IF(AND(ISNUMBER('Raw Data'!F20),'Raw Data'!F20=ROUND('Raw Data'!F20,4),IFERROR(ROUND('Raw Data'!F20,4)<=99999999999.99,FALSE))=TRUE,"",_xlfn.REGEXEXTRACT(CELL("address",'Raw Data'!F20), "\$([A-Z]+)\$[0-9]+"))),_xlfn.REGEXEXTRACT(CELL("address",'Raw Data'!F20), "\$([A-Z]+)\$[0-9]+"))} | G20: {=IFERROR(IF(OR('Raw Data'!G20="",LEN(TRIM('Raw Data'!G20))=0),"",IF(AND(ISNUMBER('Raw Data'!G20),'Raw Data'!G20=ROUND('Raw Data'!G20,4),IFERROR(ROUND('Raw Data'!G20,4)<=99999999999.99,FALSE))=TRUE,"",_xlfn.REGEXEXTRACT(CELL("address",'Raw Data'!G20), "\$([A-Z]+)\$[0-9]+"))),_xlfn.REGEXEXTRACT(CELL("address",'Raw Data'!G20), "\$([A-Z]+)\$[0-9]+"))} | H20: {=IFERROR(IF(OR('Raw Data'!H20="",LEN(TRIM('Raw Data'!H20))=0),"",IF(AND(ISNUMBER('Raw Data'!H20),'Raw Data'!H20=ROUND('Raw Data'!H20,4),IFERROR(ROUND('Raw Data'!H20,4)<=99999999999.99,FALSE))=TRUE,"",_xlfn.REGEXEXTRACT(CELL("address",'Raw Data'!H20), "\$([A-Z]+)\$[0-9]+"))),_xlfn.REGEXEXTRACT(CELL("address",'Raw Data'!H20), "\$([A-Z]+)\$[0-9]+"))} | I20: {=IFERROR(IF(OR('Raw Data'!I20="",LEN(TRIM('Raw Data'!I20))=0),"",IF(AND(ISNUMBER('Raw Data'!I20),'Raw Data'!I20=ROUND('Raw Data'!I20,4),IFERROR(ROUND('Raw Data'!I20,4)<=99999999999.99,FALSE))=TRUE,"",_xlfn.REGEXEXTRACT(CELL("address",'Raw Data'!I20), "\$([A-Z]+)\$[0-9]+"))),_xlfn.REGEXEXTRACT(CELL("address",'Raw Data'!I20), "\$([A-Z]+)\$[0-9]+"))} | J20: {=IFERROR(IF(OR('Raw Data'!J20="",LEN(TRIM('Raw Data'!J20))=0),"",IF(AND(ISNUMBER('Raw Data'!J20),'Raw Data'!J20=ROUND('Raw Data'!J20,4),IFERROR(ROUND('Raw Data'!J20,4)<=99999999999.99,FALSE))=TRUE,"",_xlfn.REGEXEXTRACT(CELL("address",'Raw Data'!J20), "\$([A-Z]+)\$[0-9]+"))),_xlfn.REGEXEXTRACT(CELL("address",'Raw Data'!J20), "\$([A-Z]+)\$[0-9]+"))}
B21: {=IFERROR(IF(OR('Raw Data'!B21="",LEN(TRIM('Raw Data'!B21))=0),"",IF(AND(LEN('Raw Data'!B21) <= 255,LEN('Raw Data'!B21)> 0),"",_xlfn.REGEXEXTRACT(CELL("address",'Raw Data'!B21),"\$([A-Z]+)\$[0-9]+"))),_xlfn.REGEXEXTRACT(CELL("address",'Raw Data'!B21),"\$([A-Z]+)\$[0-9]+"))} | C21: {=IFERROR(IF(OR('Raw Data'!C21="",LEN(TRIM('Raw Data'!C21))=0),"",IF(AND(LEN('Raw Data'!C21) <= 20,LEN('Raw Data'!C21)> 0),"",_xlfn.REGEXEXTRACT(CELL("address",'Raw Data'!C21),"\$([A-Z]+)\$[0-9]+"))),_xlfn.REGEXEXTRACT(CELL("address",'Raw Data'!C21),"\$([A-Z]+)\$[0-9]+"))} | D21: {=IFERROR(IF(OR('Raw Data'!D21="",LEN(TRIM('Raw Data'!D21))=0),"",IF(AND(ISNUMBER('Raw Data'!D21),'Raw Data'!D21>=Configuration!$D$2),"",_xlfn.REGEXEXTRACT(CELL("address",'Raw Data'!D21),"\$([A-Z]+)\$[0-9]+"))),_xlfn.REGEXEXTRACT(CELL("address",D21), "\$([A-Z]+)\$[0-9]+"))} | E21: {=IFERROR(IF(OR('Raw Data'!E21="",LEN(TRIM('Raw Data'!E21))=0),"",IF(AND(ISNUMBER('Raw Data'!E21),'Raw Data'!E21=ROUND('Raw Data'!E21,4),IFERROR(ROUND('Raw Data'!E21,4)<=99999999999.99,FALSE))=TRUE,"",_xlfn.REGEXEXTRACT(CELL("address",'Raw Data'!E21), "\$([A-Z]+)\$[0-9]+"))),_xlfn.REGEXEXTRACT(CELL("address",'Raw Data'!E21), "\$([A-Z]+)\$[0-9]+"))} | F21: {=IFERROR(IF(OR('Raw Data'!F21="",LEN(TRIM('Raw Data'!F21))=0),"",IF(AND(ISNUMBER('Raw Data'!F21),'Raw Data'!F21=ROUND('Raw Data'!F21,4),IFERROR(ROUND('Raw Data'!F21,4)<=99999999999.99,FALSE))=TRUE,"",_xlfn.REGEXEXTRACT(CELL("address",'Raw Data'!F21), "\$([A-Z]+)\$[0-9]+"))),_xlfn.REGEXEXTRACT(CELL("address",'Raw Data'!F21), "\$([A-Z]+)\$[0-9]+"))} | G21: {=IFERROR(IF(OR('Raw Data'!G21="",LEN(TRIM('Raw Data'!G21))=0),"",IF(AND(ISNUMBER('Raw Data'!G21),'Raw Data'!G21=ROUND('Raw Data'!G21,4),IFERROR(ROUND('Raw Data'!G21,4)<=99999999999.99,FALSE))=TRUE,"",_xlfn.REGEXEXTRACT(CELL("address",'Raw Data'!G21), "\$([A-Z]+)\$[0-9]+"))),_xlfn.REGEXEXTRACT(CELL("address",'Raw Data'!G21), "\$([A-Z]+)\$[0-9]+"))} | H21: {=IFERROR(IF(OR('Raw Data'!H21="",LEN(TRIM('Raw Data'!H21))=0),"",IF(AND(ISNUMBER('Raw Data'!H21),'Raw Data'!H21=ROUND('Raw Data'!H21,4),IFERROR(ROUND('Raw Data'!H21,4)<=99999999999.99,FALSE))=TRUE,"",_xlfn.REGEXEXTRACT(CELL("address",'Raw Data'!H21), "\$([A-Z]+)\$[0-9]+"))),_xlfn.REGEXEXTRACT(CELL("address",'Raw Data'!H21), "\$([A-Z]+)\$[0-9]+"))} | I21: {=IFERROR(IF(OR('Raw Data'!I21="",LEN(TRIM('Raw Data'!I21))=0),"",IF(AND(ISNUMBER('Raw Data'!I21),'Raw Data'!I21=ROUND('Raw Data'!I21,4),IFERROR(ROUND('Raw Data'!I21,4)<=99999999999.99,FALSE))=TRUE,"",_xlfn.REGEXEXTRACT(CELL("address",'Raw Data'!I21), "\$([A-Z]+)\$[0-9]+"))),_xlfn.REGEXEXTRACT(CELL("address",'Raw Data'!I21), "\$([A-Z]+)\$[0-9]+"))} | J21: {=IFERROR(IF(OR('Raw Data'!J21="",LEN(TRIM('Raw Data'!J21))=0),"",IF(AND(ISNUMBER('Raw Data'!J21),'Raw Data'!J21=ROUND('Raw Data'!J21,4),IFERROR(ROUND('Raw Data'!J21,4)<=99999999999.99,FALSE))=TRUE,"",_xlfn.REGEXEXTRACT(CELL("address",'Raw Data'!J21), "\$([A-Z]+)\$[0-9]+"))),_xlfn.REGEXEXTRACT(CELL("address",'Raw Data'!J21), "\$([A-Z]+)\$[0-9]+"))}
... B249: {=IFERROR(IF(OR('Raw Data'!B249="",LEN(TRIM('Raw Data'!B249))=0),"",IF(AND(LEN('Raw Data'!B249) <= 255,LEN('Raw Data'!B249)> 0),"",_xlfn.REGEXEXTRACT(CELL("address",'Raw Data'!B249),"\$([A-Z]+)\$[0-9]+"))),_xlfn.REGEXEXTRACT(CELL("address",'Raw Data'!B249),"\$([A-Z]+)\$[0-9]+"))} | C249: {=IFERROR(IF(OR('Raw Data'!C249="",LEN(TRIM('Raw Data'!C249))=0),"",IF(AND(LEN('Raw Data'!C249) <= 20,LEN('Raw Data'!C249)> 0),"",_xlfn.REGEXEXTRACT(CELL("address",'Raw Data'!C249),"\$([A-Z]+)\$[0-9]+"))),_xlfn.REGEXEXTRACT(CELL("address",'Raw Data'!C249),"\$([A-Z]+)\$[0-9]+"))} | D249: {=IFERROR(IF(OR('Raw Data'!D249="",LEN(TRIM('Raw Data'!D249))=0),"",IF(AND(ISNUMBER('Raw Data'!D249),'Raw Data'!D249>=Configuration!$D$2),"",_xlfn.REGEXEXTRACT(CELL("address",'Raw Data'!D249),"\$([A-Z]+)\$[0-9]+"))),_xlfn.REGEXEXTRACT(CELL("address",D249), "\$([A-Z]+)\$[0-9]+"))} | E249: {=IFERROR(IF(OR('Raw Data'!E249="",LEN(TRIM('Raw Data'!E249))=0),"",IF(AND(ISNUMBER('Raw Data'!E249),'Raw Data'!E249=ROUND('Raw Data'!E249,4),IFERROR(ROUND('Raw Data'!E249,4)<=99999999999.99,FALSE))=TRUE,"",_xlfn.REGEXEXTRACT(CELL("address",'Raw Data'!E249), "\$([A-Z]+)\$[0-9]+"))),_xlfn.REGEXEXTRACT(CELL("address",'Raw Data'!E249), "\$([A-Z]+)\$[0-9]+"))} | F249: {=IFERROR(IF(OR('Raw Data'!F249="",LEN(TRIM('Raw Data'!F249))=0),"",IF(AND(ISNUMBER('Raw Data'!F249),'Raw Data'!F249=ROUND('Raw Data'!F249,4),IFERROR(ROUND('Raw Data'!F249,4)<=99999999999.99,FALSE))=TRUE,"",_xlfn.REGEXEXTRACT(CELL("address",'Raw Data'!F249), "\$([A-Z]+)\$[0-9]+"))),_xlfn.REGEXEXTRACT(CELL("address",'Raw Data'!F249), "\$([A-Z]+)\$[0-9]+"))} | G249: {=IFERROR(IF(OR('Raw Data'!G249="",LEN(TRIM('Raw Data'!G249))=0),"",IF(AND(ISNUMBER('Raw Data'!G249),'Raw Data'!G249=ROUND('Raw Data'!G249,4),IFERROR(ROUND('Raw Data'!G249,4)<=99999999999.99,FALSE))=TRUE,"",_xlfn.REGEXEXTRACT(CELL("address",'Raw Data'!G249), "\$([A-Z]+)\$[0-9]+"))),_xlfn.REGEXEXTRACT(CELL("address",'Raw Data'!G249), "\$([A-Z]+)\$[0-9]+"))} | H249: {=IFERROR(IF(OR('Raw Data'!H249="",LEN(TRIM('Raw Data'!H249))=0),"",IF(AND(ISNUMBER('Raw Data'!H249),'Raw Data'!H249=ROUND('Raw Data'!H249,4),IFERROR(ROUND('Raw Data'!H249,4)<=99999999999.99,FALSE))=TRUE,"",_xlfn.REGEXEXTRACT(CELL("address",'Raw Data'!H249), "\$([A-Z]+)\$[0-9]+"))),_xlfn.REGEXEXTRACT(CELL("address",'Raw Data'!H249), "\$([A-Z]+)\$[0-9]+"))} | I249: {=IFERROR(IF(OR('Raw Data'!I249="",LEN(TRIM('Raw Data'!I249))=0),"",IF(AND(ISNUMBER('Raw Data'!I249),'Raw Data'!I249=ROUND('Raw Data'!I249,4),IFERROR(ROUND('Raw Data'!I249,4)<=99999999999.99,FALSE))=TRUE,"",_xlfn.REGEXEXTRACT(CELL("address",'Raw Data'!I249), "\$([A-Z]+)\$[0-9]+"))),_xlfn.REGEXEXTRACT(CELL("address",'Raw Data'!I249), "\$([A-Z]+)\$[0-9]+"))} | J249: {=IFERROR(IF(OR('Raw Data'!J249="",LEN(TRIM('Raw Data'!J249))=0),"",IF(AND(ISNUMBER('Raw Data'!J249),'Raw Data'!J249=ROUND('Raw Data'!J249,4),IFERROR(ROUND('Raw Data'!J249,4)<=99999999999.99,FALSE))=TRUE,"",_xlfn.REGEXEXTRACT(CELL("address",'Raw Data'!J249), "\$([A-Z]+)\$[0-9]+"))),_xlfn.REGEXEXTRACT(CELL("address",'Raw Data'!J249), "\$([A-Z]+)\$[0-9]+"))}

Sheet Validate_Condition
B8: Yes | C8: Yes | D8: No | E8: Yes | F8: Yes | G8: Yes | H8: Yes | I8: Yes | J8: Yes
B9: C1 | C9: C2 | D9: C3 | E9: C4 | F9: C5 | G9: C6 | H9: C7 | I9: C8 | J9: C9
B10: {=IF('Raw Data'!$B$10 = "Overall Project","",_xlfn.REGEXEXTRACT(CELL("address",'Raw Data'!B10),"\$([A-Z]+)\$[0-9]+"))} | C10: {=IF('Raw Data'!$C$10 = "Month # 1","",_xlfn.REGEXEXTRACT(CELL("address",'Raw Data'!C10),"\$([A-Z]+)\$[0-9]+"))} | E10: {=IF(AND('Raw Data'!E10>=0,'Raw Data'!E10<=1),"",_xlfn.REGEXEXTRACT(CELL("address",'Raw Data'!E10),"\$([A-Z]+)\$[0-9]+"))} | F10: {=IF(AND('Raw Data'!F10>=0,'Raw Data'!F10<=1),"",_xlfn.REGEXEXTRACT(CELL("address",'Raw Data'!F10),"\$([A-Z]+)\$[0-9]+"))} | G10: {=IF(AND('Raw Data'!G10>=0,'Raw Data'!G10<=1),"",_xlfn.REGEXEXTRACT(CELL("address",'Raw Data'!G10),"\$([A-Z]+)\$[0-9]+"))} | H10: {=IF(AND('Raw Data'!H10>=0,'Raw Data'!H10<=1),"",_xlfn.REGEXEXTRACT(CELL("address",'Raw Data'!H10),"\$([A-Z]+)\$[0-9]+"))} | I10: {=IF(AND('Raw Data'!I10>=0,'Raw Data'!I10<=1),"",_xlfn.REGEXEXTRACT(CELL("address",'Raw Data'!I10),"\$([A-Z]+)\$[0-9]+"))} | J10: {=IF(AND('Raw Data'!J10>=0,'Raw Data'!J10<=1),"",_xlfn.REGEXEXTRACT(CELL("address",'Raw Data'!J10),"\$([A-Z]+)\$[0-9]+"))}
B11: {=IF('Raw Data'!$B$10 = "Overall Project","",_xlfn.REGEXEXTRACT(CELL("address",'Raw Data'!B11),"\$([A-Z]+)\$[0-9]+"))} | C11: {=IF('Raw Data'!$C$10 = "Month # 1","",_xlfn.REGEXEXTRACT(CELL("address",'Raw Data'!C11),"\$([A-Z]+)\$[0-9]+"))} | D11: {=IFERROR(IF(OR('Raw Data'!D11="",LEN(TRIM('Raw Data'!D11))=0),"",IF(AND(ISNUMBER('Raw Data'!D11),'Raw Data'!D11>=Configuration!$D$2),"",_xlfn.REGEXEXTRACT(CELL("address",'Raw Data'!D11),"\$([A-Z]+)\$[0-9]+"))),_xlfn.REGEXEXTRACT(CELL("address",D11), "\$([A-Z]+)\$[0-9]+"))} | E11: {=IF(AND('Raw Data'!E11>=0,'Raw Data'!E11<=1),"",_xlfn.REGEXEXTRACT(CELL("address",'Raw Data'!E11),"\$([A-Z]+)\$[0-9]+"))} | F11: {=IF(AND('Raw Data'!F11>=0,'Raw Data'!F11<=1),"",_xlfn.REGEXEXTRACT(CELL("address",'Raw Data'!F11),"\$([A-Z]+)\$[0-9]+"))} | G11: {=IF(AND('Raw Data'!G11>=0,'Raw Data'!G11<=1),"",_xlfn.REGEXEXTRACT(CELL("address",'Raw Data'!G11),"\$([A-Z]+)\$[0-9]+"))} | H11: {=IF(AND('Raw Data'!H11>=0,'Raw Data'!H11<=1),"",_xlfn.REGEXEXTRACT(CELL("address",'Raw Data'!H11),"\$([A-Z]+)\$[0-9]+"))} | I11: {=IF(AND('Raw Data'!I11>=0,'Raw Data'!I11<=1),"",_xlfn.REGEXEXTRACT(CELL("address",'Raw Data'!I11),"\$([A-Z]+)\$[0-9]+"))} | J11: {=IF(AND('Raw Data'!J11>=0,'Raw Data'!J11<=1),"",_xlfn.REGEXEXTRACT(CELL("address",'Raw Data'!J11),"\$([A-Z]+)\$[0-9]+"))}
B12: {=IF('Raw Data'!$B$10 = "Overall Project","",_xlfn.REGEXEXTRACT(CELL("address",'Raw Data'!B12),"\$([A-Z]+)\$[0-9]+"))} | C12: {=IF('Raw Data'!$C$10 = "Month # 1","",_xlfn.REGEXEXTRACT(CELL("address",'Raw Data'!C12),"\$([A-Z]+)\$[0-9]+"))} | E12: {=IF(AND('Raw Data'!E12>=0,'Raw Data'!E12<=1),"",_xlfn.REGEXEXTRACT(CELL("address",'Raw Data'!E12),"\$([A-Z]+)\$[0-9]+"))} | F12: {=IF(AND('Raw Data'!F12>=0,'Raw Data'!F12<=1),"",_xlfn.REGEXEXTRACT(CELL("address",'Raw Data'!F12),"\$([A-Z]+)\$[0-9]+"))} | G12: {=IF(AND('Raw Data'!G12>=0,'Raw Data'!G12<=1),"",_xlfn.REGEXEXTRACT(CELL("address",'Raw Data'!G12),"\$([A-Z]+)\$[0-9]+"))} | H12: {=IF(AND('Raw Data'!H12>=0,'Raw Data'!H12<=1),"",_xlfn.REGEXEXTRACT(CELL("address",'Raw Data'!H12),"\$([A-Z]+)\$[0-9]+"))} | I12: {=IF(AND('Raw Data'!I12>=0,'Raw Data'!I12<=1),"",_xlfn.REGEXEXTRACT(CELL("address",'Raw Data'!I12),"\$([A-Z]+)\$[0-9]+"))} | J12: {=IF(AND('Raw Data'!J12>=0,'Raw Data'!J12<=1),"",_xlfn.REGEXEXTRACT(CELL("address",'Raw Data'!J12),"\$([A-Z]+)\$[0-9]+"))}
B13: {=IF('Raw Data'!$B$10 = "Overall Project","",_xlfn.REGEXEXTRACT(CELL("address",'Raw Data'!B13),"\$([A-Z]+)\$[0-9]+"))} | C13: {=IF('Raw Data'!$C$10 = "Month # 1","",_xlfn.REGEXEXTRACT(CELL("address",'Raw Data'!C13),"\$([A-Z]+)\$[0-9]+"))} | E13: {=IF(AND('Raw Data'!E13>=0,'Raw Data'!E13<=1),"",_xlfn.REGEXEXTRACT(CELL("address",'Raw Data'!E13),"\$([A-Z]+)\$[0-9]+"))} | F13: {=IF(AND('Raw Data'!F13>=0,'Raw Data'!F13<=1),"",_xlfn.REGEXEXTRACT(CELL("address",'Raw Data'!F13),"\$([A-Z]+)\$[0-9]+"))} | G13: {=IF(AND('Raw Data'!G13>=0,'Raw Data'!G13<=1),"",_xlfn.REGEXEXTRACT(CELL("address",'Raw Data'!G13),"\$([A-Z]+)\$[0-9]+"))} | H13: {=IF(AND('Raw Data'!H13>=0,'Raw Data'!H13<=1),"",_xlfn.REGEXEXTRACT(CELL("address",'Raw Data'!H13),"\$([A-Z]+)\$[0-9]+"))} | I13: {=IF(AND('Raw Data'!I13>=0,'Raw Data'!I13<=1),"",_xlfn.REGEXEXTRACT(CELL("address",'Raw Data'!I13),"\$([A-Z]+)\$[0-9]+"))} | J13: {=IF(AND('Raw Data'!J13>=0,'Raw Data'!J13<=1),"",_xlfn.REGEXEXTRACT(CELL("address",'Raw Data'!J13),"\$([A-Z]+)\$[0-9]+"))}
B14: {=IF('Raw Data'!$B$10 = "Overall Project","",_xlfn.REGEXEXTRACT(CELL("address",'Raw Data'!B14),"\$([A-Z]+)\$[0-9]+"))} | C14: {=IF('Raw Data'!$C$10 = "Month # 1","",_xlfn.REGEXEXTRACT(CELL("address",'Raw Data'!C14),"\$([A-Z]+)\$[0-9]+"))} | E14: {=IF(AND('Raw Data'!E14>=0,'Raw Data'!E14<=1),"",_xlfn.REGEXEXTRACT(CELL("address",'Raw Data'!E14),"\$([A-Z]+)\$[0-9]+"))} | F14: {=IF(AND('Raw Data'!F14>=0,'Raw Data'!F14<=1),"",_xlfn.REGEXEXTRACT(CELL("address",'Raw Data'!F14),"\$([A-Z]+)\$[0-9]+"))} | G14: {=IF(AND('Raw Data'!G14>=0,'Raw Data'!G14<=1),"",_xlfn.REGEXEXTRACT(CELL("address",'Raw Data'!G14),"\$([A-Z]+)\$[0-9]+"))} | H14: {=IF(AND('Raw Data'!H14>=0,'Raw Data'!H14<=1),"",_xlfn.REGEXEXTRACT(CELL("address",'Raw Data'!H14),"\$([A-Z]+)\$[0-9]+"))} | I14: {=IF(AND('Raw Data'!I14>=0,'Raw Data'!I14<=1),"",_xlfn.REGEXEXTRACT(CELL("address",'Raw Data'!I14),"\$([A-Z]+)\$[0-9]+"))} | J14: {=IF(AND('Raw Data'!J14>=0,'Raw Data'!J14<=1),"",_xlfn.REGEXEXTRACT(CELL("address",'Raw Data'!J14),"\$([A-Z]+)\$[0-9]+"))}
B15: {=IF('Raw Data'!$B$10 = "Overall Project","",_xlfn.REGEXEXTRACT(CELL("address",'Raw Data'!B15),"\$([A-Z]+)\$[0-9]+"))} | C15: {=IF('Raw Data'!$C$10 = "Month # 1","",_xlfn.REGEXEXTRACT(CELL("address",'Raw Data'!C15),"\$([A-Z]+)\$[0-9]+"))} | E15: {=IF(AND('Raw Data'!E15>=0,'Raw Data'!E15<=1),"",_xlfn.REGEXEXTRACT(CELL("address",'Raw Data'!E15),"\$([A-Z]+)\$[0-9]+"))} | F15: {=IF(AND('Raw Data'!F15>=0,'Raw Data'!F15<=1),"",_xlfn.REGEXEXTRACT(CELL("address",'Raw Data'!F15),"\$([A-Z]+)\$[0-9]+"))} | G15: {=IF(AND('Raw Data'!G15>=0,'Raw Data'!G15<=1),"",_xlfn.REGEXEXTRACT(CELL("address",'Raw Data'!G15),"\$([A-Z]+)\$[0-9]+"))} | H15: {=IF(AND('Raw Data'!H15>=0,'Raw Data'!H15<=1),"",_xlfn.REGEXEXTRACT(CELL("address",'Raw Data'!H15),"\$([A-Z]+)\$[0-9]+"))} | I15: {=IF(AND('Raw Data'!I15>=0,'Raw Data'!I15<=1),"",_xlfn.REGEXEXTRACT(CELL("address",'Raw Data'!I15),"\$([A-Z]+)\$[0-9]+"))} | J15: {=IF(AND('Raw Data'!J15>=0,'Raw Data'!J15<=1),"",_xlfn.REGEXEXTRACT(CELL("address",'Raw Data'!J15),"\$([A-Z]+)\$[0-9]+"))}
B16: {=IF('Raw Data'!$B$10 = "Overall Project","",_xlfn.REGEXEXTRACT(CELL("address",'Raw Data'!B16),"\$([A-Z]+)\$[0-9]+"))} | C16: {=IF('Raw Data'!$C$10 = "Month # 1","",_xlfn.REGEXEXTRACT(CELL("address",'Raw Data'!C16),"\$([A-Z]+)\$[0-9]+"))} | E16: {=IF(AND('Raw Data'!E16>=0,'Raw Data'!E16<=1),"",_xlfn.REGEXEXTRACT(CELL("address",'Raw Data'!E16),"\$([A-Z]+)\$[0-9]+"))} | F16: {=IF(AND('Raw Data'!F16>=0,'Raw Data'!F16<=1),"",_xlfn.REGEXEXTRACT(CELL("address",'Raw Data'!F16),"\$([A-Z]+)\$[0-9]+"))} | G16: {=IF(AND('Raw Data'!G16>=0,'Raw Data'!G16<=1),"",_xlfn.REGEXEXTRACT(CELL("address",'Raw Data'!G16),"\$([A-Z]+)\$[0-9]+"))} | H16: {=IF(AND('Raw Data'!H16>=0,'Raw Data'!H16<=1),"",_xlfn.REGEXEXTRACT(CELL("address",'Raw Data'!H16),"\$([A-Z]+)\$[0-9]+"))} | I16: {=IF(AND('Raw Data'!I16>=0,'Raw Data'!I16<=1),"",_xlfn.REGEXEXTRACT(CELL("address",'Raw Data'!I16),"\$([A-Z]+)\$[0-9]+"))} | J16: {=IF(AND('Raw Data'!J16>=0,'Raw Data'!J16<=1),"",_xlfn.REGEXEXTRACT(CELL("address",'Raw Data'!J16),"\$([A-Z]+)\$[0-9]+"))}
B17: {=IF('Raw Data'!$B$10 = "Overall Project","",_xlfn.REGEXEXTRACT(CELL("address",'Raw Data'!B17),"\$([A-Z]+)\$[0-9]+"))} | C17: {=IF('Raw Data'!$C$10 = "Month # 1","",_xlfn.REGEXEXTRACT(CELL("address",'Raw Data'!C17),"\$([A-Z]+)\$[0-9]+"))} | E17: {=IF(AND('Raw Data'!E17>=0,'Raw Data'!E17<=1),"",_xlfn.REGEXEXTRACT(CELL("address",'Raw Data'!E17),"\$([A-Z]+)\$[0-9]+"))} | F17: {=IF(AND('Raw Data'!F17>=0,'Raw Data'!F17<=1),"",_xlfn.REGEXEXTRACT(CELL("address",'Raw Data'!F17),"\$([A-Z]+)\$[0-9]+"))} | G17: {=IF(AND('Raw Data'!G17>=0,'Raw Data'!G17<=1),"",_xlfn.REGEXEXTRACT(CELL("address",'Raw Data'!G17),"\$([A-Z]+)\$[0-9]+"))} | H17: {=IF(AND('Raw Data'!H17>=0,'Raw Data'!H17<=1),"",_xlfn.REGEXEXTRACT(CELL("address",'Raw Data'!H17),"\$([A-Z]+)\$[0-9]+"))} | I17: {=IF(AND('Raw Data'!I17>=0,'Raw Data'!I17<=1),"",_xlfn.REGEXEXTRACT(CELL("address",'Raw Data'!I17),"\$([A-Z]+)\$[0-9]+"))} | J17: {=IF(AND('Raw Data'!J17>=0,'Raw Data'!J17<=1),"",_xlfn.REGEXEXTRACT(CELL("address",'Raw Data'!J17),"\$([A-Z]+)\$[0-9]+"))}
