Workbook

Sheet Raw Data
C9: C1 | D9: C2 | E9: C3 | F9: C4 | G9: C5 | H9: C6 | I9: C7 | J9: C8 | K9: C9 | L9: C10 | M9: C11 | N9: C12
C10: YYQXXX-Bidding | D10: Project Management | E10: Common of Project | F10: 703430 | G10: Insurance premium - Property (Project) | H10: Direct Cost | I10: Expense | J10: General Expense | K10: X | L10: 1 | M10: 1 | N10: 1
C11: YYQXXX-Bidding | D11: Project Management | E11: Common of Project | F11: 703852 | G11: Stamp Duty & BG | H11: Direct Cost | I11: Expense | J11: General Expense | L11: 0 | M11: 0 | N11: 0
C12: YYQXXX-Bidding | D12: Project Management | E12: Common of Project | F12: 706700-F/M&Below | G12: Unit rate allocation (Only Construction) | H12: Indirect Cost | I12: TNS Labor | J12: TNS Labor Direct | L12: 0 | M12: 0 | N12: 0
C13: YYQXXX-Bidding | D13: Project Management | E13: Common of Project | F13: 706700-S/V&Above | G13: Unit rate allocation | H13: Indirect Cost | I13: TNS Labor | J13: TNS Labor Indirect | K13: X | L13: 554935.55 | M13: 0 | N13: 0
C14: YYQXXX-Bidding | D14: Project Management | E14: Common of Project | F14: Allowance - Indirect | G14: Indirect Allowance | H14: Indirect Cost | I14: Allowance | J14: Allowance | L14: 0 | M14: 0 | N14: 0
C15: YYQXXX-Bidding | D15: Project Management | E15: Common of Project | F15: Contingency - Direct | G15: Direct Contingency | H15: Direct Cost | I15: Contingency | J15: Contingency | K15: X | L15: 1 | M15: 1 | N15: 1
C16: YYQXXX-Bidding | D16: Project Management | E16: Common of Project | F16: Contingency - Indirect | G16: Indirect Contingency | H16: Indirect Cost | I16: Contingency | J16: Contingency | L16: 0 | M16: 0 | N16: 0
C17: YYQXXX-Bidding | D17: Project Management | E17: Common of Project | F17: Cost Impact - Direct | G17: Direct Cost Impact | H17: Direct Cost | I17: Cost Impact | J17: Cost Impact | L17: 0 | M17: 0 | N17: 0
C18: YYQXXX-Bidding | D18: Project Management | E18: Common of Project | F18: Cost Impact - Indirect | G18: Indirect Cost Impact | H18: Indirect Cost | I18: Cost Impact | J18: Cost Impact | K18: X | L18: 1 | M18: 1 | N18: 1
C19: YYQXXX-Bidding | D19: Project Management | E19: Common of Project | F19: Other - Indirect | G19: Indirect Other | H19: Indirect Cost | I19: Other | J19: Other | L19: 0 | M19: 0 | N19: 0
C20: YYQCXXX | D20: Construction | E20: Common of Project | F20: 701000 | G20: Material Cost | H20: Direct Cost | I20: Materials | J20: Permanent Material | L20: 0 | M20: 0 | N20: 0
C21: YYQCXXX | D21: Construction | E21: Common of Project | F21: 701008 | G21: Procurement contingency for Materials | H21: Direct Cost | I21: Materials | J21: Permanent Material | L21: 0 | M21: 0 | N21: 0
C22: YYQCXXX | D22: Construction | E22: Common of Project | F22: 701009 | G22: Project Safety Equipment, Architectural per drawing | H22: Direct Cost | I22: Materials | J22: Permanent Material | L22: 0 | M22: 0 | N22: 0
C23: YYQCXXX | D23: Construction | E23: Load & Sail | F23: 701010 | G23: Seafastenning material, Skidding Support, Rigging P/F | H23: Direct Cost | I23: Materials | J23: Temporary Material | L23: 0 | M23: 0 | N23: 0
C24: YYQCXXX | D24: Construction | E24: Structure Steel | F24: 701011 | G24: Steel ( Not include NSC ) | H24: Direct Cost | I24: Materials | J24: Permanent Material | L24: 0 | M24: 0 | N24: 0
C25: YYQCXXX | D25: Construction | E25: Structure Steel | F25: 701012 | G25: Structure Procurement | H25: Direct Cost | I25: Materials | J25: Permanent Material | L25: 0 | M25: 0 | N25: 0
C26: YYQCXXX | D26: Construction | E26: Structure Steel | F26: 701013 | G26: Electrode for Structure | H26: Direct Cost | I26: Consumables | J26: Welding Electrode | L26: 0 | M26: 0 | N26: 0
C27: YYQCXXX | D27: Construction | E27: Blast & Paint | F27: 701014 | G27: Painting Material | H27: Direct Cost | I27: Consumables | J27: Painting Material | L27: 0 | M27: 0 | N27: 0
C28: YYQCXXX | D28: Construction | E28: Piping | F28: 701015 | G28: Piping Procurement | H28: Direct Cost | I28: Materials | J28: Permanent Material | L28: 0 | M28: 0 | N28: 0
C29: YYQCXXX | D29: Construction | E29: Electrical | F29: 701016 | G29: Electrical Procurement | H29: Direct Cost | I29: Materials | J29: Permanent Material | L29: 0 | M29: 0 | N29: 0
C30: YYQCXXX | D30: Construction | E30: Load & Sail | F30: 701017 | G30: Packing Material & Pre rigging ( Tenchnical ) | H30: Direct Cost | I30: Consumables | J30: General Consumable | L30: 0 | M30: 0 | N30: 0
C31: YYQCXXX | D31: Construction | E31: Structure Steel | F31: 701018 | G31: Other Consumable for Structure | H31: Direct Cost | I31: Consumables | J31: General Consumable | L31: 0 | M31: 0 | N31: 0
... C33: YYQCXXX | D33: Construction | E33: Instrument | F33: 701020 | G33: Instrument Procurement | H33: Direct Cost | I33: Materials | J33: Permanent Material | L33: 0 | M33: 0 | N33: 0
C34: YYQCXXX | D34: Construction | E34: Common of Project | F34: 701021 | G34: Fuel & Gasoline | H34: Direct Cost | I34: Consumables | J34: Fuel & Gasoline | K34: X | L34: 150000 | M34: 0 | N34: 0
C35: YYQCXXX | D35: Construction | E35: Common of Project | F35: 701022 | G35: Spare part | H35: Direct Cost | I35: Equipment and Tools | J35: General Tool | L35: 0 | M35: 0 | N35: 0
C36: YYQCXXX | D36: Construction | E36: Common of Project | F36: 701023 | G36: Loose tool Safety | H36: Direct Cost | I36: Consumables | J36: Safety and PPE | L36: 0 | M36: 0 | N36: 0
C37: YYQCXXX | D37: Construction | E37: Blast & Paint | F37: 701024 | G37: Grinding & Cutting for Structure | H37: Direct Cost | I37: Equipment and Tools | J37: General Tool | L37: 0 | M37: 0 | N37: 0
C38: YYQCXXX | D38: Construction | E38: Structure Steel | F38: 701025 | G38: Machining, Bending , Gavanizing, Drilling & Tap for Structure | H38: Direct Cost | I38: Service Work & Supply | J38: Machining, Bending , Gavanizing, Drilling & Tap and PWHT | L38: 0 | M38: 0 | N38: 0
C39: YYQCXXX | D39: Construction | E39: Common of Project | F39: 701026 | G39: Welding Cable and Other Accessory | H39: Direct Cost | I39: Equipment and Tools | J39: General Tool | L39: 0 | M39: 0 | N39: 0
C40: YYQCXXX | D40: Construction | E40: Load & Sail | F40: 701027 | G40: Loose tool - Technical | H40: Direct Cost | I40: Equipment and Tools | J40: General Tool | L40: 0 | M40: 0 | N40: 0
C41: YYQCXXX | D41: Construction | E41: Structure Steel | F41: 701028 | G41: Structure Consumable | H41: Direct Cost | I41: Consumables | J41: General Consumable | L41: 0 | M41: 0 | N41: 0
C42: YYQCXXX | D42: Construction | E42: Blast & Paint | F42: 701029 | G42: Other Consumable for Blast & Paint | H42: Direct Cost | I42: Consumables | J42: General Consumable | L42: 0 | M42: 0 | N42: 0
C43: YYQCXXX | D43: Construction | E43: Piping | F43: 701030 | G43: Process Testing for Process Piping & Mechanical | H43: Direct Cost | I43: Service Work & Supply | J43: General Service | L43: 0 | M43: 0 | N43: 0
C44: YYQCXXX | D44: Construction | E44: Common of Project | F44: 701031 | G44: Factory Instrument Calibration | H44: Direct Cost | I44: Equipment and Tools | J44: General Tool | L44: 0 | M44: 0 | N44: 0
C45: YYQCXXX | D45: Construction | E45: Common of Project | F45: 701032 | G45: Mechanical Procurement ( for Direct to the Project) | H45: Direct Cost | I45: Materials | J45: Permanent Material | L45: 0 | M45: 0 | N45: 0
C46: YYQCXXX | D46: Construction | E46: Common of Project | F46: 701034 | G46: Scaffolding Material & Maintenance Cost | H46: Direct Cost | I46: Equipment and Tools | J46: General Tool | L46: 0 | M46: 0 | N46: 0
... C50: YYQCXXX | D50: Construction | E50: Common of Project | F50: 701119 | G50: Final Document | H50: Direct Cost | I50: Expense | J50: General Expense | L50: 0 | M50: 0 | N50: 0
C51: YYQCXXX | D51: Construction | E51: Common of Project | F51: 701120 | G51: Third Party Inspection | H51: Direct Cost | I51: Expense | J51: General Expense | K51: X | L51: 1 | M51: 1 | N51: 1
C52: YYQCXXX | D52: Construction | E52: Common of Project | F52: 701121 | G52: Third party Expediting | H52: Direct Cost | I52: Expense | J52: General Expense | L52: 0 | M52: 0 | N52: 0
...

Sheet Validate_Empty
C8: TRUE | D8: TRUE | E8: TRUE | F8: TRUE | G8: TRUE | H8: TRUE | I8: FALSE | J8: FALSE | K8: FALSE | L8: FALSE | M8: FALSE | N8: FALSE
C9: C1 | D9: C2 | E9: C3 | F9: C4 | G9: C5 | H9: C6 | I9: C7 | J9: C8 | K9: C9 | L9: C10 | M9: C11 | N9: C12
C10: {=IFERROR(IF(OR('Raw Data'!C10="",LEN(TRIM('Raw Data'!C10))=0),_xlfn.REGEXEXTRACT(CELL("address",'Raw Data'!C10),"\$([A-Z]+)\$[0-9]+"),""),"")} | D10: {=IFERROR(IF(OR('Raw Data'!D10="",LEN(TRIM('Raw Data'!D10))=0),_xlfn.REGEXEXTRACT(CELL("address",'Raw Data'!D10),"\$([A-Z]+)\$[0-9]+"),""),"")} | E10: {=IFERROR(IF(OR('Raw Data'!E10="",LEN(TRIM('Raw Data'!E10))=0),_xlfn.REGEXEXTRACT(CELL("address",'Raw Data'!E10),"\$([A-Z]+)\$[0-9]+"),""),"")} | F10: {=IFERROR(IF(OR('Raw Data'!F10="",LEN(TRIM('Raw Data'!F10))=0),_xlfn.REGEXEXTRACT(CELL("address",'Raw Data'!F10),"\$([A-Z]+)\$[0-9]+"),""),"")} | G10: {=IFERROR(IF(OR('Raw Data'!G10="",LEN(TRIM('Raw Data'!G10))=0),_xlfn.REGEXEXTRACT(CELL("address",'Raw Data'!G10),"\$([A-Z]+)\$[0-9]+"),""),"")} | H10: {=IFERROR(IF(OR('Raw Data'!H10="",LEN(TRIM('Raw Data'!H10))=0),_xlfn.REGEXEXTRACT(CELL("address",'Raw Data'!H10),"\$([A-Z]+)\$[0-9]+"),""),"")}
C11: {=IFERROR(IF(OR('Raw Data'!C11="",LEN(TRIM('Raw Data'!C11))=0),_xlfn.REGEXEXTRACT(CELL("address",'Raw Data'!C11),"\$([A-Z]+)\$[0-9]+"),""),"")} | D11: {=IFERROR(IF(OR('Raw Data'!D11="",LEN(TRIM('Raw Data'!D11))=0),_xlfn.REGEXEXTRACT(CELL("address",'Raw Data'!D11),"\$([A-Z]+)\$[0-9]+"),""),"")} | E11: {=IFERROR(IF(OR('Raw Data'!E11="",LEN(TRIM('Raw Data'!E11))=0),_xlfn.REGEXEXTRACT(CELL("address",'Raw Data'!E11),"\$([A-Z]+)\$[0-9]+"),""),"")} | F11: {=IFERROR(IF(OR('Raw Data'!F11="",LEN(TRIM('Raw Data'!F11))=0),_xlfn.REGEXEXTRACT(CELL("address",'Raw Data'!F11),"\$([A-Z]+)\$[0-9]+"),""),"")} | G11: {=IFERROR(IF(OR('Raw Data'!G11="",LEN(TRIM('Raw Data'!G11))=0),_xlfn.REGEXEXTRACT(CELL("address",'Raw Data'!G11),"\$([A-Z]+)\$[0-9]+"),""),"")} | H11: {=IFERROR(IF(OR('Raw Data'!H11="",LEN(TRIM('Raw Data'!H11))=0),_xlfn.REGEXEXTRACT(CELL("address",'Raw Data'!H11),"\$([A-Z]+)\$[0-9]+"),""),"")}
C12: {=IFERROR(IF(OR('Raw Data'!C12="",LEN(TRIM('Raw Data'!C12))=0),_xlfn.REGEXEXTRACT(CELL("address",'Raw Data'!C12),"\$([A-Z]+)\$[0-9]+"),""),"")} | D12: {=IFERROR(IF(OR('Raw Data'!D12="",LEN(TRIM('Raw Data'!D12))=0),_xlfn.REGEXEXTRACT(CELL("address",'Raw Data'!D12),"\$([A-Z]+)\$[0-9]+"),""),"")} | E12: {=IFERROR(IF(OR('Raw Data'!E12="",LEN(TRIM('Raw Data'!E12))=0),_xlfn.REGEXEXTRACT(CELL("address",'Raw Data'!E12),"\$([A-Z]+)\$[0-9]+"),""),"")} | F12: {=IFERROR(IF(OR('Raw Data'!F12="",LEN(TRIM('Raw Data'!F12))=0),_xlfn.REGEXEXTRACT(CELL("address",'Raw Data'!F12),"\$([A-Z]+)\$[0-9]+"),""),"")} | G12: {=IFERROR(IF(OR('Raw Data'!G12="",LEN(TRIM('Raw Data'!G12))=0),_xlfn.REGEXEXTRACT(CELL("address",'Raw Data'!G12),"\$([A-Z]+)\$[0-9]+"),""),"")} | H12: {=IFERROR(IF(OR('Raw Data'!H12="",LEN(TRIM('Raw Data'!H12))=0),_xlfn.REGEXEXTRACT(CELL("address",'Raw Data'!H12),"\$([A-Z]+)\$[0-9]+"),""),"")}
C13: {=IFERROR(IF(OR('Raw Data'!C13="",LEN(TRIM('Raw Data'!C13))=0),_xlfn.REGEXEXTRACT(CELL("address",'Raw Data'!C13),"\$([A-Z]+)\$[0-9]+"),""),"")} | D13: {=IFERROR(IF(OR('Raw Data'!D13="",LEN(TRIM('Raw Data'!D13))=0),_xlfn.REGEXEXTRACT(CELL("address",'Raw Data'!D13),"\$([A-Z]+)\$[0-9]+"),""),"")} | E13: {=IFERROR(IF(OR('Raw Data'!E13="",LEN(TRIM('Raw Data'!E13))=0),_xlfn.REGEXEXTRACT(CELL("address",'Raw Data'!E13),"\$([A-Z]+)\$[0-9]+"),""),"")} | F13: {=IFERROR(IF(OR('Raw Data'!F13="",LEN(TRIM('Raw Data'!F13))=0),_xlfn.REGEXEXTRACT(CELL("address",'Raw Data'!F13),"\$([A-Z]+)\$[0-9]+"),""),"")} | G13: {=IFERROR(IF(OR('Raw Data'!G13="",LEN(TRIM('Raw Data'!G13))=0),_xlfn.REGEXEXTRACT(CELL("address",'Raw Data'!G13),"\$([A-Z]+)\$[0-9]+"),""),"")} | H13: {=IFERROR(IF(OR('Raw Data'!H13="",LEN(TRIM('Raw Data'!H13))=0),_xlfn.REGEXEXTRACT(CELL("address",'Raw Data'!H13),"\$([A-Z]+)\$[0-9]+"),""),"")}
C14: {=IFERROR(IF(OR('Raw Data'!C14="",LEN(TRIM('Raw Data'!C14))=0),_xlfn.REGEXEXTRACT(CELL("address",'Raw Data'!C14),"\$([A-Z]+)\$[0-9]+"),""),"")} | D14: {=IFERROR(IF(OR('Raw Data'!D14="",LEN(TRIM('Raw Data'!D14))=0),_xlfn.REGEXEXTRACT(CELL("address",'Raw Data'!D14),"\$([A-Z]+)\$[0-9]+"),""),"")} | E14: {=IFERROR(IF(OR('Raw Data'!E14="",LEN(TRIM('Raw Data'!E14))=0),_xlfn.REGEXEXTRACT(CELL("address",'Raw Data'!E14),"\$([A-Z]+)\$[0-9]+"),""),"")} | F14: {=IFERROR(IF(OR('Raw Data'!F14="",LEN(TRIM('Raw Data'!F14))=0),_xlfn.REGEXEXTRACT(CELL("address",'Raw Data'!F14),"\$([A-Z]+)\$[0-9]+"),""),"")} | G14: {=IFERROR(IF(OR('Raw Data'!G14="",LEN(TRIM('Raw Data'!G14))=0),_xlfn.REGEXEXTRACT(CELL("address",'Raw Data'!G14),"\$([A-Z]+)\$[0-9]+"),""),"")} | H14: {=IFERROR(IF(OR('Raw Data'!H14="",LEN(TRIM('Raw Data'!H14))=0),_xlfn.REGEXEXTRACT(CELL("address",'Raw Data'!H14),"\$([A-Z]+)\$[0-9]+"),""),"")}
C15: {=IFERROR(IF(OR('Raw Data'!C15="",LEN(TRIM('Raw Data'!C15))=0),_xlfn.REGEXEXTRACT(CELL("address",'Raw Data'!C15),"\$([A-Z]+)\$[0-9]+"),""),"")} | D15: {=IFERROR(IF(OR('Raw Data'!D15="",LEN(TRIM('Raw Data'!D15))=0),_xlfn.REGEXEXTRACT(CELL("address",'Raw Data'!D15),"\$([A-Z]+)\$[0-9]+"),""),"")} | E15: {=IFERROR(IF(OR('Raw Data'!E15="",LEN(TRIM('Raw Data'!E15))=0),_xlfn.REGEXEXTRACT(CELL("address",'Raw Data'!E15),"\$([A-Z]+)\$[0-9]+"),""),"")} | F15: {=IFERROR(IF(OR('Raw Data'!F15="",LEN(TRIM('Raw Data'!F15))=0),_xlfn.REGEXEXTRACT(CELL("address",'Raw Data'!F15),"\$([A-Z]+)\$[0-9]+"),""),"")} | G15: {=IFERROR(IF(OR('Raw Data'!G15="",LEN(TRIM('Raw Data'!G15))=0),_xlfn.REGEXEXTRACT(CELL("address",'Raw Data'!G15),"\$([A-Z]+)\$[0-9]+"),""),"")} | H15: {=IFERROR(IF(OR('Raw Data'!H15="",LEN(TRIM('Raw Data'!H15))=0),_xlfn.REGEXEXTRACT(CELL("address",'Raw Data'!H15),"\$([A-Z]+)\$[0-9]+"),""),"")}
C16: {=IFERROR(IF(OR('Raw Data'!C16="",LEN(TRIM('Raw Data'!C16))=0),_xlfn.REGEXEXTRACT(CELL("address",'Raw Data'!C16),"\$([A-Z]+)\$[0-9]+"),""),"")} | D16: {=IFERROR(IF(OR('Raw Data'!D16="",LEN(TRIM('Raw Data'!D16))=0),_xlfn.REGEXEXTRACT(CELL("address",'Raw Data'!D16),"\$([A-Z]+)\$[0-9]+"),""),"")} | E16: {=IFERROR(IF(OR('Raw Data'!E16="",LEN(TRIM('Raw Data'!E16))=0),_xlfn.REGEXEXTRACT(CELL("address",'Raw Data'!E16),"\$([A-Z]+)\$[0-9]+"),""),"")} | F16: {=IFERROR(IF(OR('Raw Data'!F16="",LEN(TRIM('Raw Data'!F16))=0),_xlfn.REGEXEXTRACT(CELL("address",'Raw Data'!F16),"\$([A-Z]+)\$[0-9]+"),""),"")} | G16: {=IFERROR(IF(OR('Raw Data'!G16="",LEN(TRIM('Raw Data'!G16))=0),_xlfn.REGEXEXTRACT(CELL("address",'Raw Data'!G16),"\$([A-Z]+)\$[0-9]+"),""),"")} | H16: {=IFERROR(IF(OR('Raw Data'!H16="",LEN(TRIM('Raw Data'!H16))=0),_xlfn.REGEXEXTRACT(CELL("address",'Raw Data'!H16),"\$([A-Z]+)\$[0-9]+"),""),"")}
C17: {=IFERROR(IF(OR('Raw Data'!C17="",LEN(TRIM('Raw Data'!C17))=0),_xlfn.REGEXEXTRACT(CELL("address",'Raw Data'!C17),"\$([A-Z]+)\$[0-9]+"),""),"")} | D17: {=IFERROR(IF(OR('Raw Data'!D17="",LEN(TRIM('Raw Data'!D17))=0),_xlfn.REGEXEXTRACT(CELL("address",'Raw Data'!D17),"\$([A-Z]+)\$[0-9]+"),""),"")} | E17: {=IFERROR(IF(OR('Raw Data'!E17="",LEN(TRIM('Raw Data'!E17))=0),_xlfn.REGEXEXTRACT(CELL("address",'Raw Data'!E17),"\$([A-Z]+)\$[0-9]+"),""),"")} | F17: {=IFERROR(IF(OR('Raw Data'!F17="",LEN(TRIM('Raw Data'!F17))=0),_xlfn.REGEXEXTRACT(CELL("address",'Raw Data'!F17),"\$([A-Z]+)\$[0-9]+"),""),"")} | G17: {=IFERROR(IF(OR('Raw Data'!G17="",LEN(TRIM('Raw Data'!G17))=0),_xlfn.REGEXEXTRACT(CELL("address",'Raw Data'!G17),"\$([A-Z]+)\$[0-9]+"),""),"")} | H17: {=IFERROR(IF(OR('Raw Data'!H17="",LEN(TRIM('Raw Data'!H17))=0),_xlfn.REGEXEXTRACT(CELL("address",'Raw Data'!H17),"\$([A-Z]+)\$[0-9]+"),""),"")}
C18: {=IFERROR(IF(OR('Raw Data'!C18="",LEN(TRIM('Raw Data'!C18))=0),_xlfn.REGEXEXTRACT(CELL("address",'Raw Data'!C18),"\$([A-Z]+)\$[0-9]+"),""),"")} | D18: {=IFERROR(IF(OR('Raw Data'!D18="",LEN(TRIM('Raw Data'!D18))=0),_xlfn.REGEXEXTRACT(CELL("address",'Raw Data'!D18),"\$([A-Z]+)\$[0-9]+"),""),"")} | E18: {=IFERROR(IF(OR('Raw Data'!E18="",LEN(TRIM('Raw Data'!E18))=0),_xlfn.REGEXEXTRACT(CELL("address",'Raw Data'!E18),"\$([A-Z]+)\$[0-9]+"),""),"")} | F18: {=IFERROR(IF(OR('Raw Data'!F18="",LEN(TRIM('Raw Data'!F18))=0),_xlfn.REGEXEXTRACT(CELL("address",'Raw Data'!F18),"\$([A-Z]+)\$[0-9]+"),""),"")} | G18: {=IFERROR(IF(OR('Raw Data'!G18="",LEN(TRIM('Raw Data'!G18))=0),_xlfn.REGEXEXTRACT(CELL("address",'Raw Data'!G18),"\$([A-Z]+)\$[0-9]+"),""),"")} | H18: {=IFERROR(IF(OR('Raw Data'!H18="",LEN(TRIM('Raw Data'!H18))=0),_xlfn.REGEXEXTRACT(CELL("address",'Raw Data'!H18),"\$([A-Z]+)\$[0-9]+"),""),"")}
C19: {=IFERROR(IF(OR('Raw Data'!C19="",LEN(TRIM('Raw Data'!C19))=0),_xlfn.REGEXEXTRACT(CELL("address",'Raw Data'!C19),"\$([A-Z]+)\$[0-9]+"),""),"")} | D19: {=IFERROR(IF(OR('Raw Data'!D19="",LEN(TRIM('Raw Data'!D19))=0),_xlfn.REGEXEXTRACT(CELL("address",'Raw Data'!D19),"\$([A-Z]+)\$[0-9]+"),""),"")} | E19: {=IFERROR(IF(OR('Raw Data'!E19="",LEN(TRIM('Raw Data'!E19))=0),_xlfn.REGEXEXTRACT(CELL("address",'Raw Data'!E19),"\$([A-Z]+)\$[0-9]+"),""),"")} | F19: {=IFERROR(IF(OR('Raw Data'!F19="",LEN(TRIM('Raw Data'!F19))=0),_xlfn.REGEXEXTRACT(CELL("address",'Raw Data'!F19),"\$([A-Z]+)\$[0-9]+"),""),"")} | G19: {=IFERROR(IF(OR('Raw Data'!G19="",LEN(TRIM('Raw Data'!G19))=0),_xlfn.REGEXEXTRACT(CELL("address",'Raw Data'!G19),"\$([A-Z]+)\$[0-9]+"),""),"")} | H19: {=IFERROR(IF(OR('Raw Data'!H19="",LEN(TRIM('Raw Data'!H19))=0),_xlfn.REGEXEXTRACT(CELL("address",'Raw Data'!H19),"\$([A-Z]+)\$[0-9]+"),""),"")}
C20: {=IFERROR(IF(OR('Raw Data'!C20="",LEN(TRIM('Raw Data'!C20))=0),_xlfn.REGEXEXTRACT(CELL("address",'Raw Data'!C20),"\$([A-Z]+)\$[0-9]+"),""),"")} | D20: {=IFERROR(IF(OR('Raw Data'!D20="",LEN(TRIM('Raw Data'!D20))=0),_xlfn.REGEXEXTRACT(CELL("address",'Raw Data'!D20),"\$([A-Z]+)\$[0-9]+"),""),"")} | E20: {=IFERROR(IF(OR('Raw Data'!E20="",LEN(TRIM('Raw Data'!E20))=0),_xlfn.REGEXEXTRACT(CELL("address",'Raw Data'!E20),"\$([A-Z]+)\$[0-9]+"),""),"")} | F20: {=IFERROR(IF(OR('Raw Data'!F20="",LEN(TRIM('Raw Data'!F20))=0),_xlfn.REGEXEXTRACT(CELL("address",'Raw Data'!F20),"\$([A-Z]+)\$[0-9]+"),""),"")} | G20: {=IFERROR(IF(OR('Raw Data'!G20="",LEN(TRIM('Raw Data'!G20))=0),_xlfn.REGEXEXTRACT(CELL("address",'Raw Data'!G20),"\$([A-Z]+)\$[0-9]+"),""),"")} | H20: {=IFERROR(IF(OR('Raw Data'!H20="",LEN(TRIM('Raw Data'!H20))=0),_xlfn.REGEXEXTRACT(CELL("address",'Raw Data'!H20),"\$([A-Z]+)\$[0-9]+"),""),"")}
C21: {=IFERROR(IF(OR('Raw Data'!C21="",LEN(TRIM('Raw Data'!C21))=0),_xlfn.REGEXEXTRACT(CELL("address",'Raw Data'!C21),"\$([A-Z]+)\$[0-9]+"),""),"")} | D21: {=IFERROR(IF(OR('Raw Data'!D21="",LEN(TRIM('Raw Data'!D21))=0),_xlfn.REGEXEXTRACT(CELL("address",'Raw Data'!D21),"\$([A-Z]+)\$[0-9]+"),""),"")} | E21: {=IFERROR(IF(OR('Raw Data'!E21="",LEN(TRIM('Raw Data'!E21))=0),_xlfn.REGEXEXTRACT(CELL("address",'Raw Data'!E21),"\$([A-Z]+)\$[0-9]+"),""),"")} | F21: {=IFERROR(IF(OR('Raw Data'!F21="",LEN(TRIM('Raw Data'!F21))=0),_xlfn.REGEXEXTRACT(CELL("address",'Raw Data'!F21),"\$([A-Z]+)\$[0-9]+"),""),"")} | G21: {=IFERROR(IF(OR('Raw Data'!G21="",LEN(TRIM('Raw Data'!G21))=0),_xlfn.REGEXEXTRACT(CELL("address",'Raw Data'!G21),"\$([A-Z]+)\$[0-9]+"),""),"")} | H21: {=IFERROR(IF(OR('Raw Data'!H21="",LEN(TRIM('Raw Data'!H21))=0),_xlfn.REGEXEXTRACT(CELL("address",'Raw Data'!H21),"\$([A-Z]+)\$[0-9]+"),""),"")}
... C1259: {=IFERROR(IF(OR('Raw Data'!C1259="",LEN(TRIM('Raw Data'!C1259))=0),_xlfn.REGEXEXTRACT(CELL("address",'Raw Data'!C1259),"\$([A-Z]+)\$[0-9]+"),""),"")} | D1259: {=IFERROR(IF(OR('Raw Data'!D1259="",LEN(TRIM('Raw Data'!D1259))=0),_xlfn.REGEXEXTRACT(CELL("address",'Raw Data'!D1259),"\$([A-Z]+)\$[0-9]+"),""),"")} | E1259: {=IFERROR(IF(OR('Raw Data'!E1259="",LEN(TRIM('Raw Data'!E1259))=0),_xlfn.REGEXEXTRACT(CELL("address",'Raw Data'!E1259),"\$([A-Z]+)\$[0-9]+"),""),"")} | F1259: {=IFERROR(IF(OR('Raw Data'!F1259="",LEN(TRIM('Raw Data'!F1259))=0),_xlfn.REGEXEXTRACT(CELL("address",'Raw Data'!F1259),"\$([A-Z]+)\$[0-9]+"),""),"")} | G1259: {=IFERROR(IF(OR('Raw Data'!G1259="",LEN(TRIM('Raw Data'!G1259))=0),_xlfn.REGEXEXTRACT(CELL("address",'Raw Data'!G1259),"\$([A-Z]+)\$[0-9]+"),""),"")} | H1259: {=IFERROR(IF(OR('Raw Data'!H1259="",LEN(TRIM('Raw Data'!H1259))=0),_xlfn.REGEXEXTRACT(CELL("address",'Raw Data'!H1259),"\$([A-Z]+)\$[0-9]+"),""),"")}

Sheet Validate_Value
C8: NVARCHAR(20) | D8: NVARCHAR(255) | E8: NVARCHAR(255) | F8: NVARCHAR(50) | G8: NVARCHAR(255) | H8: NVARCHAR(255) | I8: NVARCHAR(255) | J8: NVARCHAR(255) | K8: NVARCHAR(10) | L8: DECIMAL(13,2) | M8: DECIMAL(13,2) | N8: DECIMAL(13,2)
C9: C1 | D9: C2 | E9: C3 | F9: C4 | G9: C5 | H9: C6 | I9: C7 | J9: C8 | K9: C9 | L9: C10 | M9: C11 | N9: C12
C10: {=IFERROR(IF(OR('Raw Data'!C10="",LEN(TRIM('Raw Data'!C10))=0),"",IF(AND(LEN('Raw Data'!C10) <= 20,LEN('Raw Data'!C10)> 0),"",_xlfn.REGEXEXTRACT(CELL("address",'Raw Data'!C10),"\$([A-Z]+)\$[0-9]+"))),_xlfn.REGEXEXTRACT(CELL("address",'Raw Data'!C10),"\$([A-Z]+)\$[0-9]+"))} | D10: {=IFERROR(IF(OR('Raw Data'!D10="",LEN(TRIM('Raw Data'!D10))=0),"",IF(AND(LEN('Raw Data'!D10) <= 255,LEN('Raw Data'!D10)> 0),"",_xlfn.REGEXEXTRACT(CELL("address",'Raw Data'!D10),"\$([A-Z]+)\$[0-9]+"))),_xlfn.REGEXEXTRACT(CELL("address",'Raw Data'!D10),"\$([A-Z]+)\$[0-9]+"))} | E10: {=IFERROR(IF(OR('Raw Data'!E10="",LEN(TRIM('Raw Data'!E10))=0),"",IF(AND(LEN('Raw Data'!E10) <= 255,LEN('Raw Data'!E10)> 0),"",_xlfn.REGEXEXTRACT(CELL("address",'Raw Data'!E10),"\$([A-Z]+)\$[0-9]+"))),_xlfn.REGEXEXTRACT(CELL("address",'Raw Data'!E10),"\$([A-Z]+)\$[0-9]+"))} | F10: {=IFERROR(IF(OR('Raw Data'!F10="",LEN(TRIM('Raw Data'!F10))=0),"",IF(AND(LEN('Raw Data'!F10) <= 50,LEN('Raw Data'!F10)> 0),"",_xlfn.REGEXEXTRACT(CELL("address",'Raw Data'!F10),"\$([A-Z]+)\$[0-9]+"))),_xlfn.REGEXEXTRACT(CELL("address",'Raw Data'!F10),"\$([A-Z]+)\$[0-9]+"))} | G10: {=IFERROR(IF(OR('Raw Data'!G10="",LEN(TRIM('Raw Data'!G10))=0),"",IF(AND(LEN('Raw Data'!G10) <= 255,LEN('Raw Data'!G10)> 0),"",_xlfn.REGEXEXTRACT(CELL("address",'Raw Data'!G10),"\$([A-Z]+)\$[0-9]+"))),_xlfn.REGEXEXTRACT(CELL("address",'Raw Data'!G10),"\$([A-Z]+)\$[0-9]+"))} | H10: {=IFERROR(IF(OR('Raw Data'!H10="",LEN(TRIM('Raw Data'!H10))=0),"",IF(AND(LEN('Raw Data'!H10) <= 255,LEN('Raw Data'!H10)> 0),"",_xlfn.REGEXEXTRACT(CELL("address",'Raw Data'!H10),"\$([A-Z]+)\$[0-9]+"))),_xlfn.REGEXEXTRACT(CELL("address",'Raw Data'!H10),"\$([A-Z]+)\$[0-9]+"))} | I10: {=IFERROR(IF(OR('Raw Data'!I10="",LEN(TRIM('Raw Data'!I10))=0),"",IF(AND(LEN('Raw Data'!I10) <= 255,LEN('Raw Data'!I10)> 0),"",_xlfn.REGEXEXTRACT(CELL("address",'Raw Data'!I10),"\$([A-Z]+)\$[0-9]+"))),_xlfn.REGEXEXTRACT(CELL("address",'Raw Data'!I10),"\$([A-Z]+)\$[0-9]+"))} | J10: {=IFERROR(IF(OR('Raw Data'!J10="",LEN(TRIM('Raw Data'!J10))=0),"",IF(AND(LEN('Raw Data'!J10) <= 255,LEN('Raw Data'!J10)> 0),"",_xlfn.REGEXEXTRACT(CELL("address",'Raw Data'!J10),"\$([A-Z]+)\$[0-9]+"))),_xlfn.REGEXEXTRACT(CELL("address",'Raw Data'!J10),"\$([A-Z]+)\$[0-9]+"))} | K10: {=IFERROR(IF(OR('Raw Data'!K10="",LEN(TRIM('Raw Data'!K10))=0),"",IF(AND(LEN('Raw Data'!K10) <= 10,LEN('Raw Data'!K10)> 0),"",_xlfn.REGEXEXTRACT(CELL("address",'Raw Data'!K10),"\$([A-Z]+)\$[0-9]+"))),_xlfn.REGEXEXTRACT(CELL("address",'Raw Data'!K10),"\$([A-Z]+)\$[0-9]+"))} | L10: {=IFERROR(IF(OR('Raw Data'!L10="",LEN(TRIM('Raw Data'!L10))=0),"",IF(AND(ISNUMBER('Raw Data'!L10), IFERROR('Raw Data'!L10 = ROUND('Raw Data'!L10, 2),FALSE)),"",_xlfn.REGEXEXTRACT(CELL("address",L10), "\$([A-Z]+)\$[0-9]+"))),_xlfn.REGEXEXTRACT(CELL("address",L10), "\$([A-Z]+)\$[0-9]+"))} | M10: {=IFERROR(IF(OR('Raw Data'!M10="",LEN(TRIM('Raw Data'!M10))=0),"",IF(AND(ISNUMBER('Raw Data'!M10), IFERROR('Raw Data'!M10 = ROUND('Raw Data'!M10, 2),FALSE)),"",_xlfn.REGEXEXTRACT(CELL("address",M10), "\$([A-Z]+)\$[0-9]+"))),_xlfn.REGEXEXTRACT(CELL("address",M10), "\$([A-Z]+)\$[0-9]+"))} | N10: {=IFERROR(IF(OR('Raw Data'!N10="",LEN(TRIM('Raw Data'!N10))=0),"",IF(AND(ISNUMBER('Raw Data'!N10), IFERROR('Raw Data'!N10 = ROUND('Raw Data'!N10, 2),FALSE)),"",_xlfn.REGEXEXTRACT(CELL("address",N10), "\$([A-Z]+)\$[0-9]+"))),_xlfn.REGEXEXTRACT(CELL("address",N10), "\$([A-Z]+)\$[0-9]+"))}
C11: {=IFERROR(IF(OR('Raw Data'!C11="",LEN(TRIM('Raw Data'!C11))=0),"",IF(AND(LEN('Raw Data'!C11) <= 20,LEN('Raw Data'!C11)> 0),"",_xlfn.REGEXEXTRACT(CELL("address",'Raw Data'!C11),"\$([A-Z]+)\$[0-9]+"))),_xlfn.REGEXEXTRACT(CELL("address",'Raw Data'!C11),"\$([A-Z]+)\$[0-9]+"))} | D11: {=IFERROR(IF(OR('Raw Data'!D11="",LEN(TRIM('Raw Data'!D11))=0),"",IF(AND(LEN('Raw Data'!D11) <= 255,LEN('Raw Data'!D11)> 0),"",_xlfn.REGEXEXTRACT(CELL("address",'Raw Data'!D11),"\$([A-Z]+)\$[0-9]+"))),_xlfn.REGEXEXTRACT(CELL("address",'Raw Data'!D11),"\$([A-Z]+)\$[0-9]+"))} | E11: {=IFERROR(IF(OR('Raw Data'!E11="",LEN(TRIM('Raw Data'!E11))=0),"",IF(AND(LEN('Raw Data'!E11) <= 255,LEN('Raw Data'!E11)> 0),"",_xlfn.REGEXEXTRACT(CELL("address",'Raw Data'!E11),"\$([A-Z]+)\$[0-9]+"))),_xlfn.REGEXEXTRACT(CELL("address",'Raw Data'!E11),"\$([A-Z]+)\$[0-9]+"))} | F11: {=IFERROR(IF(OR('Raw Data'!F11="",LEN(TRIM('Raw Data'!F11))=0),"",IF(AND(LEN('Raw Data'!F11) <= 50,LEN('Raw Data'!F11)> 0),"",_xlfn.REGEXEXTRACT(CELL("address",'Raw Data'!F11),"\$([A-Z]+)\$[0-9]+"))),_xlfn.REGEXEXTRACT(CELL("address",'Raw Data'!F11),"\$([A-Z]+)\$[0-9]+"))} | G11: {=IFERROR(IF(OR('Raw Data'!G11="",LEN(TRIM('Raw Data'!G11))=0),"",IF(AND(LEN('Raw Data'!G11) <= 255,LEN('Raw Data'!G11)> 0),"",_xlfn.REGEXEXTRACT(CELL("address",'Raw Data'!G11),"\$([A-Z]+)\$[0-9]+"))),_xlfn.REGEXEXTRACT(CELL("address",'Raw Data'!G11),"\$([A-Z]+)\$[0-9]+"))} | H11: {=IFERROR(IF(OR('Raw Data'!H11="",LEN(TRIM('Raw Data'!H11))=0),"",IF(AND(LEN('Raw Data'!H11) <= 255,LEN('Raw Data'!H11)> 0),"",_xlfn.REGEXEXTRACT(CELL("address",'Raw Data'!H11),"\$([A-Z]+)\$[0-9]+"))),_xlfn.REGEXEXTRACT(CELL("address",'Raw Data'!H11),"\$([A-Z]+)\$[0-9]+"))} | I11: {=IFERROR(IF(OR('Raw Data'!I11="",LEN(TRIM('Raw Data'!I11))=0),"",IF(AND(LEN('Raw Data'!I11) <= 255,LEN('Raw Data'!I11)> 0),"",_xlfn.REGEXEXTRACT(CELL("address",'Raw Data'!I11),"\$([A-Z]+)\$[0-9]+"))),_xlfn.REGEXEXTRACT(CELL("address",'Raw Data'!I11),"\$([A-Z]+)\$[0-9]+"))} | J11: {=IFERROR(IF(OR('Raw Data'!J11="",LEN(TRIM('Raw Data'!J11))=0),"",IF(AND(LEN('Raw Data'!J11) <= 255,LEN('Raw Data'!J11)> 0),"",_xlfn.REGEXEXTRACT(CELL("address",'Raw Data'!J11),"\$([A-Z]+)\$[0-9]+"))),_xlfn.REGEXEXTRACT(CELL("address",'Raw Data'!J11),"\$([A-Z]+)\$[0-9]+"))} | K11: {=IFERROR(IF(OR('Raw Data'!K11="",LEN(TRIM('Raw Data'!K11))=0),"",IF(AND(LEN('Raw Data'!K11) <= 10,LEN('Raw Data'!K11)> 0),"",_xlfn.REGEXEXTRACT(CELL("address",'Raw Data'!K11),"\$([A-Z]+)\$[0-9]+"))),_xlfn.REGEXEXTRACT(CELL("address",'Raw Data'!K11),"\$([A-Z]+)\$[0-9]+"))} | L11: {=IFERROR(IF(OR('Raw Data'!L11="",LEN(TRIM('Raw Data'!L11))=0),"",IF(AND(ISNUMBER('Raw Data'!L11), IFERROR('Raw Data'!L11 = ROUND('Raw Data'!L11, 2),FALSE)),"",_xlfn.REGEXEXTRACT(CELL("address",L11), "\$([A-Z]+)\$[0-9]+"))),_xlfn.REGEXEXTRACT(CELL("address",L11), "\$([A-Z]+)\$[0-9]+"))} | M11: {=IFERROR(IF(OR('Raw Data'!M11="",LEN(TRIM('Raw Data'!M11))=0),"",IF(AND(ISNUMBER('Raw Data'!M11), IFERROR('Raw Data'!M11 = ROUND('Raw Data'!M11, 2),FALSE)),"",_xlfn.REGEXEXTRACT(CELL("address",M11), "\$([A-Z]+)\$[0-9]+"))),_xlfn.REGEXEXTRACT(CELL("address",M11), "\$([A-Z]+)\$[0-9]+"))} | N11: {=IFERROR(IF(OR('Raw Data'!N11="",LEN(TRIM('Raw Data'!N11))=0),"",IF(AND(ISNUMBER('Raw Data'!N11), IFERROR('Raw Data'!N11 = ROUND('Raw Data'!N11, 2),FALSE)),"",_xlfn.REGEXEXTRACT(CELL("address",N11), "\$([A-Z]+)\$[0-9]+"))),_xlfn.REGEXEXTRACT(CELL("address",N11), "\$([A-Z]+)\$[0-9]+"))}
C12: {=IFERROR(IF(OR('Raw Data'!C12="",LEN(TRIM('Raw Data'!C12))=0),"",IF(AND(LEN('Raw Data'!C12) <= 20,LEN('Raw Data'!C12)> 0),"",_xlfn.REGEXEXTRACT(CELL("address",'Raw Data'!C12),"\$([A-Z]+)\$[0-9]+"))),_xlfn.REGEXEXTRACT(CELL("address",'Raw Data'!C12),"\$([A-Z]+)\$[0-9]+"))} | D12: {=IFERROR(IF(OR('Raw Data'!D12="",LEN(TRIM('Raw Data'!D12))=0),"",IF(AND(LEN('Raw Data'!D12) <= 255,LEN('Raw Data'!D12)> 0),"",_xlfn.REGEXEXTRACT(CELL("address",'Raw Data'!D12),"\$([A-Z]+)\$[0-9]+"))),_xlfn.REGEXEXTRACT(CELL("address",'Raw Data'!D12),"\$([A-Z]+)\$[0-9]+"))} | E12: {=IFERROR(IF(OR('Raw Data'!E12="",LEN(TRIM('Raw Data'!E12))=0),"",IF(AND(LEN('Raw Data'!E12) <= 255,LEN('Raw Data'!E12)> 0),"",_xlfn.REGEXEXTRACT(CELL("address",'Raw Data'!E12),"\$([A-Z]+)\$[0-9]+"))),_xlfn.REGEXEXTRACT(CELL("address",'Raw Data'!E12),"\$([A-Z]+)\$[0-9]+"))} | F12: {=IFERROR(IF(OR('Raw Data'!F12="",LEN(TRIM('Raw Data'!F12))=0),"",IF(AND(LEN('Raw Data'!F12) <= 50,LEN('Raw Data'!F12)> 0),"",_xlfn.REGEXEXTRACT(CELL("address",'Raw Data'!F12),"\$([A-Z]+)\$[0-9]+"))),_xlfn.REGEXEXTRACT(CELL("address",'Raw Data'!F12),"\$([A-Z]+)\$[0-9]+"))} | G12: {=IFERROR(IF(OR('Raw Data'!G12="",LEN(TRIM('Raw Data'!G12))=0),"",IF(AND(LEN('Raw Data'!G12) <= 255,LEN('Raw Data'!G12)> 0),"",_xlfn.REGEXEXTRACT(CELL("address",'Raw Data'!G12),"\$([A-Z]+)\$[0-9]+"))),_xlfn.REGEXEXTRACT(CELL("address",'Raw Data'!G12),"\$([A-Z]+)\$[0-9]+"))} | H12: {=IFERROR(IF(OR('Raw Data'!H12="",LEN(TRIM('Raw Data'!H12))=0),"",IF(AND(LEN('Raw Data'!H12) <= 255,LEN('Raw Data'!H12)> 0),"",_xlfn.REGEXEXTRACT(CELL("address",'Raw Data'!H12),"\$([A-Z]+)\$[0-9]+"))),_xlfn.REGEXEXTRACT(CELL("address",'Raw Data'!H12),"\$([A-Z]+)\$[0-9]+"))} | I12: {=IFERROR(IF(OR('Raw Data'!I12="",LEN(TRIM('Raw Data'!I12))=0),"",IF(AND(LEN('Raw Data'!I12) <= 255,LEN('Raw Data'!I12)> 0),"",_xlfn.REGEXEXTRACT(CELL("address",'Raw Data'!I12),"\$([A-Z]+)\$[0-9]+"))),_xlfn.REGEXEXTRACT(CELL("address",'Raw Data'!I12),"\$([A-Z]+)\$[0-9]+"))} | J12: {=IFERROR(IF(OR('Raw Data'!J12="",LEN(TRIM('Raw Data'!J12))=0),"",IF(AND(LEN('Raw Data'!J12) <= 255,LEN('Raw Data'!J12)> 0),"",_xlfn.REGEXEXTRACT(CELL("address",'Raw Data'!J12),"\$([A-Z]+)\$[0-9]+"))),_xlfn.REGEXEXTRACT(CELL("address",'Raw Data'!J12),"\$([A-Z]+)\$[0-9]+"))} | K12: {=IFERROR(IF(OR('Raw Data'!K12="",LEN(TRIM('Raw Data'!K12))=0),"",IF(AND(LEN('Raw Data'!K12) <= 10,LEN('Raw Data'!K12)> 0),"",_xlfn.REGEXEXTRACT(CELL("address",'Raw Data'!K12),"\$([A-Z]+)\$[0-9]+"))),_xlfn.REGEXEXTRACT(CELL("address",'Raw Data'!K12),"\$([A-Z]+)\$[0-9]+"))} | L12: {=IFERROR(IF(OR('Raw Data'!L12="",LEN(TRIM('Raw Data'!L12))=0),"",IF(AND(ISNUMBER('Raw Data'!L12), IFERROR('Raw Data'!L12 = ROUND('Raw Data'!L12, 2),FALSE)),"",_xlfn.REGEXEXTRACT(CELL("address",L12), "\$([A-Z]+)\$[0-9]+"))),_xlfn.REGEXEXTRACT(CELL("address",L12), "\$([A-Z]+)\$[0-9]+"))} | M12: {=IFERROR(IF(OR('Raw Data'!M12="",LEN(TRIM('Raw Data'!M12))=0),"",IF(AND(ISNUMBER('Raw Data'!M12), IFERROR('Raw Data'!M12 = ROUND('Raw Data'!M12, 2),FALSE)),"",_xlfn.REGEXEXTRACT(CELL("address",M12), "\$([A-Z]+)\$[0-9]+"))),_xlfn.REGEXEXTRACT(CELL("address",M12), "\$([A-Z]+)\$[0-9]+"))} | N12: {=IFERROR(IF(OR('Raw Data'!N12="",LEN(TRIM('Raw Data'!N12))=0),"",IF(AND(ISNUMBER('Raw Data'!N12), IFERROR('Raw Data'!N12 = ROUND('Raw Data'!N12, 2),FALSE)),"",_xlfn.REGEXEXTRACT(CELL("address",N12), "\$([A-Z]+)\$[0-9]+"))),_xlfn.REGEXEXTRACT(CELL("address",N12), "\$([A-Z]+)\$[0-9]+"))}
C13: {=IFERROR(IF(OR('Raw Data'!C13="",LEN(TRIM('Raw Data'!C13))=0),"",IF(AND(LEN('Raw Data'!C13) <= 20,LEN('Raw Data'!C13)> 0),"",_xlfn.REGEXEXTRACT(CELL("address",'Raw Data'!C13),"\$([A-Z]+)\$[0-9]+"))),_xlfn.REGEXEXTRACT(CELL("address",'Raw Data'!C13),"\$([A-Z]+)\$[0-9]+"))} | D13: {=IFERROR(IF(OR('Raw Data'!D13="",LEN(TRIM('Raw Data'!D13))=0),"",IF(AND(LEN('Raw Data'!D13) <= 255,LEN('Raw Data'!D13)> 0),"",_xlfn.REGEXEXTRACT(CELL("address",'Raw Data'!D13),"\$([A-Z]+)\$[0-9]+"))),_xlfn.REGEXEXTRACT(CELL("address",'Raw Data'!D13),"\$([A-Z]+)\$[0-9]+"))} | E13: {=IFERROR(IF(OR('Raw Data'!E13="",LEN(TRIM('Raw Data'!E13))=0),"",IF(AND(LEN('Raw Data'!E13) <= 255,LEN('Raw Data'!E13)> 0),"",_xlfn.REGEXEXTRACT(CELL("address",'Raw Data'!E13),"\$([A-Z]+)\$[0-9]+"))),_xlfn.REGEXEXTRACT(CELL("address",'Raw Data'!E13),"\$([A-Z]+)\$[0-9]+"))} | F13: {=IFERROR(IF(OR('Raw Data'!F13="",LEN(TRIM('Raw Data'!F13))=0),"",IF(AND(LEN('Raw Data'!F13) <= 50,LEN('Raw Data'!F13)> 0),"",_xlfn.REGEXEXTRACT(CELL("address",'Raw Data'!F13),"\$([A-Z]+)\$[0-9]+"))),_xlfn.REGEXEXTRACT(CELL("address",'Raw Data'!F13),"\$([A-Z]+)\$[0-9]+"))} | G13: {=IFERROR(IF(OR('Raw Data'!G13="",LEN(TRIM('Raw Data'!G13))=0),"",IF(AND(LEN('Raw Data'!G13) <= 255,LEN('Raw Data'!G13)> 0),"",_xlfn.REGEXEXTRACT(CELL("address",'Raw Data'!G13),"\$([A-Z]+)\$[0-9]+"))),_xlfn.REGEXEXTRACT(CELL("address",'Raw Data'!G13),"\$([A-Z]+)\$[0-9]+"))} | H13: {=IFERROR(IF(OR('Raw Data'!H13="",LEN(TRIM('Raw Data'!H13))=0),"",IF(AND(LEN('Raw Data'!H13) <= 255,LEN('Raw Data'!H13)> 0),"",_xlfn.REGEXEXTRACT(CELL("address",'Raw Data'!H13),"\$([A-Z]+)\$[0-9]+"))),_xlfn.REGEXEXTRACT(CELL("address",'Raw Data'!H13),"\$([A-Z]+)\$[0-9]+"))} | I13: {=IFERROR(IF(OR('Raw Data'!I13="",LEN(TRIM('Raw Data'!I13))=0),"",IF(AND(LEN('Raw Data'!I13) <= 255,LEN('Raw Data'!I13)> 0),"",_xlfn.REGEXEXTRACT(CELL("address",'Raw Data'!I13),"\$([A-Z]+)\$[0-9]+"))),_xlfn.REGEXEXTRACT(CELL("address",'Raw Data'!I13),"\$([A-Z]+)\$[0-9]+"))} | J13: {=IFERROR(IF(OR('Raw Data'!J13="",LEN(TRIM('Raw Data'!J13))=0),"",IF(AND(LEN('Raw Data'!J13) <= 255,LEN('Raw Data'!J13)> 0),"",_xlfn.REGEXEXTRACT(CELL("address",'Raw Data'!J13),"\$([A-Z]+)\$[0-9]+"))),_xlfn.REGEXEXTRACT(CELL("address",'Raw Data'!J13),"\$([A-Z]+)\$[0-9]+"))} | K13: {=IFERROR(IF(OR('Raw Data'!K13="",LEN(TRIM('Raw Data'!K13))=0),"",IF(AND(LEN('Raw Data'!K13) <= 10,LEN('Raw Data'!K13)> 0),"",_xlfn.REGEXEXTRACT(CELL("address",'Raw Data'!K13),"\$([A-Z]+)\$[0-9]+"))),_xlfn.REGEXEXTRACT(CELL("address",'Raw Data'!K13),"\$([A-Z]+)\$[0-9]+"))} | L13: {=IFERROR(IF(OR('Raw Data'!L13="",LEN(TRIM('Raw Data'!L13))=0),"",IF(AND(ISNUMBER('Raw Data'!L13), IFERROR('Raw Data'!L13 = ROUND('Raw Data'!L13, 2),FALSE)),"",_xlfn.REGEXEXTRACT(CELL("address",L13), "\$([A-Z]+)\$[0-9]+"))),_xlfn.REGEXEXTRACT(CELL("address",L13), "\$([A-Z]+)\$[0-9]+"))} | M13: {=IFERROR(IF(OR('Raw Data'!M13="",LEN(TRIM('Raw Data'!M13))=0),"",IF(AND(ISNUMBER('Raw Data'!M13), IFERROR('Raw Data'!M13 = ROUND('Raw Data'!M13, 2),FALSE)),"",_xlfn.REGEXEXTRACT(CELL("address",M13), "\$([A-Z]+)\$[0-9]+"))),_xlfn.REGEXEXTRACT(CELL("address",M13), "\$([A-Z]+)\$[0-9]+"))} | N13: {=IFERROR(IF(OR('Raw Data'!N13="",LEN(TRIM('Raw Data'!N13))=0),"",IF(AND(ISNUMBER('Raw Data'!N13), IFERROR('Raw Data'!N13 = ROUND('Raw Data'!N13, 2),FALSE)),"",_xlfn.REGEXEXTRACT(CELL("address",N13), "\$([A-Z]+)\$[0-9]+"))),_xlfn.REGEXEXTRACT(CELL("address",N13), "\$([A-Z]+)\$[0-9]+"))}
C14: {=IFERROR(IF(OR('Raw Data'!C14="",LEN(TRIM('Raw Data'!C14))=0),"",IF(AND(LEN('Raw Data'!C14) <= 20,LEN('Raw Data'!C14)> 0),"",_xlfn.REGEXEXTRACT(CELL("address",'Raw Data'!C14),"\$([A-Z]+)\$[0-9]+"))),_xlfn.REGEXEXTRACT(CELL("address",'Raw Data'!C14),"\$([A-Z]+)\$[0-9]+"))} | D14: {=IFERROR(IF(OR('Raw Data'!D14="",LEN(TRIM('Raw Data'!D14))=0),"",IF(AND(LEN('Raw Data'!D14) <= 255,LEN('Raw Data'!D14)> 0),"",_xlfn.REGEXEXTRACT(CELL("address",'Raw Data'!D14),"\$([A-Z]+)\$[0-9]+"))),_xlfn.REGEXEXTRACT(CELL("address",'Raw Data'!D14),"\$([A-Z]+)\$[0-9]+"))} | E14: {=IFERROR(IF(OR('Raw Data'!E14="",LEN(TRIM('Raw Data'!E14))=0),"",IF(AND(LEN('Raw Data'!E14) <= 255,LEN('Raw Data'!E14)> 0),"",_xlfn.REGEXEXTRACT(CELL("address",'Raw Data'!E14),"\$([A-Z]+)\$[0-9]+"))),_xlfn.REGEXEXTRACT(CELL("address",'Raw Data'!E14),"\$([A-Z]+)\$[0-9]+"))} | F14: {=IFERROR(IF(OR('Raw Data'!F14="",LEN(TRIM('Raw Data'!F14))=0),"",IF(AND(LEN('Raw Data'!F14) <= 50,LEN('Raw Data'!F14)> 0),"",_xlfn.REGEXEXTRACT(CELL("address",'Raw Data'!F14),"\$([A-Z]+)\$[0-9]+"))),_xlfn.REGEXEXTRACT(CELL("address",'Raw Data'!F14),"\$([A-Z]+)\$[0-9]+"))} | G14: {=IFERROR(IF(OR('Raw Data'!G14="",LEN(TRIM('Raw Data'!G14))=0),"",IF(AND(LEN('Raw Data'!G14) <= 255,LEN('Raw Data'!G14)> 0),"",_xlfn.REGEXEXTRACT(CELL("address",'Raw Data'!G14),"\$([A-Z]+)\$[0-9]+"))),_xlfn.REGEXEXTRACT(CELL("address",'Raw Data'!G14),"\$([A-Z]+)\$[0-9]+"))} | H14: {=IFERROR(IF(OR('Raw Data'!H14="",LEN(TRIM('Raw Data'!H14))=0),"",IF(AND(LEN('Raw Data'!H14) <= 255,LEN('Raw Data'!H14)> 0),"",_xlfn.REGEXEXTRACT(CELL("address",'Raw Data'!H14),"\$([A-Z]+)\$[0-9]+"))),_xlfn.REGEXEXTRACT(CELL("address",'Raw Data'!H14),"\$([A-Z]+)\$[0-9]+"))} | I14: {=IFERROR(IF(OR('Raw Data'!I14="",LEN(TRIM('Raw Data'!I14))=0),"",IF(AND(LEN('Raw Data'!I14) <= 255,LEN('Raw Data'!I14)> 0),"",_xlfn.REGEXEXTRACT(CELL("address",'Raw Data'!I14),"\$([A-Z]+)\$[0-9]+"))),_xlfn.REGEXEXTRACT(CELL("address",'Raw Data'!I14),"\$([A-Z]+)\$[0-9]+"))} | J14: {=IFERROR(IF(OR('Raw Data'!J14="",LEN(TRIM('Raw Data'!J14))=0),"",IF(AND(LEN('Raw Data'!J14) <= 255,LEN('Raw Data'!J14)> 0),"",_xlfn.REGEXEXTRACT(CELL("address",'Raw Data'!J14),"\$([A-Z]+)\$[0-9]+"))),_xlfn.REGEXEXTRACT(CELL("address",'Raw Data'!J14),"\$([A-Z]+)\$[0-9]+"))} | K14: {=IFERROR(IF(OR('Raw Data'!K14="",LEN(TRIM('Raw Data'!K14))=0),"",IF(AND(LEN('Raw Data'!K14) <= 10,LEN('Raw Data'!K14)> 0),"",_xlfn.REGEXEXTRACT(CELL("address",'Raw Data'!K14),"\$([A-Z]+)\$[0-9]+"))),_xlfn.REGEXEXTRACT(CELL("address",'Raw Data'!K14),"\$([A-Z]+)\$[0-9]+"))} | L14: {=IFERROR(IF(OR('Raw Data'!L14="",LEN(TRIM('Raw Data'!L14))=0),"",IF(AND(ISNUMBER('Raw Data'!L14), IFERROR('Raw Data'!L14 = ROUND('Raw Data'!L14, 2),FALSE)),"",_xlfn.REGEXEXTRACT(CELL("address",L14), "\$([A-Z]+)\$[0-9]+"))),_xlfn.REGEXEXTRACT(CELL("address",L14), "\$([A-Z]+)\$[0-9]+"))} | M14: {=IFERROR(IF(OR('Raw Data'!M14="",LEN(TRIM('Raw Data'!M14))=0),"",IF(AND(ISNUMBER('Raw Data'!M14), IFERROR('Raw Data'!M14 = ROUND('Raw Data'!M14, 2),FALSE)),"",_xlfn.REGEXEXTRACT(CELL("address",M14), "\$([A-Z]+)\$[0-9]+"))),_xlfn.REGEXEXTRACT(CELL("address",M14), "\$([A-Z]+)\$[0-9]+"))} | N14: {=IFERROR(IF(OR('Raw Data'!N14="",LEN(TRIM('Raw Data'!N14))=0),"",IF(AND(ISNUMBER('Raw Data'!N14), IFERROR('Raw Data'!N14 = ROUND('Raw Data'!N14, 2),FALSE)),"",_xlfn.REGEXEXTRACT(CELL("address",N14), "\$([A-Z]+)\$[0-9]+"))),_xlfn.REGEXEXTRACT(CELL("address",N14), "\$([A-Z]+)\$[0-9]+"))}
C15: {=IFERROR(IF(OR('Raw Data'!C15="",LEN(TRIM('Raw Data'!C15))=0),"",IF(AND(LEN('Raw Data'!C15) <= 20,LEN('Raw Data'!C15)> 0),"",_xlfn.REGEXEXTRACT(CELL("address",'Raw Data'!C15),"\$([A-Z]+)\$[0-9]+"))),_xlfn.REGEXEXTRACT(CELL("address",'Raw Data'!C15),"\$([A-Z]+)\$[0-9]+"))} | D15: {=IFERROR(IF(OR('Raw Data'!D15="",LEN(TRIM('Raw Data'!D15))=0),"",IF(AND(LEN('Raw Data'!D15) <= 255,LEN('Raw Data'!D15)> 0),"",_xlfn.REGEXEXTRACT(CELL("address",'Raw Data'!D15),"\$([A-Z]+)\$[0-9]+"))),_xlfn.REGEXEXTRACT(CELL("address",'Raw Data'!D15),"\$([A-Z]+)\$[0-9]+"))} | E15: {=IFERROR(IF(OR('Raw Data'!E15="",LEN(TRIM('Raw Data'!E15))=0),"",IF(AND(LEN('Raw Data'!E15) <= 255,LEN('Raw Data'!E15)> 0),"",_xlfn.REGEXEXTRACT(CELL("address",'Raw Data'!E15),"\$([A-Z]+)\$[0-9]+"))),_xlfn.REGEXEXTRACT(CELL("address",'Raw Data'!E15),"\$([A-Z]+)\$[0-9]+"))} | F15: {=IFERROR(IF(OR('Raw Data'!F15="",LEN(TRIM('Raw Data'!F15))=0),"",IF(AND(LEN('Raw Data'!F15) <= 50,LEN('Raw Data'!F15)> 0),"",_xlfn.REGEXEXTRACT(CELL("address",'Raw Data'!F15),"\$([A-Z]+)\$[0-9]+"))),_xlfn.REGEXEXTRACT(CELL("address",'Raw Data'!F15),"\$([A-Z]+)\$[0-9]+"))} | G15: {=IFERROR(IF(OR('Raw Data'!G15="",LEN(TRIM('Raw Data'!G15))=0),"",IF(AND(LEN('Raw Data'!G15) <= 255,LEN('Raw Data'!G15)> 0),"",_xlfn.REGEXEXTRACT(CELL("address",'Raw Data'!G15),"\$([A-Z]+)\$[0-9]+"))),_xlfn.REGEXEXTRACT(CELL("address",'Raw Data'!G15),"\$([A-Z]+)\$[0-9]+"))} | H15: {=IFERROR(IF(OR('Raw Data'!H15="",LEN(TRIM('Raw Data'!H15))=0),"",IF(AND(LEN('Raw Data'!H15) <= 255,LEN('Raw Data'!H15)> 0),"",_xlfn.REGEXEXTRACT(CELL("address",'Raw Data'!H15),"\$([A-Z]+)\$[0-9]+"))),_xlfn.REGEXEXTRACT(CELL("address",'Raw Data'!H15),"\$([A-Z]+)\$[0-9]+"))} | I15: {=IFERROR(IF(OR('Raw Data'!I15="",LEN(TRIM('Raw Data'!I15))=0),"",IF(AND(LEN('Raw Data'!I15) <= 255,LEN('Raw Data'!I15)> 0),"",_xlfn.REGEXEXTRACT(CELL("address",'Raw Data'!I15),"\$([A-Z]+)\$[0-9]+"))),_xlfn.REGEXEXTRACT(CELL("address",'Raw Data'!I15),"\$([A-Z]+)\$[0-9]+"))} | J15: {=IFERROR(IF(OR('Raw Data'!J15="",LEN(TRIM('Raw Data'!J15))=0),"",IF(AND(LEN('Raw Data'!J15) <= 255,LEN('Raw Data'!J15)> 0),"",_xlfn.REGEXEXTRACT(CELL("address",'Raw Data'!J15),"\$([A-Z]+)\$[0-9]+"))),_xlfn.REGEXEXTRACT(CELL("address",'Raw Data'!J15),"\$([A-Z]+)\$[0-9]+"))} | K15: {=IFERROR(IF(OR('Raw Data'!K15="",LEN(TRIM('Raw Data'!K15))=0),"",IF(AND(LEN('Raw Data'!K15) <= 10,LEN('Raw Data'!K15)> 0),"",_xlfn.REGEXEXTRACT(CELL("address",'Raw Data'!K15),"\$([A-Z]+)\$[0-9]+"))),_xlfn.REGEXEXTRACT(CELL("address",'Raw Data'!K15),"\$([A-Z]+)\$[0-9]+"))} | L15: {=IFERROR(IF(OR('Raw Data'!L15="",LEN(TRIM('Raw Data'!L15))=0),"",IF(AND(ISNUMBER('Raw Data'!L15), IFERROR('Raw Data'!L15 = ROUND('Raw Data'!L15, 2),FALSE)),"",_xlfn.REGEXEXTRACT(CELL("address",L15), "\$([A-Z]+)\$[0-9]+"))),_xlfn.REGEXEXTRACT(CELL("address",L15), "\$([A-Z]+)\$[0-9]+"))} | M15: {=IFERROR(IF(OR('Raw Data'!M15="",LEN(TRIM('Raw Data'!M15))=0),"",IF(AND(ISNUMBER('Raw Data'!M15), IFERROR('Raw Data'!M15 = ROUND('Raw Data'!M15, 2),FALSE)),"",_xlfn.REGEXEXTRACT(CELL("address",M15), "\$([A-Z]+)\$[0-9]+"))),_xlfn.REGEXEXTRACT(CELL("address",M15), "\$([A-Z]+)\$[0-9]+"))} | N15: {=IFERROR(IF(OR('Raw Data'!N15="",LEN(TRIM('Raw Data'!N15))=0),"",IF(AND(ISNUMBER('Raw Data'!N15), IFERROR('Raw Data'!N15 = ROUND('Raw Data'!N15, 2),FALSE)),"",_xlfn.REGEXEXTRACT(CELL("address",N15), "\$([A-Z]+)\$[0-9]+"))),_xlfn.REGEXEXTRACT(CELL("address",N15), "\$([A-Z]+)\$[0-9]+"))}
C16: {=IFERROR(IF(OR('Raw Data'!C16="",LEN(TRIM('Raw Data'!C16))=0),"",IF(AND(LEN('Raw Data'!C16) <= 20,LEN('Raw Data'!C16)> 0),"",_xlfn.REGEXEXTRACT(CELL("address",'Raw Data'!C16),"\$([A-Z]+)\$[0-9]+"))),_xlfn.REGEXEXTRACT(CELL("address",'Raw Data'!C16),"\$([A-Z]+)\$[0-9]+"))} | D16: {=IFERROR(IF(OR('Raw Data'!D16="",LEN(TRIM('Raw Data'!D16))=0),"",IF(AND(LEN('Raw Data'!D16) <= 255,LEN('Raw Data'!D16)> 0),"",_xlfn.REGEXEXTRACT(CELL("address",'Raw Data'!D16),"\$([A-Z]+)\$[0-9]+"))),_xlfn.REGEXEXTRACT(CELL("address",'Raw Data'!D16),"\$([A-Z]+)\$[0-9]+"))} | E16: {=IFERROR(IF(OR('Raw Data'!E16="",LEN(TRIM('Raw Data'!E16))=0),"",IF(AND(LEN('Raw Data'!E16) <= 255,LEN('Raw Data'!E16)> 0),"",_xlfn.REGEXEXTRACT(CELL("address",'Raw Data'!E16),"\$([A-Z]+)\$[0-9]+"))),_xlfn.REGEXEXTRACT(CELL("address",'Raw Data'!E16),"\$([A-Z]+)\$[0-9]+"))} | F16: {=IFERROR(IF(OR('Raw Data'!F16="",LEN(TRIM('Raw Data'!F16))=0),"",IF(AND(LEN('Raw Data'!F16) <= 50,LEN('Raw Data'!F16)> 0),"",_xlfn.REGEXEXTRACT(CELL("address",'Raw Data'!F16),"\$([A-Z]+)\$[0-9]+"))),_xlfn.REGEXEXTRACT(CELL("address",'Raw Data'!F16),"\$([A-Z]+)\$[0-9]+"))} | G16: {=IFERROR(IF(OR('Raw Data'!G16="",LEN(TRIM('Raw Data'!G16))=0),"",IF(AND(LEN('Raw Data'!G16) <= 255,LEN('Raw Data'!G16)> 0),"",_xlfn.REGEXEXTRACT(CELL("address",'Raw Data'!G16),"\$([A-Z]+)\$[0-9]+"))),_xlfn.REGEXEXTRACT(CELL("address",'Raw Data'!G16),"\$([A-Z]+)\$[0-9]+"))} | H16: {=IFERROR(IF(OR('Raw Data'!H16="",LEN(TRIM('Raw Data'!H16))=0),"",IF(AND(LEN('Raw Data'!H16) <= 255,LEN('Raw Data'!H16)> 0),"",_xlfn.REGEXEXTRACT(CELL("address",'Raw Data'!H16),"\$([A-Z]+)\$[0-9]+"))),_xlfn.REGEXEXTRACT(CELL("address",'Raw Data'!H16),"\$([A-Z]+)\$[0-9]+"))} | I16: {=IFERROR(IF(OR('Raw Data'!I16="",LEN(TRIM('Raw Data'!I16))=0),"",IF(AND(LEN('Raw Data'!I16) <= 255,LEN('Raw Data'!I16)> 0),"",_xlfn.REGEXEXTRACT(CELL("address",'Raw Data'!I16),"\$([A-Z]+)\$[0-9]+"))),_xlfn.REGEXEXTRACT(CELL("address",'Raw Data'!I16),"\$([A-Z]+)\$[0-9]+"))} | J16: {=IFERROR(IF(OR('Raw Data'!J16="",LEN(TRIM('Raw Data'!J16))=0),"",IF(AND(LEN('Raw Data'!J16) <= 255,LEN('Raw Data'!J16)> 0),"",_xlfn.REGEXEXTRACT(CELL("address",'Raw Data'!J16),"\$([A-Z]+)\$[0-9]+"))),_xlfn.REGEXEXTRACT(CELL("address",'Raw Data'!J16),"\$([A-Z]+)\$[0-9]+"))} | K16: {=IFERROR(IF(OR('Raw Data'!K16="",LEN(TRIM('Raw Data'!K16))=0),"",IF(AND(LEN('Raw Data'!K16) <= 10,LEN('Raw Data'!K16)> 0),"",_xlfn.REGEXEXTRACT(CELL("address",'Raw Data'!K16),"\$([A-Z]+)\$[0-9]+"))),_xlfn.REGEXEXTRACT(CELL("address",'Raw Data'!K16),"\$([A-Z]+)\$[0-9]+"))} | L16: {=IFERROR(IF(OR('Raw Data'!L16="",LEN(TRIM('Raw Data'!L16))=0),"",IF(AND(ISNUMBER('Raw Data'!L16), IFERROR('Raw Data'!L16 = ROUND('Raw Data'!L16, 2),FALSE)),"",_xlfn.REGEXEXTRACT(CELL("address",L16), "\$([A-Z]+)\$[0-9]+"))),_xlfn.REGEXEXTRACT(CELL("address",L16), "\$([A-Z]+)\$[0-9]+"))} | M16: {=IFERROR(IF(OR('Raw Data'!M16="",LEN(TRIM('Raw Data'!M16))=0),"",IF(AND(ISNUMBER('Raw Data'!M16), IFERROR('Raw Data'!M16 = ROUND('Raw Data'!M16, 2),FALSE)),"",_xlfn.REGEXEXTRACT(CELL("address",M16), "\$([A-Z]+)\$[0-9]+"))),_xlfn.REGEXEXTRACT(CELL("address",M16), "\$([A-Z]+)\$[0-9]+"))} | N16: {=IFERROR(IF(OR('Raw Data'!N16="",LEN(TRIM('Raw Data'!N16))=0),"",IF(AND(ISNUMBER('Raw Data'!N16), IFERROR('Raw Data'!N16 = ROUND('Raw Data'!N16, 2),FALSE)),"",_xlfn.REGEXEXTRACT(CELL("address",N16), "\$([A-Z]+)\$[0-9]+"))),_xlfn.REGEXEXTRACT(CELL("address",N16), "\$([A-Z]+)\$[0-9]+"))}
C17: {=IFERROR(IF(OR('Raw Data'!C17="",LEN(TRIM('Raw Data'!C17))=0),"",IF(AND(LEN('Raw Data'!C17) <= 20,LEN('Raw Data'!C17)> 0),"",_xlfn.REGEXEXTRACT(CELL("address",'Raw Data'!C17),"\$([A-Z]+)\$[0-9]+"))),_xlfn.REGEXEXTRACT(CELL("address",'Raw Data'!C17),"\$([A-Z]+)\$[0-9]+"))} | D17: {=IFERROR(IF(OR('Raw Data'!D17="",LEN(TRIM('Raw Data'!D17))=0),"",IF(AND(LEN('Raw Data'!D17) <= 255,LEN('Raw Data'!D17)> 0),"",_xlfn.REGEXEXTRACT(CELL("address",'Raw Data'!D17),"\$([A-Z]+)\$[0-9]+"))),_xlfn.REGEXEXTRACT(CELL("address",'Raw Data'!D17),"\$([A-Z]+)\$[0-9]+"))} | E17: {=IFERROR(IF(OR('Raw Data'!E17="",LEN(TRIM('Raw Data'!E17))=0),"",IF(AND(LEN('Raw Data'!E17) <= 255,LEN('Raw Data'!E17)> 0),"",_xlfn.REGEXEXTRACT(CELL("address",'Raw Data'!E17),"\$([A-Z]+)\$[0-9]+"))),_xlfn.REGEXEXTRACT(CELL("address",'Raw Data'!E17),"\$([A-Z]+)\$[0-9]+"))} | F17: {=IFERROR(IF(OR('Raw Data'!F17="",LEN(TRIM('Raw Data'!F17))=0),"",IF(AND(LEN('Raw Data'!F17) <= 50,LEN('Raw Data'!F17)> 0),"",_xlfn.REGEXEXTRACT(CELL("address",'Raw Data'!F17),"\$([A-Z]+)\$[0-9]+"))),_xlfn.REGEXEXTRACT(CELL("address",'Raw Data'!F17),"\$([A-Z]+)\$[0-9]+"))} | G17: {=IFERROR(IF(OR('Raw Data'!G17="",LEN(TRIM('Raw Data'!G17))=0),"",IF(AND(LEN('Raw Data'!G17) <= 255,LEN('Raw Data'!G17)> 0),"",_xlfn.REGEXEXTRACT(CELL("address",'Raw Data'!G17),"\$([A-Z]+)\$[0-9]+"))),_xlfn.REGEXEXTRACT(CELL("address",'Raw Data'!G17),"\$([A-Z]+)\$[0-9]+"))} | H17: {=IFERROR(IF(OR('Raw Data'!H17="",LEN(TRIM('Raw Data'!H17))=0),"",IF(AND(LEN('Raw Data'!H17) <= 255,LEN('Raw Data'!H17)> 0),"",_xlfn.REGEXEXTRACT(CELL("address",'Raw Data'!H17),"\$([A-Z]+)\$[0-9]+"))),_xlfn.REGEXEXTRACT(CELL("address",'Raw Data'!H17),"\$([A-Z]+)\$[0-9]+"))} | I17: {=IFERROR(IF(OR('Raw Data'!I17="",LEN(TRIM('Raw Data'!I17))=0),"",IF(AND(LEN('Raw Data'!I17) <= 255,LEN('Raw Data'!I17)> 0),"",_xlfn.REGEXEXTRACT(CELL("address",'Raw Data'!I17),"\$([A-Z]+)\$[0-9]+"))),_xlfn.REGEXEXTRACT(CELL("address",'Raw Data'!I17),"\$([A-Z]+)\$[0-9]+"))} | J17: {=IFERROR(IF(OR('Raw Data'!J17="",LEN(TRIM('Raw Data'!J17))=0),"",IF(AND(LEN('Raw Data'!J17) <= 255,LEN('Raw Data'!J17)> 0),"",_xlfn.REGEXEXTRACT(CELL("address",'Raw Data'!J17),"\$([A-Z]+)\$[0-9]+"))),_xlfn.REGEXEXTRACT(CELL("address",'Raw Data'!J17),"\$([A-Z]+)\$[0-9]+"))} | K17: {=IFERROR(IF(OR('Raw Data'!K17="",LEN(TRIM('Raw Data'!K17))=0),"",IF(AND(LEN('Raw Data'!K17) <= 10,LEN('Raw Data'!K17)> 0),"",_xlfn.REGEXEXTRACT(CELL("address",'Raw Data'!K17),"\$([A-Z]+)\$[0-9]+"))),_xlfn.REGEXEXTRACT(CELL("address",'Raw Data'!K17),"\$([A-Z]+)\$[0-9]+"))} | L17: {=IFERROR(IF(OR('Raw Data'!L17="",LEN(TRIM('Raw Data'!L17))=0),"",IF(AND(ISNUMBER('Raw Data'!L17), IFERROR('Raw Data'!L17 = ROUND('Raw Data'!L17, 2),FALSE)),"",_xlfn.REGEXEXTRACT(CELL("address",L17), "\$([A-Z]+)\$[0-9]+"))),_xlfn.REGEXEXTRACT(CELL("address",L17), "\$([A-Z]+)\$[0-9]+"))} | M17: {=IFERROR(IF(OR('Raw Data'!M17="",LEN(TRIM('Raw Data'!M17))=0),"",IF(AND(ISNUMBER('Raw Data'!M17), IFERROR('Raw Data'!M17 = ROUND('Raw Data'!M17, 2),FALSE)),"",_xlfn.REGEXEXTRACT(CELL("address",M17), "\$([A-Z]+)\$[0-9]+"))),_xlfn.REGEXEXTRACT(CELL("address",M17), "\$([A-Z]+)\$[0-9]+"))} | N17: {=IFERROR(IF(OR('Raw Data'!N17="",LEN(TRIM('Raw Data'!N17))=0),"",IF(AND(ISNUMBER('Raw Data'!N17), IFERROR('Raw Data'!N17 = ROUND('Raw Data'!N17, 2),FALSE)),"",_xlfn.REGEXEXTRACT(CELL("address",N17), "\$([A-Z]+)\$[0-9]+"))),_xlfn.REGEXEXTRACT(CELL("address",N17), "\$([A-Z]+)\$[0-9]+"))}
C18: {=IFERROR(IF(OR('Raw Data'!C18="",LEN(TRIM('Raw Data'!C18))=0),"",IF(AND(LEN('Raw Data'!C18) <= 20,LEN('Raw Data'!C18)> 0),"",_xlfn.REGEXEXTRACT(CELL("address",'Raw Data'!C18),"\$([A-Z]+)\$[0-9]+"))),_xlfn.REGEXEXTRACT(CELL("address",'Raw Data'!C18),"\$([A-Z]+)\$[0-9]+"))} | D18: {=IFERROR(IF(OR('Raw Data'!D18="",LEN(TRIM('Raw Data'!D18))=0),"",IF(AND(LEN('Raw Data'!D18) <= 255,LEN('Raw Data'!D18)> 0),"",_xlfn.REGEXEXTRACT(CELL("address",'Raw Data'!D18),"\$([A-Z]+)\$[0-9]+"))),_xlfn.REGEXEXTRACT(CELL("address",'Raw Data'!D18),"\$([A-Z]+)\$[0-9]+"))} | E18: {=IFERROR(IF(OR('Raw Data'!E18="",LEN(TRIM('Raw Data'!E18))=0),"",IF(AND(LEN('Raw Data'!E18) <= 255,LEN('Raw Data'!E18)> 0),"",_xlfn.REGEXEXTRACT(CELL("address",'Raw Data'!E18),"\$([A-Z]+)\$[0-9]+"))),_xlfn.REGEXEXTRACT(CELL("address",'Raw Data'!E18),"\$([A-Z]+)\$[0-9]+"))} | F18: {=IFERROR(IF(OR('Raw Data'!F18="",LEN(TRIM('Raw Data'!F18))=0),"",IF(AND(LEN('Raw Data'!F18) <= 50,LEN('Raw Data'!F18)> 0),"",_xlfn.REGEXEXTRACT(CELL("address",'Raw Data'!F18),"\$([A-Z]+)\$[0-9]+"))),_xlfn.REGEXEXTRACT(CELL("address",'Raw Data'!F18),"\$([A-Z]+)\$[0-9]+"))} | G18: {=IFERROR(IF(OR('Raw Data'!G18="",LEN(TRIM('Raw Data'!G18))=0),"",IF(AND(LEN('Raw Data'!G18) <= 255,LEN('Raw Data'!G18)> 0),"",_xlfn.REGEXEXTRACT(CELL("address",'Raw Data'!G18),"\$([A-Z]+)\$[0-9]+"))),_xlfn.REGEXEXTRACT(CELL("address",'Raw Data'!G18),"\$([A-Z]+)\$[0-9]+"))} | H18: {=IFERROR(IF(OR('Raw Data'!H18="",LEN(TRIM('Raw Data'!H18))=0),"",IF(AND(LEN('Raw Data'!H18) <= 255,LEN('Raw Data'!H18)> 0),"",_xlfn.REGEXEXTRACT(CELL("address",'Raw Data'!H18),"\$([A-Z]+)\$[0-9]+"))),_xlfn.REGEXEXTRACT(CELL("address",'Raw Data'!H18),"\$([A-Z]+)\$[0-9]+"))} | I18: {=IFERROR(IF(OR('Raw Data'!I18="",LEN(TRIM('Raw Data'!I18))=0),"",IF(AND(LEN('Raw Data'!I18) <= 255,LEN('Raw Data'!I18)> 0),"",_xlfn.REGEXEXTRACT(CELL("address",'Raw Data'!I18),"\$([A-Z]+)\$[0-9]+"))),_xlfn.REGEXEXTRACT(CELL("address",'Raw Data'!I18),"\$([A-Z]+)\$[0-9]+"))} | J18: {=IFERROR(IF(OR('Raw Data'!J18="",LEN(TRIM('Raw Data'!J18))=0),"",IF(AND(LEN('Raw Data'!J18) <= 255,LEN('Raw Data'!J18)> 0),"",_xlfn.REGEXEXTRACT(CELL("address",'Raw Data'!J18),"\$([A-Z]+)\$[0-9]+"))),_xlfn.REGEXEXTRACT(CELL("address",'Raw Data'!J18),"\$([A-Z]+)\$[0-9]+"))} | K18: {=IFERROR(IF(OR('Raw Data'!K18="",LEN(TRIM('Raw Data'!K18))=0),"",IF(AND(LEN('Raw Data'!K18) <= 10,LEN('Raw Data'!K18)> 0),"",_xlfn.REGEXEXTRACT(CELL("address",'Raw Data'!K18),"\$([A-Z]+)\$[0-9]+"))),_xlfn.REGEXEXTRACT(CELL("address",'Raw Data'!K18),"\$([A-Z]+)\$[0-9]+"))} | L18: {=IFERROR(IF(OR('Raw Data'!L18="",LEN(TRIM('Raw Data'!L18))=0),"",IF(AND(ISNUMBER('Raw Data'!L18), IFERROR('Raw Data'!L18 = ROUND('Raw Data'!L18, 2),FALSE)),"",_xlfn.REGEXEXTRACT(CELL("address",L18), "\$([A-Z]+)\$[0-9]+"))),_xlfn.REGEXEXTRACT(CELL("address",L18), "\$([A-Z]+)\$[0-9]+"))} | M18: {=IFERROR(IF(OR('Raw Data'!M18="",LEN(TRIM('Raw Data'!M18))=0),"",IF(AND(ISNUMBER('Raw Data'!M18), IFERROR('Raw Data'!M18 = ROUND('Raw Data'!M18, 2),FALSE)),"",_xlfn.REGEXEXTRACT(CELL("address",M18), "\$([A-Z]+)\$[0-9]+"))),_xlfn.REGEXEXTRACT(CELL("address",M18), "\$([A-Z]+)\$[0-9]+"))} | N18: {=IFERROR(IF(OR('Raw Data'!N18="",LEN(TRIM('Raw Data'!N18))=0),"",IF(AND(ISNUMBER('Raw Data'!N18), IFERROR('Raw Data'!N18 = ROUND('Raw Data'!N18, 2),FALSE)),"",_xlfn.REGEXEXTRACT(CELL("address",N18), "\$([A-Z]+)\$[0-9]+"))),_xlfn.REGEXEXTRACT(CELL("address",N18), "\$([A-Z]+)\$[0-9]+"))}
C19: {=IFERROR(IF(OR('Raw Data'!C19="",LEN(TRIM('Raw Data'!C19))=0),"",IF(AND(LEN('Raw Data'!C19) <= 20,LEN('Raw Data'!C19)> 0),"",_xlfn.REGEXEXTRACT(CELL("address",'Raw Data'!C19),"\$([A-Z]+)\$[0-9]+"))),_xlfn.REGEXEXTRACT(CELL("address",'Raw Data'!C19),"\$([A-Z]+)\$[0-9]+"))} | D19: {=IFERROR(IF(OR('Raw Data'!D19="",LEN(TRIM('Raw Data'!D19))=0),"",IF(AND(LEN('Raw Data'!D19) <= 255,LEN('Raw Data'!D19)> 0),"",_xlfn.REGEXEXTRACT(CELL("address",'Raw Data'!D19),"\$([A-Z]+)\$[0-9]+"))),_xlfn.REGEXEXTRACT(CELL("address",'Raw Data'!D19),"\$([A-Z]+)\$[0-9]+"))} | E19: {=IFERROR(IF(OR('Raw Data'!E19="",LEN(TRIM('Raw Data'!E19))=0),"",IF(AND(LEN('Raw Data'!E19) <= 255,LEN('Raw Data'!E19)> 0),"",_xlfn.REGEXEXTRACT(CELL("address",'Raw Data'!E19),"\$([A-Z]+)\$[0-9]+"))),_xlfn.REGEXEXTRACT(CELL("address",'Raw Data'!E19),"\$([A-Z]+)\$[0-9]+"))} | F19: {=IFERROR(IF(OR('Raw Data'!F19="",LEN(TRIM('Raw Data'!F19))=0),"",IF(AND(LEN('Raw Data'!F19) <= 50,LEN('Raw Data'!F19)> 0),"",_xlfn.REGEXEXTRACT(CELL("address",'Raw Data'!F19),"\$([A-Z]+)\$[0-9]+"))),_xlfn.REGEXEXTRACT(CELL("address",'Raw Data'!F19),"\$([A-Z]+)\$[0-9]+"))} | G19: {=IFERROR(IF(OR('Raw Data'!G19="",LEN(TRIM('Raw Data'!G19))=0),"",IF(AND(LEN('Raw Data'!G19) <= 255,LEN('Raw Data'!G19)> 0),"",_xlfn.REGEXEXTRACT(CELL("address",'Raw Data'!G19),"\$([A-Z]+)\$[0-9]+"))),_xlfn.REGEXEXTRACT(CELL("address",'Raw Data'!G19),"\$([A-Z]+)\$[0-9]+"))} | H19: {=IFERROR(IF(OR('Raw Data'!H19="",LEN(TRIM('Raw Data'!H19))=0),"",IF(AND(LEN('Raw Data'!H19) <= 255,LEN('Raw Data'!H19)> 0),"",_xlfn.REGEXEXTRACT(CELL("address",'Raw Data'!H19),"\$([A-Z]+)\$[0-9]+"))),_xlfn.REGEXEXTRACT(CELL("address",'Raw Data'!H19),"\$([A-Z]+)\$[0-9]+"))} | I19: {=IFERROR(IF(OR('Raw Data'!I19="",LEN(TRIM('Raw Data'!I19))=0),"",IF(AND(LEN('Raw Data'!I19) <= 255,LEN('Raw Data'!I19)> 0),"",_xlfn.REGEXEXTRACT(CELL("address",'Raw Data'!I19),"\$([A-Z]+)\$[0-9]+"))),_xlfn.REGEXEXTRACT(CELL("address",'Raw Data'!I19),"\$([A-Z]+)\$[0-9]+"))} | J19: {=IFERROR(IF(OR('Raw Data'!J19="",LEN(TRIM('Raw Data'!J19))=0),"",IF(AND(LEN('Raw Data'!J19) <= 255,LEN('Raw Data'!J19)> 0),"",_xlfn.REGEXEXTRACT(CELL("address",'Raw Data'!J19),"\$([A-Z]+)\$[0-9]+"))),_xlfn.REGEXEXTRACT(CELL("address",'Raw Data'!J19),"\$([A-Z]+)\$[0-9]+"))} | K19: {=IFERROR(IF(OR('Raw Data'!K19="",LEN(TRIM('Raw Data'!K19))=0),"",IF(AND(LEN('Raw Data'!K19) <= 10,LEN('Raw Data'!K19)> 0),"",_xlfn.REGEXEXTRACT(CELL("address",'Raw Data'!K19),"\$([A-Z]+)\$[0-9]+"))),_xlfn.REGEXEXTRACT(CELL("address",'Raw Data'!K19),"\$([A-Z]+)\$[0-9]+"))} | L19: {=IFERROR(IF(OR('Raw Data'!L19="",LEN(TRIM('Raw Data'!L19))=0),"",IF(AND(ISNUMBER('Raw Data'!L19), IFERROR('Raw Data'!L19 = ROUND('Raw Data'!L19, 2),FALSE)),"",_xlfn.REGEXEXTRACT(CELL("address",L19), "\$([A-Z]+)\$[0-9]+"))),_xlfn.REGEXEXTRACT(CELL("address",L19), "\$([A-Z]+)\$[0-9]+"))} | M19: {=IFERROR(IF(OR('Raw Data'!M19="",LEN(TRIM('Raw Data'!M19))=0),"",IF(AND(ISNUMBER('Raw Data'!M19), IFERROR('Raw Data'!M19 = ROUND('Raw Data'!M19, 2),FALSE)),"",_xlfn.REGEXEXTRACT(CELL("address",M19), "\$([A-Z]+)\$[0-9]+"))),_xlfn.REGEXEXTRACT(CELL("address",M19), "\$([A-Z]+)\$[0-9]+"))} | N19: {=IFERROR(IF(OR('Raw Data'!N19="",LEN(TRIM('Raw Data'!N19))=0),"",IF(AND(ISNUMBER('Raw Data'!N19), IFERROR('Raw Data'!N19 = ROUND('Raw Data'!N19, 2),FALSE)),"",_xlfn.REGEXEXTRACT(CELL("address",N19), "\$([A-Z]+)\$[0-9]+"))),_xlfn.REGEXEXTRACT(CELL("address",N19), "\$([A-Z]+)\$[0-9]+"))}
C20: {=IFERROR(IF(OR('Raw Data'!C20="",LEN(TRIM('Raw Data'!C20))=0),"",IF(AND(LEN('Raw Data'!C20) <= 20,LEN('Raw Data'!C20)> 0),"",_xlfn.REGEXEXTRACT(CELL("address",'Raw Data'!C20),"\$([A-Z]+)\$[0-9]+"))),_xlfn.REGEXEXTRACT(CELL("address",'Raw Data'!C20),"\$([A-Z]+)\$[0-9]+"))} | D20: {=IFERROR(IF(OR('Raw Data'!D20="",LEN(TRIM('Raw Data'!D20))=0),"",IF(AND(LEN('Raw Data'!D20) <= 255,LEN('Raw Data'!D20)> 0),"",_xlfn.REGEXEXTRACT(CELL("address",'Raw Data'!D20),"\$([A-Z]+)\$[0-9]+"))),_xlfn.REGEXEXTRACT(CELL("address",'Raw Data'!D20),"\$([A-Z]+)\$[0-9]+"))} | E20: {=IFERROR(IF(OR('Raw Data'!E20="",LEN(TRIM('Raw Data'!E20))=0),"",IF(AND(LEN('Raw Data'!E20) <= 255,LEN('Raw Data'!E20)> 0),"",_xlfn.REGEXEXTRACT(CELL("address",'Raw Data'!E20),"\$([A-Z]+)\$[0-9]+"))),_xlfn.REGEXEXTRACT(CELL("address",'Raw Data'!E20),"\$([A-Z]+)\$[0-9]+"))} | F20: {=IFERROR(IF(OR('Raw Data'!F20="",LEN(TRIM('Raw Data'!F20))=0),"",IF(AND(LEN('Raw Data'!F20) <= 50,LEN('Raw Data'!F20)> 0),"",_xlfn.REGEXEXTRACT(CELL("address",'Raw Data'!F20),"\$([A-Z]+)\$[0-9]+"))),_xlfn.REGEXEXTRACT(CELL("address",'Raw Data'!F20),"\$([A-Z]+)\$[0-9]+"))} | G20: {=IFERROR(IF(OR('Raw Data'!G20="",LEN(TRIM('Raw Data'!G20))=0),"",IF(AND(LEN('Raw Data'!G20) <= 255,LEN('Raw Data'!G20)> 0),"",_xlfn.REGEXEXTRACT(CELL("address",'Raw Data'!G20),"\$([A-Z]+)\$[0-9]+"))),_xlfn.REGEXEXTRACT(CELL("address",'Raw Data'!G20),"\$([A-Z]+)\$[0-9]+"))} | H20: {=IFERROR(IF(OR('Raw Data'!H20="",LEN(TRIM('Raw Data'!H20))=0),"",IF(AND(LEN('Raw Data'!H20) <= 255,LEN('Raw Data'!H20)> 0),"",_xlfn.REGEXEXTRACT(CELL("address",'Raw Data'!H20),"\$([A-Z]+)\$[0-9]+"))),_xlfn.REGEXEXTRACT(CELL("address",'Raw Data'!H20),"\$([A-Z]+)\$[0-9]+"))} | I20: {=IFERROR(IF(OR('Raw Data'!I20="",LEN(TRIM('Raw Data'!I20))=0),"",IF(AND(LEN('Raw Data'!I20) <= 255,LEN('Raw Data'!I20)> 0),"",_xlfn.REGEXEXTRACT(CELL("address",'Raw Data'!I20),"\$([A-Z]+)\$[0-9]+"))),_xlfn.REGEXEXTRACT(CELL("address",'Raw Data'!I20),"\$([A-Z]+)\$[0-9]+"))} | J20: {=IFERROR(IF(OR('Raw Data'!J20="",LEN(TRIM('Raw Data'!J20))=0),"",IF(AND(LEN('Raw Data'!J20) <= 255,LEN('Raw Data'!J20)> 0),"",_xlfn.REGEXEXTRACT(CELL("address",'Raw Data'!J20),"\$([A-Z]+)\$[0-9]+"))),_xlfn.REGEXEXTRACT(CELL("address",'Raw Data'!J20),"\$([A-Z]+)\$[0-9]+"))} | K20: {=IFERROR(IF(OR('Raw Data'!K20="",LEN(TRIM('Raw Data'!K20))=0),"",IF(AND(LEN('Raw Data'!K20) <= 10,LEN('Raw Data'!K20)> 0),"",_xlfn.REGEXEXTRACT(CELL("address",'Raw Data'!K20),"\$([A-Z]+)\$[0-9]+"))),_xlfn.REGEXEXTRACT(CELL("address",'Raw Data'!K20),"\$([A-Z]+)\$[0-9]+"))} | L20: {=IFERROR(IF(OR('Raw Data'!L20="",LEN(TRIM('Raw Data'!L20))=0),"",IF(AND(ISNUMBER('Raw Data'!L20), IFERROR('Raw Data'!L20 = ROUND('Raw Data'!L20, 2),FALSE)),"",_xlfn.REGEXEXTRACT(CELL("address",L20), "\$([A-Z]+)\$[0-9]+"))),_xlfn.REGEXEXTRACT(CELL("address",L20), "\$([A-Z]+)\$[0-9]+"))} | M20: {=IFERROR(IF(OR('Raw Data'!M20="",LEN(TRIM('Raw Data'!M20))=0),"",IF(AND(ISNUMBER('Raw Data'!M20), IFERROR('Raw Data'!M20 = ROUND('Raw Data'!M20, 2),FALSE)),"",_xlfn.REGEXEXTRACT(CELL("address",M20), "\$([A-Z]+)\$[0-9]+"))),_xlfn.REGEXEXTRACT(CELL("address",M20), "\$([A-Z]+)\$[0-9]+"))} | N20: {=IFERROR(IF(OR('Raw Data'!N20="",LEN(TRIM('Raw Data'!N20))=0),"",IF(AND(ISNUMBER('Raw Data'!N20), IFERROR('Raw Data'!N20 = ROUND('Raw Data'!N20, 2),FALSE)),"",_xlfn.REGEXEXTRACT(CELL("address",N20), "\$([A-Z]+)\$[0-9]+"))),_xlfn.REGEXEXTRACT(CELL("address",N20), "\$([A-Z]+)\$[0-9]+"))}
