Workbook

Sheet Raw Data
B10: C1 | C10: C2 | D10: C3 | E10: C4 | F10: C5 | G10: C6 | H10: C7 | I10: C8 | J10: C9 | K10: C10 | L10: C11 | M10: C12 | N10: C13 | O10: C14 | P10: C15 | Q10: C16 | R10: C17 | S10: C18 | T10: C19 | U10: C20 | V10: C21 | W10: C22 | X10: C23 | Y10: C24 | Z10: C25 | AA10: C26 | AB10: C27 | AC10: C28 | AD10: C29 | AE10: C30 | AF10: C31 | AG10: C32 | AH10: C33 | AI10: C34 | AJ10: C35 | AK10: C36 | AL10: C37 | AM10: C38 | AN10: C39 | AO10: C40 | AP10: C41
P11: 0 | Q11: 0 | Y11: 0 | Z11: 0 | AG11: 0 | AH11: 0 | AI11: 0 | AJ11: 0 | AP11: 0
P12: 0 | Q12: 0 | Y12: 0 | Z12: 0 | AG12: 0 | AH12: 0 | AI12: 0 | AJ12: 0 | AP12: 0
P13: 0 | Q13: 0 | Y13: 0 | Z13: 0 | AG13: 0 | AH13: 0 | AI13: 0 | AJ13: 0 | AP13: 0
P14: 0 | Q14: 0 | Y14: 0 | Z14: 0 | AG14: 0 | AH14: 0 | AI14: 0 | AJ14: 0 | AP14: 0
P15: 0 | Q15: 0 | Y15: 0 | Z15: 0 | AG15: 0 | AH15: 0 | AI15: 0 | AJ15: 0 | AP15: 0
P16: 0 | Q16: 0 | Y16: 0 | Z16: 0 | AG16: 0 | AH16: 0 | AI16: 0 | AJ16: 0 | AP16: 0
P17: 0 | Q17: 0 | Y17: 0 | Z17: 0 | AG17: 0 | AH17: 0 | AI17: 0 | AJ17: 0 | AP17: 0
P18: 0 | Q18: 0 | Y18: 0 | Z18: 0 | AG18: 0 | AH18: 0 | AI18: 0 | AJ18: 0 | AP18: 0
P19: 0 | Q19: 0 | Y19: 0 | Z19: 0 | AA19: 0 | AF19: 0 | AG19: 0 | AH19: 0 | AI19: 0 | AJ19: 0 | AP19: 0
P20: 0 | Q20: 0 | Y20: 0 | Z20: 0 | AG20: 0 | AH20: 0 | AI20: 0 | AJ20: 0 | AP20: 0
P21: 0 | Q21: 0 | Y21: 0 | Z21: 0 | AG21: 0 | AH21: 0 | AI21: 0 | AJ21: 0 | AP21: 0
P22: 0 | Q22: 0 | Y22: 0 | Z22: 0 | AG22: 0 | AH22: 0 | AI22: 0 | AJ22: 0 | AP22: 0
P23: 0 | Q23: 0 | Y23: 0 | Z23: 0 | AG23: 0 | AH23: 0 | AI23: 0 | AJ23: 0 | AP23: 0
P24: 0 | Q24: 0 | Y24: 0 | Z24: 0 | AG24: 0 | AH24: 0 | AI24: 0 | AJ24: 0 | AP24: 0
P25: 0 | Q25: 0 | Y25: 0 | Z25: 0 | AG25: 0 | AH25: 0 | AI25: 0 | AJ25: 0 | AP25: 0
P26: 0 | Q26: 0 | Y26: 0 | Z26: 0 | AG26: 0 | AH26: 0 | AI26: 0 | AJ26: 0 | AP26: 0
P27: 0 | Q27: 0 | Y27: 0 | Z27: 0 | AG27: 0 | AH27: 0 | AI27: 0 | AJ27: 0 | AP27: 0
P28: 0 | Q28: 0 | Y28: 0 | Z28: 0 | AG28: 0 | AH28: 0 | AI28: 0 | AJ28: 0 | AP28: 0
P29: 0 | Q29: 0 | Y29: 0 | Z29: 0 | AG29: 0 | AH29: 0 | AI29: 0 | AJ29: 0 | AP29: 0
P30: 0 | Q30: 0 | Y30: 0 | Z30: 0 | AG30: 0 | AH30: 0 | AI30: 0 | AJ30: 0 | AP30: 0
P31: 0 | Q31: 0 | Y31: 0 | Z31: 0 | AG31: 0 | AH31: 0 | AI31: 0 | AJ31: 0 | AP31: 0
... P42: 0 | Q42: 0 | Y42: 0 | Z42: 0 | AG42: 0 | AH42: 0 | AI42: 0 | AJ42: 0 | AP42: 0
K43: 0 | P43: 0 | Q43: 0 | Y43: 0 | Z43: 0 | AG43: 0 | AH43: 0 | AI43: 0 | AJ43: 0 | AP43: 0
K44: 0 | P44: 0 | Q44: 0 | Y44: 0 | Z44: 0 | AG44: 0 | AH44: 0 | AI44: 0 | AJ44: 0 | AP44: 0
P45: 0 | Q45: 0 | Y45: 0 | Z45: 0 | AG45: 0 | AH45: 0 | AI45: 0 | AJ45: 0 | AP45: 0
P46: 0 | Q46: 0 | Y46: 0 | Z46: 0 | AG46: 0 | AH46: 0 | AI46: 0 | AJ46: 0 | AP46: 0
P47: 0 | Q47: 0 | Y47: 0 | Z47: 0 | AG47: 0 | AH47: 0 | AI47: 0 | AJ47: 0 | AP47: 0
P48: 0 | Q48: 0 | Y48: 0 | Z48: 0 | AG48: 0 | AH48: 0 | AI48: 0 | AJ48: 0 | AP48: 0
P49: 0 | Q49: 0 | Y49: 0 | Z49: 0 | AG49: 0 | AH49: 0 | AI49: 0 | AJ49: 0 | AP49: 0
P50: 0 | Q50: 0 | Y50: 0 | Z50: 0 | AG50: 0 | AH50: 0 | AI50: 0 | AJ50: 0 | AP50: 0
P51: 0 | Q51: 0 | Y51: 0 | Z51: 0 | AG51: 0 | AH51: 0 | AI51: 0 | AJ51: 0 | AP51: 0
Q52: 0 | Y52: 0 | Z52: 0 | AG52: 0 | AH52: 0 | AI52: 0 | AJ52: 0 | AP52: 0
Q53: 0 | Y53: 0 | Z53: 0 | AG53: 0 | AH53: 0 | AI53: 0 | AJ53: 0 | AP53: 0
Q54: 0 | Y54: 0 | Z54: 0 | AG54: 0 | AH54: 0 | AI54: 0 | AJ54: 0 | AP54: 0
Q55: 0 | V55: 0 | W55: 0 | X55: 0 | Y55: 0 | Z55: 0 | AG55: 0 | AH55: 0 | AI55: 0 | AJ55: 0 | AP55: 0
Q56: 0 | V56: 0 | W56: 0 | X56: 0 | Y56: 0 | Z56: 0 | AB56: 0 | AC56: 0 | AD56: 0 | AE56: 0 | AG56: 0 | AH56: 0 | AI56: 0 | AJ56: 0 | AP56: 0
Q57: 0 | V57: 0 | W57: 0 | X57: 0 | Y57: 0 | Z57: 0 | AB57: 0 | AC57: 0 | AD57: 0 | AE57: 0 | AG57: 0 | AH57: 0 | AI57: 0 | AJ57: 0 | AP57: 0
Q58: 0 | V58: 0 | W58: 0 | X58: 0 | Y58: 0 | Z58: 0 | AB58: 0 | AC58: 0 | AD58: 0 | AE58: 0 | AG58: 0 | AH58: 0 | AI58: 0 | AJ58: 0 | AP58: 0
Q59: 0 | V59: 0 | W59: 0 | X59: 0 | Y59: 0 | Z59: 0 | AB59: 0 | AC59: 0 | AD59: 0 | AE59: 0 | AG59: 0 | AH59: 0 | AI59: 0 | AJ59: 0 | AK59: 0 | AL59: 0 | AM59: 0 | AN59: 0 | AP59: 0
...

Sheet Validate_Empty
B9: FALSE | C9: FALSE | D9: FALSE | E9: FALSE | F9: FALSE | G9: FALSE | H9: FALSE | I9: FALSE | J9: FALSE | K9: FALSE | L9: FALSE | M9: FALSE | N9: FALSE | O9: FALSE | P9: FALSE | Q9: FALSE | R9: FALSE | S9: FALSE | T9: FALSE | U9: FALSE | V9: FALSE | W9: FALSE | X9: FALSE | Y9: FALSE | Z9: FALSE | AA9: FALSE | AB9: FALSE | AC9: FALSE | AD9: FALSE | AE9: FALSE | AF9: FALSE | AG9: FALSE | AH9: FALSE | AI9: FALSE | AJ9: FALSE | AK9: FALSE | AL9: FALSE | AM9: FALSE | AN9: FALSE | AO9: FALSE | AP9: FALSE
B10: C1 | C10: C2 | D10: C3 | E10: C4 | F10: C5 | G10: C6 | H10: C7 | I10: C8 | J10: C9 | K10: C10 | L10: C11 | M10: C12 | N10: C13 | O10: C14 | P10: C15 | Q10: C16 | R10: C17 | S10: C18 | T10: C19 | U10: C20 | V10: C21 | W10: C22 | X10: C23 | Y10: C24 | Z10: C25 | AA10: C26 | AB10: C27 | AC10: C28 | AD10: C29 | AE10: C30 | AF10: C31 | AG10: C32 | AH10: C33 | AI10: C34 | AJ10: C35 | AK10: C36 | AL10: C37 | AM10: C38 | AN10: C39 | AO10: C40 | AP10: C41

Sheet Validate_Value
B9: NVARCHAR(255) | C9: NVARCHAR(50) | D9: NVARCHAR(500) | E9: NVARCHAR(50) | F9: NVARCHAR(50) | G9: NVARCHAR(50) | H9: NVARCHAR(50) | I9: NVARCHAR(50) | J9: DECIMAL(13,2) | K9: DECIMAL(13,2) | L9: DECIMAL(13,2) | M9: DECIMAL(13,2) | N9: DECIMAL(13,2) | O9: DATE | P9: DECIMAL(13,2) | Q9: DECIMAL(13,2) | R9: NVARCHAR(50) | S9: NVARCHAR(50) | T9: DECIMAL(13,2) | U9: DECIMAL(13,2) | V9: DECIMAL(13,2) | W9: DECIMAL(13,2) | X9: DECIMAL(13,2) | Y9: DECIMAL(13,2) | Z9: DECIMAL(13,2) | AA9: DECIMAL(13,2) | AB9: DECIMAL(13,2) | AC9: DECIMAL(13,2) | AD9: DECIMAL(13,2) | AE9: DECIMAL(13,2) | AF9: DECIMAL(13,2) | AG9: DECIMAL(13,2) | AH9: DECIMAL(13,2) | AI9: DECIMAL(13,2) | AJ9: DECIMAL(13,2) [Percentage] | AK9: DECIMAL(13,2) | AL9: DECIMAL(13,2) | AM9: DECIMAL(13,2) | AN9: DECIMAL(13,2) | AO9: DECIMAL(13,2) | AP9: DECIMAL(13,2)
B10: C1 | C10: C2 | D10: C3 | E10: C4 | F10: C5 | G10: C6 | H10: C7 | I10: C8 | J10: C9 | K10: C10 | L10: C11 | M10: C12 | N10: C13 | O10: C14 | P10: C15 | Q10: C16 | R10: C17 | S10: C18 | T10: C19 | U10: C20 | V10: C21 | W10: C22 | X10: C23 | Y10: C24 | Z10: C25 | AA10: C26 | AB10: C27 | AC10: C28 | AD10: C29 | AE10: C30 | AF10: C31 | AG10: C32 | AH10: C33 | AI10: C34 | AJ10: C35 | AK10: C36 | AL10: C37 | AM10: C38 | AN10: C39 | AO10: C40 | AP10: C41
B11: {=IFERROR(IF(OR('Raw Data'!B11="",LEN(TRIM('Raw Data'!B11))=0),"",IF(AND(LEN('Raw Data'!B11) <= 255,LEN('Raw Data'!B11)> 0),"",_xlfn.REGEXEXTRACT(CELL("address",'Raw Data'!B11),"\$([A-Z]+)\$[0-9]+"))),_xlfn.REGEXEXTRACT(CELL("address",'Raw Data'!B11),"\$([A-Z]+)\$[0-9]+"))} | C11: {=IFERROR(IF(OR('Raw Data'!C11="",LEN(TRIM('Raw Data'!C11))=0),"",IF(AND(LEN('Raw Data'!C11) <= 50,LEN('Raw Data'!C11)> 0),"",_xlfn.REGEXEXTRACT(CELL("address",'Raw Data'!C11),"\$([A-Z]+)\$[0-9]+"))),_xlfn.REGEXEXTRACT(CELL("address",'Raw Data'!C11),"\$([A-Z]+)\$[0-9]+"))} | D11: {=IFERROR(IF(OR('Raw Data'!D11="",LEN(TRIM('Raw Data'!D11))=0),"",IF(AND(LEN('Raw Data'!D11) <= 500,LEN('Raw Data'!D11)> 0),"",_xlfn.REGEXEXTRACT(CELL("address",'Raw Data'!D11),"\$([A-Z]+)\$[0-9]+"))),_xlfn.REGEXEXTRACT(CELL("address",'Raw Data'!D11),"\$([A-Z]+)\$[0-9]+"))} | E11: {=IFERROR(IF(OR('Raw Data'!E11="",LEN(TRIM('Raw Data'!E11))=0),"",IF(AND(LEN('Raw Data'!E11) <= 50,LEN('Raw Data'!E11)> 0),"",_xlfn.REGEXEXTRACT(CELL("address",'Raw Data'!E11),"\$([A-Z]+)\$[0-9]+"))),_xlfn.REGEXEXTRACT(CELL("address",'Raw Data'!E11),"\$([A-Z]+)\$[0-9]+"))} | F11: {=IFERROR(IF(OR('Raw Data'!F11="",LEN(TRIM('Raw Data'!F11))=0),"",IF(AND(LEN('Raw Data'!F11) <= 50,LEN('Raw Data'!F11)> 0),"",_xlfn.REGEXEXTRACT(CELL("address",'Raw Data'!F11),"\$([A-Z]+)\$[0-9]+"))),_xlfn.REGEXEXTRACT(CELL("address",'Raw Data'!F11),"\$([A-Z]+)\$[0-9]+"))} | G11: {=IFERROR(IF(OR('Raw Data'!G11="",LEN(TRIM('Raw Data'!G11))=0),"",IF(AND(LEN('Raw Data'!G11) <= 50,LEN('Raw Data'!G11)> 0),"",_xlfn.REGEXEXTRACT(CELL("address",'Raw Data'!G11),"\$([A-Z]+)\$[0-9]+"))),_xlfn.REGEXEXTRACT(CELL("address",'Raw Data'!G11),"\$([A-Z]+)\$[0-9]+"))} | H11: {=IFERROR(IF(OR('Raw Data'!H11="",LEN(TRIM('Raw Data'!H11))=0),"",IF(AND(LEN('Raw Data'!H11) <= 50,LEN('Raw Data'!H11)> 0),"",_xlfn.REGEXEXTRACT(CELL("address",'Raw Data'!H11),"\$([A-Z]+)\$[0-9]+"))),_xlfn.REGEXEXTRACT(CELL("address",'Raw Data'!H11),"\$([A-Z]+)\$[0-9]+"))} | I11: {=IFERROR(IF(OR('Raw Data'!I11="",LEN(TRIM('Raw Data'!I11))=0),"",IF(AND(LEN('Raw Data'!I11) <= 50,LEN('Raw Data'!I11)> 0),"",_xlfn.REGEXEXTRACT(CELL("address",'Raw Data'!I11),"\$([A-Z]+)\$[0-9]+"))),_xlfn.REGEXEXTRACT(CELL("address",'Raw Data'!I11),"\$([A-Z]+)\$[0-9]+"))} | J11: {=IFERROR(IF(OR('Raw Data'!J11="",LEN(TRIM('Raw Data'!J11))=0),"",IF(AND(ISNUMBER('Raw Data'!J11), IFERROR('Raw Data'!J11 = ROUND('Raw Data'!J11, 2),FALSE)),"",_xlfn.REGEXEXTRACT(CELL("address",J11), "\$([A-Z]+)\$[0-9]+"))),_xlfn.REGEXEXTRACT(CELL("address",J11), "\$([A-Z]+)\$[0-9]+"))} | K11: {=IFERROR(IF(OR('Raw Data'!K11="",LEN(TRIM('Raw Data'!K11))=0),"",IF(AND(ISNUMBER('Raw Data'!K11), IFERROR('Raw Data'!K11 = ROUND('Raw Data'!K11, 2),FALSE)),"",_xlfn.REGEXEXTRACT(CELL("address",K11), "\$([A-Z]+)\$[0-9]+"))),_xlfn.REGEXEXTRACT(CELL("address",K11), "\$([A-Z]+)\$[0-9]+"))} | L11: {=IFERROR(IF(OR('Raw Data'!L11="",LEN(TRIM('Raw Data'!L11))=0),"",IF(AND(ISNUMBER('Raw Data'!L11), IFERROR('Raw Data'!L11 = ROUND('Raw Data'!L11, 2),FALSE)),"",_xlfn.REGEXEXTRACT(CELL("address",L11), "\$([A-Z]+)\$[0-9]+"))),_xlfn.REGEXEXTRACT(CELL("address",L11), "\$([A-Z]+)\$[0-9]+"))} | M11: {=IFERROR(IF(OR('Raw Data'!M11="",LEN(TRIM('Raw Data'!M11))=0),"",IF(AND(ISNUMBER('Raw Data'!M11), IFERROR('Raw Data'!M11 = ROUND('Raw Data'!M11, 2),FALSE)),"",_xlfn.REGEXEXTRACT(CELL("address",M11), "\$([A-Z]+)\$[0-9]+"))),_xlfn.REGEXEXTRACT(CELL("address",M11), "\$([A-Z]+)\$[0-9]+"))} | N11: {=IFERROR(IF(OR('Raw Data'!N11="",LEN(TRIM('Raw Data'!N11))=0),"",IF(AND(ISNUMBER('Raw Data'!N11), IFERROR('Raw Data'!N11 = ROUND('Raw Data'!N11, 2),FALSE)),"",_xlfn.REGEXEXTRACT(CELL("address",N11), "\$([A-Z]+)\$[0-9]+"))),_xlfn.REGEXEXTRACT(CELL("address",N11), "\$([A-Z]+)\$[0-9]+"))} | O11: {=IFERROR(IF(OR('Raw Data'!O11="",LEN(TRIM('Raw Data'!O11))=0),"",IF(AND(ISNUMBER('Raw Data'!O11),'Raw Data'!O11>=Configuration!$D$2),"",_xlfn.REGEXEXTRACT(CELL("address",'Raw Data'!O11),"\$([A-Z]+)\$[0-9]+"))),_xlfn.REGEXEXTRACT(CELL("address",O11), "\$([A-Z]+)\$[0-9]+"))} | P11: {=IFERROR(IF(OR('Raw Data'!P11="",LEN(TRIM('Raw Data'!P11))=0),"",IF(AND(ISNUMBER('Raw Data'!P11), IFERROR('Raw Data'!P11 = ROUND('Raw Data'!P11, 2),FALSE)),"",_xlfn.REGEXEXTRACT(CELL("address",P11), "\$([A-Z]+)\$[0-9]+"))),_xlfn.REGEXEXTRACT(CELL("address",P11), "\$([A-Z]+)\$[0-9]+"))} | Q11: {=IFERROR(IF(OR('Raw Data'!Q11="",LEN(TRIM('Raw Data'!Q11))=0),"",IF(AND(ISNUMBER('Raw Data'!Q11), IFERROR('Raw Data'!Q11 = ROUND('Raw Data'!Q11, 2),FALSE)),"",_xlfn.REGEXEXTRACT(CELL("address",Q11), "\$([A-Z]+)\$[0-9]+"))),_xlfn.REGEXEXTRACT(CELL("address",Q11), "\$([A-Z]+)\$[0-9]+"))} | R11: {=IFERROR(IF(OR('Raw Data'!R11="",LEN(TRIM('Raw Data'!R11))=0),"",IF(AND(LEN('Raw Data'!R11) <= 50,LEN('Raw Data'!R11)> 0),"",_xlfn.REGEXEXTRACT(CELL("address",'Raw Data'!R11),"\$([A-Z]+)\$[0-9]+"))),_xlfn.REGEXEXTRACT(CELL("address",'Raw Data'!R11),"\$([A-Z]+)\$[0-9]+"))} | S11: {=IFERROR(IF(OR('Raw Data'!S11="",LEN(TRIM('Raw Data'!S11))=0),"",IF(AND(LEN('Raw Data'!S11) <= 50,LEN('Raw Data'!S11)> 0),"",_xlfn.REGEXEXTRACT(CELL("address",'Raw Data'!S11),"\$([A-Z]+)\$[0-9]+"))),_xlfn.REGEXEXTRACT(CELL("address",'Raw Data'!S11),"\$([A-Z]+)\$[0-9]+"))} | T11: {=IFERROR(IF(OR('Raw Data'!T11="",LEN(TRIM('Raw Data'!T11))=0),"",IF(AND(ISNUMBER('Raw Data'!T11), IFERROR('Raw Data'!T11 = ROUND('Raw Data'!T11, 2),FALSE)),"",_xlfn.REGEXEXTRACT(CELL("address",T11), "\$([A-Z]+)\$[0-9]+"))),_xlfn.REGEXEXTRACT(CELL("address",T11), "\$([A-Z]+)\$[0-9]+"))} | U11: {=IFERROR(IF(OR('Raw Data'!U11="",LEN(TRIM('Raw Data'!U11))=0),"",IF(AND(ISNUMBER('Raw Data'!U11), IFERROR('Raw Data'!U11 = ROUND('Raw Data'!U11, 2),FALSE)),"",_xlfn.REGEXEXTRACT(CELL("address",U11), "\$([A-Z]+)\$[0-9]+"))),_xlfn.REGEXEXTRACT(CELL("address",U11), "\$([A-Z]+)\$[0-9]+"))} | V11: {=IFERROR(IF(OR('Raw Data'!V11="",LEN(TRIM('Raw Data'!V11))=0),"",IF(AND(ISNUMBER('Raw Data'!V11), IFERROR('Raw Data'!V11 = ROUND('Raw Data'!V11, 2),FALSE)),"",_xlfn.REGEXEXTRACT(CELL("address",V11), "\$([A-Z]+)\$[0-9]+"))),_xlfn.REGEXEXTRACT(CELL("address",V11), "\$([A-Z]+)\$[0-9]+"))} | W11: {=IFERROR(IF(OR('Raw Data'!W11="",LEN(TRIM('Raw Data'!W11))=0),"",IF(AND(ISNUMBER('Raw Data'!W11), IFERROR('Raw Data'!W11 = ROUND('Raw Data'!W11, 2),FALSE)),"",_xlfn.REGEXEXTRACT(CELL("address",W11), "\$([A-Z]+)\$[0-9]+"))),_xlfn.REGEXEXTRACT(CELL("address",W11), "\$([A-Z]+)\$[0-9]+"))} | X11: {=IFERROR(IF(OR('Raw Data'!X11="",LEN(TRIM('Raw Data'!X11))=0),"",IF(AND(ISNUMBER('Raw Data'!X11), IFERROR('Raw Data'!X11 = ROUND('Raw Data'!X11, 2),FALSE)),"",_xlfn.REGEXEXTRACT(CELL("address",X11), "\$([A-Z]+)\$[0-9]+"))),_xlfn.REGEXEXTRACT(CELL("address",X11), "\$([A-Z]+)\$[0-9]+"))} | Y11: {=IFERROR(IF(OR('Raw Data'!Y11="",LEN(TRIM('Raw Data'!Y11))=0),"",IF(AND(ISNUMBER('Raw Data'!Y11), IFERROR('Raw Data'!Y11 = ROUND('Raw Data'!Y11, 2),FALSE)),"",_xlfn.REGEXEXTRACT(CELL("address",Y11), "\$([A-Z]+)\$[0-9]+"))),_xlfn.REGEXEXTRACT(CELL("address",Y11), "\$([A-Z]+)\$[0-9]+"))} | Z11: {=IFERROR(IF(OR('Raw Data'!Z11="",LEN(TRIM('Raw Data'!Z11))=0),"",IF(AND(ISNUMBER('Raw Data'!Z11), IFERROR('Raw Data'!Z11 = ROUND('Raw Data'!Z11, 2),FALSE)),"",_xlfn.REGEXEXTRACT(CELL("address",Z11), "\$([A-Z]+)\$[0-9]+"))),_xlfn.REGEXEXTRACT(CELL("address",Z11), "\$([A-Z]+)\$[0-9]+"))} | AA11: {=IFERROR(IF(OR('Raw Data'!AA11="",LEN(TRIM('Raw Data'!AA11))=0),"",IF(AND(ISNUMBER('Raw Data'!AA11), IFERROR('Raw Data'!AA11 = ROUND('Raw Data'!AA11, 2),FALSE)),"",_xlfn.REGEXEXTRACT(CELL("address",AA11), "\$([A-Z]+)\$[0-9]+"))),_xlfn.REGEXEXTRACT(CELL("address",AA11), "\$([A-Z]+)\$[0-9]+"))} | ... AI11: {=IFERROR(IF(OR('Raw Data'!AI11="",LEN(TRIM('Raw Data'!AI11))=0),"",IF(AND(ISNUMBER('Raw Data'!AI11), IFERROR('Raw Data'!AI11 = ROUND('Raw Data'!AI11, 2),FALSE)),"",_xlfn.REGEXEXTRACT(CELL("address",AI11), "\$([A-Z]+)\$[0-9]+"))),_xlfn.REGEXEXTRACT(CELL("address",AI11), "\$([A-Z]+)\$[0-9]+"))} | AJ11: {=IFERROR(IF(OR('Raw Data'!AJ11="",LEN(TRIM('Raw Data'!AJ11))=0),"",IF(AND(ISNUMBER('Raw Data'!AJ11), IFERROR('Raw Data'!AJ11 = ROUND('Raw Data'!AJ11, 4),FALSE)),"",_xlfn.REGEXEXTRACT(CELL("address",AJ11), "\$([A-Z]+)\$[0-9]+"))),_xlfn.REGEXEXTRACT(CELL("address",AJ11), "\$([A-Z]+)\$[0-9]+"))} | AK11: {=IFERROR(IF(OR('Raw Data'!AK11="",LEN(TRIM('Raw Data'!AK11))=0),"",IF(AND(ISNUMBER('Raw Data'!AK11), IFERROR('Raw Data'!AK11 = ROUND('Raw Data'!AK11, 2),FALSE)),"",_xlfn.REGEXEXTRACT(CELL("address",AK11), "\$([A-Z]+)\$[0-9]+"))),_xlfn.REGEXEXTRACT(CELL("address",AK11), "\$([A-Z]+)\$[0-9]+"))} | AL11: {=IFERROR(IF(OR('Raw Data'!AL11="",LEN(TRIM('Raw Data'!AL11))=0),"",IF(AND(ISNUMBER('Raw Data'!AL11), IFERROR('Raw Data'!AL11 = ROUND('Raw Data'!AL11, 2),FALSE)),"",_xlfn.REGEXEXTRACT(CELL("address",AL11), "\$([A-Z]+)\$[0-9]+"))),_xlfn.REGEXEXTRACT(CELL("address",AL11), "\$([A-Z]+)\$[0-9]+"))} | AM11: {=IFERROR(IF(OR('Raw Data'!AM11="",LEN(TRIM('Raw Data'!AM11))=0),"",IF(AND(ISNUMBER('Raw Data'!AM11), IFERROR('Raw Data'!AM11 = ROUND('Raw Data'!AM11, 2),FALSE)),"",_xlfn.REGEXEXTRACT(CELL("address",AM11), "\$([A-Z]+)\$[0-9]+"))),_xlfn.REGEXEXTRACT(CELL("address",AM11), "\$([A-Z]+)\$[0-9]+"))} | AN11: {=IFERROR(IF(OR('Raw Data'!AN11="",LEN(TRIM('Raw Data'!AN11))=0),"",IF(AND(ISNUMBER('Raw Data'!AN11), IFERROR('Raw Data'!AN11 = ROUND('Raw Data'!AN11, 2),FALSE)),"",_xlfn.REGEXEXTRACT(CELL("address",AN11), "\$([A-Z]+)\$[0-9]+"))),_xlfn.REGEXEXTRACT(CELL("address",AN11), "\$([A-Z]+)\$[0-9]+"))} | AO11: {=IFERROR(IF(OR('Raw Data'!AO11="",LEN(TRIM('Raw Data'!AO11))=0),"",IF(AND(ISNUMBER('Raw Data'!AO11), IFERROR('Raw Data'!AO11 = ROUND('Raw Data'!AO11, 2),FALSE)),"",_xlfn.REGEXEXTRACT(CELL("address",AO11), "\$([A-Z]+)\$[0-9]+"))),_xlfn.REGEXEXTRACT(CELL("address",AO11), "\$([A-Z]+)\$[0-9]+"))} | AP11: {=IFERROR(IF(OR('Raw Data'!AP11="",LEN(TRIM('Raw Data'!AP11))=0),"",IF(AND(ISNUMBER('Raw Data'!AP11), IFERROR('Raw Data'!AP11 = ROUND('Raw Data'!AP11, 2),FALSE)),"",_xlfn.REGEXEXTRACT(CELL("address",AP11), "\$([A-Z]+)\$[0-9]+"))),_xlfn.REGEXEXTRACT(CELL("address",AP11), "\$([A-Z]+)\$[0-9]+"))}
B12: {=IFERROR(IF(OR('Raw Data'!B12="",LEN(TRIM('Raw Data'!B12))=0),"",IF(AND(LEN('Raw Data'!B12) <= 255,LEN('Raw Data'!B12)> 0),"",_xlfn.REGEXEXTRACT(CELL("address",'Raw Data'!B12),"\$([A-Z]+)\$[0-9]+"))),_xlfn.REGEXEXTRACT(CELL("address",'Raw Data'!B12),"\$([A-Z]+)\$[0-9]+"))} | C12: {=IFERROR(IF(OR('Raw Data'!C12="",LEN(TRIM('Raw Data'!C12))=0),"",IF(AND(LEN('Raw Data'!C12) <= 50,LEN('Raw Data'!C12)> 0),"",_xlfn.REGEXEXTRACT(CELL("address",'Raw Data'!C12),"\$([A-Z]+)\$[0-9]+"))),_xlfn.REGEXEXTRACT(CELL("address",'Raw Data'!C12),"\$([A-Z]+)\$[0-9]+"))} | D12: {=IFERROR(IF(OR('Raw Data'!D12="",LEN(TRIM('Raw Data'!D12))=0),"",IF(AND(LEN('Raw Data'!D12) <= 500,LEN('Raw Data'!D12)> 0),"",_xlfn.REGEXEXTRACT(CELL("address",'Raw Data'!D12),"\$([A-Z]+)\$[0-9]+"))),_xlfn.REGEXEXTRACT(CELL("address",'Raw Data'!D12),"\$([A-Z]+)\$[0-9]+"))} | E12: {=IFERROR(IF(OR('Raw Data'!E12="",LEN(TRIM('Raw Data'!E12))=0),"",IF(AND(LEN('Raw Data'!E12) <= 50,LEN('Raw Data'!E12)> 0),"",_xlfn.REGEXEXTRACT(CELL("address",'Raw Data'!E12),"\$([A-Z]+)\$[0-9]+"))),_xlfn.REGEXEXTRACT(CELL("address",'Raw Data'!E12),"\$([A-Z]+)\$[0-9]+"))} | F12: {=IFERROR(IF(OR('Raw Data'!F12="",LEN(TRIM('Raw Data'!F12))=0),"",IF(AND(LEN('Raw Data'!F12) <= 50,LEN('Raw Data'!F12)> 0),"",_xlfn.REGEXEXTRACT(CELL("address",'Raw Data'!F12),"\$([A-Z]+)\$[0-9]+"))),_xlfn.REGEXEXTRACT(CELL("address",'Raw Data'!F12),"\$([A-Z]+)\$[0-9]+"))} | G12: {=IFERROR(IF(OR('Raw Data'!G12="",LEN(TRIM('Raw Data'!G12))=0),"",IF(AND(LEN('Raw Data'!G12) <= 50,LEN('Raw Data'!G12)> 0),"",_xlfn.REGEXEXTRACT(CELL("address",'Raw Data'!G12),"\$([A-Z]+)\$[0-9]+"))),_xlfn.REGEXEXTRACT(CELL("address",'Raw Data'!G12),"\$([A-Z]+)\$[0-9]+"))} | H12: {=IFERROR(IF(OR('Raw Data'!H12="",LEN(TRIM('Raw Data'!H12))=0),"",IF(AND(LEN('Raw Data'!H12) <= 50,LEN('Raw Data'!H12)> 0),"",_xlfn.REGEXEXTRACT(CELL("address",'Raw Data'!H12),"\$([A-Z]+)\$[0-9]+"))),_xlfn.REGEXEXTRACT(CELL("address",'Raw Data'!H12),"\$([A-Z]+)\$[0-9]+"))} | I12: {=IFERROR(IF(OR('Raw Data'!I12="",LEN(TRIM('Raw Data'!I12))=0),"",IF(AND(LEN('Raw Data'!I12) <= 50,LEN('Raw Data'!I12)> 0),"",_xlfn.REGEXEXTRACT(CELL("address",'Raw Data'!I12),"\$([A-Z]+)\$[0-9]+"))),_xlfn.REGEXEXTRACT(CELL("address",'Raw Data'!I12),"\$([A-Z]+)\$[0-9]+"))} | J12: {=IFERROR(IF(OR('Raw Data'!J12="",LEN(TRIM('Raw Data'!J12))=0),"",IF(AND(ISNUMBER('Raw Data'!J12), IFERROR('Raw Data'!J12 = ROUND('Raw Data'!J12, 2),FALSE)),"",_xlfn.REGEXEXTRACT(CELL("address",J12), "\$([A-Z]+)\$[0-9]+"))),_xlfn.REGEXEXTRACT(CELL("address",J12), "\$([A-Z]+)\$[0-9]+"))} | K12: {=IFERROR(IF(OR('Raw Data'!K12="",LEN(TRIM('Raw Data'!K12))=0),"",IF(AND(ISNUMBER('Raw Data'!K12), IFERROR('Raw Data'!K12 = ROUND('Raw Data'!K12, 2),FALSE)),"",_xlfn.REGEXEXTRACT(CELL("address",K12), "\$([A-Z]+)\$[0-9]+"))),_xlfn.REGEXEXTRACT(CELL("address",K12), "\$([A-Z]+)\$[0-9]+"))} | L12: {=IFERROR(IF(OR('Raw Data'!L12="",LEN(TRIM('Raw Data'!L12))=0),"",IF(AND(ISNUMBER('Raw Data'!L12), IFERROR('Raw Data'!L12 = ROUND('Raw Data'!L12, 2),FALSE)),"",_xlfn.REGEXEXTRACT(CELL("address",L12), "\$([A-Z]+)\$[0-9]+"))),_xlfn.REGEXEXTRACT(CELL("address",L12), "\$([A-Z]+)\$[0-9]+"))} | M12: {=IFERROR(IF(OR('Raw Data'!M12="",LEN(TRIM('Raw Data'!M12))=0),"",IF(AND(ISNUMBER('Raw Data'!M12), IFERROR('Raw Data'!M12 = ROUND('Raw Data'!M12, 2),FALSE)),"",_xlfn.REGEXEXTRACT(CELL("address",M12), "\$([A-Z]+)\$[0-9]+"))),_xlfn.REGEXEXTRACT(CELL("address",M12), "\$([A-Z]+)\$[0-9]+"))} | N12: {=IFERROR(IF(OR('Raw Data'!N12="",LEN(TRIM('Raw Data'!N12))=0),"",IF(AND(ISNUMBER('Raw Data'!N12), IFERROR('Raw Data'!N12 = ROUND('Raw Data'!N12, 2),FALSE)),"",_xlfn.REGEXEXTRACT(CELL("address",N12), "\$([A-Z]+)\$[0-9]+"))),_xlfn.REGEXEXTRACT(CELL("address",N12), "\$([A-Z]+)\$[0-9]+"))} | O12: {=IFERROR(IF(OR('Raw Data'!O12="",LEN(TRIM('Raw Data'!O12))=0),"",IF(AND(ISNUMBER('Raw Data'!O12),'Raw Data'!O12>=Configuration!$D$2),"",_xlfn.REGEXEXTRACT(CELL("address",'Raw Data'!O12),"\$([A-Z]+)\$[0-9]+"))),_xlfn.REGEXEXTRACT(CELL("address",O12), "\$([A-Z]+)\$[0-9]+"))} | P12: {=IFERROR(IF(OR('Raw Data'!P12="",LEN(TRIM('Raw Data'!P12))=0),"",IF(AND(ISNUMBER('Raw Data'!P12), IFERROR('Raw Data'!P12 = ROUND('Raw Data'!P12, 2),FALSE)),"",_xlfn.REGEXEXTRACT(CELL("address",P12), "\$([A-Z]+)\$[0-9]+"))),_xlfn.REGEXEXTRACT(CELL("address",P12), "\$([A-Z]+)\$[0-9]+"))} | Q12: {=IFERROR(IF(OR('Raw Data'!Q12="",LEN(TRIM('Raw Data'!Q12))=0),"",IF(AND(ISNUMBER('Raw Data'!Q12), IFERROR('Raw Data'!Q12 = ROUND('Raw Data'!Q12, 2),FALSE)),"",_xlfn.REGEXEXTRACT(CELL("address",Q12), "\$([A-Z]+)\$[0-9]+"))),_xlfn.REGEXEXTRACT(CELL("address",Q12), "\$([A-Z]+)\$[0-9]+"))} | R12: {=IFERROR(IF(OR('Raw Data'!R12="",LEN(TRIM('Raw Data'!R12))=0),"",IF(AND(LEN('Raw Data'!R12) <= 50,LEN('Raw Data'!R12)> 0),"",_xlfn.REGEXEXTRACT(CELL("address",'Raw Data'!R12),"\$([A-Z]+)\$[0-9]+"))),_xlfn.REGEXEXTRACT(CELL("address",'Raw Data'!R12),"\$([A-Z]+)\$[0-9]+"))} | S12: {=IFERROR(IF(OR('Raw Data'!S12="",LEN(TRIM('Raw Data'!S12))=0),"",IF(AND(LEN('Raw Data'!S12) <= 50,LEN('Raw Data'!S12)> 0),"",_xlfn.REGEXEXTRACT(CELL("address",'Raw Data'!S12),"\$([A-Z]+)\$[0-9]+"))),_xlfn.REGEXEXTRACT(CELL("address",'Raw Data'!S12),"\$([A-Z]+)\$[0-9]+"))} | T12: {=IFERROR(IF(OR('Raw Data'!T12="",LEN(TRIM('Raw Data'!T12))=0),"",IF(AND(ISNUMBER('Raw Data'!T12), IFERROR('Raw Data'!T12 = ROUND('Raw Data'!T12, 2),FALSE)),"",_xlfn.REGEXEXTRACT(CELL("address",T12), "\$([A-Z]+)\$[0-9]+"))),_xlfn.REGEXEXTRACT(CELL("address",T12), "\$([A-Z]+)\$[0-9]+"))} | U12: {=IFERROR(IF(OR('Raw Data'!U12="",LEN(TRIM('Raw Data'!U12))=0),"",IF(AND(ISNUMBER('Raw Data'!U12), IFERROR('Raw Data'!U12 = ROUND('Raw Data'!U12, 2),FALSE)),"",_xlfn.REGEXEXTRACT(CELL("address",U12), "\$([A-Z]+)\$[0-9]+"))),_xlfn.REGEXEXTRACT(CELL("address",U12), "\$([A-Z]+)\$[0-9]+"))} | V12: {=IFERROR(IF(OR('Raw Data'!V12="",LEN(TRIM('Raw Data'!V12))=0),"",IF(AND(ISNUMBER('Raw Data'!V12), IFERROR('Raw Data'!V12 = ROUND('Raw Data'!V12, 2),FALSE)),"",_xlfn.REGEXEXTRACT(CELL("address",V12), "\$([A-Z]+)\$[0-9]+"))),_xlfn.REGEXEXTRACT(CELL("address",V12), "\$([A-Z]+)\$[0-9]+"))} | W12: {=IFERROR(IF(OR('Raw Data'!W12="",LEN(TRIM('Raw Data'!W12))=0),"",IF(AND(ISNUMBER('Raw Data'!W12), IFERROR('Raw Data'!W12 = ROUND('Raw Data'!W12, 2),FALSE)),"",_xlfn.REGEXEXTRACT(CELL("address",W12), "\$([A-Z]+)\$[0-9]+"))),_xlfn.REGEXEXTRACT(CELL("address",W12), "\$([A-Z]+)\$[0-9]+"))} | X12: {=IFERROR(IF(OR('Raw Data'!X12="",LEN(TRIM('Raw Data'!X12))=0),"",IF(AND(ISNUMBER('Raw Data'!X12), IFERROR('Raw Data'!X12 = ROUND('Raw Data'!X12, 2),FALSE)),"",_xlfn.REGEXEXTRACT(CELL("address",X12), "\$([A-Z]+)\$[0-9]+"))),_xlfn.REGEXEXTRACT(CELL("address",X12), "\$([A-Z]+)\$[0-9]+"))} | Y12: {=IFERROR(IF(OR('Raw Data'!Y12="",LEN(TRIM('Raw Data'!Y12))=0),"",IF(AND(ISNUMBER('Raw Data'!Y12), IFERROR('Raw Data'!Y12 = ROUND('Raw Data'!Y12, 2),FALSE)),"",_xlfn.REGEXEXTRACT(CELL("address",Y12), "\$([A-Z]+)\$[0-9]+"))),_xlfn.REGEXEXTRACT(CELL("address",Y12), "\$([A-Z]+)\$[0-9]+"))} | Z12: {=IFERROR(IF(OR('Raw Data'!Z12="",LEN(TRIM('Raw Data'!Z12))=0),"",IF(AND(ISNUMBER('Raw Data'!Z12), IFERROR('Raw Data'!Z12 = ROUND('Raw Data'!Z12, 2),FALSE)),"",_xlfn.REGEXEXTRACT(CELL("address",Z12), "\$([A-Z]+)\$[0-9]+"))),_xlfn.REGEXEXTRACT(CELL("address",Z12), "\$([A-Z]+)\$[0-9]+"))} | AA12: {=IFERROR(IF(OR('Raw Data'!AA12="",LEN(TRIM('Raw Data'!AA12))=0),"",IF(AND(ISNUMBER('Raw Data'!AA12), IFERROR('Raw Data'!AA12 = ROUND('Raw Data'!AA12, 2),FALSE)),"",_xlfn.REGEXEXTRACT(CELL("address",AA12), "\$([A-Z]+)\$[0-9]+"))),_xlfn.REGEXEXTRACT(CELL("address",AA12), "\$([A-Z]+)\$[0-9]+"))} | ... AI12: {=IFERROR(IF(OR('Raw Data'!AI12="",LEN(TRIM('Raw Data'!AI12))=0),"",IF(AND(ISNUMBER('Raw Data'!AI12), IFERROR('Raw Data'!AI12 = ROUND('Raw Data'!AI12, 2),FALSE)),"",_xlfn.REGEXEXTRACT(CELL("address",AI12), "\$([A-Z]+)\$[0-9]+"))),_xlfn.REGEXEXTRACT(CELL("address",AI12), "\$([A-Z]+)\$[0-9]+"))} | AJ12: {=IFERROR(IF(OR('Raw Data'!AJ12="",LEN(TRIM('Raw Data'!AJ12))=0),"",IF(AND(ISNUMBER('Raw Data'!AJ12), IFERROR('Raw Data'!AJ12 = ROUND('Raw Data'!AJ12, 4),FALSE)),"",_xlfn.REGEXEXTRACT(CELL("address",AJ12), "\$([A-Z]+)\$[0-9]+"))),_xlfn.REGEXEXTRACT(CELL("address",AJ12), "\$([A-Z]+)\$[0-9]+"))} | AK12: {=IFERROR(IF(OR('Raw Data'!AK12="",LEN(TRIM('Raw Data'!AK12))=0),"",IF(AND(ISNUMBER('Raw Data'!AK12), IFERROR('Raw Data'!AK12 = ROUND('Raw Data'!AK12, 2),FALSE)),"",_xlfn.REGEXEXTRACT(CELL("address",AK12), "\$([A-Z]+)\$[0-9]+"))),_xlfn.REGEXEXTRACT(CELL("address",AK12), "\$([A-Z]+)\$[0-9]+"))} | AL12: {=IFERROR(IF(OR('Raw Data'!AL12="",LEN(TRIM('Raw Data'!AL12))=0),"",IF(AND(ISNUMBER('Raw Data'!AL12), IFERROR('Raw Data'!AL12 = ROUND('Raw Data'!AL12, 2),FALSE)),"",_xlfn.REGEXEXTRACT(CELL("address",AL12), "\$([A-Z]+)\$[0-9]+"))),_xlfn.REGEXEXTRACT(CELL("address",AL12), "\$([A-Z]+)\$[0-9]+"))} | AM12: {=IFERROR(IF(OR('Raw Data'!AM12="",LEN(TRIM('Raw Data'!AM12))=0),"",IF(AND(ISNUMBER('Raw Data'!AM12), IFERROR('Raw Data'!AM12 = ROUND('Raw Data'!AM12, 2),FALSE)),"",_xlfn.REGEXEXTRACT(CELL("address",AM12), "\$([A-Z]+)\$[0-9]+"))),_xlfn.REGEXEXTRACT(CELL("address",AM12), "\$([A-Z]+)\$[0-9]+"))} | AN12: {=IFERROR(IF(OR('Raw Data'!AN12="",LEN(TRIM('Raw Data'!AN12))=0),"",IF(AND(ISNUMBER('Raw Data'!AN12), IFERROR('Raw Data'!AN12 = ROUND('Raw Data'!AN12, 2),FALSE)),"",_xlfn.REGEXEXTRACT(CELL("address",AN12), "\$([A-Z]+)\$[0-9]+"))),_xlfn.REGEXEXTRACT(CELL("address",AN12), "\$([A-Z]+)\$[0-9]+"))} | AO12: {=IFERROR(IF(OR('Raw Data'!AO12="",LEN(TRIM('Raw Data'!AO12))=0),"",IF(AND(ISNUMBER('Raw Data'!AO12), IFERROR('Raw Data'!AO12 = ROUND('Raw Data'!AO12, 2),FALSE)),"",_xlfn.REGEXEXTRACT(CELL("address",AO12), "\$([A-Z]+)\$[0-9]+"))),_xlfn.REGEXEXTRACT(CELL("address",AO12), "\$([A-Z]+)\$[0-9]+"))} | AP12: {=IFERROR(IF(OR('Raw Data'!AP12="",LEN(TRIM('Raw Data'!AP12))=0),"",IF(AND(ISNUMBER('Raw Data'!AP12), IFERROR('Raw Data'!AP12 = ROUND('Raw Data'!AP12, 2),FALSE)),"",_xlfn.REGEXEXTRACT(CELL("address",AP12), "\$([A-Z]+)\$[0-9]+"))),_xlfn.REGEXEXTRACT(CELL("address",AP12), "\$([A-Z]+)\$[0-9]+"))}
B13: {=IFERROR(IF(OR('Raw Data'!B13="",LEN(TRIM('Raw Data'!B13))=0),"",IF(AND(LEN('Raw Data'!B13) <= 255,LEN('Raw Data'!B13)> 0),"",_xlfn.REGEXEXTRACT(CELL("address",'Raw Data'!B13),"\$([A-Z]+)\$[0-9]+"))),_xlfn.REGEXEXTRACT(CELL("address",'Raw Data'!B13),"\$([A-Z]+)\$[0-9]+"))} | C13: {=IFERROR(IF(OR('Raw Data'!C13="",LEN(TRIM('Raw Data'!C13))=0),"",IF(AND(LEN('Raw Data'!C13) <= 50,LEN('Raw Data'!C13)> 0),"",_xlfn.REGEXEXTRACT(CELL("address",'Raw Data'!C13),"\$([A-Z]+)\$[0-9]+"))),_xlfn.REGEXEXTRACT(CELL("address",'Raw Data'!C13),"\$([A-Z]+)\$[0-9]+"))} | D13: {=IFERROR(IF(OR('Raw Data'!D13="",LEN(TRIM('Raw Data'!D13))=0),"",IF(AND(LEN('Raw Data'!D13) <= 500,LEN('Raw Data'!D13)> 0),"",_xlfn.REGEXEXTRACT(CELL("address",'Raw Data'!D13),"\$([A-Z]+)\$[0-9]+"))),_xlfn.REGEXEXTRACT(CELL("address",'Raw Data'!D13),"\$([A-Z]+)\$[0-9]+"))} | E13: {=IFERROR(IF(OR('Raw Data'!E13="",LEN(TRIM('Raw Data'!E13))=0),"",IF(AND(LEN('Raw Data'!E13) <= 50,LEN('Raw Data'!E13)> 0),"",_xlfn.REGEXEXTRACT(CELL("address",'Raw Data'!E13),"\$([A-Z]+)\$[0-9]+"))),_xlfn.REGEXEXTRACT(CELL("address",'Raw Data'!E13),"\$([A-Z]+)\$[0-9]+"))} | F13: {=IFERROR(IF(OR('Raw Data'!F13="",LEN(TRIM('Raw Data'!F13))=0),"",IF(AND(LEN('Raw Data'!F13) <= 50,LEN('Raw Data'!F13)> 0),"",_xlfn.REGEXEXTRACT(CELL("address",'Raw Data'!F13),"\$([A-Z]+)\$[0-9]+"))),_xlfn.REGEXEXTRACT(CELL("address",'Raw Data'!F13),"\$([A-Z]+)\$[0-9]+"))} | G13: {=IFERROR(IF(OR('Raw Data'!G13="",LEN(TRIM('Raw Data'!G13))=0),"",IF(AND(LEN('Raw Data'!G13) <= 50,LEN('Raw Data'!G13)> 0),"",_xlfn.REGEXEXTRACT(CELL("address",'Raw Data'!G13),"\$([A-Z]+)\$[0-9]+"))),_xlfn.REGEXEXTRACT(CELL("address",'Raw Data'!G13),"\$([A-Z]+)\$[0-9]+"))} | H13: {=IFERROR(IF(OR('Raw Data'!H13="",LEN(TRIM('Raw Data'!H13))=0),"",IF(AND(LEN('Raw Data'!H13) <= 50,LEN('Raw Data'!H13)> 0),"",_xlfn.REGEXEXTRACT(CELL("address",'Raw Data'!H13),"\$([A-Z]+)\$[0-9]+"))),_xlfn.REGEXEXTRACT(CELL("address",'Raw Data'!H13),"\$([A-Z]+)\$[0-9]+"))} | I13: {=IFERROR(IF(OR('Raw Data'!I13="",LEN(TRIM('Raw Data'!I13))=0),"",IF(AND(LEN('Raw Data'!I13) <= 50,LEN('Raw Data'!I13)> 0),"",_xlfn.REGEXEXTRACT(CELL("address",'Raw Data'!I13),"\$([A-Z]+)\$[0-9]+"))),_xlfn.REGEXEXTRACT(CELL("address",'Raw Data'!I13),"\$([A-Z]+)\$[0-9]+"))} | J13: {=IFERROR(IF(OR('Raw Data'!J13="",LEN(TRIM('Raw Data'!J13))=0),"",IF(AND(ISNUMBER('Raw Data'!J13), IFERROR('Raw Data'!J13 = ROUND('Raw Data'!J13, 2),FALSE)),"",_xlfn.REGEXEXTRACT(CELL("address",J13), "\$([A-Z]+)\$[0-9]+"))),_xlfn.REGEXEXTRACT(CELL("address",J13), "\$([A-Z]+)\$[0-9]+"))} | K13: {=IFERROR(IF(OR('Raw Data'!K13="",LEN(TRIM('Raw Data'!K13))=0),"",IF(AND(ISNUMBER('Raw Data'!K13), IFERROR('Raw Data'!K13 = ROUND('Raw Data'!K13, 2),FALSE)),"",_xlfn.REGEXEXTRACT(CELL("address",K13), "\$([A-Z]+)\$[0-9]+"))),_xlfn.REGEXEXTRACT(CELL("address",K13), "\$([A-Z]+)\$[0-9]+"))} | L13: {=IFERROR(IF(OR('Raw Data'!L13="",LEN(TRIM('Raw Data'!L13))=0),"",IF(AND(ISNUMBER('Raw Data'!L13), IFERROR('Raw Data'!L13 = ROUND('Raw Data'!L13, 2),FALSE)),"",_xlfn.REGEXEXTRACT(CELL("address",L13), "\$([A-Z]+)\$[0-9]+"))),_xlfn.REGEXEXTRACT(CELL("address",L13), "\$([A-Z]+)\$[0-9]+"))} | M13: {=IFERROR(IF(OR('Raw Data'!M13="",LEN(TRIM('Raw Data'!M13))=0),"",IF(AND(ISNUMBER('Raw Data'!M13), IFERROR('Raw Data'!M13 = ROUND('Raw Data'!M13, 2),FALSE)),"",_xlfn.REGEXEXTRACT(CELL("address",M13), "\$([A-Z]+)\$[0-9]+"))),_xlfn.REGEXEXTRACT(CELL("address",M13), "\$([A-Z]+)\$[0-9]+"))} | N13: {=IFERROR(IF(OR('Raw Data'!N13="",LEN(TRIM('Raw Data'!N13))=0),"",IF(AND(ISNUMBER('Raw Data'!N13), IFERROR('Raw Data'!N13 = ROUND('Raw Data'!N13, 2),FALSE)),"",_xlfn.REGEXEXTRACT(CELL("address",N13), "\$([A-Z]+)\$[0-9]+"))),_xlfn.REGEXEXTRACT(CELL("address",N13), "\$([A-Z]+)\$[0-9]+"))} | O13: {=IFERROR(IF(OR('Raw Data'!O13="",LEN(TRIM('Raw Data'!O13))=0),"",IF(AND(ISNUMBER('Raw Data'!O13),'Raw Data'!O13>=Configuration!$D$2),"",_xlfn.REGEXEXTRACT(CELL("address",'Raw Data'!O13),"\$([A-Z]+)\$[0-9]+"))),_xlfn.REGEXEXTRACT(CELL("address",O13), "\$([A-Z]+)\$[0-9]+"))} | P13: {=IFERROR(IF(OR('Raw Data'!P13="",LEN(TRIM('Raw Data'!P13))=0),"",IF(AND(ISNUMBER('Raw Data'!P13), IFERROR('Raw Data'!P13 = ROUND('Raw Data'!P13, 2),FALSE)),"",_xlfn.REGEXEXTRACT(CELL("address",P13), "\$([A-Z]+)\$[0-9]+"))),_xlfn.REGEXEXTRACT(CELL("address",P13), "\$([A-Z]+)\$[0-9]+"))} | Q13: {=IFERROR(IF(OR('Raw Data'!Q13="",LEN(TRIM('Raw Data'!Q13))=0),"",IF(AND(ISNUMBER('Raw Data'!Q13), IFERROR('Raw Data'!Q13 = ROUND('Raw Data'!Q13, 2),FALSE)),"",_xlfn.REGEXEXTRACT(CELL("address",Q13), "\$([A-Z]+)\$[0-9]+"))),_xlfn.REGEXEXTRACT(CELL("address",Q13), "\$([A-Z]+)\$[0-9]+"))} | R13: {=IFERROR(IF(OR('Raw Data'!R13="",LEN(TRIM('Raw Data'!R13))=0),"",IF(AND(LEN('Raw Data'!R13) <= 50,LEN('Raw Data'!R13)> 0),"",_xlfn.REGEXEXTRACT(CELL("address",'Raw Data'!R13),"\$([A-Z]+)\$[0-9]+"))),_xlfn.REGEXEXTRACT(CELL("address",'Raw Data'!R13),"\$([A-Z]+)\$[0-9]+"))} | S13: {=IFERROR(IF(OR('Raw Data'!S13="",LEN(TRIM('Raw Data'!S13))=0),"",IF(AND(LEN('Raw Data'!S13) <= 50,LEN('Raw Data'!S13)> 0),"",_xlfn.REGEXEXTRACT(CELL("address",'Raw Data'!S13),"\$([A-Z]+)\$[0-9]+"))),_xlfn.REGEXEXTRACT(CELL("address",'Raw Data'!S13),"\$([A-Z]+)\$[0-9]+"))} | T13: {=IFERROR(IF(OR('Raw Data'!T13="",LEN(TRIM('Raw Data'!T13))=0),"",IF(AND(ISNUMBER('Raw Data'!T13), IFERROR('Raw Data'!T13 = ROUND('Raw Data'!T13, 2),FALSE)),"",_xlfn.REGEXEXTRACT(CELL("address",T13), "\$([A-Z]+)\$[0-9]+"))),_xlfn.REGEXEXTRACT(CELL("address",T13), "\$([A-Z]+)\$[0-9]+"))} | U13: {=IFERROR(IF(OR('Raw Data'!U13="",LEN(TRIM('Raw Data'!U13))=0),"",IF(AND(ISNUMBER('Raw Data'!U13), IFERROR('Raw Data'!U13 = ROUND('Raw Data'!U13, 2),FALSE)),"",_xlfn.REGEXEXTRACT(CELL("address",U13), "\$([A-Z]+)\$[0-9]+"))),_xlfn.REGEXEXTRACT(CELL("address",U13), "\$([A-Z]+)\$[0-9]+"))} | V13: {=IFERROR(IF(OR('Raw Data'!V13="",LEN(TRIM('Raw Data'!V13))=0),"",IF(AND(ISNUMBER('Raw Data'!V13), IFERROR('Raw Data'!V13 = ROUND('Raw Data'!V13, 2),FALSE)),"",_xlfn.REGEXEXTRACT(CELL("address",V13), "\$([A-Z]+)\$[0-9]+"))),_xlfn.REGEXEXTRACT(CELL("address",V13), "\$([A-Z]+)\$[0-9]+"))} | W13: {=IFERROR(IF(OR('Raw Data'!W13="",LEN(TRIM('Raw Data'!W13))=0),"",IF(AND(ISNUMBER('Raw Data'!W13), IFERROR('Raw Data'!W13 = ROUND('Raw Data'!W13, 2),FALSE)),"",_xlfn.REGEXEXTRACT(CELL("address",W13), "\$([A-Z]+)\$[0-9]+"))),_xlfn.REGEXEXTRACT(CELL("address",W13), "\$([A-Z]+)\$[0-9]+"))} | X13: {=IFERROR(IF(OR('Raw Data'!X13="",LEN(TRIM('Raw Data'!X13))=0),"",IF(AND(ISNUMBER('Raw Data'!X13), IFERROR('Raw Data'!X13 = ROUND('Raw Data'!X13, 2),FALSE)),"",_xlfn.REGEXEXTRACT(CELL("address",X13), "\$([A-Z]+)\$[0-9]+"))),_xlfn.REGEXEXTRACT(CELL("address",X13), "\$([A-Z]+)\$[0-9]+"))} | Y13: {=IFERROR(IF(OR('Raw Data'!Y13="",LEN(TRIM('Raw Data'!Y13))=0),"",IF(AND(ISNUMBER('Raw Data'!Y13), IFERROR('Raw Data'!Y13 = ROUND('Raw Data'!Y13, 2),FALSE)),"",_xlfn.REGEXEXTRACT(CELL("address",Y13), "\$([A-Z]+)\$[0-9]+"))),_xlfn.REGEXEXTRACT(CELL("address",Y13), "\$([A-Z]+)\$[0-9]+"))} | Z13: {=IFERROR(IF(OR('Raw Data'!Z13="",LEN(TRIM('Raw Data'!Z13))=0),"",IF(AND(ISNUMBER('Raw Data'!Z13), IFERROR('Raw Data'!Z13 = ROUND('Raw Data'!Z13, 2),FALSE)),"",_xlfn.REGEXEXTRACT(CELL("address",Z13), "\$([A-Z]+)\$[0-9]+"))),_xlfn.REGEXEXTRACT(CELL("address",Z13), "\$([A-Z]+)\$[0-9]+"))} | AA13: {=IFERROR(IF(OR('Raw Data'!AA13="",LEN(TRIM('Raw Data'!AA13))=0),"",IF(AND(ISNUMBER('Raw Data'!AA13), IFERROR('Raw Data'!AA13 = ROUND('Raw Data'!AA13, 2),FALSE)),"",_xlfn.REGEXEXTRACT(CELL("address",AA13), "\$([A-Z]+)\$[0-9]+"))),_xlfn.REGEXEXTRACT(CELL("address",AA13), "\$([A-Z]+)\$[0-9]+"))} | ... AI13: {=IFERROR(IF(OR('Raw Data'!AI13="",LEN(TRIM('Raw Data'!AI13))=0),"",IF(AND(ISNUMBER('Raw Data'!AI13), IFERROR('Raw Data'!AI13 = ROUND('Raw Data'!AI13, 2),FALSE)),"",_xlfn.REGEXEXTRACT(CELL("address",AI13), "\$([A-Z]+)\$[0-9]+"))),_xlfn.REGEXEXTRACT(CELL("address",AI13), "\$([A-Z]+)\$[0-9]+"))} | AJ13: {=IFERROR(IF(OR('Raw Data'!AJ13="",LEN(TRIM('Raw Data'!AJ13))=0),"",IF(AND(ISNUMBER('Raw Data'!AJ13), IFERROR('Raw Data'!AJ13 = ROUND('Raw Data'!AJ13, 4),FALSE)),"",_xlfn.REGEXEXTRACT(CELL("address",AJ13), "\$([A-Z]+)\$[0-9]+"))),_xlfn.REGEXEXTRACT(CELL("address",AJ13), "\$([A-Z]+)\$[0-9]+"))} | AK13: {=IFERROR(IF(OR('Raw Data'!AK13="",LEN(TRIM('Raw Data'!AK13))=0),"",IF(AND(ISNUMBER('Raw Data'!AK13), IFERROR('Raw Data'!AK13 = ROUND('Raw Data'!AK13, 2),FALSE)),"",_xlfn.REGEXEXTRACT(CELL("address",AK13), "\$([A-Z]+)\$[0-9]+"))),_xlfn.REGEXEXTRACT(CELL("address",AK13), "\$([A-Z]+)\$[0-9]+"))} | AL13: {=IFERROR(IF(OR('Raw Data'!AL13="",LEN(TRIM('Raw Data'!AL13))=0),"",IF(AND(ISNUMBER('Raw Data'!AL13), IFERROR('Raw Data'!AL13 = ROUND('Raw Data'!AL13, 2),FALSE)),"",_xlfn.REGEXEXTRACT(CELL("address",AL13), "\$([A-Z]+)\$[0-9]+"))),_xlfn.REGEXEXTRACT(CELL("address",AL13), "\$([A-Z]+)\$[0-9]+"))} | AM13: {=IFERROR(IF(OR('Raw Data'!AM13="",LEN(TRIM('Raw Data'!AM13))=0),"",IF(AND(ISNUMBER('Raw Data'!AM13), IFERROR('Raw Data'!AM13 = ROUND('Raw Data'!AM13, 2),FALSE)),"",_xlfn.REGEXEXTRACT(CELL("address",AM13), "\$([A-Z]+)\$[0-9]+"))),_xlfn.REGEXEXTRACT(CELL("address",AM13), "\$([A-Z]+)\$[0-9]+"))} | AN13: {=IFERROR(IF(OR('Raw Data'!AN13="",LEN(TRIM('Raw Data'!AN13))=0),"",IF(AND(ISNUMBER('Raw Data'!AN13), IFERROR('Raw Data'!AN13 = ROUND('Raw Data'!AN13, 2),FALSE)),"",_xlfn.REGEXEXTRACT(CELL("address",AN13), "\$([A-Z]+)\$[0-9]+"))),_xlfn.REGEXEXTRACT(CELL("address",AN13), "\$([A-Z]+)\$[0-9]+"))} | AO13: {=IFERROR(IF(OR('Raw Data'!AO13="",LEN(TRIM('Raw Data'!AO13))=0),"",IF(AND(ISNUMBER('Raw Data'!AO13), IFERROR('Raw Data'!AO13 = ROUND('Raw Data'!AO13, 2),FALSE)),"",_xlfn.REGEXEXTRACT(CELL("address",AO13), "\$([A-Z]+)\$[0-9]+"))),_xlfn.REGEXEXTRACT(CELL("address",AO13), "\$([A-Z]+)\$[0-9]+"))} | AP13: {=IFERROR(IF(OR('Raw Data'!AP13="",LEN(TRIM('Raw Data'!AP13))=0),"",IF(AND(ISNUMBER('Raw Data'!AP13), IFERROR('Raw Data'!AP13 = ROUND('Raw Data'!AP13, 2),FALSE)),"",_xlfn.REGEXEXTRACT(CELL("address",AP13), "\$([A-Z]+)\$[0-9]+"))),_xlfn.REGEXEXTRACT(CELL("address",AP13), "\$([A-Z]+)\$[0-9]+"))}
B14: {=IFERROR(IF(OR('Raw Data'!B14="",LEN(TRIM('Raw Data'!B14))=0),"",IF(AND(LEN('Raw Data'!B14) <= 255,LEN('Raw Data'!B14)> 0),"",_xlfn.REGEXEXTRACT(CELL("address",'Raw Data'!B14),"\$([A-Z]+)\$[0-9]+"))),_xlfn.REGEXEXTRACT(CELL("address",'Raw Data'!B14),"\$([A-Z]+)\$[0-9]+"))} | C14: {=IFERROR(IF(OR('Raw Data'!C14="",LEN(TRIM('Raw Data'!C14))=0),"",IF(AND(LEN('Raw Data'!C14) <= 50,LEN('Raw Data'!C14)> 0),"",_xlfn.REGEXEXTRACT(CELL("address",'Raw Data'!C14),"\$([A-Z]+)\$[0-9]+"))),_xlfn.REGEXEXTRACT(CELL("address",'Raw Data'!C14),"\$([A-Z]+)\$[0-9]+"))} | D14: {=IFERROR(IF(OR('Raw Data'!D14="",LEN(TRIM('Raw Data'!D14))=0),"",IF(AND(LEN('Raw Data'!D14) <= 500,LEN('Raw Data'!D14)> 0),"",_xlfn.REGEXEXTRACT(CELL("address",'Raw Data'!D14),"\$([A-Z]+)\$[0-9]+"))),_xlfn.REGEXEXTRACT(CELL("address",'Raw Data'!D14),"\$([A-Z]+)\$[0-9]+"))} | E14: {=IFERROR(IF(OR('Raw Data'!E14="",LEN(TRIM('Raw Data'!E14))=0),"",IF(AND(LEN('Raw Data'!E14) <= 50,LEN('Raw Data'!E14)> 0),"",_xlfn.REGEXEXTRACT(CELL("address",'Raw Data'!E14),"\$([A-Z]+)\$[0-9]+"))),_xlfn.REGEXEXTRACT(CELL("address",'Raw Data'!E14),"\$([A-Z]+)\$[0-9]+"))} | F14: {=IFERROR(IF(OR('Raw Data'!F14="",LEN(TRIM('Raw Data'!F14))=0),"",IF(AND(LEN('Raw Data'!F14) <= 50,LEN('Raw Data'!F14)> 0),"",_xlfn.REGEXEXTRACT(CELL("address",'Raw Data'!F14),"\$([A-Z]+)\$[0-9]+"))),_xlfn.REGEXEXTRACT(CELL("address",'Raw Data'!F14),"\$([A-Z]+)\$[0-9]+"))} | G14: {=IFERROR(IF(OR('Raw Data'!G14="",LEN(TRIM('Raw Data'!G14))=0),"",IF(AND(LEN('Raw Data'!G14) <= 50,LEN('Raw Data'!G14)> 0),"",_xlfn.REGEXEXTRACT(CELL("address",'Raw Data'!G14),"\$([A-Z]+)\$[0-9]+"))),_xlfn.REGEXEXTRACT(CELL("address",'Raw Data'!G14),"\$([A-Z]+)\$[0-9]+"))} | H14: {=IFERROR(IF(OR('Raw Data'!H14="",LEN(TRIM('Raw Data'!H14))=0),"",IF(AND(LEN('Raw Data'!H14) <= 50,LEN('Raw Data'!H14)> 0),"",_xlfn.REGEXEXTRACT(CELL("address",'Raw Data'!H14),"\$([A-Z]+)\$[0-9]+"))),_xlfn.REGEXEXTRACT(CELL("address",'Raw Data'!H14),"\$([A-Z]+)\$[0-9]+"))} | I14: {=IFERROR(IF(OR('Raw Data'!I14="",LEN(TRIM('Raw Data'!I14))=0),"",IF(AND(LEN('Raw Data'!I14) <= 50,LEN('Raw Data'!I14)> 0),"",_xlfn.REGEXEXTRACT(CELL("address",'Raw Data'!I14),"\$([A-Z]+)\$[0-9]+"))),_xlfn.REGEXEXTRACT(CELL("address",'Raw Data'!I14),"\$([A-Z]+)\$[0-9]+"))} | J14: {=IFERROR(IF(OR('Raw Data'!J14="",LEN(TRIM('Raw Data'!J14))=0),"",IF(AND(ISNUMBER('Raw Data'!J14), IFERROR('Raw Data'!J14 = ROUND('Raw Data'!J14, 2),FALSE)),"",_xlfn.REGEXEXTRACT(CELL("address",J14), "\$([A-Z]+)\$[0-9]+"))),_xlfn.REGEXEXTRACT(CELL("address",J14), "\$([A-Z]+)\$[0-9]+"))} | K14: {=IFERROR(IF(OR('Raw Data'!K14="",LEN(TRIM('Raw Data'!K14))=0),"",IF(AND(ISNUMBER('Raw Data'!K14), IFERROR('Raw Data'!K14 = ROUND('Raw Data'!K14, 2),FALSE)),"",_xlfn.REGEXEXTRACT(CELL("address",K14), "\$([A-Z]+)\$[0-9]+"))),_xlfn.REGEXEXTRACT(CELL("address",K14), "\$([A-Z]+)\$[0-9]+"))} | L14: {=IFERROR(IF(OR('Raw Data'!L14="",LEN(TRIM('Raw Data'!L14))=0),"",IF(AND(ISNUMBER('Raw Data'!L14), IFERROR('Raw Data'!L14 = ROUND('Raw Data'!L14, 2),FALSE)),"",_xlfn.REGEXEXTRACT(CELL("address",L14), "\$([A-Z]+)\$[0-9]+"))),_xlfn.REGEXEXTRACT(CELL("address",L14), "\$([A-Z]+)\$[0-9]+"))} | M14: {=IFERROR(IF(OR('Raw Data'!M14="",LEN(TRIM('Raw Data'!M14))=0),"",IF(AND(ISNUMBER('Raw Data'!M14), IFERROR('Raw Data'!M14 = ROUND('Raw Data'!M14, 2),FALSE)),"",_xlfn.REGEXEXTRACT(CELL("address",M14), "\$([A-Z]+)\$[0-9]+"))),_xlfn.REGEXEXTRACT(CELL("address",M14), "\$([A-Z]+)\$[0-9]+"))} | N14: {=IFERROR(IF(OR('Raw Data'!N14="",LEN(TRIM('Raw Data'!N14))=0),"",IF(AND(ISNUMBER('Raw Data'!N14), IFERROR('Raw Data'!N14 = ROUND('Raw Data'!N14, 2),FALSE)),"",_xlfn.REGEXEXTRACT(CELL("address",N14), "\$([A-Z]+)\$[0-9]+"))),_xlfn.REGEXEXTRACT(CELL("address",N14), "\$([A-Z]+)\$[0-9]+"))} | O14: {=IFERROR(IF(OR('Raw Data'!O14="",LEN(TRIM('Raw Data'!O14))=0),"",IF(AND(ISNUMBER('Raw Data'!O14),'Raw Data'!O14>=Configuration!$D$2),"",_xlfn.REGEXEXTRACT(CELL("address",'Raw Data'!O14),"\$([A-Z]+)\$[0-9]+"))),_xlfn.REGEXEXTRACT(CELL("address",O14), "\$([A-Z]+)\$[0-9]+"))} | P14: {=IFERROR(IF(OR('Raw Data'!P14="",LEN(TRIM('Raw Data'!P14))=0),"",IF(AND(ISNUMBER('Raw Data'!P14), IFERROR('Raw Data'!P14 = ROUND('Raw Data'!P14, 2),FALSE)),"",_xlfn.REGEXEXTRACT(CELL("address",P14), "\$([A-Z]+)\$[0-9]+"))),_xlfn.REGEXEXTRACT(CELL("address",P14), "\$([A-Z]+)\$[0-9]+"))} | Q14: {=IFERROR(IF(OR('Raw Data'!Q14="",LEN(TRIM('Raw Data'!Q14))=0),"",IF(AND(ISNUMBER('Raw Data'!Q14), IFERROR('Raw Data'!Q14 = ROUND('Raw Data'!Q14, 2),FALSE)),"",_xlfn.REGEXEXTRACT(CELL("address",Q14), "\$([A-Z]+)\$[0-9]+"))),_xlfn.REGEXEXTRACT(CELL("address",Q14), "\$([A-Z]+)\$[0-9]+"))} | R14: {=IFERROR(IF(OR('Raw Data'!R14="",LEN(TRIM('Raw Data'!R14))=0),"",IF(AND(LEN('Raw Data'!R14) <= 50,LEN('Raw Data'!R14)> 0),"",_xlfn.REGEXEXTRACT(CELL("address",'Raw Data'!R14),"\$([A-Z]+)\$[0-9]+"))),_xlfn.REGEXEXTRACT(CELL("address",'Raw Data'!R14),"\$([A-Z]+)\$[0-9]+"))} | S14: {=IFERROR(IF(OR('Raw Data'!S14="",LEN(TRIM('Raw Data'!S14))=0),"",IF(AND(LEN('Raw Data'!S14) <= 50,LEN('Raw Data'!S14)> 0),"",_xlfn.REGEXEXTRACT(CELL("address",'Raw Data'!S14),"\$([A-Z]+)\$[0-9]+"))),_xlfn.REGEXEXTRACT(CELL("address",'Raw Data'!S14),"\$([A-Z]+)\$[0-9]+"))} | T14: {=IFERROR(IF(OR('Raw Data'!T14="",LEN(TRIM('Raw Data'!T14))=0),"",IF(AND(ISNUMBER('Raw Data'!T14), IFERROR('Raw Data'!T14 = ROUND('Raw Data'!T14, 2),FALSE)),"",_xlfn.REGEXEXTRACT(CELL("address",T14), "\$([A-Z]+)\$[0-9]+"))),_xlfn.REGEXEXTRACT(CELL("address",T14), "\$([A-Z]+)\$[0-9]+"))} | U14: {=IFERROR(IF(OR('Raw Data'!U14="",LEN(TRIM('Raw Data'!U14))=0),"",IF(AND(ISNUMBER('Raw Data'!U14), IFERROR('Raw Data'!U14 = ROUND('Raw Data'!U14, 2),FALSE)),"",_xlfn.REGEXEXTRACT(CELL("address",U14), "\$([A-Z]+)\$[0-9]+"))),_xlfn.REGEXEXTRACT(CELL("address",U14), "\$([A-Z]+)\$[0-9]+"))} | V14: {=IFERROR(IF(OR('Raw Data'!V14="",LEN(TRIM('Raw Data'!V14))=0),"",IF(AND(ISNUMBER('Raw Data'!V14), IFERROR('Raw Data'!V14 = ROUND('Raw Data'!V14, 2),FALSE)),"",_xlfn.REGEXEXTRACT(CELL("address",V14), "\$([A-Z]+)\$[0-9]+"))),_xlfn.REGEXEXTRACT(CELL("address",V14), "\$([A-Z]+)\$[0-9]+"))} | W14: {=IFERROR(IF(OR('Raw Data'!W14="",LEN(TRIM('Raw Data'!W14))=0),"",IF(AND(ISNUMBER('Raw Data'!W14), IFERROR('Raw Data'!W14 = ROUND('Raw Data'!W14, 2),FALSE)),"",_xlfn.REGEXEXTRACT(CELL("address",W14), "\$([A-Z]+)\$[0-9]+"))),_xlfn.REGEXEXTRACT(CELL("address",W14), "\$([A-Z]+)\$[0-9]+"))} | X14: {=IFERROR(IF(OR('Raw Data'!X14="",LEN(TRIM('Raw Data'!X14))=0),"",IF(AND(ISNUMBER('Raw Data'!X14), IFERROR('Raw Data'!X14 = ROUND('Raw Data'!X14, 2),FALSE)),"",_xlfn.REGEXEXTRACT(CELL("address",X14), "\$([A-Z]+)\$[0-9]+"))),_xlfn.REGEXEXTRACT(CELL("address",X14), "\$([A-Z]+)\$[0-9]+"))} | Y14: {=IFERROR(IF(OR('Raw Data'!Y14="",LEN(TRIM('Raw Data'!Y14))=0),"",IF(AND(ISNUMBER('Raw Data'!Y14), IFERROR('Raw Data'!Y14 = ROUND('Raw Data'!Y14, 2),FALSE)),"",_xlfn.REGEXEXTRACT(CELL("address",Y14), "\$([A-Z]+)\$[0-9]+"))),_xlfn.REGEXEXTRACT(CELL("address",Y14), "\$([A-Z]+)\$[0-9]+"))} | Z14: {=IFERROR(IF(OR('Raw Data'!Z14="",LEN(TRIM('Raw Data'!Z14))=0),"",IF(AND(ISNUMBER('Raw Data'!Z14), IFERROR('Raw Data'!Z14 = ROUND('Raw Data'!Z14, 2),FALSE)),"",_xlfn.REGEXEXTRACT(CELL("address",Z14), "\$([A-Z]+)\$[0-9]+"))),_xlfn.REGEXEXTRACT(CELL("address",Z14), "\$([A-Z]+)\$[0-9]+"))} | AA14: {=IFERROR(IF(OR('Raw Data'!AA14="",LEN(TRIM('Raw Data'!AA14))=0),"",IF(AND(ISNUMBER('Raw Data'!AA14), IFERROR('Raw Data'!AA14 = ROUND('Raw Data'!AA14, 2),FALSE)),"",_xlfn.REGEXEXTRACT(CELL("address",AA14), "\$([A-Z]+)\$[0-9]+"))),_xlfn.REGEXEXTRACT(CELL("address",AA14), "\$([A-Z]+)\$[0-9]+"))} | ... AI14: {=IFERROR(IF(OR('Raw Data'!AI14="",LEN(TRIM('Raw Data'!AI14))=0),"",IF(AND(ISNUMBER('Raw Data'!AI14), IFERROR('Raw Data'!AI14 = ROUND('Raw Data'!AI14, 2),FALSE)),"",_xlfn.REGEXEXTRACT(CELL("address",AI14), "\$([A-Z]+)\$[0-9]+"))),_xlfn.REGEXEXTRACT(CELL("address",AI14), "\$([A-Z]+)\$[0-9]+"))} | AJ14: {=IFERROR(IF(OR('Raw Data'!AJ14="",LEN(TRIM('Raw Data'!AJ14))=0),"",IF(AND(ISNUMBER('Raw Data'!AJ14), IFERROR('Raw Data'!AJ14 = ROUND('Raw Data'!AJ14, 4),FALSE)),"",_xlfn.REGEXEXTRACT(CELL("address",AJ14), "\$([A-Z]+)\$[0-9]+"))),_xlfn.REGEXEXTRACT(CELL("address",AJ14), "\$([A-Z]+)\$[0-9]+"))} | AK14: {=IFERROR(IF(OR('Raw Data'!AK14="",LEN(TRIM('Raw Data'!AK14))=0),"",IF(AND(ISNUMBER('Raw Data'!AK14), IFERROR('Raw Data'!AK14 = ROUND('Raw Data'!AK14, 2),FALSE)),"",_xlfn.REGEXEXTRACT(CELL("address",AK14), "\$([A-Z]+)\$[0-9]+"))),_xlfn.REGEXEXTRACT(CELL("address",AK14), "\$([A-Z]+)\$[0-9]+"))} | AL14: {=IFERROR(IF(OR('Raw Data'!AL14="",LEN(TRIM('Raw Data'!AL14))=0),"",IF(AND(ISNUMBER('Raw Data'!AL14), IFERROR('Raw Data'!AL14 = ROUND('Raw Data'!AL14, 2),FALSE)),"",_xlfn.REGEXEXTRACT(CELL("address",AL14), "\$([A-Z]+)\$[0-9]+"))),_xlfn.REGEXEXTRACT(CELL("address",AL14), "\$([A-Z]+)\$[0-9]+"))} | AM14: {=IFERROR(IF(OR('Raw Data'!AM14="",LEN(TRIM('Raw Data'!AM14))=0),"",IF(AND(ISNUMBER('Raw Data'!AM14), IFERROR('Raw Data'!AM14 = ROUND('Raw Data'!AM14, 2),FALSE)),"",_xlfn.REGEXEXTRACT(CELL("address",AM14), "\$([A-Z]+)\$[0-9]+"))),_xlfn.REGEXEXTRACT(CELL("address",AM14), "\$([A-Z]+)\$[0-9]+"))} | AN14: {=IFERROR(IF(OR('Raw Data'!AN14="",LEN(TRIM('Raw Data'!AN14))=0),"",IF(AND(ISNUMBER('Raw Data'!AN14), IFERROR('Raw Data'!AN14 = ROUND('Raw Data'!AN14, 2),FALSE)),"",_xlfn.REGEXEXTRACT(CELL("address",AN14), "\$([A-Z]+)\$[0-9]+"))),_xlfn.REGEXEXTRACT(CELL("address",AN14), "\$([A-Z]+)\$[0-9]+"))} | AO14: {=IFERROR(IF(OR('Raw Data'!AO14="",LEN(TRIM('Raw Data'!AO14))=0),"",IF(AND(ISNUMBER('Raw Data'!AO14), IFERROR('Raw Data'!AO14 = ROUND('Raw Data'!AO14, 2),FALSE)),"",_xlfn.REGEXEXTRACT(CELL("address",AO14), "\$([A-Z]+)\$[0-9]+"))),_xlfn.REGEXEXTRACT(CELL("address",AO14), "\$([A-Z]+)\$[0-9]+"))} | AP14: {=IFERROR(IF(OR('Raw Data'!AP14="",LEN(TRIM('Raw Data'!AP14))=0),"",IF(AND(ISNUMBER('Raw Data'!AP14), IFERROR('Raw Data'!AP14 = ROUND('Raw Data'!AP14, 2),FALSE)),"",_xlfn.REGEXEXTRACT(CELL("address",AP14), "\$([A-Z]+)\$[0-9]+"))),_xlfn.REGEXEXTRACT(CELL("address",AP14), "\$([A-Z]+)\$[0-9]+"))}
B15: {=IFERROR(IF(OR('Raw Data'!B15="",LEN(TRIM('Raw Data'!B15))=0),"",IF(AND(LEN('Raw Data'!B15) <= 255,LEN('Raw Data'!B15)> 0),"",_xlfn.REGEXEXTRACT(CELL("address",'Raw Data'!B15),"\$([A-Z]+)\$[0-9]+"))),_xlfn.REGEXEXTRACT(CELL("address",'Raw Data'!B15),"\$([A-Z]+)\$[0-9]+"))} | C15: {=IFERROR(IF(OR('Raw Data'!C15="",LEN(TRIM('Raw Data'!C15))=0),"",IF(AND(LEN('Raw Data'!C15) <= 50,LEN('Raw Data'!C15)> 0),"",_xlfn.REGEXEXTRACT(CELL("address",'Raw Data'!C15),"\$([A-Z]+)\$[0-9]+"))),_xlfn.REGEXEXTRACT(CELL("address",'Raw Data'!C15),"\$([A-Z]+)\$[0-9]+"))} | D15: {=IFERROR(IF(OR('Raw Data'!D15="",LEN(TRIM('Raw Data'!D15))=0),"",IF(AND(LEN('Raw Data'!D15) <= 500,LEN('Raw Data'!D15)> 0),"",_xlfn.REGEXEXTRACT(CELL("address",'Raw Data'!D15),"\$([A-Z]+)\$[0-9]+"))),_xlfn.REGEXEXTRACT(CELL("address",'Raw Data'!D15),"\$([A-Z]+)\$[0-9]+"))} | E15: {=IFERROR(IF(OR('Raw Data'!E15="",LEN(TRIM('Raw Data'!E15))=0),"",IF(AND(LEN('Raw Data'!E15) <= 50,LEN('Raw Data'!E15)> 0),"",_xlfn.REGEXEXTRACT(CELL("address",'Raw Data'!E15),"\$([A-Z]+)\$[0-9]+"))),_xlfn.REGEXEXTRACT(CELL("address",'Raw Data'!E15),"\$([A-Z]+)\$[0-9]+"))} | F15: {=IFERROR(IF(OR('Raw Data'!F15="",LEN(TRIM('Raw Data'!F15))=0),"",IF(AND(LEN('Raw Data'!F15) <= 50,LEN('Raw Data'!F15)> 0),"",_xlfn.REGEXEXTRACT(CELL("address",'Raw Data'!F15),"\$([A-Z]+)\$[0-9]+"))),_xlfn.REGEXEXTRACT(CELL("address",'Raw Data'!F15),"\$([A-Z]+)\$[0-9]+"))} | G15: {=IFERROR(IF(OR('Raw Data'!G15="",LEN(TRIM('Raw Data'!G15))=0),"",IF(AND(LEN('Raw Data'!G15) <= 50,LEN('Raw Data'!G15)> 0),"",_xlfn.REGEXEXTRACT(CELL("address",'Raw Data'!G15),"\$([A-Z]+)\$[0-9]+"))),_xlfn.REGEXEXTRACT(CELL("address",'Raw Data'!G15),"\$([A-Z]+)\$[0-9]+"))} | H15: {=IFERROR(IF(OR('Raw Data'!H15="",LEN(TRIM('Raw Data'!H15))=0),"",IF(AND(LEN('Raw Data'!H15) <= 50,LEN('Raw Data'!H15)> 0),"",_xlfn.REGEXEXTRACT(CELL("address",'Raw Data'!H15),"\$([A-Z]+)\$[0-9]+"))),_xlfn.REGEXEXTRACT(CELL("address",'Raw Data'!H15),"\$([A-Z]+)\$[0-9]+"))} | I15: {=IFERROR(IF(OR('Raw Data'!I15="",LEN(TRIM('Raw Data'!I15))=0),"",IF(AND(LEN('Raw Data'!I15) <= 50,LEN('Raw Data'!I15)> 0),"",_xlfn.REGEXEXTRACT(CELL("address",'Raw Data'!I15),"\$([A-Z]+)\$[0-9]+"))),_xlfn.REGEXEXTRACT(CELL("address",'Raw Data'!I15),"\$([A-Z]+)\$[0-9]+"))} | J15: {=IFERROR(IF(OR('Raw Data'!J15="",LEN(TRIM('Raw Data'!J15))=0),"",IF(AND(ISNUMBER('Raw Data'!J15), IFERROR('Raw Data'!J15 = ROUND('Raw Data'!J15, 2),FALSE)),"",_xlfn.REGEXEXTRACT(CELL("address",J15), "\$([A-Z]+)\$[0-9]+"))),_xlfn.REGEXEXTRACT(CELL("address",J15), "\$([A-Z]+)\$[0-9]+"))} | K15: {=IFERROR(IF(OR('Raw Data'!K15="",LEN(TRIM('Raw Data'!K15))=0),"",IF(AND(ISNUMBER('Raw Data'!K15), IFERROR('Raw Data'!K15 = ROUND('Raw Data'!K15, 2),FALSE)),"",_xlfn.REGEXEXTRACT(CELL("address",K15), "\$([A-Z]+)\$[0-9]+"))),_xlfn.REGEXEXTRACT(CELL("address",K15), "\$([A-Z]+)\$[0-9]+"))} | L15: {=IFERROR(IF(OR('Raw Data'!L15="",LEN(TRIM('Raw Data'!L15))=0),"",IF(AND(ISNUMBER('Raw Data'!L15), IFERROR('Raw Data'!L15 = ROUND('Raw Data'!L15, 2),FALSE)),"",_xlfn.REGEXEXTRACT(CELL("address",L15), "\$([A-Z]+)\$[0-9]+"))),_xlfn.REGEXEXTRACT(CELL("address",L15), "\$([A-Z]+)\$[0-9]+"))} | M15: {=IFERROR(IF(OR('Raw Data'!M15="",LEN(TRIM('Raw Data'!M15))=0),"",IF(AND(ISNUMBER('Raw Data'!M15), IFERROR('Raw Data'!M15 = ROUND('Raw Data'!M15, 2),FALSE)),"",_xlfn.REGEXEXTRACT(CELL("address",M15), "\$([A-Z]+)\$[0-9]+"))),_xlfn.REGEXEXTRACT(CELL("address",M15), "\$([A-Z]+)\$[0-9]+"))} | N15: {=IFERROR(IF(OR('Raw Data'!N15="",LEN(TRIM('Raw Data'!N15))=0),"",IF(AND(ISNUMBER('Raw Data'!N15), IFERROR('Raw Data'!N15 = ROUND('Raw Data'!N15, 2),FALSE)),"",_xlfn.REGEXEXTRACT(CELL("address",N15), "\$([A-Z]+)\$[0-9]+"))),_xlfn.REGEXEXTRACT(CELL("address",N15), "\$([A-Z]+)\$[0-9]+"))} | O15: {=IFERROR(IF(OR('Raw Data'!O15="",LEN(TRIM('Raw Data'!O15))=0),"",IF(AND(ISNUMBER('Raw Data'!O15),'Raw Data'!O15>=Configuration!$D$2),"",_xlfn.REGEXEXTRACT(CELL("address",'Raw Data'!O15),"\$([A-Z]+)\$[0-9]+"))),_xlfn.REGEXEXTRACT(CELL("address",O15), "\$([A-Z]+)\$[0-9]+"))} | P15: {=IFERROR(IF(OR('Raw Data'!P15="",LEN(TRIM('Raw Data'!P15))=0),"",IF(AND(ISNUMBER('Raw Data'!P15), IFERROR('Raw Data'!P15 = ROUND('Raw Data'!P15, 2),FALSE)),"",_xlfn.REGEXEXTRACT(CELL("address",P15), "\$([A-Z]+)\$[0-9]+"))),_xlfn.REGEXEXTRACT(CELL("address",P15), "\$([A-Z]+)\$[0-9]+"))} | Q15: {=IFERROR(IF(OR('Raw Data'!Q15="",LEN(TRIM('Raw Data'!Q15))=0),"",IF(AND(ISNUMBER('Raw Data'!Q15), IFERROR('Raw Data'!Q15 = ROUND('Raw Data'!Q15, 2),FALSE)),"",_xlfn.REGEXEXTRACT(CELL("address",Q15), "\$([A-Z]+)\$[0-9]+"))),_xlfn.REGEXEXTRACT(CELL("address",Q15), "\$([A-Z]+)\$[0-9]+"))} | R15: {=IFERROR(IF(OR('Raw Data'!R15="",LEN(TRIM('Raw Data'!R15))=0),"",IF(AND(LEN('Raw Data'!R15) <= 50,LEN('Raw Data'!R15)> 0),"",_xlfn.REGEXEXTRACT(CELL("address",'Raw Data'!R15),"\$([A-Z]+)\$[0-9]+"))),_xlfn.REGEXEXTRACT(CELL("address",'Raw Data'!R15),"\$([A-Z]+)\$[0-9]+"))} | S15: {=IFERROR(IF(OR('Raw Data'!S15="",LEN(TRIM('Raw Data'!S15))=0),"",IF(AND(LEN('Raw Data'!S15) <= 50,LEN('Raw Data'!S15)> 0),"",_xlfn.REGEXEXTRACT(CELL("address",'Raw Data'!S15),"\$([A-Z]+)\$[0-9]+"))),_xlfn.REGEXEXTRACT(CELL("address",'Raw Data'!S15),"\$([A-Z]+)\$[0-9]+"))} | T15: {=IFERROR(IF(OR('Raw Data'!T15="",LEN(TRIM('Raw Data'!T15))=0),"",IF(AND(ISNUMBER('Raw Data'!T15), IFERROR('Raw Data'!T15 = ROUND('Raw Data'!T15, 2),FALSE)),"",_xlfn.REGEXEXTRACT(CELL("address",T15), "\$([A-Z]+)\$[0-9]+"))),_xlfn.REGEXEXTRACT(CELL("address",T15), "\$([A-Z]+)\$[0-9]+"))} | U15: {=IFERROR(IF(OR('Raw Data'!U15="",LEN(TRIM('Raw Data'!U15))=0),"",IF(AND(ISNUMBER('Raw Data'!U15), IFERROR('Raw Data'!U15 = ROUND('Raw Data'!U15, 2),FALSE)),"",_xlfn.REGEXEXTRACT(CELL("address",U15), "\$([A-Z]+)\$[0-9]+"))),_xlfn.REGEXEXTRACT(CELL("address",U15), "\$([A-Z]+)\$[0-9]+"))} | V15: {=IFERROR(IF(OR('Raw Data'!V15="",LEN(TRIM('Raw Data'!V15))=0),"",IF(AND(ISNUMBER('Raw Data'!V15), IFERROR('Raw Data'!V15 = ROUND('Raw Data'!V15, 2),FALSE)),"",_xlfn.REGEXEXTRACT(CELL("address",V15), "\$([A-Z]+)\$[0-9]+"))),_xlfn.REGEXEXTRACT(CELL("address",V15), "\$([A-Z]+)\$[0-9]+"))} | W15: {=IFERROR(IF(OR('Raw Data'!W15="",LEN(TRIM('Raw Data'!W15))=0),"",IF(AND(ISNUMBER('Raw Data'!W15), IFERROR('Raw Data'!W15 = ROUND('Raw Data'!W15, 2),FALSE)),"",_xlfn.REGEXEXTRACT(CELL("address",W15), "\$([A-Z]+)\$[0-9]+"))),_xlfn.REGEXEXTRACT(CELL("address",W15), "\$([A-Z]+)\$[0-9]+"))} | X15: {=IFERROR(IF(OR('Raw Data'!X15="",LEN(TRIM('Raw Data'!X15))=0),"",IF(AND(ISNUMBER('Raw Data'!X15), IFERROR('Raw Data'!X15 = ROUND('Raw Data'!X15, 2),FALSE)),"",_xlfn.REGEXEXTRACT(CELL("address",X15), "\$([A-Z]+)\$[0-9]+"))),_xlfn.REGEXEXTRACT(CELL("address",X15), "\$([A-Z]+)\$[0-9]+"))} | Y15: {=IFERROR(IF(OR('Raw Data'!Y15="",LEN(TRIM('Raw Data'!Y15))=0),"",IF(AND(ISNUMBER('Raw Data'!Y15), IFERROR('Raw Data'!Y15 = ROUND('Raw Data'!Y15, 2),FALSE)),"",_xlfn.REGEXEXTRACT(CELL("address",Y15), "\$([A-Z]+)\$[0-9]+"))),_xlfn.REGEXEXTRACT(CELL("address",Y15), "\$([A-Z]+)\$[0-9]+"))} | Z15: {=IFERROR(IF(OR('Raw Data'!Z15="",LEN(TRIM('Raw Data'!Z15))=0),"",IF(AND(ISNUMBER('Raw Data'!Z15), IFERROR('Raw Data'!Z15 = ROUND('Raw Data'!Z15, 2),FALSE)),"",_xlfn.REGEXEXTRACT(CELL("address",Z15), "\$([A-Z]+)\$[0-9]+"))),_xlfn.REGEXEXTRACT(CELL("address",Z15), "\$([A-Z]+)\$[0-9]+"))} | AA15: {=IFERROR(IF(OR('Raw Data'!AA15="",LEN(TRIM('Raw Data'!AA15))=0),"",IF(AND(ISNUMBER('Raw Data'!AA15), IFERROR('Raw Data'!AA15 = ROUND('Raw Data'!AA15, 2),FALSE)),"",_xlfn.REGEXEXTRACT(CELL("address",AA15), "\$([A-Z]+)\$[0-9]+"))),_xlfn.REGEXEXTRACT(CELL("address",AA15), "\$([A-Z]+)\$[0-9]+"))} | ... AI15: {=IFERROR(IF(OR('Raw Data'!AI15="",LEN(TRIM('Raw Data'!AI15))=0),"",IF(AND(ISNUMBER('Raw Data'!AI15), IFERROR('Raw Data'!AI15 = ROUND('Raw Data'!AI15, 2),FALSE)),"",_xlfn.REGEXEXTRACT(CELL("address",AI15), "\$([A-Z]+)\$[0-9]+"))),_xlfn.REGEXEXTRACT(CELL("address",AI15), "\$([A-Z]+)\$[0-9]+"))} | AJ15: {=IFERROR(IF(OR('Raw Data'!AJ15="",LEN(TRIM('Raw Data'!AJ15))=0),"",IF(AND(ISNUMBER('Raw Data'!AJ15), IFERROR('Raw Data'!AJ15 = ROUND('Raw Data'!AJ15, 4),FALSE)),"",_xlfn.REGEXEXTRACT(CELL("address",AJ15), "\$([A-Z]+)\$[0-9]+"))),_xlfn.REGEXEXTRACT(CELL("address",AJ15), "\$([A-Z]+)\$[0-9]+"))} | AK15: {=IFERROR(IF(OR('Raw Data'!AK15="",LEN(TRIM('Raw Data'!AK15))=0),"",IF(AND(ISNUMBER('Raw Data'!AK15), IFERROR('Raw Data'!AK15 = ROUND('Raw Data'!AK15, 2),FALSE)),"",_xlfn.REGEXEXTRACT(CELL("address",AK15), "\$([A-Z]+)\$[0-9]+"))),_xlfn.REGEXEXTRACT(CELL("address",AK15), "\$([A-Z]+)\$[0-9]+"))} | AL15: {=IFERROR(IF(OR('Raw Data'!AL15="",LEN(TRIM('Raw Data'!AL15))=0),"",IF(AND(ISNUMBER('Raw Data'!AL15), IFERROR('Raw Data'!AL15 = ROUND('Raw Data'!AL15, 2),FALSE)),"",_xlfn.REGEXEXTRACT(CELL("address",AL15), "\$([A-Z]+)\$[0-9]+"))),_xlfn.REGEXEXTRACT(CELL("address",AL15), "\$([A-Z]+)\$[0-9]+"))} | AM15: {=IFERROR(IF(OR('Raw Data'!AM15="",LEN(TRIM('Raw Data'!AM15))=0),"",IF(AND(ISNUMBER('Raw Data'!AM15), IFERROR('Raw Data'!AM15 = ROUND('Raw Data'!AM15, 2),FALSE)),"",_xlfn.REGEXEXTRACT(CELL("address",AM15), "\$([A-Z]+)\$[0-9]+"))),_xlfn.REGEXEXTRACT(CELL("address",AM15), "\$([A-Z]+)\$[0-9]+"))} | AN15: {=IFERROR(IF(OR('Raw Data'!AN15="",LEN(TRIM('Raw Data'!AN15))=0),"",IF(AND(ISNUMBER('Raw Data'!AN15), IFERROR('Raw Data'!AN15 = ROUND('Raw Data'!AN15, 2),FALSE)),"",_xlfn.REGEXEXTRACT(CELL("address",AN15), "\$([A-Z]+)\$[0-9]+"))),_xlfn.REGEXEXTRACT(CELL("address",AN15), "\$([A-Z]+)\$[0-9]+"))} | AO15: {=IFERROR(IF(OR('Raw Data'!AO15="",LEN(TRIM('Raw Data'!AO15))=0),"",IF(AND(ISNUMBER('Raw Data'!AO15), IFERROR('Raw Data'!AO15 = ROUND('Raw Data'!AO15, 2),FALSE)),"",_xlfn.REGEXEXTRACT(CELL("address",AO15), "\$([A-Z]+)\$[0-9]+"))),_xlfn.REGEXEXTRACT(CELL("address",AO15), "\$([A-Z]+)\$[0-9]+"))} | AP15: {=IFERROR(IF(OR('Raw Data'!AP15="",LEN(TRIM('Raw Data'!AP15))=0),"",IF(AND(ISNUMBER('Raw Data'!AP15), IFERROR('Raw Data'!AP15 = ROUND('Raw Data'!AP15, 2),FALSE)),"",_xlfn.REGEXEXTRACT(CELL("address",AP15), "\$([A-Z]+)\$[0-9]+"))),_xlfn.REGEXEXTRACT(CELL("address",AP15), "\$([A-Z]+)\$[0-9]+"))}
