Workbook

Sheet Raw Data
B9: C1 | C9: C2 | D9: C3 | E9: C4 | F9: C5 | G9: C6 | H9: C7 | I9: C8 | J9: C9 | K9: C10 | L9: C11 | M9: C12 | N9: C13 | O9: C14 | P9: C15 | Q9: C16 | R9: C17 | S9: C18 | T9: C19 | U9: C20 | V9: C21 | W9: C22 | X9: C23 | Y9: C24
B10: 100 | C10: 100-1 | D10: 100-1-1 | E10: 100-1-1-1 | F10: 100-1-1-1-1 | G10: ENG | H10: 100-1-1-1-1-ENG | I10: Offshore | J10: Offshore WHP | K10: WHP Gas | L10: Pile (New) | M10: CSA | N10: Engineering | O10: Offshore-Offshore WHP-WHP Gas-Pile (New)-CSA-Engineering | P10: SQM | W10: 0 | X10: 0 | Y10: 0
B11: 100 | C11: 100-1 | D11: 100-1-1 | E11: 100-1-1-1 | F11: 100-1-1-1-2 | G11: ENG | H11: 100-1-1-1-2-ENG | I11: Offshore | J11: Offshore WHP | K11: WHP Gas | L11: Pile (New) | M11: Structure Steel | N11: Engineering | O11: Offshore-Offshore WHP-WHP Gas-Pile (New)-Structure Steel-Engineering | P11: MT | W11: 0 | X11: 0 | Y11: 0
B12: 100 | C12: 100-1 | D12: 100-1-1 | E12: 100-1-1-1 | F12: 100-1-1-1-3 | G12: ENG | H12: 100-1-1-1-3-ENG | I12: Offshore | J12: Offshore WHP | K12: WHP Gas | L12: Pile (New) | M12: Process | N12: Engineering | O12: Offshore-Offshore WHP-WHP Gas-Pile (New)-Process-Engineering | P12: Lot | W12: 0 | X12: 0 | Y12: 0
B13: 100 | C13: 100-1 | D13: 100-1-1 | E13: 100-1-1-1 | F13: 100-1-1-1-4 | G13: ENG | H13: 100-1-1-1-4-ENG | I13: Offshore | J13: Offshore WHP | K13: WHP Gas | L13: Pile (New) | M13: Piping | N13: Engineering | O13: Offshore-Offshore WHP-WHP Gas-Pile (New)-Piping-Engineering | P13: DB | W13: 0 | X13: 0 | Y13: 0
B14: 100 | C14: 100-1 | D14: 100-1-1 | E14: 100-1-1-1 | F14: 100-1-1-1-5 | G14: ENG | H14: 100-1-1-1-5-ENG | I14: Offshore | J14: Offshore WHP | K14: WHP Gas | L14: Pile (New) | M14: Mechanical | N14: Engineering | O14: Offshore-Offshore WHP-WHP Gas-Pile (New)-Mechanical-Engineering | P14: MT | W14: 0 | X14: 0 | Y14: 0
B15: 100 | C15: 100-1 | D15: 100-1-1 | E15: 100-1-1-1 | F15: 100-1-1-1-6 | G15: ENG | H15: 100-1-1-1-6-ENG | I15: Offshore | J15: Offshore WHP | K15: WHP Gas | L15: Pile (New) | M15: Electrical | N15: Engineering | O15: Offshore-Offshore WHP-WHP Gas-Pile (New)-Electrical-Engineering | P15: M | W15: 0 | X15: 0 | Y15: 0
B16: 100 | C16: 100-1 | D16: 100-1-1 | E16: 100-1-1-1 | F16: 100-1-1-1-7 | G16: ENG | H16: 100-1-1-1-7-ENG | I16: Offshore | J16: Offshore WHP | K16: WHP Gas | L16: Pile (New) | M16: Instrument | N16: Engineering | O16: Offshore-Offshore WHP-WHP Gas-Pile (New)-Instrument-Engineering | P16: M | W16: 0 | X16: 0 | Y16: 0
B17: 100 | C17: 100-1 | D17: 100-1-1 | E17: 100-1-1-1 | F17: 100-1-1-1-8 | G17: ENG | H17: 100-1-1-1-8-ENG | I17: Offshore | J17: Offshore WHP | K17: WHP Gas | L17: Pile (New) | M17: Blast & Paint | N17: Engineering | O17: Offshore-Offshore WHP-WHP Gas-Pile (New)-Blast & Paint-Engineering | P17: SQM | W17: 0 | X17: 0 | Y17: 0
B18: 100 | C18: 100-1 | D18: 100-1-1 | E18: 100-1-1-1 | F18: 100-1-1-1-9 | G18: ENG | H18: 100-1-1-1-9-ENG | I18: Offshore | J18: Offshore WHP | K18: WHP Gas | L18: Pile (New) | M18: Insulation | N18: Engineering | O18: Offshore-Offshore WHP-WHP Gas-Pile (New)-Insulation-Engineering | P18: SQM | W18: 0 | X18: 0 | Y18: 0
B19: 100 | C19: 100-1 | D19: 100-1-1 | E19: 100-1-1-1 | F19: 100-1-1-1-10 | G19: ENG | H19: 100-1-1-1-10-ENG | I19: Offshore | J19: Offshore WHP | K19: WHP Gas | L19: Pile (New) | M19: Fireproofing | N19: Engineering | O19: Offshore-Offshore WHP-WHP Gas-Pile (New)-Fireproofing-Engineering | P19: SQM | W19: 0 | X19: 0 | Y19: 0
B20: 100 | C20: 100-1 | D20: 100-1-1 | E20: 100-1-1-1 | F20: 100-1-1-1-11 | G20: ENG | H20: 100-1-1-1-11-ENG | I20: Offshore | J20: Offshore WHP | K20: WHP Gas | L20: Pile (New) | M20: Load & Sail | N20: Engineering | O20: Offshore-Offshore WHP-WHP Gas-Pile (New)-Load & Sail-Engineering | P20: MT | W20: 0 | X20: 0 | Y20: 0
B21: 100 | C21: 100-1 | D21: 100-1-1 | E21: 100-1-1-1 | F21: 100-1-1-1-12 | G21: ENG | H21: 100-1-1-1-12-ENG | I21: Offshore | J21: Offshore WHP | K21: WHP Gas | L21: Pile (New) | M21: Common of Project | N21: Engineering | O21: Offshore-Offshore WHP-WHP Gas-Pile (New)-Common of Project-Engineering | P21: Lot | W21: 0 | X21: 0 | Y21: 0
... B74: 100 | C74: 100-1 | D74: 100-1-1 | E74: 100-1-1-1 | F74: 100-1-1-1-13 | G74: HUC | H74: 100-1-1-1-13-HUC | I74: Offshore | J74: Offshore WHP | K74: WHP Gas | L74: Pile (New) | M74: Other | N74: HUC | O74: Offshore-Offshore WHP-WHP Gas-Pile (New)-Other-HUC | P74: Lot | W74: 0 | X74: 0 | Y74: 0
B75: 100 | C75: 100-1 | D75: 100-1-1 | E75: 100-1-1-1 | F75: 100-1-1-1-1 | G75: ALL | H75: 100-1-1-1-1-ALL | I75: Offshore | J75: Offshore WHP | K75: WHP Gas | L75: Pile (New) | M75: CSA | N75: Overall Project | O75: Offshore-Offshore WHP-WHP Gas-Pile (New)-CSA-Overall Project | P75: SQM | T75: 0 | U75: 0 | V75: 0 | W75: 0 | X75: 0 | Y75: 0
B76: 100 | C76: 100-1 | D76: 100-1-1 | E76: 100-1-1-1 | F76: 100-1-1-1-2 | G76: ALL | H76: 100-1-1-1-2-ALL | I76: Offshore | J76: Offshore WHP | K76: WHP Gas | L76: Pile (New) | M76: Structure Steel | N76: Overall Project | O76: Offshore-Offshore WHP-WHP Gas-Pile (New)-Structure Steel-Overall Project | P76: MT | T76: 0 | U76: 0 | V76: 0 | W76: 0 | X76: 0 | Y76: 0
B77: 100 | C77: 100-1 | D77: 100-1-1 | E77: 100-1-1-1 | F77: 100-1-1-1-3 | G77: ALL | H77: 100-1-1-1-3-ALL | I77: Offshore | J77: Offshore WHP | K77: WHP Gas | L77: Pile (New) | M77: Process | N77: Overall Project | O77: Offshore-Offshore WHP-WHP Gas-Pile (New)-Process-Overall Project | P77: Lot | T77: 0 | U77: 0 | V77: 0 | W77: 0 | X77: 0 | Y77: 0
B78: 100 | C78: 100-1 | D78: 100-1-1 | E78: 100-1-1-1 | F78: 100-1-1-1-4 | G78: ALL | H78: 100-1-1-1-4-ALL | I78: Offshore | J78: Offshore WHP | K78: WHP Gas | L78: Pile (New) | M78: Piping | N78: Overall Project | O78: Offshore-Offshore WHP-WHP Gas-Pile (New)-Piping-Overall Project | P78: DB | T78: 0 | U78: 0 | V78: 0 | W78: 0 | X78: 0 | Y78: 0
B79: 100 | C79: 100-1 | D79: 100-1-1 | E79: 100-1-1-1 | F79: 100-1-1-1-5 | G79: ALL | H79: 100-1-1-1-5-ALL | I79: Offshore | J79: Offshore WHP | K79: WHP Gas | L79: Pile (New) | M79: Mechanical | N79: Overall Project | O79: Offshore-Offshore WHP-WHP Gas-Pile (New)-Mechanical-Overall Project | P79: MT | T79: 0 | U79: 0 | V79: 0 | W79: 0 | X79: 0 | Y79: 0
B80: 100 | C80: 100-1 | D80: 100-1-1 | E80: 100-1-1-1 | F80: 100-1-1-1-6 | G80: ALL | H80: 100-1-1-1-6-ALL | I80: Offshore | J80: Offshore WHP | K80: WHP Gas | L80: Pile (New) | M80: Electrical | N80: Overall Project | O80: Offshore-Offshore WHP-WHP Gas-Pile (New)-Electrical-Overall Project | P80: M | T80: 0 | U80: 0 | V80: 0 | W80: 0 | X80: 0 | Y80: 0
B81: 100 | C81: 100-1 | D81: 100-1-1 | E81: 100-1-1-1 | F81: 100-1-1-1-7 | G81: ALL | H81: 100-1-1-1-7-ALL | I81: Offshore | J81: Offshore WHP | K81: WHP Gas | L81: Pile (New) | M81: Instrument | N81: Overall Project | O81: Offshore-Offshore WHP-WHP Gas-Pile (New)-Instrument-Overall Project | P81: M | T81: 0 | U81: 0 | V81: 0 | W81: 0 | X81: 0 | Y81: 0
B82: 100 | C82: 100-1 | D82: 100-1-1 | E82: 100-1-1-1 | F82: 100-1-1-1-8 | G82: ALL | H82: 100-1-1-1-8-ALL | I82: Offshore | J82: Offshore WHP | K82: WHP Gas | L82: Pile (New) | M82: Blast & Paint | N82: Overall Project | O82: Offshore-Offshore WHP-WHP Gas-Pile (New)-Blast & Paint-Overall Project | P82: SQM | T82: 0 | U82: 0 | V82: 0 | W82: 0 | X82: 0 | Y82: 0
B83: 100 | C83: 100-1 | D83: 100-1-1 | E83: 100-1-1-1 | F83: 100-1-1-1-9 | G83: ALL | H83: 100-1-1-1-9-ALL | I83: Offshore | J83: Offshore WHP | K83: WHP Gas | L83: Pile (New) | M83: Insulation | N83: Overall Project | O83: Offshore-Offshore WHP-WHP Gas-Pile (New)-Insulation-Overall Project | P83: SQM | T83: 0 | U83: 0 | V83: 0 | W83: 0 | X83: 0 | Y83: 0
B84: 100 | C84: 100-1 | D84: 100-1-1 | E84: 100-1-1-1 | F84: 100-1-1-1-10 | G84: ALL | H84: 100-1-1-1-10-ALL | I84: Offshore | J84: Offshore WHP | K84: WHP Gas | L84: Pile (New) | M84: Fireproofing | N84: Overall Project | O84: Offshore-Offshore WHP-WHP Gas-Pile (New)-Fireproofing-Overall Project | P84: SQM | T84: 0 | U84: 0 | V84: 0 | W84: 0 | X84: 0 | Y84: 0
B85: 100 | C85: 100-1 | D85: 100-1-1 | E85: 100-1-1-1 | F85: 100-1-1-1-11 | G85: ALL | H85: 100-1-1-1-11-ALL | I85: Offshore | J85: Offshore WHP | K85: WHP Gas | L85: Pile (New) | M85: Load & Sail | N85: Overall Project | O85: Offshore-Offshore WHP-WHP Gas-Pile (New)-Load & Sail-Overall Project | P85: MT | T85: 0 | U85: 0 | V85: 0 | W85: 0 | X85: 0 | Y85: 0
B86: 100 | C86: 100-1 | D86: 100-1-1 | E86: 100-1-1-1 | F86: 100-1-1-1-12 | G86: ALL | H86: 100-1-1-1-12-ALL | I86: Offshore | J86: Offshore WHP | K86: WHP Gas | L86: Pile (New) | M86: Common of Project | N86: Overall Project | O86: Offshore-Offshore WHP-WHP Gas-Pile (New)-Common of Project-Overall Project | P86: Lot | T86: 0 | U86: 0 | V86: 0 | W86: 0 | X86: 0 | Y86: 0
B87: 100 | C87: 100-1 | D87: 100-1-1 | E87: 100-1-1-1 | F87: 100-1-1-1-13 | G87: ALL | H87: 100-1-1-1-13-ALL | I87: Offshore | J87: Offshore WHP | K87: WHP Gas | L87: Pile (New) | M87: Other | N87: Overall Project | O87: Offshore-Offshore WHP-WHP Gas-Pile (New)-Other-Overall Project | P87: Lot | T87: 0 | U87: 0 | V87: 0 | W87: 0 | X87: 0 | Y87: 0
B88: 100 | C88: 100-1 | D88: 100-1-1 | E88: 100-1-1-2 | F88: 100-1-1-2-1 | G88: ENG | H88: 100-1-1-2-1-ENG | I88: Offshore | J88: Offshore WHP | K88: WHP Gas | L88: Topside (New) | M88: CSA | N88: Engineering | O88: Offshore-Offshore WHP-WHP Gas-Topside (New)-CSA-Engineering | P88: SQM | W88: 0 | X88: 0 | Y88: 0
B89: 100 | C89: 100-1 | D89: 100-1-1 | E89: 100-1-1-2 | F89: 100-1-1-2-2 | G89: ENG | H89: 100-1-1-2-2-ENG | I89: Offshore | J89: Offshore WHP | K89: WHP Gas | L89: Topside (New) | M89: Structure Steel | N89: Engineering | O89: Offshore-Offshore WHP-WHP Gas-Topside (New)-Structure Steel-Engineering | P89: MT | W89: 0 | X89: 0 | Y89: 0
B90: 100 | C90: 100-1 | D90: 100-1-1 | E90: 100-1-1-2 | F90: 100-1-1-2-3 | G90: ENG | H90: 100-1-1-2-3-ENG | I90: Offshore | J90: Offshore WHP | K90: WHP Gas | L90: Topside (New) | M90: Process | N90: Engineering | O90: Offshore-Offshore WHP-WHP Gas-Topside (New)-Process-Engineering | P90: Lot | W90: 0 | X90: 0 | Y90: 0
B91: 100 | C91: 100-1 | D91: 100-1-1 | E91: 100-1-1-2 | F91: 100-1-1-2-4 | G91: ENG | H91: 100-1-1-2-4-ENG | I91: Offshore | J91: Offshore WHP | K91: WHP Gas | L91: Topside (New) | M91: Piping | N91: Engineering | O91: Offshore-Offshore WHP-WHP Gas-Topside (New)-Piping-Engineering | P91: DB | W91: 0 | X91: 0 | Y91: 0
B92: 100 | C92: 100-1 | D92: 100-1-1 | E92: 100-1-1-2 | F92: 100-1-1-2-5 | G92: ENG | H92: 100-1-1-2-5-ENG | I92: Offshore | J92: Offshore WHP | K92: WHP Gas | L92: Topside (New) | M92: Mechanical | N92: Engineering | O92: Offshore-Offshore WHP-WHP Gas-Topside (New)-Mechanical-Engineering | P92: MT | W92: 0 | X92: 0 | Y92: 0
B93: 100 | C93: 100-1 | D93: 100-1-1 | E93: 100-1-1-2 | F93: 100-1-1-2-6 | G93: ENG | H93: 100-1-1-2-6-ENG | I93: Offshore | J93: Offshore WHP | K93: WHP Gas | L93: Topside (New) | M93: Electrical | N93: Engineering | O93: Offshore-Offshore WHP-WHP Gas-Topside (New)-Electrical-Engineering | P93: M | W93: 0 | X93: 0 | Y93: 0
B94: 100 | C94: 100-1 | D94: 100-1-1 | E94: 100-1-1-2 | F94: 100-1-1-2-7 | G94: ENG | H94: 100-1-1-2-7-ENG | I94: Offshore | J94: Offshore WHP | K94: WHP Gas | L94: Topside (New) | M94: Instrument | N94: Engineering | O94: Offshore-Offshore WHP-WHP Gas-Topside (New)-Instrument-Engineering | P94: M | W94: 0 | X94: 0 | Y94: 0
B95: 100 | C95: 100-1 | D95: 100-1-1 | E95: 100-1-1-2 | F95: 100-1-1-2-8 | G95: ENG | H95: 100-1-1-2-8-ENG | I95: Offshore | J95: Offshore WHP | K95: WHP Gas | L95: Topside (New) | M95: Blast & Paint | N95: Engineering | O95: Offshore-Offshore WHP-WHP Gas-Topside (New)-Blast & Paint-Engineering | P95: SQM | W95: 0 | X95: 0 | Y95: 0
B96: 100 | C96: 100-1 | D96: 100-1-1 | E96: 100-1-1-2 | F96: 100-1-1-2-9 | G96: ENG | H96: 100-1-1-2-9-ENG | I96: Offshore | J96: Offshore WHP | K96: WHP Gas | L96: Topside (New) | M96: Insulation | N96: Engineering | O96: Offshore-Offshore WHP-WHP Gas-Topside (New)-Insulation-Engineering | P96: SQM | W96: 0 | X96: 0 | Y96: 0
B97: 100 | C97: 100-1 | D97: 100-1-1 | E97: 100-1-1-2 | F97: 100-1-1-2-10 | G97: ENG | H97: 100-1-1-2-10-ENG | I97: Offshore | J97: Offshore WHP | K97: WHP Gas | L97: Topside (New) | M97: Fireproofing | N97: Engineering | O97: Offshore-Offshore WHP-WHP Gas-Topside (New)-Fireproofing-Engineering | P97: SQM | W97: 0 | X97: 0 | Y97: 0
B98: 100 | C98: 100-1 | D98: 100-1-1 | E98: 100-1-1-2 | F98: 100-1-1-2-11 | G98: ENG | H98: 100-1-1-2-11-ENG | I98: Offshore | J98: Offshore WHP | K98: WHP Gas | L98: Topside (New) | M98: Load & Sail | N98: Engineering | O98: Offshore-Offshore WHP-WHP Gas-Topside (New)-Load & Sail-Engineering | P98: MT | W98: 0 | X98: 0 | Y98: 0
B99: 100 | C99: 100-1 | D99: 100-1-1 | E99: 100-1-1-2 | F99: 100-1-1-2-12 | G99: ENG | H99: 100-1-1-2-12-ENG | I99: Offshore | J99: Offshore WHP | K99: WHP Gas | L99: Topside (New) | M99: Common of Project | N99: Engineering | O99: Offshore-Offshore WHP-WHP Gas-Topside (New)-Common of Project-Engineering | P99: Lot | W99: 0 | X99: 0 | Y99: 0
... B152: 100 | C152: 100-1 | D152: 100-1-1 | E152: 100-1-1-2 | F152: 100-1-1-2-13 | G152: HUC | H152: 100-1-1-2-13-HUC | I152: Offshore | J152: Offshore WHP | K152: WHP Gas | L152: Topside (New) | M152: Other | N152: HUC | O152: Offshore-Offshore WHP-WHP Gas-Topside (New)-Other-HUC | P152: Lot | W152: 0 | X152: 0 | Y152: 0
...

Sheet Validate_Empty
B8: TRUE | C8: TRUE | D8: TRUE | E8: TRUE | F8: TRUE | G8: TRUE | H8: TRUE | I8: TRUE | J8: TRUE | K8: TRUE | L8: TRUE | M8: TRUE | N8: TRUE | O8: TRUE | P8: TRUE | Q8: FALSE | R8: FALSE | S8: FALSE | T8: FALSE | U8: FALSE | V8: FALSE | W8: FALSE | X8: FALSE | Y8: FALSE
B9: C1 | C9: C2 | D9: C3 | E9: C4 | F9: C5 | G9: C6 | H9: C7 | I9: C8 | J9: C9 | K9: C10 | L9: C11 | M9: C12 | N9: C13 | O9: C14 | P9: C15 | Q9: C16 | R9: C17 | S9: C18 | T9: C19 | U9: C20 | V9: C21 | W9: C22 | X9: C23 | Y9: C24
B10: {=IFERROR(IF(OR('Raw Data'!B10="",LEN(TRIM('Raw Data'!B10))=0),_xlfn.REGEXEXTRACT(CELL("address",'Raw Data'!B10),"\$([A-Z]+)\$[0-9]+"),""),"")} | C10: {=IFERROR(IF(OR('Raw Data'!C10="",LEN(TRIM('Raw Data'!C10))=0),_xlfn.REGEXEXTRACT(CELL("address",'Raw Data'!C10),"\$([A-Z]+)\$[0-9]+"),""),"")} | D10: {=IFERROR(IF(OR('Raw Data'!D10="",LEN(TRIM('Raw Data'!D10))=0),_xlfn.REGEXEXTRACT(CELL("address",'Raw Data'!D10),"\$([A-Z]+)\$[0-9]+"),""),"")} | E10: {=IFERROR(IF(OR('Raw Data'!E10="",LEN(TRIM('Raw Data'!E10))=0),_xlfn.REGEXEXTRACT(CELL("address",'Raw Data'!E10),"\$([A-Z]+)\$[0-9]+"),""),"")} | F10: {=IFERROR(IF(OR('Raw Data'!F10="",LEN(TRIM('Raw Data'!F10))=0),_xlfn.REGEXEXTRACT(CELL("address",'Raw Data'!F10),"\$([A-Z]+)\$[0-9]+"),""),"")} | G10: {=IFERROR(IF(OR('Raw Data'!G10="",LEN(TRIM('Raw Data'!G10))=0),_xlfn.REGEXEXTRACT(CELL("address",'Raw Data'!G10),"\$([A-Z]+)\$[0-9]+"),""),"")} | H10: {=IFERROR(IF(OR('Raw Data'!H10="",LEN(TRIM('Raw Data'!H10))=0),_xlfn.REGEXEXTRACT(CELL("address",'Raw Data'!H10),"\$([A-Z]+)\$[0-9]+"),""),"")} | I10: {=IFERROR(IF(OR('Raw Data'!I10="",LEN(TRIM('Raw Data'!I10))=0),_xlfn.REGEXEXTRACT(CELL("address",'Raw Data'!I10),"\$([A-Z]+)\$[0-9]+"),""),"")} | ... P10: {=IFERROR(IF(OR('Raw Data'!P10="",LEN(TRIM('Raw Data'!P10))=0),_xlfn.REGEXEXTRACT(CELL("address",'Raw Data'!P10),"\$([A-Z]+)\$[0-9]+"),""),"")}
B11: {=IFERROR(IF(OR('Raw Data'!B11="",LEN(TRIM('Raw Data'!B11))=0),_xlfn.REGEXEXTRACT(CELL("address",'Raw Data'!B11),"\$([A-Z]+)\$[0-9]+"),""),"")} | C11: {=IFERROR(IF(OR('Raw Data'!C11="",LEN(TRIM('Raw Data'!C11))=0),_xlfn.REGEXEXTRACT(CELL("address",'Raw Data'!C11),"\$([A-Z]+)\$[0-9]+"),""),"")} | D11: {=IFERROR(IF(OR('Raw Data'!D11="",LEN(TRIM('Raw Data'!D11))=0),_xlfn.REGEXEXTRACT(CELL("address",'Raw Data'!D11),"\$([A-Z]+)\$[0-9]+"),""),"")} | E11: {=IFERROR(IF(OR('Raw Data'!E11="",LEN(TRIM('Raw Data'!E11))=0),_xlfn.REGEXEXTRACT(CELL("address",'Raw Data'!E11),"\$([A-Z]+)\$[0-9]+"),""),"")} | F11: {=IFERROR(IF(OR('Raw Data'!F11="",LEN(TRIM('Raw Data'!F11))=0),_xlfn.REGEXEXTRACT(CELL("address",'Raw Data'!F11),"\$([A-Z]+)\$[0-9]+"),""),"")} | G11: {=IFERROR(IF(OR('Raw Data'!G11="",LEN(TRIM('Raw Data'!G11))=0),_xlfn.REGEXEXTRACT(CELL("address",'Raw Data'!G11),"\$([A-Z]+)\$[0-9]+"),""),"")} | H11: {=IFERROR(IF(OR('Raw Data'!H11="",LEN(TRIM('Raw Data'!H11))=0),_xlfn.REGEXEXTRACT(CELL("address",'Raw Data'!H11),"\$([A-Z]+)\$[0-9]+"),""),"")} | I11: {=IFERROR(IF(OR('Raw Data'!I11="",LEN(TRIM('Raw Data'!I11))=0),_xlfn.REGEXEXTRACT(CELL("address",'Raw Data'!I11),"\$([A-Z]+)\$[0-9]+"),""),"")} | ... P11: {=IFERROR(IF(OR('Raw Data'!P11="",LEN(TRIM('Raw Data'!P11))=0),_xlfn.REGEXEXTRACT(CELL("address",'Raw Data'!P11),"\$([A-Z]+)\$[0-9]+"),""),"")}
B12: {=IFERROR(IF(OR('Raw Data'!B12="",LEN(TRIM('Raw Data'!B12))=0),_xlfn.REGEXEXTRACT(CELL("address",'Raw Data'!B12),"\$([A-Z]+)\$[0-9]+"),""),"")} | C12: {=IFERROR(IF(OR('Raw Data'!C12="",LEN(TRIM('Raw Data'!C12))=0),_xlfn.REGEXEXTRACT(CELL("address",'Raw Data'!C12),"\$([A-Z]+)\$[0-9]+"),""),"")} | D12: {=IFERROR(IF(OR('Raw Data'!D12="",LEN(TRIM('Raw Data'!D12))=0),_xlfn.REGEXEXTRACT(CELL("address",'Raw Data'!D12),"\$([A-Z]+)\$[0-9]+"),""),"")} | E12: {=IFERROR(IF(OR('Raw Data'!E12="",LEN(TRIM('Raw Data'!E12))=0),_xlfn.REGEXEXTRACT(CELL("address",'Raw Data'!E12),"\$([A-Z]+)\$[0-9]+"),""),"")} | F12: {=IFERROR(IF(OR('Raw Data'!F12="",LEN(TRIM('Raw Data'!F12))=0),_xlfn.REGEXEXTRACT(CELL("address",'Raw Data'!F12),"\$([A-Z]+)\$[0-9]+"),""),"")} | G12: {=IFERROR(IF(OR('Raw Data'!G12="",LEN(TRIM('Raw Data'!G12))=0),_xlfn.REGEXEXTRACT(CELL("address",'Raw Data'!G12),"\$([A-Z]+)\$[0-9]+"),""),"")} | H12: {=IFERROR(IF(OR('Raw Data'!H12="",LEN(TRIM('Raw Data'!H12))=0),_xlfn.REGEXEXTRACT(CELL("address",'Raw Data'!H12),"\$([A-Z]+)\$[0-9]+"),""),"")} | I12: {=IFERROR(IF(OR('Raw Data'!I12="",LEN(TRIM('Raw Data'!I12))=0),_xlfn.REGEXEXTRACT(CELL("address",'Raw Data'!I12),"\$([A-Z]+)\$[0-9]+"),""),"")} | ... P12: {=IFERROR(IF(OR('Raw Data'!P12="",LEN(TRIM('Raw Data'!P12))=0),_xlfn.REGEXEXTRACT(CELL("address",'Raw Data'!P12),"\$([A-Z]+)\$[0-9]+"),""),"")}
B13: {=IFERROR(IF(OR('Raw Data'!B13="",LEN(TRIM('Raw Data'!B13))=0),_xlfn.REGEXEXTRACT(CELL("address",'Raw Data'!B13),"\$([A-Z]+)\$[0-9]+"),""),"")} | C13: {=IFERROR(IF(OR('Raw Data'!C13="",LEN(TRIM('Raw Data'!C13))=0),_xlfn.REGEXEXTRACT(CELL("address",'Raw Data'!C13),"\$([A-Z]+)\$[0-9]+"),""),"")} | D13: {=IFERROR(IF(OR('Raw Data'!D13="",LEN(TRIM('Raw Data'!D13))=0),_xlfn.REGEXEXTRACT(CELL("address",'Raw Data'!D13),"\$([A-Z]+)\$[0-9]+"),""),"")} | E13: {=IFERROR(IF(OR('Raw Data'!E13="",LEN(TRIM('Raw Data'!E13))=0),_xlfn.REGEXEXTRACT(CELL("address",'Raw Data'!E13),"\$([A-Z]+)\$[0-9]+"),""),"")} | F13: {=IFERROR(IF(OR('Raw Data'!F13="",LEN(TRIM('Raw Data'!F13))=0),_xlfn.REGEXEXTRACT(CELL("address",'Raw Data'!F13),"\$([A-Z]+)\$[0-9]+"),""),"")} | G13: {=IFERROR(IF(OR('Raw Data'!G13="",LEN(TRIM('Raw Data'!G13))=0),_xlfn.REGEXEXTRACT(CELL("address",'Raw Data'!G13),"\$([A-Z]+)\$[0-9]+"),""),"")} | H13: {=IFERROR(IF(OR('Raw Data'!H13="",LEN(TRIM('Raw Data'!H13))=0),_xlfn.REGEXEXTRACT(CELL("address",'Raw Data'!H13),"\$([A-Z]+)\$[0-9]+"),""),"")} | I13: {=IFERROR(IF(OR('Raw Data'!I13="",LEN(TRIM('Raw Data'!I13))=0),_xlfn.REGEXEXTRACT(CELL("address",'Raw Data'!I13),"\$([A-Z]+)\$[0-9]+"),""),"")} | ... P13: {=IFERROR(IF(OR('Raw Data'!P13="",LEN(TRIM('Raw Data'!P13))=0),_xlfn.REGEXEXTRACT(CELL("address",'Raw Data'!P13),"\$([A-Z]+)\$[0-9]+"),""),"")}
B14: {=IFERROR(IF(OR('Raw Data'!B14="",LEN(TRIM('Raw Data'!B14))=0),_xlfn.REGEXEXTRACT(CELL("address",'Raw Data'!B14),"\$([A-Z]+)\$[0-9]+"),""),"")} | C14: {=IFERROR(IF(OR('Raw Data'!C14="",LEN(TRIM('Raw Data'!C14))=0),_xlfn.REGEXEXTRACT(CELL("address",'Raw Data'!C14),"\$([A-Z]+)\$[0-9]+"),""),"")} | D14: {=IFERROR(IF(OR('Raw Data'!D14="",LEN(TRIM('Raw Data'!D14))=0),_xlfn.REGEXEXTRACT(CELL("address",'Raw Data'!D14),"\$([A-Z]+)\$[0-9]+"),""),"")} | E14: {=IFERROR(IF(OR('Raw Data'!E14="",LEN(TRIM('Raw Data'!E14))=0),_xlfn.REGEXEXTRACT(CELL("address",'Raw Data'!E14),"\$([A-Z]+)\$[0-9]+"),""),"")} | F14: {=IFERROR(IF(OR('Raw Data'!F14="",LEN(TRIM('Raw Data'!F14))=0),_xlfn.REGEXEXTRACT(CELL("address",'Raw Data'!F14),"\$([A-Z]+)\$[0-9]+"),""),"")} | G14: {=IFERROR(IF(OR('Raw Data'!G14="",LEN(TRIM('Raw Data'!G14))=0),_xlfn.REGEXEXTRACT(CELL("address",'Raw Data'!G14),"\$([A-Z]+)\$[0-9]+"),""),"")} | H14: {=IFERROR(IF(OR('Raw Data'!H14="",LEN(TRIM('Raw Data'!H14))=0),_xlfn.REGEXEXTRACT(CELL("address",'Raw Data'!H14),"\$([A-Z]+)\$[0-9]+"),""),"")} | I14: {=IFERROR(IF(OR('Raw Data'!I14="",LEN(TRIM('Raw Data'!I14))=0),_xlfn.REGEXEXTRACT(CELL("address",'Raw Data'!I14),"\$([A-Z]+)\$[0-9]+"),""),"")} | ... P14: {=IFERROR(IF(OR('Raw Data'!P14="",LEN(TRIM('Raw Data'!P14))=0),_xlfn.REGEXEXTRACT(CELL("address",'Raw Data'!P14),"\$([A-Z]+)\$[0-9]+"),""),"")}
B15: {=IFERROR(IF(OR('Raw Data'!B15="",LEN(TRIM('Raw Data'!B15))=0),_xlfn.REGEXEXTRACT(CELL("address",'Raw Data'!B15),"\$([A-Z]+)\$[0-9]+"),""),"")} | C15: {=IFERROR(IF(OR('Raw Data'!C15="",LEN(TRIM('Raw Data'!C15))=0),_xlfn.REGEXEXTRACT(CELL("address",'Raw Data'!C15),"\$([A-Z]+)\$[0-9]+"),""),"")} | D15: {=IFERROR(IF(OR('Raw Data'!D15="",LEN(TRIM('Raw Data'!D15))=0),_xlfn.REGEXEXTRACT(CELL("address",'Raw Data'!D15),"\$([A-Z]+)\$[0-9]+"),""),"")} | E15: {=IFERROR(IF(OR('Raw Data'!E15="",LEN(TRIM('Raw Data'!E15))=0),_xlfn.REGEXEXTRACT(CELL("address",'Raw Data'!E15),"\$([A-Z]+)\$[0-9]+"),""),"")} | F15: {=IFERROR(IF(OR('Raw Data'!F15="",LEN(TRIM('Raw Data'!F15))=0),_xlfn.REGEXEXTRACT(CELL("address",'Raw Data'!F15),"\$([A-Z]+)\$[0-9]+"),""),"")} | G15: {=IFERROR(IF(OR('Raw Data'!G15="",LEN(TRIM('Raw Data'!G15))=0),_xlfn.REGEXEXTRACT(CELL("address",'Raw Data'!G15),"\$([A-Z]+)\$[0-9]+"),""),"")} | H15: {=IFERROR(IF(OR('Raw Data'!H15="",LEN(TRIM('Raw Data'!H15))=0),_xlfn.REGEXEXTRACT(CELL("address",'Raw Data'!H15),"\$([A-Z]+)\$[0-9]+"),""),"")} | I15: {=IFERROR(IF(OR('Raw Data'!I15="",LEN(TRIM('Raw Data'!I15))=0),_xlfn.REGEXEXTRACT(CELL("address",'Raw Data'!I15),"\$([A-Z]+)\$[0-9]+"),""),"")} | ... P15: {=IFERROR(IF(OR('Raw Data'!P15="",LEN(TRIM('Raw Data'!P15))=0),_xlfn.REGEXEXTRACT(CELL("address",'Raw Data'!P15),"\$([A-Z]+)\$[0-9]+"),""),"")}
B16: {=IFERROR(IF(OR('Raw Data'!B16="",LEN(TRIM('Raw Data'!B16))=0),_xlfn.REGEXEXTRACT(CELL("address",'Raw Data'!B16),"\$([A-Z]+)\$[0-9]+"),""),"")} | C16: {=IFERROR(IF(OR('Raw Data'!C16="",LEN(TRIM('Raw Data'!C16))=0),_xlfn.REGEXEXTRACT(CELL("address",'Raw Data'!C16),"\$([A-Z]+)\$[0-9]+"),""),"")} | D16: {=IFERROR(IF(OR('Raw Data'!D16="",LEN(TRIM('Raw Data'!D16))=0),_xlfn.REGEXEXTRACT(CELL("address",'Raw Data'!D16),"\$([A-Z]+)\$[0-9]+"),""),"")} | E16: {=IFERROR(IF(OR('Raw Data'!E16="",LEN(TRIM('Raw Data'!E16))=0),_xlfn.REGEXEXTRACT(CELL("address",'Raw Data'!E16),"\$([A-Z]+)\$[0-9]+"),""),"")} | F16: {=IFERROR(IF(OR('Raw Data'!F16="",LEN(TRIM('Raw Data'!F16))=0),_xlfn.REGEXEXTRACT(CELL("address",'Raw Data'!F16),"\$([A-Z]+)\$[0-9]+"),""),"")} | G16: {=IFERROR(IF(OR('Raw Data'!G16="",LEN(TRIM('Raw Data'!G16))=0),_xlfn.REGEXEXTRACT(CELL("address",'Raw Data'!G16),"\$([A-Z]+)\$[0-9]+"),""),"")} | H16: {=IFERROR(IF(OR('Raw Data'!H16="",LEN(TRIM('Raw Data'!H16))=0),_xlfn.REGEXEXTRACT(CELL("address",'Raw Data'!H16),"\$([A-Z]+)\$[0-9]+"),""),"")} | I16: {=IFERROR(IF(OR('Raw Data'!I16="",LEN(TRIM('Raw Data'!I16))=0),_xlfn.REGEXEXTRACT(CELL("address",'Raw Data'!I16),"\$([A-Z]+)\$[0-9]+"),""),"")} | ... P16: {=IFERROR(IF(OR('Raw Data'!P16="",LEN(TRIM('Raw Data'!P16))=0),_xlfn.REGEXEXTRACT(CELL("address",'Raw Data'!P16),"\$([A-Z]+)\$[0-9]+"),""),"")}
B17: {=IFERROR(IF(OR('Raw Data'!B17="",LEN(TRIM('Raw Data'!B17))=0),_xlfn.REGEXEXTRACT(CELL("address",'Raw Data'!B17),"\$([A-Z]+)\$[0-9]+"),""),"")} | C17: {=IFERROR(IF(OR('Raw Data'!C17="",LEN(TRIM('Raw Data'!C17))=0),_xlfn.REGEXEXTRACT(CELL("address",'Raw Data'!C17),"\$([A-Z]+)\$[0-9]+"),""),"")} | D17: {=IFERROR(IF(OR('Raw Data'!D17="",LEN(TRIM('Raw Data'!D17))=0),_xlfn.REGEXEXTRACT(CELL("address",'Raw Data'!D17),"\$([A-Z]+)\$[0-9]+"),""),"")} | E17: {=IFERROR(IF(OR('Raw Data'!E17="",LEN(TRIM('Raw Data'!E17))=0),_xlfn.REGEXEXTRACT(CELL("address",'Raw Data'!E17),"\$([A-Z]+)\$[0-9]+"),""),"")} | F17: {=IFERROR(IF(OR('Raw Data'!F17="",LEN(TRIM('Raw Data'!F17))=0),_xlfn.REGEXEXTRACT(CELL("address",'Raw Data'!F17),"\$([A-Z]+)\$[0-9]+"),""),"")} | G17: {=IFERROR(IF(OR('Raw Data'!G17="",LEN(TRIM('Raw Data'!G17))=0),_xlfn.REGEXEXTRACT(CELL("address",'Raw Data'!G17),"\$([A-Z]+)\$[0-9]+"),""),"")} | H17: {=IFERROR(IF(OR('Raw Data'!H17="",LEN(TRIM('Raw Data'!H17))=0),_xlfn.REGEXEXTRACT(CELL("address",'Raw Data'!H17),"\$([A-Z]+)\$[0-9]+"),""),"")} | I17: {=IFERROR(IF(OR('Raw Data'!I17="",LEN(TRIM('Raw Data'!I17))=0),_xlfn.REGEXEXTRACT(CELL("address",'Raw Data'!I17),"\$([A-Z]+)\$[0-9]+"),""),"")} | ... P17: {=IFERROR(IF(OR('Raw Data'!P17="",LEN(TRIM('Raw Data'!P17))=0),_xlfn.REGEXEXTRACT(CELL("address",'Raw Data'!P17),"\$([A-Z]+)\$[0-9]+"),""),"")}
B18: {=IFERROR(IF(OR('Raw Data'!B18="",LEN(TRIM('Raw Data'!B18))=0),_xlfn.REGEXEXTRACT(CELL("address",'Raw Data'!B18),"\$([A-Z]+)\$[0-9]+"),""),"")} | C18: {=IFERROR(IF(OR('Raw Data'!C18="",LEN(TRIM('Raw Data'!C18))=0),_xlfn.REGEXEXTRACT(CELL("address",'Raw Data'!C18),"\$([A-Z]+)\$[0-9]+"),""),"")} | D18: {=IFERROR(IF(OR('Raw Data'!D18="",LEN(TRIM('Raw Data'!D18))=0),_xlfn.REGEXEXTRACT(CELL("address",'Raw Data'!D18),"\$([A-Z]+)\$[0-9]+"),""),"")} | E18: {=IFERROR(IF(OR('Raw Data'!E18="",LEN(TRIM('Raw Data'!E18))=0),_xlfn.REGEXEXTRACT(CELL("address",'Raw Data'!E18),"\$([A-Z]+)\$[0-9]+"),""),"")} | F18: {=IFERROR(IF(OR('Raw Data'!F18="",LEN(TRIM('Raw Data'!F18))=0),_xlfn.REGEXEXTRACT(CELL("address",'Raw Data'!F18),"\$([A-Z]+)\$[0-9]+"),""),"")} | G18: {=IFERROR(IF(OR('Raw Data'!G18="",LEN(TRIM('Raw Data'!G18))=0),_xlfn.REGEXEXTRACT(CELL("address",'Raw Data'!G18),"\$([A-Z]+)\$[0-9]+"),""),"")} | H18: {=IFERROR(IF(OR('Raw Data'!H18="",LEN(TRIM('Raw Data'!H18))=0),_xlfn.REGEXEXTRACT(CELL("address",'Raw Data'!H18),"\$([A-Z]+)\$[0-9]+"),""),"")} | I18: {=IFERROR(IF(OR('Raw Data'!I18="",LEN(TRIM('Raw Data'!I18))=0),_xlfn.REGEXEXTRACT(CELL("address",'Raw Data'!I18),"\$([A-Z]+)\$[0-9]+"),""),"")} | ... P18: {=IFERROR(IF(OR('Raw Data'!P18="",LEN(TRIM('Raw Data'!P18))=0),_xlfn.REGEXEXTRACT(CELL("address",'Raw Data'!P18),"\$([A-Z]+)\$[0-9]+"),""),"")}
B19: {=IFERROR(IF(OR('Raw Data'!B19="",LEN(TRIM('Raw Data'!B19))=0),_xlfn.REGEXEXTRACT(CELL("address",'Raw Data'!B19),"\$([A-Z]+)\$[0-9]+"),""),"")} | C19: {=IFERROR(IF(OR('Raw Data'!C19="",LEN(TRIM('Raw Data'!C19))=0),_xlfn.REGEXEXTRACT(CELL("address",'Raw Data'!C19),"\$([A-Z]+)\$[0-9]+"),""),"")} | D19: {=IFERROR(IF(OR('Raw Data'!D19="",LEN(TRIM('Raw Data'!D19))=0),_xlfn.REGEXEXTRACT(CELL("address",'Raw Data'!D19),"\$([A-Z]+)\$[0-9]+"),""),"")} | E19: {=IFERROR(IF(OR('Raw Data'!E19="",LEN(TRIM('Raw Data'!E19))=0),_xlfn.REGEXEXTRACT(CELL("address",'Raw Data'!E19),"\$([A-Z]+)\$[0-9]+"),""),"")} | F19: {=IFERROR(IF(OR('Raw Data'!F19="",LEN(TRIM('Raw Data'!F19))=0),_xlfn.REGEXEXTRACT(CELL("address",'Raw Data'!F19),"\$([A-Z]+)\$[0-9]+"),""),"")} | G19: {=IFERROR(IF(OR('Raw Data'!G19="",LEN(TRIM('Raw Data'!G19))=0),_xlfn.REGEXEXTRACT(CELL("address",'Raw Data'!G19),"\$([A-Z]+)\$[0-9]+"),""),"")} | H19: {=IFERROR(IF(OR('Raw Data'!H19="",LEN(TRIM('Raw Data'!H19))=0),_xlfn.REGEXEXTRACT(CELL("address",'Raw Data'!H19),"\$([A-Z]+)\$[0-9]+"),""),"")} | I19: {=IFERROR(IF(OR('Raw Data'!I19="",LEN(TRIM('Raw Data'!I19))=0),_xlfn.REGEXEXTRACT(CELL("address",'Raw Data'!I19),"\$([A-Z]+)\$[0-9]+"),""),"")} | ... P19: {=IFERROR(IF(OR('Raw Data'!P19="",LEN(TRIM('Raw Data'!P19))=0),_xlfn.REGEXEXTRACT(CELL("address",'Raw Data'!P19),"\$([A-Z]+)\$[0-9]+"),""),"")}
B20: {=IFERROR(IF(OR('Raw Data'!B20="",LEN(TRIM('Raw Data'!B20))=0),_xlfn.REGEXEXTRACT(CELL("address",'Raw Data'!B20),"\$([A-Z]+)\$[0-9]+"),""),"")} | C20: {=IFERROR(IF(OR('Raw Data'!C20="",LEN(TRIM('Raw Data'!C20))=0),_xlfn.REGEXEXTRACT(CELL("address",'Raw Data'!C20),"\$([A-Z]+)\$[0-9]+"),""),"")} | D20: {=IFERROR(IF(OR('Raw Data'!D20="",LEN(TRIM('Raw Data'!D20))=0),_xlfn.REGEXEXTRACT(CELL("address",'Raw Data'!D20),"\$([A-Z]+)\$[0-9]+"),""),"")} | E20: {=IFERROR(IF(OR('Raw Data'!E20="",LEN(TRIM('Raw Data'!E20))=0),_xlfn.REGEXEXTRACT(CELL("address",'Raw Data'!E20),"\$([A-Z]+)\$[0-9]+"),""),"")} | F20: {=IFERROR(IF(OR('Raw Data'!F20="",LEN(TRIM('Raw Data'!F20))=0),_xlfn.REGEXEXTRACT(CELL("address",'Raw Data'!F20),"\$([A-Z]+)\$[0-9]+"),""),"")} | G20: {=IFERROR(IF(OR('Raw Data'!G20="",LEN(TRIM('Raw Data'!G20))=0),_xlfn.REGEXEXTRACT(CELL("address",'Raw Data'!G20),"\$([A-Z]+)\$[0-9]+"),""),"")} | H20: {=IFERROR(IF(OR('Raw Data'!H20="",LEN(TRIM('Raw Data'!H20))=0),_xlfn.REGEXEXTRACT(CELL("address",'Raw Data'!H20),"\$([A-Z]+)\$[0-9]+"),""),"")} | I20: {=IFERROR(IF(OR('Raw Data'!I20="",LEN(TRIM('Raw Data'!I20))=0),_xlfn.REGEXEXTRACT(CELL("address",'Raw Data'!I20),"\$([A-Z]+)\$[0-9]+"),""),"")} | ... P20: {=IFERROR(IF(OR('Raw Data'!P20="",LEN(TRIM('Raw Data'!P20))=0),_xlfn.REGEXEXTRACT(CELL("address",'Raw Data'!P20),"\$([A-Z]+)\$[0-9]+"),""),"")}
B21: {=IFERROR(IF(OR('Raw Data'!B21="",LEN(TRIM('Raw Data'!B21))=0),_xlfn.REGEXEXTRACT(CELL("address",'Raw Data'!B21),"\$([A-Z]+)\$[0-9]+"),""),"")} | C21: {=IFERROR(IF(OR('Raw Data'!C21="",LEN(TRIM('Raw Data'!C21))=0),_xlfn.REGEXEXTRACT(CELL("address",'Raw Data'!C21),"\$([A-Z]+)\$[0-9]+"),""),"")} | D21: {=IFERROR(IF(OR('Raw Data'!D21="",LEN(TRIM('Raw Data'!D21))=0),_xlfn.REGEXEXTRACT(CELL("address",'Raw Data'!D21),"\$([A-Z]+)\$[0-9]+"),""),"")} | E21: {=IFERROR(IF(OR('Raw Data'!E21="",LEN(TRIM('Raw Data'!E21))=0),_xlfn.REGEXEXTRACT(CELL("address",'Raw Data'!E21),"\$([A-Z]+)\$[0-9]+"),""),"")} | F21: {=IFERROR(IF(OR('Raw Data'!F21="",LEN(TRIM('Raw Data'!F21))=0),_xlfn.REGEXEXTRACT(CELL("address",'Raw Data'!F21),"\$([A-Z]+)\$[0-9]+"),""),"")} | G21: {=IFERROR(IF(OR('Raw Data'!G21="",LEN(TRIM('Raw Data'!G21))=0),_xlfn.REGEXEXTRACT(CELL("address",'Raw Data'!G21),"\$([A-Z]+)\$[0-9]+"),""),"")} | H21: {=IFERROR(IF(OR('Raw Data'!H21="",LEN(TRIM('Raw Data'!H21))=0),_xlfn.REGEXEXTRACT(CELL("address",'Raw Data'!H21),"\$([A-Z]+)\$[0-9]+"),""),"")} | I21: {=IFERROR(IF(OR('Raw Data'!I21="",LEN(TRIM('Raw Data'!I21))=0),_xlfn.REGEXEXTRACT(CELL("address",'Raw Data'!I21),"\$([A-Z]+)\$[0-9]+"),""),"")} | ... P21: {=IFERROR(IF(OR('Raw Data'!P21="",LEN(TRIM('Raw Data'!P21))=0),_xlfn.REGEXEXTRACT(CELL("address",'Raw Data'!P21),"\$([A-Z]+)\$[0-9]+"),""),"")}
... B1647: {=IFERROR(IF(OR('Raw Data'!B1647="",LEN(TRIM('Raw Data'!B1647))=0),_xlfn.REGEXEXTRACT(CELL("address",'Raw Data'!B1647),"\$([A-Z]+)\$[0-9]+"),""),"")} | C1647: {=IFERROR(IF(OR('Raw Data'!C1647="",LEN(TRIM('Raw Data'!C1647))=0),_xlfn.REGEXEXTRACT(CELL("address",'Raw Data'!C1647),"\$([A-Z]+)\$[0-9]+"),""),"")} | D1647: {=IFERROR(IF(OR('Raw Data'!D1647="",LEN(TRIM('Raw Data'!D1647))=0),_xlfn.REGEXEXTRACT(CELL("address",'Raw Data'!D1647),"\$([A-Z]+)\$[0-9]+"),""),"")} | E1647: {=IFERROR(IF(OR('Raw Data'!E1647="",LEN(TRIM('Raw Data'!E1647))=0),_xlfn.REGEXEXTRACT(CELL("address",'Raw Data'!E1647),"\$([A-Z]+)\$[0-9]+"),""),"")} | F1647: {=IFERROR(IF(OR('Raw Data'!F1647="",LEN(TRIM('Raw Data'!F1647))=0),_xlfn.REGEXEXTRACT(CELL("address",'Raw Data'!F1647),"\$([A-Z]+)\$[0-9]+"),""),"")} | G1647: {=IFERROR(IF(OR('Raw Data'!G1647="",LEN(TRIM('Raw Data'!G1647))=0),_xlfn.REGEXEXTRACT(CELL("address",'Raw Data'!G1647),"\$([A-Z]+)\$[0-9]+"),""),"")} | H1647: {=IFERROR(IF(OR('Raw Data'!H1647="",LEN(TRIM('Raw Data'!H1647))=0),_xlfn.REGEXEXTRACT(CELL("address",'Raw Data'!H1647),"\$([A-Z]+)\$[0-9]+"),""),"")} | I1647: {=IFERROR(IF(OR('Raw Data'!I1647="",LEN(TRIM('Raw Data'!I1647))=0),_xlfn.REGEXEXTRACT(CELL("address",'Raw Data'!I1647),"\$([A-Z]+)\$[0-9]+"),""),"")} | ... P1647: {=IFERROR(IF(OR('Raw Data'!P1647="",LEN(TRIM('Raw Data'!P1647))=0),_xlfn.REGEXEXTRACT(CELL("address",'Raw Data'!P1647),"\$([A-Z]+)\$[0-9]+"),""),"")}

Sheet Validate_Value
B8: NVARCHAR(10) | C8: NVARCHAR(20) | D8: NVARCHAR(20) | E8: NVARCHAR(20) | F8: NVARCHAR(20) | G8: NVARCHAR(10) | H8: NVARCHAR(255) | I8: NVARCHAR(255) | J8: NVARCHAR(255) | K8: NVARCHAR(255) | L8: NVARCHAR(255) | M8: NVARCHAR(255) | N8: NVARCHAR(255) | O8: NVARCHAR(255) | P8: NVARCHAR(10) | Q8: DECIMAL(13,2) | R8: DECIMAL(13,2) | S8: DECIMAL(13,2) | T8: DECIMAL(13,2) | U8: DECIMAL(13,2) | V8: DECIMAL(13,2) | W8: DECIMAL(13,2) | X8: DECIMAL(13,2) | Y8: DECIMAL(13,2)
B9: C1 | C9: C2 | D9: C3 | E9: C4 | F9: C5 | G9: C6 | H9: C7 | I9: C8 | J9: C9 | K9: C10 | L9: C11 | M9: C12 | N9: C13 | O9: C14 | P9: C15 | Q9: C16 | R9: C17 | S9: C18 | T9: C19 | U9: C20 | V9: C21 | W9: C22 | X9: C23 | Y9: C24
B10: {=IFERROR(IF(OR('Raw Data'!B10="",LEN(TRIM('Raw Data'!B10))=0),"",IF(AND(LEN('Raw Data'!B10) <= 10,LEN('Raw Data'!B10)> 0),"",_xlfn.REGEXEXTRACT(CELL("address",'Raw Data'!B10),"\$([A-Z]+)\$[0-9]+"))),_xlfn.REGEXEXTRACT(CELL("address",'Raw Data'!B10),"\$([A-Z]+)\$[0-9]+"))} | C10: {=IFERROR(IF(OR('Raw Data'!C10="",LEN(TRIM('Raw Data'!C10))=0),"",IF(AND(LEN('Raw Data'!C10) <= 20,LEN('Raw Data'!C10)> 0),"",_xlfn.REGEXEXTRACT(CELL("address",'Raw Data'!C10),"\$([A-Z]+)\$[0-9]+"))),_xlfn.REGEXEXTRACT(CELL("address",'Raw Data'!C10),"\$([A-Z]+)\$[0-9]+"))} | D10: {=IFERROR(IF(OR('Raw Data'!D10="",LEN(TRIM('Raw Data'!D10))=0),"",IF(AND(LEN('Raw Data'!D10) <= 20,LEN('Raw Data'!D10)> 0),"",_xlfn.REGEXEXTRACT(CELL("address",'Raw Data'!D10),"\$([A-Z]+)\$[0-9]+"))),_xlfn.REGEXEXTRACT(CELL("address",'Raw Data'!D10),"\$([A-Z]+)\$[0-9]+"))} | E10: {=IFERROR(IF(OR('Raw Data'!E10="",LEN(TRIM('Raw Data'!E10))=0),"",IF(AND(LEN('Raw Data'!E10) <= 20,LEN('Raw Data'!E10)> 0),"",_xlfn.REGEXEXTRACT(CELL("address",'Raw Data'!E10),"\$([A-Z]+)\$[0-9]+"))),_xlfn.REGEXEXTRACT(CELL("address",'Raw Data'!E10),"\$([A-Z]+)\$[0-9]+"))} | F10: {=IFERROR(IF(OR('Raw Data'!F10="",LEN(TRIM('Raw Data'!F10))=0),"",IF(AND(LEN('Raw Data'!F10) <= 20,LEN('Raw Data'!F10)> 0),"",_xlfn.REGEXEXTRACT(CELL("address",'Raw Data'!F10),"\$([A-Z]+)\$[0-9]+"))),_xlfn.REGEXEXTRACT(CELL("address",'Raw Data'!F10),"\$([A-Z]+)\$[0-9]+"))} | G10: {=IFERROR(IF(OR('Raw Data'!G10="",LEN(TRIM('Raw Data'!G10))=0),"",IF(AND(LEN('Raw Data'!G10) <= 10,LEN('Raw Data'!G10)> 0),"",_xlfn.REGEXEXTRACT(CELL("address",'Raw Data'!G10),"\$([A-Z]+)\$[0-9]+"))),_xlfn.REGEXEXTRACT(CELL("address",'Raw Data'!G10),"\$([A-Z]+)\$[0-9]+"))} | H10: {=IFERROR(IF(OR('Raw Data'!H10="",LEN(TRIM('Raw Data'!H10))=0),"",IF(AND(LEN('Raw Data'!H10) <= 255,LEN('Raw Data'!H10)> 0),"",_xlfn.REGEXEXTRACT(CELL("address",'Raw Data'!H10),"\$([A-Z]+)\$[0-9]+"))),_xlfn.REGEXEXTRACT(CELL("address",'Raw Data'!H10),"\$([A-Z]+)\$[0-9]+"))} | I10: {=IFERROR(IF(OR('Raw Data'!I10="",LEN(TRIM('Raw Data'!I10))=0),"",IF(AND(LEN('Raw Data'!I10) <= 255,LEN('Raw Data'!I10)> 0),"",_xlfn.REGEXEXTRACT(CELL("address",'Raw Data'!I10),"\$([A-Z]+)\$[0-9]+"))),_xlfn.REGEXEXTRACT(CELL("address",'Raw Data'!I10),"\$([A-Z]+)\$[0-9]+"))} | J10: {=IFERROR(IF(OR('Raw Data'!J10="",LEN(TRIM('Raw Data'!J10))=0),"",IF(AND(LEN('Raw Data'!J10) <= 255,LEN('Raw Data'!J10)> 0),"",_xlfn.REGEXEXTRACT(CELL("address",'Raw Data'!J10),"\$([A-Z]+)\$[0-9]+"))),_xlfn.REGEXEXTRACT(CELL("address",'Raw Data'!J10),"\$([A-Z]+)\$[0-9]+"))} | K10: {=IFERROR(IF(OR('Raw Data'!K10="",LEN(TRIM('Raw Data'!K10))=0),"",IF(AND(LEN('Raw Data'!K10) <= 255,LEN('Raw Data'!K10)> 0),"",_xlfn.REGEXEXTRACT(CELL("address",'Raw Data'!K10),"\$([A-Z]+)\$[0-9]+"))),_xlfn.REGEXEXTRACT(CELL("address",'Raw Data'!K10),"\$([A-Z]+)\$[0-9]+"))} | L10: {=IFERROR(IF(OR('Raw Data'!L10="",LEN(TRIM('Raw Data'!L10))=0),"",IF(AND(LEN('Raw Data'!L10) <= 255,LEN('Raw Data'!L10)> 0),"",_xlfn.REGEXEXTRACT(CELL("address",'Raw Data'!L10),"\$([A-Z]+)\$[0-9]+"))),_xlfn.REGEXEXTRACT(CELL("address",'Raw Data'!L10),"\$([A-Z]+)\$[0-9]+"))} | M10: {=IFERROR(IF(OR('Raw Data'!M10="",LEN(TRIM('Raw Data'!M10))=0),"",IF(AND(LEN('Raw Data'!M10) <= 255,LEN('Raw Data'!M10)> 0),"",_xlfn.REGEXEXTRACT(CELL("address",'Raw Data'!M10),"\$([A-Z]+)\$[0-9]+"))),_xlfn.REGEXEXTRACT(CELL("address",'Raw Data'!M10),"\$([A-Z]+)\$[0-9]+"))} | N10: {=IFERROR(IF(OR('Raw Data'!N10="",LEN(TRIM('Raw Data'!N10))=0),"",IF(AND(LEN('Raw Data'!N10) <= 255,LEN('Raw Data'!N10)> 0),"",_xlfn.REGEXEXTRACT(CELL("address",'Raw Data'!N10),"\$([A-Z]+)\$[0-9]+"))),_xlfn.REGEXEXTRACT(CELL("address",'Raw Data'!N10),"\$([A-Z]+)\$[0-9]+"))} | O10: {=IFERROR(IF(OR('Raw Data'!O10="",LEN(TRIM('Raw Data'!O10))=0),"",IF(AND(LEN('Raw Data'!O10) <= 255,LEN('Raw Data'!O10)> 0),"",_xlfn.REGEXEXTRACT(CELL("address",'Raw Data'!O10),"\$([A-Z]+)\$[0-9]+"))),_xlfn.REGEXEXTRACT(CELL("address",'Raw Data'!O10),"\$([A-Z]+)\$[0-9]+"))} | P10: {=IFERROR(IF(OR('Raw Data'!P10="",LEN(TRIM('Raw Data'!P10))=0),"",IF(AND(LEN('Raw Data'!P10) <= 10,LEN('Raw Data'!P10)> 0),"",_xlfn.REGEXEXTRACT(CELL("address",'Raw Data'!P10),"\$([A-Z]+)\$[0-9]+"))),_xlfn.REGEXEXTRACT(CELL("address",'Raw Data'!P10),"\$([A-Z]+)\$[0-9]+"))} | Q10: {=IFERROR(IF(OR('Raw Data'!Q10="",LEN(TRIM('Raw Data'!Q10))=0),"",IF(AND(ISNUMBER('Raw Data'!Q10), IFERROR('Raw Data'!Q10 = ROUND('Raw Data'!Q10, 2),FALSE)),"",_xlfn.REGEXEXTRACT(CELL("address",Q10), "\$([A-Z]+)\$[0-9]+"))),_xlfn.REGEXEXTRACT(CELL("address",Q10), "\$([A-Z]+)\$[0-9]+"))} | R10: {=IFERROR(IF(OR('Raw Data'!R10="",LEN(TRIM('Raw Data'!R10))=0),"",IF(AND(ISNUMBER('Raw Data'!R10), IFERROR('Raw Data'!R10 = ROUND('Raw Data'!R10, 2),FALSE)),"",_xlfn.REGEXEXTRACT(CELL("address",R10), "\$([A-Z]+)\$[0-9]+"))),_xlfn.REGEXEXTRACT(CELL("address",R10), "\$([A-Z]+)\$[0-9]+"))} | S10: {=IFERROR(IF(OR('Raw Data'!S10="",LEN(TRIM('Raw Data'!S10))=0),"",IF(AND(ISNUMBER('Raw Data'!S10), IFERROR('Raw Data'!S10 = ROUND('Raw Data'!S10, 2),FALSE)),"",_xlfn.REGEXEXTRACT(CELL("address",S10), "\$([A-Z]+)\$[0-9]+"))),_xlfn.REGEXEXTRACT(CELL("address",S10), "\$([A-Z]+)\$[0-9]+"))} | T10: {=IFERROR(IF(OR('Raw Data'!T10="",LEN(TRIM('Raw Data'!T10))=0),"",IF(AND(ISNUMBER('Raw Data'!T10), IFERROR('Raw Data'!T10 = ROUND('Raw Data'!T10, 2),FALSE)),"",_xlfn.REGEXEXTRACT(CELL("address",T10), "\$([A-Z]+)\$[0-9]+"))),_xlfn.REGEXEXTRACT(CELL("address",T10), "\$([A-Z]+)\$[0-9]+"))} | U10: {=IFERROR(IF(OR('Raw Data'!U10="",LEN(TRIM('Raw Data'!U10))=0),"",IF(AND(ISNUMBER('Raw Data'!U10), IFERROR('Raw Data'!U10 = ROUND('Raw Data'!U10, 2),FALSE)),"",_xlfn.REGEXEXTRACT(CELL("address",U10), "\$([A-Z]+)\$[0-9]+"))),_xlfn.REGEXEXTRACT(CELL("address",U10), "\$([A-Z]+)\$[0-9]+"))} | V10: {=IFERROR(IF(OR('Raw Data'!V10="",LEN(TRIM('Raw Data'!V10))=0),"",IF(AND(ISNUMBER('Raw Data'!V10), IFERROR('Raw Data'!V10 = ROUND('Raw Data'!V10, 2),FALSE)),"",_xlfn.REGEXEXTRACT(CELL("address",V10), "\$([A-Z]+)\$[0-9]+"))),_xlfn.REGEXEXTRACT(CELL("address",V10), "\$([A-Z]+)\$[0-9]+"))} | W10: {=IFERROR(IF(OR('Raw Data'!W10="",LEN(TRIM('Raw Data'!W10))=0),"",IF(AND(ISNUMBER('Raw Data'!W10), IFERROR('Raw Data'!W10 = ROUND('Raw Data'!W10, 2),FALSE)),"",_xlfn.REGEXEXTRACT(CELL("address",W10), "\$([A-Z]+)\$[0-9]+"))),_xlfn.REGEXEXTRACT(CELL("address",W10), "\$([A-Z]+)\$[0-9]+"))} | X10: {=IFERROR(IF(OR('Raw Data'!X10="",LEN(TRIM('Raw Data'!X10))=0),"",IF(AND(ISNUMBER('Raw Data'!X10), IFERROR('Raw Data'!X10 = ROUND('Raw Data'!X10, 2),FALSE)),"",_xlfn.REGEXEXTRACT(CELL("address",X10), "\$([A-Z]+)\$[0-9]+"))),_xlfn.REGEXEXTRACT(CELL("address",X10), "\$([A-Z]+)\$[0-9]+"))} | Y10: {=IFERROR(IF(OR('Raw Data'!Y10="",LEN(TRIM('Raw Data'!Y10))=0),"",IF(AND(ISNUMBER('Raw Data'!Y10), IFERROR('Raw Data'!Y10 = ROUND('Raw Data'!Y10, 2),FALSE)),"",_xlfn.REGEXEXTRACT(CELL("address",Y10), "\$([A-Z]+)\$[0-9]+"))),_xlfn.REGEXEXTRACT(CELL("address",Y10), "\$([A-Z]+)\$[0-9]+"))}
B11: {=IFERROR(IF(OR('Raw Data'!B11="",LEN(TRIM('Raw Data'!B11))=0),"",IF(AND(LEN('Raw Data'!B11) <= 10,LEN('Raw Data'!B11)> 0),"",_xlfn.REGEXEXTRACT(CELL("address",'Raw Data'!B11),"\$([A-Z]+)\$[0-9]+"))),_xlfn.REGEXEXTRACT(CELL("address",'Raw Data'!B11),"\$([A-Z]+)\$[0-9]+"))} | C11: {=IFERROR(IF(OR('Raw Data'!C11="",LEN(TRIM('Raw Data'!C11))=0),"",IF(AND(LEN('Raw Data'!C11) <= 20,LEN('Raw Data'!C11)> 0),"",_xlfn.REGEXEXTRACT(CELL("address",'Raw Data'!C11),"\$([A-Z]+)\$[0-9]+"))),_xlfn.REGEXEXTRACT(CELL("address",'Raw Data'!C11),"\$([A-Z]+)\$[0-9]+"))} | D11: {=IFERROR(IF(OR('Raw Data'!D11="",LEN(TRIM('Raw Data'!D11))=0),"",IF(AND(LEN('Raw Data'!D11) <= 20,LEN('Raw Data'!D11)> 0),"",_xlfn.REGEXEXTRACT(CELL("address",'Raw Data'!D11),"\$([A-Z]+)\$[0-9]+"))),_xlfn.REGEXEXTRACT(CELL("address",'Raw Data'!D11),"\$([A-Z]+)\$[0-9]+"))} | E11: {=IFERROR(IF(OR('Raw Data'!E11="",LEN(TRIM('Raw Data'!E11))=0),"",IF(AND(LEN('Raw Data'!E11) <= 20,LEN('Raw Data'!E11)> 0),"",_xlfn.REGEXEXTRACT(CELL("address",'Raw Data'!E11),"\$([A-Z]+)\$[0-9]+"))),_xlfn.REGEXEXTRACT(CELL("address",'Raw Data'!E11),"\$([A-Z]+)\$[0-9]+"))} | F11: {=IFERROR(IF(OR('Raw Data'!F11="",LEN(TRIM('Raw Data'!F11))=0),"",IF(AND(LEN('Raw Data'!F11) <= 20,LEN('Raw Data'!F11)> 0),"",_xlfn.REGEXEXTRACT(CELL("address",'Raw Data'!F11),"\$([A-Z]+)\$[0-9]+"))),_xlfn.REGEXEXTRACT(CELL("address",'Raw Data'!F11),"\$([A-Z]+)\$[0-9]+"))} | G11: {=IFERROR(IF(OR('Raw Data'!G11="",LEN(TRIM('Raw Data'!G11))=0),"",IF(AND(LEN('Raw Data'!G11) <= 10,LEN('Raw Data'!G11)> 0),"",_xlfn.REGEXEXTRACT(CELL("address",'Raw Data'!G11),"\$([A-Z]+)\$[0-9]+"))),_xlfn.REGEXEXTRACT(CELL("address",'Raw Data'!G11),"\$([A-Z]+)\$[0-9]+"))} | H11: {=IFERROR(IF(OR('Raw Data'!H11="",LEN(TRIM('Raw Data'!H11))=0),"",IF(AND(LEN('Raw Data'!H11) <= 255,LEN('Raw Data'!H11)> 0),"",_xlfn.REGEXEXTRACT(CELL("address",'Raw Data'!H11),"\$([A-Z]+)\$[0-9]+"))),_xlfn.REGEXEXTRACT(CELL("address",'Raw Data'!H11),"\$([A-Z]+)\$[0-9]+"))} | I11: {=IFERROR(IF(OR('Raw Data'!I11="",LEN(TRIM('Raw Data'!I11))=0),"",IF(AND(LEN('Raw Data'!I11) <= 255,LEN('Raw Data'!I11)> 0),"",_xlfn.REGEXEXTRACT(CELL("address",'Raw Data'!I11),"\$([A-Z]+)\$[0-9]+"))),_xlfn.REGEXEXTRACT(CELL("address",'Raw Data'!I11),"\$([A-Z]+)\$[0-9]+"))} | J11: {=IFERROR(IF(OR('Raw Data'!J11="",LEN(TRIM('Raw Data'!J11))=0),"",IF(AND(LEN('Raw Data'!J11) <= 255,LEN('Raw Data'!J11)> 0),"",_xlfn.REGEXEXTRACT(CELL("address",'Raw Data'!J11),"\$([A-Z]+)\$[0-9]+"))),_xlfn.REGEXEXTRACT(CELL("address",'Raw Data'!J11),"\$([A-Z]+)\$[0-9]+"))} | K11: {=IFERROR(IF(OR('Raw Data'!K11="",LEN(TRIM('Raw Data'!K11))=0),"",IF(AND(LEN('Raw Data'!K11) <= 255,LEN('Raw Data'!K11)> 0),"",_xlfn.REGEXEXTRACT(CELL("address",'Raw Data'!K11),"\$([A-Z]+)\$[0-9]+"))),_xlfn.REGEXEXTRACT(CELL("address",'Raw Data'!K11),"\$([A-Z]+)\$[0-9]+"))} | L11: {=IFERROR(IF(OR('Raw Data'!L11="",LEN(TRIM('Raw Data'!L11))=0),"",IF(AND(LEN('Raw Data'!L11) <= 255,LEN('Raw Data'!L11)> 0),"",_xlfn.REGEXEXTRACT(CELL("address",'Raw Data'!L11),"\$([A-Z]+)\$[0-9]+"))),_xlfn.REGEXEXTRACT(CELL("address",'Raw Data'!L11),"\$([A-Z]+)\$[0-9]+"))} | M11: {=IFERROR(IF(OR('Raw Data'!M11="",LEN(TRIM('Raw Data'!M11))=0),"",IF(AND(LEN('Raw Data'!M11) <= 255,LEN('Raw Data'!M11)> 0),"",_xlfn.REGEXEXTRACT(CELL("address",'Raw Data'!M11),"\$([A-Z]+)\$[0-9]+"))),_xlfn.REGEXEXTRACT(CELL("address",'Raw Data'!M11),"\$([A-Z]+)\$[0-9]+"))} | N11: {=IFERROR(IF(OR('Raw Data'!N11="",LEN(TRIM('Raw Data'!N11))=0),"",IF(AND(LEN('Raw Data'!N11) <= 255,LEN('Raw Data'!N11)> 0),"",_xlfn.REGEXEXTRACT(CELL("address",'Raw Data'!N11),"\$([A-Z]+)\$[0-9]+"))),_xlfn.REGEXEXTRACT(CELL("address",'Raw Data'!N11),"\$([A-Z]+)\$[0-9]+"))} | O11: {=IFERROR(IF(OR('Raw Data'!O11="",LEN(TRIM('Raw Data'!O11))=0),"",IF(AND(LEN('Raw Data'!O11) <= 255,LEN('Raw Data'!O11)> 0),"",_xlfn.REGEXEXTRACT(CELL("address",'Raw Data'!O11),"\$([A-Z]+)\$[0-9]+"))),_xlfn.REGEXEXTRACT(CELL("address",'Raw Data'!O11),"\$([A-Z]+)\$[0-9]+"))} | P11: {=IFERROR(IF(OR('Raw Data'!P11="",LEN(TRIM('Raw Data'!P11))=0),"",IF(AND(LEN('Raw Data'!P11) <= 10,LEN('Raw Data'!P11)> 0),"",_xlfn.REGEXEXTRACT(CELL("address",'Raw Data'!P11),"\$([A-Z]+)\$[0-9]+"))),_xlfn.REGEXEXTRACT(CELL("address",'Raw Data'!P11),"\$([A-Z]+)\$[0-9]+"))} | Q11: {=IFERROR(IF(OR('Raw Data'!Q11="",LEN(TRIM('Raw Data'!Q11))=0),"",IF(AND(ISNUMBER('Raw Data'!Q11), IFERROR('Raw Data'!Q11 = ROUND('Raw Data'!Q11, 2),FALSE)),"",_xlfn.REGEXEXTRACT(CELL("address",Q11), "\$([A-Z]+)\$[0-9]+"))),_xlfn.REGEXEXTRACT(CELL("address",Q11), "\$([A-Z]+)\$[0-9]+"))} | R11: {=IFERROR(IF(OR('Raw Data'!R11="",LEN(TRIM('Raw Data'!R11))=0),"",IF(AND(ISNUMBER('Raw Data'!R11), IFERROR('Raw Data'!R11 = ROUND('Raw Data'!R11, 2),FALSE)),"",_xlfn.REGEXEXTRACT(CELL("address",R11), "\$([A-Z]+)\$[0-9]+"))),_xlfn.REGEXEXTRACT(CELL("address",R11), "\$([A-Z]+)\$[0-9]+"))} | S11: {=IFERROR(IF(OR('Raw Data'!S11="",LEN(TRIM('Raw Data'!S11))=0),"",IF(AND(ISNUMBER('Raw Data'!S11), IFERROR('Raw Data'!S11 = ROUND('Raw Data'!S11, 2),FALSE)),"",_xlfn.REGEXEXTRACT(CELL("address",S11), "\$([A-Z]+)\$[0-9]+"))),_xlfn.REGEXEXTRACT(CELL("address",S11), "\$([A-Z]+)\$[0-9]+"))} | T11: {=IFERROR(IF(OR('Raw Data'!T11="",LEN(TRIM('Raw Data'!T11))=0),"",IF(AND(ISNUMBER('Raw Data'!T11), IFERROR('Raw Data'!T11 = ROUND('Raw Data'!T11, 2),FALSE)),"",_xlfn.REGEXEXTRACT(CELL("address",T11), "\$([A-Z]+)\$[0-9]+"))),_xlfn.REGEXEXTRACT(CELL("address",T11), "\$([A-Z]+)\$[0-9]+"))} | U11: {=IFERROR(IF(OR('Raw Data'!U11="",LEN(TRIM('Raw Data'!U11))=0),"",IF(AND(ISNUMBER('Raw Data'!U11), IFERROR('Raw Data'!U11 = ROUND('Raw Data'!U11, 2),FALSE)),"",_xlfn.REGEXEXTRACT(CELL("address",U11), "\$([A-Z]+)\$[0-9]+"))),_xlfn.REGEXEXTRACT(CELL("address",U11), "\$([A-Z]+)\$[0-9]+"))} | V11: {=IFERROR(IF(OR('Raw Data'!V11="",LEN(TRIM('Raw Data'!V11))=0),"",IF(AND(ISNUMBER('Raw Data'!V11), IFERROR('Raw Data'!V11 = ROUND('Raw Data'!V11, 2),FALSE)),"",_xlfn.REGEXEXTRACT(CELL("address",V11), "\$([A-Z]+)\$[0-9]+"))),_xlfn.REGEXEXTRACT(CELL("address",V11), "\$([A-Z]+)\$[0-9]+"))} | W11: {=IFERROR(IF(OR('Raw Data'!W11="",LEN(TRIM('Raw Data'!W11))=0),"",IF(AND(ISNUMBER('Raw Data'!W11), IFERROR('Raw Data'!W11 = ROUND('Raw Data'!W11, 2),FALSE)),"",_xlfn.REGEXEXTRACT(CELL("address",W11), "\$([A-Z]+)\$[0-9]+"))),_xlfn.REGEXEXTRACT(CELL("address",W11), "\$([A-Z]+)\$[0-9]+"))} | X11: {=IFERROR(IF(OR('Raw Data'!X11="",LEN(TRIM('Raw Data'!X11))=0),"",IF(AND(ISNUMBER('Raw Data'!X11), IFERROR('Raw Data'!X11 = ROUND('Raw Data'!X11, 2),FALSE)),"",_xlfn.REGEXEXTRACT(CELL("address",X11), "\$([A-Z]+)\$[0-9]+"))),_xlfn.REGEXEXTRACT(CELL("address",X11), "\$([A-Z]+)\$[0-9]+"))} | Y11: {=IFERROR(IF(OR('Raw Data'!Y11="",LEN(TRIM('Raw Data'!Y11))=0),"",IF(AND(ISNUMBER('Raw Data'!Y11), IFERROR('Raw Data'!Y11 = ROUND('Raw Data'!Y11, 2),FALSE)),"",_xlfn.REGEXEXTRACT(CELL("address",Y11), "\$([A-Z]+)\$[0-9]+"))),_xlfn.REGEXEXTRACT(CELL("address",Y11), "\$([A-Z]+)\$[0-9]+"))}
B12: {=IFERROR(IF(OR('Raw Data'!B12="",LEN(TRIM('Raw Data'!B12))=0),"",IF(AND(LEN('Raw Data'!B12) <= 10,LEN('Raw Data'!B12)> 0),"",_xlfn.REGEXEXTRACT(CELL("address",'Raw Data'!B12),"\$([A-Z]+)\$[0-9]+"))),_xlfn.REGEXEXTRACT(CELL("address",'Raw Data'!B12),"\$([A-Z]+)\$[0-9]+"))} | C12: {=IFERROR(IF(OR('Raw Data'!C12="",LEN(TRIM('Raw Data'!C12))=0),"",IF(AND(LEN('Raw Data'!C12) <= 20,LEN('Raw Data'!C12)> 0),"",_xlfn.REGEXEXTRACT(CELL("address",'Raw Data'!C12),"\$([A-Z]+)\$[0-9]+"))),_xlfn.REGEXEXTRACT(CELL("address",'Raw Data'!C12),"\$([A-Z]+)\$[0-9]+"))} | D12: {=IFERROR(IF(OR('Raw Data'!D12="",LEN(TRIM('Raw Data'!D12))=0),"",IF(AND(LEN('Raw Data'!D12) <= 20,LEN('Raw Data'!D12)> 0),"",_xlfn.REGEXEXTRACT(CELL("address",'Raw Data'!D12),"\$([A-Z]+)\$[0-9]+"))),_xlfn.REGEXEXTRACT(CELL("address",'Raw Data'!D12),"\$([A-Z]+)\$[0-9]+"))} | E12: {=IFERROR(IF(OR('Raw Data'!E12="",LEN(TRIM('Raw Data'!E12))=0),"",IF(AND(LEN('Raw Data'!E12) <= 20,LEN('Raw Data'!E12)> 0),"",_xlfn.REGEXEXTRACT(CELL("address",'Raw Data'!E12),"\$([A-Z]+)\$[0-9]+"))),_xlfn.REGEXEXTRACT(CELL("address",'Raw Data'!E12),"\$([A-Z]+)\$[0-9]+"))} | F12: {=IFERROR(IF(OR('Raw Data'!F12="",LEN(TRIM('Raw Data'!F12))=0),"",IF(AND(LEN('Raw Data'!F12) <= 20,LEN('Raw Data'!F12)> 0),"",_xlfn.REGEXEXTRACT(CELL("address",'Raw Data'!F12),"\$([A-Z]+)\$[0-9]+"))),_xlfn.REGEXEXTRACT(CELL("address",'Raw Data'!F12),"\$([A-Z]+)\$[0-9]+"))} | G12: {=IFERROR(IF(OR('Raw Data'!G12="",LEN(TRIM('Raw Data'!G12))=0),"",IF(AND(LEN('Raw Data'!G12) <= 10,LEN('Raw Data'!G12)> 0),"",_xlfn.REGEXEXTRACT(CELL("address",'Raw Data'!G12),"\$([A-Z]+)\$[0-9]+"))),_xlfn.REGEXEXTRACT(CELL("address",'Raw Data'!G12),"\$([A-Z]+)\$[0-9]+"))} | H12: {=IFERROR(IF(OR('Raw Data'!H12="",LEN(TRIM('Raw Data'!H12))=0),"",IF(AND(LEN('Raw Data'!H12) <= 255,LEN('Raw Data'!H12)> 0),"",_xlfn.REGEXEXTRACT(CELL("address",'Raw Data'!H12),"\$([A-Z]+)\$[0-9]+"))),_xlfn.REGEXEXTRACT(CELL("address",'Raw Data'!H12),"\$([A-Z]+)\$[0-9]+"))} | I12: {=IFERROR(IF(OR('Raw Data'!I12="",LEN(TRIM('Raw Data'!I12))=0),"",IF(AND(LEN('Raw Data'!I12) <= 255,LEN('Raw Data'!I12)> 0),"",_xlfn.REGEXEXTRACT(CELL("address",'Raw Data'!I12),"\$([A-Z]+)\$[0-9]+"))),_xlfn.REGEXEXTRACT(CELL("address",'Raw Data'!I12),"\$([A-Z]+)\$[0-9]+"))} | J12: {=IFERROR(IF(OR('Raw Data'!J12="",LEN(TRIM('Raw Data'!J12))=0),"",IF(AND(LEN('Raw Data'!J12) <= 255,LEN('Raw Data'!J12)> 0),"",_xlfn.REGEXEXTRACT(CELL("address",'Raw Data'!J12),"\$([A-Z]+)\$[0-9]+"))),_xlfn.REGEXEXTRACT(CELL("address",'Raw Data'!J12),"\$([A-Z]+)\$[0-9]+"))} | K12: {=IFERROR(IF(OR('Raw Data'!K12="",LEN(TRIM('Raw Data'!K12))=0),"",IF(AND(LEN('Raw Data'!K12) <= 255,LEN('Raw Data'!K12)> 0),"",_xlfn.REGEXEXTRACT(CELL("address",'Raw Data'!K12),"\$([A-Z]+)\$[0-9]+"))),_xlfn.REGEXEXTRACT(CELL("address",'Raw Data'!K12),"\$([A-Z]+)\$[0-9]+"))} | L12: {=IFERROR(IF(OR('Raw Data'!L12="",LEN(TRIM('Raw Data'!L12))=0),"",IF(AND(LEN('Raw Data'!L12) <= 255,LEN('Raw Data'!L12)> 0),"",_xlfn.REGEXEXTRACT(CELL("address",'Raw Data'!L12),"\$([A-Z]+)\$[0-9]+"))),_xlfn.REGEXEXTRACT(CELL("address",'Raw Data'!L12),"\$([A-Z]+)\$[0-9]+"))} | M12: {=IFERROR(IF(OR('Raw Data'!M12="",LEN(TRIM('Raw Data'!M12))=0),"",IF(AND(LEN('Raw Data'!M12) <= 255,LEN('Raw Data'!M12)> 0),"",_xlfn.REGEXEXTRACT(CELL("address",'Raw Data'!M12),"\$([A-Z]+)\$[0-9]+"))),_xlfn.REGEXEXTRACT(CELL("address",'Raw Data'!M12),"\$([A-Z]+)\$[0-9]+"))} | N12: {=IFERROR(IF(OR('Raw Data'!N12="",LEN(TRIM('Raw Data'!N12))=0),"",IF(AND(LEN('Raw Data'!N12) <= 255,LEN('Raw Data'!N12)> 0),"",_xlfn.REGEXEXTRACT(CELL("address",'Raw Data'!N12),"\$([A-Z]+)\$[0-9]+"))),_xlfn.REGEXEXTRACT(CELL("address",'Raw Data'!N12),"\$([A-Z]+)\$[0-9]+"))} | O12: {=IFERROR(IF(OR('Raw Data'!O12="",LEN(TRIM('Raw Data'!O12))=0),"",IF(AND(LEN('Raw Data'!O12) <= 255,LEN('Raw Data'!O12)> 0),"",_xlfn.REGEXEXTRACT(CELL("address",'Raw Data'!O12),"\$([A-Z]+)\$[0-9]+"))),_xlfn.REGEXEXTRACT(CELL("address",'Raw Data'!O12),"\$([A-Z]+)\$[0-9]+"))} | P12: {=IFERROR(IF(OR('Raw Data'!P12="",LEN(TRIM('Raw Data'!P12))=0),"",IF(AND(LEN('Raw Data'!P12) <= 10,LEN('Raw Data'!P12)> 0),"",_xlfn.REGEXEXTRACT(CELL("address",'Raw Data'!P12),"\$([A-Z]+)\$[0-9]+"))),_xlfn.REGEXEXTRACT(CELL("address",'Raw Data'!P12),"\$([A-Z]+)\$[0-9]+"))} | Q12: {=IFERROR(IF(OR('Raw Data'!Q12="",LEN(TRIM('Raw Data'!Q12))=0),"",IF(AND(ISNUMBER('Raw Data'!Q12), IFERROR('Raw Data'!Q12 = ROUND('Raw Data'!Q12, 2),FALSE)),"",_xlfn.REGEXEXTRACT(CELL("address",Q12), "\$([A-Z]+)\$[0-9]+"))),_xlfn.REGEXEXTRACT(CELL("address",Q12), "\$([A-Z]+)\$[0-9]+"))} | R12: {=IFERROR(IF(OR('Raw Data'!R12="",LEN(TRIM('Raw Data'!R12))=0),"",IF(AND(ISNUMBER('Raw Data'!R12), IFERROR('Raw Data'!R12 = ROUND('Raw Data'!R12, 2),FALSE)),"",_xlfn.REGEXEXTRACT(CELL("address",R12), "\$([A-Z]+)\$[0-9]+"))),_xlfn.REGEXEXTRACT(CELL("address",R12), "\$([A-Z]+)\$[0-9]+"))} | S12: {=IFERROR(IF(OR('Raw Data'!S12="",LEN(TRIM('Raw Data'!S12))=0),"",IF(AND(ISNUMBER('Raw Data'!S12), IFERROR('Raw Data'!S12 = ROUND('Raw Data'!S12, 2),FALSE)),"",_xlfn.REGEXEXTRACT(CELL("address",S12), "\$([A-Z]+)\$[0-9]+"))),_xlfn.REGEXEXTRACT(CELL("address",S12), "\$([A-Z]+)\$[0-9]+"))} | T12: {=IFERROR(IF(OR('Raw Data'!T12="",LEN(TRIM('Raw Data'!T12))=0),"",IF(AND(ISNUMBER('Raw Data'!T12), IFERROR('Raw Data'!T12 = ROUND('Raw Data'!T12, 2),FALSE)),"",_xlfn.REGEXEXTRACT(CELL("address",T12), "\$([A-Z]+)\$[0-9]+"))),_xlfn.REGEXEXTRACT(CELL("address",T12), "\$([A-Z]+)\$[0-9]+"))} | U12: {=IFERROR(IF(OR('Raw Data'!U12="",LEN(TRIM('Raw Data'!U12))=0),"",IF(AND(ISNUMBER('Raw Data'!U12), IFERROR('Raw Data'!U12 = ROUND('Raw Data'!U12, 2),FALSE)),"",_xlfn.REGEXEXTRACT(CELL("address",U12), "\$([A-Z]+)\$[0-9]+"))),_xlfn.REGEXEXTRACT(CELL("address",U12), "\$([A-Z]+)\$[0-9]+"))} | V12: {=IFERROR(IF(OR('Raw Data'!V12="",LEN(TRIM('Raw Data'!V12))=0),"",IF(AND(ISNUMBER('Raw Data'!V12), IFERROR('Raw Data'!V12 = ROUND('Raw Data'!V12, 2),FALSE)),"",_xlfn.REGEXEXTRACT(CELL("address",V12), "\$([A-Z]+)\$[0-9]+"))),_xlfn.REGEXEXTRACT(CELL("address",V12), "\$([A-Z]+)\$[0-9]+"))} | W12: {=IFERROR(IF(OR('Raw Data'!W12="",LEN(TRIM('Raw Data'!W12))=0),"",IF(AND(ISNUMBER('Raw Data'!W12), IFERROR('Raw Data'!W12 = ROUND('Raw Data'!W12, 2),FALSE)),"",_xlfn.REGEXEXTRACT(CELL("address",W12), "\$([A-Z]+)\$[0-9]+"))),_xlfn.REGEXEXTRACT(CELL("address",W12), "\$([A-Z]+)\$[0-9]+"))} | X12: {=IFERROR(IF(OR('Raw Data'!X12="",LEN(TRIM('Raw Data'!X12))=0),"",IF(AND(ISNUMBER('Raw Data'!X12), IFERROR('Raw Data'!X12 = ROUND('Raw Data'!X12, 2),FALSE)),"",_xlfn.REGEXEXTRACT(CELL("address",X12), "\$([A-Z]+)\$[0-9]+"))),_xlfn.REGEXEXTRACT(CELL("address",X12), "\$([A-Z]+)\$[0-9]+"))} | Y12: {=IFERROR(IF(OR('Raw Data'!Y12="",LEN(TRIM('Raw Data'!Y12))=0),"",IF(AND(ISNUMBER('Raw Data'!Y12), IFERROR('Raw Data'!Y12 = ROUND('Raw Data'!Y12, 2),FALSE)),"",_xlfn.REGEXEXTRACT(CELL("address",Y12), "\$([A-Z]+)\$[0-9]+"))),_xlfn.REGEXEXTRACT(CELL("address",Y12), "\$([A-Z]+)\$[0-9]+"))}
B13: {=IFERROR(IF(OR('Raw Data'!B13="",LEN(TRIM('Raw Data'!B13))=0),"",IF(AND(LEN('Raw Data'!B13) <= 10,LEN('Raw Data'!B13)> 0),"",_xlfn.REGEXEXTRACT(CELL("address",'Raw Data'!B13),"\$([A-Z]+)\$[0-9]+"))),_xlfn.REGEXEXTRACT(CELL("address",'Raw Data'!B13),"\$([A-Z]+)\$[0-9]+"))} | C13: {=IFERROR(IF(OR('Raw Data'!C13="",LEN(TRIM('Raw Data'!C13))=0),"",IF(AND(LEN('Raw Data'!C13) <= 20,LEN('Raw Data'!C13)> 0),"",_xlfn.REGEXEXTRACT(CELL("address",'Raw Data'!C13),"\$([A-Z]+)\$[0-9]+"))),_xlfn.REGEXEXTRACT(CELL("address",'Raw Data'!C13),"\$([A-Z]+)\$[0-9]+"))} | D13: {=IFERROR(IF(OR('Raw Data'!D13="",LEN(TRIM('Raw Data'!D13))=0),"",IF(AND(LEN('Raw Data'!D13) <= 20,LEN('Raw Data'!D13)> 0),"",_xlfn.REGEXEXTRACT(CELL("address",'Raw Data'!D13),"\$([A-Z]+)\$[0-9]+"))),_xlfn.REGEXEXTRACT(CELL("address",'Raw Data'!D13),"\$([A-Z]+)\$[0-9]+"))} | E13: {=IFERROR(IF(OR('Raw Data'!E13="",LEN(TRIM('Raw Data'!E13))=0),"",IF(AND(LEN('Raw Data'!E13) <= 20,LEN('Raw Data'!E13)> 0),"",_xlfn.REGEXEXTRACT(CELL("address",'Raw Data'!E13),"\$([A-Z]+)\$[0-9]+"))),_xlfn.REGEXEXTRACT(CELL("address",'Raw Data'!E13),"\$([A-Z]+)\$[0-9]+"))} | F13: {=IFERROR(IF(OR('Raw Data'!F13="",LEN(TRIM('Raw Data'!F13))=0),"",IF(AND(LEN('Raw Data'!F13) <= 20,LEN('Raw Data'!F13)> 0),"",_xlfn.REGEXEXTRACT(CELL("address",'Raw Data'!F13),"\$([A-Z]+)\$[0-9]+"))),_xlfn.REGEXEXTRACT(CELL("address",'Raw Data'!F13),"\$([A-Z]+)\$[0-9]+"))} | G13: {=IFERROR(IF(OR('Raw Data'!G13="",LEN(TRIM('Raw Data'!G13))=0),"",IF(AND(LEN('Raw Data'!G13) <= 10,LEN('Raw Data'!G13)> 0),"",_xlfn.REGEXEXTRACT(CELL("address",'Raw Data'!G13),"\$([A-Z]+)\$[0-9]+"))),_xlfn.REGEXEXTRACT(CELL("address",'Raw Data'!G13),"\$([A-Z]+)\$[0-9]+"))} | H13: {=IFERROR(IF(OR('Raw Data'!H13="",LEN(TRIM('Raw Data'!H13))=0),"",IF(AND(LEN('Raw Data'!H13) <= 255,LEN('Raw Data'!H13)> 0),"",_xlfn.REGEXEXTRACT(CELL("address",'Raw Data'!H13),"\$([A-Z]+)\$[0-9]+"))),_xlfn.REGEXEXTRACT(CELL("address",'Raw Data'!H13),"\$([A-Z]+)\$[0-9]+"))} | I13: {=IFERROR(IF(OR('Raw Data'!I13="",LEN(TRIM('Raw Data'!I13))=0),"",IF(AND(LEN('Raw Data'!I13) <= 255,LEN('Raw Data'!I13)> 0),"",_xlfn.REGEXEXTRACT(CELL("address",'Raw Data'!I13),"\$([A-Z]+)\$[0-9]+"))),_xlfn.REGEXEXTRACT(CELL("address",'Raw Data'!I13),"\$([A-Z]+)\$[0-9]+"))} | J13: {=IFERROR(IF(OR('Raw Data'!J13="",LEN(TRIM('Raw Data'!J13))=0),"",IF(AND(LEN('Raw Data'!J13) <= 255,LEN('Raw Data'!J13)> 0),"",_xlfn.REGEXEXTRACT(CELL("address",'Raw Data'!J13),"\$([A-Z]+)\$[0-9]+"))),_xlfn.REGEXEXTRACT(CELL("address",'Raw Data'!J13),"\$([A-Z]+)\$[0-9]+"))} | K13: {=IFERROR(IF(OR('Raw Data'!K13="",LEN(TRIM('Raw Data'!K13))=0),"",IF(AND(LEN('Raw Data'!K13) <= 255,LEN('Raw Data'!K13)> 0),"",_xlfn.REGEXEXTRACT(CELL("address",'Raw Data'!K13),"\$([A-Z]+)\$[0-9]+"))),_xlfn.REGEXEXTRACT(CELL("address",'Raw Data'!K13),"\$([A-Z]+)\$[0-9]+"))} | L13: {=IFERROR(IF(OR('Raw Data'!L13="",LEN(TRIM('Raw Data'!L13))=0),"",IF(AND(LEN('Raw Data'!L13) <= 255,LEN('Raw Data'!L13)> 0),"",_xlfn.REGEXEXTRACT(CELL("address",'Raw Data'!L13),"\$([A-Z]+)\$[0-9]+"))),_xlfn.REGEXEXTRACT(CELL("address",'Raw Data'!L13),"\$([A-Z]+)\$[0-9]+"))} | M13: {=IFERROR(IF(OR('Raw Data'!M13="",LEN(TRIM('Raw Data'!M13))=0),"",IF(AND(LEN('Raw Data'!M13) <= 255,LEN('Raw Data'!M13)> 0),"",_xlfn.REGEXEXTRACT(CELL("address",'Raw Data'!M13),"\$([A-Z]+)\$[0-9]+"))),_xlfn.REGEXEXTRACT(CELL("address",'Raw Data'!M13),"\$([A-Z]+)\$[0-9]+"))} | N13: {=IFERROR(IF(OR('Raw Data'!N13="",LEN(TRIM('Raw Data'!N13))=0),"",IF(AND(LEN('Raw Data'!N13) <= 255,LEN('Raw Data'!N13)> 0),"",_xlfn.REGEXEXTRACT(CELL("address",'Raw Data'!N13),"\$([A-Z]+)\$[0-9]+"))),_xlfn.REGEXEXTRACT(CELL("address",'Raw Data'!N13),"\$([A-Z]+)\$[0-9]+"))} | O13: {=IFERROR(IF(OR('Raw Data'!O13="",LEN(TRIM('Raw Data'!O13))=0),"",IF(AND(LEN('Raw Data'!O13) <= 255,LEN('Raw Data'!O13)> 0),"",_xlfn.REGEXEXTRACT(CELL("address",'Raw Data'!O13),"\$([A-Z]+)\$[0-9]+"))),_xlfn.REGEXEXTRACT(CELL("address",'Raw Data'!O13),"\$([A-Z]+)\$[0-9]+"))} | P13: {=IFERROR(IF(OR('Raw Data'!P13="",LEN(TRIM('Raw Data'!P13))=0),"",IF(AND(LEN('Raw Data'!P13) <= 10,LEN('Raw Data'!P13)> 0),"",_xlfn.REGEXEXTRACT(CELL("address",'Raw Data'!P13),"\$([A-Z]+)\$[0-9]+"))),_xlfn.REGEXEXTRACT(CELL("address",'Raw Data'!P13),"\$([A-Z]+)\$[0-9]+"))} | Q13: {=IFERROR(IF(OR('Raw Data'!Q13="",LEN(TRIM('Raw Data'!Q13))=0),"",IF(AND(ISNUMBER('Raw Data'!Q13), IFERROR('Raw Data'!Q13 = ROUND('Raw Data'!Q13, 2),FALSE)),"",_xlfn.REGEXEXTRACT(CELL("address",Q13), "\$([A-Z]+)\$[0-9]+"))),_xlfn.REGEXEXTRACT(CELL("address",Q13), "\$([A-Z]+)\$[0-9]+"))} | R13: {=IFERROR(IF(OR('Raw Data'!R13="",LEN(TRIM('Raw Data'!R13))=0),"",IF(AND(ISNUMBER('Raw Data'!R13), IFERROR('Raw Data'!R13 = ROUND('Raw Data'!R13, 2),FALSE)),"",_xlfn.REGEXEXTRACT(CELL("address",R13), "\$([A-Z]+)\$[0-9]+"))),_xlfn.REGEXEXTRACT(CELL("address",R13), "\$([A-Z]+)\$[0-9]+"))} | S13: {=IFERROR(IF(OR('Raw Data'!S13="",LEN(TRIM('Raw Data'!S13))=0),"",IF(AND(ISNUMBER('Raw Data'!S13), IFERROR('Raw Data'!S13 = ROUND('Raw Data'!S13, 2),FALSE)),"",_xlfn.REGEXEXTRACT(CELL("address",S13), "\$([A-Z]+)\$[0-9]+"))),_xlfn.REGEXEXTRACT(CELL("address",S13), "\$([A-Z]+)\$[0-9]+"))} | T13: {=IFERROR(IF(OR('Raw Data'!T13="",LEN(TRIM('Raw Data'!T13))=0),"",IF(AND(ISNUMBER('Raw Data'!T13), IFERROR('Raw Data'!T13 = ROUND('Raw Data'!T13, 2),FALSE)),"",_xlfn.REGEXEXTRACT(CELL("address",T13), "\$([A-Z]+)\$[0-9]+"))),_xlfn.REGEXEXTRACT(CELL("address",T13), "\$([A-Z]+)\$[0-9]+"))} | U13: {=IFERROR(IF(OR('Raw Data'!U13="",LEN(TRIM('Raw Data'!U13))=0),"",IF(AND(ISNUMBER('Raw Data'!U13), IFERROR('Raw Data'!U13 = ROUND('Raw Data'!U13, 2),FALSE)),"",_xlfn.REGEXEXTRACT(CELL("address",U13), "\$([A-Z]+)\$[0-9]+"))),_xlfn.REGEXEXTRACT(CELL("address",U13), "\$([A-Z]+)\$[0-9]+"))} | V13: {=IFERROR(IF(OR('Raw Data'!V13="",LEN(TRIM('Raw Data'!V13))=0),"",IF(AND(ISNUMBER('Raw Data'!V13), IFERROR('Raw Data'!V13 = ROUND('Raw Data'!V13, 2),FALSE)),"",_xlfn.REGEXEXTRACT(CELL("address",V13), "\$([A-Z]+)\$[0-9]+"))),_xlfn.REGEXEXTRACT(CELL("address",V13), "\$([A-Z]+)\$[0-9]+"))} | W13: {=IFERROR(IF(OR('Raw Data'!W13="",LEN(TRIM('Raw Data'!W13))=0),"",IF(AND(ISNUMBER('Raw Data'!W13), IFERROR('Raw Data'!W13 = ROUND('Raw Data'!W13, 2),FALSE)),"",_xlfn.REGEXEXTRACT(CELL("address",W13), "\$([A-Z]+)\$[0-9]+"))),_xlfn.REGEXEXTRACT(CELL("address",W13), "\$([A-Z]+)\$[0-9]+"))} | X13: {=IFERROR(IF(OR('Raw Data'!X13="",LEN(TRIM('Raw Data'!X13))=0),"",IF(AND(ISNUMBER('Raw Data'!X13), IFERROR('Raw Data'!X13 = ROUND('Raw Data'!X13, 2),FALSE)),"",_xlfn.REGEXEXTRACT(CELL("address",X13), "\$([A-Z]+)\$[0-9]+"))),_xlfn.REGEXEXTRACT(CELL("address",X13), "\$([A-Z]+)\$[0-9]+"))} | Y13: {=IFERROR(IF(OR('Raw Data'!Y13="",LEN(TRIM('Raw Data'!Y13))=0),"",IF(AND(ISNUMBER('Raw Data'!Y13), IFERROR('Raw Data'!Y13 = ROUND('Raw Data'!Y13, 2),FALSE)),"",_xlfn.REGEXEXTRACT(CELL("address",Y13), "\$([A-Z]+)\$[0-9]+"))),_xlfn.REGEXEXTRACT(CELL("address",Y13), "\$([A-Z]+)\$[0-9]+"))}
