Workbook

Sheet Raw Data
B9: C1 | C9: C2 | D9: C3 | E9: C4 | F9: C5 | G9: C6 | H9: C7 | I9: C8 | J9: C9 | K9: C10 | L9: C11 | M9: C12 | N9: C13 | O9: C14 | P9: C15 | Q9: C16 | R9: C17 | S9: C18 | T9: C19 | U9: C20 | V9: C21
B10: Overall Project | C10: Month # 1 | D10: 0 | E10: 0 | F10: 0 | G10: 0 | H10: 0 | I10: 0 | J10: 0 | K10: 0 | L10: 0 | M10: 0 | N10: 0 | O10: 0 | P10: 0 | Q10: 0 | R10: 0 | S10: 0 | T10: 0 | U10: 0 | V10: 0
B11: Overall Project | C11: Month # 2 | D11: 0 | E11: 0 | F11: 0 | G11: 0 | H11: 0 | I11: 0 | K11: 0 | L11: 0 | M11: 0 | N11: 0 | O11: 0 | P11: 0 | Q11: 0 | R11: 0 | S11: 0 | T11: 0 | U11: 0 | V11: 0
B12: Overall Project | C12: Month # 3 | D12: 0 | E12: 0 | F12: 0 | G12: 0 | H12: 0 | I12: 0 | K12: 0 | L12: 0 | M12: 0 | N12: 0 | O12: 0 | P12: 0 | Q12: 0 | R12: 0 | S12: 0 | T12: 0 | U12: 0 | V12: 0
B13: Overall Project | C13: Month # 4 | D13: 0 | E13: 0 | F13: 0 | G13: 0 | H13: 0 | I13: 0 | K13: 0 | L13: 0 | M13: 0 | N13: 0 | O13: 0 | P13: 0 | Q13: 0 | R13: 0 | S13: 0 | T13: 0 | U13: 0 | V13: 0
B14: Overall Project | C14: Month # 5 | D14: 0 | E14: 0 | F14: 0 | G14: 0 | H14: 0 | I14: 0 | K14: 0 | L14: 0 | M14: 0 | N14: 0 | O14: 0 | P14: 0 | Q14: 0 | R14: 0 | S14: 0 | T14: 0 | U14: 0 | V14: 0
B15: Overall Project | C15: Month # 6 | D15: 0 | E15: 0 | F15: 0 | G15: 0 | H15: 0 | I15: 0 | K15: 0 | L15: 0 | M15: 0 | N15: 0 | O15: 0 | P15: 0 | Q15: 0 | R15: 0 | S15: 0 | T15: 0 | U15: 0 | V15: 0
B16: Overall Project | C16: Month # 7 | D16: 0 | E16: 0 | F16: 0 | G16: 0 | H16: 0 | I16: 0 | K16: 0 | L16: 0 | M16: 0 | N16: 0 | O16: 0 | P16: 0 | Q16: 0 | R16: 0 | S16: 0 | T16: 0 | U16: 0 | V16: 0
B17: Overall Project | C17: Month # 8 | D17: 0 | E17: 0 | F17: 0 | G17: 0 | H17: 0 | I17: 0 | K17: 0 | L17: 0 | M17: 0 | N17: 0 | O17: 0 | P17: 0 | Q17: 0 | R17: 0 | S17: 0 | T17: 0 | U17: 0 | V17: 0
B18: Overall Project | C18: Month # 9 | D18: 0 | E18: 0 | F18: 0 | G18: 0 | H18: 0 | I18: 0 | K18: 0 | L18: 0 | M18: 0 | N18: 0 | O18: 0 | P18: 0 | Q18: 0 | R18: 0 | S18: 0 | T18: 0 | U18: 0 | V18: 0
B19: Overall Project | C19: Month # 10 | D19: 0 | E19: 0 | F19: 0 | G19: 0 | H19: 0 | I19: 0 | K19: 0 | L19: 0 | M19: 0 | N19: 0 | O19: 0 | P19: 0 | Q19: 0 | R19: 0 | S19: 0 | T19: 0 | U19: 0 | V19: 0
B20: Overall Project | C20: Month # 11 | D20: 0 | E20: 0 | F20: 0 | G20: 0 | H20: 0 | I20: 0 | K20: 0 | L20: 0 | M20: 0 | N20: 0 | O20: 0 | P20: 0 | Q20: 0 | R20: 0 | S20: 0 | T20: 0 | U20: 0 | V20: 0
B21: Overall Project | C21: Month # 12 | D21: 0 | E21: 0 | F21: 0 | G21: 0 | H21: 0 | I21: 0 | K21: 0 | L21: 0 | M21: 0 | N21: 0 | O21: 0 | P21: 0 | Q21: 0 | R21: 0 | S21: 0 | T21: 0 | U21: 0 | V21: 0
B22: Overall Project | C22: Month # 13 | D22: 0 | E22: 0 | F22: 0 | G22: 0 | H22: 0 | I22: 0 | K22: 0 | L22: 0 | M22: 0 | N22: 0 | O22: 0 | P22: 0 | Q22: 0 | R22: 0 | S22: 0 | T22: 0 | U22: 0 | V22: 0
... B26: Overall Project | C26: Month # 17 | D26: 0 | E26: 0 | F26: 0 | G26: 0 | H26: 0 | I26: 0 | K26: 0 | L26: 0 | M26: 0 | N26: 0 | O26: 0 | P26: 0 | Q26: 0 | R26: 0 | S26: 0 | T26: 0 | U26: 0 | V26: 0
B27: Overall Project | C27: Month # 18 | D27: 0 | E27: 0 | F27: 0 | G27: 0 | H27: 0 | I27: 0 | K27: 0 | L27: 0
B28: Overall Project | C28: Month # 19 | D28: 0 | E28: 0 | F28: 0 | G28: 0 | H28: 0 | I28: 0 | K28: 0 | L28: 0
B29: Overall Project | C29: Month # 20 | D29: 0 | E29: 0 | F29: 0 | G29: 0 | H29: 0 | I29: 0 | K29: 0 | L29: 0
B30: Overall Project | C30: Month # 21 | D30: 0 | E30: 0 | F30: 0 | G30: 0 | H30: 0 | I30: 0 | K30: 0 | L30: 0
B31: Overall Project | C31: Month # 22 | D31: 0 | E31: 0 | F31: 0 | G31: 0 | H31: 0 | I31: 0 | K31: 0 | L31: 0
B32: Overall Project | C32: Month # 23 | D32: 0 | E32: 0 | F32: 0 | G32: 0 | H32: 0 | I32: 0 | K32: 0 | L32: 0
B33: Overall Project | C33: Month # 24 | D33: 0 | E33: 0 | F33: 0 | G33: 0 | H33: 0 | I33: 0 | K33: 0 | L33: 0
B34: Engineering | C34: Month # 1 | D34: 0 | E34: 0 | F34: 0 | G34: 0 | H34: 0 | I34: 0 | J34: 0 | K34: 0 | L34: 0 | M34: 0 | N34: 0 | O34: 0 | P34: 0 | Q34: 0 | R34: 0 | S34: 0 | T34: 0 | U34: 0 | V34: 0
B35: Engineering | C35: Month # 2 | D35: 0 | E35: 0 | F35: 0 | G35: 0 | H35: 0 | I35: 0 | K35: 0 | L35: 0 | M35: 0 | N35: 0 | O35: 0 | P35: 0 | Q35: 0 | R35: 0 | S35: 0 | T35: 0 | U35: 0 | V35: 0
B36: Engineering | C36: Month # 3 | D36: 0 | E36: 0 | F36: 0 | G36: 0 | H36: 0 | I36: 0 | K36: 0 | L36: 0 | M36: 0 | N36: 0 | O36: 0 | P36: 0 | Q36: 0 | R36: 0 | S36: 0 | T36: 0 | U36: 0 | V36: 0
B37: Engineering | C37: Month # 4 | D37: 0 | E37: 0 | F37: 0 | G37: 0 | H37: 0 | I37: 0 | K37: 0 | L37: 0 | M37: 0 | N37: 0 | O37: 0 | P37: 0 | Q37: 0 | R37: 0 | S37: 0 | T37: 0 | U37: 0 | V37: 0
B38: Engineering | C38: Month # 5 | D38: 0 | E38: 0 | F38: 0 | G38: 0 | H38: 0 | I38: 0 | K38: 0 | L38: 0 | M38: 0 | N38: 0 | O38: 0 | P38: 0 | Q38: 0 | R38: 0 | S38: 0 | T38: 0 | U38: 0 | V38: 0
B39: Engineering | C39: Month # 6 | D39: 0 | E39: 0 | F39: 0 | G39: 0 | H39: 0 | I39: 0 | K39: 0 | L39: 0 | M39: 0 | N39: 0 | O39: 0 | P39: 0 | Q39: 0 | R39: 0 | S39: 0 | T39: 0 | U39: 0 | V39: 0
B40: Engineering | C40: Month # 7 | D40: 0 | E40: 0 | F40: 0 | G40: 0 | H40: 0 | I40: 0 | K40: 0 | L40: 0 | M40: 0 | N40: 0 | O40: 0 | P40: 0 | Q40: 0 | R40: 0 | S40: 0 | T40: 0 | U40: 0 | V40: 0
B41: Engineering | C41: Month # 8 | D41: 0 | E41: 0 | F41: 0 | G41: 0 | H41: 0 | I41: 0 | K41: 0 | L41: 0 | M41: 0 | N41: 0 | O41: 0 | P41: 0 | Q41: 0 | R41: 0 | S41: 0 | T41: 0 | U41: 0 | V41: 0
B42: Engineering | C42: Month # 9 | D42: 0 | E42: 0 | F42: 0 | G42: 0 | H42: 0 | I42: 0 | K42: 0 | L42: 0 | M42: 0 | N42: 0 | O42: 0 | P42: 0 | Q42: 0 | R42: 0 | S42: 0 | T42: 0 | U42: 0 | V42: 0
B43: Engineering | C43: Month # 10 | D43: 0 | E43: 0 | F43: 0 | G43: 0 | H43: 0 | I43: 0 | K43: 0 | L43: 0 | M43: 0 | N43: 0 | O43: 0 | P43: 0 | Q43: 0 | R43: 0 | S43: 0 | T43: 0 | U43: 0 | V43: 0
B44: Engineering | C44: Month # 11 | D44: 0 | E44: 0 | F44: 0 | G44: 0 | H44: 0 | I44: 0 | K44: 0 | L44: 0 | M44: 0 | N44: 0 | O44: 0 | P44: 0 | Q44: 0 | R44: 0 | S44: 0 | T44: 0 | U44: 0 | V44: 0
B45: Engineering | C45: Month # 12 | D45: 0 | E45: 0 | F45: 0 | G45: 0 | H45: 0 | I45: 0 | K45: 0 | L45: 0 | M45: 0 | N45: 0 | O45: 0 | P45: 0 | Q45: 0 | R45: 0 | S45: 0 | T45: 0 | U45: 0 | V45: 0
B46: Engineering | C46: Month # 13 | D46: 0 | E46: 0 | F46: 0 | G46: 0 | H46: 0 | I46: 0 | K46: 0 | L46: 0 | M46: 0 | N46: 0 | O46: 0 | P46: 0 | Q46: 0 | R46: 0 | S46: 0 | T46: 0 | U46: 0 | V46: 0
... B50: Engineering | C50: Month # 17 | D50: 0 | E50: 0 | F50: 0 | G50: 0 | H50: 0 | I50: 0 | K50: 0 | L50: 0 | M50: 0 | N50: 0 | O50: 0 | P50: 0 | Q50: 0 | R50: 0 | S50: 0 | T50: 0 | U50: 0 | V50: 0
B51: Engineering | C51: Month # 18 | D51: 0 | E51: 0 | F51: 0 | G51: 0 | H51: 0 | I51: 0 | K51: 0 | L51: 0
B52: Engineering | C52: Month # 19 | D52: 0 | E52: 0 | F52: 0 | G52: 0 | H52: 0 | I52: 0 | K52: 0 | L52: 0
B53: Engineering | C53: Month # 20 | D53: 0 | E53: 0 | F53: 0 | G53: 0 | H53: 0 | I53: 0 | K53: 0 | L53: 0
B54: Engineering | C54: Month # 21 | D54: 0 | E54: 0 | F54: 0 | G54: 0 | H54: 0 | I54: 0 | K54: 0 | L54: 0
...

Sheet Validate_Empty
B8: TRUE | C8: TRUE | D8: FALSE | E8: TRUE | F8: FALSE | G8: FALSE | H8: TRUE | I8: FALSE | J8: FALSE | K8: FALSE | L8: FALSE | M8: FALSE | N8: FALSE | O8: FALSE | P8: FALSE | Q8: FALSE | R8: FALSE | S8: FALSE | T8: FALSE | U8: FALSE | V8: FALSE
B9: C1 | C9: C2 | D9: C3 | E9: C4 | F9: C5 | G9: C6 | H9: C7 | I9: C8 | J9: C9 | K9: C10 | L9: C11 | M9: C12 | N9: C13 | O9: C14 | P9: C15 | Q9: C16 | R9: C17 | S9: C18 | T9: C19 | U9: C20 | V9: C21
B10: {=IFERROR(IF(OR('Raw Data'!B10="",LEN(TRIM('Raw Data'!B10))=0),_xlfn.REGEXEXTRACT(CELL("address",'Raw Data'!B10),"\$([A-Z]+)\$[0-9]+"),""),"")} | C10: {=IFERROR(IF(OR('Raw Data'!C10="",LEN(TRIM('Raw Data'!C10))=0),_xlfn.REGEXEXTRACT(CELL("address",'Raw Data'!C10),"\$([A-Z]+)\$[0-9]+"),""),"")} | E10: {=IFERROR(IF(OR('Raw Data'!E10="",LEN(TRIM('Raw Data'!E10))=0),_xlfn.REGEXEXTRACT(CELL("address",'Raw Data'!E10),"\$([A-Z]+)\$[0-9]+"),""),"")} | H10: {=IFERROR(IF(OR('Raw Data'!H10="",LEN(TRIM('Raw Data'!H10))=0),_xlfn.REGEXEXTRACT(CELL("address",'Raw Data'!H10),"\$([A-Z]+)\$[0-9]+"),""),"")}
B11: {=IFERROR(IF(OR('Raw Data'!B11="",LEN(TRIM('Raw Data'!B11))=0),_xlfn.REGEXEXTRACT(CELL("address",'Raw Data'!B11),"\$([A-Z]+)\$[0-9]+"),""),"")} | C11: {=IFERROR(IF(OR('Raw Data'!C11="",LEN(TRIM('Raw Data'!C11))=0),_xlfn.REGEXEXTRACT(CELL("address",'Raw Data'!C11),"\$([A-Z]+)\$[0-9]+"),""),"")} | E11: {=IFERROR(IF(OR('Raw Data'!E11="",LEN(TRIM('Raw Data'!E11))=0),_xlfn.REGEXEXTRACT(CELL("address",'Raw Data'!E11),"\$([A-Z]+)\$[0-9]+"),""),"")} | H11: {=IFERROR(IF(OR('Raw Data'!H11="",LEN(TRIM('Raw Data'!H11))=0),_xlfn.REGEXEXTRACT(CELL("address",'Raw Data'!H11),"\$([A-Z]+)\$[0-9]+"),""),"")}
B12: {=IFERROR(IF(OR('Raw Data'!B12="",LEN(TRIM('Raw Data'!B12))=0),_xlfn.REGEXEXTRACT(CELL("address",'Raw Data'!B12),"\$([A-Z]+)\$[0-9]+"),""),"")} | C12: {=IFERROR(IF(OR('Raw Data'!C12="",LEN(TRIM('Raw Data'!C12))=0),_xlfn.REGEXEXTRACT(CELL("address",'Raw Data'!C12),"\$([A-Z]+)\$[0-9]+"),""),"")} | E12: {=IFERROR(IF(OR('Raw Data'!E12="",LEN(TRIM('Raw Data'!E12))=0),_xlfn.REGEXEXTRACT(CELL("address",'Raw Data'!E12),"\$([A-Z]+)\$[0-9]+"),""),"")} | H12: {=IFERROR(IF(OR('Raw Data'!H12="",LEN(TRIM('Raw Data'!H12))=0),_xlfn.REGEXEXTRACT(CELL("address",'Raw Data'!H12),"\$([A-Z]+)\$[0-9]+"),""),"")}
B13: {=IFERROR(IF(OR('Raw Data'!B13="",LEN(TRIM('Raw Data'!B13))=0),_xlfn.REGEXEXTRACT(CELL("address",'Raw Data'!B13),"\$([A-Z]+)\$[0-9]+"),""),"")} | C13: {=IFERROR(IF(OR('Raw Data'!C13="",LEN(TRIM('Raw Data'!C13))=0),_xlfn.REGEXEXTRACT(CELL("address",'Raw Data'!C13),"\$([A-Z]+)\$[0-9]+"),""),"")} | E13: {=IFERROR(IF(OR('Raw Data'!E13="",LEN(TRIM('Raw Data'!E13))=0),_xlfn.REGEXEXTRACT(CELL("address",'Raw Data'!E13),"\$([A-Z]+)\$[0-9]+"),""),"")} | H13: {=IFERROR(IF(OR('Raw Data'!H13="",LEN(TRIM('Raw Data'!H13))=0),_xlfn.REGEXEXTRACT(CELL("address",'Raw Data'!H13),"\$([A-Z]+)\$[0-9]+"),""),"")}
B14: {=IFERROR(IF(OR('Raw Data'!B14="",LEN(TRIM('Raw Data'!B14))=0),_xlfn.REGEXEXTRACT(CELL("address",'Raw Data'!B14),"\$([A-Z]+)\$[0-9]+"),""),"")} | C14: {=IFERROR(IF(OR('Raw Data'!C14="",LEN(TRIM('Raw Data'!C14))=0),_xlfn.REGEXEXTRACT(CELL("address",'Raw Data'!C14),"\$([A-Z]+)\$[0-9]+"),""),"")} | E14: {=IFERROR(IF(OR('Raw Data'!E14="",LEN(TRIM('Raw Data'!E14))=0),_xlfn.REGEXEXTRACT(CELL("address",'Raw Data'!E14),"\$([A-Z]+)\$[0-9]+"),""),"")} | H14: {=IFERROR(IF(OR('Raw Data'!H14="",LEN(TRIM('Raw Data'!H14))=0),_xlfn.REGEXEXTRACT(CELL("address",'Raw Data'!H14),"\$([A-Z]+)\$[0-9]+"),""),"")}
B15: {=IFERROR(IF(OR('Raw Data'!B15="",LEN(TRIM('Raw Data'!B15))=0),_xlfn.REGEXEXTRACT(CELL("address",'Raw Data'!B15),"\$([A-Z]+)\$[0-9]+"),""),"")} | C15: {=IFERROR(IF(OR('Raw Data'!C15="",LEN(TRIM('Raw Data'!C15))=0),_xlfn.REGEXEXTRACT(CELL("address",'Raw Data'!C15),"\$([A-Z]+)\$[0-9]+"),""),"")} | E15: {=IFERROR(IF(OR('Raw Data'!E15="",LEN(TRIM('Raw Data'!E15))=0),_xlfn.REGEXEXTRACT(CELL("address",'Raw Data'!E15),"\$([A-Z]+)\$[0-9]+"),""),"")} | H15: {=IFERROR(IF(OR('Raw Data'!H15="",LEN(TRIM('Raw Data'!H15))=0),_xlfn.REGEXEXTRACT(CELL("address",'Raw Data'!H15),"\$([A-Z]+)\$[0-9]+"),""),"")}
B16: {=IFERROR(IF(OR('Raw Data'!B16="",LEN(TRIM('Raw Data'!B16))=0),_xlfn.REGEXEXTRACT(CELL("address",'Raw Data'!B16),"\$([A-Z]+)\$[0-9]+"),""),"")} | C16: {=IFERROR(IF(OR('Raw Data'!C16="",LEN(TRIM('Raw Data'!C16))=0),_xlfn.REGEXEXTRACT(CELL("address",'Raw Data'!C16),"\$([A-Z]+)\$[0-9]+"),""),"")} | E16: {=IFERROR(IF(OR('Raw Data'!E16="",LEN(TRIM('Raw Data'!E16))=0),_xlfn.REGEXEXTRACT(CELL("address",'Raw Data'!E16),"\$([A-Z]+)\$[0-9]+"),""),"")} | H16: {=IFERROR(IF(OR('Raw Data'!H16="",LEN(TRIM('Raw Data'!H16))=0),_xlfn.REGEXEXTRACT(CELL("address",'Raw Data'!H16),"\$([A-Z]+)\$[0-9]+"),""),"")}
B17: {=IFERROR(IF(OR('Raw Data'!B17="",LEN(TRIM('Raw Data'!B17))=0),_xlfn.REGEXEXTRACT(CELL("address",'Raw Data'!B17),"\$([A-Z]+)\$[0-9]+"),""),"")} | C17: {=IFERROR(IF(OR('Raw Data'!C17="",LEN(TRIM('Raw Data'!C17))=0),_xlfn.REGEXEXTRACT(CELL("address",'Raw Data'!C17),"\$([A-Z]+)\$[0-9]+"),""),"")} | E17: {=IFERROR(IF(OR('Raw Data'!E17="",LEN(TRIM('Raw Data'!E17))=0),_xlfn.REGEXEXTRACT(CELL("address",'Raw Data'!E17),"\$([A-Z]+)\$[0-9]+"),""),"")} | H17: {=IFERROR(IF(OR('Raw Data'!H17="",LEN(TRIM('Raw Data'!H17))=0),_xlfn.REGEXEXTRACT(CELL("address",'Raw Data'!H17),"\$([A-Z]+)\$[0-9]+"),""),"")}
B18: {=IFERROR(IF(OR('Raw Data'!B18="",LEN(TRIM('Raw Data'!B18))=0),_xlfn.REGEXEXTRACT(CELL("address",'Raw Data'!B18),"\$([A-Z]+)\$[0-9]+"),""),"")} | C18: {=IFERROR(IF(OR('Raw Data'!C18="",LEN(TRIM('Raw Data'!C18))=0),_xlfn.REGEXEXTRACT(CELL("address",'Raw Data'!C18),"\$([A-Z]+)\$[0-9]+"),""),"")} | E18: {=IFERROR(IF(OR('Raw Data'!E18="",LEN(TRIM('Raw Data'!E18))=0),_xlfn.REGEXEXTRACT(CELL("address",'Raw Data'!E18),"\$([A-Z]+)\$[0-9]+"),""),"")} | H18: {=IFERROR(IF(OR('Raw Data'!H18="",LEN(TRIM('Raw Data'!H18))=0),_xlfn.REGEXEXTRACT(CELL("address",'Raw Data'!H18),"\$([A-Z]+)\$[0-9]+"),""),"")}
B19: {=IFERROR(IF(OR('Raw Data'!B19="",LEN(TRIM('Raw Data'!B19))=0),_xlfn.REGEXEXTRACT(CELL("address",'Raw Data'!B19),"\$([A-Z]+)\$[0-9]+"),""),"")} | C19: {=IFERROR(IF(OR('Raw Data'!C19="",LEN(TRIM('Raw Data'!C19))=0),_xlfn.REGEXEXTRACT(CELL("address",'Raw Data'!C19),"\$([A-Z]+)\$[0-9]+"),""),"")} | E19: {=IFERROR(IF(OR('Raw Data'!E19="",LEN(TRIM('Raw Data'!E19))=0),_xlfn.REGEXEXTRACT(CELL("address",'Raw Data'!E19),"\$([A-Z]+)\$[0-9]+"),""),"")} | H19: {=IFERROR(IF(OR('Raw Data'!H19="",LEN(TRIM('Raw Data'!H19))=0),_xlfn.REGEXEXTRACT(CELL("address",'Raw Data'!H19),"\$([A-Z]+)\$[0-9]+"),""),"")}
B20: {=IFERROR(IF(OR('Raw Data'!B20="",LEN(TRIM('Raw Data'!B20))=0),_xlfn.REGEXEXTRACT(CELL("address",'Raw Data'!B20),"\$([A-Z]+)\$[0-9]+"),""),"")} | C20: {=IFERROR(IF(OR('Raw Data'!C20="",LEN(TRIM('Raw Data'!C20))=0),_xlfn.REGEXEXTRACT(CELL("address",'Raw Data'!C20),"\$([A-Z]+)\$[0-9]+"),""),"")} | E20: {=IFERROR(IF(OR('Raw Data'!E20="",LEN(TRIM('Raw Data'!E20))=0),_xlfn.REGEXEXTRACT(CELL("address",'Raw Data'!E20),"\$([A-Z]+)\$[0-9]+"),""),"")} | H20: {=IFERROR(IF(OR('Raw Data'!H20="",LEN(TRIM('Raw Data'!H20))=0),_xlfn.REGEXEXTRACT(CELL("address",'Raw Data'!H20),"\$([A-Z]+)\$[0-9]+"),""),"")}
B21: {=IFERROR(IF(OR('Raw Data'!B21="",LEN(TRIM('Raw Data'!B21))=0),_xlfn.REGEXEXTRACT(CELL("address",'Raw Data'!B21),"\$([A-Z]+)\$[0-9]+"),""),"")} | C21: {=IFERROR(IF(OR('Raw Data'!C21="",LEN(TRIM('Raw Data'!C21))=0),_xlfn.REGEXEXTRACT(CELL("address",'Raw Data'!C21),"\$([A-Z]+)\$[0-9]+"),""),"")} | E21: {=IFERROR(IF(OR('Raw Data'!E21="",LEN(TRIM('Raw Data'!E21))=0),_xlfn.REGEXEXTRACT(CELL("address",'Raw Data'!E21),"\$([A-Z]+)\$[0-9]+"),""),"")} | H21: {=IFERROR(IF(OR('Raw Data'!H21="",LEN(TRIM('Raw Data'!H21))=0),_xlfn.REGEXEXTRACT(CELL("address",'Raw Data'!H21),"\$([A-Z]+)\$[0-9]+"),""),"")}
... B249: {=IFERROR(IF(OR('Raw Data'!B249="",LEN(TRIM('Raw Data'!B249))=0),_xlfn.REGEXEXTRACT(CELL("address",'Raw Data'!B249),"\$([A-Z]+)\$[0-9]+"),""),"")} | C249: {=IFERROR(IF(OR('Raw Data'!C249="",LEN(TRIM('Raw Data'!C249))=0),_xlfn.REGEXEXTRACT(CELL("address",'Raw Data'!C249),"\$([A-Z]+)\$[0-9]+"),""),"")} | E249: {=IFERROR(IF(OR('Raw Data'!E249="",LEN(TRIM('Raw Data'!E249))=0),_xlfn.REGEXEXTRACT(CELL("address",'Raw Data'!E249),"\$([A-Z]+)\$[0-9]+"),""),"")} | H249: {=IFERROR(IF(OR('Raw Data'!H249="",LEN(TRIM('Raw Data'!H249))=0),_xlfn.REGEXEXTRACT(CELL("address",'Raw Data'!H249),"\$([A-Z]+)\$[0-9]+"),""),"")}

Sheet Validate_Value
B8: NVARCHAR(255) | C8: NVARCHAR(20) | D8: DATE | E8: DECIMAL(13,4) [Percentage] | F8: DECIMAL(13,4) [Percentage] | G8: DECIMAL(13,4) [Percentage] | H8: DECIMAL(13,4) [Percentage] | I8: DECIMAL(13,4) [Percentage] | J8: DECIMAL(13,4) [Percentage] | K8: DECIMAL(13,2) | L8: DECIMAL(13,2) | M8: DECIMAL(13,2) | N8: DECIMAL(13,2) | O8: DECIMAL(13,2) | P8: DECIMAL(13,2) | Q8: DECIMAL(13,2) | R8: DECIMAL(13,2) | S8: DECIMAL(13,2) | T8: DECIMAL(13,2) | U8: DECIMAL(13,2) | V8: DECIMAL(13,2)
B9: C1 | C9: C2 | D9: C3 | E9: C4 | F9: C5 | G9: C6 | H9: C7 | I9: C8 | J9: C9 | K9: C10 | L9: C11 | M9: C12 | N9: C13 | O9: C14 | P9: C15 | Q9: C16 | R9: C17 | S9: C18 | T9: C19 | U9: C20 | V9: C21
B10: {=IFERROR(IF(OR('Raw Data'!B10="",LEN(TRIM('Raw Data'!B10))=0),"",IF(AND(LEN('Raw Data'!B10) <= 255,LEN('Raw Data'!B10)> 0),"",_xlfn.REGEXEXTRACT(CELL("address",'Raw Data'!B10),"\$([A-Z]+)\$[0-9]+"))),_xlfn.REGEXEXTRACT(CELL("address",'Raw Data'!B10),"\$([A-Z]+)\$[0-9]+"))} | C10: {=IFERROR(IF(OR('Raw Data'!C10="",LEN(TRIM('Raw Data'!C10))=0),"",IF(AND(LEN('Raw Data'!C10) <= 20,LEN('Raw Data'!C10)> 0),"",_xlfn.REGEXEXTRACT(CELL("address",'Raw Data'!C10),"\$([A-Z]+)\$[0-9]+"))),_xlfn.REGEXEXTRACT(CELL("address",'Raw Data'!C10),"\$([A-Z]+)\$[0-9]+"))} | D10: {=IFERROR(IF(OR('Raw Data'!D10="",LEN(TRIM('Raw Data'!D10))=0),"",IF(AND(ISNUMBER('Raw Data'!D10),'Raw Data'!D10>=Configuration!$D$2),"",_xlfn.REGEXEXTRACT(CELL("address",'Raw Data'!D10),"\$([A-Z]+)\$[0-9]+"))),_xlfn.REGEXEXTRACT(CELL("address",D10), "\$([A-Z]+)\$[0-9]+"))} -> $D$10 | E10: {=IFERROR(IF(OR('Raw Data'!E10="",LEN(TRIM('Raw Data'!E10))=0),"",IF(AND(ISNUMBER('Raw Data'!E10), IFERROR('Raw Data'!E10 = ROUND('Raw Data'!E10, 4),FALSE)),"",_xlfn.REGEXEXTRACT(CELL("address",E10), "\$([A-Z]+)\$[0-9]+"))),_xlfn.REGEXEXTRACT(CELL("address",E10), "\$([A-Z]+)\$[0-9]+"))} | F10: {=IFERROR(IF(OR('Raw Data'!F10="",LEN(TRIM('Raw Data'!F10))=0),"",IF(AND(ISNUMBER('Raw Data'!F10), IFERROR('Raw Data'!F10 = ROUND('Raw Data'!F10, 4),FALSE)),"",_xlfn.REGEXEXTRACT(CELL("address",F10), "\$([A-Z]+)\$[0-9]+"))),_xlfn.REGEXEXTRACT(CELL("address",F10), "\$([A-Z]+)\$[0-9]+"))} | G10: {=IFERROR(IF(OR('Raw Data'!G10="",LEN(TRIM('Raw Data'!G10))=0),"",IF(AND(ISNUMBER('Raw Data'!G10), IFERROR('Raw Data'!G10 = ROUND('Raw Data'!G10, 4),FALSE)),"",_xlfn.REGEXEXTRACT(CELL("address",G10), "\$([A-Z]+)\$[0-9]+"))),_xlfn.REGEXEXTRACT(CELL("address",G10), "\$([A-Z]+)\$[0-9]+"))} | H10: {=IFERROR(IF(OR('Raw Data'!H10="",LEN(TRIM('Raw Data'!H10))=0),"",IF(AND(ISNUMBER('Raw Data'!H10), IFERROR('Raw Data'!H10 = ROUND('Raw Data'!H10, 4),FALSE)),"",_xlfn.REGEXEXTRACT(CELL("address",H10), "\$([A-Z]+)\$[0-9]+"))),_xlfn.REGEXEXTRACT(CELL("address",H10), "\$([A-Z]+)\$[0-9]+"))} | I10: {=IFERROR(IF(OR('Raw Data'!I10="",LEN(TRIM('Raw Data'!I10))=0),"",IF(AND(ISNUMBER('Raw Data'!I10), IFERROR('Raw Data'!I10 = ROUND('Raw Data'!I10, 4),FALSE)),"",_xlfn.REGEXEXTRACT(CELL("address",I10), "\$([A-Z]+)\$[0-9]+"))),_xlfn.REGEXEXTRACT(CELL("address",I10), "\$([A-Z]+)\$[0-9]+"))} | J10: {=IFERROR(IF(OR('Raw Data'!J10="",LEN(TRIM('Raw Data'!J10))=0),"",IF(AND(ISNUMBER('Raw Data'!J10), IFERROR('Raw Data'!J10 = ROUND('Raw Data'!J10, 4),FALSE)),"",_xlfn.REGEXEXTRACT(CELL("address",J10), "\$([A-Z]+)\$[0-9]+"))),_xlfn.REGEXEXTRACT(CELL("address",J10), "\$([A-Z]+)\$[0-9]+"))} | K10: {=IFERROR(IF(OR('Raw Data'!K10="",LEN(TRIM('Raw Data'!K10))=0),"",IF(AND(ISNUMBER('Raw Data'!K10), IFERROR('Raw Data'!K10 = ROUND('Raw Data'!K10, 2),FALSE)),"",_xlfn.REGEXEXTRACT(CELL("address",K10), "\$([A-Z]+)\$[0-9]+"))),_xlfn.REGEXEXTRACT(CELL("address",K10), "\$([A-Z]+)\$[0-9]+"))} | L10: {=IFERROR(IF(OR('Raw Data'!L10="",LEN(TRIM('Raw Data'!L10))=0),"",IF(AND(ISNUMBER('Raw Data'!L10), IFERROR('Raw Data'!L10 = ROUND('Raw Data'!L10, 2),FALSE)),"",_xlfn.REGEXEXTRACT(CELL("address",L10), "\$([A-Z]+)\$[0-9]+"))),_xlfn.REGEXEXTRACT(CELL("address",L10), "\$([A-Z]+)\$[0-9]+"))} | M10: {=IFERROR(IF(OR('Raw Data'!M10="",LEN(TRIM('Raw Data'!M10))=0),"",IF(AND(ISNUMBER('Raw Data'!M10), IFERROR('Raw Data'!M10 = ROUND('Raw Data'!M10, 2),FALSE)),"",_xlfn.REGEXEXTRACT(CELL("address",M10), "\$([A-Z]+)\$[0-9]+"))),_xlfn.REGEXEXTRACT(CELL("address",M10), "\$([A-Z]+)\$[0-9]+"))} | N10: {=IFERROR(IF(OR('Raw Data'!N10="",LEN(TRIM('Raw Data'!N10))=0),"",IF(AND(ISNUMBER('Raw Data'!N10), IFERROR('Raw Data'!N10 = ROUND('Raw Data'!N10, 2),FALSE)),"",_xlfn.REGEXEXTRACT(CELL("address",N10), "\$([A-Z]+)\$[0-9]+"))),_xlfn.REGEXEXTRACT(CELL("address",N10), "\$([A-Z]+)\$[0-9]+"))} | O10: {=IFERROR(IF(OR('Raw Data'!O10="",LEN(TRIM('Raw Data'!O10))=0),"",IF(AND(ISNUMBER('Raw Data'!O10), IFERROR('Raw Data'!O10 = ROUND('Raw Data'!O10, 2),FALSE)),"",_xlfn.REGEXEXTRACT(CELL("address",O10), "\$([A-Z]+)\$[0-9]+"))),_xlfn.REGEXEXTRACT(CELL("address",O10), "\$([A-Z]+)\$[0-9]+"))} | P10: {=IFERROR(IF(OR('Raw Data'!P10="",LEN(TRIM('Raw Data'!P10))=0),"",IF(AND(ISNUMBER('Raw Data'!P10), IFERROR('Raw Data'!P10 = ROUND('Raw Data'!P10, 2),FALSE)),"",_xlfn.REGEXEXTRACT(CELL("address",P10), "\$([A-Z]+)\$[0-9]+"))),_xlfn.REGEXEXTRACT(CELL("address",P10), "\$([A-Z]+)\$[0-9]+"))} | Q10: {=IFERROR(IF(OR('Raw Data'!Q10="",LEN(TRIM('Raw Data'!Q10))=0),"",IF(AND(ISNUMBER('Raw Data'!Q10), IFERROR('Raw Data'!Q10 = ROUND('Raw Data'!Q10, 2),FALSE)),"",_xlfn.REGEXEXTRACT(CELL("address",Q10), "\$([A-Z]+)\$[0-9]+"))),_xlfn.REGEXEXTRACT(CELL("address",Q10), "\$([A-Z]+)\$[0-9]+"))} | R10: {=IFERROR(IF(OR('Raw Data'!R10="",LEN(TRIM('Raw Data'!R10))=0),"",IF(AND(ISNUMBER('Raw Data'!R10), IFERROR('Raw Data'!R10 = ROUND('Raw Data'!R10, 2),FALSE)),"",_xlfn.REGEXEXTRACT(CELL("address",R10), "\$([A-Z]+)\$[0-9]+"))),_xlfn.REGEXEXTRACT(CELL("address",R10), "\$([A-Z]+)\$[0-9]+"))} | ... V10: {=IFERROR(IF(OR('Raw Data'!V10="",LEN(TRIM('Raw Data'!V10))=0),"",IF(AND(ISNUMBER('Raw Data'!V10), IFERROR('Raw Data'!V10 = ROUND('Raw Data'!V10, 2),FALSE)),"",_xlfn.REGEXEXTRACT(CELL("address",V10), "\$([A-Z]+)\$[0-9]+"))),_xlfn.REGEXEXTRACT(CELL("address",V10), "\$([A-Z]+)\$[0-9]+"))}
B11: {=IFERROR(IF(OR('Raw Data'!B11="",LEN(TRIM('Raw Data'!B11))=0),"",IF(AND(LEN('Raw Data'!B11) <= 255,LEN('Raw Data'!B11)> 0),"",_xlfn.REGEXEXTRACT(CELL("address",'Raw Data'!B11),"\$([A-Z]+)\$[0-9]+"))),_xlfn.REGEXEXTRACT(CELL("address",'Raw Data'!B11),"\$([A-Z]+)\$[0-9]+"))} | C11: {=IFERROR(IF(OR('Raw Data'!C11="",LEN(TRIM('Raw Data'!C11))=0),"",IF(AND(LEN('Raw Data'!C11) <= 20,LEN('Raw Data'!C11)> 0),"",_xlfn.REGEXEXTRACT(CELL("address",'Raw Data'!C11),"\$([A-Z]+)\$[0-9]+"))),_xlfn.REGEXEXTRACT(CELL("address",'Raw Data'!C11),"\$([A-Z]+)\$[0-9]+"))} | D11: {=IFERROR(IF(OR('Raw Data'!D11="",LEN(TRIM('Raw Data'!D11))=0),"",IF(AND(ISNUMBER('Raw Data'!D11),'Raw Data'!D11>=Configuration!$D$2),"",_xlfn.REGEXEXTRACT(CELL("address",'Raw Data'!D11),"\$([A-Z]+)\$[0-9]+"))),_xlfn.REGEXEXTRACT(CELL("address",D11), "\$([A-Z]+)\$[0-9]+"))} -> $D$11 | E11: {=IFERROR(IF(OR('Raw Data'!E11="",LEN(TRIM('Raw Data'!E11))=0),"",IF(AND(ISNUMBER('Raw Data'!E11), IFERROR('Raw Data'!E11 = ROUND('Raw Data'!E11, 4),FALSE)),"",_xlfn.REGEXEXTRACT(CELL("address",E11), "\$([A-Z]+)\$[0-9]+"))),_xlfn.REGEXEXTRACT(CELL("address",E11), "\$([A-Z]+)\$[0-9]+"))} | F11: {=IFERROR(IF(OR('Raw Data'!F11="",LEN(TRIM('Raw Data'!F11))=0),"",IF(AND(ISNUMBER('Raw Data'!F11), IFERROR('Raw Data'!F11 = ROUND('Raw Data'!F11, 4),FALSE)),"",_xlfn.REGEXEXTRACT(CELL("address",F11), "\$([A-Z]+)\$[0-9]+"))),_xlfn.REGEXEXTRACT(CELL("address",F11), "\$([A-Z]+)\$[0-9]+"))} | G11: {=IFERROR(IF(OR('Raw Data'!G11="",LEN(TRIM('Raw Data'!G11))=0),"",IF(AND(ISNUMBER('Raw Data'!G11), IFERROR('Raw Data'!G11 = ROUND('Raw Data'!G11, 4),FALSE)),"",_xlfn.REGEXEXTRACT(CELL("address",G11), "\$([A-Z]+)\$[0-9]+"))),_xlfn.REGEXEXTRACT(CELL("address",G11), "\$([A-Z]+)\$[0-9]+"))} | H11: {=IFERROR(IF(OR('Raw Data'!H11="",LEN(TRIM('Raw Data'!H11))=0),"",IF(AND(ISNUMBER('Raw Data'!H11), IFERROR('Raw Data'!H11 = ROUND('Raw Data'!H11, 4),FALSE)),"",_xlfn.REGEXEXTRACT(CELL("address",H11), "\$([A-Z]+)\$[0-9]+"))),_xlfn.REGEXEXTRACT(CELL("address",H11), "\$([A-Z]+)\$[0-9]+"))} | I11: {=IFERROR(IF(OR('Raw Data'!I11="",LEN(TRIM('Raw Data'!I11))=0),"",IF(AND(ISNUMBER('Raw Data'!I11), IFERROR('Raw Data'!I11 = ROUND('Raw Data'!I11, 4),FALSE)),"",_xlfn.REGEXEXTRACT(CELL("address",I11), "\$([A-Z]+)\$[0-9]+"))),_xlfn.REGEXEXTRACT(CELL("address",I11), "\$([A-Z]+)\$[0-9]+"))} | J11: {=IFERROR(IF(OR('Raw Data'!J11="",LEN(TRIM('Raw Data'!J11))=0),"",IF(AND(ISNUMBER('Raw Data'!J11), IFERROR('Raw Data'!J11 = ROUND('Raw Data'!J11, 4),FALSE)),"",_xlfn.REGEXEXTRACT(CELL("address",J11), "\$([A-Z]+)\$[0-9]+"))),_xlfn.REGEXEXTRACT(CELL("address",J11), "\$([A-Z]+)\$[0-9]+"))} | K11: {=IFERROR(IF(OR('Raw Data'!K11="",LEN(TRIM('Raw Data'!K11))=0),"",IF(AND(ISNUMBER('Raw Data'!K11), IFERROR('Raw Data'!K11 = ROUND('Raw Data'!K11, 2),FALSE)),"",_xlfn.REGEXEXTRACT(CELL("address",K11), "\$([A-Z]+)\$[0-9]+"))),_xlfn.REGEXEXTRACT(CELL("address",K11), "\$([A-Z]+)\$[0-9]+"))} | L11: {=IFERROR(IF(OR('Raw Data'!L11="",LEN(TRIM('Raw Data'!L11))=0),"",IF(AND(ISNUMBER('Raw Data'!L11), IFERROR('Raw Data'!L11 = ROUND('Raw Data'!L11, 2),FALSE)),"",_xlfn.REGEXEXTRACT(CELL("address",L11), "\$([A-Z]+)\$[0-9]+"))),_xlfn.REGEXEXTRACT(CELL("address",L11), "\$([A-Z]+)\$[0-9]+"))} | M11: {=IFERROR(IF(OR('Raw Data'!M11="",LEN(TRIM('Raw Data'!M11))=0),"",IF(AND(ISNUMBER('Raw Data'!M11), IFERROR('Raw Data'!M11 = ROUND('Raw Data'!M11, 2),FALSE)),"",_xlfn.REGEXEXTRACT(CELL("address",M11), "\$([A-Z]+)\$[0-9]+"))),_xlfn.REGEXEXTRACT(CELL("address",M11), "\$([A-Z]+)\$[0-9]+"))} | N11: {=IFERROR(IF(OR('Raw Data'!N11="",LEN(TRIM('Raw Data'!N11))=0),"",IF(AND(ISNUMBER('Raw Data'!N11), IFERROR('Raw Data'!N11 = ROUND('Raw Data'!N11, 2),FALSE)),"",_xlfn.REGEXEXTRACT(CELL("address",N11), "\$([A-Z]+)\$[0-9]+"))),_xlfn.REGEXEXTRACT(CELL("address",N11), "\$([A-Z]+)\$[0-9]+"))} | O11: {=IFERROR(IF(OR('Raw Data'!O11="",LEN(TRIM('Raw Data'!O11))=0),"",IF(AND(ISNUMBER('Raw Data'!O11), IFERROR('Raw Data'!O11 = ROUND('Raw Data'!O11, 2),FALSE)),"",_xlfn.REGEXEXTRACT(CELL("address",O11), "\$([A-Z]+)\$[0-9]+"))),_xlfn.REGEXEXTRACT(CELL("address",O11), "\$([A-Z]+)\$[0-9]+"))} | P11: {=IFERROR(IF(OR('Raw Data'!P11="",LEN(TRIM('Raw Data'!P11))=0),"",IF(AND(ISNUMBER('Raw Data'!P11), IFERROR('Raw Data'!P11 = ROUND('Raw Data'!P11, 2),FALSE)),"",_xlfn.REGEXEXTRACT(CELL("address",P11), "\$([A-Z]+)\$[0-9]+"))),_xlfn.REGEXEXTRACT(CELL("address",P11), "\$([A-Z]+)\$[0-9]+"))} | Q11: {=IFERROR(IF(OR('Raw Data'!Q11="",LEN(TRIM('Raw Data'!Q11))=0),"",IF(AND(ISNUMBER('Raw Data'!Q11), IFERROR('Raw Data'!Q11 = ROUND('Raw Data'!Q11, 2),FALSE)),"",_xlfn.REGEXEXTRACT(CELL("address",Q11), "\$([A-Z]+)\$[0-9]+"))),_xlfn.REGEXEXTRACT(CELL("address",Q11), "\$([A-Z]+)\$[0-9]+"))} | R11: {=IFERROR(IF(OR('Raw Data'!R11="",LEN(TRIM('Raw Data'!R11))=0),"",IF(AND(ISNUMBER('Raw Data'!R11), IFERROR('Raw Data'!R11 = ROUND('Raw Data'!R11, 2),FALSE)),"",_xlfn.REGEXEXTRACT(CELL("address",R11), "\$([A-Z]+)\$[0-9]+"))),_xlfn.REGEXEXTRACT(CELL("address",R11), "\$([A-Z]+)\$[0-9]+"))} | ... V11: {=IFERROR(IF(OR('Raw Data'!V11="",LEN(TRIM('Raw Data'!V11))=0),"",IF(AND(ISNUMBER('Raw Data'!V11), IFERROR('Raw Data'!V11 = ROUND('Raw Data'!V11, 2),FALSE)),"",_xlfn.REGEXEXTRACT(CELL("address",V11), "\$([A-Z]+)\$[0-9]+"))),_xlfn.REGEXEXTRACT(CELL("address",V11), "\$([A-Z]+)\$[0-9]+"))}
B12: {=IFERROR(IF(OR('Raw Data'!B12="",LEN(TRIM('Raw Data'!B12))=0),"",IF(AND(LEN('Raw Data'!B12) <= 255,LEN('Raw Data'!B12)> 0),"",_xlfn.REGEXEXTRACT(CELL("address",'Raw Data'!B12),"\$([A-Z]+)\$[0-9]+"))),_xlfn.REGEXEXTRACT(CELL("address",'Raw Data'!B12),"\$([A-Z]+)\$[0-9]+"))} | C12: {=IFERROR(IF(OR('Raw Data'!C12="",LEN(TRIM('Raw Data'!C12))=0),"",IF(AND(LEN('Raw Data'!C12) <= 20,LEN('Raw Data'!C12)> 0),"",_xlfn.REGEXEXTRACT(CELL("address",'Raw Data'!C12),"\$([A-Z]+)\$[0-9]+"))),_xlfn.REGEXEXTRACT(CELL("address",'Raw Data'!C12),"\$([A-Z]+)\$[0-9]+"))} | D12: {=IFERROR(IF(OR('Raw Data'!D12="",LEN(TRIM('Raw Data'!D12))=0),"",IF(AND(ISNUMBER('Raw Data'!D12),'Raw Data'!D12>=Configuration!$D$2),"",_xlfn.REGEXEXTRACT(CELL("address",'Raw Data'!D12),"\$([A-Z]+)\$[0-9]+"))),_xlfn.REGEXEXTRACT(CELL("address",D12), "\$([A-Z]+)\$[0-9]+"))} -> $D$12 | E12: {=IFERROR(IF(OR('Raw Data'!E12="",LEN(TRIM('Raw Data'!E12))=0),"",IF(AND(ISNUMBER('Raw Data'!E12), IFERROR('Raw Data'!E12 = ROUND('Raw Data'!E12, 4),FALSE)),"",_xlfn.REGEXEXTRACT(CELL("address",E12), "\$([A-Z]+)\$[0-9]+"))),_xlfn.REGEXEXTRACT(CELL("address",E12), "\$([A-Z]+)\$[0-9]+"))} | F12: {=IFERROR(IF(OR('Raw Data'!F12="",LEN(TRIM('Raw Data'!F12))=0),"",IF(AND(ISNUMBER('Raw Data'!F12), IFERROR('Raw Data'!F12 = ROUND('Raw Data'!F12, 4),FALSE)),"",_xlfn.REGEXEXTRACT(CELL("address",F12), "\$([A-Z]+)\$[0-9]+"))),_xlfn.REGEXEXTRACT(CELL("address",F12), "\$([A-Z]+)\$[0-9]+"))} | G12: {=IFERROR(IF(OR('Raw Data'!G12="",LEN(TRIM('Raw Data'!G12))=0),"",IF(AND(ISNUMBER('Raw Data'!G12), IFERROR('Raw Data'!G12 = ROUND('Raw Data'!G12, 4),FALSE)),"",_xlfn.REGEXEXTRACT(CELL("address",G12), "\$([A-Z]+)\$[0-9]+"))),_xlfn.REGEXEXTRACT(CELL("address",G12), "\$([A-Z]+)\$[0-9]+"))} | H12: {=IFERROR(IF(OR('Raw Data'!H12="",LEN(TRIM('Raw Data'!H12))=0),"",IF(AND(ISNUMBER('Raw Data'!H12), IFERROR('Raw Data'!H12 = ROUND('Raw Data'!H12, 4),FALSE)),"",_xlfn.REGEXEXTRACT(CELL("address",H12), "\$([A-Z]+)\$[0-9]+"))),_xlfn.REGEXEXTRACT(CELL("address",H12), "\$([A-Z]+)\$[0-9]+"))} | I12: {=IFERROR(IF(OR('Raw Data'!I12="",LEN(TRIM('Raw Data'!I12))=0),"",IF(AND(ISNUMBER('Raw Data'!I12), IFERROR('Raw Data'!I12 = ROUND('Raw Data'!I12, 4),FALSE)),"",_xlfn.REGEXEXTRACT(CELL("address",I12), "\$([A-Z]+)\$[0-9]+"))),_xlfn.REGEXEXTRACT(CELL("address",I12), "\$([A-Z]+)\$[0-9]+"))} | J12: {=IFERROR(IF(OR('Raw Data'!J12="",LEN(TRIM('Raw Data'!J12))=0),"",IF(AND(ISNUMBER('Raw Data'!J12), IFERROR('Raw Data'!J12 = ROUND('Raw Data'!J12, 4),FALSE)),"",_xlfn.REGEXEXTRACT(CELL("address",J12), "\$([A-Z]+)\$[0-9]+"))),_xlfn.REGEXEXTRACT(CELL("address",J12), "\$([A-Z]+)\$[0-9]+"))} | K12: {=IFERROR(IF(OR('Raw Data'!K12="",LEN(TRIM('Raw Data'!K12))=0),"",IF(AND(ISNUMBER('Raw Data'!K12), IFERROR('Raw Data'!K12 = ROUND('Raw Data'!K12, 2),FALSE)),"",_xlfn.REGEXEXTRACT(CELL("address",K12), "\$([A-Z]+)\$[0-9]+"))),_xlfn.REGEXEXTRACT(CELL("address",K12), "\$([A-Z]+)\$[0-9]+"))} | L12: {=IFERROR(IF(OR('Raw Data'!L12="",LEN(TRIM('Raw Data'!L12))=0),"",IF(AND(ISNUMBER('Raw Data'!L12), IFERROR('Raw Data'!L12 = ROUND('Raw Data'!L12, 2),FALSE)),"",_xlfn.REGEXEXTRACT(CELL("address",L12), "\$([A-Z]+)\$[0-9]+"))),_xlfn.REGEXEXTRACT(CELL("address",L12), "\$([A-Z]+)\$[0-9]+"))} | M12: {=IFERROR(IF(OR('Raw Data'!M12="",LEN(TRIM('Raw Data'!M12))=0),"",IF(AND(ISNUMBER('Raw Data'!M12), IFERROR('Raw Data'!M12 = ROUND('Raw Data'!M12, 2),FALSE)),"",_xlfn.REGEXEXTRACT(CELL("address",M12), "\$([A-Z]+)\$[0-9]+"))),_xlfn.REGEXEXTRACT(CELL("address",M12), "\$([A-Z]+)\$[0-9]+"))} | N12: {=IFERROR(IF(OR('Raw Data'!N12="",LEN(TRIM('Raw Data'!N12))=0),"",IF(AND(ISNUMBER('Raw Data'!N12), IFERROR('Raw Data'!N12 = ROUND('Raw Data'!N12, 2),FALSE)),"",_xlfn.REGEXEXTRACT(CELL("address",N12), "\$([A-Z]+)\$[0-9]+"))),_xlfn.REGEXEXTRACT(CELL("address",N12), "\$([A-Z]+)\$[0-9]+"))} | O12: {=IFERROR(IF(OR('Raw Data'!O12="",LEN(TRIM('Raw Data'!O12))=0),"",IF(AND(ISNUMBER('Raw Data'!O12), IFERROR('Raw Data'!O12 = ROUND('Raw Data'!O12, 2),FALSE)),"",_xlfn.REGEXEXTRACT(CELL("address",O12), "\$([A-Z]+)\$[0-9]+"))),_xlfn.REGEXEXTRACT(CELL("address",O12), "\$([A-Z]+)\$[0-9]+"))} | P12: {=IFERROR(IF(OR('Raw Data'!P12="",LEN(TRIM('Raw Data'!P12))=0),"",IF(AND(ISNUMBER('Raw Data'!P12), IFERROR('Raw Data'!P12 = ROUND('Raw Data'!P12, 2),FALSE)),"",_xlfn.REGEXEXTRACT(CELL("address",P12), "\$([A-Z]+)\$[0-9]+"))),_xlfn.REGEXEXTRACT(CELL("address",P12), "\$([A-Z]+)\$[0-9]+"))} | Q12: {=IFERROR(IF(OR('Raw Data'!Q12="",LEN(TRIM('Raw Data'!Q12))=0),"",IF(AND(ISNUMBER('Raw Data'!Q12), IFERROR('Raw Data'!Q12 = ROUND('Raw Data'!Q12, 2),FALSE)),"",_xlfn.REGEXEXTRACT(CELL("address",Q12), "\$([A-Z]+)\$[0-9]+"))),_xlfn.REGEXEXTRACT(CELL("address",Q12), "\$([A-Z]+)\$[0-9]+"))} | R12: {=IFERROR(IF(OR('Raw Data'!R12="",LEN(TRIM('Raw Data'!R12))=0),"",IF(AND(ISNUMBER('Raw Data'!R12), IFERROR('Raw Data'!R12 = ROUND('Raw Data'!R12, 2),FALSE)),"",_xlfn.REGEXEXTRACT(CELL("address",R12), "\$([A-Z]+)\$[0-9]+"))),_xlfn.REGEXEXTRACT(CELL("address",R12), "\$([A-Z]+)\$[0-9]+"))} | ... V12: {=IFERROR(IF(OR('Raw Data'!V12="",LEN(TRIM('Raw Data'!V12))=0),"",IF(AND(ISNUMBER('Raw Data'!V12), IFERROR('Raw Data'!V12 = ROUND('Raw Data'!V12, 2),FALSE)),"",_xlfn.REGEXEXTRACT(CELL("address",V12), "\$([A-Z]+)\$[0-9]+"))),_xlfn.REGEXEXTRACT(CELL("address",V12), "\$([A-Z]+)\$[0-9]+"))}
B13: {=IFERROR(IF(OR('Raw Data'!B13="",LEN(TRIM('Raw Data'!B13))=0),"",IF(AND(LEN('Raw Data'!B13) <= 255,LEN('Raw Data'!B13)> 0),"",_xlfn.REGEXEXTRACT(CELL("address",'Raw Data'!B13),"\$([A-Z]+)\$[0-9]+"))),_xlfn.REGEXEXTRACT(CELL("address",'Raw Data'!B13),"\$([A-Z]+)\$[0-9]+"))} | C13: {=IFERROR(IF(OR('Raw Data'!C13="",LEN(TRIM('Raw Data'!C13))=0),"",IF(AND(LEN('Raw Data'!C13) <= 20,LEN('Raw Data'!C13)> 0),"",_xlfn.REGEXEXTRACT(CELL("address",'Raw Data'!C13),"\$([A-Z]+)\$[0-9]+"))),_xlfn.REGEXEXTRACT(CELL("address",'Raw Data'!C13),"\$([A-Z]+)\$[0-9]+"))} | D13: {=IFERROR(IF(OR('Raw Data'!D13="",LEN(TRIM('Raw Data'!D13))=0),"",IF(AND(ISNUMBER('Raw Data'!D13),'Raw Data'!D13>=Configuration!$D$2),"",_xlfn.REGEXEXTRACT(CELL("address",'Raw Data'!D13),"\$([A-Z]+)\$[0-9]+"))),_xlfn.REGEXEXTRACT(CELL("address",D13), "\$([A-Z]+)\$[0-9]+"))} -> $D$13 | E13: {=IFERROR(IF(OR('Raw Data'!E13="",LEN(TRIM('Raw Data'!E13))=0),"",IF(AND(ISNUMBER('Raw Data'!E13), IFERROR('Raw Data'!E13 = ROUND('Raw Data'!E13, 4),FALSE)),"",_xlfn.REGEXEXTRACT(CELL("address",E13), "\$([A-Z]+)\$[0-9]+"))),_xlfn.REGEXEXTRACT(CELL("address",E13), "\$([A-Z]+)\$[0-9]+"))} | F13: {=IFERROR(IF(OR('Raw Data'!F13="",LEN(TRIM('Raw Data'!F13))=0),"",IF(AND(ISNUMBER('Raw Data'!F13), IFERROR('Raw Data'!F13 = ROUND('Raw Data'!F13, 4),FALSE)),"",_xlfn.REGEXEXTRACT(CELL("address",F13), "\$([A-Z]+)\$[0-9]+"))),_xlfn.REGEXEXTRACT(CELL("address",F13), "\$([A-Z]+)\$[0-9]+"))} | G13: {=IFERROR(IF(OR('Raw Data'!G13="",LEN(TRIM('Raw Data'!G13))=0),"",IF(AND(ISNUMBER('Raw Data'!G13), IFERROR('Raw Data'!G13 = ROUND('Raw Data'!G13, 4),FALSE)),"",_xlfn.REGEXEXTRACT(CELL("address",G13), "\$([A-Z]+)\$[0-9]+"))),_xlfn.REGEXEXTRACT(CELL("address",G13), "\$([A-Z]+)\$[0-9]+"))} | H13: {=IFERROR(IF(OR('Raw Data'!H13="",LEN(TRIM('Raw Data'!H13))=0),"",IF(AND(ISNUMBER('Raw Data'!H13), IFERROR('Raw Data'!H13 = ROUND('Raw Data'!H13, 4),FALSE)),"",_xlfn.REGEXEXTRACT(CELL("address",H13), "\$([A-Z]+)\$[0-9]+"))),_xlfn.REGEXEXTRACT(CELL("address",H13), "\$([A-Z]+)\$[0-9]+"))} | I13: {=IFERROR(IF(OR('Raw Data'!I13="",LEN(TRIM('Raw Data'!I13))=0),"",IF(AND(ISNUMBER('Raw Data'!I13), IFERROR('Raw Data'!I13 = ROUND('Raw Data'!I13, 4),FALSE)),"",_xlfn.REGEXEXTRACT(CELL("address",I13), "\$([A-Z]+)\$[0-9]+"))),_xlfn.REGEXEXTRACT(CELL("address",I13), "\$([A-Z]+)\$[0-9]+"))} | J13: {=IFERROR(IF(OR('Raw Data'!J13="",LEN(TRIM('Raw Data'!J13))=0),"",IF(AND(ISNUMBER('Raw Data'!J13), IFERROR('Raw Data'!J13 = ROUND('Raw Data'!J13, 4),FALSE)),"",_xlfn.REGEXEXTRACT(CELL("address",J13), "\$([A-Z]+)\$[0-9]+"))),_xlfn.REGEXEXTRACT(CELL("address",J13), "\$([A-Z]+)\$[0-9]+"))} | K13: {=IFERROR(IF(OR('Raw Data'!K13="",LEN(TRIM('Raw Data'!K13))=0),"",IF(AND(ISNUMBER('Raw Data'!K13), IFERROR('Raw Data'!K13 = ROUND('Raw Data'!K13, 2),FALSE)),"",_xlfn.REGEXEXTRACT(CELL("address",K13), "\$([A-Z]+)\$[0-9]+"))),_xlfn.REGEXEXTRACT(CELL("address",K13), "\$([A-Z]+)\$[0-9]+"))} | L13: {=IFERROR(IF(OR('Raw Data'!L13="",LEN(TRIM('Raw Data'!L13))=0),"",IF(AND(ISNUMBER('Raw Data'!L13), IFERROR('Raw Data'!L13 = ROUND('Raw Data'!L13, 2),FALSE)),"",_xlfn.REGEXEXTRACT(CELL("address",L13), "\$([A-Z]+)\$[0-9]+"))),_xlfn.REGEXEXTRACT(CELL("address",L13), "\$([A-Z]+)\$[0-9]+"))} | M13: {=IFERROR(IF(OR('Raw Data'!M13="",LEN(TRIM('Raw Data'!M13))=0),"",IF(AND(ISNUMBER('Raw Data'!M13), IFERROR('Raw Data'!M13 = ROUND('Raw Data'!M13, 2),FALSE)),"",_xlfn.REGEXEXTRACT(CELL("address",M13), "\$([A-Z]+)\$[0-9]+"))),_xlfn.REGEXEXTRACT(CELL("address",M13), "\$([A-Z]+)\$[0-9]+"))} | N13: {=IFERROR(IF(OR('Raw Data'!N13="",LEN(TRIM('Raw Data'!N13))=0),"",IF(AND(ISNUMBER('Raw Data'!N13), IFERROR('Raw Data'!N13 = ROUND('Raw Data'!N13, 2),FALSE)),"",_xlfn.REGEXEXTRACT(CELL("address",N13), "\$([A-Z]+)\$[0-9]+"))),_xlfn.REGEXEXTRACT(CELL("address",N13), "\$([A-Z]+)\$[0-9]+"))} | O13: {=IFERROR(IF(OR('Raw Data'!O13="",LEN(TRIM('Raw Data'!O13))=0),"",IF(AND(ISNUMBER('Raw Data'!O13), IFERROR('Raw Data'!O13 = ROUND('Raw Data'!O13, 2),FALSE)),"",_xlfn.REGEXEXTRACT(CELL("address",O13), "\$([A-Z]+)\$[0-9]+"))),_xlfn.REGEXEXTRACT(CELL("address",O13), "\$([A-Z]+)\$[0-9]+"))} | P13: {=IFERROR(IF(OR('Raw Data'!P13="",LEN(TRIM('Raw Data'!P13))=0),"",IF(AND(ISNUMBER('Raw Data'!P13), IFERROR('Raw Data'!P13 = ROUND('Raw Data'!P13, 2),FALSE)),"",_xlfn.REGEXEXTRACT(CELL("address",P13), "\$([A-Z]+)\$[0-9]+"))),_xlfn.REGEXEXTRACT(CELL("address",P13), "\$([A-Z]+)\$[0-9]+"))} | Q13: {=IFERROR(IF(OR('Raw Data'!Q13="",LEN(TRIM('Raw Data'!Q13))=0),"",IF(AND(ISNUMBER('Raw Data'!Q13), IFERROR('Raw Data'!Q13 = ROUND('Raw Data'!Q13, 2),FALSE)),"",_xlfn.REGEXEXTRACT(CELL("address",Q13), "\$([A-Z]+)\$[0-9]+"))),_xlfn.REGEXEXTRACT(CELL("address",Q13), "\$([A-Z]+)\$[0-9]+"))} | R13: {=IFERROR(IF(OR('Raw Data'!R13="",LEN(TRIM('Raw Data'!R13))=0),"",IF(AND(ISNUMBER('Raw Data'!R13), IFERROR('Raw Data'!R13 = ROUND('Raw Data'!R13, 2),FALSE)),"",_xlfn.REGEXEXTRACT(CELL("address",R13), "\$([A-Z]+)\$[0-9]+"))),_xlfn.REGEXEXTRACT(CELL("address",R13), "\$([A-Z]+)\$[0-9]+"))} | ... V13: {=IFERROR(IF(OR('Raw Data'!V13="",LEN(TRIM('Raw Data'!V13))=0),"",IF(AND(ISNUMBER('Raw Data'!V13), IFERROR('Raw Data'!V13 = ROUND('Raw Data'!V13, 2),FALSE)),"",_xlfn.REGEXEXTRACT(CELL("address",V13), "\$([A-Z]+)\$[0-9]+"))),_xlfn.REGEXEXTRACT(CELL("address",V13), "\$([A-Z]+)\$[0-9]+"))}
B14: {=IFERROR(IF(OR('Raw Data'!B14="",LEN(TRIM('Raw Data'!B14))=0),"",IF(AND(LEN('Raw Data'!B14) <= 255,LEN('Raw Data'!B14)> 0),"",_xlfn.REGEXEXTRACT(CELL("address",'Raw Data'!B14),"\$([A-Z]+)\$[0-9]+"))),_xlfn.REGEXEXTRACT(CELL("address",'Raw Data'!B14),"\$([A-Z]+)\$[0-9]+"))} | C14: {=IFERROR(IF(OR('Raw Data'!C14="",LEN(TRIM('Raw Data'!C14))=0),"",IF(AND(LEN('Raw Data'!C14) <= 20,LEN('Raw Data'!C14)> 0),"",_xlfn.REGEXEXTRACT(CELL("address",'Raw Data'!C14),"\$([A-Z]+)\$[0-9]+"))),_xlfn.REGEXEXTRACT(CELL("address",'Raw Data'!C14),"\$([A-Z]+)\$[0-9]+"))} | D14: {=IFERROR(IF(OR('Raw Data'!D14="",LEN(TRIM('Raw Data'!D14))=0),"",IF(AND(ISNUMBER('Raw Data'!D14),'Raw Data'!D14>=Configuration!$D$2),"",_xlfn.REGEXEXTRACT(CELL("address",'Raw Data'!D14),"\$([A-Z]+)\$[0-9]+"))),_xlfn.REGEXEXTRACT(CELL("address",D14), "\$([A-Z]+)\$[0-9]+"))} -> $D$14 | E14: {=IFERROR(IF(OR('Raw Data'!E14="",LEN(TRIM('Raw Data'!E14))=0),"",IF(AND(ISNUMBER('Raw Data'!E14), IFERROR('Raw Data'!E14 = ROUND('Raw Data'!E14, 4),FALSE)),"",_xlfn.REGEXEXTRACT(CELL("address",E14), "\$([A-Z]+)\$[0-9]+"))),_xlfn.REGEXEXTRACT(CELL("address",E14), "\$([A-Z]+)\$[0-9]+"))} | F14: {=IFERROR(IF(OR('Raw Data'!F14="",LEN(TRIM('Raw Data'!F14))=0),"",IF(AND(ISNUMBER('Raw Data'!F14), IFERROR('Raw Data'!F14 = ROUND('Raw Data'!F14, 4),FALSE)),"",_xlfn.REGEXEXTRACT(CELL("address",F14), "\$([A-Z]+)\$[0-9]+"))),_xlfn.REGEXEXTRACT(CELL("address",F14), "\$([A-Z]+)\$[0-9]+"))} | G14: {=IFERROR(IF(OR('Raw Data'!G14="",LEN(TRIM('Raw Data'!G14))=0),"",IF(AND(ISNUMBER('Raw Data'!G14), IFERROR('Raw Data'!G14 = ROUND('Raw Data'!G14, 4),FALSE)),"",_xlfn.REGEXEXTRACT(CELL("address",G14), "\$([A-Z]+)\$[0-9]+"))),_xlfn.REGEXEXTRACT(CELL("address",G14), "\$([A-Z]+)\$[0-9]+"))} | H14: {=IFERROR(IF(OR('Raw Data'!H14="",LEN(TRIM('Raw Data'!H14))=0),"",IF(AND(ISNUMBER('Raw Data'!H14), IFERROR('Raw Data'!H14 = ROUND('Raw Data'!H14, 4),FALSE)),"",_xlfn.REGEXEXTRACT(CELL("address",H14), "\$([A-Z]+)\$[0-9]+"))),_xlfn.REGEXEXTRACT(CELL("address",H14), "\$([A-Z]+)\$[0-9]+"))} | I14: {=IFERROR(IF(OR('Raw Data'!I14="",LEN(TRIM('Raw Data'!I14))=0),"",IF(AND(ISNUMBER('Raw Data'!I14), IFERROR('Raw Data'!I14 = ROUND('Raw Data'!I14, 4),FALSE)),"",_xlfn.REGEXEXTRACT(CELL("address",I14), "\$([A-Z]+)\$[0-9]+"))),_xlfn.REGEXEXTRACT(CELL("address",I14), "\$([A-Z]+)\$[0-9]+"))} | J14: {=IFERROR(IF(OR('Raw Data'!J14="",LEN(TRIM('Raw Data'!J14))=0),"",IF(AND(ISNUMBER('Raw Data'!J14), IFERROR('Raw Data'!J14 = ROUND('Raw Data'!J14, 4),FALSE)),"",_xlfn.REGEXEXTRACT(CELL("address",J14), "\$([A-Z]+)\$[0-9]+"))),_xlfn.REGEXEXTRACT(CELL("address",J14), "\$([A-Z]+)\$[0-9]+"))} | K14: {=IFERROR(IF(OR('Raw Data'!K14="",LEN(TRIM('Raw Data'!K14))=0),"",IF(AND(ISNUMBER('Raw Data'!K14), IFERROR('Raw Data'!K14 = ROUND('Raw Data'!K14, 2),FALSE)),"",_xlfn.REGEXEXTRACT(CELL("address",K14), "\$([A-Z]+)\$[0-9]+"))),_xlfn.REGEXEXTRACT(CELL("address",K14), "\$([A-Z]+)\$[0-9]+"))} | L14: {=IFERROR(IF(OR('Raw Data'!L14="",LEN(TRIM('Raw Data'!L14))=0),"",IF(AND(ISNUMBER('Raw Data'!L14), IFERROR('Raw Data'!L14 = ROUND('Raw Data'!L14, 2),FALSE)),"",_xlfn.REGEXEXTRACT(CELL("address",L14), "\$([A-Z]+)\$[0-9]+"))),_xlfn.REGEXEXTRACT(CELL("address",L14), "\$([A-Z]+)\$[0-9]+"))} | M14: {=IFERROR(IF(OR('Raw Data'!M14="",LEN(TRIM('Raw Data'!M14))=0),"",IF(AND(ISNUMBER('Raw Data'!M14), IFERROR('Raw Data'!M14 = ROUND('Raw Data'!M14, 2),FALSE)),"",_xlfn.REGEXEXTRACT(CELL("address",M14), "\$([A-Z]+)\$[0-9]+"))),_xlfn.REGEXEXTRACT(CELL("address",M14), "\$([A-Z]+)\$[0-9]+"))} | N14: {=IFERROR(IF(OR('Raw Data'!N14="",LEN(TRIM('Raw Data'!N14))=0),"",IF(AND(ISNUMBER('Raw Data'!N14), IFERROR('Raw Data'!N14 = ROUND('Raw Data'!N14, 2),FALSE)),"",_xlfn.REGEXEXTRACT(CELL("address",N14), "\$([A-Z]+)\$[0-9]+"))),_xlfn.REGEXEXTRACT(CELL("address",N14), "\$([A-Z]+)\$[0-9]+"))} | O14: {=IFERROR(IF(OR('Raw Data'!O14="",LEN(TRIM('Raw Data'!O14))=0),"",IF(AND(ISNUMBER('Raw Data'!O14), IFERROR('Raw Data'!O14 = ROUND('Raw Data'!O14, 2),FALSE)),"",_xlfn.REGEXEXTRACT(CELL("address",O14), "\$([A-Z]+)\$[0-9]+"))),_xlfn.REGEXEXTRACT(CELL("address",O14), "\$([A-Z]+)\$[0-9]+"))} | P14: {=IFERROR(IF(OR('Raw Data'!P14="",LEN(TRIM('Raw Data'!P14))=0),"",IF(AND(ISNUMBER('Raw Data'!P14), IFERROR('Raw Data'!P14 = ROUND('Raw Data'!P14, 2),FALSE)),"",_xlfn.REGEXEXTRACT(CELL("address",P14), "\$([A-Z]+)\$[0-9]+"))),_xlfn.REGEXEXTRACT(CELL("address",P14), "\$([A-Z]+)\$[0-9]+"))} | Q14: {=IFERROR(IF(OR('Raw Data'!Q14="",LEN(TRIM('Raw Data'!Q14))=0),"",IF(AND(ISNUMBER('Raw Data'!Q14), IFERROR('Raw Data'!Q14 = ROUND('Raw Data'!Q14, 2),FALSE)),"",_xlfn.REGEXEXTRACT(CELL("address",Q14), "\$([A-Z]+)\$[0-9]+"))),_xlfn.REGEXEXTRACT(CELL("address",Q14), "\$([A-Z]+)\$[0-9]+"))} | R14: {=IFERROR(IF(OR('Raw Data'!R14="",LEN(TRIM('Raw Data'!R14))=0),"",IF(AND(ISNUMBER('Raw Data'!R14), IFERROR('Raw Data'!R14 = ROUND('Raw Data'!R14, 2),FALSE)),"",_xlfn.REGEXEXTRACT(CELL("address",R14), "\$([A-Z]+)\$[0-9]+"))),_xlfn.REGEXEXTRACT(CELL("address",R14), "\$([A-Z]+)\$[0-9]+"))} | ... V14: {=IFERROR(IF(OR('Raw Data'!V14="",LEN(TRIM('Raw Data'!V14))=0),"",IF(AND(ISNUMBER('Raw Data'!V14), IFERROR('Raw Data'!V14 = ROUND('Raw Data'!V14, 2),FALSE)),"",_xlfn.REGEXEXTRACT(CELL("address",V14), "\$([A-Z]+)\$[0-9]+"))),_xlfn.REGEXEXTRACT(CELL("address",V14), "\$([A-Z]+)\$[0-9]+"))}
B15: {=IFERROR(IF(OR('Raw Data'!B15="",LEN(TRIM('Raw Data'!B15))=0),"",IF(AND(LEN('Raw Data'!B15) <= 255,LEN('Raw Data'!B15)> 0),"",_xlfn.REGEXEXTRACT(CELL("address",'Raw Data'!B15),"\$([A-Z]+)\$[0-9]+"))),_xlfn.REGEXEXTRACT(CELL("address",'Raw Data'!B15),"\$([A-Z]+)\$[0-9]+"))} | C15: {=IFERROR(IF(OR('Raw Data'!C15="",LEN(TRIM('Raw Data'!C15))=0),"",IF(AND(LEN('Raw Data'!C15) <= 20,LEN('Raw Data'!C15)> 0),"",_xlfn.REGEXEXTRACT(CELL("address",'Raw Data'!C15),"\$([A-Z]+)\$[0-9]+"))),_xlfn.REGEXEXTRACT(CELL("address",'Raw Data'!C15),"\$([A-Z]+)\$[0-9]+"))} | D15: {=IFERROR(IF(OR('Raw Data'!D15="",LEN(TRIM('Raw Data'!D15))=0),"",IF(AND(ISNUMBER('Raw Data'!D15),'Raw Data'!D15>=Configuration!$D$2),"",_xlfn.REGEXEXTRACT(CELL("address",'Raw Data'!D15),"\$([A-Z]+)\$[0-9]+"))),_xlfn.REGEXEXTRACT(CELL("address",D15), "\$([A-Z]+)\$[0-9]+"))} -> $D$15 | E15: {=IFERROR(IF(OR('Raw Data'!E15="",LEN(TRIM('Raw Data'!E15))=0),"",IF(AND(ISNUMBER('Raw Data'!E15), IFERROR('Raw Data'!E15 = ROUND('Raw Data'!E15, 4),FALSE)),"",_xlfn.REGEXEXTRACT(CELL("address",E15), "\$([A-Z]+)\$[0-9]+"))),_xlfn.REGEXEXTRACT(CELL("address",E15), "\$([A-Z]+)\$[0-9]+"))} | F15: {=IFERROR(IF(OR('Raw Data'!F15="",LEN(TRIM('Raw Data'!F15))=0),"",IF(AND(ISNUMBER('Raw Data'!F15), IFERROR('Raw Data'!F15 = ROUND('Raw Data'!F15, 4),FALSE)),"",_xlfn.REGEXEXTRACT(CELL("address",F15), "\$([A-Z]+)\$[0-9]+"))),_xlfn.REGEXEXTRACT(CELL("address",F15), "\$([A-Z]+)\$[0-9]+"))} | G15: {=IFERROR(IF(OR('Raw Data'!G15="",LEN(TRIM('Raw Data'!G15))=0),"",IF(AND(ISNUMBER('Raw Data'!G15), IFERROR('Raw Data'!G15 = ROUND('Raw Data'!G15, 4),FALSE)),"",_xlfn.REGEXEXTRACT(CELL("address",G15), "\$([A-Z]+)\$[0-9]+"))),_xlfn.REGEXEXTRACT(CELL("address",G15), "\$([A-Z]+)\$[0-9]+"))} | H15: {=IFERROR(IF(OR('Raw Data'!H15="",LEN(TRIM('Raw Data'!H15))=0),"",IF(AND(ISNUMBER('Raw Data'!H15), IFERROR('Raw Data'!H15 = ROUND('Raw Data'!H15, 4),FALSE)),"",_xlfn.REGEXEXTRACT(CELL("address",H15), "\$([A-Z]+)\$[0-9]+"))),_xlfn.REGEXEXTRACT(CELL("address",H15), "\$([A-Z]+)\$[0-9]+"))} | I15: {=IFERROR(IF(OR('Raw Data'!I15="",LEN(TRIM('Raw Data'!I15))=0),"",IF(AND(ISNUMBER('Raw Data'!I15), IFERROR('Raw Data'!I15 = ROUND('Raw Data'!I15, 4),FALSE)),"",_xlfn.REGEXEXTRACT(CELL("address",I15), "\$([A-Z]+)\$[0-9]+"))),_xlfn.REGEXEXTRACT(CELL("address",I15), "\$([A-Z]+)\$[0-9]+"))} | J15: {=IFERROR(IF(OR('Raw Data'!J15="",LEN(TRIM('Raw Data'!J15))=0),"",IF(AND(ISNUMBER('Raw Data'!J15), IFERROR('Raw Data'!J15 = ROUND('Raw Data'!J15, 4),FALSE)),"",_xlfn.REGEXEXTRACT(CELL("address",J15), "\$([A-Z]+)\$[0-9]+"))),_xlfn.REGEXEXTRACT(CELL("address",J15), "\$([A-Z]+)\$[0-9]+"))} | K15: {=IFERROR(IF(OR('Raw Data'!K15="",LEN(TRIM('Raw Data'!K15))=0),"",IF(AND(ISNUMBER('Raw Data'!K15), IFERROR('Raw Data'!K15 = ROUND('Raw Data'!K15, 2),FALSE)),"",_xlfn.REGEXEXTRACT(CELL("address",K15), "\$([A-Z]+)\$[0-9]+"))),_xlfn.REGEXEXTRACT(CELL("address",K15), "\$([A-Z]+)\$[0-9]+"))} | L15: {=IFERROR(IF(OR('Raw Data'!L15="",LEN(TRIM('Raw Data'!L15))=0),"",IF(AND(ISNUMBER('Raw Data'!L15), IFERROR('Raw Data'!L15 = ROUND('Raw Data'!L15, 2),FALSE)),"",_xlfn.REGEXEXTRACT(CELL("address",L15), "\$([A-Z]+)\$[0-9]+"))),_xlfn.REGEXEXTRACT(CELL("address",L15), "\$([A-Z]+)\$[0-9]+"))} | M15: {=IFERROR(IF(OR('Raw Data'!M15="",LEN(TRIM('Raw Data'!M15))=0),"",IF(AND(ISNUMBER('Raw Data'!M15), IFERROR('Raw Data'!M15 = ROUND('Raw Data'!M15, 2),FALSE)),"",_xlfn.REGEXEXTRACT(CELL("address",M15), "\$([A-Z]+)\$[0-9]+"))),_xlfn.REGEXEXTRACT(CELL("address",M15), "\$([A-Z]+)\$[0-9]+"))} | N15: {=IFERROR(IF(OR('Raw Data'!N15="",LEN(TRIM('Raw Data'!N15))=0),"",IF(AND(ISNUMBER('Raw Data'!N15), IFERROR('Raw Data'!N15 = ROUND('Raw Data'!N15, 2),FALSE)),"",_xlfn.REGEXEXTRACT(CELL("address",N15), "\$([A-Z]+)\$[0-9]+"))),_xlfn.REGEXEXTRACT(CELL("address",N15), "\$([A-Z]+)\$[0-9]+"))} | O15: {=IFERROR(IF(OR('Raw Data'!O15="",LEN(TRIM('Raw Data'!O15))=0),"",IF(AND(ISNUMBER('Raw Data'!O15), IFERROR('Raw Data'!O15 = ROUND('Raw Data'!O15, 2),FALSE)),"",_xlfn.REGEXEXTRACT(CELL("address",O15), "\$([A-Z]+)\$[0-9]+"))),_xlfn.REGEXEXTRACT(CELL("address",O15), "\$([A-Z]+)\$[0-9]+"))} | P15: {=IFERROR(IF(OR('Raw Data'!P15="",LEN(TRIM('Raw Data'!P15))=0),"",IF(AND(ISNUMBER('Raw Data'!P15), IFERROR('Raw Data'!P15 = ROUND('Raw Data'!P15, 2),FALSE)),"",_xlfn.REGEXEXTRACT(CELL("address",P15), "\$([A-Z]+)\$[0-9]+"))),_xlfn.REGEXEXTRACT(CELL("address",P15), "\$([A-Z]+)\$[0-9]+"))} | Q15: {=IFERROR(IF(OR('Raw Data'!Q15="",LEN(TRIM('Raw Data'!Q15))=0),"",IF(AND(ISNUMBER('Raw Data'!Q15), IFERROR('Raw Data'!Q15 = ROUND('Raw Data'!Q15, 2),FALSE)),"",_xlfn.REGEXEXTRACT(CELL("address",Q15), "\$([A-Z]+)\$[0-9]+"))),_xlfn.REGEXEXTRACT(CELL("address",Q15), "\$([A-Z]+)\$[0-9]+"))} | R15: {=IFERROR(IF(OR('Raw Data'!R15="",LEN(TRIM('Raw Data'!R15))=0),"",IF(AND(ISNUMBER('Raw Data'!R15), IFERROR('Raw Data'!R15 = ROUND('Raw Data'!R15, 2),FALSE)),"",_xlfn.REGEXEXTRACT(CELL("address",R15), "\$([A-Z]+)\$[0-9]+"))),_xlfn.REGEXEXTRACT(CELL("address",R15), "\$([A-Z]+)\$[0-9]+"))} | ... V15: {=IFERROR(IF(OR('Raw Data'!V15="",LEN(TRIM('Raw Data'!V15))=0),"",IF(AND(ISNUMBER('Raw Data'!V15), IFERROR('Raw Data'!V15 = ROUND('Raw Data'!V15, 2),FALSE)),"",_xlfn.REGEXEXTRACT(CELL("address",V15), "\$([A-Z]+)\$[0-9]+"))),_xlfn.REGEXEXTRACT(CELL("address",V15), "\$([A-Z]+)\$[0-9]+"))}
B16: {=IFERROR(IF(OR('Raw Data'!B16="",LEN(TRIM('Raw Data'!B16))=0),"",IF(AND(LEN('Raw Data'!B16) <= 255,LEN('Raw Data'!B16)> 0),"",_xlfn.REGEXEXTRACT(CELL("address",'Raw Data'!B16),"\$([A-Z]+)\$[0-9]+"))),_xlfn.REGEXEXTRACT(CELL("address",'Raw Data'!B16),"\$([A-Z]+)\$[0-9]+"))} | C16: {=IFERROR(IF(OR('Raw Data'!C16="",LEN(TRIM('Raw Data'!C16))=0),"",IF(AND(LEN('Raw Data'!C16) <= 20,LEN('Raw Data'!C16)> 0),"",_xlfn.REGEXEXTRACT(CELL("address",'Raw Data'!C16),"\$([A-Z]+)\$[0-9]+"))),_xlfn.REGEXEXTRACT(CELL("address",'Raw Data'!C16),"\$([A-Z]+)\$[0-9]+"))} | D16: {=IFERROR(IF(OR('Raw Data'!D16="",LEN(TRIM('Raw Data'!D16))=0),"",IF(AND(ISNUMBER('Raw Data'!D16),'Raw Data'!D16>=Configuration!$D$2),"",_xlfn.REGEXEXTRACT(CELL("address",'Raw Data'!D16),"\$([A-Z]+)\$[0-9]+"))),_xlfn.REGEXEXTRACT(CELL("address",D16), "\$([A-Z]+)\$[0-9]+"))} -> $D$16 | E16: {=IFERROR(IF(OR('Raw Data'!E16="",LEN(TRIM('Raw Data'!E16))=0),"",IF(AND(ISNUMBER('Raw Data'!E16), IFERROR('Raw Data'!E16 = ROUND('Raw Data'!E16, 4),FALSE)),"",_xlfn.REGEXEXTRACT(CELL("address",E16), "\$([A-Z]+)\$[0-9]+"))),_xlfn.REGEXEXTRACT(CELL("address",E16), "\$([A-Z]+)\$[0-9]+"))} | F16: {=IFERROR(IF(OR('Raw Data'!F16="",LEN(TRIM('Raw Data'!F16))=0),"",IF(AND(ISNUMBER('Raw Data'!F16), IFERROR('Raw Data'!F16 = ROUND('Raw Data'!F16, 4),FALSE)),"",_xlfn.REGEXEXTRACT(CELL("address",F16), "\$([A-Z]+)\$[0-9]+"))),_xlfn.REGEXEXTRACT(CELL("address",F16), "\$([A-Z]+)\$[0-9]+"))} | G16: {=IFERROR(IF(OR('Raw Data'!G16="",LEN(TRIM('Raw Data'!G16))=0),"",IF(AND(ISNUMBER('Raw Data'!G16), IFERROR('Raw Data'!G16 = ROUND('Raw Data'!G16, 4),FALSE)),"",_xlfn.REGEXEXTRACT(CELL("address",G16), "\$([A-Z]+)\$[0-9]+"))),_xlfn.REGEXEXTRACT(CELL("address",G16), "\$([A-Z]+)\$[0-9]+"))} | H16: {=IFERROR(IF(OR('Raw Data'!H16="",LEN(TRIM('Raw Data'!H16))=0),"",IF(AND(ISNUMBER('Raw Data'!H16), IFERROR('Raw Data'!H16 = ROUND('Raw Data'!H16, 4),FALSE)),"",_xlfn.REGEXEXTRACT(CELL("address",H16), "\$([A-Z]+)\$[0-9]+"))),_xlfn.REGEXEXTRACT(CELL("address",H16), "\$([A-Z]+)\$[0-9]+"))} | I16: {=IFERROR(IF(OR('Raw Data'!I16="",LEN(TRIM('Raw Data'!I16))=0),"",IF(AND(ISNUMBER('Raw Data'!I16), IFERROR('Raw Data'!I16 = ROUND('Raw Data'!I16, 4),FALSE)),"",_xlfn.REGEXEXTRACT(CELL("address",I16), "\$([A-Z]+)\$[0-9]+"))),_xlfn.REGEXEXTRACT(CELL("address",I16), "\$([A-Z]+)\$[0-9]+"))} | J16: {=IFERROR(IF(OR('Raw Data'!J16="",LEN(TRIM('Raw Data'!J16))=0),"",IF(AND(ISNUMBER('Raw Data'!J16), IFERROR('Raw Data'!J16 = ROUND('Raw Data'!J16, 4),FALSE)),"",_xlfn.REGEXEXTRACT(CELL("address",J16), "\$([A-Z]+)\$[0-9]+"))),_xlfn.REGEXEXTRACT(CELL("address",J16), "\$([A-Z]+)\$[0-9]+"))} | K16: {=IFERROR(IF(OR('Raw Data'!K16="",LEN(TRIM('Raw Data'!K16))=0),"",IF(AND(ISNUMBER('Raw Data'!K16), IFERROR('Raw Data'!K16 = ROUND('Raw Data'!K16, 2),FALSE)),"",_xlfn.REGEXEXTRACT(CELL("address",K16), "\$([A-Z]+)\$[0-9]+"))),_xlfn.REGEXEXTRACT(CELL("address",K16), "\$([A-Z]+)\$[0-9]+"))} | L16: {=IFERROR(IF(OR('Raw Data'!L16="",LEN(TRIM('Raw Data'!L16))=0),"",IF(AND(ISNUMBER('Raw Data'!L16), IFERROR('Raw Data'!L16 = ROUND('Raw Data'!L16, 2),FALSE)),"",_xlfn.REGEXEXTRACT(CELL("address",L16), "\$([A-Z]+)\$[0-9]+"))),_xlfn.REGEXEXTRACT(CELL("address",L16), "\$([A-Z]+)\$[0-9]+"))} | M16: {=IFERROR(IF(OR('Raw Data'!M16="",LEN(TRIM('Raw Data'!M16))=0),"",IF(AND(ISNUMBER('Raw Data'!M16), IFERROR('Raw Data'!M16 = ROUND('Raw Data'!M16, 2),FALSE)),"",_xlfn.REGEXEXTRACT(CELL("address",M16), "\$([A-Z]+)\$[0-9]+"))),_xlfn.REGEXEXTRACT(CELL("address",M16), "\$([A-Z]+)\$[0-9]+"))} | N16: {=IFERROR(IF(OR('Raw Data'!N16="",LEN(TRIM('Raw Data'!N16))=0),"",IF(AND(ISNUMBER('Raw Data'!N16), IFERROR('Raw Data'!N16 = ROUND('Raw Data'!N16, 2),FALSE)),"",_xlfn.REGEXEXTRACT(CELL("address",N16), "\$([A-Z]+)\$[0-9]+"))),_xlfn.REGEXEXTRACT(CELL("address",N16), "\$([A-Z]+)\$[0-9]+"))} | O16: {=IFERROR(IF(OR('Raw Data'!O16="",LEN(TRIM('Raw Data'!O16))=0),"",IF(AND(ISNUMBER('Raw Data'!O16), IFERROR('Raw Data'!O16 = ROUND('Raw Data'!O16, 2),FALSE)),"",_xlfn.REGEXEXTRACT(CELL("address",O16), "\$([A-Z]+)\$[0-9]+"))),_xlfn.REGEXEXTRACT(CELL("address",O16), "\$([A-Z]+)\$[0-9]+"))} | P16: {=IFERROR(IF(OR('Raw Data'!P16="",LEN(TRIM('Raw Data'!P16))=0),"",IF(AND(ISNUMBER('Raw Data'!P16), IFERROR('Raw Data'!P16 = ROUND('Raw Data'!P16, 2),FALSE)),"",_xlfn.REGEXEXTRACT(CELL("address",P16), "\$([A-Z]+)\$[0-9]+"))),_xlfn.REGEXEXTRACT(CELL("address",P16), "\$([A-Z]+)\$[0-9]+"))} | Q16: {=IFERROR(IF(OR('Raw Data'!Q16="",LEN(TRIM('Raw Data'!Q16))=0),"",IF(AND(ISNUMBER('Raw Data'!Q16), IFERROR('Raw Data'!Q16 = ROUND('Raw Data'!Q16, 2),FALSE)),"",_xlfn.REGEXEXTRACT(CELL("address",Q16), "\$([A-Z]+)\$[0-9]+"))),_xlfn.REGEXEXTRACT(CELL("address",Q16), "\$([A-Z]+)\$[0-9]+"))} | R16: {=IFERROR(IF(OR('Raw Data'!R16="",LEN(TRIM('Raw Data'!R16))=0),"",IF(AND(ISNUMBER('Raw Data'!R16), IFERROR('Raw Data'!R16 = ROUND('Raw Data'!R16, 2),FALSE)),"",_xlfn.REGEXEXTRACT(CELL("address",R16), "\$([A-Z]+)\$[0-9]+"))),_xlfn.REGEXEXTRACT(CELL("address",R16), "\$([A-Z]+)\$[0-9]+"))} | ... V16: {=IFERROR(IF(OR('Raw Data'!V16="",LEN(TRIM('Raw Data'!V16))=0),"",IF(AND(ISNUMBER('Raw Data'!V16), IFERROR('Raw Data'!V16 = ROUND('Raw Data'!V16, 2),FALSE)),"",_xlfn.REGEXEXTRACT(CELL("address",V16), "\$([A-Z]+)\$[0-9]+"))),_xlfn.REGEXEXTRACT(CELL("address",V16), "\$([A-Z]+)\$[0-9]+"))}
B17: {=IFERROR(IF(OR('Raw Data'!B17="",LEN(TRIM('Raw Data'!B17))=0),"",IF(AND(LEN('Raw Data'!B17) <= 255,LEN('Raw Data'!B17)> 0),"",_xlfn.REGEXEXTRACT(CELL("address",'Raw Data'!B17),"\$([A-Z]+)\$[0-9]+"))),_xlfn.REGEXEXTRACT(CELL("address",'Raw Data'!B17),"\$([A-Z]+)\$[0-9]+"))} | C17: {=IFERROR(IF(OR('Raw Data'!C17="",LEN(TRIM('Raw Data'!C17))=0),"",IF(AND(LEN('Raw Data'!C17) <= 20,LEN('Raw Data'!C17)> 0),"",_xlfn.REGEXEXTRACT(CELL("address",'Raw Data'!C17),"\$([A-Z]+)\$[0-9]+"))),_xlfn.REGEXEXTRACT(CELL("address",'Raw Data'!C17),"\$([A-Z]+)\$[0-9]+"))} | D17: {=IFERROR(IF(OR('Raw Data'!D17="",LEN(TRIM('Raw Data'!D17))=0),"",IF(AND(ISNUMBER('Raw Data'!D17),'Raw Data'!D17>=Configuration!$D$2),"",_xlfn.REGEXEXTRACT(CELL("address",'Raw Data'!D17),"\$([A-Z]+)\$[0-9]+"))),_xlfn.REGEXEXTRACT(CELL("address",D17), "\$([A-Z]+)\$[0-9]+"))} -> $D$17 | E17: {=IFERROR(IF(OR('Raw Data'!E17="",LEN(TRIM('Raw Data'!E17))=0),"",IF(AND(ISNUMBER('Raw Data'!E17), IFERROR('Raw Data'!E17 = ROUND('Raw Data'!E17, 4),FALSE)),"",_xlfn.REGEXEXTRACT(CELL("address",E17), "\$([A-Z]+)\$[0-9]+"))),_xlfn.REGEXEXTRACT(CELL("address",E17), "\$([A-Z]+)\$[0-9]+"))} | F17: {=IFERROR(IF(OR('Raw Data'!F17="",LEN(TRIM('Raw Data'!F17))=0),"",IF(AND(ISNUMBER('Raw Data'!F17), IFERROR('Raw Data'!F17 = ROUND('Raw Data'!F17, 4),FALSE)),"",_xlfn.REGEXEXTRACT(CELL("address",F17), "\$([A-Z]+)\$[0-9]+"))),_xlfn.REGEXEXTRACT(CELL("address",F17), "\$([A-Z]+)\$[0-9]+"))} | G17: {=IFERROR(IF(OR('Raw Data'!G17="",LEN(TRIM('Raw Data'!G17))=0),"",IF(AND(ISNUMBER('Raw Data'!G17), IFERROR('Raw Data'!G17 = ROUND('Raw Data'!G17, 4),FALSE)),"",_xlfn.REGEXEXTRACT(CELL("address",G17), "\$([A-Z]+)\$[0-9]+"))),_xlfn.REGEXEXTRACT(CELL("address",G17), "\$([A-Z]+)\$[0-9]+"))} | H17: {=IFERROR(IF(OR('Raw Data'!H17="",LEN(TRIM('Raw Data'!H17))=0),"",IF(AND(ISNUMBER('Raw Data'!H17), IFERROR('Raw Data'!H17 = ROUND('Raw Data'!H17, 4),FALSE)),"",_xlfn.REGEXEXTRACT(CELL("address",H17), "\$([A-Z]+)\$[0-9]+"))),_xlfn.REGEXEXTRACT(CELL("address",H17), "\$([A-Z]+)\$[0-9]+"))} | I17: {=IFERROR(IF(OR('Raw Data'!I17="",LEN(TRIM('Raw Data'!I17))=0),"",IF(AND(ISNUMBER('Raw Data'!I17), IFERROR('Raw Data'!I17 = ROUND('Raw Data'!I17, 4),FALSE)),"",_xlfn.REGEXEXTRACT(CELL("address",I17), "\$([A-Z]+)\$[0-9]+"))),_xlfn.REGEXEXTRACT(CELL("address",I17), "\$([A-Z]+)\$[0-9]+"))} | J17: {=IFERROR(IF(OR('Raw Data'!J17="",LEN(TRIM('Raw Data'!J17))=0),"",IF(AND(ISNUMBER('Raw Data'!J17), IFERROR('Raw Data'!J17 = ROUND('Raw Data'!J17, 4),FALSE)),"",_xlfn.REGEXEXTRACT(CELL("address",J17), "\$([A-Z]+)\$[0-9]+"))),_xlfn.REGEXEXTRACT(CELL("address",J17), "\$([A-Z]+)\$[0-9]+"))} | K17: {=IFERROR(IF(OR('Raw Data'!K17="",LEN(TRIM('Raw Data'!K17))=0),"",IF(AND(ISNUMBER('Raw Data'!K17), IFERROR('Raw Data'!K17 = ROUND('Raw Data'!K17, 2),FALSE)),"",_xlfn.REGEXEXTRACT(CELL("address",K17), "\$([A-Z]+)\$[0-9]+"))),_xlfn.REGEXEXTRACT(CELL("address",K17), "\$([A-Z]+)\$[0-9]+"))} | L17: {=IFERROR(IF(OR('Raw Data'!L17="",LEN(TRIM('Raw Data'!L17))=0),"",IF(AND(ISNUMBER('Raw Data'!L17), IFERROR('Raw Data'!L17 = ROUND('Raw Data'!L17, 2),FALSE)),"",_xlfn.REGEXEXTRACT(CELL("address",L17), "\$([A-Z]+)\$[0-9]+"))),_xlfn.REGEXEXTRACT(CELL("address",L17), "\$([A-Z]+)\$[0-9]+"))} | M17: {=IFERROR(IF(OR('Raw Data'!M17="",LEN(TRIM('Raw Data'!M17))=0),"",IF(AND(ISNUMBER('Raw Data'!M17), IFERROR('Raw Data'!M17 = ROUND('Raw Data'!M17, 2),FALSE)),"",_xlfn.REGEXEXTRACT(CELL("address",M17), "\$([A-Z]+)\$[0-9]+"))),_xlfn.REGEXEXTRACT(CELL("address",M17), "\$([A-Z]+)\$[0-9]+"))} | N17: {=IFERROR(IF(OR('Raw Data'!N17="",LEN(TRIM('Raw Data'!N17))=0),"",IF(AND(ISNUMBER('Raw Data'!N17), IFERROR('Raw Data'!N17 = ROUND('Raw Data'!N17, 2),FALSE)),"",_xlfn.REGEXEXTRACT(CELL("address",N17), "\$([A-Z]+)\$[0-9]+"))),_xlfn.REGEXEXTRACT(CELL("address",N17), "\$([A-Z]+)\$[0-9]+"))} | O17: {=IFERROR(IF(OR('Raw Data'!O17="",LEN(TRIM('Raw Data'!O17))=0),"",IF(AND(ISNUMBER('Raw Data'!O17), IFERROR('Raw Data'!O17 = ROUND('Raw Data'!O17, 2),FALSE)),"",_xlfn.REGEXEXTRACT(CELL("address",O17), "\$([A-Z]+)\$[0-9]+"))),_xlfn.REGEXEXTRACT(CELL("address",O17), "\$([A-Z]+)\$[0-9]+"))} | P17: {=IFERROR(IF(OR('Raw Data'!P17="",LEN(TRIM('Raw Data'!P17))=0),"",IF(AND(ISNUMBER('Raw Data'!P17), IFERROR('Raw Data'!P17 = ROUND('Raw Data'!P17, 2),FALSE)),"",_xlfn.REGEXEXTRACT(CELL("address",P17), "\$([A-Z]+)\$[0-9]+"))),_xlfn.REGEXEXTRACT(CELL("address",P17), "\$([A-Z]+)\$[0-9]+"))} | Q17: {=IFERROR(IF(OR('Raw Data'!Q17="",LEN(TRIM('Raw Data'!Q17))=0),"",IF(AND(ISNUMBER('Raw Data'!Q17), IFERROR('Raw Data'!Q17 = ROUND('Raw Data'!Q17, 2),FALSE)),"",_xlfn.REGEXEXTRACT(CELL("address",Q17), "\$([A-Z]+)\$[0-9]+"))),_xlfn.REGEXEXTRACT(CELL("address",Q17), "\$([A-Z]+)\$[0-9]+"))} | R17: {=IFERROR(IF(OR('Raw Data'!R17="",LEN(TRIM('Raw Data'!R17))=0),"",IF(AND(ISNUMBER('Raw Data'!R17), IFERROR('Raw Data'!R17 = ROUND('Raw Data'!R17, 2),FALSE)),"",_xlfn.REGEXEXTRACT(CELL("address",R17), "\$([A-Z]+)\$[0-9]+"))),_xlfn.REGEXEXTRACT(CELL("address",R17), "\$([A-Z]+)\$[0-9]+"))} | ... V17: {=IFERROR(IF(OR('Raw Data'!V17="",LEN(TRIM('Raw Data'!V17))=0),"",IF(AND(ISNUMBER('Raw Data'!V17), IFERROR('Raw Data'!V17 = ROUND('Raw Data'!V17, 2),FALSE)),"",_xlfn.REGEXEXTRACT(CELL("address",V17), "\$([A-Z]+)\$[0-9]+"))),_xlfn.REGEXEXTRACT(CELL("address",V17), "\$([A-Z]+)\$[0-9]+"))}
