Workbook

Sheet Raw Data
B9: C1 | C9: C2 | D9: C3 | E9: C4 | F9: C5 | G9: C6 | H9: C7 | I9: C8 | J9: C9 | K9: C10 | L9: C11 | M9: C12 | N9: C13 | O9: C14 | P9: C15 | Q9: C16 | R9: C17 | S9: C18 | T9: C19 | U9: C20 | V9: C21 | W9: C22 | X9: C23 | Y9: C24 | Z9: C25 | AA9: C26 | AB9: C27 | AC9: C28 | AD9: C29
B10: QA001 | C10: Overall Project | D10: Summary | G10: 0 | H10: 0 | I10: 0 | J10: 0 | K10: 0 | L10: 0
B11: QA001 | C11: Overall Project | D11: Month # 1 | E11: 45536 | F11: 0.03 | G11: 0 | H11: 0 | I11: 0 | J11: 402109.02 | K11: 508493.02 | L11: 910602.04 | M11: 0 | N11: 0 | O11: 0 | P11: 0 | Q11: 0 | R11: 0 | S11: 0 | T11: 0 | U11: 0 | V11: 402109.02 | W11: 508493.02 | X11: 910602.04 | Y11: 0 | Z11: 0 | AA11: 0 | AB11: 0 | AC11: 0 | AD11: 0
B12: QA001 | C12: Overall Project | D12: Month # 2 | E12: 45566 | F12: 0.11 | G12: 0 | H12: 402109.02 | I12: 402109.02 | J12: 859171.26 | K12: 911124.69 | L12: 1770295.9 | M12: 0 | N12: 0 | O12: 0 | P12: 0 | Q12: 0 | R12: 0 | S12: 0 | T12: 402109.02 | U12: 402109.02 | V12: 1261280.3 | W12: 1419617.7 | X12: 2680898 | Y12: 0 | Z12: 0 | AA12: 0 | AB12: 0 | AC12: 0 | AD12: 0
B13: QA001 | C13: Overall Project | D13: Month # 3 | E13: 45597 | F13: 0.19 | G13: 0 | H13: 859171.26 | I13: 859171.26 | J13: -1261280.3 | K13: -1419617.7 | L13: -2680898 | M13: 0 | N13: 0 | O13: 0 | P13: 0 | Q13: 0 | R13: 0 | S13: 0 | T13: 1261280.3 | U13: 1261280.3 | V13: 0 | W13: 0 | X13: 0 | Y13: 0 | Z13: 0 | AA13: 0 | AB13: 0 | AC13: 0 | AD13: 0
B14: QA001 | C14: Overall Project | D14: Month # 4 | E14: 45627 | F14: 0.24 | G14: 0 | H14: 1400573.8 | I14: 1400573.8 | J14: 0 | K14: 0 | L14: 0 | M14: 0 | N14: 0 | O14: 0 | P14: 0 | Q14: 0 | R14: 0 | S14: 0 | T14: 2661854.1 | U14: 2661854.1 | V14: 0 | W14: 0 | X14: 0 | Y14: 0 | Z14: 0 | AA14: 0 | AB14: 0 | AC14: 0 | AD14: 0
B15: QA001 | C15: Overall Project | D15: Month # 5 | E15: 45658 | F15: 0.31 | G15: 0 | H15: 1582457.8 | I15: 1582457.8 | J15: 0 | K15: 0 | L15: 0 | M15: 0 | N15: 0 | O15: 0 | P15: 0 | Q15: 0 | R15: 0 | S15: 0 | T15: 4244311.9 | U15: 4244311.9 | V15: 0 | W15: 0 | X15: 0 | Y15: 0 | Z15: 0 | AA15: 0 | AB15: 0 | AC15: 0 | AD15: 0
B16: QA001 | C16: Overall Project | D16: Month # 6 | E16: 45689 | F16: 0.46 | G16: 0 | H16: 1453772.8 | I16: 1453772.8 | J16: 0 | K16: 0 | L16: 0 | M16: 0 | N16: 0 | O16: 0 | P16: 0 | Q16: 0 | R16: 0 | S16: 0 | T16: 5698084.7 | U16: 5698084.7 | V16: 0 | W16: 0 | X16: 0 | Y16: 0 | Z16: 0 | AA16: 0 | AB16: 0 | AC16: 0 | AD16: 0
B17: QA001 | C17: Overall Project | D17: Month # 7 | E17: 45717 | F17: 0.62 | G17: 0 | H17: 2080094.7 | I17: 2080094.7 | J17: 0 | K17: 0 | L17: 0 | M17: 0 | N17: 0 | O17: 0 | P17: 0 | Q17: 0 | R17: 0 | S17: 0 | T17: 7778179.4 | U17: 7778179.4 | V17: 0 | W17: 0 | X17: 0 | Y17: 0 | Z17: 0 | AA17: 0 | AB17: 0 | AC17: 0 | AD17: 0
B18: QA001 | C18: Overall Project | D18: Month # 8 | E18: 45748 | F18: 0.78 | G18: 0 | H18: 1558161.2 | I18: 1558161.2 | J18: 0 | K18: 0 | L18: 0 | M18: 0 | N18: 0 | O18: 0 | P18: 0 | Q18: 0 | R18: 0 | S18: 0 | T18: 9336340.6 | U18: 9336340.6 | V18: 0 | W18: 0 | X18: 0 | Y18: 0 | Z18: 0 | AA18: 0 | AB18: 0 | AC18: 0 | AD18: 0
B19: QA001 | C19: Overall Project | D19: Month # 9 | E19: 45778 | F19: 0.79 | G19: 0 | H19: 1467853.7 | I19: 1467853.7 | J19: 0 | K19: 0 | L19: 0 | M19: 0 | N19: 0 | O19: 0 | P19: 0 | Q19: 0 | R19: 0 | S19: 0 | T19: 10804194 | U19: 10804194 | V19: 0 | W19: 0 | X19: 0 | Y19: 0 | Z19: 0 | AA19: 0 | AB19: 0 | AC19: 0 | AD19: 0
B20: QA001 | C20: Overall Project | D20: Month # 10 | E20: 45809 | F20: 0.82 | G20: 0 | H20: 1035421.4 | I20: 1035421.4 | J20: 0 | K20: 0 | L20: 0 | M20: 0 | N20: 0 | O20: 0 | P20: 0 | Q20: 0 | R20: 0 | S20: 0 | T20: 11839616 | U20: 11839616 | V20: 0 | W20: 0 | X20: 0 | Y20: 0 | Z20: 0 | AA20: 0 | AB20: 0 | AC20: 0 | AD20: 0
B21: QA001 | C21: Overall Project | D21: Month # 11 | E21: 45839 | F21: 0.87 | G21: 0 | H21: 1358709.9 | I21: 1358709.9 | J21: 0 | K21: 0 | L21: 0 | M21: 0 | N21: 0 | O21: 0 | P21: 0 | Q21: 0 | R21: 0 | S21: 0 | T21: 13198326 | U21: 13198326 | V21: 0 | W21: 0 | X21: 0 | Y21: 0 | Z21: 0 | AA21: 0 | AB21: 0 | AC21: 0 | AD21: 0
B22: QA001 | C22: Overall Project | D22: Month # 12 | E22: 45870 | F22: 0.92 | G22: 0 | H22: 701573.75 | I22: 701573.75 | J22: 0 | K22: 0 | L22: 0 | M22: 0 | N22: 0 | O22: 0 | P22: 0 | Q22: 0 | R22: 0 | S22: 0 | T22: 13899899 | U22: 13899899 | V22: 0 | W22: 0 | X22: 0 | Y22: 0 | Z22: 0 | AA22: 0 | AB22: 0 | AC22: 0 | AD22: 0
... B28: QA001 | C28: Overall Project | D28: Month # 18 | E28: 46054 | F28: 1 | G28: 0 | H28: 75655.56 | I28: 75655.56 | J28: 0 | K28: 0 | L28: 0 | M28: 0 | N28: 0 | O28: 0 | P28: 0 | Q28: 0 | R28: 0 | S28: 0 | T28: 16926678 | U28: 16926678 | V28: 0 | W28: 0 | X28: 0 | Y28: 0 | Z28: 0 | AA28: 0 | AB28: 0 | AC28: 0 | AD28: 0
B29: QA001 | C29: Overall Project | D29: Month # 19 | E29: 46082 | F29: 1 | G29: 0 | H29: 0 | I29: 0 | J29: 0 | K29: 0 | L29: 0 | M29: 0 | N29: 0 | O29: 0 | P29: 0 | Q29: 0 | R29: 0 | S29: 0 | T29: 16926678 | U29: 16926678 | X29: 0 | Y29: 0 | Z29: 0 | AA29: 0 | AB29: 0 | AC29: 0 | AD29: 0
B30: QA001 | C30: Overall Project | D30: Month # 20 | E30: 46113 | F30: 1 | G30: 0 | H30: 0 | I30: 0 | J30: 0 | K30: 0 | L30: 0 | M30: 0 | N30: 0 | O30: 0 | P30: 0 | Q30: 0 | R30: 0 | S30: 0 | T30: 16926678 | U30: 16926678 | X30: 0 | Y30: 0 | Z30: 0 | AA30: 0 | AB30: 0 | AC30: 0 | AD30: 0
B31: QA001 | C31: Overall Project | D31: Month # 21 | E31: 46143 | F31: 1 | G31: 0 | H31: 0 | I31: 0 | J31: 0 | K31: 0 | L31: 0 | M31: 0 | N31: 0 | O31: 0 | P31: 0 | Q31: 0 | R31: 0 | S31: 0 | T31: 16926678 | U31: 16926678 | X31: 0 | Y31: 0 | Z31: 0 | AA31: 0 | AB31: 0 | AC31: 0 | AD31: 0
B32: QA001 | C32: Overall Project | D32: Month # 22 | E32: 46174 | F32: 1 | G32: 0 | H32: 0 | I32: 0 | J32: 0 | K32: 0 | L32: 0 | M32: 0 | N32: 0 | O32: 0 | P32: 0 | Q32: 0 | R32: 0 | S32: 0 | T32: 16926678 | U32: 16926678 | X32: 0 | Y32: 0 | Z32: 0 | AA32: 0 | AB32: 0 | AC32: 0 | AD32: 0
B33: QA001 | C33: Overall Project | D33: Month # 23 | E33: 46204 | F33: 1 | G33: 0 | H33: 0 | I33: 0 | J33: 0 | K33: 0 | L33: 0 | M33: 0 | N33: 0 | O33: 0 | P33: 0 | Q33: 0 | R33: 0 | S33: 0 | T33: 16926678 | U33: 16926678 | X33: 0 | Y33: 0 | Z33: 0 | AA33: 0 | AB33: 0 | AC33: 0 | AD33: 0
B34: QA001 | C34: Overall Project | D34: Month # 24 | E34: 46235 | F34: 1 | G34: 0 | H34: 0 | I34: 0 | J34: 0 | K34: 0 | L34: 0 | M34: 0 | N34: 0 | O34: 0 | P34: 0 | Q34: 0 | R34: 0 | S34: 0 | T34: 16926678 | U34: 16926678 | X34: 0 | Y34: 0 | Z34: 0 | AA34: 0 | AB34: 0 | AC34: 0 | AD34: 0
B35: QAE001 | C35: Engineering | D35: Summary | G35: 0 | H35: 3808634.7 | I35: 3808634.7 | J35: 0 | K35: 0 | L35: 0 | AA35: 0 | AD35: 0
B36: QAE001 | C36: Engineering | D36: Month # 1 | E36: 45536 | F36: 0.03 | G36: 0 | H36: 0 | I36: 0 | J36: 41258 | K36: 41258 | L36: 82516 | O36: 0 | R36: 0 | S36: 0 | T36: 0 | U36: 0 | V36: 41258 | W36: 41258 | X36: 82516 | AA36: 0 | AD36: 0
B37: QAE001 | C37: Engineering | D37: Month # 2 | E37: 45566 | F37: 0.42 | G37: 0 | H37: 41258 | I37: 41258 | J37: 302067.5 | K37: 329126 | L37: 631193.5 | O37: 0 | R37: 0 | S37: 0 | T37: 41258 | U37: 41258 | V37: 343325.5 | W37: 370384 | X37: 713709.5 | AA37: 0 | AD37: 0
B38: QAE001 | C38: Engineering | D38: Month # 3 | E38: 45597 | F38: 0.86 | G38: 0 | H38: 302067.5 | I38: 302067.5 | J38: -343325.5 | K38: -370384 | L38: -713709.5 | O38: 0 | R38: 0 | S38: 0 | T38: 343325.5 | U38: 343325.5 | V38: 0 | W38: 0 | X38: 0 | AA38: 0 | AD38: 0
B39: QAE001 | C39: Engineering | D39: Month # 4 | E39: 45627 | F39: 0.99 | G39: 0 | H39: 519025.64 | I39: 519025.64 | J39: 0 | K39: 0 | L39: 0 | O39: 0 | R39: 0 | S39: 0 | T39: 862351.14 | U39: 862351.14 | V39: 0 | W39: 0 | X39: 0 | AA39: 0 | AD39: 0
B40: QAE001 | C40: Engineering | D40: Month # 5 | E40: 45658 | F40: 1 | G40: 0 | H40: 667571.28 | I40: 667571.28 | J40: 0 | K40: 0 | L40: 0 | O40: 0 | R40: 0 | S40: 0 | T40: 1529922.4 | U40: 1529922.4 | V40: 0 | W40: 0 | X40: 0 | AA40: 0 | AD40: 0
B41: QAE001 | C41: Engineering | D41: Month # 6 | E41: 45689 | F41: 1 | G41: 0 | H41: 528070.25 | I41: 528070.25 | J41: 0 | K41: 0 | L41: 0 | O41: 0 | R41: 0 | S41: 0 | T41: 2057992.7 | U41: 2057992.7 | V41: 0 | W41: 0 | X41: 0 | AA41: 0 | AD41: 0
B42: QAE001 | C42: Engineering | D42: Month # 7 | E42: 45717 | F42: 1 | G42: 0 | H42: 760644.5 | I42: 760644.5 | J42: 0 | K42: 0 | L42: 0 | O42: 0 | R42: 0 | S42: 0 | T42: 2818637.2 | U42: 2818637.2 | V42: 0 | W42: 0 | X42: 0 | AA42: 0 | AD42: 0
B43: QAE001 | C43: Engineering | D43: Month # 8 | E43: 45748 | F43: 1 | G43: 0 | H43: 467442.03 | I43: 467442.03 | J43: 0 | K43: 0 | L43: 0 | O43: 0 | R43: 0 | S43: 0 | T43: 3286079.2 | U43: 3286079.2 | V43: 0 | W43: 0 | X43: 0 | AA43: 0 | AD43: 0
B44: QAE001 | C44: Engineering | D44: Month # 9 | E44: 45778 | F44: 1 | G44: 0 | H44: 111884.75 | I44: 111884.75 | J44: 0 | K44: 0 | L44: 0 | O44: 0 | R44: 0 | S44: 0 | T44: 3397964 | U44: 3397964 | V44: 0 | W44: 0 | X44: 0 | AA44: 0 | AD44: 0
B45: QAE001 | C45: Engineering | D45: Month # 10 | E45: 45809 | F45: 1 | G45: 0 | H45: 37581.25 | I45: 37581.25 | J45: 0 | K45: 0 | L45: 0 | O45: 0 | R45: 0 | S45: 0 | T45: 3435545.2 | U45: 3435545.2 | V45: 0 | W45: 0 | X45: 0 | AA45: 0 | AD45: 0
B46: QAE001 | C46: Engineering | D46: Month # 11 | E46: 45839 | F46: 1 | G46: 0 | H46: 91268.75 | I46: 91268.75 | J46: 0 | K46: 0 | L46: 0 | O46: 0 | R46: 0 | S46: 0 | T46: 3526814 | U46: 3526814 | V46: 0 | W46: 0 | X46: 0 | AA46: 0 | AD46: 0
B47: QAE001 | C47: Engineering | D47: Month # 12 | E47: 45870 | F47: 1 | G47: 0 | H47: 0 | I47: 0 | J47: 0 | K47: 0 | L47: 0 | O47: 0 | R47: 0 | S47: 0 | T47: 3526814 | U47: 3526814 | V47: 0 | W47: 0 | X47: 0 | AA47: 0 | AD47: 0
... B59: QAE001 | C59: Engineering | D59: Month # 24 | E59: 46235 | F59: 1 | G59: 0 | H59: 0 | I59: 0 | J59: 0 | K59: 0 | L59: 0 | O59: 0 | R59: 0 | S59: 0 | T59: 3808634.7 | U59: 3808634.7 | V59: 0 | W59: 0 | X59: 0 | AA59: 0 | AD59: 0
B60: QAP001 | C60: Procurement | D60: Summary | G60: 0 | H60: 1800963.2 | I60: 1800963.2 | J60: 0 | K60: 0 | L60: 0
B61: QAP001 | C61: Procurement | D61: Month # 1 | E61: 45536 | F61: 0 | G61: 0 | H61: 0 | I61: 0 | J61: 51665.62 | K61: 51665.62 | L61: 103331.24 | S61: 0 | T61: 0 | U61: 0 | V61: 51665.62 | W61: 51665.62 | X61: 103331.24
B62: QAP001 | C62: Procurement | D62: Month # 2 | E62: 45566 | F62: 0.2 | G62: 0 | H62: 51665.62 | I62: 51665.62 | J62: 225388.96 | K62: 225388.96 | L62: 450777.92 | O62: 0 | R62: 0 | S62: 0 | T62: 51665.62 | U62: 51665.62 | V62: 277054.58 | W62: 277054.58 | X62: 554109.16 | AA62: 0 | AD62: 0
B63: QAP001 | C63: Procurement | D63: Month # 3 | E63: 45597 | F63: 0.48 | G63: 0 | H63: 225388.96 | I63: 225388.96 | J63: -277054.58 | K63: -277054.58 | L63: -554109.16 | O63: 0 | R63: 0 | S63: 0 | T63: 277054.58 | U63: 277054.58 | V63: 0 | W63: 0 | X63: 0 | AA63: 0 | AD63: 0
B64: QAP001 | C64: Procurement | D64: Month # 4 | E64: 45627 | F64: 0.59 | G64: 0 | H64: 297870.17 | I64: 297870.17 | J64: 0 | K64: 0 | L64: 0 | O64: 0 | R64: 0 | S64: 0 | T64: 574924.75 | U64: 574924.75 | V64: 0 | W64: 0 | X64: 0 | AA64: 0 | AD64: 0
...

Sheet Validate_Empty
B8: TRUE | C8: TRUE | D8: FALSE | E8: FALSE | F8: FALSE | G8: FALSE | H8: FALSE | I8: FALSE | J8: FALSE | K8: FALSE | L8: FALSE | M8: FALSE | N8: FALSE | O8: FALSE | P8: FALSE | Q8: FALSE | R8: FALSE | S8: FALSE | T8: FALSE | U8: FALSE | V8: FALSE | W8: FALSE | X8: FALSE | Y8: FALSE | Z8: FALSE | AA8: FALSE | AB8: FALSE | AC8: FALSE | AD8: FALSE
B9: C1 | C9: C2 | D9: C3 | E9: C4 | F9: C5 | G9: C6 | H9: C7 | I9: C8 | J9: C9 | K9: C10 | L9: C11 | M9: C12 | N9: C13 | O9: C14 | P9: C15 | Q9: C16 | R9: C17 | S9: C18 | T9: C19 | U9: C20 | V9: C21 | W9: C22 | X9: C23 | Y9: C24 | Z9: C25 | AA9: C26 | AB9: C27 | AC9: C28 | AD9: C29
B10: {=IFERROR(IF(OR('Raw Data'!B10="",LEN(TRIM('Raw Data'!B10))=0),_xlfn.REGEXEXTRACT(CELL("address",'Raw Data'!B10),"\$([A-Z]+)\$[0-9]+"),""),"")} | C10: {=IFERROR(IF(OR('Raw Data'!C10="",LEN(TRIM('Raw Data'!C10))=0),_xlfn.REGEXEXTRACT(CELL("address",'Raw Data'!C10),"\$([A-Z]+)\$[0-9]+"),""),"")}
B11: {=IFERROR(IF(OR('Raw Data'!B11="",LEN(TRIM('Raw Data'!B11))=0),_xlfn.REGEXEXTRACT(CELL("address",'Raw Data'!B11),"\$([A-Z]+)\$[0-9]+"),""),"")} | C11: {=IFERROR(IF(OR('Raw Data'!C11="",LEN(TRIM('Raw Data'!C11))=0),_xlfn.REGEXEXTRACT(CELL("address",'Raw Data'!C11),"\$([A-Z]+)\$[0-9]+"),""),"")}
B12: {=IFERROR(IF(OR('Raw Data'!B12="",LEN(TRIM('Raw Data'!B12))=0),_xlfn.REGEXEXTRACT(CELL("address",'Raw Data'!B12),"\$([A-Z]+)\$[0-9]+"),""),"")} | C12: {=IFERROR(IF(OR('Raw Data'!C12="",LEN(TRIM('Raw Data'!C12))=0),_xlfn.REGEXEXTRACT(CELL("address",'Raw Data'!C12),"\$([A-Z]+)\$[0-9]+"),""),"")}
B13: {=IFERROR(IF(OR('Raw Data'!B13="",LEN(TRIM('Raw Data'!B13))=0),_xlfn.REGEXEXTRACT(CELL("address",'Raw Data'!B13),"\$([A-Z]+)\$[0-9]+"),""),"")} | C13: {=IFERROR(IF(OR('Raw Data'!C13="",LEN(TRIM('Raw Data'!C13))=0),_xlfn.REGEXEXTRACT(CELL("address",'Raw Data'!C13),"\$([A-Z]+)\$[0-9]+"),""),"")}
B14: {=IFERROR(IF(OR('Raw Data'!B14="",LEN(TRIM('Raw Data'!B14))=0),_xlfn.REGEXEXTRACT(CELL("address",'Raw Data'!B14),"\$([A-Z]+)\$[0-9]+"),""),"")} | C14: {=IFERROR(IF(OR('Raw Data'!C14="",LEN(TRIM('Raw Data'!C14))=0),_xlfn.REGEXEXTRACT(CELL("address",'Raw Data'!C14),"\$([A-Z]+)\$[0-9]+"),""),"")}
B15: {=IFERROR(IF(OR('Raw Data'!B15="",LEN(TRIM('Raw Data'!B15))=0),_xlfn.REGEXEXTRACT(CELL("address",'Raw Data'!B15),"\$([A-Z]+)\$[0-9]+"),""),"")} | C15: {=IFERROR(IF(OR('Raw Data'!C15="",LEN(TRIM('Raw Data'!C15))=0),_xlfn.REGEXEXTRACT(CELL("address",'Raw Data'!C15),"\$([A-Z]+)\$[0-9]+"),""),"")}
B16: {=IFERROR(IF(OR('Raw Data'!B16="",LEN(TRIM('Raw Data'!B16))=0),_xlfn.REGEXEXTRACT(CELL("address",'Raw Data'!B16),"\$([A-Z]+)\$[0-9]+"),""),"")} | C16: {=IFERROR(IF(OR('Raw Data'!C16="",LEN(TRIM('Raw Data'!C16))=0),_xlfn.REGEXEXTRACT(CELL("address",'Raw Data'!C16),"\$([A-Z]+)\$[0-9]+"),""),"")}
B17: {=IFERROR(IF(OR('Raw Data'!B17="",LEN(TRIM('Raw Data'!B17))=0),_xlfn.REGEXEXTRACT(CELL("address",'Raw Data'!B17),"\$([A-Z]+)\$[0-9]+"),""),"")} | C17: {=IFERROR(IF(OR('Raw Data'!C17="",LEN(TRIM('Raw Data'!C17))=0),_xlfn.REGEXEXTRACT(CELL("address",'Raw Data'!C17),"\$([A-Z]+)\$[0-9]+"),""),"")}
B18: {=IFERROR(IF(OR('Raw Data'!B18="",LEN(TRIM('Raw Data'!B18))=0),_xlfn.REGEXEXTRACT(CELL("address",'Raw Data'!B18),"\$([A-Z]+)\$[0-9]+"),""),"")} | C18: {=IFERROR(IF(OR('Raw Data'!C18="",LEN(TRIM('Raw Data'!C18))=0),_xlfn.REGEXEXTRACT(CELL("address",'Raw Data'!C18),"\$([A-Z]+)\$[0-9]+"),""),"")}
B19: {=IFERROR(IF(OR('Raw Data'!B19="",LEN(TRIM('Raw Data'!B19))=0),_xlfn.REGEXEXTRACT(CELL("address",'Raw Data'!B19),"\$([A-Z]+)\$[0-9]+"),""),"")} | C19: {=IFERROR(IF(OR('Raw Data'!C19="",LEN(TRIM('Raw Data'!C19))=0),_xlfn.REGEXEXTRACT(CELL("address",'Raw Data'!C19),"\$([A-Z]+)\$[0-9]+"),""),"")}
B20: {=IFERROR(IF(OR('Raw Data'!B20="",LEN(TRIM('Raw Data'!B20))=0),_xlfn.REGEXEXTRACT(CELL("address",'Raw Data'!B20),"\$([A-Z]+)\$[0-9]+"),""),"")} | C20: {=IFERROR(IF(OR('Raw Data'!C20="",LEN(TRIM('Raw Data'!C20))=0),_xlfn.REGEXEXTRACT(CELL("address",'Raw Data'!C20),"\$([A-Z]+)\$[0-9]+"),""),"")}
B21: {=IFERROR(IF(OR('Raw Data'!B21="",LEN(TRIM('Raw Data'!B21))=0),_xlfn.REGEXEXTRACT(CELL("address",'Raw Data'!B21),"\$([A-Z]+)\$[0-9]+"),""),"")} | C21: {=IFERROR(IF(OR('Raw Data'!C21="",LEN(TRIM('Raw Data'!C21))=0),_xlfn.REGEXEXTRACT(CELL("address",'Raw Data'!C21),"\$([A-Z]+)\$[0-9]+"),""),"")}
... B295: {=IFERROR(IF(OR('Raw Data'!B295="",LEN(TRIM('Raw Data'!B295))=0),_xlfn.REGEXEXTRACT(CELL("address",'Raw Data'!B295),"\$([A-Z]+)\$[0-9]+"),""),"")} -> $B$295 | C295: {=IFERROR(IF(OR('Raw Data'!C295="",LEN(TRIM('Raw Data'!C295))=0),_xlfn.REGEXEXTRACT(CELL("address",'Raw Data'!C295),"\$([A-Z]+)\$[0-9]+"),""),"")} -> $C$295

Sheet Validate_Value
B8: NVARCHAR(20) | C8: NVARCHAR(255) | D8: NVARCHAR(20) | E8: DATE | F8: DECIMAL(13,2) [Percentage] | G8: DECIMAL(13,2) | H8: DECIMAL(13,2) | I8: DECIMAL(13,2) | J8: DECIMAL(13,2) | K8: DECIMAL(13,2) | L8: DECIMAL(13,2) | M8: DECIMAL(13,2) | N8: DECIMAL(13,2) | O8: DECIMAL(13,2) | P8: DECIMAL(13,2) | Q8: DECIMAL(13,2) | R8: DECIMAL(13,2) | S8: DECIMAL(13,2) | T8: DECIMAL(13,2) | U8: DECIMAL(13,2) | V8: DECIMAL(13,2) | W8: DECIMAL(13,2) | X8: DECIMAL(13,2) | Y8: DECIMAL(13,2) | Z8: DECIMAL(13,2) | AA8: DECIMAL(13,2) | AB8: DECIMAL(13,2) | AC8: DECIMAL(13,2) | AD8: DECIMAL(13,2)
B9: C1 | C9: C2 | D9: C3 | E9: C4 | F9: C5 | G9: C6 | H9: C7 | I9: C8 | J9: C9 | K9: C10 | L9: C11 | M9: C12 | N9: C13 | O9: C14 | P9: C15 | Q9: C16 | R9: C17 | S9: C18 | T9: C19 | U9: C20 | V9: C21 | W9: C22 | X9: C23 | Y9: C24 | Z9: C25 | AA9: C26 | AB9: C27 | AC9: C28 | AD9: C29
B10: {=IFERROR(IF(OR('Raw Data'!B10="",LEN(TRIM('Raw Data'!B10))=0),"",IF(AND(LEN('Raw Data'!B10) <= 20,LEN('Raw Data'!B10)> 0),"",_xlfn.REGEXEXTRACT(CELL("address",'Raw Data'!B10),"\$([A-Z]+)\$[0-9]+"))),_xlfn.REGEXEXTRACT(CELL("address",'Raw Data'!B10),"\$([A-Z]+)\$[0-9]+"))} | C10: {=IFERROR(IF(OR('Raw Data'!C10="",LEN(TRIM('Raw Data'!C10))=0),"",IF(AND(LEN('Raw Data'!C10) <= 255,LEN('Raw Data'!C10)> 0),"",_xlfn.REGEXEXTRACT(CELL("address",'Raw Data'!C10),"\$([A-Z]+)\$[0-9]+"))),_xlfn.REGEXEXTRACT(CELL("address",'Raw Data'!C10),"\$([A-Z]+)\$[0-9]+"))} | D10: {=IFERROR(IF(OR('Raw Data'!D10="",LEN(TRIM('Raw Data'!D10))=0),"",IF(AND(LEN('Raw Data'!D10) <= 20,LEN('Raw Data'!D10)> 0),"",_xlfn.REGEXEXTRACT(CELL("address",'Raw Data'!D10),"\$([A-Z]+)\$[0-9]+"))),_xlfn.REGEXEXTRACT(CELL("address",'Raw Data'!D10),"\$([A-Z]+)\$[0-9]+"))} | E10: {=IFERROR(IF(OR('Raw Data'!E10="",LEN(TRIM('Raw Data'!E10))=0),"",IF(AND(ISNUMBER('Raw Data'!E10),'Raw Data'!E10>=Configuration!$D$2),"",_xlfn.REGEXEXTRACT(CELL("address",'Raw Data'!E10),"\$([A-Z]+)\$[0-9]+"))),_xlfn.REGEXEXTRACT(CELL("address",E10), "\$([A-Z]+)\$[0-9]+"))} | F10: {=IFERROR(IF(OR('Raw Data'!F10="",LEN(TRIM('Raw Data'!F10))=0),"",IF(AND(ISNUMBER('Raw Data'!F10), IFERROR('Raw Data'!F10 = ROUND('Raw Data'!F10, 4),FALSE)),"",_xlfn.REGEXEXTRACT(CELL("address",F10), "\$([A-Z]+)\$[0-9]+"))),_xlfn.REGEXEXTRACT(CELL("address",F10), "\$([A-Z]+)\$[0-9]+"))} | G10: {=IFERROR(IF(OR('Raw Data'!G10="",LEN(TRIM('Raw Data'!G10))=0),"",IF(AND(ISNUMBER('Raw Data'!G10), IFERROR('Raw Data'!G10 = ROUND('Raw Data'!G10, 2),FALSE)),"",_xlfn.REGEXEXTRACT(CELL("address",G10), "\$([A-Z]+)\$[0-9]+"))),_xlfn.REGEXEXTRACT(CELL("address",G10), "\$([A-Z]+)\$[0-9]+"))} | H10: {=IFERROR(IF(OR('Raw Data'!H10="",LEN(TRIM('Raw Data'!H10))=0),"",IF(AND(ISNUMBER('Raw Data'!H10), IFERROR('Raw Data'!H10 = ROUND('Raw Data'!H10, 2),FALSE)),"",_xlfn.REGEXEXTRACT(CELL("address",H10), "\$([A-Z]+)\$[0-9]+"))),_xlfn.REGEXEXTRACT(CELL("address",H10), "\$([A-Z]+)\$[0-9]+"))} | I10: {=IFERROR(IF(OR('Raw Data'!I10="",LEN(TRIM('Raw Data'!I10))=0),"",IF(AND(ISNUMBER('Raw Data'!I10), IFERROR('Raw Data'!I10 = ROUND('Raw Data'!I10, 2),FALSE)),"",_xlfn.REGEXEXTRACT(CELL("address",I10), "\$([A-Z]+)\$[0-9]+"))),_xlfn.REGEXEXTRACT(CELL("address",I10), "\$([A-Z]+)\$[0-9]+"))} | J10: {=IFERROR(IF(OR('Raw Data'!J10="",LEN(TRIM('Raw Data'!J10))=0),"",IF(AND(ISNUMBER('Raw Data'!J10), IFERROR('Raw Data'!J10 = ROUND('Raw Data'!J10, 2),FALSE)),"",_xlfn.REGEXEXTRACT(CELL("address",J10), "\$([A-Z]+)\$[0-9]+"))),_xlfn.REGEXEXTRACT(CELL("address",J10), "\$([A-Z]+)\$[0-9]+"))} | K10: {=IFERROR(IF(OR('Raw Data'!K10="",LEN(TRIM('Raw Data'!K10))=0),"",IF(AND(ISNUMBER('Raw Data'!K10), IFERROR('Raw Data'!K10 = ROUND('Raw Data'!K10, 2),FALSE)),"",_xlfn.REGEXEXTRACT(CELL("address",K10), "\$([A-Z]+)\$[0-9]+"))),_xlfn.REGEXEXTRACT(CELL("address",K10), "\$([A-Z]+)\$[0-9]+"))} | L10: {=IFERROR(IF(OR('Raw Data'!L10="",LEN(TRIM('Raw Data'!L10))=0),"",IF(AND(ISNUMBER('Raw Data'!L10), IFERROR('Raw Data'!L10 = ROUND('Raw Data'!L10, 2),FALSE)),"",_xlfn.REGEXEXTRACT(CELL("address",L10), "\$([A-Z]+)\$[0-9]+"))),_xlfn.REGEXEXTRACT(CELL("address",L10), "\$([A-Z]+)\$[0-9]+"))} | M10: {=IFERROR(IF(OR('Raw Data'!M10="",LEN(TRIM('Raw Data'!M10))=0),"",IF(AND(ISNUMBER('Raw Data'!M10), IFERROR('Raw Data'!M10 = ROUND('Raw Data'!M10, 2),FALSE)),"",_xlfn.REGEXEXTRACT(CELL("address",M10), "\$([A-Z]+)\$[0-9]+"))),_xlfn.REGEXEXTRACT(CELL("address",M10), "\$([A-Z]+)\$[0-9]+"))} | N10: {=IFERROR(IF(OR('Raw Data'!N10="",LEN(TRIM('Raw Data'!N10))=0),"",IF(AND(ISNUMBER('Raw Data'!N10), IFERROR('Raw Data'!N10 = ROUND('Raw Data'!N10, 2),FALSE)),"",_xlfn.REGEXEXTRACT(CELL("address",N10), "\$([A-Z]+)\$[0-9]+"))),_xlfn.REGEXEXTRACT(CELL("address",N10), "\$([A-Z]+)\$[0-9]+"))} | ... AD10: {=IFERROR(IF(OR('Raw Data'!AD10="",LEN(TRIM('Raw Data'!AD10))=0),"",IF(AND(ISNUMBER('Raw Data'!AD10), IFERROR('Raw Data'!AD10 = ROUND('Raw Data'!AD10, 2),FALSE)),"",_xlfn.REGEXEXTRACT(CELL("address",AD10), "\$([A-Z]+)\$[0-9]+"))),_xlfn.REGEXEXTRACT(CELL("address",AD10), "\$([A-Z]+)\$[0-9]+"))}
B11: {=IFERROR(IF(OR('Raw Data'!B11="",LEN(TRIM('Raw Data'!B11))=0),"",IF(AND(LEN('Raw Data'!B11) <= 20,LEN('Raw Data'!B11)> 0),"",_xlfn.REGEXEXTRACT(CELL("address",'Raw Data'!B11),"\$([A-Z]+)\$[0-9]+"))),_xlfn.REGEXEXTRACT(CELL("address",'Raw Data'!B11),"\$([A-Z]+)\$[0-9]+"))} | C11: {=IFERROR(IF(OR('Raw Data'!C11="",LEN(TRIM('Raw Data'!C11))=0),"",IF(AND(LEN('Raw Data'!C11) <= 255,LEN('Raw Data'!C11)> 0),"",_xlfn.REGEXEXTRACT(CELL("address",'Raw Data'!C11),"\$([A-Z]+)\$[0-9]+"))),_xlfn.REGEXEXTRACT(CELL("address",'Raw Data'!C11),"\$([A-Z]+)\$[0-9]+"))} | D11: {=IFERROR(IF(OR('Raw Data'!D11="",LEN(TRIM('Raw Data'!D11))=0),"",IF(AND(LEN('Raw Data'!D11) <= 20,LEN('Raw Data'!D11)> 0),"",_xlfn.REGEXEXTRACT(CELL("address",'Raw Data'!D11),"\$([A-Z]+)\$[0-9]+"))),_xlfn.REGEXEXTRACT(CELL("address",'Raw Data'!D11),"\$([A-Z]+)\$[0-9]+"))} | E11: {=IFERROR(IF(OR('Raw Data'!E11="",LEN(TRIM('Raw Data'!E11))=0),"",IF(AND(ISNUMBER('Raw Data'!E11),'Raw Data'!E11>=Configuration!$D$2),"",_xlfn.REGEXEXTRACT(CELL("address",'Raw Data'!E11),"\$([A-Z]+)\$[0-9]+"))),_xlfn.REGEXEXTRACT(CELL("address",E11), "\$([A-Z]+)\$[0-9]+"))} | F11: {=IFERROR(IF(OR('Raw Data'!F11="",LEN(TRIM('Raw Data'!F11))=0),"",IF(AND(ISNUMBER('Raw Data'!F11), IFERROR('Raw Data'!F11 = ROUND('Raw Data'!F11, 4),FALSE)),"",_xlfn.REGEXEXTRACT(CELL("address",F11), "\$([A-Z]+)\$[0-9]+"))),_xlfn.REGEXEXTRACT(CELL("address",F11), "\$([A-Z]+)\$[0-9]+"))} | G11: {=IFERROR(IF(OR('Raw Data'!G11="",LEN(TRIM('Raw Data'!G11))=0),"",IF(AND(ISNUMBER('Raw Data'!G11), IFERROR('Raw Data'!G11 = ROUND('Raw Data'!G11, 2),FALSE)),"",_xlfn.REGEXEXTRACT(CELL("address",G11), "\$([A-Z]+)\$[0-9]+"))),_xlfn.REGEXEXTRACT(CELL("address",G11), "\$([A-Z]+)\$[0-9]+"))} | H11: {=IFERROR(IF(OR('Raw Data'!H11="",LEN(TRIM('Raw Data'!H11))=0),"",IF(AND(ISNUMBER('Raw Data'!H11), IFERROR('Raw Data'!H11 = ROUND('Raw Data'!H11, 2),FALSE)),"",_xlfn.REGEXEXTRACT(CELL("address",H11), "\$([A-Z]+)\$[0-9]+"))),_xlfn.REGEXEXTRACT(CELL("address",H11), "\$([A-Z]+)\$[0-9]+"))} | I11: {=IFERROR(IF(OR('Raw Data'!I11="",LEN(TRIM('Raw Data'!I11))=0),"",IF(AND(ISNUMBER('Raw Data'!I11), IFERROR('Raw Data'!I11 = ROUND('Raw Data'!I11, 2),FALSE)),"",_xlfn.REGEXEXTRACT(CELL("address",I11), "\$([A-Z]+)\$[0-9]+"))),_xlfn.REGEXEXTRACT(CELL("address",I11), "\$([A-Z]+)\$[0-9]+"))} | J11: {=IFERROR(IF(OR('Raw Data'!J11="",LEN(TRIM('Raw Data'!J11))=0),"",IF(AND(ISNUMBER('Raw Data'!J11), IFERROR('Raw Data'!J11 = ROUND('Raw Data'!J11, 2),FALSE)),"",_xlfn.REGEXEXTRACT(CELL("address",J11), "\$([A-Z]+)\$[0-9]+"))),_xlfn.REGEXEXTRACT(CELL("address",J11), "\$([A-Z]+)\$[0-9]+"))} | K11: {=IFERROR(IF(OR('Raw Data'!K11="",LEN(TRIM('Raw Data'!K11))=0),"",IF(AND(ISNUMBER('Raw Data'!K11), IFERROR('Raw Data'!K11 = ROUND('Raw Data'!K11, 2),FALSE)),"",_xlfn.REGEXEXTRACT(CELL("address",K11), "\$([A-Z]+)\$[0-9]+"))),_xlfn.REGEXEXTRACT(CELL("address",K11), "\$([A-Z]+)\$[0-9]+"))} | L11: {=IFERROR(IF(OR('Raw Data'!L11="",LEN(TRIM('Raw Data'!L11))=0),"",IF(AND(ISNUMBER('Raw Data'!L11), IFERROR('Raw Data'!L11 = ROUND('Raw Data'!L11, 2),FALSE)),"",_xlfn.REGEXEXTRACT(CELL("address",L11), "\$([A-Z]+)\$[0-9]+"))),_xlfn.REGEXEXTRACT(CELL("address",L11), "\$([A-Z]+)\$[0-9]+"))} | M11: {=IFERROR(IF(OR('Raw Data'!M11="",LEN(TRIM('Raw Data'!M11))=0),"",IF(AND(ISNUMBER('Raw Data'!M11), IFERROR('Raw Data'!M11 = ROUND('Raw Data'!M11, 2),FALSE)),"",_xlfn.REGEXEXTRACT(CELL("address",M11), "\$([A-Z]+)\$[0-9]+"))),_xlfn.REGEXEXTRACT(CELL("address",M11), "\$([A-Z]+)\$[0-9]+"))} | N11: {=IFERROR(IF(OR('Raw Data'!N11="",LEN(TRIM('Raw Data'!N11))=0),"",IF(AND(ISNUMBER('Raw Data'!N11), IFERROR('Raw Data'!N11 = ROUND('Raw Data'!N11, 2),FALSE)),"",_xlfn.REGEXEXTRACT(CELL("address",N11), "\$([A-Z]+)\$[0-9]+"))),_xlfn.REGEXEXTRACT(CELL("address",N11), "\$([A-Z]+)\$[0-9]+"))} | ... AD11: {=IFERROR(IF(OR('Raw Data'!AD11="",LEN(TRIM('Raw Data'!AD11))=0),"",IF(AND(ISNUMBER('Raw Data'!AD11), IFERROR('Raw Data'!AD11 = ROUND('Raw Data'!AD11, 2),FALSE)),"",_xlfn.REGEXEXTRACT(CELL("address",AD11), "\$([A-Z]+)\$[0-9]+"))),_xlfn.REGEXEXTRACT(CELL("address",AD11), "\$([A-Z]+)\$[0-9]+"))}
B12: {=IFERROR(IF(OR('Raw Data'!B12="",LEN(TRIM('Raw Data'!B12))=0),"",IF(AND(LEN('Raw Data'!B12) <= 20,LEN('Raw Data'!B12)> 0),"",_xlfn.REGEXEXTRACT(CELL("address",'Raw Data'!B12),"\$([A-Z]+)\$[0-9]+"))),_xlfn.REGEXEXTRACT(CELL("address",'Raw Data'!B12),"\$([A-Z]+)\$[0-9]+"))} | C12: {=IFERROR(IF(OR('Raw Data'!C12="",LEN(TRIM('Raw Data'!C12))=0),"",IF(AND(LEN('Raw Data'!C12) <= 255,LEN('Raw Data'!C12)> 0),"",_xlfn.REGEXEXTRACT(CELL("address",'Raw Data'!C12),"\$([A-Z]+)\$[0-9]+"))),_xlfn.REGEXEXTRACT(CELL("address",'Raw Data'!C12),"\$([A-Z]+)\$[0-9]+"))} | D12: {=IFERROR(IF(OR('Raw Data'!D12="",LEN(TRIM('Raw Data'!D12))=0),"",IF(AND(LEN('Raw Data'!D12) <= 20,LEN('Raw Data'!D12)> 0),"",_xlfn.REGEXEXTRACT(CELL("address",'Raw Data'!D12),"\$([A-Z]+)\$[0-9]+"))),_xlfn.REGEXEXTRACT(CELL("address",'Raw Data'!D12),"\$([A-Z]+)\$[0-9]+"))} | E12: {=IFERROR(IF(OR('Raw Data'!E12="",LEN(TRIM('Raw Data'!E12))=0),"",IF(AND(ISNUMBER('Raw Data'!E12),'Raw Data'!E12>=Configuration!$D$2),"",_xlfn.REGEXEXTRACT(CELL("address",'Raw Data'!E12),"\$([A-Z]+)\$[0-9]+"))),_xlfn.REGEXEXTRACT(CELL("address",E12), "\$([A-Z]+)\$[0-9]+"))} | F12: {=IFERROR(IF(OR('Raw Data'!F12="",LEN(TRIM('Raw Data'!F12))=0),"",IF(AND(ISNUMBER('Raw Data'!F12), IFERROR('Raw Data'!F12 = ROUND('Raw Data'!F12, 4),FALSE)),"",_xlfn.REGEXEXTRACT(CELL("address",F12), "\$([A-Z]+)\$[0-9]+"))),_xlfn.REGEXEXTRACT(CELL("address",F12), "\$([A-Z]+)\$[0-9]+"))} | G12: {=IFERROR(IF(OR('Raw Data'!G12="",LEN(TRIM('Raw Data'!G12))=0),"",IF(AND(ISNUMBER('Raw Data'!G12), IFERROR('Raw Data'!G12 = ROUND('Raw Data'!G12, 2),FALSE)),"",_xlfn.REGEXEXTRACT(CELL("address",G12), "\$([A-Z]+)\$[0-9]+"))),_xlfn.REGEXEXTRACT(CELL("address",G12), "\$([A-Z]+)\$[0-9]+"))} | H12: {=IFERROR(IF(OR('Raw Data'!H12="",LEN(TRIM('Raw Data'!H12))=0),"",IF(AND(ISNUMBER('Raw Data'!H12), IFERROR('Raw Data'!H12 = ROUND('Raw Data'!H12, 2),FALSE)),"",_xlfn.REGEXEXTRACT(CELL("address",H12), "\$([A-Z]+)\$[0-9]+"))),_xlfn.REGEXEXTRACT(CELL("address",H12), "\$([A-Z]+)\$[0-9]+"))} | I12: {=IFERROR(IF(OR('Raw Data'!I12="",LEN(TRIM('Raw Data'!I12))=0),"",IF(AND(ISNUMBER('Raw Data'!I12), IFERROR('Raw Data'!I12 = ROUND('Raw Data'!I12, 2),FALSE)),"",_xlfn.REGEXEXTRACT(CELL("address",I12), "\$([A-Z]+)\$[0-9]+"))),_xlfn.REGEXEXTRACT(CELL("address",I12), "\$([A-Z]+)\$[0-9]+"))} | J12: {=IFERROR(IF(OR('Raw Data'!J12="",LEN(TRIM('Raw Data'!J12))=0),"",IF(AND(ISNUMBER('Raw Data'!J12), IFERROR('Raw Data'!J12 = ROUND('Raw Data'!J12, 2),FALSE)),"",_xlfn.REGEXEXTRACT(CELL("address",J12), "\$([A-Z]+)\$[0-9]+"))),_xlfn.REGEXEXTRACT(CELL("address",J12), "\$([A-Z]+)\$[0-9]+"))} | K12: {=IFERROR(IF(OR('Raw Data'!K12="",LEN(TRIM('Raw Data'!K12))=0),"",IF(AND(ISNUMBER('Raw Data'!K12), IFERROR('Raw Data'!K12 = ROUND('Raw Data'!K12, 2),FALSE)),"",_xlfn.REGEXEXTRACT(CELL("address",K12), "\$([A-Z]+)\$[0-9]+"))),_xlfn.REGEXEXTRACT(CELL("address",K12), "\$([A-Z]+)\$[0-9]+"))} | L12: {=IFERROR(IF(OR('Raw Data'!L12="",LEN(TRIM('Raw Data'!L12))=0),"",IF(AND(ISNUMBER('Raw Data'!L12), IFERROR('Raw Data'!L12 = ROUND('Raw Data'!L12, 2),FALSE)),"",_xlfn.REGEXEXTRACT(CELL("address",L12), "\$([A-Z]+)\$[0-9]+"))),_xlfn.REGEXEXTRACT(CELL("address",L12), "\$([A-Z]+)\$[0-9]+"))} | M12: {=IFERROR(IF(OR('Raw Data'!M12="",LEN(TRIM('Raw Data'!M12))=0),"",IF(AND(ISNUMBER('Raw Data'!M12), IFERROR('Raw Data'!M12 = ROUND('Raw Data'!M12, 2),FALSE)),"",_xlfn.REGEXEXTRACT(CELL("address",M12), "\$([A-Z]+)\$[0-9]+"))),_xlfn.REGEXEXTRACT(CELL("address",M12), "\$([A-Z]+)\$[0-9]+"))} | N12: {=IFERROR(IF(OR('Raw Data'!N12="",LEN(TRIM('Raw Data'!N12))=0),"",IF(AND(ISNUMBER('Raw Data'!N12), IFERROR('Raw Data'!N12 = ROUND('Raw Data'!N12, 2),FALSE)),"",_xlfn.REGEXEXTRACT(CELL("address",N12), "\$([A-Z]+)\$[0-9]+"))),_xlfn.REGEXEXTRACT(CELL("address",N12), "\$([A-Z]+)\$[0-9]+"))} | ... AD12: {=IFERROR(IF(OR('Raw Data'!AD12="",LEN(TRIM('Raw Data'!AD12))=0),"",IF(AND(ISNUMBER('Raw Data'!AD12), IFERROR('Raw Data'!AD12 = ROUND('Raw Data'!AD12, 2),FALSE)),"",_xlfn.REGEXEXTRACT(CELL("address",AD12), "\$([A-Z]+)\$[0-9]+"))),_xlfn.REGEXEXTRACT(CELL("address",AD12), "\$([A-Z]+)\$[0-9]+"))}
B13: {=IFERROR(IF(OR('Raw Data'!B13="",LEN(TRIM('Raw Data'!B13))=0),"",IF(AND(LEN('Raw Data'!B13) <= 20,LEN('Raw Data'!B13)> 0),"",_xlfn.REGEXEXTRACT(CELL("address",'Raw Data'!B13),"\$([A-Z]+)\$[0-9]+"))),_xlfn.REGEXEXTRACT(CELL("address",'Raw Data'!B13),"\$([A-Z]+)\$[0-9]+"))} | C13: {=IFERROR(IF(OR('Raw Data'!C13="",LEN(TRIM('Raw Data'!C13))=0),"",IF(AND(LEN('Raw Data'!C13) <= 255,LEN('Raw Data'!C13)> 0),"",_xlfn.REGEXEXTRACT(CELL("address",'Raw Data'!C13),"\$([A-Z]+)\$[0-9]+"))),_xlfn.REGEXEXTRACT(CELL("address",'Raw Data'!C13),"\$([A-Z]+)\$[0-9]+"))} | D13: {=IFERROR(IF(OR('Raw Data'!D13="",LEN(TRIM('Raw Data'!D13))=0),"",IF(AND(LEN('Raw Data'!D13) <= 20,LEN('Raw Data'!D13)> 0),"",_xlfn.REGEXEXTRACT(CELL("address",'Raw Data'!D13),"\$([A-Z]+)\$[0-9]+"))),_xlfn.REGEXEXTRACT(CELL("address",'Raw Data'!D13),"\$([A-Z]+)\$[0-9]+"))} | E13: {=IFERROR(IF(OR('Raw Data'!E13="",LEN(TRIM('Raw Data'!E13))=0),"",IF(AND(ISNUMBER('Raw Data'!E13),'Raw Data'!E13>=Configuration!$D$2),"",_xlfn.REGEXEXTRACT(CELL("address",'Raw Data'!E13),"\$([A-Z]+)\$[0-9]+"))),_xlfn.REGEXEXTRACT(CELL("address",E13), "\$([A-Z]+)\$[0-9]+"))} | F13: {=IFERROR(IF(OR('Raw Data'!F13="",LEN(TRIM('Raw Data'!F13))=0),"",IF(AND(ISNUMBER('Raw Data'!F13), IFERROR('Raw Data'!F13 = ROUND('Raw Data'!F13, 4),FALSE)),"",_xlfn.REGEXEXTRACT(CELL("address",F13), "\$([A-Z]+)\$[0-9]+"))),_xlfn.REGEXEXTRACT(CELL("address",F13), "\$([A-Z]+)\$[0-9]+"))} | G13: {=IFERROR(IF(OR('Raw Data'!G13="",LEN(TRIM('Raw Data'!G13))=0),"",IF(AND(ISNUMBER('Raw Data'!G13), IFERROR('Raw Data'!G13 = ROUND('Raw Data'!G13, 2),FALSE)),"",_xlfn.REGEXEXTRACT(CELL("address",G13), "\$([A-Z]+)\$[0-9]+"))),_xlfn.REGEXEXTRACT(CELL("address",G13), "\$([A-Z]+)\$[0-9]+"))} | H13: {=IFERROR(IF(OR('Raw Data'!H13="",LEN(TRIM('Raw Data'!H13))=0),"",IF(AND(ISNUMBER('Raw Data'!H13), IFERROR('Raw Data'!H13 = ROUND('Raw Data'!H13, 2),FALSE)),"",_xlfn.REGEXEXTRACT(CELL("address",H13), "\$([A-Z]+)\$[0-9]+"))),_xlfn.REGEXEXTRACT(CELL("address",H13), "\$([A-Z]+)\$[0-9]+"))} | I13: {=IFERROR(IF(OR('Raw Data'!I13="",LEN(TRIM('Raw Data'!I13))=0),"",IF(AND(ISNUMBER('Raw Data'!I13), IFERROR('Raw Data'!I13 = ROUND('Raw Data'!I13, 2),FALSE)),"",_xlfn.REGEXEXTRACT(CELL("address",I13), "\$([A-Z]+)\$[0-9]+"))),_xlfn.REGEXEXTRACT(CELL("address",I13), "\$([A-Z]+)\$[0-9]+"))} | J13: {=IFERROR(IF(OR('Raw Data'!J13="",LEN(TRIM('Raw Data'!J13))=0),"",IF(AND(ISNUMBER('Raw Data'!J13), IFERROR('Raw Data'!J13 = ROUND('Raw Data'!J13, 2),FALSE)),"",_xlfn.REGEXEXTRACT(CELL("address",J13), "\$([A-Z]+)\$[0-9]+"))),_xlfn.REGEXEXTRACT(CELL("address",J13), "\$([A-Z]+)\$[0-9]+"))} | K13: {=IFERROR(IF(OR('Raw Data'!K13="",LEN(TRIM('Raw Data'!K13))=0),"",IF(AND(ISNUMBER('Raw Data'!K13), IFERROR('Raw Data'!K13 = ROUND('Raw Data'!K13, 2),FALSE)),"",_xlfn.REGEXEXTRACT(CELL("address",K13), "\$([A-Z]+)\$[0-9]+"))),_xlfn.REGEXEXTRACT(CELL("address",K13), "\$([A-Z]+)\$[0-9]+"))} | L13: {=IFERROR(IF(OR('Raw Data'!L13="",LEN(TRIM('Raw Data'!L13))=0),"",IF(AND(ISNUMBER('Raw Data'!L13), IFERROR('Raw Data'!L13 = ROUND('Raw Data'!L13, 2),FALSE)),"",_xlfn.REGEXEXTRACT(CELL("address",L13), "\$([A-Z]+)\$[0-9]+"))),_xlfn.REGEXEXTRACT(CELL("address",L13), "\$([A-Z]+)\$[0-9]+"))} | M13: {=IFERROR(IF(OR('Raw Data'!M13="",LEN(TRIM('Raw Data'!M13))=0),"",IF(AND(ISNUMBER('Raw Data'!M13), IFERROR('Raw Data'!M13 = ROUND('Raw Data'!M13, 2),FALSE)),"",_xlfn.REGEXEXTRACT(CELL("address",M13), "\$([A-Z]+)\$[0-9]+"))),_xlfn.REGEXEXTRACT(CELL("address",M13), "\$([A-Z]+)\$[0-9]+"))} | N13: {=IFERROR(IF(OR('Raw Data'!N13="",LEN(TRIM('Raw Data'!N13))=0),"",IF(AND(ISNUMBER('Raw Data'!N13), IFERROR('Raw Data'!N13 = ROUND('Raw Data'!N13, 2),FALSE)),"",_xlfn.REGEXEXTRACT(CELL("address",N13), "\$([A-Z]+)\$[0-9]+"))),_xlfn.REGEXEXTRACT(CELL("address",N13), "\$([A-Z]+)\$[0-9]+"))} | ... AD13: {=IFERROR(IF(OR('Raw Data'!AD13="",LEN(TRIM('Raw Data'!AD13))=0),"",IF(AND(ISNUMBER('Raw Data'!AD13), IFERROR('Raw Data'!AD13 = ROUND('Raw Data'!AD13, 2),FALSE)),"",_xlfn.REGEXEXTRACT(CELL("address",AD13), "\$([A-Z]+)\$[0-9]+"))),_xlfn.REGEXEXTRACT(CELL("address",AD13), "\$([A-Z]+)\$[0-9]+"))}
B14: {=IFERROR(IF(OR('Raw Data'!B14="",LEN(TRIM('Raw Data'!B14))=0),"",IF(AND(LEN('Raw Data'!B14) <= 20,LEN('Raw Data'!B14)> 0),"",_xlfn.REGEXEXTRACT(CELL("address",'Raw Data'!B14),"\$([A-Z]+)\$[0-9]+"))),_xlfn.REGEXEXTRACT(CELL("address",'Raw Data'!B14),"\$([A-Z]+)\$[0-9]+"))} | C14: {=IFERROR(IF(OR('Raw Data'!C14="",LEN(TRIM('Raw Data'!C14))=0),"",IF(AND(LEN('Raw Data'!C14) <= 255,LEN('Raw Data'!C14)> 0),"",_xlfn.REGEXEXTRACT(CELL("address",'Raw Data'!C14),"\$([A-Z]+)\$[0-9]+"))),_xlfn.REGEXEXTRACT(CELL("address",'Raw Data'!C14),"\$([A-Z]+)\$[0-9]+"))} | D14: {=IFERROR(IF(OR('Raw Data'!D14="",LEN(TRIM('Raw Data'!D14))=0),"",IF(AND(LEN('Raw Data'!D14) <= 20,LEN('Raw Data'!D14)> 0),"",_xlfn.REGEXEXTRACT(CELL("address",'Raw Data'!D14),"\$([A-Z]+)\$[0-9]+"))),_xlfn.REGEXEXTRACT(CELL("address",'Raw Data'!D14),"\$([A-Z]+)\$[0-9]+"))} | E14: {=IFERROR(IF(OR('Raw Data'!E14="",LEN(TRIM('Raw Data'!E14))=0),"",IF(AND(ISNUMBER('Raw Data'!E14),'Raw Data'!E14>=Configuration!$D$2),"",_xlfn.REGEXEXTRACT(CELL("address",'Raw Data'!E14),"\$([A-Z]+)\$[0-9]+"))),_xlfn.REGEXEXTRACT(CELL("address",E14), "\$([A-Z]+)\$[0-9]+"))} | F14: {=IFERROR(IF(OR('Raw Data'!F14="",LEN(TRIM('Raw Data'!F14))=0),"",IF(AND(ISNUMBER('Raw Data'!F14), IFERROR('Raw Data'!F14 = ROUND('Raw Data'!F14, 4),FALSE)),"",_xlfn.REGEXEXTRACT(CELL("address",F14), "\$([A-Z]+)\$[0-9]+"))),_xlfn.REGEXEXTRACT(CELL("address",F14), "\$([A-Z]+)\$[0-9]+"))} | G14: {=IFERROR(IF(OR('Raw Data'!G14="",LEN(TRIM('Raw Data'!G14))=0),"",IF(AND(ISNUMBER('Raw Data'!G14), IFERROR('Raw Data'!G14 = ROUND('Raw Data'!G14, 2),FALSE)),"",_xlfn.REGEXEXTRACT(CELL("address",G14), "\$([A-Z]+)\$[0-9]+"))),_xlfn.REGEXEXTRACT(CELL("address",G14), "\$([A-Z]+)\$[0-9]+"))} | H14: {=IFERROR(IF(OR('Raw Data'!H14="",LEN(TRIM('Raw Data'!H14))=0),"",IF(AND(ISNUMBER('Raw Data'!H14), IFERROR('Raw Data'!H14 = ROUND('Raw Data'!H14, 2),FALSE)),"",_xlfn.REGEXEXTRACT(CELL("address",H14), "\$([A-Z]+)\$[0-9]+"))),_xlfn.REGEXEXTRACT(CELL("address",H14), "\$([A-Z]+)\$[0-9]+"))} | I14: {=IFERROR(IF(OR('Raw Data'!I14="",LEN(TRIM('Raw Data'!I14))=0),"",IF(AND(ISNUMBER('Raw Data'!I14), IFERROR('Raw Data'!I14 = ROUND('Raw Data'!I14, 2),FALSE)),"",_xlfn.REGEXEXTRACT(CELL("address",I14), "\$([A-Z]+)\$[0-9]+"))),_xlfn.REGEXEXTRACT(CELL("address",I14), "\$([A-Z]+)\$[0-9]+"))} | J14: {=IFERROR(IF(OR('Raw Data'!J14="",LEN(TRIM('Raw Data'!J14))=0),"",IF(AND(ISNUMBER('Raw Data'!J14), IFERROR('Raw Data'!J14 = ROUND('Raw Data'!J14, 2),FALSE)),"",_xlfn.REGEXEXTRACT(CELL("address",J14), "\$([A-Z]+)\$[0-9]+"))),_xlfn.REGEXEXTRACT(CELL("address",J14), "\$([A-Z]+)\$[0-9]+"))} | K14: {=IFERROR(IF(OR('Raw Data'!K14="",LEN(TRIM('Raw Data'!K14))=0),"",IF(AND(ISNUMBER('Raw Data'!K14), IFERROR('Raw Data'!K14 = ROUND('Raw Data'!K14, 2),FALSE)),"",_xlfn.REGEXEXTRACT(CELL("address",K14), "\$([A-Z]+)\$[0-9]+"))),_xlfn.REGEXEXTRACT(CELL("address",K14), "\$([A-Z]+)\$[0-9]+"))} | L14: {=IFERROR(IF(OR('Raw Data'!L14="",LEN(TRIM('Raw Data'!L14))=0),"",IF(AND(ISNUMBER('Raw Data'!L14), IFERROR('Raw Data'!L14 = ROUND('Raw Data'!L14, 2),FALSE)),"",_xlfn.REGEXEXTRACT(CELL("address",L14), "\$([A-Z]+)\$[0-9]+"))),_xlfn.REGEXEXTRACT(CELL("address",L14), "\$([A-Z]+)\$[0-9]+"))} | M14: {=IFERROR(IF(OR('Raw Data'!M14="",LEN(TRIM('Raw Data'!M14))=0),"",IF(AND(ISNUMBER('Raw Data'!M14), IFERROR('Raw Data'!M14 = ROUND('Raw Data'!M14, 2),FALSE)),"",_xlfn.REGEXEXTRACT(CELL("address",M14), "\$([A-Z]+)\$[0-9]+"))),_xlfn.REGEXEXTRACT(CELL("address",M14), "\$([A-Z]+)\$[0-9]+"))} | N14: {=IFERROR(IF(OR('Raw Data'!N14="",LEN(TRIM('Raw Data'!N14))=0),"",IF(AND(ISNUMBER('Raw Data'!N14), IFERROR('Raw Data'!N14 = ROUND('Raw Data'!N14, 2),FALSE)),"",_xlfn.REGEXEXTRACT(CELL("address",N14), "\$([A-Z]+)\$[0-9]+"))),_xlfn.REGEXEXTRACT(CELL("address",N14), "\$([A-Z]+)\$[0-9]+"))} | ... AD14: {=IFERROR(IF(OR('Raw Data'!AD14="",LEN(TRIM('Raw Data'!AD14))=0),"",IF(AND(ISNUMBER('Raw Data'!AD14), IFERROR('Raw Data'!AD14 = ROUND('Raw Data'!AD14, 2),FALSE)),"",_xlfn.REGEXEXTRACT(CELL("address",AD14), "\$([A-Z]+)\$[0-9]+"))),_xlfn.REGEXEXTRACT(CELL("address",AD14), "\$([A-Z]+)\$[0-9]+"))}
B15: {=IFERROR(IF(OR('Raw Data'!B15="",LEN(TRIM('Raw Data'!B15))=0),"",IF(AND(LEN('Raw Data'!B15) <= 20,LEN('Raw Data'!B15)> 0),"",_xlfn.REGEXEXTRACT(CELL("address",'Raw Data'!B15),"\$([A-Z]+)\$[0-9]+"))),_xlfn.REGEXEXTRACT(CELL("address",'Raw Data'!B15),"\$([A-Z]+)\$[0-9]+"))} | C15: {=IFERROR(IF(OR('Raw Data'!C15="",LEN(TRIM('Raw Data'!C15))=0),"",IF(AND(LEN('Raw Data'!C15) <= 255,LEN('Raw Data'!C15)> 0),"",_xlfn.REGEXEXTRACT(CELL("address",'Raw Data'!C15),"\$([A-Z]+)\$[0-9]+"))),_xlfn.REGEXEXTRACT(CELL("address",'Raw Data'!C15),"\$([A-Z]+)\$[0-9]+"))} | D15: {=IFERROR(IF(OR('Raw Data'!D15="",LEN(TRIM('Raw Data'!D15))=0),"",IF(AND(LEN('Raw Data'!D15) <= 20,LEN('Raw Data'!D15)> 0),"",_xlfn.REGEXEXTRACT(CELL("address",'Raw Data'!D15),"\$([A-Z]+)\$[0-9]+"))),_xlfn.REGEXEXTRACT(CELL("address",'Raw Data'!D15),"\$([A-Z]+)\$[0-9]+"))} | E15: {=IFERROR(IF(OR('Raw Data'!E15="",LEN(TRIM('Raw Data'!E15))=0),"",IF(AND(ISNUMBER('Raw Data'!E15),'Raw Data'!E15>=Configuration!$D$2),"",_xlfn.REGEXEXTRACT(CELL("address",'Raw Data'!E15),"\$([A-Z]+)\$[0-9]+"))),_xlfn.REGEXEXTRACT(CELL("address",E15), "\$([A-Z]+)\$[0-9]+"))} | F15: {=IFERROR(IF(OR('Raw Data'!F15="",LEN(TRIM('Raw Data'!F15))=0),"",IF(AND(ISNUMBER('Raw Data'!F15), IFERROR('Raw Data'!F15 = ROUND('Raw Data'!F15, 4),FALSE)),"",_xlfn.REGEXEXTRACT(CELL("address",F15), "\$([A-Z]+)\$[0-9]+"))),_xlfn.REGEXEXTRACT(CELL("address",F15), "\$([A-Z]+)\$[0-9]+"))} | G15: {=IFERROR(IF(OR('Raw Data'!G15="",LEN(TRIM('Raw Data'!G15))=0),"",IF(AND(ISNUMBER('Raw Data'!G15), IFERROR('Raw Data'!G15 = ROUND('Raw Data'!G15, 2),FALSE)),"",_xlfn.REGEXEXTRACT(CELL("address",G15), "\$([A-Z]+)\$[0-9]+"))),_xlfn.REGEXEXTRACT(CELL("address",G15), "\$([A-Z]+)\$[0-9]+"))} | H15: {=IFERROR(IF(OR('Raw Data'!H15="",LEN(TRIM('Raw Data'!H15))=0),"",IF(AND(ISNUMBER('Raw Data'!H15), IFERROR('Raw Data'!H15 = ROUND('Raw Data'!H15, 2),FALSE)),"",_xlfn.REGEXEXTRACT(CELL("address",H15), "\$([A-Z]+)\$[0-9]+"))),_xlfn.REGEXEXTRACT(CELL("address",H15), "\$([A-Z]+)\$[0-9]+"))} | I15: {=IFERROR(IF(OR('Raw Data'!I15="",LEN(TRIM('Raw Data'!I15))=0),"",IF(AND(ISNUMBER('Raw Data'!I15), IFERROR('Raw Data'!I15 = ROUND('Raw Data'!I15, 2),FALSE)),"",_xlfn.REGEXEXTRACT(CELL("address",I15), "\$([A-Z]+)\$[0-9]+"))),_xlfn.REGEXEXTRACT(CELL("address",I15), "\$([A-Z]+)\$[0-9]+"))} | J15: {=IFERROR(IF(OR('Raw Data'!J15="",LEN(TRIM('Raw Data'!J15))=0),"",IF(AND(ISNUMBER('Raw Data'!J15), IFERROR('Raw Data'!J15 = ROUND('Raw Data'!J15, 2),FALSE)),"",_xlfn.REGEXEXTRACT(CELL("address",J15), "\$([A-Z]+)\$[0-9]+"))),_xlfn.REGEXEXTRACT(CELL("address",J15), "\$([A-Z]+)\$[0-9]+"))} | K15: {=IFERROR(IF(OR('Raw Data'!K15="",LEN(TRIM('Raw Data'!K15))=0),"",IF(AND(ISNUMBER('Raw Data'!K15), IFERROR('Raw Data'!K15 = ROUND('Raw Data'!K15, 2),FALSE)),"",_xlfn.REGEXEXTRACT(CELL("address",K15), "\$([A-Z]+)\$[0-9]+"))),_xlfn.REGEXEXTRACT(CELL("address",K15), "\$([A-Z]+)\$[0-9]+"))} | L15: {=IFERROR(IF(OR('Raw Data'!L15="",LEN(TRIM('Raw Data'!L15))=0),"",IF(AND(ISNUMBER('Raw Data'!L15), IFERROR('Raw Data'!L15 = ROUND('Raw Data'!L15, 2),FALSE)),"",_xlfn.REGEXEXTRACT(CELL("address",L15), "\$([A-Z]+)\$[0-9]+"))),_xlfn.REGEXEXTRACT(CELL("address",L15), "\$([A-Z]+)\$[0-9]+"))} | M15: {=IFERROR(IF(OR('Raw Data'!M15="",LEN(TRIM('Raw Data'!M15))=0),"",IF(AND(ISNUMBER('Raw Data'!M15), IFERROR('Raw Data'!M15 = ROUND('Raw Data'!M15, 2),FALSE)),"",_xlfn.REGEXEXTRACT(CELL("address",M15), "\$([A-Z]+)\$[0-9]+"))),_xlfn.REGEXEXTRACT(CELL("address",M15), "\$([A-Z]+)\$[0-9]+"))} | N15: {=IFERROR(IF(OR('Raw Data'!N15="",LEN(TRIM('Raw Data'!N15))=0),"",IF(AND(ISNUMBER('Raw Data'!N15), IFERROR('Raw Data'!N15 = ROUND('Raw Data'!N15, 2),FALSE)),"",_xlfn.REGEXEXTRACT(CELL("address",N15), "\$([A-Z]+)\$[0-9]+"))),_xlfn.REGEXEXTRACT(CELL("address",N15), "\$([A-Z]+)\$[0-9]+"))} | ... AD15: {=IFERROR(IF(OR('Raw Data'!AD15="",LEN(TRIM('Raw Data'!AD15))=0),"",IF(AND(ISNUMBER('Raw Data'!AD15), IFERROR('Raw Data'!AD15 = ROUND('Raw Data'!AD15, 2),FALSE)),"",_xlfn.REGEXEXTRACT(CELL("address",AD15), "\$([A-Z]+)\$[0-9]+"))),_xlfn.REGEXEXTRACT(CELL("address",AD15), "\$([A-Z]+)\$[0-9]+"))}
B16: {=IFERROR(IF(OR('Raw Data'!B16="",LEN(TRIM('Raw Data'!B16))=0),"",IF(AND(LEN('Raw Data'!B16) <= 20,LEN('Raw Data'!B16)> 0),"",_xlfn.REGEXEXTRACT(CELL("address",'Raw Data'!B16),"\$([A-Z]+)\$[0-9]+"))),_xlfn.REGEXEXTRACT(CELL("address",'Raw Data'!B16),"\$([A-Z]+)\$[0-9]+"))} | C16: {=IFERROR(IF(OR('Raw Data'!C16="",LEN(TRIM('Raw Data'!C16))=0),"",IF(AND(LEN('Raw Data'!C16) <= 255,LEN('Raw Data'!C16)> 0),"",_xlfn.REGEXEXTRACT(CELL("address",'Raw Data'!C16),"\$([A-Z]+)\$[0-9]+"))),_xlfn.REGEXEXTRACT(CELL("address",'Raw Data'!C16),"\$([A-Z]+)\$[0-9]+"))} | D16: {=IFERROR(IF(OR('Raw Data'!D16="",LEN(TRIM('Raw Data'!D16))=0),"",IF(AND(LEN('Raw Data'!D16) <= 20,LEN('Raw Data'!D16)> 0),"",_xlfn.REGEXEXTRACT(CELL("address",'Raw Data'!D16),"\$([A-Z]+)\$[0-9]+"))),_xlfn.REGEXEXTRACT(CELL("address",'Raw Data'!D16),"\$([A-Z]+)\$[0-9]+"))} | E16: {=IFERROR(IF(OR('Raw Data'!E16="",LEN(TRIM('Raw Data'!E16))=0),"",IF(AND(ISNUMBER('Raw Data'!E16),'Raw Data'!E16>=Configuration!$D$2),"",_xlfn.REGEXEXTRACT(CELL("address",'Raw Data'!E16),"\$([A-Z]+)\$[0-9]+"))),_xlfn.REGEXEXTRACT(CELL("address",E16), "\$([A-Z]+)\$[0-9]+"))} | F16: {=IFERROR(IF(OR('Raw Data'!F16="",LEN(TRIM('Raw Data'!F16))=0),"",IF(AND(ISNUMBER('Raw Data'!F16), IFERROR('Raw Data'!F16 = ROUND('Raw Data'!F16, 4),FALSE)),"",_xlfn.REGEXEXTRACT(CELL("address",F16), "\$([A-Z]+)\$[0-9]+"))),_xlfn.REGEXEXTRACT(CELL("address",F16), "\$([A-Z]+)\$[0-9]+"))} | G16: {=IFERROR(IF(OR('Raw Data'!G16="",LEN(TRIM('Raw Data'!G16))=0),"",IF(AND(ISNUMBER('Raw Data'!G16), IFERROR('Raw Data'!G16 = ROUND('Raw Data'!G16, 2),FALSE)),"",_xlfn.REGEXEXTRACT(CELL("address",G16), "\$([A-Z]+)\$[0-9]+"))),_xlfn.REGEXEXTRACT(CELL("address",G16), "\$([A-Z]+)\$[0-9]+"))} | H16: {=IFERROR(IF(OR('Raw Data'!H16="",LEN(TRIM('Raw Data'!H16))=0),"",IF(AND(ISNUMBER('Raw Data'!H16), IFERROR('Raw Data'!H16 = ROUND('Raw Data'!H16, 2),FALSE)),"",_xlfn.REGEXEXTRACT(CELL("address",H16), "\$([A-Z]+)\$[0-9]+"))),_xlfn.REGEXEXTRACT(CELL("address",H16), "\$([A-Z]+)\$[0-9]+"))} | I16: {=IFERROR(IF(OR('Raw Data'!I16="",LEN(TRIM('Raw Data'!I16))=0),"",IF(AND(ISNUMBER('Raw Data'!I16), IFERROR('Raw Data'!I16 = ROUND('Raw Data'!I16, 2),FALSE)),"",_xlfn.REGEXEXTRACT(CELL("address",I16), "\$([A-Z]+)\$[0-9]+"))),_xlfn.REGEXEXTRACT(CELL("address",I16), "\$([A-Z]+)\$[0-9]+"))} | J16: {=IFERROR(IF(OR('Raw Data'!J16="",LEN(TRIM('Raw Data'!J16))=0),"",IF(AND(ISNUMBER('Raw Data'!J16), IFERROR('Raw Data'!J16 = ROUND('Raw Data'!J16, 2),FALSE)),"",_xlfn.REGEXEXTRACT(CELL("address",J16), "\$([A-Z]+)\$[0-9]+"))),_xlfn.REGEXEXTRACT(CELL("address",J16), "\$([A-Z]+)\$[0-9]+"))} | K16: {=IFERROR(IF(OR('Raw Data'!K16="",LEN(TRIM('Raw Data'!K16))=0),"",IF(AND(ISNUMBER('Raw Data'!K16), IFERROR('Raw Data'!K16 = ROUND('Raw Data'!K16, 2),FALSE)),"",_xlfn.REGEXEXTRACT(CELL("address",K16), "\$([A-Z]+)\$[0-9]+"))),_xlfn.REGEXEXTRACT(CELL("address",K16), "\$([A-Z]+)\$[0-9]+"))} | L16: {=IFERROR(IF(OR('Raw Data'!L16="",LEN(TRIM('Raw Data'!L16))=0),"",IF(AND(ISNUMBER('Raw Data'!L16), IFERROR('Raw Data'!L16 = ROUND('Raw Data'!L16, 2),FALSE)),"",_xlfn.REGEXEXTRACT(CELL("address",L16), "\$([A-Z]+)\$[0-9]+"))),_xlfn.REGEXEXTRACT(CELL("address",L16), "\$([A-Z]+)\$[0-9]+"))} | M16: {=IFERROR(IF(OR('Raw Data'!M16="",LEN(TRIM('Raw Data'!M16))=0),"",IF(AND(ISNUMBER('Raw Data'!M16), IFERROR('Raw Data'!M16 = ROUND('Raw Data'!M16, 2),FALSE)),"",_xlfn.REGEXEXTRACT(CELL("address",M16), "\$([A-Z]+)\$[0-9]+"))),_xlfn.REGEXEXTRACT(CELL("address",M16), "\$([A-Z]+)\$[0-9]+"))} | N16: {=IFERROR(IF(OR('Raw Data'!N16="",LEN(TRIM('Raw Data'!N16))=0),"",IF(AND(ISNUMBER('Raw Data'!N16), IFERROR('Raw Data'!N16 = ROUND('Raw Data'!N16, 2),FALSE)),"",_xlfn.REGEXEXTRACT(CELL("address",N16), "\$([A-Z]+)\$[0-9]+"))),_xlfn.REGEXEXTRACT(CELL("address",N16), "\$([A-Z]+)\$[0-9]+"))} | ... AD16: {=IFERROR(IF(OR('Raw Data'!AD16="",LEN(TRIM('Raw Data'!AD16))=0),"",IF(AND(ISNUMBER('Raw Data'!AD16), IFERROR('Raw Data'!AD16 = ROUND('Raw Data'!AD16, 2),FALSE)),"",_xlfn.REGEXEXTRACT(CELL("address",AD16), "\$([A-Z]+)\$[0-9]+"))),_xlfn.REGEXEXTRACT(CELL("address",AD16), "\$([A-Z]+)\$[0-9]+"))}
B17: {=IFERROR(IF(OR('Raw Data'!B17="",LEN(TRIM('Raw Data'!B17))=0),"",IF(AND(LEN('Raw Data'!B17) <= 20,LEN('Raw Data'!B17)> 0),"",_xlfn.REGEXEXTRACT(CELL("address",'Raw Data'!B17),"\$([A-Z]+)\$[0-9]+"))),_xlfn.REGEXEXTRACT(CELL("address",'Raw Data'!B17),"\$([A-Z]+)\$[0-9]+"))} | C17: {=IFERROR(IF(OR('Raw Data'!C17="",LEN(TRIM('Raw Data'!C17))=0),"",IF(AND(LEN('Raw Data'!C17) <= 255,LEN('Raw Data'!C17)> 0),"",_xlfn.REGEXEXTRACT(CELL("address",'Raw Data'!C17),"\$([A-Z]+)\$[0-9]+"))),_xlfn.REGEXEXTRACT(CELL("address",'Raw Data'!C17),"\$([A-Z]+)\$[0-9]+"))} | D17: {=IFERROR(IF(OR('Raw Data'!D17="",LEN(TRIM('Raw Data'!D17))=0),"",IF(AND(LEN('Raw Data'!D17) <= 20,LEN('Raw Data'!D17)> 0),"",_xlfn.REGEXEXTRACT(CELL("address",'Raw Data'!D17),"\$([A-Z]+)\$[0-9]+"))),_xlfn.REGEXEXTRACT(CELL("address",'Raw Data'!D17),"\$([A-Z]+)\$[0-9]+"))} | E17: {=IFERROR(IF(OR('Raw Data'!E17="",LEN(TRIM('Raw Data'!E17))=0),"",IF(AND(ISNUMBER('Raw Data'!E17),'Raw Data'!E17>=Configuration!$D$2),"",_xlfn.REGEXEXTRACT(CELL("address",'Raw Data'!E17),"\$([A-Z]+)\$[0-9]+"))),_xlfn.REGEXEXTRACT(CELL("address",E17), "\$([A-Z]+)\$[0-9]+"))} | F17: {=IFERROR(IF(OR('Raw Data'!F17="",LEN(TRIM('Raw Data'!F17))=0),"",IF(AND(ISNUMBER('Raw Data'!F17), IFERROR('Raw Data'!F17 = ROUND('Raw Data'!F17, 4),FALSE)),"",_xlfn.REGEXEXTRACT(CELL("address",F17), "\$([A-Z]+)\$[0-9]+"))),_xlfn.REGEXEXTRACT(CELL("address",F17), "\$([A-Z]+)\$[0-9]+"))} | G17: {=IFERROR(IF(OR('Raw Data'!G17="",LEN(TRIM('Raw Data'!G17))=0),"",IF(AND(ISNUMBER('Raw Data'!G17), IFERROR('Raw Data'!G17 = ROUND('Raw Data'!G17, 2),FALSE)),"",_xlfn.REGEXEXTRACT(CELL("address",G17), "\$([A-Z]+)\$[0-9]+"))),_xlfn.REGEXEXTRACT(CELL("address",G17), "\$([A-Z]+)\$[0-9]+"))} | H17: {=IFERROR(IF(OR('Raw Data'!H17="",LEN(TRIM('Raw Data'!H17))=0),"",IF(AND(ISNUMBER('Raw Data'!H17), IFERROR('Raw Data'!H17 = ROUND('Raw Data'!H17, 2),FALSE)),"",_xlfn.REGEXEXTRACT(CELL("address",H17), "\$([A-Z]+)\$[0-9]+"))),_xlfn.REGEXEXTRACT(CELL("address",H17), "\$([A-Z]+)\$[0-9]+"))} | I17: {=IFERROR(IF(OR('Raw Data'!I17="",LEN(TRIM('Raw Data'!I17))=0),"",IF(AND(ISNUMBER('Raw Data'!I17), IFERROR('Raw Data'!I17 = ROUND('Raw Data'!I17, 2),FALSE)),"",_xlfn.REGEXEXTRACT(CELL("address",I17), "\$([A-Z]+)\$[0-9]+"))),_xlfn.REGEXEXTRACT(CELL("address",I17), "\$([A-Z]+)\$[0-9]+"))} | J17: {=IFERROR(IF(OR('Raw Data'!J17="",LEN(TRIM('Raw Data'!J17))=0),"",IF(AND(ISNUMBER('Raw Data'!J17), IFERROR('Raw Data'!J17 = ROUND('Raw Data'!J17, 2),FALSE)),"",_xlfn.REGEXEXTRACT(CELL("address",J17), "\$([A-Z]+)\$[0-9]+"))),_xlfn.REGEXEXTRACT(CELL("address",J17), "\$([A-Z]+)\$[0-9]+"))} | K17: {=IFERROR(IF(OR('Raw Data'!K17="",LEN(TRIM('Raw Data'!K17))=0),"",IF(AND(ISNUMBER('Raw Data'!K17), IFERROR('Raw Data'!K17 = ROUND('Raw Data'!K17, 2),FALSE)),"",_xlfn.REGEXEXTRACT(CELL("address",K17), "\$([A-Z]+)\$[0-9]+"))),_xlfn.REGEXEXTRACT(CELL("address",K17), "\$([A-Z]+)\$[0-9]+"))} | L17: {=IFERROR(IF(OR('Raw Data'!L17="",LEN(TRIM('Raw Data'!L17))=0),"",IF(AND(ISNUMBER('Raw Data'!L17), IFERROR('Raw Data'!L17 = ROUND('Raw Data'!L17, 2),FALSE)),"",_xlfn.REGEXEXTRACT(CELL("address",L17), "\$([A-Z]+)\$[0-9]+"))),_xlfn.REGEXEXTRACT(CELL("address",L17), "\$([A-Z]+)\$[0-9]+"))} | M17: {=IFERROR(IF(OR('Raw Data'!M17="",LEN(TRIM('Raw Data'!M17))=0),"",IF(AND(ISNUMBER('Raw Data'!M17), IFERROR('Raw Data'!M17 = ROUND('Raw Data'!M17, 2),FALSE)),"",_xlfn.REGEXEXTRACT(CELL("address",M17), "\$([A-Z]+)\$[0-9]+"))),_xlfn.REGEXEXTRACT(CELL("address",M17), "\$([A-Z]+)\$[0-9]+"))} | N17: {=IFERROR(IF(OR('Raw Data'!N17="",LEN(TRIM('Raw Data'!N17))=0),"",IF(AND(ISNUMBER('Raw Data'!N17), IFERROR('Raw Data'!N17 = ROUND('Raw Data'!N17, 2),FALSE)),"",_xlfn.REGEXEXTRACT(CELL("address",N17), "\$([A-Z]+)\$[0-9]+"))),_xlfn.REGEXEXTRACT(CELL("address",N17), "\$([A-Z]+)\$[0-9]+"))} | ... AD17: {=IFERROR(IF(OR('Raw Data'!AD17="",LEN(TRIM('Raw Data'!AD17))=0),"",IF(AND(ISNUMBER('Raw Data'!AD17), IFERROR('Raw Data'!AD17 = ROUND('Raw Data'!AD17, 2),FALSE)),"",_xlfn.REGEXEXTRACT(CELL("address",AD17), "\$([A-Z]+)\$[0-9]+"))),_xlfn.REGEXEXTRACT(CELL("address",AD17), "\$([A-Z]+)\$[0-9]+"))}
B18: {=IFERROR(IF(OR('Raw Data'!B18="",LEN(TRIM('Raw Data'!B18))=0),"",IF(AND(LEN('Raw Data'!B18) <= 20,LEN('Raw Data'!B18)> 0),"",_xlfn.REGEXEXTRACT(CELL("address",'Raw Data'!B18),"\$([A-Z]+)\$[0-9]+"))),_xlfn.REGEXEXTRACT(CELL("address",'Raw Data'!B18),"\$([A-Z]+)\$[0-9]+"))} | C18: {=IFERROR(IF(OR('Raw Data'!C18="",LEN(TRIM('Raw Data'!C18))=0),"",IF(AND(LEN('Raw Data'!C18) <= 255,LEN('Raw Data'!C18)> 0),"",_xlfn.REGEXEXTRACT(CELL("address",'Raw Data'!C18),"\$([A-Z]+)\$[0-9]+"))),_xlfn.REGEXEXTRACT(CELL("address",'Raw Data'!C18),"\$([A-Z]+)\$[0-9]+"))} | D18: {=IFERROR(IF(OR('Raw Data'!D18="",LEN(TRIM('Raw Data'!D18))=0),"",IF(AND(LEN('Raw Data'!D18) <= 20,LEN('Raw Data'!D18)> 0),"",_xlfn.REGEXEXTRACT(CELL("address",'Raw Data'!D18),"\$([A-Z]+)\$[0-9]+"))),_xlfn.REGEXEXTRACT(CELL("address",'Raw Data'!D18),"\$([A-Z]+)\$[0-9]+"))} | E18: {=IFERROR(IF(OR('Raw Data'!E18="",LEN(TRIM('Raw Data'!E18))=0),"",IF(AND(ISNUMBER('Raw Data'!E18),'Raw Data'!E18>=Configuration!$D$2),"",_xlfn.REGEXEXTRACT(CELL("address",'Raw Data'!E18),"\$([A-Z]+)\$[0-9]+"))),_xlfn.REGEXEXTRACT(CELL("address",E18), "\$([A-Z]+)\$[0-9]+"))} | F18: {=IFERROR(IF(OR('Raw Data'!F18="",LEN(TRIM('Raw Data'!F18))=0),"",IF(AND(ISNUMBER('Raw Data'!F18), IFERROR('Raw Data'!F18 = ROUND('Raw Data'!F18, 4),FALSE)),"",_xlfn.REGEXEXTRACT(CELL("address",F18), "\$([A-Z]+)\$[0-9]+"))),_xlfn.REGEXEXTRACT(CELL("address",F18), "\$([A-Z]+)\$[0-9]+"))} | G18: {=IFERROR(IF(OR('Raw Data'!G18="",LEN(TRIM('Raw Data'!G18))=0),"",IF(AND(ISNUMBER('Raw Data'!G18), IFERROR('Raw Data'!G18 = ROUND('Raw Data'!G18, 2),FALSE)),"",_xlfn.REGEXEXTRACT(CELL("address",G18), "\$([A-Z]+)\$[0-9]+"))),_xlfn.REGEXEXTRACT(CELL("address",G18), "\$([A-Z]+)\$[0-9]+"))} | H18: {=IFERROR(IF(OR('Raw Data'!H18="",LEN(TRIM('Raw Data'!H18))=0),"",IF(AND(ISNUMBER('Raw Data'!H18), IFERROR('Raw Data'!H18 = ROUND('Raw Data'!H18, 2),FALSE)),"",_xlfn.REGEXEXTRACT(CELL("address",H18), "\$([A-Z]+)\$[0-9]+"))),_xlfn.REGEXEXTRACT(CELL("address",H18), "\$([A-Z]+)\$[0-9]+"))} | I18: {=IFERROR(IF(OR('Raw Data'!I18="",LEN(TRIM('Raw Data'!I18))=0),"",IF(AND(ISNUMBER('Raw Data'!I18), IFERROR('Raw Data'!I18 = ROUND('Raw Data'!I18, 2),FALSE)),"",_xlfn.REGEXEXTRACT(CELL("address",I18), "\$([A-Z]+)\$[0-9]+"))),_xlfn.REGEXEXTRACT(CELL("address",I18), "\$([A-Z]+)\$[0-9]+"))} | J18: {=IFERROR(IF(OR('Raw Data'!J18="",LEN(TRIM('Raw Data'!J18))=0),"",IF(AND(ISNUMBER('Raw Data'!J18), IFERROR('Raw Data'!J18 = ROUND('Raw Data'!J18, 2),FALSE)),"",_xlfn.REGEXEXTRACT(CELL("address",J18), "\$([A-Z]+)\$[0-9]+"))),_xlfn.REGEXEXTRACT(CELL("address",J18), "\$([A-Z]+)\$[0-9]+"))} | K18: {=IFERROR(IF(OR('Raw Data'!K18="",LEN(TRIM('Raw Data'!K18))=0),"",IF(AND(ISNUMBER('Raw Data'!K18), IFERROR('Raw Data'!K18 = ROUND('Raw Data'!K18, 2),FALSE)),"",_xlfn.REGEXEXTRACT(CELL("address",K18), "\$([A-Z]+)\$[0-9]+"))),_xlfn.REGEXEXTRACT(CELL("address",K18), "\$([A-Z]+)\$[0-9]+"))} | L18: {=IFERROR(IF(OR('Raw Data'!L18="",LEN(TRIM('Raw Data'!L18))=0),"",IF(AND(ISNUMBER('Raw Data'!L18), IFERROR('Raw Data'!L18 = ROUND('Raw Data'!L18, 2),FALSE)),"",_xlfn.REGEXEXTRACT(CELL("address",L18), "\$([A-Z]+)\$[0-9]+"))),_xlfn.REGEXEXTRACT(CELL("address",L18), "\$([A-Z]+)\$[0-9]+"))} | M18: {=IFERROR(IF(OR('Raw Data'!M18="",LEN(TRIM('Raw Data'!M18))=0),"",IF(AND(ISNUMBER('Raw Data'!M18), IFERROR('Raw Data'!M18 = ROUND('Raw Data'!M18, 2),FALSE)),"",_xlfn.REGEXEXTRACT(CELL("address",M18), "\$([A-Z]+)\$[0-9]+"))),_xlfn.REGEXEXTRACT(CELL("address",M18), "\$([A-Z]+)\$[0-9]+"))} | N18: {=IFERROR(IF(OR('Raw Data'!N18="",LEN(TRIM('Raw Data'!N18))=0),"",IF(AND(ISNUMBER('Raw Data'!N18), IFERROR('Raw Data'!N18 = ROUND('Raw Data'!N18, 2),FALSE)),"",_xlfn.REGEXEXTRACT(CELL("address",N18), "\$([A-Z]+)\$[0-9]+"))),_xlfn.REGEXEXTRACT(CELL("address",N18), "\$([A-Z]+)\$[0-9]+"))} | ... AD18: {=IFERROR(IF(OR('Raw Data'!AD18="",LEN(TRIM('Raw Data'!AD18))=0),"",IF(AND(ISNUMBER('Raw Data'!AD18), IFERROR('Raw Data'!AD18 = ROUND('Raw Data'!AD18, 2),FALSE)),"",_xlfn.REGEXEXTRACT(CELL("address",AD18), "\$([A-Z]+)\$[0-9]+"))),_xlfn.REGEXEXTRACT(CELL("address",AD18), "\$([A-Z]+)\$[0-9]+"))}
B19: {=IFERROR(IF(OR('Raw Data'!B19="",LEN(TRIM('Raw Data'!B19))=0),"",IF(AND(LEN('Raw Data'!B19) <= 20,LEN('Raw Data'!B19)> 0),"",_xlfn.REGEXEXTRACT(CELL("address",'Raw Data'!B19),"\$([A-Z]+)\$[0-9]+"))),_xlfn.REGEXEXTRACT(CELL("address",'Raw Data'!B19),"\$([A-Z]+)\$[0-9]+"))} | C19: {=IFERROR(IF(OR('Raw Data'!C19="",LEN(TRIM('Raw Data'!C19))=0),"",IF(AND(LEN('Raw Data'!C19) <= 255,LEN('Raw Data'!C19)> 0),"",_xlfn.REGEXEXTRACT(CELL("address",'Raw Data'!C19),"\$([A-Z]+)\$[0-9]+"))),_xlfn.REGEXEXTRACT(CELL("address",'Raw Data'!C19),"\$([A-Z]+)\$[0-9]+"))} | D19: {=IFERROR(IF(OR('Raw Data'!D19="",LEN(TRIM('Raw Data'!D19))=0),"",IF(AND(LEN('Raw Data'!D19) <= 20,LEN('Raw Data'!D19)> 0),"",_xlfn.REGEXEXTRACT(CELL("address",'Raw Data'!D19),"\$([A-Z]+)\$[0-9]+"))),_xlfn.REGEXEXTRACT(CELL("address",'Raw Data'!D19),"\$([A-Z]+)\$[0-9]+"))} | E19: {=IFERROR(IF(OR('Raw Data'!E19="",LEN(TRIM('Raw Data'!E19))=0),"",IF(AND(ISNUMBER('Raw Data'!E19),'Raw Data'!E19>=Configuration!$D$2),"",_xlfn.REGEXEXTRACT(CELL("address",'Raw Data'!E19),"\$([A-Z]+)\$[0-9]+"))),_xlfn.REGEXEXTRACT(CELL("address",E19), "\$([A-Z]+)\$[0-9]+"))} | F19: {=IFERROR(IF(OR('Raw Data'!F19="",LEN(TRIM('Raw Data'!F19))=0),"",IF(AND(ISNUMBER('Raw Data'!F19), IFERROR('Raw Data'!F19 = ROUND('Raw Data'!F19, 4),FALSE)),"",_xlfn.REGEXEXTRACT(CELL("address",F19), "\$([A-Z]+)\$[0-9]+"))),_xlfn.REGEXEXTRACT(CELL("address",F19), "\$([A-Z]+)\$[0-9]+"))} | G19: {=IFERROR(IF(OR('Raw Data'!G19="",LEN(TRIM('Raw Data'!G19))=0),"",IF(AND(ISNUMBER('Raw Data'!G19), IFERROR('Raw Data'!G19 = ROUND('Raw Data'!G19, 2),FALSE)),"",_xlfn.REGEXEXTRACT(CELL("address",G19), "\$([A-Z]+)\$[0-9]+"))),_xlfn.REGEXEXTRACT(CELL("address",G19), "\$([A-Z]+)\$[0-9]+"))} | H19: {=IFERROR(IF(OR('Raw Data'!H19="",LEN(TRIM('Raw Data'!H19))=0),"",IF(AND(ISNUMBER('Raw Data'!H19), IFERROR('Raw Data'!H19 = ROUND('Raw Data'!H19, 2),FALSE)),"",_xlfn.REGEXEXTRACT(CELL("address",H19), "\$([A-Z]+)\$[0-9]+"))),_xlfn.REGEXEXTRACT(CELL("address",H19), "\$([A-Z]+)\$[0-9]+"))} | I19: {=IFERROR(IF(OR('Raw Data'!I19="",LEN(TRIM('Raw Data'!I19))=0),"",IF(AND(ISNUMBER('Raw Data'!I19), IFERROR('Raw Data'!I19 = ROUND('Raw Data'!I19, 2),FALSE)),"",_xlfn.REGEXEXTRACT(CELL("address",I19), "\$([A-Z]+)\$[0-9]+"))),_xlfn.REGEXEXTRACT(CELL("address",I19), "\$([A-Z]+)\$[0-9]+"))} | J19: {=IFERROR(IF(OR('Raw Data'!J19="",LEN(TRIM('Raw Data'!J19))=0),"",IF(AND(ISNUMBER('Raw Data'!J19), IFERROR('Raw Data'!J19 = ROUND('Raw Data'!J19, 2),FALSE)),"",_xlfn.REGEXEXTRACT(CELL("address",J19), "\$([A-Z]+)\$[0-9]+"))),_xlfn.REGEXEXTRACT(CELL("address",J19), "\$([A-Z]+)\$[0-9]+"))} | K19: {=IFERROR(IF(OR('Raw Data'!K19="",LEN(TRIM('Raw Data'!K19))=0),"",IF(AND(ISNUMBER('Raw Data'!K19), IFERROR('Raw Data'!K19 = ROUND('Raw Data'!K19, 2),FALSE)),"",_xlfn.REGEXEXTRACT(CELL("address",K19), "\$([A-Z]+)\$[0-9]+"))),_xlfn.REGEXEXTRACT(CELL("address",K19), "\$([A-Z]+)\$[0-9]+"))} | L19: {=IFERROR(IF(OR('Raw Data'!L19="",LEN(TRIM('Raw Data'!L19))=0),"",IF(AND(ISNUMBER('Raw Data'!L19), IFERROR('Raw Data'!L19 = ROUND('Raw Data'!L19, 2),FALSE)),"",_xlfn.REGEXEXTRACT(CELL("address",L19), "\$([A-Z]+)\$[0-9]+"))),_xlfn.REGEXEXTRACT(CELL("address",L19), "\$([A-Z]+)\$[0-9]+"))} | M19: {=IFERROR(IF(OR('Raw Data'!M19="",LEN(TRIM('Raw Data'!M19))=0),"",IF(AND(ISNUMBER('Raw Data'!M19), IFERROR('Raw Data'!M19 = ROUND('Raw Data'!M19, 2),FALSE)),"",_xlfn.REGEXEXTRACT(CELL("address",M19), "\$([A-Z]+)\$[0-9]+"))),_xlfn.REGEXEXTRACT(CELL("address",M19), "\$([A-Z]+)\$[0-9]+"))} | N19: {=IFERROR(IF(OR('Raw Data'!N19="",LEN(TRIM('Raw Data'!N19))=0),"",IF(AND(ISNUMBER('Raw Data'!N19), IFERROR('Raw Data'!N19 = ROUND('Raw Data'!N19, 2),FALSE)),"",_xlfn.REGEXEXTRACT(CELL("address",N19), "\$([A-Z]+)\$[0-9]+"))),_xlfn.REGEXEXTRACT(CELL("address",N19), "\$([A-Z]+)\$[0-9]+"))} | ... AD19: {=IFERROR(IF(OR('Raw Data'!AD19="",LEN(TRIM('Raw Data'!AD19))=0),"",IF(AND(ISNUMBER('Raw Data'!AD19), IFERROR('Raw Data'!AD19 = ROUND('Raw Data'!AD19, 2),FALSE)),"",_xlfn.REGEXEXTRACT(CELL("address",AD19), "\$([A-Z]+)\$[0-9]+"))),_xlfn.REGEXEXTRACT(CELL("address",AD19), "\$([A-Z]+)\$[0-9]+"))}
