Workbook

Sheet Raw Data
B9: C1 | C9: C2 | D9: C3 | E9: C4 | F9: C5 | G9: C6 | H9: C7 | I9: C8 | J9: C9 | K9: C10 | L9: C11 | M9: C12 | N9: C13 | O9: C14 | P9: C15 | Q9: C16 | R9: C17 | S9: C18 | T9: C19 | U9: C20 | V9: C21 | W9: C22 | X9: C23 | Y9: C24
B10: 200 | C10: 200-1 | D10: 200-1-1 | E10: 200-1-1-1 | F10: 200-1-1-1-1 | G10: ENG | H10: 200-1-1-1-1-ENG | I10: Onshore | J10: Small EPC | K10: EPC | L10: Power Plant | M10: CSA | N10: Engineering | O10: Onshore-Small EPC-EPC-Power Plant-CSA-Engineering | P10: SQM | W10: 0 | X10: 0 | Y10: 0
B11: 200 | C11: 200-1 | D11: 200-1-1 | E11: 200-1-1-1 | F11: 200-1-1-1-2 | G11: ENG | H11: 200-1-1-1-2-ENG | I11: Onshore | J11: Small EPC | K11: EPC | L11: Power Plant | M11: Structure Steel | N11: Engineering | O11: Onshore-Small EPC-EPC-Power Plant-Structure Steel-Engineering | P11: MT | W11: 0 | X11: 0 | Y11: 0
B12: 200 | C12: 200-1 | D12: 200-1-1 | E12: 200-1-1-1 | F12: 200-1-1-1-3 | G12: ENG | H12: 200-1-1-1-3-ENG | I12: Onshore | J12: Small EPC | K12: EPC | L12: Power Plant | M12: Process | N12: Engineering | O12: Onshore-Small EPC-EPC-Power Plant-Process-Engineering | P12: Lot | W12: 0 | X12: 0 | Y12: 0
B13: 200 | C13: 200-1 | D13: 200-1-1 | E13: 200-1-1-1 | F13: 200-1-1-1-4 | G13: ENG | H13: 200-1-1-1-4-ENG | I13: Onshore | J13: Small EPC | K13: EPC | L13: Power Plant | M13: Piping | N13: Engineering | O13: Onshore-Small EPC-EPC-Power Plant-Piping-Engineering | P13: DB | W13: 0 | X13: 0 | Y13: 0
B14: 200 | C14: 200-1 | D14: 200-1-1 | E14: 200-1-1-1 | F14: 200-1-1-1-5 | G14: ENG | H14: 200-1-1-1-5-ENG | I14: Onshore | J14: Small EPC | K14: EPC | L14: Power Plant | M14: Mechanical | N14: Engineering | O14: Onshore-Small EPC-EPC-Power Plant-Mechanical-Engineering | P14: MT | W14: 0 | X14: 0 | Y14: 0
B15: 200 | C15: 200-1 | D15: 200-1-1 | E15: 200-1-1-1 | F15: 200-1-1-1-6 | G15: ENG | H15: 200-1-1-1-6-ENG | I15: Onshore | J15: Small EPC | K15: EPC | L15: Power Plant | M15: Electrical | N15: Engineering | O15: Onshore-Small EPC-EPC-Power Plant-Electrical-Engineering | P15: M | W15: 0 | X15: 0 | Y15: 0
B16: 200 | C16: 200-1 | D16: 200-1-1 | E16: 200-1-1-1 | F16: 200-1-1-1-7 | G16: ENG | H16: 200-1-1-1-7-ENG | I16: Onshore | J16: Small EPC | K16: EPC | L16: Power Plant | M16: Instrument | N16: Engineering | O16: Onshore-Small EPC-EPC-Power Plant-Instrument-Engineering | P16: M | W16: 0 | X16: 0 | Y16: 0
B17: 200 | C17: 200-1 | D17: 200-1-1 | E17: 200-1-1-1 | F17: 200-1-1-1-8 | G17: ENG | H17: 200-1-1-1-8-ENG | I17: Onshore | J17: Small EPC | K17: EPC | L17: Power Plant | M17: Blast & Paint | N17: Engineering | O17: Onshore-Small EPC-EPC-Power Plant-Blast & Paint-Engineering | P17: SQM | W17: 0 | X17: 0 | Y17: 0
B18: 200 | C18: 200-1 | D18: 200-1-1 | E18: 200-1-1-1 | F18: 200-1-1-1-9 | G18: ENG | H18: 200-1-1-1-9-ENG | I18: Onshore | J18: Small EPC | K18: EPC | L18: Power Plant | M18: Insulation | N18: Engineering | O18: Onshore-Small EPC-EPC-Power Plant-Insulation-Engineering | P18: SQM | W18: 0 | X18: 0 | Y18: 0
B19: 200 | C19: 200-1 | D19: 200-1-1 | E19: 200-1-1-1 | F19: 200-1-1-1-10 | G19: ENG | H19: 200-1-1-1-10-ENG | I19: Onshore | J19: Small EPC | K19: EPC | L19: Power Plant | M19: Fireproofing | N19: Engineering | O19: Onshore-Small EPC-EPC-Power Plant-Fireproofing-Engineering | P19: SQM | W19: 0 | X19: 0 | Y19: 0
B20: 200 | C20: 200-1 | D20: 200-1-1 | E20: 200-1-1-1 | F20: 200-1-1-1-11 | G20: ENG | H20: 200-1-1-1-11-ENG | I20: Onshore | J20: Small EPC | K20: EPC | L20: Power Plant | M20: Load & Sail | N20: Engineering | O20: Onshore-Small EPC-EPC-Power Plant-Load & Sail-Engineering | P20: MT | W20: 0 | X20: 0 | Y20: 0
B21: 200 | C21: 200-1 | D21: 200-1-1 | E21: 200-1-1-1 | F21: 200-1-1-1-12 | G21: ENG | H21: 200-1-1-1-12-ENG | I21: Onshore | J21: Small EPC | K21: EPC | L21: Power Plant | M21: Common of Project | N21: Engineering | O21: Onshore-Small EPC-EPC-Power Plant-Common of Project-Engineering | P21: Lot | W21: 0 | X21: 0 | Y21: 0
... B74: 200 | C74: 200-1 | D74: 200-1-1 | E74: 200-1-1-1 | F74: 200-1-1-1-13 | G74: HUC | H74: 200-1-1-1-13-HUC | I74: Onshore | J74: Small EPC | K74: EPC | L74: Power Plant | M74: Other | N74: HUC | O74: Onshore-Small EPC-EPC-Power Plant-Other-HUC | P74: Lot | W74: 0 | X74: 0 | Y74: 0
B75: 200 | C75: 200-1 | D75: 200-1-1 | E75: 200-1-1-1 | F75: 200-1-1-1-1 | G75: ALL | H75: 200-1-1-1-1-ALL | I75: Onshore | J75: Small EPC | K75: EPC | L75: Power Plant | M75: CSA | N75: Overall Project | O75: Onshore-Small EPC-EPC-Power Plant-CSA-Overall Project | P75: SQM | T75: 0 | U75: 0 | V75: 0 | W75: 0 | X75: 0 | Y75: 0
B76: 200 | C76: 200-1 | D76: 200-1-1 | E76: 200-1-1-1 | F76: 200-1-1-1-2 | G76: ALL | H76: 200-1-1-1-2-ALL | I76: Onshore | J76: Small EPC | K76: EPC | L76: Power Plant | M76: Structure Steel | N76: Overall Project | O76: Onshore-Small EPC-EPC-Power Plant-Structure Steel-Overall Project | P76: MT | T76: 0 | U76: 0 | V76: 0 | W76: 0 | X76: 0 | Y76: 0
B77: 200 | C77: 200-1 | D77: 200-1-1 | E77: 200-1-1-1 | F77: 200-1-1-1-3 | G77: ALL | H77: 200-1-1-1-3-ALL | I77: Onshore | J77: Small EPC | K77: EPC | L77: Power Plant | M77: Process | N77: Overall Project | O77: Onshore-Small EPC-EPC-Power Plant-Process-Overall Project | P77: Lot | T77: 0 | U77: 0 | V77: 0 | W77: 0 | X77: 0 | Y77: 0
B78: 200 | C78: 200-1 | D78: 200-1-1 | E78: 200-1-1-1 | F78: 200-1-1-1-4 | G78: ALL | H78: 200-1-1-1-4-ALL | I78: Onshore | J78: Small EPC | K78: EPC | L78: Power Plant | M78: Piping | N78: Overall Project | O78: Onshore-Small EPC-EPC-Power Plant-Piping-Overall Project | P78: DB | T78: 0 | U78: 0 | V78: 0 | W78: 0 | X78: 0 | Y78: 0
B79: 200 | C79: 200-1 | D79: 200-1-1 | E79: 200-1-1-1 | F79: 200-1-1-1-5 | G79: ALL | H79: 200-1-1-1-5-ALL | I79: Onshore | J79: Small EPC | K79: EPC | L79: Power Plant | M79: Mechanical | N79: Overall Project | O79: Onshore-Small EPC-EPC-Power Plant-Mechanical-Overall Project | P79: MT | T79: 0 | U79: 0 | V79: 0 | W79: 0 | X79: 0 | Y79: 0
B80: 200 | C80: 200-1 | D80: 200-1-1 | E80: 200-1-1-1 | F80: 200-1-1-1-6 | G80: ALL | H80: 200-1-1-1-6-ALL | I80: Onshore | J80: Small EPC | K80: EPC | L80: Power Plant | M80: Electrical | N80: Overall Project | O80: Onshore-Small EPC-EPC-Power Plant-Electrical-Overall Project | P80: M | T80: 0 | U80: 0 | V80: 0 | W80: 0 | X80: 0 | Y80: 0
B81: 200 | C81: 200-1 | D81: 200-1-1 | E81: 200-1-1-1 | F81: 200-1-1-1-7 | G81: ALL | H81: 200-1-1-1-7-ALL | I81: Onshore | J81: Small EPC | K81: EPC | L81: Power Plant | M81: Instrument | N81: Overall Project | O81: Onshore-Small EPC-EPC-Power Plant-Instrument-Overall Project | P81: M | T81: 0 | U81: 0 | V81: 0 | W81: 0 | X81: 0 | Y81: 0
B82: 200 | C82: 200-1 | D82: 200-1-1 | E82: 200-1-1-1 | F82: 200-1-1-1-8 | G82: ALL | H82: 200-1-1-1-8-ALL | I82: Onshore | J82: Small EPC | K82: EPC | L82: Power Plant | M82: Blast & Paint | N82: Overall Project | O82: Onshore-Small EPC-EPC-Power Plant-Blast & Paint-Overall Project | P82: SQM | T82: 0 | U82: 0 | V82: 0 | W82: 0 | X82: 0 | Y82: 0
B83: 200 | C83: 200-1 | D83: 200-1-1 | E83: 200-1-1-1 | F83: 200-1-1-1-9 | G83: ALL | H83: 200-1-1-1-9-ALL | I83: Onshore | J83: Small EPC | K83: EPC | L83: Power Plant | M83: Insulation | N83: Overall Project | O83: Onshore-Small EPC-EPC-Power Plant-Insulation-Overall Project | P83: SQM | T83: 0 | U83: 0 | V83: 0 | W83: 0 | X83: 0 | Y83: 0
B84: 200 | C84: 200-1 | D84: 200-1-1 | E84: 200-1-1-1 | F84: 200-1-1-1-10 | G84: ALL | H84: 200-1-1-1-10-ALL | I84: Onshore | J84: Small EPC | K84: EPC | L84: Power Plant | M84: Fireproofing | N84: Overall Project | O84: Onshore-Small EPC-EPC-Power Plant-Fireproofing-Overall Project | P84: SQM | T84: 0 | U84: 0 | V84: 0 | W84: 0 | X84: 0 | Y84: 0
B85: 200 | C85: 200-1 | D85: 200-1-1 | E85: 200-1-1-1 | F85: 200-1-1-1-11 | G85: ALL | H85: 200-1-1-1-11-ALL | I85: Onshore | J85: Small EPC | K85: EPC | L85: Power Plant | M85: Load & Sail | N85: Overall Project | O85: Onshore-Small EPC-EPC-Power Plant-Load & Sail-Overall Project | P85: MT | T85: 0 | U85: 0 | V85: 0 | W85: 0 | X85: 0 | Y85: 0
B86: 200 | C86: 200-1 | D86: 200-1-1 | E86: 200-1-1-1 | F86: 200-1-1-1-12 | G86: ALL | H86: 200-1-1-1-12-ALL | I86: Onshore | J86: Small EPC | K86: EPC | L86: Power Plant | M86: Common of Project | N86: Overall Project | O86: Onshore-Small EPC-EPC-Power Plant-Common of Project-Overall Project | P86: Lot | T86: 0 | U86: 0 | V86: 0 | W86: 0 | X86: 0 | Y86: 0
B87: 200 | C87: 200-1 | D87: 200-1-1 | E87: 200-1-1-1 | F87: 200-1-1-1-13 | G87: ALL | H87: 200-1-1-1-13-ALL | I87: Onshore | J87: Small EPC | K87: EPC | L87: Power Plant | M87: Other | N87: Overall Project | O87: Onshore-Small EPC-EPC-Power Plant-Other-Overall Project | P87: Lot | T87: 0 | U87: 0 | V87: 0 | W87: 0 | X87: 0 | Y87: 0
B88: 200 | C88: 200-1 | D88: 200-1-1 | E88: 200-1-1-2 | F88: 200-1-1-2-1 | G88: ENG | H88: 200-1-1-2-1-ENG | I88: Onshore | J88: Small EPC | K88: EPC | L88: Factory Plant | M88: CSA | N88: Engineering | O88: Onshore-Small EPC-EPC-Factory Plant-CSA-Engineering | P88: SQM | W88: 0 | X88: 0 | Y88: 0
B89: 200 | C89: 200-1 | D89: 200-1-1 | E89: 200-1-1-2 | F89: 200-1-1-2-2 | G89: ENG | H89: 200-1-1-2-2-ENG | I89: Onshore | J89: Small EPC | K89: EPC | L89: Factory Plant | M89: Structure Steel | N89: Engineering | O89: Onshore-Small EPC-EPC-Factory Plant-Structure Steel-Engineering | P89: MT | W89: 0 | X89: 0 | Y89: 0
B90: 200 | C90: 200-1 | D90: 200-1-1 | E90: 200-1-1-2 | F90: 200-1-1-2-3 | G90: ENG | H90: 200-1-1-2-3-ENG | I90: Onshore | J90: Small EPC | K90: EPC | L90: Factory Plant | M90: Process | N90: Engineering | O90: Onshore-Small EPC-EPC-Factory Plant-Process-Engineering | P90: Lot | W90: 0 | X90: 0 | Y90: 0
B91: 200 | C91: 200-1 | D91: 200-1-1 | E91: 200-1-1-2 | F91: 200-1-1-2-4 | G91: ENG | H91: 200-1-1-2-4-ENG | I91: Onshore | J91: Small EPC | K91: EPC | L91: Factory Plant | M91: Piping | N91: Engineering | O91: Onshore-Small EPC-EPC-Factory Plant-Piping-Engineering | P91: DB | W91: 0 | X91: 0 | Y91: 0
B92: 200 | C92: 200-1 | D92: 200-1-1 | E92: 200-1-1-2 | F92: 200-1-1-2-5 | G92: ENG | H92: 200-1-1-2-5-ENG | I92: Onshore | J92: Small EPC | K92: EPC | L92: Factory Plant | M92: Mechanical | N92: Engineering | O92: Onshore-Small EPC-EPC-Factory Plant-Mechanical-Engineering | P92: MT | W92: 0 | X92: 0 | Y92: 0
B93: 200 | C93: 200-1 | D93: 200-1-1 | E93: 200-1-1-2 | F93: 200-1-1-2-6 | G93: ENG | H93: 200-1-1-2-6-ENG | I93: Onshore | J93: Small EPC | K93: EPC | L93: Factory Plant | M93: Electrical | N93: Engineering | O93: Onshore-Small EPC-EPC-Factory Plant-Electrical-Engineering | P93: M | W93: 0 | X93: 0 | Y93: 0
B94: 200 | C94: 200-1 | D94: 200-1-1 | E94: 200-1-1-2 | F94: 200-1-1-2-7 | G94: ENG | H94: 200-1-1-2-7-ENG | I94: Onshore | J94: Small EPC | K94: EPC | L94: Factory Plant | M94: Instrument | N94: Engineering | O94: Onshore-Small EPC-EPC-Factory Plant-Instrument-Engineering | P94: M | W94: 0 | X94: 0 | Y94: 0
B95: 200 | C95: 200-1 | D95: 200-1-1 | E95: 200-1-1-2 | F95: 200-1-1-2-8 | G95: ENG | H95: 200-1-1-2-8-ENG | I95: Onshore | J95: Small EPC | K95: EPC | L95: Factory Plant | M95: Blast & Paint | N95: Engineering | O95: Onshore-Small EPC-EPC-Factory Plant-Blast & Paint-Engineering | P95: SQM | W95: 0 | X95: 0 | Y95: 0
B96: 200 | C96: 200-1 | D96: 200-1-1 | E96: 200-1-1-2 | F96: 200-1-1-2-9 | G96: ENG | H96: 200-1-1-2-9-ENG | I96: Onshore | J96: Small EPC | K96: EPC | L96: Factory Plant | M96: Insulation | N96: Engineering | O96: Onshore-Small EPC-EPC-Factory Plant-Insulation-Engineering | P96: SQM | W96: 0 | X96: 0 | Y96: 0
B97: 200 | C97: 200-1 | D97: 200-1-1 | E97: 200-1-1-2 | F97: 200-1-1-2-10 | G97: ENG | H97: 200-1-1-2-10-ENG | I97: Onshore | J97: Small EPC | K97: EPC | L97: Factory Plant | M97: Fireproofing | N97: Engineering | O97: Onshore-Small EPC-EPC-Factory Plant-Fireproofing-Engineering | P97: SQM | W97: 0 | X97: 0 | Y97: 0
B98: 200 | C98: 200-1 | D98: 200-1-1 | E98: 200-1-1-2 | F98: 200-1-1-2-11 | G98: ENG | H98: 200-1-1-2-11-ENG | I98: Onshore | J98: Small EPC | K98: EPC | L98: Factory Plant | M98: Load & Sail | N98: Engineering | O98: Onshore-Small EPC-EPC-Factory Plant-Load & Sail-Engineering | P98: MT | W98: 0 | X98: 0 | Y98: 0
B99: 200 | C99: 200-1 | D99: 200-1-1 | E99: 200-1-1-2 | F99: 200-1-1-2-12 | G99: ENG | H99: 200-1-1-2-12-ENG | I99: Onshore | J99: Small EPC | K99: EPC | L99: Factory Plant | M99: Common of Project | N99: Engineering | O99: Onshore-Small EPC-EPC-Factory Plant-Common of Project-Engineering | P99: Lot | W99: 0 | X99: 0 | Y99: 0
... B152: 200 | C152: 200-1 | D152: 200-1-1 | E152: 200-1-1-2 | F152: 200-1-1-2-13 | G152: HUC | H152: 200-1-1-2-13-HUC | I152: Onshore | J152: Small EPC | K152: EPC | L152: Factory Plant | M152: Other | N152: HUC | O152: Onshore-Small EPC-EPC-Factory Plant-Other-HUC | P152: Lot | W152: 0 | X152: 0 | Y152: 0
...

Sheet Validate_Empty
B8: TRUE | C8: TRUE | D8: TRUE | E8: TRUE | F8: TRUE | G8: TRUE | H8: TRUE | I8: TRUE | J8: TRUE | K8: TRUE | L8: TRUE | M8: TRUE | N8: TRUE | O8: TRUE | P8: TRUE | Q8: FALSE | R8: FALSE | S8: FALSE | T8: FALSE | U8: FALSE | V8: FALSE | W8: FALSE | X8: FALSE | Y8: FALSE
B9: C1 | C9: C2 | D9: C3 | E9: C4 | F9: C5 | G9: C6 | H9: C7 | I9: C8 | J9: C9 | K9: C10 | L9: C11 | M9: C12 | N9: C13 | O9: C14 | P9: C15 | Q9: C16 | R9: C17 | S9: C18 | T9: C19 | U9: C20 | V9: C21 | W9: C22 | X9: C23 | Y9: C24
B10: {=IFERROR(IF(OR('Raw Data'!B10="",LEN(TRIM('Raw Data'!B10))=0),_xlfn.REGEXEXTRACT(CELL("address",'Raw Data'!B10),"\$([A-Z]+)\$[0-9]+"),""),_xlfn.REGEXEXTRACT(CELL("address",'Raw Data'!B10),"\$([A-Z]+)\$[0-9]+"))} | C10: {=IFERROR(IF(OR('Raw Data'!C10="",LEN(TRIM('Raw Data'!C10))=0),_xlfn.REGEXEXTRACT(CELL("address",'Raw Data'!C10),"\$([A-Z]+)\$[0-9]+"),""),_xlfn.REGEXEXTRACT(CELL("address",'Raw Data'!C10),"\$([A-Z]+)\$[0-9]+"))} | D10: {=IFERROR(IF(OR('Raw Data'!D10="",LEN(TRIM('Raw Data'!D10))=0),_xlfn.REGEXEXTRACT(CELL("address",'Raw Data'!D10),"\$([A-Z]+)\$[0-9]+"),""),_xlfn.REGEXEXTRACT(CELL("address",'Raw Data'!D10),"\$([A-Z]+)\$[0-9]+"))} | E10: {=IFERROR(IF(OR('Raw Data'!E10="",LEN(TRIM('Raw Data'!E10))=0),_xlfn.REGEXEXTRACT(CELL("address",'Raw Data'!E10),"\$([A-Z]+)\$[0-9]+"),""),_xlfn.REGEXEXTRACT(CELL("address",'Raw Data'!E10),"\$([A-Z]+)\$[0-9]+"))} | F10: {=IFERROR(IF(OR('Raw Data'!F10="",LEN(TRIM('Raw Data'!F10))=0),_xlfn.REGEXEXTRACT(CELL("address",'Raw Data'!F10),"\$([A-Z]+)\$[0-9]+"),""),_xlfn.REGEXEXTRACT(CELL("address",'Raw Data'!F10),"\$([A-Z]+)\$[0-9]+"))} | G10: {=IFERROR(IF(OR('Raw Data'!G10="",LEN(TRIM('Raw Data'!G10))=0),_xlfn.REGEXEXTRACT(CELL("address",'Raw Data'!G10),"\$([A-Z]+)\$[0-9]+"),""),_xlfn.REGEXEXTRACT(CELL("address",'Raw Data'!G10),"\$([A-Z]+)\$[0-9]+"))} | H10: {=IFERROR(IF(OR('Raw Data'!H10="",LEN(TRIM('Raw Data'!H10))=0),_xlfn.REGEXEXTRACT(CELL("address",'Raw Data'!H10),"\$([A-Z]+)\$[0-9]+"),""),_xlfn.REGEXEXTRACT(CELL("address",'Raw Data'!H10),"\$([A-Z]+)\$[0-9]+"))} | I10: {=IFERROR(IF(OR('Raw Data'!I10="",LEN(TRIM('Raw Data'!I10))=0),_xlfn.REGEXEXTRACT(CELL("address",'Raw Data'!I10),"\$([A-Z]+)\$[0-9]+"),""),_xlfn.REGEXEXTRACT(CELL("address",'Raw Data'!I10),"\$([A-Z]+)\$[0-9]+"))} | ... P10: {=IFERROR(IF(OR('Raw Data'!P10="",LEN(TRIM('Raw Data'!P10))=0),_xlfn.REGEXEXTRACT(CELL("address",'Raw Data'!P10),"\$([A-Z]+)\$[0-9]+"),""),_xlfn.REGEXEXTRACT(CELL("address",'Raw Data'!P10),"\$([A-Z]+)\$[0-9]+"))}
B11: {=IFERROR(IF(OR('Raw Data'!B11="",LEN(TRIM('Raw Data'!B11))=0),_xlfn.REGEXEXTRACT(CELL("address",'Raw Data'!B11),"\$([A-Z]+)\$[0-9]+"),""),_xlfn.REGEXEXTRACT(CELL("address",'Raw Data'!B11),"\$([A-Z]+)\$[0-9]+"))} | C11: {=IFERROR(IF(OR('Raw Data'!C11="",LEN(TRIM('Raw Data'!C11))=0),_xlfn.REGEXEXTRACT(CELL("address",'Raw Data'!C11),"\$([A-Z]+)\$[0-9]+"),""),_xlfn.REGEXEXTRACT(CELL("address",'Raw Data'!C11),"\$([A-Z]+)\$[0-9]+"))} | D11: {=IFERROR(IF(OR('Raw Data'!D11="",LEN(TRIM('Raw Data'!D11))=0),_xlfn.REGEXEXTRACT(CELL("address",'Raw Data'!D11),"\$([A-Z]+)\$[0-9]+"),""),_xlfn.REGEXEXTRACT(CELL("address",'Raw Data'!D11),"\$([A-Z]+)\$[0-9]+"))} | E11: {=IFERROR(IF(OR('Raw Data'!E11="",LEN(TRIM('Raw Data'!E11))=0),_xlfn.REGEXEXTRACT(CELL("address",'Raw Data'!E11),"\$([A-Z]+)\$[0-9]+"),""),_xlfn.REGEXEXTRACT(CELL("address",'Raw Data'!E11),"\$([A-Z]+)\$[0-9]+"))} | F11: {=IFERROR(IF(OR('Raw Data'!F11="",LEN(TRIM('Raw Data'!F11))=0),_xlfn.REGEXEXTRACT(CELL("address",'Raw Data'!F11),"\$([A-Z]+)\$[0-9]+"),""),_xlfn.REGEXEXTRACT(CELL("address",'Raw Data'!F11),"\$([A-Z]+)\$[0-9]+"))} | G11: {=IFERROR(IF(OR('Raw Data'!G11="",LEN(TRIM('Raw Data'!G11))=0),_xlfn.REGEXEXTRACT(CELL("address",'Raw Data'!G11),"\$([A-Z]+)\$[0-9]+"),""),_xlfn.REGEXEXTRACT(CELL("address",'Raw Data'!G11),"\$([A-Z]+)\$[0-9]+"))} | H11: {=IFERROR(IF(OR('Raw Data'!H11="",LEN(TRIM('Raw Data'!H11))=0),_xlfn.REGEXEXTRACT(CELL("address",'Raw Data'!H11),"\$([A-Z]+)\$[0-9]+"),""),_xlfn.REGEXEXTRACT(CELL("address",'Raw Data'!H11),"\$([A-Z]+)\$[0-9]+"))} | I11: {=IFERROR(IF(OR('Raw Data'!I11="",LEN(TRIM('Raw Data'!I11))=0),_xlfn.REGEXEXTRACT(CELL("address",'Raw Data'!I11),"\$([A-Z]+)\$[0-9]+"),""),_xlfn.REGEXEXTRACT(CELL("address",'Raw Data'!I11),"\$([A-Z]+)\$[0-9]+"))} | ... P11: {=IFERROR(IF(OR('Raw Data'!P11="",LEN(TRIM('Raw Data'!P11))=0),_xlfn.REGEXEXTRACT(CELL("address",'Raw Data'!P11),"\$([A-Z]+)\$[0-9]+"),""),_xlfn.REGEXEXTRACT(CELL("address",'Raw Data'!P11),"\$([A-Z]+)\$[0-9]+"))}
B12: {=IFERROR(IF(OR('Raw Data'!B12="",LEN(TRIM('Raw Data'!B12))=0),_xlfn.REGEXEXTRACT(CELL("address",'Raw Data'!B12),"\$([A-Z]+)\$[0-9]+"),""),_xlfn.REGEXEXTRACT(CELL("address",'Raw Data'!B12),"\$([A-Z]+)\$[0-9]+"))} | C12: {=IFERROR(IF(OR('Raw Data'!C12="",LEN(TRIM('Raw Data'!C12))=0),_xlfn.REGEXEXTRACT(CELL("address",'Raw Data'!C12),"\$([A-Z]+)\$[0-9]+"),""),_xlfn.REGEXEXTRACT(CELL("address",'Raw Data'!C12),"\$([A-Z]+)\$[0-9]+"))} | D12: {=IFERROR(IF(OR('Raw Data'!D12="",LEN(TRIM('Raw Data'!D12))=0),_xlfn.REGEXEXTRACT(CELL("address",'Raw Data'!D12),"\$([A-Z]+)\$[0-9]+"),""),_xlfn.REGEXEXTRACT(CELL("address",'Raw Data'!D12),"\$([A-Z]+)\$[0-9]+"))} | E12: {=IFERROR(IF(OR('Raw Data'!E12="",LEN(TRIM('Raw Data'!E12))=0),_xlfn.REGEXEXTRACT(CELL("address",'Raw Data'!E12),"\$([A-Z]+)\$[0-9]+"),""),_xlfn.REGEXEXTRACT(CELL("address",'Raw Data'!E12),"\$([A-Z]+)\$[0-9]+"))} | F12: {=IFERROR(IF(OR('Raw Data'!F12="",LEN(TRIM('Raw Data'!F12))=0),_xlfn.REGEXEXTRACT(CELL("address",'Raw Data'!F12),"\$([A-Z]+)\$[0-9]+"),""),_xlfn.REGEXEXTRACT(CELL("address",'Raw Data'!F12),"\$([A-Z]+)\$[0-9]+"))} | G12: {=IFERROR(IF(OR('Raw Data'!G12="",LEN(TRIM('Raw Data'!G12))=0),_xlfn.REGEXEXTRACT(CELL("address",'Raw Data'!G12),"\$([A-Z]+)\$[0-9]+"),""),_xlfn.REGEXEXTRACT(CELL("address",'Raw Data'!G12),"\$([A-Z]+)\$[0-9]+"))} | H12: {=IFERROR(IF(OR('Raw Data'!H12="",LEN(TRIM('Raw Data'!H12))=0),_xlfn.REGEXEXTRACT(CELL("address",'Raw Data'!H12),"\$([A-Z]+)\$[0-9]+"),""),_xlfn.REGEXEXTRACT(CELL("address",'Raw Data'!H12),"\$([A-Z]+)\$[0-9]+"))} | I12: {=IFERROR(IF(OR('Raw Data'!I12="",LEN(TRIM('Raw Data'!I12))=0),_xlfn.REGEXEXTRACT(CELL("address",'Raw Data'!I12),"\$([A-Z]+)\$[0-9]+"),""),_xlfn.REGEXEXTRACT(CELL("address",'Raw Data'!I12),"\$([A-Z]+)\$[0-9]+"))} | ... P12: {=IFERROR(IF(OR('Raw Data'!P12="",LEN(TRIM('Raw Data'!P12))=0),_xlfn.REGEXEXTRACT(CELL("address",'Raw Data'!P12),"\$([A-Z]+)\$[0-9]+"),""),_xlfn.REGEXEXTRACT(CELL("address",'Raw Data'!P12),"\$([A-Z]+)\$[0-9]+"))}
B13: {=IFERROR(IF(OR('Raw Data'!B13="",LEN(TRIM('Raw Data'!B13))=0),_xlfn.REGEXEXTRACT(CELL("address",'Raw Data'!B13),"\$([A-Z]+)\$[0-9]+"),""),_xlfn.REGEXEXTRACT(CELL("address",'Raw Data'!B13),"\$([A-Z]+)\$[0-9]+"))} | C13: {=IFERROR(IF(OR('Raw Data'!C13="",LEN(TRIM('Raw Data'!C13))=0),_xlfn.REGEXEXTRACT(CELL("address",'Raw Data'!C13),"\$([A-Z]+)\$[0-9]+"),""),_xlfn.REGEXEXTRACT(CELL("address",'Raw Data'!C13),"\$([A-Z]+)\$[0-9]+"))} | D13: {=IFERROR(IF(OR('Raw Data'!D13="",LEN(TRIM('Raw Data'!D13))=0),_xlfn.REGEXEXTRACT(CELL("address",'Raw Data'!D13),"\$([A-Z]+)\$[0-9]+"),""),_xlfn.REGEXEXTRACT(CELL("address",'Raw Data'!D13),"\$([A-Z]+)\$[0-9]+"))} | E13: {=IFERROR(IF(OR('Raw Data'!E13="",LEN(TRIM('Raw Data'!E13))=0),_xlfn.REGEXEXTRACT(CELL("address",'Raw Data'!E13),"\$([A-Z]+)\$[0-9]+"),""),_xlfn.REGEXEXTRACT(CELL("address",'Raw Data'!E13),"\$([A-Z]+)\$[0-9]+"))} | F13: {=IFERROR(IF(OR('Raw Data'!F13="",LEN(TRIM('Raw Data'!F13))=0),_xlfn.REGEXEXTRACT(CELL("address",'Raw Data'!F13),"\$([A-Z]+)\$[0-9]+"),""),_xlfn.REGEXEXTRACT(CELL("address",'Raw Data'!F13),"\$([A-Z]+)\$[0-9]+"))} | G13: {=IFERROR(IF(OR('Raw Data'!G13="",LEN(TRIM('Raw Data'!G13))=0),_xlfn.REGEXEXTRACT(CELL("address",'Raw Data'!G13),"\$([A-Z]+)\$[0-9]+"),""),_xlfn.REGEXEXTRACT(CELL("address",'Raw Data'!G13),"\$([A-Z]+)\$[0-9]+"))} | H13: {=IFERROR(IF(OR('Raw Data'!H13="",LEN(TRIM('Raw Data'!H13))=0),_xlfn.REGEXEXTRACT(CELL("address",'Raw Data'!H13),"\$([A-Z]+)\$[0-9]+"),""),_xlfn.REGEXEXTRACT(CELL("address",'Raw Data'!H13),"\$([A-Z]+)\$[0-9]+"))} | I13: {=IFERROR(IF(OR('Raw Data'!I13="",LEN(TRIM('Raw Data'!I13))=0),_xlfn.REGEXEXTRACT(CELL("address",'Raw Data'!I13),"\$([A-Z]+)\$[0-9]+"),""),_xlfn.REGEXEXTRACT(CELL("address",'Raw Data'!I13),"\$([A-Z]+)\$[0-9]+"))} | ... P13: {=IFERROR(IF(OR('Raw Data'!P13="",LEN(TRIM('Raw Data'!P13))=0),_xlfn.REGEXEXTRACT(CELL("address",'Raw Data'!P13),"\$([A-Z]+)\$[0-9]+"),""),_xlfn.REGEXEXTRACT(CELL("address",'Raw Data'!P13),"\$([A-Z]+)\$[0-9]+"))}
B14: {=IFERROR(IF(OR('Raw Data'!B14="",LEN(TRIM('Raw Data'!B14))=0),_xlfn.REGEXEXTRACT(CELL("address",'Raw Data'!B14),"\$([A-Z]+)\$[0-9]+"),""),_xlfn.REGEXEXTRACT(CELL("address",'Raw Data'!B14),"\$([A-Z]+)\$[0-9]+"))} | C14: {=IFERROR(IF(OR('Raw Data'!C14="",LEN(TRIM('Raw Data'!C14))=0),_xlfn.REGEXEXTRACT(CELL("address",'Raw Data'!C14),"\$([A-Z]+)\$[0-9]+"),""),_xlfn.REGEXEXTRACT(CELL("address",'Raw Data'!C14),"\$([A-Z]+)\$[0-9]+"))} | D14: {=IFERROR(IF(OR('Raw Data'!D14="",LEN(TRIM('Raw Data'!D14))=0),_xlfn.REGEXEXTRACT(CELL("address",'Raw Data'!D14),"\$([A-Z]+)\$[0-9]+"),""),_xlfn.REGEXEXTRACT(CELL("address",'Raw Data'!D14),"\$([A-Z]+)\$[0-9]+"))} | E14: {=IFERROR(IF(OR('Raw Data'!E14="",LEN(TRIM('Raw Data'!E14))=0),_xlfn.REGEXEXTRACT(CELL("address",'Raw Data'!E14),"\$([A-Z]+)\$[0-9]+"),""),_xlfn.REGEXEXTRACT(CELL("address",'Raw Data'!E14),"\$([A-Z]+)\$[0-9]+"))} | F14: {=IFERROR(IF(OR('Raw Data'!F14="",LEN(TRIM('Raw Data'!F14))=0),_xlfn.REGEXEXTRACT(CELL("address",'Raw Data'!F14),"\$([A-Z]+)\$[0-9]+"),""),_xlfn.REGEXEXTRACT(CELL("address",'Raw Data'!F14),"\$([A-Z]+)\$[0-9]+"))} | G14: {=IFERROR(IF(OR('Raw Data'!G14="",LEN(TRIM('Raw Data'!G14))=0),_xlfn.REGEXEXTRACT(CELL("address",'Raw Data'!G14),"\$([A-Z]+)\$[0-9]+"),""),_xlfn.REGEXEXTRACT(CELL("address",'Raw Data'!G14),"\$([A-Z]+)\$[0-9]+"))} | H14: {=IFERROR(IF(OR('Raw Data'!H14="",LEN(TRIM('Raw Data'!H14))=0),_xlfn.REGEXEXTRACT(CELL("address",'Raw Data'!H14),"\$([A-Z]+)\$[0-9]+"),""),_xlfn.REGEXEXTRACT(CELL("address",'Raw Data'!H14),"\$([A-Z]+)\$[0-9]+"))} | I14: {=IFERROR(IF(OR('Raw Data'!I14="",LEN(TRIM('Raw Data'!I14))=0),_xlfn.REGEXEXTRACT(CELL("address",'Raw Data'!I14),"\$([A-Z]+)\$[0-9]+"),""),_xlfn.REGEXEXTRACT(CELL("address",'Raw Data'!I14),"\$([A-Z]+)\$[0-9]+"))} | ... P14: {=IFERROR(IF(OR('Raw Data'!P14="",LEN(TRIM('Raw Data'!P14))=0),_xlfn.REGEXEXTRACT(CELL("address",'Raw Data'!P14),"\$([A-Z]+)\$[0-9]+"),""),_xlfn.REGEXEXTRACT(CELL("address",'Raw Data'!P14),"\$([A-Z]+)\$[0-9]+"))}
B15: {=IFERROR(IF(OR('Raw Data'!B15="",LEN(TRIM('Raw Data'!B15))=0),_xlfn.REGEXEXTRACT(CELL("address",'Raw Data'!B15),"\$([A-Z]+)\$[0-9]+"),""),_xlfn.REGEXEXTRACT(CELL("address",'Raw Data'!B15),"\$([A-Z]+)\$[0-9]+"))} | C15: {=IFERROR(IF(OR('Raw Data'!C15="",LEN(TRIM('Raw Data'!C15))=0),_xlfn.REGEXEXTRACT(CELL("address",'Raw Data'!C15),"\$([A-Z]+)\$[0-9]+"),""),_xlfn.REGEXEXTRACT(CELL("address",'Raw Data'!C15),"\$([A-Z]+)\$[0-9]+"))} | D15: {=IFERROR(IF(OR('Raw Data'!D15="",LEN(TRIM('Raw Data'!D15))=0),_xlfn.REGEXEXTRACT(CELL("address",'Raw Data'!D15),"\$([A-Z]+)\$[0-9]+"),""),_xlfn.REGEXEXTRACT(CELL("address",'Raw Data'!D15),"\$([A-Z]+)\$[0-9]+"))} | E15: {=IFERROR(IF(OR('Raw Data'!E15="",LEN(TRIM('Raw Data'!E15))=0),_xlfn.REGEXEXTRACT(CELL("address",'Raw Data'!E15),"\$([A-Z]+)\$[0-9]+"),""),_xlfn.REGEXEXTRACT(CELL("address",'Raw Data'!E15),"\$([A-Z]+)\$[0-9]+"))} | F15: {=IFERROR(IF(OR('Raw Data'!F15="",LEN(TRIM('Raw Data'!F15))=0),_xlfn.REGEXEXTRACT(CELL("address",'Raw Data'!F15),"\$([A-Z]+)\$[0-9]+"),""),_xlfn.REGEXEXTRACT(CELL("address",'Raw Data'!F15),"\$([A-Z]+)\$[0-9]+"))} | G15: {=IFERROR(IF(OR('Raw Data'!G15="",LEN(TRIM('Raw Data'!G15))=0),_xlfn.REGEXEXTRACT(CELL("address",'Raw Data'!G15),"\$([A-Z]+)\$[0-9]+"),""),_xlfn.REGEXEXTRACT(CELL("address",'Raw Data'!G15),"\$([A-Z]+)\$[0-9]+"))} | H15: {=IFERROR(IF(OR('Raw Data'!H15="",LEN(TRIM('Raw Data'!H15))=0),_xlfn.REGEXEXTRACT(CELL("address",'Raw Data'!H15),"\$([A-Z]+)\$[0-9]+"),""),_xlfn.REGEXEXTRACT(CELL("address",'Raw Data'!H15),"\$([A-Z]+)\$[0-9]+"))} | I15: {=IFERROR(IF(OR('Raw Data'!I15="",LEN(TRIM('Raw Data'!I15))=0),_xlfn.REGEXEXTRACT(CELL("address",'Raw Data'!I15),"\$([A-Z]+)\$[0-9]+"),""),_xlfn.REGEXEXTRACT(CELL("address",'Raw Data'!I15),"\$([A-Z]+)\$[0-9]+"))} | ... P15: {=IFERROR(IF(OR('Raw Data'!P15="",LEN(TRIM('Raw Data'!P15))=0),_xlfn.REGEXEXTRACT(CELL("address",'Raw Data'!P15),"\$([A-Z]+)\$[0-9]+"),""),_xlfn.REGEXEXTRACT(CELL("address",'Raw Data'!P15),"\$([A-Z]+)\$[0-9]+"))}
B16: {=IFERROR(IF(OR('Raw Data'!B16="",LEN(TRIM('Raw Data'!B16))=0),_xlfn.REGEXEXTRACT(CELL("address",'Raw Data'!B16),"\$([A-Z]+)\$[0-9]+"),""),_xlfn.REGEXEXTRACT(CELL("address",'Raw Data'!B16),"\$([A-Z]+)\$[0-9]+"))} | C16: {=IFERROR(IF(OR('Raw Data'!C16="",LEN(TRIM('Raw Data'!C16))=0),_xlfn.REGEXEXTRACT(CELL("address",'Raw Data'!C16),"\$([A-Z]+)\$[0-9]+"),""),_xlfn.REGEXEXTRACT(CELL("address",'Raw Data'!C16),"\$([A-Z]+)\$[0-9]+"))} | D16: {=IFERROR(IF(OR('Raw Data'!D16="",LEN(TRIM('Raw Data'!D16))=0),_xlfn.REGEXEXTRACT(CELL("address",'Raw Data'!D16),"\$([A-Z]+)\$[0-9]+"),""),_xlfn.REGEXEXTRACT(CELL("address",'Raw Data'!D16),"\$([A-Z]+)\$[0-9]+"))} | E16: {=IFERROR(IF(OR('Raw Data'!E16="",LEN(TRIM('Raw Data'!E16))=0),_xlfn.REGEXEXTRACT(CELL("address",'Raw Data'!E16),"\$([A-Z]+)\$[0-9]+"),""),_xlfn.REGEXEXTRACT(CELL("address",'Raw Data'!E16),"\$([A-Z]+)\$[0-9]+"))} | F16: {=IFERROR(IF(OR('Raw Data'!F16="",LEN(TRIM('Raw Data'!F16))=0),_xlfn.REGEXEXTRACT(CELL("address",'Raw Data'!F16),"\$([A-Z]+)\$[0-9]+"),""),_xlfn.REGEXEXTRACT(CELL("address",'Raw Data'!F16),"\$([A-Z]+)\$[0-9]+"))} | G16: {=IFERROR(IF(OR('Raw Data'!G16="",LEN(TRIM('Raw Data'!G16))=0),_xlfn.REGEXEXTRACT(CELL("address",'Raw Data'!G16),"\$([A-Z]+)\$[0-9]+"),""),_xlfn.REGEXEXTRACT(CELL("address",'Raw Data'!G16),"\$([A-Z]+)\$[0-9]+"))} | H16: {=IFERROR(IF(OR('Raw Data'!H16="",LEN(TRIM('Raw Data'!H16))=0),_xlfn.REGEXEXTRACT(CELL("address",'Raw Data'!H16),"\$([A-Z]+)\$[0-9]+"),""),_xlfn.REGEXEXTRACT(CELL("address",'Raw Data'!H16),"\$([A-Z]+)\$[0-9]+"))} | I16: {=IFERROR(IF(OR('Raw Data'!I16="",LEN(TRIM('Raw Data'!I16))=0),_xlfn.REGEXEXTRACT(CELL("address",'Raw Data'!I16),"\$([A-Z]+)\$[0-9]+"),""),_xlfn.REGEXEXTRACT(CELL("address",'Raw Data'!I16),"\$([A-Z]+)\$[0-9]+"))} | ... P16: {=IFERROR(IF(OR('Raw Data'!P16="",LEN(TRIM('Raw Data'!P16))=0),_xlfn.REGEXEXTRACT(CELL("address",'Raw Data'!P16),"\$([A-Z]+)\$[0-9]+"),""),_xlfn.REGEXEXTRACT(CELL("address",'Raw Data'!P16),"\$([A-Z]+)\$[0-9]+"))}
B17: {=IFERROR(IF(OR('Raw Data'!B17="",LEN(TRIM('Raw Data'!B17))=0),_xlfn.REGEXEXTRACT(CELL("address",'Raw Data'!B17),"\$([A-Z]+)\$[0-9]+"),""),_xlfn.REGEXEXTRACT(CELL("address",'Raw Data'!B17),"\$([A-Z]+)\$[0-9]+"))} | C17: {=IFERROR(IF(OR('Raw Data'!C17="",LEN(TRIM('Raw Data'!C17))=0),_xlfn.REGEXEXTRACT(CELL("address",'Raw Data'!C17),"\$([A-Z]+)\$[0-9]+"),""),_xlfn.REGEXEXTRACT(CELL("address",'Raw Data'!C17),"\$([A-Z]+)\$[0-9]+"))} | D17: {=IFERROR(IF(OR('Raw Data'!D17="",LEN(TRIM('Raw Data'!D17))=0),_xlfn.REGEXEXTRACT(CELL("address",'Raw Data'!D17),"\$([A-Z]+)\$[0-9]+"),""),_xlfn.REGEXEXTRACT(CELL("address",'Raw Data'!D17),"\$([A-Z]+)\$[0-9]+"))} | E17: {=IFERROR(IF(OR('Raw Data'!E17="",LEN(TRIM('Raw Data'!E17))=0),_xlfn.REGEXEXTRACT(CELL("address",'Raw Data'!E17),"\$([A-Z]+)\$[0-9]+"),""),_xlfn.REGEXEXTRACT(CELL("address",'Raw Data'!E17),"\$([A-Z]+)\$[0-9]+"))} | F17: {=IFERROR(IF(OR('Raw Data'!F17="",LEN(TRIM('Raw Data'!F17))=0),_xlfn.REGEXEXTRACT(CELL("address",'Raw Data'!F17),"\$([A-Z]+)\$[0-9]+"),""),_xlfn.REGEXEXTRACT(CELL("address",'Raw Data'!F17),"\$([A-Z]+)\$[0-9]+"))} | G17: {=IFERROR(IF(OR('Raw Data'!G17="",LEN(TRIM('Raw Data'!G17))=0),_xlfn.REGEXEXTRACT(CELL("address",'Raw Data'!G17),"\$([A-Z]+)\$[0-9]+"),""),_xlfn.REGEXEXTRACT(CELL("address",'Raw Data'!G17),"\$([A-Z]+)\$[0-9]+"))} | H17: {=IFERROR(IF(OR('Raw Data'!H17="",LEN(TRIM('Raw Data'!H17))=0),_xlfn.REGEXEXTRACT(CELL("address",'Raw Data'!H17),"\$([A-Z]+)\$[0-9]+"),""),_xlfn.REGEXEXTRACT(CELL("address",'Raw Data'!H17),"\$([A-Z]+)\$[0-9]+"))} | I17: {=IFERROR(IF(OR('Raw Data'!I17="",LEN(TRIM('Raw Data'!I17))=0),_xlfn.REGEXEXTRACT(CELL("address",'Raw Data'!I17),"\$([A-Z]+)\$[0-9]+"),""),_xlfn.REGEXEXTRACT(CELL("address",'Raw Data'!I17),"\$([A-Z]+)\$[0-9]+"))} | ... P17: {=IFERROR(IF(OR('Raw Data'!P17="",LEN(TRIM('Raw Data'!P17))=0),_xlfn.REGEXEXTRACT(CELL("address",'Raw Data'!P17),"\$([A-Z]+)\$[0-9]+"),""),_xlfn.REGEXEXTRACT(CELL("address",'Raw Data'!P17),"\$([A-Z]+)\$[0-9]+"))}
B18: {=IFERROR(IF(OR('Raw Data'!B18="",LEN(TRIM('Raw Data'!B18))=0),_xlfn.REGEXEXTRACT(CELL("address",'Raw Data'!B18),"\$([A-Z]+)\$[0-9]+"),""),_xlfn.REGEXEXTRACT(CELL("address",'Raw Data'!B18),"\$([A-Z]+)\$[0-9]+"))} | C18: {=IFERROR(IF(OR('Raw Data'!C18="",LEN(TRIM('Raw Data'!C18))=0),_xlfn.REGEXEXTRACT(CELL("address",'Raw Data'!C18),"\$([A-Z]+)\$[0-9]+"),""),_xlfn.REGEXEXTRACT(CELL("address",'Raw Data'!C18),"\$([A-Z]+)\$[0-9]+"))} | D18: {=IFERROR(IF(OR('Raw Data'!D18="",LEN(TRIM('Raw Data'!D18))=0),_xlfn.REGEXEXTRACT(CELL("address",'Raw Data'!D18),"\$([A-Z]+)\$[0-9]+"),""),_xlfn.REGEXEXTRACT(CELL("address",'Raw Data'!D18),"\$([A-Z]+)\$[0-9]+"))} | E18: {=IFERROR(IF(OR('Raw Data'!E18="",LEN(TRIM('Raw Data'!E18))=0),_xlfn.REGEXEXTRACT(CELL("address",'Raw Data'!E18),"\$([A-Z]+)\$[0-9]+"),""),_xlfn.REGEXEXTRACT(CELL("address",'Raw Data'!E18),"\$([A-Z]+)\$[0-9]+"))} | F18: {=IFERROR(IF(OR('Raw Data'!F18="",LEN(TRIM('Raw Data'!F18))=0),_xlfn.REGEXEXTRACT(CELL("address",'Raw Data'!F18),"\$([A-Z]+)\$[0-9]+"),""),_xlfn.REGEXEXTRACT(CELL("address",'Raw Data'!F18),"\$([A-Z]+)\$[0-9]+"))} | G18: {=IFERROR(IF(OR('Raw Data'!G18="",LEN(TRIM('Raw Data'!G18))=0),_xlfn.REGEXEXTRACT(CELL("address",'Raw Data'!G18),"\$([A-Z]+)\$[0-9]+"),""),_xlfn.REGEXEXTRACT(CELL("address",'Raw Data'!G18),"\$([A-Z]+)\$[0-9]+"))} | H18: {=IFERROR(IF(OR('Raw Data'!H18="",LEN(TRIM('Raw Data'!H18))=0),_xlfn.REGEXEXTRACT(CELL("address",'Raw Data'!H18),"\$([A-Z]+)\$[0-9]+"),""),_xlfn.REGEXEXTRACT(CELL("address",'Raw Data'!H18),"\$([A-Z]+)\$[0-9]+"))} | I18: {=IFERROR(IF(OR('Raw Data'!I18="",LEN(TRIM('Raw Data'!I18))=0),_xlfn.REGEXEXTRACT(CELL("address",'Raw Data'!I18),"\$([A-Z]+)\$[0-9]+"),""),_xlfn.REGEXEXTRACT(CELL("address",'Raw Data'!I18),"\$([A-Z]+)\$[0-9]+"))} | ... P18: {=IFERROR(IF(OR('Raw Data'!P18="",LEN(TRIM('Raw Data'!P18))=0),_xlfn.REGEXEXTRACT(CELL("address",'Raw Data'!P18),"\$([A-Z]+)\$[0-9]+"),""),_xlfn.REGEXEXTRACT(CELL("address",'Raw Data'!P18),"\$([A-Z]+)\$[0-9]+"))}
B19: {=IFERROR(IF(OR('Raw Data'!B19="",LEN(TRIM('Raw Data'!B19))=0),_xlfn.REGEXEXTRACT(CELL("address",'Raw Data'!B19),"\$([A-Z]+)\$[0-9]+"),""),_xlfn.REGEXEXTRACT(CELL("address",'Raw Data'!B19),"\$([A-Z]+)\$[0-9]+"))} | C19: {=IFERROR(IF(OR('Raw Data'!C19="",LEN(TRIM('Raw Data'!C19))=0),_xlfn.REGEXEXTRACT(CELL("address",'Raw Data'!C19),"\$([A-Z]+)\$[0-9]+"),""),_xlfn.REGEXEXTRACT(CELL("address",'Raw Data'!C19),"\$([A-Z]+)\$[0-9]+"))} | D19: {=IFERROR(IF(OR('Raw Data'!D19="",LEN(TRIM('Raw Data'!D19))=0),_xlfn.REGEXEXTRACT(CELL("address",'Raw Data'!D19),"\$([A-Z]+)\$[0-9]+"),""),_xlfn.REGEXEXTRACT(CELL("address",'Raw Data'!D19),"\$([A-Z]+)\$[0-9]+"))} | E19: {=IFERROR(IF(OR('Raw Data'!E19="",LEN(TRIM('Raw Data'!E19))=0),_xlfn.REGEXEXTRACT(CELL("address",'Raw Data'!E19),"\$([A-Z]+)\$[0-9]+"),""),_xlfn.REGEXEXTRACT(CELL("address",'Raw Data'!E19),"\$([A-Z]+)\$[0-9]+"))} | F19: {=IFERROR(IF(OR('Raw Data'!F19="",LEN(TRIM('Raw Data'!F19))=0),_xlfn.REGEXEXTRACT(CELL("address",'Raw Data'!F19),"\$([A-Z]+)\$[0-9]+"),""),_xlfn.REGEXEXTRACT(CELL("address",'Raw Data'!F19),"\$([A-Z]+)\$[0-9]+"))} | G19: {=IFERROR(IF(OR('Raw Data'!G19="",LEN(TRIM('Raw Data'!G19))=0),_xlfn.REGEXEXTRACT(CELL("address",'Raw Data'!G19),"\$([A-Z]+)\$[0-9]+"),""),_xlfn.REGEXEXTRACT(CELL("address",'Raw Data'!G19),"\$([A-Z]+)\$[0-9]+"))} | H19: {=IFERROR(IF(OR('Raw Data'!H19="",LEN(TRIM('Raw Data'!H19))=0),_xlfn.REGEXEXTRACT(CELL("address",'Raw Data'!H19),"\$([A-Z]+)\$[0-9]+"),""),_xlfn.REGEXEXTRACT(CELL("address",'Raw Data'!H19),"\$([A-Z]+)\$[0-9]+"))} | I19: {=IFERROR(IF(OR('Raw Data'!I19="",LEN(TRIM('Raw Data'!I19))=0),_xlfn.REGEXEXTRACT(CELL("address",'Raw Data'!I19),"\$([A-Z]+)\$[0-9]+"),""),_xlfn.REGEXEXTRACT(CELL("address",'Raw Data'!I19),"\$([A-Z]+)\$[0-9]+"))} | ... P19: {=IFERROR(IF(OR('Raw Data'!P19="",LEN(TRIM('Raw Data'!P19))=0),_xlfn.REGEXEXTRACT(CELL("address",'Raw Data'!P19),"\$([A-Z]+)\$[0-9]+"),""),_xlfn.REGEXEXTRACT(CELL("address",'Raw Data'!P19),"\$([A-Z]+)\$[0-9]+"))}
B20: {=IFERROR(IF(OR('Raw Data'!B20="",LEN(TRIM('Raw Data'!B20))=0),_xlfn.REGEXEXTRACT(CELL("address",'Raw Data'!B20),"\$([A-Z]+)\$[0-9]+"),""),_xlfn.REGEXEXTRACT(CELL("address",'Raw Data'!B20),"\$([A-Z]+)\$[0-9]+"))} | C20: {=IFERROR(IF(OR('Raw Data'!C20="",LEN(TRIM('Raw Data'!C20))=0),_xlfn.REGEXEXTRACT(CELL("address",'Raw Data'!C20),"\$([A-Z]+)\$[0-9]+"),""),_xlfn.REGEXEXTRACT(CELL("address",'Raw Data'!C20),"\$([A-Z]+)\$[0-9]+"))} | D20: {=IFERROR(IF(OR('Raw Data'!D20="",LEN(TRIM('Raw Data'!D20))=0),_xlfn.REGEXEXTRACT(CELL("address",'Raw Data'!D20),"\$([A-Z]+)\$[0-9]+"),""),_xlfn.REGEXEXTRACT(CELL("address",'Raw Data'!D20),"\$([A-Z]+)\$[0-9]+"))} | E20: {=IFERROR(IF(OR('Raw Data'!E20="",LEN(TRIM('Raw Data'!E20))=0),_xlfn.REGEXEXTRACT(CELL("address",'Raw Data'!E20),"\$([A-Z]+)\$[0-9]+"),""),_xlfn.REGEXEXTRACT(CELL("address",'Raw Data'!E20),"\$([A-Z]+)\$[0-9]+"))} | F20: {=IFERROR(IF(OR('Raw Data'!F20="",LEN(TRIM('Raw Data'!F20))=0),_xlfn.REGEXEXTRACT(CELL("address",'Raw Data'!F20),"\$([A-Z]+)\$[0-9]+"),""),_xlfn.REGEXEXTRACT(CELL("address",'Raw Data'!F20),"\$([A-Z]+)\$[0-9]+"))} | G20: {=IFERROR(IF(OR('Raw Data'!G20="",LEN(TRIM('Raw Data'!G20))=0),_xlfn.REGEXEXTRACT(CELL("address",'Raw Data'!G20),"\$([A-Z]+)\$[0-9]+"),""),_xlfn.REGEXEXTRACT(CELL("address",'Raw Data'!G20),"\$([A-Z]+)\$[0-9]+"))} | H20: {=IFERROR(IF(OR('Raw Data'!H20="",LEN(TRIM('Raw Data'!H20))=0),_xlfn.REGEXEXTRACT(CELL("address",'Raw Data'!H20),"\$([A-Z]+)\$[0-9]+"),""),_xlfn.REGEXEXTRACT(CELL("address",'Raw Data'!H20),"\$([A-Z]+)\$[0-9]+"))} | I20: {=IFERROR(IF(OR('Raw Data'!I20="",LEN(TRIM('Raw Data'!I20))=0),_xlfn.REGEXEXTRACT(CELL("address",'Raw Data'!I20),"\$([A-Z]+)\$[0-9]+"),""),_xlfn.REGEXEXTRACT(CELL("address",'Raw Data'!I20),"\$([A-Z]+)\$[0-9]+"))} | ... P20: {=IFERROR(IF(OR('Raw Data'!P20="",LEN(TRIM('Raw Data'!P20))=0),_xlfn.REGEXEXTRACT(CELL("address",'Raw Data'!P20),"\$([A-Z]+)\$[0-9]+"),""),_xlfn.REGEXEXTRACT(CELL("address",'Raw Data'!P20),"\$([A-Z]+)\$[0-9]+"))}
B21: {=IFERROR(IF(OR('Raw Data'!B21="",LEN(TRIM('Raw Data'!B21))=0),_xlfn.REGEXEXTRACT(CELL("address",'Raw Data'!B21),"\$([A-Z]+)\$[0-9]+"),""),_xlfn.REGEXEXTRACT(CELL("address",'Raw Data'!B21),"\$([A-Z]+)\$[0-9]+"))} | C21: {=IFERROR(IF(OR('Raw Data'!C21="",LEN(TRIM('Raw Data'!C21))=0),_xlfn.REGEXEXTRACT(CELL("address",'Raw Data'!C21),"\$([A-Z]+)\$[0-9]+"),""),_xlfn.REGEXEXTRACT(CELL("address",'Raw Data'!C21),"\$([A-Z]+)\$[0-9]+"))} | D21: {=IFERROR(IF(OR('Raw Data'!D21="",LEN(TRIM('Raw Data'!D21))=0),_xlfn.REGEXEXTRACT(CELL("address",'Raw Data'!D21),"\$([A-Z]+)\$[0-9]+"),""),_xlfn.REGEXEXTRACT(CELL("address",'Raw Data'!D21),"\$([A-Z]+)\$[0-9]+"))} | E21: {=IFERROR(IF(OR('Raw Data'!E21="",LEN(TRIM('Raw Data'!E21))=0),_xlfn.REGEXEXTRACT(CELL("address",'Raw Data'!E21),"\$([A-Z]+)\$[0-9]+"),""),_xlfn.REGEXEXTRACT(CELL("address",'Raw Data'!E21),"\$([A-Z]+)\$[0-9]+"))} | F21: {=IFERROR(IF(OR('Raw Data'!F21="",LEN(TRIM('Raw Data'!F21))=0),_xlfn.REGEXEXTRACT(CELL("address",'Raw Data'!F21),"\$([A-Z]+)\$[0-9]+"),""),_xlfn.REGEXEXTRACT(CELL("address",'Raw Data'!F21),"\$([A-Z]+)\$[0-9]+"))} | G21: {=IFERROR(IF(OR('Raw Data'!G21="",LEN(TRIM('Raw Data'!G21))=0),_xlfn.REGEXEXTRACT(CELL("address",'Raw Data'!G21),"\$([A-Z]+)\$[0-9]+"),""),_xlfn.REGEXEXTRACT(CELL("address",'Raw Data'!G21),"\$([A-Z]+)\$[0-9]+"))} | H21: {=IFERROR(IF(OR('Raw Data'!H21="",LEN(TRIM('Raw Data'!H21))=0),_xlfn.REGEXEXTRACT(CELL("address",'Raw Data'!H21),"\$([A-Z]+)\$[0-9]+"),""),_xlfn.REGEXEXTRACT(CELL("address",'Raw Data'!H21),"\$([A-Z]+)\$[0-9]+"))} | I21: {=IFERROR(IF(OR('Raw Data'!I21="",LEN(TRIM('Raw Data'!I21))=0),_xlfn.REGEXEXTRACT(CELL("address",'Raw Data'!I21),"\$([A-Z]+)\$[0-9]+"),""),_xlfn.REGEXEXTRACT(CELL("address",'Raw Data'!I21),"\$([A-Z]+)\$[0-9]+"))} | ... P21: {=IFERROR(IF(OR('Raw Data'!P21="",LEN(TRIM('Raw Data'!P21))=0),_xlfn.REGEXEXTRACT(CELL("address",'Raw Data'!P21),"\$([A-Z]+)\$[0-9]+"),""),_xlfn.REGEXEXTRACT(CELL("address",'Raw Data'!P21),"\$([A-Z]+)\$[0-9]+"))}
... B399: {=IFERROR(IF(OR('Raw Data'!B399="",LEN(TRIM('Raw Data'!B399))=0),_xlfn.REGEXEXTRACT(CELL("address",'Raw Data'!B399),"\$([A-Z]+)\$[0-9]+"),""),_xlfn.REGEXEXTRACT(CELL("address",'Raw Data'!B399),"\$([A-Z]+)\$[0-9]+"))} | C399: {=IFERROR(IF(OR('Raw Data'!C399="",LEN(TRIM('Raw Data'!C399))=0),_xlfn.REGEXEXTRACT(CELL("address",'Raw Data'!C399),"\$([A-Z]+)\$[0-9]+"),""),_xlfn.REGEXEXTRACT(CELL("address",'Raw Data'!C399),"\$([A-Z]+)\$[0-9]+"))} | D399: {=IFERROR(IF(OR('Raw Data'!D399="",LEN(TRIM('Raw Data'!D399))=0),_xlfn.REGEXEXTRACT(CELL("address",'Raw Data'!D399),"\$([A-Z]+)\$[0-9]+"),""),_xlfn.REGEXEXTRACT(CELL("address",'Raw Data'!D399),"\$([A-Z]+)\$[0-9]+"))} | E399: {=IFERROR(IF(OR('Raw Data'!E399="",LEN(TRIM('Raw Data'!E399))=0),_xlfn.REGEXEXTRACT(CELL("address",'Raw Data'!E399),"\$([A-Z]+)\$[0-9]+"),""),_xlfn.REGEXEXTRACT(CELL("address",'Raw Data'!E399),"\$([A-Z]+)\$[0-9]+"))} | F399: {=IFERROR(IF(OR('Raw Data'!F399="",LEN(TRIM('Raw Data'!F399))=0),_xlfn.REGEXEXTRACT(CELL("address",'Raw Data'!F399),"\$([A-Z]+)\$[0-9]+"),""),_xlfn.REGEXEXTRACT(CELL("address",'Raw Data'!F399),"\$([A-Z]+)\$[0-9]+"))} | G399: {=IFERROR(IF(OR('Raw Data'!G399="",LEN(TRIM('Raw Data'!G399))=0),_xlfn.REGEXEXTRACT(CELL("address",'Raw Data'!G399),"\$([A-Z]+)\$[0-9]+"),""),_xlfn.REGEXEXTRACT(CELL("address",'Raw Data'!G399),"\$([A-Z]+)\$[0-9]+"))} | H399: {=IFERROR(IF(OR('Raw Data'!H399="",LEN(TRIM('Raw Data'!H399))=0),_xlfn.REGEXEXTRACT(CELL("address",'Raw Data'!H399),"\$([A-Z]+)\$[0-9]+"),""),_xlfn.REGEXEXTRACT(CELL("address",'Raw Data'!H399),"\$([A-Z]+)\$[0-9]+"))} | I399: {=IFERROR(IF(OR('Raw Data'!I399="",LEN(TRIM('Raw Data'!I399))=0),_xlfn.REGEXEXTRACT(CELL("address",'Raw Data'!I399),"\$([A-Z]+)\$[0-9]+"),""),_xlfn.REGEXEXTRACT(CELL("address",'Raw Data'!I399),"\$([A-Z]+)\$[0-9]+"))} | ... P399: {=IFERROR(IF(OR('Raw Data'!P399="",LEN(TRIM('Raw Data'!P399))=0),_xlfn.REGEXEXTRACT(CELL("address",'Raw Data'!P399),"\$([A-Z]+)\$[0-9]+"),""),_xlfn.REGEXEXTRACT(CELL("address",'Raw Data'!P399),"\$([A-Z]+)\$[0-9]+"))}

Sheet Validate_Value
B8: NVARCHAR(10) | C8: NVARCHAR(20) | D8: NVARCHAR(20) | E8: NVARCHAR(20) | F8: NVARCHAR(20) | G8: NVARCHAR(10) | H8: NVARCHAR(255) | I8: NVARCHAR(255) | J8: NVARCHAR(255) | K8: NVARCHAR(255) | L8: NVARCHAR(255) | M8: NVARCHAR(255) | N8: NVARCHAR(255) | O8: NVARCHAR(255) | P8: NVARCHAR(10) | Q8: DECIMAL(13,2) | R8: DECIMAL(13,2) | S8: DECIMAL(13,2) | T8: DECIMAL(13,2) | U8: DECIMAL(13,2) | V8: DECIMAL(13,2) | W8: DECIMAL(13,2) | X8: DECIMAL(13,2) | Y8: DECIMAL(13,2)
B9: C1 | C9: C2 | D9: C3 | E9: C4 | F9: C5 | G9: C6 | H9: C7 | I9: C8 | J9: C9 | K9: C10 | L9: C11 | M9: C12 | N9: C13 | O9: C14 | P9: C15 | Q9: C16 | R9: C17 | S9: C18 | T9: C19 | U9: C20 | V9: C21 | W9: C22 | X9: C23 | Y9: C24
B10: {=IFERROR(IF(OR('Raw Data'!B10="",LEN(TRIM('Raw Data'!B10))=0),"",IF(AND(LEN('Raw Data'!B10) <= 10,LEN('Raw Data'!B10)> 0),"",_xlfn.REGEXEXTRACT(CELL("address",'Raw Data'!B10),"\$([A-Z]+)\$[0-9]+"))),_xlfn.REGEXEXTRACT(CELL("address",'Raw Data'!B10),"\$([A-Z]+)\$[0-9]+"))} | C10: {=IFERROR(IF(OR('Raw Data'!C10="",LEN(TRIM('Raw Data'!C10))=0),"",IF(AND(LEN('Raw Data'!C10) <= 20,LEN('Raw Data'!C10)> 0),"",_xlfn.REGEXEXTRACT(CELL("address",'Raw Data'!C10),"\$([A-Z]+)\$[0-9]+"))),_xlfn.REGEXEXTRACT(CELL("address",'Raw Data'!C10),"\$([A-Z]+)\$[0-9]+"))} | D10: {=IFERROR(IF(OR('Raw Data'!D10="",LEN(TRIM('Raw Data'!D10))=0),"",IF(AND(LEN('Raw Data'!D10) <= 20,LEN('Raw Data'!D10)> 0),"",_xlfn.REGEXEXTRACT(CELL("address",'Raw Data'!D10),"\$([A-Z]+)\$[0-9]+"))),_xlfn.REGEXEXTRACT(CELL("address",'Raw Data'!D10),"\$([A-Z]+)\$[0-9]+"))} | E10: {=IFERROR(IF(OR('Raw Data'!E10="",LEN(TRIM('Raw Data'!E10))=0),"",IF(AND(LEN('Raw Data'!E10) <= 20,LEN('Raw Data'!E10)> 0),"",_xlfn.REGEXEXTRACT(CELL("address",'Raw Data'!E10),"\$([A-Z]+)\$[0-9]+"))),_xlfn.REGEXEXTRACT(CELL("address",'Raw Data'!E10),"\$([A-Z]+)\$[0-9]+"))} | F10: {=IFERROR(IF(OR('Raw Data'!F10="",LEN(TRIM('Raw Data'!F10))=0),"",IF(AND(LEN('Raw Data'!F10) <= 20,LEN('Raw Data'!F10)> 0),"",_xlfn.REGEXEXTRACT(CELL("address",'Raw Data'!F10),"\$([A-Z]+)\$[0-9]+"))),_xlfn.REGEXEXTRACT(CELL("address",'Raw Data'!F10),"\$([A-Z]+)\$[0-9]+"))} | G10: {=IFERROR(IF(OR('Raw Data'!G10="",LEN(TRIM('Raw Data'!G10))=0),"",IF(AND(LEN('Raw Data'!G10) <= 10,LEN('Raw Data'!G10)> 0),"",_xlfn.REGEXEXTRACT(CELL("address",'Raw Data'!G10),"\$([A-Z]+)\$[0-9]+"))),_xlfn.REGEXEXTRACT(CELL("address",'Raw Data'!G10),"\$([A-Z]+)\$[0-9]+"))} | H10: {=IFERROR(IF(OR('Raw Data'!H10="",LEN(TRIM('Raw Data'!H10))=0),"",IF(AND(LEN('Raw Data'!H10) <= 255,LEN('Raw Data'!H10)> 0),"",_xlfn.REGEXEXTRACT(CELL("address",'Raw Data'!H10),"\$([A-Z]+)\$[0-9]+"))),_xlfn.REGEXEXTRACT(CELL("address",'Raw Data'!H10),"\$([A-Z]+)\$[0-9]+"))} | I10: {=IFERROR(IF(OR('Raw Data'!I10="",LEN(TRIM('Raw Data'!I10))=0),"",IF(AND(LEN('Raw Data'!I10) <= 255,LEN('Raw Data'!I10)> 0),"",_xlfn.REGEXEXTRACT(CELL("address",'Raw Data'!I10),"\$([A-Z]+)\$[0-9]+"))),_xlfn.REGEXEXTRACT(CELL("address",'Raw Data'!I10),"\$([A-Z]+)\$[0-9]+"))} | J10: {=IFERROR(IF(OR('Raw Data'!J10="",LEN(TRIM('Raw Data'!J10))=0),"",IF(AND(LEN('Raw Data'!J10) <= 255,LEN('Raw Data'!J10)> 0),"",_xlfn.REGEXEXTRACT(CELL("address",'Raw Data'!J10),"\$([A-Z]+)\$[0-9]+"))),_xlfn.REGEXEXTRACT(CELL("address",'Raw Data'!J10),"\$([A-Z]+)\$[0-9]+"))} | K10: {=IFERROR(IF(OR('Raw Data'!K10="",LEN(TRIM('Raw Data'!K10))=0),"",IF(AND(LEN('Raw Data'!K10) <= 255,LEN('Raw Data'!K10)> 0),"",_xlfn.REGEXEXTRACT(CELL("address",'Raw Data'!K10),"\$([A-Z]+)\$[0-9]+"))),_xlfn.REGEXEXTRACT(CELL("address",'Raw Data'!K10),"\$([A-Z]+)\$[0-9]+"))} | L10: {=IFERROR(IF(OR('Raw Data'!L10="",LEN(TRIM('Raw Data'!L10))=0),"",IF(AND(LEN('Raw Data'!L10) <= 255,LEN('Raw Data'!L10)> 0),"",_xlfn.REGEXEXTRACT(CELL("address",'Raw Data'!L10),"\$([A-Z]+)\$[0-9]+"))),_xlfn.REGEXEXTRACT(CELL("address",'Raw Data'!L10),"\$([A-Z]+)\$[0-9]+"))} | M10: {=IFERROR(IF(OR('Raw Data'!M10="",LEN(TRIM('Raw Data'!M10))=0),"",IF(AND(LEN('Raw Data'!M10) <= 255,LEN('Raw Data'!M10)> 0),"",_xlfn.REGEXEXTRACT(CELL("address",'Raw Data'!M10),"\$([A-Z]+)\$[0-9]+"))),_xlfn.REGEXEXTRACT(CELL("address",'Raw Data'!M10),"\$([A-Z]+)\$[0-9]+"))} | N10: {=IFERROR(IF(OR('Raw Data'!N10="",LEN(TRIM('Raw Data'!N10))=0),"",IF(AND(LEN('Raw Data'!N10) <= 255,LEN('Raw Data'!N10)> 0),"",_xlfn.REGEXEXTRACT(CELL("address",'Raw Data'!N10),"\$([A-Z]+)\$[0-9]+"))),_xlfn.REGEXEXTRACT(CELL("address",'Raw Data'!N10),"\$([A-Z]+)\$[0-9]+"))} | O10: {=IFERROR(IF(OR('Raw Data'!O10="",LEN(TRIM('Raw Data'!O10))=0),"",IF(AND(LEN('Raw Data'!O10) <= 255,LEN('Raw Data'!O10)> 0),"",_xlfn.REGEXEXTRACT(CELL("address",'Raw Data'!O10),"\$([A-Z]+)\$[0-9]+"))),_xlfn.REGEXEXTRACT(CELL("address",'Raw Data'!O10),"\$([A-Z]+)\$[0-9]+"))} | P10: {=IFERROR(IF(OR('Raw Data'!P10="",LEN(TRIM('Raw Data'!P10))=0),"",IF(AND(LEN('Raw Data'!P10) <= 10,LEN('Raw Data'!P10)> 0),"",_xlfn.REGEXEXTRACT(CELL("address",'Raw Data'!P10),"\$([A-Z]+)\$[0-9]+"))),_xlfn.REGEXEXTRACT(CELL("address",'Raw Data'!P10),"\$([A-Z]+)\$[0-9]+"))} | Q10: {=IFERROR(IF(OR('Raw Data'!Q10="",LEN(TRIM('Raw Data'!Q10))=0),"",IF(AND(ISNUMBER('Raw Data'!Q10), IFERROR('Raw Data'!Q10 = ROUND('Raw Data'!Q10, 2),FALSE)),"",_xlfn.REGEXEXTRACT(CELL("address",Q10), "\$([A-Z]+)\$[0-9]+"))),_xlfn.REGEXEXTRACT(CELL("address",Q10), "\$([A-Z]+)\$[0-9]+"))} | R10: {=IFERROR(IF(OR('Raw Data'!R10="",LEN(TRIM('Raw Data'!R10))=0),"",IF(AND(ISNUMBER('Raw Data'!R10), IFERROR('Raw Data'!R10 = ROUND('Raw Data'!R10, 2),FALSE)),"",_xlfn.REGEXEXTRACT(CELL("address",R10), "\$([A-Z]+)\$[0-9]+"))),_xlfn.REGEXEXTRACT(CELL("address",R10), "\$([A-Z]+)\$[0-9]+"))} | S10: {=IFERROR(IF(OR('Raw Data'!S10="",LEN(TRIM('Raw Data'!S10))=0),"",IF(AND(ISNUMBER('Raw Data'!S10), IFERROR('Raw Data'!S10 = ROUND('Raw Data'!S10, 2),FALSE)),"",_xlfn.REGEXEXTRACT(CELL("address",S10), "\$([A-Z]+)\$[0-9]+"))),_xlfn.REGEXEXTRACT(CELL("address",S10), "\$([A-Z]+)\$[0-9]+"))} | T10: {=IFERROR(IF(OR('Raw Data'!T10="",LEN(TRIM('Raw Data'!T10))=0),"",IF(AND(ISNUMBER('Raw Data'!T10), IFERROR('Raw Data'!T10 = ROUND('Raw Data'!T10, 2),FALSE)),"",_xlfn.REGEXEXTRACT(CELL("address",T10), "\$([A-Z]+)\$[0-9]+"))),_xlfn.REGEXEXTRACT(CELL("address",T10), "\$([A-Z]+)\$[0-9]+"))} | U10: {=IFERROR(IF(OR('Raw Data'!U10="",LEN(TRIM('Raw Data'!U10))=0),"",IF(AND(ISNUMBER('Raw Data'!U10), IFERROR('Raw Data'!U10 = ROUND('Raw Data'!U10, 2),FALSE)),"",_xlfn.REGEXEXTRACT(CELL("address",U10), "\$([A-Z]+)\$[0-9]+"))),_xlfn.REGEXEXTRACT(CELL("address",U10), "\$([A-Z]+)\$[0-9]+"))} | V10: {=IFERROR(IF(OR('Raw Data'!V10="",LEN(TRIM('Raw Data'!V10))=0),"",IF(AND(ISNUMBER('Raw Data'!V10), IFERROR('Raw Data'!V10 = ROUND('Raw Data'!V10, 2),FALSE)),"",_xlfn.REGEXEXTRACT(CELL("address",V10), "\$([A-Z]+)\$[0-9]+"))),_xlfn.REGEXEXTRACT(CELL("address",V10), "\$([A-Z]+)\$[0-9]+"))} | W10: {=IFERROR(IF(OR('Raw Data'!W10="",LEN(TRIM('Raw Data'!W10))=0),"",IF(AND(ISNUMBER('Raw Data'!W10), IFERROR('Raw Data'!W10 = ROUND('Raw Data'!W10, 2),FALSE)),"",_xlfn.REGEXEXTRACT(CELL("address",W10), "\$([A-Z]+)\$[0-9]+"))),_xlfn.REGEXEXTRACT(CELL("address",W10), "\$([A-Z]+)\$[0-9]+"))} | X10: {=IFERROR(IF(OR('Raw Data'!X10="",LEN(TRIM('Raw Data'!X10))=0),"",IF(AND(ISNUMBER('Raw Data'!X10), IFERROR('Raw Data'!X10 = ROUND('Raw Data'!X10, 2),FALSE)),"",_xlfn.REGEXEXTRACT(CELL("address",X10), "\$([A-Z]+)\$[0-9]+"))),_xlfn.REGEXEXTRACT(CELL("address",X10), "\$([A-Z]+)\$[0-9]+"))} | Y10: {=IFERROR(IF(OR('Raw Data'!Y10="",LEN(TRIM('Raw Data'!Y10))=0),"",IF(AND(ISNUMBER('Raw Data'!Y10), IFERROR('Raw Data'!Y10 = ROUND('Raw Data'!Y10, 2),FALSE)),"",_xlfn.REGEXEXTRACT(CELL("address",Y10), "\$([A-Z]+)\$[0-9]+"))),_xlfn.REGEXEXTRACT(CELL("address",Y10), "\$([A-Z]+)\$[0-9]+"))}
B11: {=IFERROR(IF(OR('Raw Data'!B11="",LEN(TRIM('Raw Data'!B11))=0),"",IF(AND(LEN('Raw Data'!B11) <= 10,LEN('Raw Data'!B11)> 0),"",_xlfn.REGEXEXTRACT(CELL("address",'Raw Data'!B11),"\$([A-Z]+)\$[0-9]+"))),_xlfn.REGEXEXTRACT(CELL("address",'Raw Data'!B11),"\$([A-Z]+)\$[0-9]+"))} | C11: {=IFERROR(IF(OR('Raw Data'!C11="",LEN(TRIM('Raw Data'!C11))=0),"",IF(AND(LEN('Raw Data'!C11) <= 20,LEN('Raw Data'!C11)> 0),"",_xlfn.REGEXEXTRACT(CELL("address",'Raw Data'!C11),"\$([A-Z]+)\$[0-9]+"))),_xlfn.REGEXEXTRACT(CELL("address",'Raw Data'!C11),"\$([A-Z]+)\$[0-9]+"))} | D11: {=IFERROR(IF(OR('Raw Data'!D11="",LEN(TRIM('Raw Data'!D11))=0),"",IF(AND(LEN('Raw Data'!D11) <= 20,LEN('Raw Data'!D11)> 0),"",_xlfn.REGEXEXTRACT(CELL("address",'Raw Data'!D11),"\$([A-Z]+)\$[0-9]+"))),_xlfn.REGEXEXTRACT(CELL("address",'Raw Data'!D11),"\$([A-Z]+)\$[0-9]+"))} | E11: {=IFERROR(IF(OR('Raw Data'!E11="",LEN(TRIM('Raw Data'!E11))=0),"",IF(AND(LEN('Raw Data'!E11) <= 20,LEN('Raw Data'!E11)> 0),"",_xlfn.REGEXEXTRACT(CELL("address",'Raw Data'!E11),"\$([A-Z]+)\$[0-9]+"))),_xlfn.REGEXEXTRACT(CELL("address",'Raw Data'!E11),"\$([A-Z]+)\$[0-9]+"))} | F11: {=IFERROR(IF(OR('Raw Data'!F11="",LEN(TRIM('Raw Data'!F11))=0),"",IF(AND(LEN('Raw Data'!F11) <= 20,LEN('Raw Data'!F11)> 0),"",_xlfn.REGEXEXTRACT(CELL("address",'Raw Data'!F11),"\$([A-Z]+)\$[0-9]+"))),_xlfn.REGEXEXTRACT(CELL("address",'Raw Data'!F11),"\$([A-Z]+)\$[0-9]+"))} | G11: {=IFERROR(IF(OR('Raw Data'!G11="",LEN(TRIM('Raw Data'!G11))=0),"",IF(AND(LEN('Raw Data'!G11) <= 10,LEN('Raw Data'!G11)> 0),"",_xlfn.REGEXEXTRACT(CELL("address",'Raw Data'!G11),"\$([A-Z]+)\$[0-9]+"))),_xlfn.REGEXEXTRACT(CELL("address",'Raw Data'!G11),"\$([A-Z]+)\$[0-9]+"))} | H11: {=IFERROR(IF(OR('Raw Data'!H11="",LEN(TRIM('Raw Data'!H11))=0),"",IF(AND(LEN('Raw Data'!H11) <= 255,LEN('Raw Data'!H11)> 0),"",_xlfn.REGEXEXTRACT(CELL("address",'Raw Data'!H11),"\$([A-Z]+)\$[0-9]+"))),_xlfn.REGEXEXTRACT(CELL("address",'Raw Data'!H11),"\$([A-Z]+)\$[0-9]+"))} | I11: {=IFERROR(IF(OR('Raw Data'!I11="",LEN(TRIM('Raw Data'!I11))=0),"",IF(AND(LEN('Raw Data'!I11) <= 255,LEN('Raw Data'!I11)> 0),"",_xlfn.REGEXEXTRACT(CELL("address",'Raw Data'!I11),"\$([A-Z]+)\$[0-9]+"))),_xlfn.REGEXEXTRACT(CELL("address",'Raw Data'!I11),"\$([A-Z]+)\$[0-9]+"))} | J11: {=IFERROR(IF(OR('Raw Data'!J11="",LEN(TRIM('Raw Data'!J11))=0),"",IF(AND(LEN('Raw Data'!J11) <= 255,LEN('Raw Data'!J11)> 0),"",_xlfn.REGEXEXTRACT(CELL("address",'Raw Data'!J11),"\$([A-Z]+)\$[0-9]+"))),_xlfn.REGEXEXTRACT(CELL("address",'Raw Data'!J11),"\$([A-Z]+)\$[0-9]+"))} | K11: {=IFERROR(IF(OR('Raw Data'!K11="",LEN(TRIM('Raw Data'!K11))=0),"",IF(AND(LEN('Raw Data'!K11) <= 255,LEN('Raw Data'!K11)> 0),"",_xlfn.REGEXEXTRACT(CELL("address",'Raw Data'!K11),"\$([A-Z]+)\$[0-9]+"))),_xlfn.REGEXEXTRACT(CELL("address",'Raw Data'!K11),"\$([A-Z]+)\$[0-9]+"))} | L11: {=IFERROR(IF(OR('Raw Data'!L11="",LEN(TRIM('Raw Data'!L11))=0),"",IF(AND(LEN('Raw Data'!L11) <= 255,LEN('Raw Data'!L11)> 0),"",_xlfn.REGEXEXTRACT(CELL("address",'Raw Data'!L11),"\$([A-Z]+)\$[0-9]+"))),_xlfn.REGEXEXTRACT(CELL("address",'Raw Data'!L11),"\$([A-Z]+)\$[0-9]+"))} | M11: {=IFERROR(IF(OR('Raw Data'!M11="",LEN(TRIM('Raw Data'!M11))=0),"",IF(AND(LEN('Raw Data'!M11) <= 255,LEN('Raw Data'!M11)> 0),"",_xlfn.REGEXEXTRACT(CELL("address",'Raw Data'!M11),"\$([A-Z]+)\$[0-9]+"))),_xlfn.REGEXEXTRACT(CELL("address",'Raw Data'!M11),"\$([A-Z]+)\$[0-9]+"))} | N11: {=IFERROR(IF(OR('Raw Data'!N11="",LEN(TRIM('Raw Data'!N11))=0),"",IF(AND(LEN('Raw Data'!N11) <= 255,LEN('Raw Data'!N11)> 0),"",_xlfn.REGEXEXTRACT(CELL("address",'Raw Data'!N11),"\$([A-Z]+)\$[0-9]+"))),_xlfn.REGEXEXTRACT(CELL("address",'Raw Data'!N11),"\$([A-Z]+)\$[0-9]+"))} | O11: {=IFERROR(IF(OR('Raw Data'!O11="",LEN(TRIM('Raw Data'!O11))=0),"",IF(AND(LEN('Raw Data'!O11) <= 255,LEN('Raw Data'!O11)> 0),"",_xlfn.REGEXEXTRACT(CELL("address",'Raw Data'!O11),"\$([A-Z]+)\$[0-9]+"))),_xlfn.REGEXEXTRACT(CELL("address",'Raw Data'!O11),"\$([A-Z]+)\$[0-9]+"))} | P11: {=IFERROR(IF(OR('Raw Data'!P11="",LEN(TRIM('Raw Data'!P11))=0),"",IF(AND(LEN('Raw Data'!P11) <= 10,LEN('Raw Data'!P11)> 0),"",_xlfn.REGEXEXTRACT(CELL("address",'Raw Data'!P11),"\$([A-Z]+)\$[0-9]+"))),_xlfn.REGEXEXTRACT(CELL("address",'Raw Data'!P11),"\$([A-Z]+)\$[0-9]+"))} | Q11: {=IFERROR(IF(OR('Raw Data'!Q11="",LEN(TRIM('Raw Data'!Q11))=0),"",IF(AND(ISNUMBER('Raw Data'!Q11), IFERROR('Raw Data'!Q11 = ROUND('Raw Data'!Q11, 2),FALSE)),"",_xlfn.REGEXEXTRACT(CELL("address",Q11), "\$([A-Z]+)\$[0-9]+"))),_xlfn.REGEXEXTRACT(CELL("address",Q11), "\$([A-Z]+)\$[0-9]+"))} | R11: {=IFERROR(IF(OR('Raw Data'!R11="",LEN(TRIM('Raw Data'!R11))=0),"",IF(AND(ISNUMBER('Raw Data'!R11), IFERROR('Raw Data'!R11 = ROUND('Raw Data'!R11, 2),FALSE)),"",_xlfn.REGEXEXTRACT(CELL("address",R11), "\$([A-Z]+)\$[0-9]+"))),_xlfn.REGEXEXTRACT(CELL("address",R11), "\$([A-Z]+)\$[0-9]+"))} | S11: {=IFERROR(IF(OR('Raw Data'!S11="",LEN(TRIM('Raw Data'!S11))=0),"",IF(AND(ISNUMBER('Raw Data'!S11), IFERROR('Raw Data'!S11 = ROUND('Raw Data'!S11, 2),FALSE)),"",_xlfn.REGEXEXTRACT(CELL("address",S11), "\$([A-Z]+)\$[0-9]+"))),_xlfn.REGEXEXTRACT(CELL("address",S11), "\$([A-Z]+)\$[0-9]+"))} | T11: {=IFERROR(IF(OR('Raw Data'!T11="",LEN(TRIM('Raw Data'!T11))=0),"",IF(AND(ISNUMBER('Raw Data'!T11), IFERROR('Raw Data'!T11 = ROUND('Raw Data'!T11, 2),FALSE)),"",_xlfn.REGEXEXTRACT(CELL("address",T11), "\$([A-Z]+)\$[0-9]+"))),_xlfn.REGEXEXTRACT(CELL("address",T11), "\$([A-Z]+)\$[0-9]+"))} | U11: {=IFERROR(IF(OR('Raw Data'!U11="",LEN(TRIM('Raw Data'!U11))=0),"",IF(AND(ISNUMBER('Raw Data'!U11), IFERROR('Raw Data'!U11 = ROUND('Raw Data'!U11, 2),FALSE)),"",_xlfn.REGEXEXTRACT(CELL("address",U11), "\$([A-Z]+)\$[0-9]+"))),_xlfn.REGEXEXTRACT(CELL("address",U11), "\$([A-Z]+)\$[0-9]+"))} | V11: {=IFERROR(IF(OR('Raw Data'!V11="",LEN(TRIM('Raw Data'!V11))=0),"",IF(AND(ISNUMBER('Raw Data'!V11), IFERROR('Raw Data'!V11 = ROUND('Raw Data'!V11, 2),FALSE)),"",_xlfn.REGEXEXTRACT(CELL("address",V11), "\$([A-Z]+)\$[0-9]+"))),_xlfn.REGEXEXTRACT(CELL("address",V11), "\$([A-Z]+)\$[0-9]+"))} | W11: {=IFERROR(IF(OR('Raw Data'!W11="",LEN(TRIM('Raw Data'!W11))=0),"",IF(AND(ISNUMBER('Raw Data'!W11), IFERROR('Raw Data'!W11 = ROUND('Raw Data'!W11, 2),FALSE)),"",_xlfn.REGEXEXTRACT(CELL("address",W11), "\$([A-Z]+)\$[0-9]+"))),_xlfn.REGEXEXTRACT(CELL("address",W11), "\$([A-Z]+)\$[0-9]+"))} | X11: {=IFERROR(IF(OR('Raw Data'!X11="",LEN(TRIM('Raw Data'!X11))=0),"",IF(AND(ISNUMBER('Raw Data'!X11), IFERROR('Raw Data'!X11 = ROUND('Raw Data'!X11, 2),FALSE)),"",_xlfn.REGEXEXTRACT(CELL("address",X11), "\$([A-Z]+)\$[0-9]+"))),_xlfn.REGEXEXTRACT(CELL("address",X11), "\$([A-Z]+)\$[0-9]+"))} | Y11: {=IFERROR(IF(OR('Raw Data'!Y11="",LEN(TRIM('Raw Data'!Y11))=0),"",IF(AND(ISNUMBER('Raw Data'!Y11), IFERROR('Raw Data'!Y11 = ROUND('Raw Data'!Y11, 2),FALSE)),"",_xlfn.REGEXEXTRACT(CELL("address",Y11), "\$([A-Z]+)\$[0-9]+"))),_xlfn.REGEXEXTRACT(CELL("address",Y11), "\$([A-Z]+)\$[0-9]+"))}
