Workbook

Sheet Raw Data
B9: C1 | C9: C2 | D9: C3 | E9: C4 | F9: C5 | G9: C6 | H9: C7 | I9: C8 | J9: C9 | K9: C10 | L9: C11 | M9: C12 | N9: C13 | O9: C14 | P9: C15 | Q9: C16 | R9: C17 | S9: C18 | T9: C19 | U9: C20 | V9: C21 | W9: C22 | X9: C23 | Y9: C24 | Z9: C25 | AA9: C26 | AB9: C27 | AC9: C28 | AD9: C29 | AE9: C30 | AF9: C31 | AG9: C32 | AH9: C33 | AI9: C34 | AJ9: C35
B10: Overall Project | C10: Month # 1 | D10: 45536 | E10: 0 | F10: 0 | G10: 0 | H10: 0 | I10: 0 | J10: 0 | K10: 0 | L10: 0 | M10: 0 | N10: 0 | O10: 0 | P10: 0 | Q10: 1013.34 | R10: 0 | S10: 0 | T10: 1013.34 | U10: 0 | V10: 0 | W10: 0 | X10: 0 | Y10: 0 | Z10: 0 | AA10: 0 | AB10: 0 | AC10: 0 | AD10: 0 | AE10: 0 | AF10: 0 | AG10: 1013.34 | AH10: 0 | AI10: 0 | AJ10: 1013.34
B11: Overall Project | C11: Month # 2 | D11: 45566 | E11: 414.61 | F11: 0 | G11: 0 | H11: 414.61 | I11: 598.64 | J11: 8.75 | K11: 0 | L11: 607.39 | M11: 444.93 | N11: 8.75 | O11: 0 | P11: 453.68 | Q11: 1819.62 | R11: 8.75 | S11: 0 | T11: 1828.37 | U11: 414.61 | V11: 0 | W11: 0 | X11: 414.61 | Y11: 598.64 | Z11: 8.75 | AA11: 0 | AB11: 607.39 | AC11: 444.93 | AD11: 8.75 | AE11: 0 | AF11: 453.68 | AG11: 1819.62 | AH11: 8.75 | AI11: 0 | AJ11: 2841.71
B12: Overall Project | C12: Month # 3 | D12: 45597 | E12: 2791.29 | F12: 0 | G12: 0 | H12: 2791.29 | I12: 1195.24 | J12: 271.75 | K12: 0 | L12: 1466.99 | M12: 1013.34 | N12: 293.25 | O12: 0 | P12: 1306.59 | Q12: 2165.07 | R12: 293.25 | S12: 0 | T12: 2458.32 | U12: 3205.9 | V12: 0 | W12: 0 | X12: 3205.9 | Y12: 1793.88 | Z12: 280.5 | AA12: 0 | AB12: 2074.38 | AC12: 1458.27 | AD12: 302 | AE12: 0 | AF12: 1760.27 | AG12: 3984.69 | AH12: 302 | AI12: 0 | AJ12: 5300.03
B13: Overall Project | C13: Month # 4 | D13: 45627 | E13: 3104.71 | F13: 0 | G13: 0 | H13: 3104.71 | I13: 1922.86 | J13: 397.1 | K13: 0 | L13: 2319.96 | M13: 1819.62 | N13: 447.5 | O13: 0 | P13: 2267.12 | Q13: 1968.3 | R13: 447.5 | S13: 0 | T13: 2415.8 | U13: 6310.61 | V13: 0 | W13: 0 | X13: 6310.61 | Y13: 3716.74 | Z13: 677.6 | AA13: 0 | AB13: 4394.34 | AC13: 3277.89 | AD13: 749.5 | AE13: 0 | AF13: 4027.39 | AG13: 5952.99 | AH13: 749.5 | AI13: 0 | AJ13: 7715.83
B14: Overall Project | C14: Month # 5 | D14: 45658 | E14: 3449.31 | F14: 0 | G14: 0 | H14: 3449.31 | I14: 2379.22 | J14: 417.41 | K14: 0 | L14: 2796.63 | M14: 2165.07 | N14: 674 | O14: 0 | P14: 2839.07 | Q14: 2960.43 | R14: 674 | S14: 0 | T14: 3634.43 | U14: 9759.92 | V14: 0 | W14: 0 | X14: 9759.92 | Y14: 6095.96 | Z14: 1095.01 | AA14: 0 | AB14: 7190.97 | AC14: 5442.96 | AD14: 1423.5 | AE14: 0 | AF14: 6866.46 | AG14: 8913.42 | AH14: 1423.5 | AI14: 0 | AJ14: 11350.26
B15: Overall Project | C15: Month # 6 | D15: 45689 | E15: 3091.51 | F15: 0 | G15: 0 | H15: 3091.51 | I15: 2195.44 | J15: 0 | K15: 0 | L15: 2195.44 | M15: 1968.3 | N15: 634.75 | O15: 0 | P15: 2603.05 | Q15: 2283.5 | R15: 634.75 | S15: 0 | T15: 2918.25 | U15: 12851.43 | V15: 0 | W15: 0 | X15: 12851.43 | Y15: 8291.4 | Z15: 1095.01 | AA15: 0 | AB15: 9386.41 | AC15: 7411.26 | AD15: 2058.25 | AE15: 0 | AF15: 9469.51 | AG15: 11196.92 | AH15: 2058.25 | AI15: 0 | AJ15: 14268.51
B16: Overall Project | C16: Month # 7 | D16: 45717 | E16: 1928.54 | F16: 0 | G16: 0 | H16: 1928.54 | I16: 1562.04 | J16: 0 | K16: 0 | L16: 1562.04 | M16: 2960.43 | N16: 482 | O16: 0 | P16: 3442.43 | Q16: 2361.35 | R16: 482 | S16: 0 | T16: 2843.35 | U16: 14779.97 | V16: 0 | W16: 0 | X16: 14779.97 | Y16: 9853.44 | Z16: 1095.01 | AA16: 0 | AB16: 10948.45 | AC16: 10371.69 | AD16: 2540.25 | AE16: 0 | AF16: 12911.94 | AG16: 13558.27 | AH16: 2540.25 | AI16: 0 | AJ16: 17111.86
B17: Overall Project | C17: Month # 8 | D17: 45748 | E17: 2880.9 | F17: 0 | G17: 0 | H17: 2880.9 | I17: 1773.57 | J17: 0 | K17: 0 | L17: 1773.57 | M17: 2283.5 | N17: 568.75 | O17: 0 | P17: 2852.25 | Q17: 1703.55 | R17: 568.75 | S17: 0 | T17: 2272.3 | U17: 17660.87 | V17: 0 | W17: 0 | X17: 17660.87 | Y17: 11627.01 | Z17: 1095.01 | AA17: 0 | AB17: 12722.02 | AC17: 12655.19 | AD17: 3109 | AE17: 0 | AF17: 15764.19 | AG17: 15261.82 | AH17: 3109 | AI17: 0 | AJ17: 19384.16
B18: Overall Project | C18: Month # 9 | D18: 45778 | E18: 3551.28 | F18: 0 | G18: 0 | H18: 3551.28 | I18: 1923.47 | J18: 0 | K18: 0 | L18: 1923.47 | M18: 2361.35 | N18: 264.5 | O18: 0 | P18: 2625.85 | Q18: 2204.45 | R18: 56.5 | S18: 0 | T18: 2260.95 | U18: 21212.15 | V18: 0 | W18: 0 | X18: 21212.15 | Y18: 13550.48 | Z18: 1095.01 | AA18: 0 | AB18: 14645.49 | AC18: 15016.54 | AD18: 3373.5 | AE18: 0 | AF18: 18390.04 | AG18: 17466.27 | AH18: 3165.5 | AI18: 0 | AJ18: 21645.11
B19: Overall Project | C19: Month # 10 | D19: 45809 | E19: 2014.06 | F19: 0 | G19: 0 | H19: 2014.06 | I19: 1097.25 | J19: 0 | K19: 0 | L19: 1097.25 | M19: 1703.8 | N19: 382.16 | O19: 0 | P19: 2085.96 | Q19: 1217.35 | R19: 122.5 | S19: 0 | T19: 1339.85 | U19: 23226.21 | V19: 0 | W19: 0 | X19: 23226.21 | Y19: 14647.73 | Z19: 1095.01 | AA19: 0 | AB19: 15742.74 | AC19: 16720.34 | AD19: 3755.66 | AE19: 0 | AF19: 20476 | AG19: 18683.62 | AH19: 3288 | AI19: 0 | AJ19: 22984.96
B20: Overall Project | C20: Month # 11 | D20: 45839 | E20: 1373.4 | F20: 0 | G20: 0 | H20: 1373.4 | I20: 757.89 | J20: 0 | K20: 0 | L20: 757.89 | M20: 2204.2 | N20: 200 | O20: 0 | P20: 2404.2 | Q20: 1199.62 | R20: 17.5 | S20: 0 | T20: 1217.12 | U20: 24599.61 | V20: 0 | W20: 0 | X20: 24599.61 | Y20: 15405.62 | Z20: 1095.01 | AA20: 0 | AB20: 16500.63 | AC20: 18924.54 | AD20: 3955.66 | AE20: 0 | AF20: 22880.2 | AG20: 19883.24 | AH20: 3305.5 | AI20: 0 | AJ20: 24202.08
B21: Overall Project | C21: Month # 12 | D21: 45870 | E21: 1316.45 | F21: 0 | G21: 0 | H21: 1316.45 | I21: 770.74 | J21: 0 | K21: 0 | L21: 770.74 | M21: 1217.35 | N21: 200 | O21: 0 | P21: 1417.35 | Q21: 1052.63 | R21: 0 | S21: 0 | T21: 1052.63 | U21: 25916.06 | V21: 0 | W21: 0 | X21: 25916.06 | Y21: 16176.36 | Z21: 1095.01 | AA21: 0 | AB21: 17271.37 | AC21: 20141.89 | AD21: 4155.66 | AE21: 0 | AF21: 24297.55 | AG21: 20935.87 | AH21: 3305.5 | AI21: 0 | AJ21: 25254.71
... B33: Overall Project | C33: Month # 24 | D33: 46235 | E33: 0 | F33: 0 | G33: 0 | H33: 0 | I33: 0 | J33: 0 | K33: 0 | L33: 0 | M33: 0 | N33: 0 | O33: 0 | P33: 0 | Q33: 0 | R33: 0 | S33: 0 | T33: 0 | U33: 29811.55 | V33: 0 | W33: 0 | X33: 29811.55 | Y33: 18698.73 | Z33: 1095.01 | AA33: 0 | AB33: 19793.74 | AC33: 25695.13 | AD33: 4520.59 | AE33: 0 | AF33: 30215.72 | AG33: 23896.88 | AH33: 3305.5 | AI33: 0 | AJ33: 28215.72
B34: Engineering | C34: Month # 1 | D34: 45536 | E34: 0 | H34: 0 | I34: 0 | L34: 0 | M34: 0 | P34: 0 | Q34: 358.75 | S34: 0 | T34: 358.75 | U34: 0 | W34: 0 | X34: 0 | Y34: 0 | Z34: 0 | AA34: 0 | AB34: 0 | AC34: 0 | AD34: 0 | AE34: 0 | AF34: 0 | AG34: 358.75 | AH34: 0 | AI34: 0 | AJ34: 358.75
B35: Engineering | C35: Month # 2 | D35: 45566 | E35: 52.38 | H35: 52.38 | I35: 44 | J35: 8.75 | L35: 52.75 | M35: 49 | N35: 8.75 | P35: 57.75 | Q35: 616.42 | R35: 8.75 | T35: 625.17 | U35: 52.38 | W35: 0 | X35: 52.38 | Y35: 44 | Z35: 8.75 | AA35: 0 | AB35: 52.75 | AC35: 49 | AD35: 8.75 | AE35: 0 | AF35: 57.75 | AG35: 975.17 | AH35: 8.75 | AI35: 0 | AJ35: 983.92
B36: Engineering | C36: Month # 3 | D36: 45597 | E36: 615.6 | H36: 615.6 | I36: 472 | J36: 271.75 | L36: 743.75 | M36: 358.75 | N36: 293.25 | P36: 652 | Q36: 792.84 | R36: 293.25 | T36: 1086.09 | U36: 667.98 | W36: 0 | X36: 667.98 | Y36: 516 | Z36: 280.5 | AA36: 0 | AB36: 796.5 | AC36: 407.75 | AD36: 302 | AE36: 0 | AF36: 709.75 | AG36: 1768.01 | AH36: 302 | AI36: 0 | AJ36: 2070.01
B37: Engineering | C37: Month # 4 | D37: 45627 | E37: 587.45 | H37: 587.45 | I37: 436 | J37: 397.1 | L37: 833.1 | M37: 616.42 | N37: 447.5 | P37: 1063.92 | Q37: 614.75 | R37: 447.5 | T37: 1062.25 | U37: 1255.43 | W37: 0 | X37: 1255.43 | Y37: 952 | Z37: 677.6 | AA37: 0 | AB37: 1629.6 | AC37: 1024.17 | AD37: 749.5 | AE37: 0 | AF37: 1773.67 | AG37: 2382.76 | AH37: 749.5 | AI37: 0 | AJ37: 3132.26
B38: Engineering | C38: Month # 5 | D38: 45658 | E38: 494.03 | H38: 494.03 | I38: 302 | J38: 417.41 | L38: 719.41 | M38: 792.84 | N38: 674 | P38: 1466.84 | Q38: 885.5 | R38: 674 | T38: 1559.5 | U38: 1749.46 | W38: 0 | X38: 1749.46 | Y38: 1254 | Z38: 1095.01 | AA38: 0 | AB38: 2349.01 | AC38: 1817.01 | AD38: 1423.5 | AE38: 0 | AF38: 3240.51 | AG38: 3268.26 | AH38: 1423.5 | AI38: 0 | AJ38: 4691.76
B39: Engineering | C39: Month # 6 | D39: 45689 | E39: 329.65 | H39: 329.65 | I39: 168 | L39: 168 | M39: 614.75 | N39: 634.75 | P39: 1249.5 | Q39: 544.17 | R39: 634.75 | T39: 1178.92 | U39: 2079.11 | W39: 0 | X39: 2079.11 | Y39: 1422 | Z39: 1095.01 | AA39: 0 | AB39: 2517.01 | AC39: 2431.76 | AD39: 2058.25 | AE39: 0 | AF39: 4490.01 | AG39: 3812.43 | AH39: 2058.25 | AI39: 0 | AJ39: 5870.68
B40: Engineering | C40: Month # 7 | D40: 45717 | E40: 95.58 | H40: 95.58 | I40: 92 | L40: 92 | M40: 885.5 | N40: 482 | P40: 1367.5 | Q40: 130.25 | R40: 482 | T40: 612.25 | U40: 2174.69 | W40: 0 | X40: 2174.69 | Y40: 1514 | Z40: 1095.01 | AA40: 0 | AB40: 2609.01 | AC40: 3317.26 | AD40: 2540.25 | AE40: 0 | AF40: 5857.51 | AG40: 3942.68 | AH40: 2540.25 | AI40: 0 | AJ40: 6482.93
B41: Engineering | C41: Month # 8 | D41: 45748 | E41: 49.59 | H41: 49.59 | I41: 48 | L41: 48 | M41: 544.17 | N41: 568.75 | P41: 1112.92 | Q41: 43.5 | R41: 568.75 | T41: 612.25 | U41: 2224.28 | W41: 0 | X41: 2224.28 | Y41: 1562 | Z41: 1095.01 | AA41: 0 | AB41: 2657.01 | AC41: 3861.43 | AD41: 3109 | AE41: 0 | AF41: 6970.43 | AG41: 3986.18 | AH41: 3109 | AI41: 0 | AJ41: 7095.18
B42: Engineering | C42: Month # 9 | D42: 45778 | E42: 43.33 | H42: 43.33 | I42: 40 | L42: 40 | M42: 130.25 | N42: 264.5 | P42: 394.75 | Q42: 106.5 | R42: 56.5 | T42: 163 | U42: 2267.61 | W42: 0 | X42: 2267.61 | Y42: 1602 | Z42: 1095.01 | AA42: 0 | AB42: 2697.01 | AC42: 3991.68 | AD42: 3373.5 | AE42: 0 | AF42: 7365.18 | AG42: 4092.68 | AH42: 3165.5 | AI42: 0 | AJ42: 7258.18
B43: Engineering | C43: Month # 10 | D43: 45809 | E43: 26.26 | H43: 26.26 | I43: 28 | L43: 28 | M43: 43.75 | N43: 382.16 | P43: 425.91 | Q43: 0 | R43: 122.5 | T43: 122.5 | U43: 2293.87 | W43: 0 | X43: 2293.87 | Y43: 1630 | Z43: 1095.01 | AA43: 0 | AB43: 2725.01 | AC43: 4035.43 | AD43: 3755.66 | AE43: 0 | AF43: 7791.09 | AG43: 4092.68 | AH43: 3288 | AI43: 0 | AJ43: 7380.68
B44: Engineering | C44: Month # 11 | D44: 45839 | E44: 30 | H44: 30 | I44: 30 | L44: 30 | M44: 106.25 | N44: 200 | P44: 306.25 | Q44: 4 | R44: 17.5 | T44: 21.5 | U44: 2323.87 | W44: 0 | X44: 2323.87 | Y44: 1660 | Z44: 1095.01 | AA44: 0 | AB44: 2755.01 | AC44: 4141.68 | AD44: 3955.66 | AE44: 0 | AF44: 8097.34 | AG44: 4096.68 | AH44: 3305.5 | AI44: 0 | AJ44: 7402.18
B45: Engineering | C45: Month # 12 | D45: 45870 | E45: 30.23 | H45: 30.23 | I45: 32 | L45: 32 | M45: 0 | N45: 200 | P45: 200 | Q45: 35.75 | T45: 35.75 | U45: 2354.1 | W45: 0 | X45: 2354.1 | Y45: 1692 | Z45: 1095.01 | AA45: 0 | AB45: 2787.01 | AC45: 4141.68 | AD45: 4155.66 | AE45: 0 | AF45: 8297.34 | AG45: 4132.43 | AH45: 3305.5 | AI45: 0 | AJ45: 7437.93
B46: Engineering | C46: Month # 13 | D46: 45901 | E46: 30.23 | H46: 30.23 | I46: 32 | L46: 32 | M46: 4 | N46: 200 | P46: 204 | Q46: 71.4 | T46: 71.4 | U46: 2384.33 | W46: 0 | X46: 2384.33 | Y46: 1724 | Z46: 1095.01 | AA46: 0 | AB46: 2819.01 | AC46: 4145.68 | AD46: 4355.66 | AE46: 0 | AF46: 8501.34 | AG46: 4203.83 | AH46: 3305.5 | AI46: 0 | AJ46: 7509.33
B47: Engineering | C47: Month # 14 | D47: 45931 | E47: 40.31 | H47: 40.31 | I47: 40 | L47: 40 | M47: 35.75 | N47: 164.93 | P47: 200.68 | Q47: 198.93 | T47: 198.93 | U47: 2424.64 | W47: 0 | X47: 2424.64 | Y47: 1764 | Z47: 1095.01 | AA47: 0 | AB47: 2859.01 | AC47: 4181.43 | AD47: 4520.59 | AE47: 0 | AF47: 8702.02 | AG47: 4402.76 | AH47: 3305.5 | AI47: 0 | AJ47: 7708.26
B48: Engineering | C48: Month # 15 | D48: 45962 | E48: 195.89 | H48: 195.89 | I48: 116 | L48: 116 | M48: 71.4 | P48: 71.4 | Q48: 0 | T48: 0 | U48: 2620.53 | W48: 0 | X48: 2620.53 | Y48: 1880 | Z48: 1095.01 | AA48: 0 | AB48: 2975.01 | AC48: 4252.83 | AD48: 4520.59 | AE48: 0 | AF48: 8773.42 | AG48: 4402.76 | AH48: 3305.5 | AI48: 0 | AJ48: 7708.26
B49: Engineering | C49: Month # 16 | D49: 45992 | E49: 431.09 | H49: 431.09 | I49: 240.1 | L49: 240.1 | M49: 198.93 | P49: 198.93 | Q49: 0 | T49: 0 | U49: 3051.62 | W49: 0 | X49: 3051.62 | Y49: 2120.1 | Z49: 1095.01 | AA49: 0 | AB49: 3215.11 | AC49: 4451.76 | AD49: 4520.59 | AE49: 0 | AF49: 8972.35 | AG49: 4402.76 | AH49: 3305.5 | AI49: 0 | AJ49: 7708.26
B50: Engineering | C50: Month # 17 | D50: 46023 | E50: 36.49 | H50: 36.49 | I50: 40 | L50: 40 | M50: 0 | P50: 0 | Q50: 0 | T50: 0 | U50: 3088.11 | W50: 0 | X50: 3088.11 | Y50: 2160.1 | Z50: 1095.01 | AA50: 0 | AB50: 3255.11 | AC50: 4451.76 | AD50: 4520.59 | AE50: 0 | AF50: 8972.35 | AG50: 4402.76 | AH50: 3305.5 | AI50: 0 | AJ50: 7708.26
B51: Engineering | C51: Month # 18 | D51: 46054 | E51: 0 | H51: 0 | I51: 0 | L51: 0 | M51: 18 | P51: 18 | Q51: 0 | T51: 0 | U51: 3088.11 | W51: 0 | X51: 3088.11 | Y51: 2160.1 | Z51: 1095.01 | AA51: 0 | AB51: 3255.11 | AC51: 4469.76 | AD51: 4520.59 | AE51: 0 | AF51: 8990.35 | AG51: 4402.76 | AH51: 3305.5 | AI51: 0 | AJ51: 7708.26
B52: Engineering | C52: Month # 19 | D52: 46082 | E52: 0 | H52: 0 | I52: 0 | L52: 0 | M52: 64 | P52: 64 | Q52: 0 | T52: 0 | U52: 3088.11 | W52: 0 | X52: 3088.11 | Y52: 2160.1 | Z52: 1095.01 | AA52: 0 | AB52: 3255.11 | AC52: 4533.76 | AD52: 4520.59 | AE52: 0 | AF52: 9054.35 | AG52: 4402.76 | AH52: 3305.5 | AI52: 0 | AJ52: 7708.26
B53: Engineering | C53: Month # 20 | D53: 46113 | E53: 0 | H53: 0 | I53: 0 | L53: 0 | M53: 0 | P53: 0 | Q53: 0 | T53: 0 | U53: 3088.11 | W53: 0 | X53: 3088.11 | Y53: 2160.1 | Z53: 1095.01 | AA53: 0 | AB53: 3255.11 | AC53: 4533.76 | AD53: 4520.59 | AE53: 0 | AF53: 9054.35 | AG53: 4402.76 | AH53: 3305.5 | AI53: 0 | AJ53: 7708.26
B54: Engineering | C54: Month # 21 | D54: 46143 | E54: 0 | H54: 0 | I54: 0 | L54: 0 | M54: 0 | P54: 0 | Q54: 0 | T54: 0 | U54: 3088.11 | W54: 0 | X54: 3088.11 | Y54: 2160.1 | Z54: 1095.01 | AA54: 0 | AB54: 3255.11 | AC54: 4533.76 | AD54: 4520.59 | AE54: 0 | AF54: 9054.35 | AG54: 4402.76 | AH54: 3305.5 | AI54: 0 | AJ54: 7708.26
B55: Engineering | C55: Month # 22 | D55: 46174 | E55: 0 | H55: 0 | I55: 0 | L55: 0 | M55: 0 | P55: 0 | Q55: 0 | T55: 0 | U55: 3088.11 | W55: 0 | X55: 3088.11 | Y55: 2160.1 | Z55: 1095.01 | AA55: 0 | AB55: 3255.11 | AC55: 4533.76 | AD55: 4520.59 | AE55: 0 | AF55: 9054.35 | AG55: 4402.76 | AH55: 3305.5 | AI55: 0 | AJ55: 7708.26
B56: Engineering | C56: Month # 23 | D56: 46204 | E56: 0 | H56: 0 | I56: 0 | L56: 0 | M56: 0 | P56: 0 | Q56: 0 | T56: 0 | U56: 3088.11 | W56: 0 | X56: 3088.11 | Y56: 2160.1 | Z56: 1095.01 | AA56: 0 | AB56: 3255.11 | AC56: 4533.76 | AD56: 4520.59 | AE56: 0 | AF56: 9054.35 | AG56: 4402.76 | AH56: 3305.5 | AI56: 0 | AJ56: 7708.26
B57: Engineering | C57: Month # 24 | D57: 46235 | E57: 0 | H57: 0 | I57: 0 | L57: 0 | M57: 0 | P57: 0 | Q57: 0 | T57: 0 | U57: 3088.11 | W57: 0 | X57: 3088.11 | Y57: 2160.1 | Z57: 1095.01 | AA57: 0 | AB57: 3255.11 | AC57: 4533.76 | AD57: 4520.59 | AE57: 0 | AF57: 9054.35 | AG57: 4402.76 | AH57: 3305.5 | AI57: 0 | AJ57: 7708.26
B58: Procurement | C58: Month # 1 | D58: 45536 | E58: 0 | H58: 0 | I58: 0 | L58: 0 | M58: 0 | P58: 0 | Q58: 268.64 | T58: 268.64 | U58: 0 | W58: 0 | X58: 0 | Y58: 0 | Z58: 0 | AA58: 0 | AB58: 0 | AC58: 0 | AD58: 0 | AE58: 0 | AF58: 0 | AG58: 268.64 | AH58: 0 | AI58: 0 | AJ58: 268.64
B59: Procurement | C59: Month # 2 | D59: 45566 | E59: 72.1 | H59: 72.1 | I59: 224.64 | L59: 224.64 | M59: 61.58 | P59: 61.58 | Q59: 355.03 | T59: 355.03 | U59: 72.1 | W59: 0 | X59: 72.1 | Y59: 224.64 | Z59: 0 | AA59: 0 | AB59: 224.64 | AC59: 61.58 | AD59: 0 | AE59: 0 | AF59: 61.58 | AG59: 623.67 | AH59: 0 | AI59: 0 | AJ59: 623.67
...

Sheet Validate_Empty
B8: TRUE | C8: TRUE | D8: FALSE | E8: FALSE | F8: FALSE | G8: FALSE | H8: FALSE | I8: FALSE | J8: FALSE | K8: FALSE | L8: FALSE | M8: FALSE | N8: FALSE | O8: FALSE | P8: FALSE | Q8: FALSE | R8: FALSE | S8: FALSE | T8: FALSE | U8: FALSE | V8: FALSE | W8: FALSE | X8: FALSE | Y8: FALSE | Z8: FALSE | AA8: FALSE | AB8: FALSE | AC8: FALSE | AD8: FALSE | AE8: FALSE | AF8: FALSE | AG8: FALSE | AH8: FALSE | AI8: FALSE | AJ8: FALSE
B9: C1 | C9: C2 | D9: C3 | E9: C4 | F9: C5 | G9: C6 | H9: C7 | I9: C8 | J9: C9 | K9: C10 | L9: C11 | M9: C12 | N9: C13 | O9: C14 | P9: C15 | Q9: C16 | R9: C17 | S9: C18 | T9: C19 | U9: C20 | V9: C21 | W9: C22 | X9: C23 | Y9: C24 | Z9: C25 | AA9: C26 | AB9: C27 | AC9: C28 | AD9: C29 | AE9: C30 | AF9: C31 | AG9: C32 | AH9: C33 | AI9: C34 | AJ9: C35
B10: {=IFERROR(IF(OR('Raw Data'!B10="",LEN(TRIM('Raw Data'!B10))=0),_xlfn.REGEXEXTRACT(CELL("address",'Raw Data'!B10),"\$([A-Z]+)\$[0-9]+"),""),"")} | C10: {=IFERROR(IF(OR('Raw Data'!C10="",LEN(TRIM('Raw Data'!C10))=0),_xlfn.REGEXEXTRACT(CELL("address",'Raw Data'!C10),"\$([A-Z]+)\$[0-9]+"),""),"")}
B11: {=IFERROR(IF(OR('Raw Data'!B11="",LEN(TRIM('Raw Data'!B11))=0),_xlfn.REGEXEXTRACT(CELL("address",'Raw Data'!B11),"\$([A-Z]+)\$[0-9]+"),""),"")} | C11: {=IFERROR(IF(OR('Raw Data'!C11="",LEN(TRIM('Raw Data'!C11))=0),_xlfn.REGEXEXTRACT(CELL("address",'Raw Data'!C11),"\$([A-Z]+)\$[0-9]+"),""),"")}
B12: {=IFERROR(IF(OR('Raw Data'!B12="",LEN(TRIM('Raw Data'!B12))=0),_xlfn.REGEXEXTRACT(CELL("address",'Raw Data'!B12),"\$([A-Z]+)\$[0-9]+"),""),"")} | C12: {=IFERROR(IF(OR('Raw Data'!C12="",LEN(TRIM('Raw Data'!C12))=0),_xlfn.REGEXEXTRACT(CELL("address",'Raw Data'!C12),"\$([A-Z]+)\$[0-9]+"),""),"")}
B13: {=IFERROR(IF(OR('Raw Data'!B13="",LEN(TRIM('Raw Data'!B13))=0),_xlfn.REGEXEXTRACT(CELL("address",'Raw Data'!B13),"\$([A-Z]+)\$[0-9]+"),""),"")} | C13: {=IFERROR(IF(OR('Raw Data'!C13="",LEN(TRIM('Raw Data'!C13))=0),_xlfn.REGEXEXTRACT(CELL("address",'Raw Data'!C13),"\$([A-Z]+)\$[0-9]+"),""),"")}
B14: {=IFERROR(IF(OR('Raw Data'!B14="",LEN(TRIM('Raw Data'!B14))=0),_xlfn.REGEXEXTRACT(CELL("address",'Raw Data'!B14),"\$([A-Z]+)\$[0-9]+"),""),"")} | C14: {=IFERROR(IF(OR('Raw Data'!C14="",LEN(TRIM('Raw Data'!C14))=0),_xlfn.REGEXEXTRACT(CELL("address",'Raw Data'!C14),"\$([A-Z]+)\$[0-9]+"),""),"")}
B15: {=IFERROR(IF(OR('Raw Data'!B15="",LEN(TRIM('Raw Data'!B15))=0),_xlfn.REGEXEXTRACT(CELL("address",'Raw Data'!B15),"\$([A-Z]+)\$[0-9]+"),""),"")} | C15: {=IFERROR(IF(OR('Raw Data'!C15="",LEN(TRIM('Raw Data'!C15))=0),_xlfn.REGEXEXTRACT(CELL("address",'Raw Data'!C15),"\$([A-Z]+)\$[0-9]+"),""),"")}
B16: {=IFERROR(IF(OR('Raw Data'!B16="",LEN(TRIM('Raw Data'!B16))=0),_xlfn.REGEXEXTRACT(CELL("address",'Raw Data'!B16),"\$([A-Z]+)\$[0-9]+"),""),"")} | C16: {=IFERROR(IF(OR('Raw Data'!C16="",LEN(TRIM('Raw Data'!C16))=0),_xlfn.REGEXEXTRACT(CELL("address",'Raw Data'!C16),"\$([A-Z]+)\$[0-9]+"),""),"")}
B17: {=IFERROR(IF(OR('Raw Data'!B17="",LEN(TRIM('Raw Data'!B17))=0),_xlfn.REGEXEXTRACT(CELL("address",'Raw Data'!B17),"\$([A-Z]+)\$[0-9]+"),""),"")} | C17: {=IFERROR(IF(OR('Raw Data'!C17="",LEN(TRIM('Raw Data'!C17))=0),_xlfn.REGEXEXTRACT(CELL("address",'Raw Data'!C17),"\$([A-Z]+)\$[0-9]+"),""),"")}
B18: {=IFERROR(IF(OR('Raw Data'!B18="",LEN(TRIM('Raw Data'!B18))=0),_xlfn.REGEXEXTRACT(CELL("address",'Raw Data'!B18),"\$([A-Z]+)\$[0-9]+"),""),"")} | C18: {=IFERROR(IF(OR('Raw Data'!C18="",LEN(TRIM('Raw Data'!C18))=0),_xlfn.REGEXEXTRACT(CELL("address",'Raw Data'!C18),"\$([A-Z]+)\$[0-9]+"),""),"")}
B19: {=IFERROR(IF(OR('Raw Data'!B19="",LEN(TRIM('Raw Data'!B19))=0),_xlfn.REGEXEXTRACT(CELL("address",'Raw Data'!B19),"\$([A-Z]+)\$[0-9]+"),""),"")} | C19: {=IFERROR(IF(OR('Raw Data'!C19="",LEN(TRIM('Raw Data'!C19))=0),_xlfn.REGEXEXTRACT(CELL("address",'Raw Data'!C19),"\$([A-Z]+)\$[0-9]+"),""),"")}
B20: {=IFERROR(IF(OR('Raw Data'!B20="",LEN(TRIM('Raw Data'!B20))=0),_xlfn.REGEXEXTRACT(CELL("address",'Raw Data'!B20),"\$([A-Z]+)\$[0-9]+"),""),"")} | C20: {=IFERROR(IF(OR('Raw Data'!C20="",LEN(TRIM('Raw Data'!C20))=0),_xlfn.REGEXEXTRACT(CELL("address",'Raw Data'!C20),"\$([A-Z]+)\$[0-9]+"),""),"")}
B21: {=IFERROR(IF(OR('Raw Data'!B21="",LEN(TRIM('Raw Data'!B21))=0),_xlfn.REGEXEXTRACT(CELL("address",'Raw Data'!B21),"\$([A-Z]+)\$[0-9]+"),""),"")} | C21: {=IFERROR(IF(OR('Raw Data'!C21="",LEN(TRIM('Raw Data'!C21))=0),_xlfn.REGEXEXTRACT(CELL("address",'Raw Data'!C21),"\$([A-Z]+)\$[0-9]+"),""),"")}
... B295: {=IFERROR(IF(OR('Raw Data'!B295="",LEN(TRIM('Raw Data'!B295))=0),_xlfn.REGEXEXTRACT(CELL("address",'Raw Data'!B295),"\$([A-Z]+)\$[0-9]+"),""),"")} -> $B$295 | C295: {=IFERROR(IF(OR('Raw Data'!C295="",LEN(TRIM('Raw Data'!C295))=0),_xlfn.REGEXEXTRACT(CELL("address",'Raw Data'!C295),"\$([A-Z]+)\$[0-9]+"),""),"")} -> $C$295

Sheet Validate_Value
B8: NVARCHAR(255) | C8: NVARCHAR(20) | D8: DATE | E8: DECIMAL(13,2) | F8: DECIMAL(13,2) | G8: DECIMAL(13,2) | H8: DECIMAL(13,2) | I8: DECIMAL(13,2) | J8: DECIMAL(13,2) | K8: DECIMAL(13,2) | L8: DECIMAL(13,2) | M8: DECIMAL(13,2) | N8: DECIMAL(13,2) | O8: DECIMAL(13,2) | P8: DECIMAL(13,2) | Q8: DECIMAL(13,2) | R8: DECIMAL(13,2) | S8: DECIMAL(13,2) | T8: DECIMAL(13,2) | U8: DECIMAL(13,2) | V8: DECIMAL(13,2) | W8: DECIMAL(13,2) | X8: DECIMAL(13,2) | Y8: DECIMAL(13,2) | Z8: DECIMAL(13,2) | AA8: DECIMAL(13,2) | AB8: DECIMAL(13,2) | AC8: DECIMAL(13,2) | AD8: DECIMAL(13,2) | AE8: DECIMAL(13,2) | AF8: DECIMAL(13,2) | AG8: DECIMAL(13,2) | AH8: DECIMAL(13,2) | AI8: DECIMAL(13,2) | AJ8: DECIMAL(13,2)
B9: C1 | C9: C2 | D9: C3 | E9: C4 | F9: C5 | G9: C6 | H9: C7 | I9: C8 | J9: C9 | K9: C10 | L9: C11 | M9: C12 | N9: C13 | O9: C14 | P9: C15 | Q9: C16 | R9: C17 | S9: C18 | T9: C19 | U9: C20 | V9: C21 | W9: C22 | X9: C23 | Y9: C24 | Z9: C25 | AA9: C26 | AB9: C27 | AC9: C28 | AD9: C29 | AE9: C30 | AF9: C31 | AG9: C32 | AH9: C33 | AI9: C34 | AJ9: C35
B10: {=IFERROR(IF(OR('Raw Data'!B10="",LEN(TRIM('Raw Data'!B10))=0),"",IF(AND(LEN('Raw Data'!B10) <= 255,LEN('Raw Data'!B10)> 0),"",_xlfn.REGEXEXTRACT(CELL("address",'Raw Data'!B10),"\$([A-Z]+)\$[0-9]+"))),_xlfn.REGEXEXTRACT(CELL("address",'Raw Data'!B10),"\$([A-Z]+)\$[0-9]+"))} | C10: {=IFERROR(IF(OR('Raw Data'!C10="",LEN(TRIM('Raw Data'!C10))=0),"",IF(AND(LEN('Raw Data'!C10) <= 20,LEN('Raw Data'!C10)> 0),"",_xlfn.REGEXEXTRACT(CELL("address",'Raw Data'!C10),"\$([A-Z]+)\$[0-9]+"))),_xlfn.REGEXEXTRACT(CELL("address",'Raw Data'!C10),"\$([A-Z]+)\$[0-9]+"))} | D10: {=IFERROR(IF(OR('Raw Data'!D10="",LEN(TRIM('Raw Data'!D10))=0),"",IF(AND(ISNUMBER('Raw Data'!D10),'Raw Data'!D10>=Configuration!$D$2),"",_xlfn.REGEXEXTRACT(CELL("address",'Raw Data'!D10),"\$([A-Z]+)\$[0-9]+"))),_xlfn.REGEXEXTRACT(CELL("address",D10), "\$([A-Z]+)\$[0-9]+"))} | E10: {=IFERROR(IF(OR('Raw Data'!E10="",LEN(TRIM('Raw Data'!E10))=0),"",IF(AND(ISNUMBER('Raw Data'!E10), IFERROR('Raw Data'!E10 = ROUND('Raw Data'!E10, 2),FALSE)),"",_xlfn.REGEXEXTRACT(CELL("address",E10), "\$([A-Z]+)\$[0-9]+"))),_xlfn.REGEXEXTRACT(CELL("address",E10), "\$([A-Z]+)\$[0-9]+"))} | F10: {=IFERROR(IF(OR('Raw Data'!F10="",LEN(TRIM('Raw Data'!F10))=0),"",IF(AND(ISNUMBER('Raw Data'!F10), IFERROR('Raw Data'!F10 = ROUND('Raw Data'!F10, 2),FALSE)),"",_xlfn.REGEXEXTRACT(CELL("address",F10), "\$([A-Z]+)\$[0-9]+"))),_xlfn.REGEXEXTRACT(CELL("address",F10), "\$([A-Z]+)\$[0-9]+"))} | G10: {=IFERROR(IF(OR('Raw Data'!G10="",LEN(TRIM('Raw Data'!G10))=0),"",IF(AND(ISNUMBER('Raw Data'!G10), IFERROR('Raw Data'!G10 = ROUND('Raw Data'!G10, 2),FALSE)),"",_xlfn.REGEXEXTRACT(CELL("address",G10), "\$([A-Z]+)\$[0-9]+"))),_xlfn.REGEXEXTRACT(CELL("address",G10), "\$([A-Z]+)\$[0-9]+"))} | H10: {=IFERROR(IF(OR('Raw Data'!H10="",LEN(TRIM('Raw Data'!H10))=0),"",IF(AND(ISNUMBER('Raw Data'!H10), IFERROR('Raw Data'!H10 = ROUND('Raw Data'!H10, 2),FALSE)),"",_xlfn.REGEXEXTRACT(CELL("address",H10), "\$([A-Z]+)\$[0-9]+"))),_xlfn.REGEXEXTRACT(CELL("address",H10), "\$([A-Z]+)\$[0-9]+"))} | I10: {=IFERROR(IF(OR('Raw Data'!I10="",LEN(TRIM('Raw Data'!I10))=0),"",IF(AND(ISNUMBER('Raw Data'!I10), IFERROR('Raw Data'!I10 = ROUND('Raw Data'!I10, 2),FALSE)),"",_xlfn.REGEXEXTRACT(CELL("address",I10), "\$([A-Z]+)\$[0-9]+"))),_xlfn.REGEXEXTRACT(CELL("address",I10), "\$([A-Z]+)\$[0-9]+"))} | J10: {=IFERROR(IF(OR('Raw Data'!J10="",LEN(TRIM('Raw Data'!J10))=0),"",IF(AND(ISNUMBER('Raw Data'!J10), IFERROR('Raw Data'!J10 = ROUND('Raw Data'!J10, 2),FALSE)),"",_xlfn.REGEXEXTRACT(CELL("address",J10), "\$([A-Z]+)\$[0-9]+"))),_xlfn.REGEXEXTRACT(CELL("address",J10), "\$([A-Z]+)\$[0-9]+"))} | K10: {=IFERROR(IF(OR('Raw Data'!K10="",LEN(TRIM('Raw Data'!K10))=0),"",IF(AND(ISNUMBER('Raw Data'!K10), IFERROR('Raw Data'!K10 = ROUND('Raw Data'!K10, 2),FALSE)),"",_xlfn.REGEXEXTRACT(CELL("address",K10), "\$([A-Z]+)\$[0-9]+"))),_xlfn.REGEXEXTRACT(CELL("address",K10), "\$([A-Z]+)\$[0-9]+"))} | L10: {=IFERROR(IF(OR('Raw Data'!L10="",LEN(TRIM('Raw Data'!L10))=0),"",IF(AND(ISNUMBER('Raw Data'!L10), IFERROR('Raw Data'!L10 = ROUND('Raw Data'!L10, 2),FALSE)),"",_xlfn.REGEXEXTRACT(CELL("address",L10), "\$([A-Z]+)\$[0-9]+"))),_xlfn.REGEXEXTRACT(CELL("address",L10), "\$([A-Z]+)\$[0-9]+"))} | ... AJ10: {=IFERROR(IF(OR('Raw Data'!AJ10="",LEN(TRIM('Raw Data'!AJ10))=0),"",IF(AND(ISNUMBER('Raw Data'!AJ10), IFERROR('Raw Data'!AJ10 = ROUND('Raw Data'!AJ10, 2),FALSE)),"",_xlfn.REGEXEXTRACT(CELL("address",AJ10), "\$([A-Z]+)\$[0-9]+"))),_xlfn.REGEXEXTRACT(CELL("address",AJ10), "\$([A-Z]+)\$[0-9]+"))}
B11: {=IFERROR(IF(OR('Raw Data'!B11="",LEN(TRIM('Raw Data'!B11))=0),"",IF(AND(LEN('Raw Data'!B11) <= 255,LEN('Raw Data'!B11)> 0),"",_xlfn.REGEXEXTRACT(CELL("address",'Raw Data'!B11),"\$([A-Z]+)\$[0-9]+"))),_xlfn.REGEXEXTRACT(CELL("address",'Raw Data'!B11),"\$([A-Z]+)\$[0-9]+"))} | C11: {=IFERROR(IF(OR('Raw Data'!C11="",LEN(TRIM('Raw Data'!C11))=0),"",IF(AND(LEN('Raw Data'!C11) <= 20,LEN('Raw Data'!C11)> 0),"",_xlfn.REGEXEXTRACT(CELL("address",'Raw Data'!C11),"\$([A-Z]+)\$[0-9]+"))),_xlfn.REGEXEXTRACT(CELL("address",'Raw Data'!C11),"\$([A-Z]+)\$[0-9]+"))} | D11: {=IFERROR(IF(OR('Raw Data'!D11="",LEN(TRIM('Raw Data'!D11))=0),"",IF(AND(ISNUMBER('Raw Data'!D11),'Raw Data'!D11>=Configuration!$D$2),"",_xlfn.REGEXEXTRACT(CELL("address",'Raw Data'!D11),"\$([A-Z]+)\$[0-9]+"))),_xlfn.REGEXEXTRACT(CELL("address",D11), "\$([A-Z]+)\$[0-9]+"))} | E11: {=IFERROR(IF(OR('Raw Data'!E11="",LEN(TRIM('Raw Data'!E11))=0),"",IF(AND(ISNUMBER('Raw Data'!E11), IFERROR('Raw Data'!E11 = ROUND('Raw Data'!E11, 2),FALSE)),"",_xlfn.REGEXEXTRACT(CELL("address",E11), "\$([A-Z]+)\$[0-9]+"))),_xlfn.REGEXEXTRACT(CELL("address",E11), "\$([A-Z]+)\$[0-9]+"))} | F11: {=IFERROR(IF(OR('Raw Data'!F11="",LEN(TRIM('Raw Data'!F11))=0),"",IF(AND(ISNUMBER('Raw Data'!F11), IFERROR('Raw Data'!F11 = ROUND('Raw Data'!F11, 2),FALSE)),"",_xlfn.REGEXEXTRACT(CELL("address",F11), "\$([A-Z]+)\$[0-9]+"))),_xlfn.REGEXEXTRACT(CELL("address",F11), "\$([A-Z]+)\$[0-9]+"))} | G11: {=IFERROR(IF(OR('Raw Data'!G11="",LEN(TRIM('Raw Data'!G11))=0),"",IF(AND(ISNUMBER('Raw Data'!G11), IFERROR('Raw Data'!G11 = ROUND('Raw Data'!G11, 2),FALSE)),"",_xlfn.REGEXEXTRACT(CELL("address",G11), "\$([A-Z]+)\$[0-9]+"))),_xlfn.REGEXEXTRACT(CELL("address",G11), "\$([A-Z]+)\$[0-9]+"))} | H11: {=IFERROR(IF(OR('Raw Data'!H11="",LEN(TRIM('Raw Data'!H11))=0),"",IF(AND(ISNUMBER('Raw Data'!H11), IFERROR('Raw Data'!H11 = ROUND('Raw Data'!H11, 2),FALSE)),"",_xlfn.REGEXEXTRACT(CELL("address",H11), "\$([A-Z]+)\$[0-9]+"))),_xlfn.REGEXEXTRACT(CELL("address",H11), "\$([A-Z]+)\$[0-9]+"))} | I11: {=IFERROR(IF(OR('Raw Data'!I11="",LEN(TRIM('Raw Data'!I11))=0),"",IF(AND(ISNUMBER('Raw Data'!I11), IFERROR('Raw Data'!I11 = ROUND('Raw Data'!I11, 2),FALSE)),"",_xlfn.REGEXEXTRACT(CELL("address",I11), "\$([A-Z]+)\$[0-9]+"))),_xlfn.REGEXEXTRACT(CELL("address",I11), "\$([A-Z]+)\$[0-9]+"))} | J11: {=IFERROR(IF(OR('Raw Data'!J11="",LEN(TRIM('Raw Data'!J11))=0),"",IF(AND(ISNUMBER('Raw Data'!J11), IFERROR('Raw Data'!J11 = ROUND('Raw Data'!J11, 2),FALSE)),"",_xlfn.REGEXEXTRACT(CELL("address",J11), "\$([A-Z]+)\$[0-9]+"))),_xlfn.REGEXEXTRACT(CELL("address",J11), "\$([A-Z]+)\$[0-9]+"))} | K11: {=IFERROR(IF(OR('Raw Data'!K11="",LEN(TRIM('Raw Data'!K11))=0),"",IF(AND(ISNUMBER('Raw Data'!K11), IFERROR('Raw Data'!K11 = ROUND('Raw Data'!K11, 2),FALSE)),"",_xlfn.REGEXEXTRACT(CELL("address",K11), "\$([A-Z]+)\$[0-9]+"))),_xlfn.REGEXEXTRACT(CELL("address",K11), "\$([A-Z]+)\$[0-9]+"))} | L11: {=IFERROR(IF(OR('Raw Data'!L11="",LEN(TRIM('Raw Data'!L11))=0),"",IF(AND(ISNUMBER('Raw Data'!L11), IFERROR('Raw Data'!L11 = ROUND('Raw Data'!L11, 2),FALSE)),"",_xlfn.REGEXEXTRACT(CELL("address",L11), "\$([A-Z]+)\$[0-9]+"))),_xlfn.REGEXEXTRACT(CELL("address",L11), "\$([A-Z]+)\$[0-9]+"))} | ... AJ11: {=IFERROR(IF(OR('Raw Data'!AJ11="",LEN(TRIM('Raw Data'!AJ11))=0),"",IF(AND(ISNUMBER('Raw Data'!AJ11), IFERROR('Raw Data'!AJ11 = ROUND('Raw Data'!AJ11, 2),FALSE)),"",_xlfn.REGEXEXTRACT(CELL("address",AJ11), "\$([A-Z]+)\$[0-9]+"))),_xlfn.REGEXEXTRACT(CELL("address",AJ11), "\$([A-Z]+)\$[0-9]+"))}
B12: {=IFERROR(IF(OR('Raw Data'!B12="",LEN(TRIM('Raw Data'!B12))=0),"",IF(AND(LEN('Raw Data'!B12) <= 255,LEN('Raw Data'!B12)> 0),"",_xlfn.REGEXEXTRACT(CELL("address",'Raw Data'!B12),"\$([A-Z]+)\$[0-9]+"))),_xlfn.REGEXEXTRACT(CELL("address",'Raw Data'!B12),"\$([A-Z]+)\$[0-9]+"))} | C12: {=IFERROR(IF(OR('Raw Data'!C12="",LEN(TRIM('Raw Data'!C12))=0),"",IF(AND(LEN('Raw Data'!C12) <= 20,LEN('Raw Data'!C12)> 0),"",_xlfn.REGEXEXTRACT(CELL("address",'Raw Data'!C12),"\$([A-Z]+)\$[0-9]+"))),_xlfn.REGEXEXTRACT(CELL("address",'Raw Data'!C12),"\$([A-Z]+)\$[0-9]+"))} | D12: {=IFERROR(IF(OR('Raw Data'!D12="",LEN(TRIM('Raw Data'!D12))=0),"",IF(AND(ISNUMBER('Raw Data'!D12),'Raw Data'!D12>=Configuration!$D$2),"",_xlfn.REGEXEXTRACT(CELL("address",'Raw Data'!D12),"\$([A-Z]+)\$[0-9]+"))),_xlfn.REGEXEXTRACT(CELL("address",D12), "\$([A-Z]+)\$[0-9]+"))} | E12: {=IFERROR(IF(OR('Raw Data'!E12="",LEN(TRIM('Raw Data'!E12))=0),"",IF(AND(ISNUMBER('Raw Data'!E12), IFERROR('Raw Data'!E12 = ROUND('Raw Data'!E12, 2),FALSE)),"",_xlfn.REGEXEXTRACT(CELL("address",E12), "\$([A-Z]+)\$[0-9]+"))),_xlfn.REGEXEXTRACT(CELL("address",E12), "\$([A-Z]+)\$[0-9]+"))} | F12: {=IFERROR(IF(OR('Raw Data'!F12="",LEN(TRIM('Raw Data'!F12))=0),"",IF(AND(ISNUMBER('Raw Data'!F12), IFERROR('Raw Data'!F12 = ROUND('Raw Data'!F12, 2),FALSE)),"",_xlfn.REGEXEXTRACT(CELL("address",F12), "\$([A-Z]+)\$[0-9]+"))),_xlfn.REGEXEXTRACT(CELL("address",F12), "\$([A-Z]+)\$[0-9]+"))} | G12: {=IFERROR(IF(OR('Raw Data'!G12="",LEN(TRIM('Raw Data'!G12))=0),"",IF(AND(ISNUMBER('Raw Data'!G12), IFERROR('Raw Data'!G12 = ROUND('Raw Data'!G12, 2),FALSE)),"",_xlfn.REGEXEXTRACT(CELL("address",G12), "\$([A-Z]+)\$[0-9]+"))),_xlfn.REGEXEXTRACT(CELL("address",G12), "\$([A-Z]+)\$[0-9]+"))} | H12: {=IFERROR(IF(OR('Raw Data'!H12="",LEN(TRIM('Raw Data'!H12))=0),"",IF(AND(ISNUMBER('Raw Data'!H12), IFERROR('Raw Data'!H12 = ROUND('Raw Data'!H12, 2),FALSE)),"",_xlfn.REGEXEXTRACT(CELL("address",H12), "\$([A-Z]+)\$[0-9]+"))),_xlfn.REGEXEXTRACT(CELL("address",H12), "\$([A-Z]+)\$[0-9]+"))} | I12: {=IFERROR(IF(OR('Raw Data'!I12="",LEN(TRIM('Raw Data'!I12))=0),"",IF(AND(ISNUMBER('Raw Data'!I12), IFERROR('Raw Data'!I12 = ROUND('Raw Data'!I12, 2),FALSE)),"",_xlfn.REGEXEXTRACT(CELL("address",I12), "\$([A-Z]+)\$[0-9]+"))),_xlfn.REGEXEXTRACT(CELL("address",I12), "\$([A-Z]+)\$[0-9]+"))} | J12: {=IFERROR(IF(OR('Raw Data'!J12="",LEN(TRIM('Raw Data'!J12))=0),"",IF(AND(ISNUMBER('Raw Data'!J12), IFERROR('Raw Data'!J12 = ROUND('Raw Data'!J12, 2),FALSE)),"",_xlfn.REGEXEXTRACT(CELL("address",J12), "\$([A-Z]+)\$[0-9]+"))),_xlfn.REGEXEXTRACT(CELL("address",J12), "\$([A-Z]+)\$[0-9]+"))} | K12: {=IFERROR(IF(OR('Raw Data'!K12="",LEN(TRIM('Raw Data'!K12))=0),"",IF(AND(ISNUMBER('Raw Data'!K12), IFERROR('Raw Data'!K12 = ROUND('Raw Data'!K12, 2),FALSE)),"",_xlfn.REGEXEXTRACT(CELL("address",K12), "\$([A-Z]+)\$[0-9]+"))),_xlfn.REGEXEXTRACT(CELL("address",K12), "\$([A-Z]+)\$[0-9]+"))} | L12: {=IFERROR(IF(OR('Raw Data'!L12="",LEN(TRIM('Raw Data'!L12))=0),"",IF(AND(ISNUMBER('Raw Data'!L12), IFERROR('Raw Data'!L12 = ROUND('Raw Data'!L12, 2),FALSE)),"",_xlfn.REGEXEXTRACT(CELL("address",L12), "\$([A-Z]+)\$[0-9]+"))),_xlfn.REGEXEXTRACT(CELL("address",L12), "\$([A-Z]+)\$[0-9]+"))} | ... AJ12: {=IFERROR(IF(OR('Raw Data'!AJ12="",LEN(TRIM('Raw Data'!AJ12))=0),"",IF(AND(ISNUMBER('Raw Data'!AJ12), IFERROR('Raw Data'!AJ12 = ROUND('Raw Data'!AJ12, 2),FALSE)),"",_xlfn.REGEXEXTRACT(CELL("address",AJ12), "\$([A-Z]+)\$[0-9]+"))),_xlfn.REGEXEXTRACT(CELL("address",AJ12), "\$([A-Z]+)\$[0-9]+"))}
B13: {=IFERROR(IF(OR('Raw Data'!B13="",LEN(TRIM('Raw Data'!B13))=0),"",IF(AND(LEN('Raw Data'!B13) <= 255,LEN('Raw Data'!B13)> 0),"",_xlfn.REGEXEXTRACT(CELL("address",'Raw Data'!B13),"\$([A-Z]+)\$[0-9]+"))),_xlfn.REGEXEXTRACT(CELL("address",'Raw Data'!B13),"\$([A-Z]+)\$[0-9]+"))} | C13: {=IFERROR(IF(OR('Raw Data'!C13="",LEN(TRIM('Raw Data'!C13))=0),"",IF(AND(LEN('Raw Data'!C13) <= 20,LEN('Raw Data'!C13)> 0),"",_xlfn.REGEXEXTRACT(CELL("address",'Raw Data'!C13),"\$([A-Z]+)\$[0-9]+"))),_xlfn.REGEXEXTRACT(CELL("address",'Raw Data'!C13),"\$([A-Z]+)\$[0-9]+"))} | D13: {=IFERROR(IF(OR('Raw Data'!D13="",LEN(TRIM('Raw Data'!D13))=0),"",IF(AND(ISNUMBER('Raw Data'!D13),'Raw Data'!D13>=Configuration!$D$2),"",_xlfn.REGEXEXTRACT(CELL("address",'Raw Data'!D13),"\$([A-Z]+)\$[0-9]+"))),_xlfn.REGEXEXTRACT(CELL("address",D13), "\$([A-Z]+)\$[0-9]+"))} | E13: {=IFERROR(IF(OR('Raw Data'!E13="",LEN(TRIM('Raw Data'!E13))=0),"",IF(AND(ISNUMBER('Raw Data'!E13), IFERROR('Raw Data'!E13 = ROUND('Raw Data'!E13, 2),FALSE)),"",_xlfn.REGEXEXTRACT(CELL("address",E13), "\$([A-Z]+)\$[0-9]+"))),_xlfn.REGEXEXTRACT(CELL("address",E13), "\$([A-Z]+)\$[0-9]+"))} | F13: {=IFERROR(IF(OR('Raw Data'!F13="",LEN(TRIM('Raw Data'!F13))=0),"",IF(AND(ISNUMBER('Raw Data'!F13), IFERROR('Raw Data'!F13 = ROUND('Raw Data'!F13, 2),FALSE)),"",_xlfn.REGEXEXTRACT(CELL("address",F13), "\$([A-Z]+)\$[0-9]+"))),_xlfn.REGEXEXTRACT(CELL("address",F13), "\$([A-Z]+)\$[0-9]+"))} | G13: {=IFERROR(IF(OR('Raw Data'!G13="",LEN(TRIM('Raw Data'!G13))=0),"",IF(AND(ISNUMBER('Raw Data'!G13), IFERROR('Raw Data'!G13 = ROUND('Raw Data'!G13, 2),FALSE)),"",_xlfn.REGEXEXTRACT(CELL("address",G13), "\$([A-Z]+)\$[0-9]+"))),_xlfn.REGEXEXTRACT(CELL("address",G13), "\$([A-Z]+)\$[0-9]+"))} | H13: {=IFERROR(IF(OR('Raw Data'!H13="",LEN(TRIM('Raw Data'!H13))=0),"",IF(AND(ISNUMBER('Raw Data'!H13), IFERROR('Raw Data'!H13 = ROUND('Raw Data'!H13, 2),FALSE)),"",_xlfn.REGEXEXTRACT(CELL("address",H13), "\$([A-Z]+)\$[0-9]+"))),_xlfn.REGEXEXTRACT(CELL("address",H13), "\$([A-Z]+)\$[0-9]+"))} | I13: {=IFERROR(IF(OR('Raw Data'!I13="",LEN(TRIM('Raw Data'!I13))=0),"",IF(AND(ISNUMBER('Raw Data'!I13), IFERROR('Raw Data'!I13 = ROUND('Raw Data'!I13, 2),FALSE)),"",_xlfn.REGEXEXTRACT(CELL("address",I13), "\$([A-Z]+)\$[0-9]+"))),_xlfn.REGEXEXTRACT(CELL("address",I13), "\$([A-Z]+)\$[0-9]+"))} | J13: {=IFERROR(IF(OR('Raw Data'!J13="",LEN(TRIM('Raw Data'!J13))=0),"",IF(AND(ISNUMBER('Raw Data'!J13), IFERROR('Raw Data'!J13 = ROUND('Raw Data'!J13, 2),FALSE)),"",_xlfn.REGEXEXTRACT(CELL("address",J13), "\$([A-Z]+)\$[0-9]+"))),_xlfn.REGEXEXTRACT(CELL("address",J13), "\$([A-Z]+)\$[0-9]+"))} | K13: {=IFERROR(IF(OR('Raw Data'!K13="",LEN(TRIM('Raw Data'!K13))=0),"",IF(AND(ISNUMBER('Raw Data'!K13), IFERROR('Raw Data'!K13 = ROUND('Raw Data'!K13, 2),FALSE)),"",_xlfn.REGEXEXTRACT(CELL("address",K13), "\$([A-Z]+)\$[0-9]+"))),_xlfn.REGEXEXTRACT(CELL("address",K13), "\$([A-Z]+)\$[0-9]+"))} | L13: {=IFERROR(IF(OR('Raw Data'!L13="",LEN(TRIM('Raw Data'!L13))=0),"",IF(AND(ISNUMBER('Raw Data'!L13), IFERROR('Raw Data'!L13 = ROUND('Raw Data'!L13, 2),FALSE)),"",_xlfn.REGEXEXTRACT(CELL("address",L13), "\$([A-Z]+)\$[0-9]+"))),_xlfn.REGEXEXTRACT(CELL("address",L13), "\$([A-Z]+)\$[0-9]+"))} | ... AJ13: {=IFERROR(IF(OR('Raw Data'!AJ13="",LEN(TRIM('Raw Data'!AJ13))=0),"",IF(AND(ISNUMBER('Raw Data'!AJ13), IFERROR('Raw Data'!AJ13 = ROUND('Raw Data'!AJ13, 2),FALSE)),"",_xlfn.REGEXEXTRACT(CELL("address",AJ13), "\$([A-Z]+)\$[0-9]+"))),_xlfn.REGEXEXTRACT(CELL("address",AJ13), "\$([A-Z]+)\$[0-9]+"))}
B14: {=IFERROR(IF(OR('Raw Data'!B14="",LEN(TRIM('Raw Data'!B14))=0),"",IF(AND(LEN('Raw Data'!B14) <= 255,LEN('Raw Data'!B14)> 0),"",_xlfn.REGEXEXTRACT(CELL("address",'Raw Data'!B14),"\$([A-Z]+)\$[0-9]+"))),_xlfn.REGEXEXTRACT(CELL("address",'Raw Data'!B14),"\$([A-Z]+)\$[0-9]+"))} | C14: {=IFERROR(IF(OR('Raw Data'!C14="",LEN(TRIM('Raw Data'!C14))=0),"",IF(AND(LEN('Raw Data'!C14) <= 20,LEN('Raw Data'!C14)> 0),"",_xlfn.REGEXEXTRACT(CELL("address",'Raw Data'!C14),"\$([A-Z]+)\$[0-9]+"))),_xlfn.REGEXEXTRACT(CELL("address",'Raw Data'!C14),"\$([A-Z]+)\$[0-9]+"))} | D14: {=IFERROR(IF(OR('Raw Data'!D14="",LEN(TRIM('Raw Data'!D14))=0),"",IF(AND(ISNUMBER('Raw Data'!D14),'Raw Data'!D14>=Configuration!$D$2),"",_xlfn.REGEXEXTRACT(CELL("address",'Raw Data'!D14),"\$([A-Z]+)\$[0-9]+"))),_xlfn.REGEXEXTRACT(CELL("address",D14), "\$([A-Z]+)\$[0-9]+"))} | E14: {=IFERROR(IF(OR('Raw Data'!E14="",LEN(TRIM('Raw Data'!E14))=0),"",IF(AND(ISNUMBER('Raw Data'!E14), IFERROR('Raw Data'!E14 = ROUND('Raw Data'!E14, 2),FALSE)),"",_xlfn.REGEXEXTRACT(CELL("address",E14), "\$([A-Z]+)\$[0-9]+"))),_xlfn.REGEXEXTRACT(CELL("address",E14), "\$([A-Z]+)\$[0-9]+"))} | F14: {=IFERROR(IF(OR('Raw Data'!F14="",LEN(TRIM('Raw Data'!F14))=0),"",IF(AND(ISNUMBER('Raw Data'!F14), IFERROR('Raw Data'!F14 = ROUND('Raw Data'!F14, 2),FALSE)),"",_xlfn.REGEXEXTRACT(CELL("address",F14), "\$([A-Z]+)\$[0-9]+"))),_xlfn.REGEXEXTRACT(CELL("address",F14), "\$([A-Z]+)\$[0-9]+"))} | G14: {=IFERROR(IF(OR('Raw Data'!G14="",LEN(TRIM('Raw Data'!G14))=0),"",IF(AND(ISNUMBER('Raw Data'!G14), IFERROR('Raw Data'!G14 = ROUND('Raw Data'!G14, 2),FALSE)),"",_xlfn.REGEXEXTRACT(CELL("address",G14), "\$([A-Z]+)\$[0-9]+"))),_xlfn.REGEXEXTRACT(CELL("address",G14), "\$([A-Z]+)\$[0-9]+"))} | H14: {=IFERROR(IF(OR('Raw Data'!H14="",LEN(TRIM('Raw Data'!H14))=0),"",IF(AND(ISNUMBER('Raw Data'!H14), IFERROR('Raw Data'!H14 = ROUND('Raw Data'!H14, 2),FALSE)),"",_xlfn.REGEXEXTRACT(CELL("address",H14), "\$([A-Z]+)\$[0-9]+"))),_xlfn.REGEXEXTRACT(CELL("address",H14), "\$([A-Z]+)\$[0-9]+"))} | I14: {=IFERROR(IF(OR('Raw Data'!I14="",LEN(TRIM('Raw Data'!I14))=0),"",IF(AND(ISNUMBER('Raw Data'!I14), IFERROR('Raw Data'!I14 = ROUND('Raw Data'!I14, 2),FALSE)),"",_xlfn.REGEXEXTRACT(CELL("address",I14), "\$([A-Z]+)\$[0-9]+"))),_xlfn.REGEXEXTRACT(CELL("address",I14), "\$([A-Z]+)\$[0-9]+"))} | J14: {=IFERROR(IF(OR('Raw Data'!J14="",LEN(TRIM('Raw Data'!J14))=0),"",IF(AND(ISNUMBER('Raw Data'!J14), IFERROR('Raw Data'!J14 = ROUND('Raw Data'!J14, 2),FALSE)),"",_xlfn.REGEXEXTRACT(CELL("address",J14), "\$([A-Z]+)\$[0-9]+"))),_xlfn.REGEXEXTRACT(CELL("address",J14), "\$([A-Z]+)\$[0-9]+"))} | K14: {=IFERROR(IF(OR('Raw Data'!K14="",LEN(TRIM('Raw Data'!K14))=0),"",IF(AND(ISNUMBER('Raw Data'!K14), IFERROR('Raw Data'!K14 = ROUND('Raw Data'!K14, 2),FALSE)),"",_xlfn.REGEXEXTRACT(CELL("address",K14), "\$([A-Z]+)\$[0-9]+"))),_xlfn.REGEXEXTRACT(CELL("address",K14), "\$([A-Z]+)\$[0-9]+"))} | L14: {=IFERROR(IF(OR('Raw Data'!L14="",LEN(TRIM('Raw Data'!L14))=0),"",IF(AND(ISNUMBER('Raw Data'!L14), IFERROR('Raw Data'!L14 = ROUND('Raw Data'!L14, 2),FALSE)),"",_xlfn.REGEXEXTRACT(CELL("address",L14), "\$([A-Z]+)\$[0-9]+"))),_xlfn.REGEXEXTRACT(CELL("address",L14), "\$([A-Z]+)\$[0-9]+"))} | ... AJ14: {=IFERROR(IF(OR('Raw Data'!AJ14="",LEN(TRIM('Raw Data'!AJ14))=0),"",IF(AND(ISNUMBER('Raw Data'!AJ14), IFERROR('Raw Data'!AJ14 = ROUND('Raw Data'!AJ14, 2),FALSE)),"",_xlfn.REGEXEXTRACT(CELL("address",AJ14), "\$([A-Z]+)\$[0-9]+"))),_xlfn.REGEXEXTRACT(CELL("address",AJ14), "\$([A-Z]+)\$[0-9]+"))}
B15: {=IFERROR(IF(OR('Raw Data'!B15="",LEN(TRIM('Raw Data'!B15))=0),"",IF(AND(LEN('Raw Data'!B15) <= 255,LEN('Raw Data'!B15)> 0),"",_xlfn.REGEXEXTRACT(CELL("address",'Raw Data'!B15),"\$([A-Z]+)\$[0-9]+"))),_xlfn.REGEXEXTRACT(CELL("address",'Raw Data'!B15),"\$([A-Z]+)\$[0-9]+"))} | C15: {=IFERROR(IF(OR('Raw Data'!C15="",LEN(TRIM('Raw Data'!C15))=0),"",IF(AND(LEN('Raw Data'!C15) <= 20,LEN('Raw Data'!C15)> 0),"",_xlfn.REGEXEXTRACT(CELL("address",'Raw Data'!C15),"\$([A-Z]+)\$[0-9]+"))),_xlfn.REGEXEXTRACT(CELL("address",'Raw Data'!C15),"\$([A-Z]+)\$[0-9]+"))} | D15: {=IFERROR(IF(OR('Raw Data'!D15="",LEN(TRIM('Raw Data'!D15))=0),"",IF(AND(ISNUMBER('Raw Data'!D15),'Raw Data'!D15>=Configuration!$D$2),"",_xlfn.REGEXEXTRACT(CELL("address",'Raw Data'!D15),"\$([A-Z]+)\$[0-9]+"))),_xlfn.REGEXEXTRACT(CELL("address",D15), "\$([A-Z]+)\$[0-9]+"))} | E15: {=IFERROR(IF(OR('Raw Data'!E15="",LEN(TRIM('Raw Data'!E15))=0),"",IF(AND(ISNUMBER('Raw Data'!E15), IFERROR('Raw Data'!E15 = ROUND('Raw Data'!E15, 2),FALSE)),"",_xlfn.REGEXEXTRACT(CELL("address",E15), "\$([A-Z]+)\$[0-9]+"))),_xlfn.REGEXEXTRACT(CELL("address",E15), "\$([A-Z]+)\$[0-9]+"))} | F15: {=IFERROR(IF(OR('Raw Data'!F15="",LEN(TRIM('Raw Data'!F15))=0),"",IF(AND(ISNUMBER('Raw Data'!F15), IFERROR('Raw Data'!F15 = ROUND('Raw Data'!F15, 2),FALSE)),"",_xlfn.REGEXEXTRACT(CELL("address",F15), "\$([A-Z]+)\$[0-9]+"))),_xlfn.REGEXEXTRACT(CELL("address",F15), "\$([A-Z]+)\$[0-9]+"))} | G15: {=IFERROR(IF(OR('Raw Data'!G15="",LEN(TRIM('Raw Data'!G15))=0),"",IF(AND(ISNUMBER('Raw Data'!G15), IFERROR('Raw Data'!G15 = ROUND('Raw Data'!G15, 2),FALSE)),"",_xlfn.REGEXEXTRACT(CELL("address",G15), "\$([A-Z]+)\$[0-9]+"))),_xlfn.REGEXEXTRACT(CELL("address",G15), "\$([A-Z]+)\$[0-9]+"))} | H15: {=IFERROR(IF(OR('Raw Data'!H15="",LEN(TRIM('Raw Data'!H15))=0),"",IF(AND(ISNUMBER('Raw Data'!H15), IFERROR('Raw Data'!H15 = ROUND('Raw Data'!H15, 2),FALSE)),"",_xlfn.REGEXEXTRACT(CELL("address",H15), "\$([A-Z]+)\$[0-9]+"))),_xlfn.REGEXEXTRACT(CELL("address",H15), "\$([A-Z]+)\$[0-9]+"))} | I15: {=IFERROR(IF(OR('Raw Data'!I15="",LEN(TRIM('Raw Data'!I15))=0),"",IF(AND(ISNUMBER('Raw Data'!I15), IFERROR('Raw Data'!I15 = ROUND('Raw Data'!I15, 2),FALSE)),"",_xlfn.REGEXEXTRACT(CELL("address",I15), "\$([A-Z]+)\$[0-9]+"))),_xlfn.REGEXEXTRACT(CELL("address",I15), "\$([A-Z]+)\$[0-9]+"))} | J15: {=IFERROR(IF(OR('Raw Data'!J15="",LEN(TRIM('Raw Data'!J15))=0),"",IF(AND(ISNUMBER('Raw Data'!J15), IFERROR('Raw Data'!J15 = ROUND('Raw Data'!J15, 2),FALSE)),"",_xlfn.REGEXEXTRACT(CELL("address",J15), "\$([A-Z]+)\$[0-9]+"))),_xlfn.REGEXEXTRACT(CELL("address",J15), "\$([A-Z]+)\$[0-9]+"))} | K15: {=IFERROR(IF(OR('Raw Data'!K15="",LEN(TRIM('Raw Data'!K15))=0),"",IF(AND(ISNUMBER('Raw Data'!K15), IFERROR('Raw Data'!K15 = ROUND('Raw Data'!K15, 2),FALSE)),"",_xlfn.REGEXEXTRACT(CELL("address",K15), "\$([A-Z]+)\$[0-9]+"))),_xlfn.REGEXEXTRACT(CELL("address",K15), "\$([A-Z]+)\$[0-9]+"))} | L15: {=IFERROR(IF(OR('Raw Data'!L15="",LEN(TRIM('Raw Data'!L15))=0),"",IF(AND(ISNUMBER('Raw Data'!L15), IFERROR('Raw Data'!L15 = ROUND('Raw Data'!L15, 2),FALSE)),"",_xlfn.REGEXEXTRACT(CELL("address",L15), "\$([A-Z]+)\$[0-9]+"))),_xlfn.REGEXEXTRACT(CELL("address",L15), "\$([A-Z]+)\$[0-9]+"))} | ... AJ15: {=IFERROR(IF(OR('Raw Data'!AJ15="",LEN(TRIM('Raw Data'!AJ15))=0),"",IF(AND(ISNUMBER('Raw Data'!AJ15), IFERROR('Raw Data'!AJ15 = ROUND('Raw Data'!AJ15, 2),FALSE)),"",_xlfn.REGEXEXTRACT(CELL("address",AJ15), "\$([A-Z]+)\$[0-9]+"))),_xlfn.REGEXEXTRACT(CELL("address",AJ15), "\$([A-Z]+)\$[0-9]+"))}
B16: {=IFERROR(IF(OR('Raw Data'!B16="",LEN(TRIM('Raw Data'!B16))=0),"",IF(AND(LEN('Raw Data'!B16) <= 255,LEN('Raw Data'!B16)> 0),"",_xlfn.REGEXEXTRACT(CELL("address",'Raw Data'!B16),"\$([A-Z]+)\$[0-9]+"))),_xlfn.REGEXEXTRACT(CELL("address",'Raw Data'!B16),"\$([A-Z]+)\$[0-9]+"))} | C16: {=IFERROR(IF(OR('Raw Data'!C16="",LEN(TRIM('Raw Data'!C16))=0),"",IF(AND(LEN('Raw Data'!C16) <= 20,LEN('Raw Data'!C16)> 0),"",_xlfn.REGEXEXTRACT(CELL("address",'Raw Data'!C16),"\$([A-Z]+)\$[0-9]+"))),_xlfn.REGEXEXTRACT(CELL("address",'Raw Data'!C16),"\$([A-Z]+)\$[0-9]+"))} | D16: {=IFERROR(IF(OR('Raw Data'!D16="",LEN(TRIM('Raw Data'!D16))=0),"",IF(AND(ISNUMBER('Raw Data'!D16),'Raw Data'!D16>=Configuration!$D$2),"",_xlfn.REGEXEXTRACT(CELL("address",'Raw Data'!D16),"\$([A-Z]+)\$[0-9]+"))),_xlfn.REGEXEXTRACT(CELL("address",D16), "\$([A-Z]+)\$[0-9]+"))} | E16: {=IFERROR(IF(OR('Raw Data'!E16="",LEN(TRIM('Raw Data'!E16))=0),"",IF(AND(ISNUMBER('Raw Data'!E16), IFERROR('Raw Data'!E16 = ROUND('Raw Data'!E16, 2),FALSE)),"",_xlfn.REGEXEXTRACT(CELL("address",E16), "\$([A-Z]+)\$[0-9]+"))),_xlfn.REGEXEXTRACT(CELL("address",E16), "\$([A-Z]+)\$[0-9]+"))} | F16: {=IFERROR(IF(OR('Raw Data'!F16="",LEN(TRIM('Raw Data'!F16))=0),"",IF(AND(ISNUMBER('Raw Data'!F16), IFERROR('Raw Data'!F16 = ROUND('Raw Data'!F16, 2),FALSE)),"",_xlfn.REGEXEXTRACT(CELL("address",F16), "\$([A-Z]+)\$[0-9]+"))),_xlfn.REGEXEXTRACT(CELL("address",F16), "\$([A-Z]+)\$[0-9]+"))} | G16: {=IFERROR(IF(OR('Raw Data'!G16="",LEN(TRIM('Raw Data'!G16))=0),"",IF(AND(ISNUMBER('Raw Data'!G16), IFERROR('Raw Data'!G16 = ROUND('Raw Data'!G16, 2),FALSE)),"",_xlfn.REGEXEXTRACT(CELL("address",G16), "\$([A-Z]+)\$[0-9]+"))),_xlfn.REGEXEXTRACT(CELL("address",G16), "\$([A-Z]+)\$[0-9]+"))} | H16: {=IFERROR(IF(OR('Raw Data'!H16="",LEN(TRIM('Raw Data'!H16))=0),"",IF(AND(ISNUMBER('Raw Data'!H16), IFERROR('Raw Data'!H16 = ROUND('Raw Data'!H16, 2),FALSE)),"",_xlfn.REGEXEXTRACT(CELL("address",H16), "\$([A-Z]+)\$[0-9]+"))),_xlfn.REGEXEXTRACT(CELL("address",H16), "\$([A-Z]+)\$[0-9]+"))} | I16: {=IFERROR(IF(OR('Raw Data'!I16="",LEN(TRIM('Raw Data'!I16))=0),"",IF(AND(ISNUMBER('Raw Data'!I16), IFERROR('Raw Data'!I16 = ROUND('Raw Data'!I16, 2),FALSE)),"",_xlfn.REGEXEXTRACT(CELL("address",I16), "\$([A-Z]+)\$[0-9]+"))),_xlfn.REGEXEXTRACT(CELL("address",I16), "\$([A-Z]+)\$[0-9]+"))} | J16: {=IFERROR(IF(OR('Raw Data'!J16="",LEN(TRIM('Raw Data'!J16))=0),"",IF(AND(ISNUMBER('Raw Data'!J16), IFERROR('Raw Data'!J16 = ROUND('Raw Data'!J16, 2),FALSE)),"",_xlfn.REGEXEXTRACT(CELL("address",J16), "\$([A-Z]+)\$[0-9]+"))),_xlfn.REGEXEXTRACT(CELL("address",J16), "\$([A-Z]+)\$[0-9]+"))} | K16: {=IFERROR(IF(OR('Raw Data'!K16="",LEN(TRIM('Raw Data'!K16))=0),"",IF(AND(ISNUMBER('Raw Data'!K16), IFERROR('Raw Data'!K16 = ROUND('Raw Data'!K16, 2),FALSE)),"",_xlfn.REGEXEXTRACT(CELL("address",K16), "\$([A-Z]+)\$[0-9]+"))),_xlfn.REGEXEXTRACT(CELL("address",K16), "\$([A-Z]+)\$[0-9]+"))} | L16: {=IFERROR(IF(OR('Raw Data'!L16="",LEN(TRIM('Raw Data'!L16))=0),"",IF(AND(ISNUMBER('Raw Data'!L16), IFERROR('Raw Data'!L16 = ROUND('Raw Data'!L16, 2),FALSE)),"",_xlfn.REGEXEXTRACT(CELL("address",L16), "\$([A-Z]+)\$[0-9]+"))),_xlfn.REGEXEXTRACT(CELL("address",L16), "\$([A-Z]+)\$[0-9]+"))} | ... AJ16: {=IFERROR(IF(OR('Raw Data'!AJ16="",LEN(TRIM('Raw Data'!AJ16))=0),"",IF(AND(ISNUMBER('Raw Data'!AJ16), IFERROR('Raw Data'!AJ16 = ROUND('Raw Data'!AJ16, 2),FALSE)),"",_xlfn.REGEXEXTRACT(CELL("address",AJ16), "\$([A-Z]+)\$[0-9]+"))),_xlfn.REGEXEXTRACT(CELL("address",AJ16), "\$([A-Z]+)\$[0-9]+"))}
B17: {=IFERROR(IF(OR('Raw Data'!B17="",LEN(TRIM('Raw Data'!B17))=0),"",IF(AND(LEN('Raw Data'!B17) <= 255,LEN('Raw Data'!B17)> 0),"",_xlfn.REGEXEXTRACT(CELL("address",'Raw Data'!B17),"\$([A-Z]+)\$[0-9]+"))),_xlfn.REGEXEXTRACT(CELL("address",'Raw Data'!B17),"\$([A-Z]+)\$[0-9]+"))} | C17: {=IFERROR(IF(OR('Raw Data'!C17="",LEN(TRIM('Raw Data'!C17))=0),"",IF(AND(LEN('Raw Data'!C17) <= 20,LEN('Raw Data'!C17)> 0),"",_xlfn.REGEXEXTRACT(CELL("address",'Raw Data'!C17),"\$([A-Z]+)\$[0-9]+"))),_xlfn.REGEXEXTRACT(CELL("address",'Raw Data'!C17),"\$([A-Z]+)\$[0-9]+"))} | D17: {=IFERROR(IF(OR('Raw Data'!D17="",LEN(TRIM('Raw Data'!D17))=0),"",IF(AND(ISNUMBER('Raw Data'!D17),'Raw Data'!D17>=Configuration!$D$2),"",_xlfn.REGEXEXTRACT(CELL("address",'Raw Data'!D17),"\$([A-Z]+)\$[0-9]+"))),_xlfn.REGEXEXTRACT(CELL("address",D17), "\$([A-Z]+)\$[0-9]+"))} | E17: {=IFERROR(IF(OR('Raw Data'!E17="",LEN(TRIM('Raw Data'!E17))=0),"",IF(AND(ISNUMBER('Raw Data'!E17), IFERROR('Raw Data'!E17 = ROUND('Raw Data'!E17, 2),FALSE)),"",_xlfn.REGEXEXTRACT(CELL("address",E17), "\$([A-Z]+)\$[0-9]+"))),_xlfn.REGEXEXTRACT(CELL("address",E17), "\$([A-Z]+)\$[0-9]+"))} | F17: {=IFERROR(IF(OR('Raw Data'!F17="",LEN(TRIM('Raw Data'!F17))=0),"",IF(AND(ISNUMBER('Raw Data'!F17), IFERROR('Raw Data'!F17 = ROUND('Raw Data'!F17, 2),FALSE)),"",_xlfn.REGEXEXTRACT(CELL("address",F17), "\$([A-Z]+)\$[0-9]+"))),_xlfn.REGEXEXTRACT(CELL("address",F17), "\$([A-Z]+)\$[0-9]+"))} | G17: {=IFERROR(IF(OR('Raw Data'!G17="",LEN(TRIM('Raw Data'!G17))=0),"",IF(AND(ISNUMBER('Raw Data'!G17), IFERROR('Raw Data'!G17 = ROUND('Raw Data'!G17, 2),FALSE)),"",_xlfn.REGEXEXTRACT(CELL("address",G17), "\$([A-Z]+)\$[0-9]+"))),_xlfn.REGEXEXTRACT(CELL("address",G17), "\$([A-Z]+)\$[0-9]+"))} | H17: {=IFERROR(IF(OR('Raw Data'!H17="",LEN(TRIM('Raw Data'!H17))=0),"",IF(AND(ISNUMBER('Raw Data'!H17), IFERROR('Raw Data'!H17 = ROUND('Raw Data'!H17, 2),FALSE)),"",_xlfn.REGEXEXTRACT(CELL("address",H17), "\$([A-Z]+)\$[0-9]+"))),_xlfn.REGEXEXTRACT(CELL("address",H17), "\$([A-Z]+)\$[0-9]+"))} | I17: {=IFERROR(IF(OR('Raw Data'!I17="",LEN(TRIM('Raw Data'!I17))=0),"",IF(AND(ISNUMBER('Raw Data'!I17), IFERROR('Raw Data'!I17 = ROUND('Raw Data'!I17, 2),FALSE)),"",_xlfn.REGEXEXTRACT(CELL("address",I17), "\$([A-Z]+)\$[0-9]+"))),_xlfn.REGEXEXTRACT(CELL("address",I17), "\$([A-Z]+)\$[0-9]+"))} | J17: {=IFERROR(IF(OR('Raw Data'!J17="",LEN(TRIM('Raw Data'!J17))=0),"",IF(AND(ISNUMBER('Raw Data'!J17), IFERROR('Raw Data'!J17 = ROUND('Raw Data'!J17, 2),FALSE)),"",_xlfn.REGEXEXTRACT(CELL("address",J17), "\$([A-Z]+)\$[0-9]+"))),_xlfn.REGEXEXTRACT(CELL("address",J17), "\$([A-Z]+)\$[0-9]+"))} | K17: {=IFERROR(IF(OR('Raw Data'!K17="",LEN(TRIM('Raw Data'!K17))=0),"",IF(AND(ISNUMBER('Raw Data'!K17), IFERROR('Raw Data'!K17 = ROUND('Raw Data'!K17, 2),FALSE)),"",_xlfn.REGEXEXTRACT(CELL("address",K17), "\$([A-Z]+)\$[0-9]+"))),_xlfn.REGEXEXTRACT(CELL("address",K17), "\$([A-Z]+)\$[0-9]+"))} | L17: {=IFERROR(IF(OR('Raw Data'!L17="",LEN(TRIM('Raw Data'!L17))=0),"",IF(AND(ISNUMBER('Raw Data'!L17), IFERROR('Raw Data'!L17 = ROUND('Raw Data'!L17, 2),FALSE)),"",_xlfn.REGEXEXTRACT(CELL("address",L17), "\$([A-Z]+)\$[0-9]+"))),_xlfn.REGEXEXTRACT(CELL("address",L17), "\$([A-Z]+)\$[0-9]+"))} | ... AJ17: {=IFERROR(IF(OR('Raw Data'!AJ17="",LEN(TRIM('Raw Data'!AJ17))=0),"",IF(AND(ISNUMBER('Raw Data'!AJ17), IFERROR('Raw Data'!AJ17 = ROUND('Raw Data'!AJ17, 2),FALSE)),"",_xlfn.REGEXEXTRACT(CELL("address",AJ17), "\$([A-Z]+)\$[0-9]+"))),_xlfn.REGEXEXTRACT(CELL("address",AJ17), "\$([A-Z]+)\$[0-9]+"))}
B18: {=IFERROR(IF(OR('Raw Data'!B18="",LEN(TRIM('Raw Data'!B18))=0),"",IF(AND(LEN('Raw Data'!B18) <= 255,LEN('Raw Data'!B18)> 0),"",_xlfn.REGEXEXTRACT(CELL("address",'Raw Data'!B18),"\$([A-Z]+)\$[0-9]+"))),_xlfn.REGEXEXTRACT(CELL("address",'Raw Data'!B18),"\$([A-Z]+)\$[0-9]+"))} | C18: {=IFERROR(IF(OR('Raw Data'!C18="",LEN(TRIM('Raw Data'!C18))=0),"",IF(AND(LEN('Raw Data'!C18) <= 20,LEN('Raw Data'!C18)> 0),"",_xlfn.REGEXEXTRACT(CELL("address",'Raw Data'!C18),"\$([A-Z]+)\$[0-9]+"))),_xlfn.REGEXEXTRACT(CELL("address",'Raw Data'!C18),"\$([A-Z]+)\$[0-9]+"))} | D18: {=IFERROR(IF(OR('Raw Data'!D18="",LEN(TRIM('Raw Data'!D18))=0),"",IF(AND(ISNUMBER('Raw Data'!D18),'Raw Data'!D18>=Configuration!$D$2),"",_xlfn.REGEXEXTRACT(CELL("address",'Raw Data'!D18),"\$([A-Z]+)\$[0-9]+"))),_xlfn.REGEXEXTRACT(CELL("address",D18), "\$([A-Z]+)\$[0-9]+"))} | E18: {=IFERROR(IF(OR('Raw Data'!E18="",LEN(TRIM('Raw Data'!E18))=0),"",IF(AND(ISNUMBER('Raw Data'!E18), IFERROR('Raw Data'!E18 = ROUND('Raw Data'!E18, 2),FALSE)),"",_xlfn.REGEXEXTRACT(CELL("address",E18), "\$([A-Z]+)\$[0-9]+"))),_xlfn.REGEXEXTRACT(CELL("address",E18), "\$([A-Z]+)\$[0-9]+"))} | F18: {=IFERROR(IF(OR('Raw Data'!F18="",LEN(TRIM('Raw Data'!F18))=0),"",IF(AND(ISNUMBER('Raw Data'!F18), IFERROR('Raw Data'!F18 = ROUND('Raw Data'!F18, 2),FALSE)),"",_xlfn.REGEXEXTRACT(CELL("address",F18), "\$([A-Z]+)\$[0-9]+"))),_xlfn.REGEXEXTRACT(CELL("address",F18), "\$([A-Z]+)\$[0-9]+"))} | G18: {=IFERROR(IF(OR('Raw Data'!G18="",LEN(TRIM('Raw Data'!G18))=0),"",IF(AND(ISNUMBER('Raw Data'!G18), IFERROR('Raw Data'!G18 = ROUND('Raw Data'!G18, 2),FALSE)),"",_xlfn.REGEXEXTRACT(CELL("address",G18), "\$([A-Z]+)\$[0-9]+"))),_xlfn.REGEXEXTRACT(CELL("address",G18), "\$([A-Z]+)\$[0-9]+"))} | H18: {=IFERROR(IF(OR('Raw Data'!H18="",LEN(TRIM('Raw Data'!H18))=0),"",IF(AND(ISNUMBER('Raw Data'!H18), IFERROR('Raw Data'!H18 = ROUND('Raw Data'!H18, 2),FALSE)),"",_xlfn.REGEXEXTRACT(CELL("address",H18), "\$([A-Z]+)\$[0-9]+"))),_xlfn.REGEXEXTRACT(CELL("address",H18), "\$([A-Z]+)\$[0-9]+"))} | I18: {=IFERROR(IF(OR('Raw Data'!I18="",LEN(TRIM('Raw Data'!I18))=0),"",IF(AND(ISNUMBER('Raw Data'!I18), IFERROR('Raw Data'!I18 = ROUND('Raw Data'!I18, 2),FALSE)),"",_xlfn.REGEXEXTRACT(CELL("address",I18), "\$([A-Z]+)\$[0-9]+"))),_xlfn.REGEXEXTRACT(CELL("address",I18), "\$([A-Z]+)\$[0-9]+"))} | J18: {=IFERROR(IF(OR('Raw Data'!J18="",LEN(TRIM('Raw Data'!J18))=0),"",IF(AND(ISNUMBER('Raw Data'!J18), IFERROR('Raw Data'!J18 = ROUND('Raw Data'!J18, 2),FALSE)),"",_xlfn.REGEXEXTRACT(CELL("address",J18), "\$([A-Z]+)\$[0-9]+"))),_xlfn.REGEXEXTRACT(CELL("address",J18), "\$([A-Z]+)\$[0-9]+"))} | K18: {=IFERROR(IF(OR('Raw Data'!K18="",LEN(TRIM('Raw Data'!K18))=0),"",IF(AND(ISNUMBER('Raw Data'!K18), IFERROR('Raw Data'!K18 = ROUND('Raw Data'!K18, 2),FALSE)),"",_xlfn.REGEXEXTRACT(CELL("address",K18), "\$([A-Z]+)\$[0-9]+"))),_xlfn.REGEXEXTRACT(CELL("address",K18), "\$([A-Z]+)\$[0-9]+"))} | L18: {=IFERROR(IF(OR('Raw Data'!L18="",LEN(TRIM('Raw Data'!L18))=0),"",IF(AND(ISNUMBER('Raw Data'!L18), IFERROR('Raw Data'!L18 = ROUND('Raw Data'!L18, 2),FALSE)),"",_xlfn.REGEXEXTRACT(CELL("address",L18), "\$([A-Z]+)\$[0-9]+"))),_xlfn.REGEXEXTRACT(CELL("address",L18), "\$([A-Z]+)\$[0-9]+"))} | ... AJ18: {=IFERROR(IF(OR('Raw Data'!AJ18="",LEN(TRIM('Raw Data'!AJ18))=0),"",IF(AND(ISNUMBER('Raw Data'!AJ18), IFERROR('Raw Data'!AJ18 = ROUND('Raw Data'!AJ18, 2),FALSE)),"",_xlfn.REGEXEXTRACT(CELL("address",AJ18), "\$([A-Z]+)\$[0-9]+"))),_xlfn.REGEXEXTRACT(CELL("address",AJ18), "\$([A-Z]+)\$[0-9]+"))}
B19: {=IFERROR(IF(OR('Raw Data'!B19="",LEN(TRIM('Raw Data'!B19))=0),"",IF(AND(LEN('Raw Data'!B19) <= 255,LEN('Raw Data'!B19)> 0),"",_xlfn.REGEXEXTRACT(CELL("address",'Raw Data'!B19),"\$([A-Z]+)\$[0-9]+"))),_xlfn.REGEXEXTRACT(CELL("address",'Raw Data'!B19),"\$([A-Z]+)\$[0-9]+"))} | C19: {=IFERROR(IF(OR('Raw Data'!C19="",LEN(TRIM('Raw Data'!C19))=0),"",IF(AND(LEN('Raw Data'!C19) <= 20,LEN('Raw Data'!C19)> 0),"",_xlfn.REGEXEXTRACT(CELL("address",'Raw Data'!C19),"\$([A-Z]+)\$[0-9]+"))),_xlfn.REGEXEXTRACT(CELL("address",'Raw Data'!C19),"\$([A-Z]+)\$[0-9]+"))} | D19: {=IFERROR(IF(OR('Raw Data'!D19="",LEN(TRIM('Raw Data'!D19))=0),"",IF(AND(ISNUMBER('Raw Data'!D19),'Raw Data'!D19>=Configuration!$D$2),"",_xlfn.REGEXEXTRACT(CELL("address",'Raw Data'!D19),"\$([A-Z]+)\$[0-9]+"))),_xlfn.REGEXEXTRACT(CELL("address",D19), "\$([A-Z]+)\$[0-9]+"))} | E19: {=IFERROR(IF(OR('Raw Data'!E19="",LEN(TRIM('Raw Data'!E19))=0),"",IF(AND(ISNUMBER('Raw Data'!E19), IFERROR('Raw Data'!E19 = ROUND('Raw Data'!E19, 2),FALSE)),"",_xlfn.REGEXEXTRACT(CELL("address",E19), "\$([A-Z]+)\$[0-9]+"))),_xlfn.REGEXEXTRACT(CELL("address",E19), "\$([A-Z]+)\$[0-9]+"))} | F19: {=IFERROR(IF(OR('Raw Data'!F19="",LEN(TRIM('Raw Data'!F19))=0),"",IF(AND(ISNUMBER('Raw Data'!F19), IFERROR('Raw Data'!F19 = ROUND('Raw Data'!F19, 2),FALSE)),"",_xlfn.REGEXEXTRACT(CELL("address",F19), "\$([A-Z]+)\$[0-9]+"))),_xlfn.REGEXEXTRACT(CELL("address",F19), "\$([A-Z]+)\$[0-9]+"))} | G19: {=IFERROR(IF(OR('Raw Data'!G19="",LEN(TRIM('Raw Data'!G19))=0),"",IF(AND(ISNUMBER('Raw Data'!G19), IFERROR('Raw Data'!G19 = ROUND('Raw Data'!G19, 2),FALSE)),"",_xlfn.REGEXEXTRACT(CELL("address",G19), "\$([A-Z]+)\$[0-9]+"))),_xlfn.REGEXEXTRACT(CELL("address",G19), "\$([A-Z]+)\$[0-9]+"))} | H19: {=IFERROR(IF(OR('Raw Data'!H19="",LEN(TRIM('Raw Data'!H19))=0),"",IF(AND(ISNUMBER('Raw Data'!H19), IFERROR('Raw Data'!H19 = ROUND('Raw Data'!H19, 2),FALSE)),"",_xlfn.REGEXEXTRACT(CELL("address",H19), "\$([A-Z]+)\$[0-9]+"))),_xlfn.REGEXEXTRACT(CELL("address",H19), "\$([A-Z]+)\$[0-9]+"))} | I19: {=IFERROR(IF(OR('Raw Data'!I19="",LEN(TRIM('Raw Data'!I19))=0),"",IF(AND(ISNUMBER('Raw Data'!I19), IFERROR('Raw Data'!I19 = ROUND('Raw Data'!I19, 2),FALSE)),"",_xlfn.REGEXEXTRACT(CELL("address",I19), "\$([A-Z]+)\$[0-9]+"))),_xlfn.REGEXEXTRACT(CELL("address",I19), "\$([A-Z]+)\$[0-9]+"))} | J19: {=IFERROR(IF(OR('Raw Data'!J19="",LEN(TRIM('Raw Data'!J19))=0),"",IF(AND(ISNUMBER('Raw Data'!J19), IFERROR('Raw Data'!J19 = ROUND('Raw Data'!J19, 2),FALSE)),"",_xlfn.REGEXEXTRACT(CELL("address",J19), "\$([A-Z]+)\$[0-9]+"))),_xlfn.REGEXEXTRACT(CELL("address",J19), "\$([A-Z]+)\$[0-9]+"))} | K19: {=IFERROR(IF(OR('Raw Data'!K19="",LEN(TRIM('Raw Data'!K19))=0),"",IF(AND(ISNUMBER('Raw Data'!K19), IFERROR('Raw Data'!K19 = ROUND('Raw Data'!K19, 2),FALSE)),"",_xlfn.REGEXEXTRACT(CELL("address",K19), "\$([A-Z]+)\$[0-9]+"))),_xlfn.REGEXEXTRACT(CELL("address",K19), "\$([A-Z]+)\$[0-9]+"))} | L19: {=IFERROR(IF(OR('Raw Data'!L19="",LEN(TRIM('Raw Data'!L19))=0),"",IF(AND(ISNUMBER('Raw Data'!L19), IFERROR('Raw Data'!L19 = ROUND('Raw Data'!L19, 2),FALSE)),"",_xlfn.REGEXEXTRACT(CELL("address",L19), "\$([A-Z]+)\$[0-9]+"))),_xlfn.REGEXEXTRACT(CELL("address",L19), "\$([A-Z]+)\$[0-9]+"))} | ... AJ19: {=IFERROR(IF(OR('Raw Data'!AJ19="",LEN(TRIM('Raw Data'!AJ19))=0),"",IF(AND(ISNUMBER('Raw Data'!AJ19), IFERROR('Raw Data'!AJ19 = ROUND('Raw Data'!AJ19, 2),FALSE)),"",_xlfn.REGEXEXTRACT(CELL("address",AJ19), "\$([A-Z]+)\$[0-9]+"))),_xlfn.REGEXEXTRACT(CELL("address",AJ19), "\$([A-Z]+)\$[0-9]+"))}
B20: {=IFERROR(IF(OR('Raw Data'!B20="",LEN(TRIM('Raw Data'!B20))=0),"",IF(AND(LEN('Raw Data'!B20) <= 255,LEN('Raw Data'!B20)> 0),"",_xlfn.REGEXEXTRACT(CELL("address",'Raw Data'!B20),"\$([A-Z]+)\$[0-9]+"))),_xlfn.REGEXEXTRACT(CELL("address",'Raw Data'!B20),"\$([A-Z]+)\$[0-9]+"))} | C20: {=IFERROR(IF(OR('Raw Data'!C20="",LEN(TRIM('Raw Data'!C20))=0),"",IF(AND(LEN('Raw Data'!C20) <= 20,LEN('Raw Data'!C20)> 0),"",_xlfn.REGEXEXTRACT(CELL("address",'Raw Data'!C20),"\$([A-Z]+)\$[0-9]+"))),_xlfn.REGEXEXTRACT(CELL("address",'Raw Data'!C20),"\$([A-Z]+)\$[0-9]+"))} | D20: {=IFERROR(IF(OR('Raw Data'!D20="",LEN(TRIM('Raw Data'!D20))=0),"",IF(AND(ISNUMBER('Raw Data'!D20),'Raw Data'!D20>=Configuration!$D$2),"",_xlfn.REGEXEXTRACT(CELL("address",'Raw Data'!D20),"\$([A-Z]+)\$[0-9]+"))),_xlfn.REGEXEXTRACT(CELL("address",D20), "\$([A-Z]+)\$[0-9]+"))} | E20: {=IFERROR(IF(OR('Raw Data'!E20="",LEN(TRIM('Raw Data'!E20))=0),"",IF(AND(ISNUMBER('Raw Data'!E20), IFERROR('Raw Data'!E20 = ROUND('Raw Data'!E20, 2),FALSE)),"",_xlfn.REGEXEXTRACT(CELL("address",E20), "\$([A-Z]+)\$[0-9]+"))),_xlfn.REGEXEXTRACT(CELL("address",E20), "\$([A-Z]+)\$[0-9]+"))} | F20: {=IFERROR(IF(OR('Raw Data'!F20="",LEN(TRIM('Raw Data'!F20))=0),"",IF(AND(ISNUMBER('Raw Data'!F20), IFERROR('Raw Data'!F20 = ROUND('Raw Data'!F20, 2),FALSE)),"",_xlfn.REGEXEXTRACT(CELL("address",F20), "\$([A-Z]+)\$[0-9]+"))),_xlfn.REGEXEXTRACT(CELL("address",F20), "\$([A-Z]+)\$[0-9]+"))} | G20: {=IFERROR(IF(OR('Raw Data'!G20="",LEN(TRIM('Raw Data'!G20))=0),"",IF(AND(ISNUMBER('Raw Data'!G20), IFERROR('Raw Data'!G20 = ROUND('Raw Data'!G20, 2),FALSE)),"",_xlfn.REGEXEXTRACT(CELL("address",G20), "\$([A-Z]+)\$[0-9]+"))),_xlfn.REGEXEXTRACT(CELL("address",G20), "\$([A-Z]+)\$[0-9]+"))} | H20: {=IFERROR(IF(OR('Raw Data'!H20="",LEN(TRIM('Raw Data'!H20))=0),"",IF(AND(ISNUMBER('Raw Data'!H20), IFERROR('Raw Data'!H20 = ROUND('Raw Data'!H20, 2),FALSE)),"",_xlfn.REGEXEXTRACT(CELL("address",H20), "\$([A-Z]+)\$[0-9]+"))),_xlfn.REGEXEXTRACT(CELL("address",H20), "\$([A-Z]+)\$[0-9]+"))} | I20: {=IFERROR(IF(OR('Raw Data'!I20="",LEN(TRIM('Raw Data'!I20))=0),"",IF(AND(ISNUMBER('Raw Data'!I20), IFERROR('Raw Data'!I20 = ROUND('Raw Data'!I20, 2),FALSE)),"",_xlfn.REGEXEXTRACT(CELL("address",I20), "\$([A-Z]+)\$[0-9]+"))),_xlfn.REGEXEXTRACT(CELL("address",I20), "\$([A-Z]+)\$[0-9]+"))} | J20: {=IFERROR(IF(OR('Raw Data'!J20="",LEN(TRIM('Raw Data'!J20))=0),"",IF(AND(ISNUMBER('Raw Data'!J20), IFERROR('Raw Data'!J20 = ROUND('Raw Data'!J20, 2),FALSE)),"",_xlfn.REGEXEXTRACT(CELL("address",J20), "\$([A-Z]+)\$[0-9]+"))),_xlfn.REGEXEXTRACT(CELL("address",J20), "\$([A-Z]+)\$[0-9]+"))} | K20: {=IFERROR(IF(OR('Raw Data'!K20="",LEN(TRIM('Raw Data'!K20))=0),"",IF(AND(ISNUMBER('Raw Data'!K20), IFERROR('Raw Data'!K20 = ROUND('Raw Data'!K20, 2),FALSE)),"",_xlfn.REGEXEXTRACT(CELL("address",K20), "\$([A-Z]+)\$[0-9]+"))),_xlfn.REGEXEXTRACT(CELL("address",K20), "\$([A-Z]+)\$[0-9]+"))} | L20: {=IFERROR(IF(OR('Raw Data'!L20="",LEN(TRIM('Raw Data'!L20))=0),"",IF(AND(ISNUMBER('Raw Data'!L20), IFERROR('Raw Data'!L20 = ROUND('Raw Data'!L20, 2),FALSE)),"",_xlfn.REGEXEXTRACT(CELL("address",L20), "\$([A-Z]+)\$[0-9]+"))),_xlfn.REGEXEXTRACT(CELL("address",L20), "\$([A-Z]+)\$[0-9]+"))} | ... AJ20: {=IFERROR(IF(OR('Raw Data'!AJ20="",LEN(TRIM('Raw Data'!AJ20))=0),"",IF(AND(ISNUMBER('Raw Data'!AJ20), IFERROR('Raw Data'!AJ20 = ROUND('Raw Data'!AJ20, 2),FALSE)),"",_xlfn.REGEXEXTRACT(CELL("address",AJ20), "\$([A-Z]+)\$[0-9]+"))),_xlfn.REGEXEXTRACT(CELL("address",AJ20), "\$([A-Z]+)\$[0-9]+"))}
