Workbook

Sheet Raw Data
F9: Sakura Project | G9: C1 | H9: =LEN(F9) -> 14
F10: Type I - Small Project | G10: C2
F11: QA001 | G11: C3
F12: XXXX | G12: C4
F13: Multi Project Code | G13: C5
F14: Rayong, Thailand | G14: C6
F15: 45536 | G15: C7
F16: 46034 | G16: C8
F17: Client 3 | G17: C9
F18: 45550 | G18: C10
F19: MGT-1234 | G19: C11
F20: 45530 | G20: C12
F21: 200 Onshore | G21: C13
F22: 200-1 Small EPC | G22: C14
F23: 200-1-4 Plant Maintenance & Modification | G23: C15
F24: Factory Plant | G24: C16
F25: Mr. Surachai Chobsaard | G25: C17
F26: Mr. Ramon P. Alcontin | G26: C18
F27: None | G27: C19
F28: Mr. Jatuporn Luengluesak | G28: C20
F29: Mr. Chaithut Boonprakong | G29: C21
F30: Mr. Chakris Onto | G30: C22
F31: Mr. Surasak Sereepong | G31: C23
F32: None | G32: C24
... F43: Retention Required | G43: C35
F44: 30 | G44: C36
F45: Standard Rates Rev. 13, 7 June 2024 | G45: C37
F46: Not consider | G46: C38
F47: 0.03 | G47: C39 | I47: {=IF(AND(ISNUMBER(H47),IFERROR(ROUND(H47,2)<=99999999999.99,FALSE))=TRUE,"",_xlfn.REGEXEXTRACT(CELL("address",H47), "\$([A-Z]+)\$[0-9]+"))} -> $H$47
F48: 0.02 | G48: C40 | I48: {=IF(AND(ISNUMBER(H48),IFERROR(ROUND(H48,2)<=99999999999.99,FALSE))=TRUE,"",_xlfn.REGEXEXTRACT(CELL("address",H48), "\$([A-Z]+)\$[0-9]+"))} -> $H$48
F49: 0.01 | G49: C41 | I49: {=IF(AND(ISNUMBER(H49),IFERROR(ROUND(H49,2)<=99999999999.99,FALSE))=TRUE,"",_xlfn.REGEXEXTRACT(CELL("address",H49), "\$([A-Z]+)\$[0-9]+"))} -> $H$49
F50: 0.0011 | G50: C42 | I50: {=IF(AND(ISNUMBER(H50),IFERROR(ROUND(H50,2)<=99999999999.99,FALSE))=TRUE,"",_xlfn.REGEXEXTRACT(CELL("address",H50), "\$([A-Z]+)\$[0-9]+"))} -> $H$50
F51: 0.001 | G51: C43 | I51: {=IF(AND(ISNUMBER(H51),IFERROR(ROUND(H51,2)<=99999999999.99,FALSE))=TRUE,"",_xlfn.REGEXEXTRACT(CELL("address",H51), "\$([A-Z]+)\$[0-9]+"))} -> $H$51
F52: None | G52: C44
F53: 35.7 | G53: C45
F54: Contract Effective Date: 15-Aug-2024 | G54: C46
F55: Mechanical Completion: Mid of May-2025 (ED + 9 Months) | G55: C47
F56: Commissioning Completion: Mid of MaSep-2025 (ED + 13 Months) | G56: C48
F57: Provisional Acceptance (Final Documentation): Mid of Nov-2025 (ED + 15 Months) | G57: C49
F58: Not Require | G58: C50
...

Sheet Validate_Empty
F9: {=IFERROR(IF(OR('Raw Data'!F9="",LEN(TRIM('Raw Data'!F9))=0),_xlfn.REGEXEXTRACT(CELL("address",'Raw Data'!F9),"\$([A-Z]+)\$[0-9]+"),""),"")} | G9: C1 | H9: Check Empty | I9: TRUE
F10: {=IFERROR(IF(OR('Raw Data'!F10="",LEN(TRIM('Raw Data'!F10))=0),_xlfn.REGEXEXTRACT(CELL("address",'Raw Data'!F10),"\$([A-Z]+)\$[0-9]+"),""),"")} | G10: C2 | H10: Check Empty | I10: TRUE
F11: {=IFERROR(IF(OR('Raw Data'!F11="",LEN(TRIM('Raw Data'!F11))=0),_xlfn.REGEXEXTRACT(CELL("address",'Raw Data'!F11),"\$([A-Z]+)\$[0-9]+"),""),"")} | G11: C3 | H11: Check Empty | I11: TRUE
F12: {=IFERROR(IF(OR('Raw Data'!F12="",LEN(TRIM('Raw Data'!F12))=0),_xlfn.REGEXEXTRACT(CELL("address",'Raw Data'!F12),"\$([A-Z]+)\$[0-9]+"),""),"")} | G12: C4 | H12: Check Empty | I12: TRUE
F13: {=IFERROR(IF(OR('Raw Data'!F13="",LEN(TRIM('Raw Data'!F13))=0),_xlfn.REGEXEXTRACT(CELL("address",'Raw Data'!F13),"\$([A-Z]+)\$[0-9]+"),""),"")} | G13: C5 | H13: Check Empty | I13: TRUE
F14: {=IFERROR(IF(OR('Raw Data'!F14="",LEN(TRIM('Raw Data'!F14))=0),_xlfn.REGEXEXTRACT(CELL("address",'Raw Data'!F14),"\$([A-Z]+)\$[0-9]+"),""),"")} | G14: C6 | H14: Check Empty | I14: TRUE
F15: {=IFERROR(IF(OR('Raw Data'!F15="",LEN(TRIM('Raw Data'!F15))=0),_xlfn.REGEXEXTRACT(CELL("address",'Raw Data'!F15),"\$([A-Z]+)\$[0-9]+"),""),"")} | G15: C7 | H15: Check Empty | I15: TRUE
F16: {=IFERROR(IF(OR('Raw Data'!F16="",LEN(TRIM('Raw Data'!F16))=0),_xlfn.REGEXEXTRACT(CELL("address",'Raw Data'!F16),"\$([A-Z]+)\$[0-9]+"),""),"")} | G16: C8 | H16: Check Empty | I16: TRUE
F17: {=IFERROR(IF(OR('Raw Data'!F17="",LEN(TRIM('Raw Data'!F17))=0),_xlfn.REGEXEXTRACT(CELL("address",'Raw Data'!F17),"\$([A-Z]+)\$[0-9]+"),""),"")} | G17: C9 | H17: Check Empty | I17: TRUE
F18: {=IFERROR(IF(OR('Raw Data'!F18="",LEN(TRIM('Raw Data'!F18))=0),_xlfn.REGEXEXTRACT(CELL("address",'Raw Data'!F18),"\$([A-Z]+)\$[0-9]+"),""),"")} | G18: C10 | H18: Check Empty | I18: TRUE
F19: {=IFERROR(IF(OR('Raw Data'!F19="",LEN(TRIM('Raw Data'!F19))=0),_xlfn.REGEXEXTRACT(CELL("address",'Raw Data'!F19),"\$([A-Z]+)\$[0-9]+"),""),"")} | G19: C11 | H19: Check Empty | I19: TRUE
F20: {=IFERROR(IF(OR('Raw Data'!F20="",LEN(TRIM('Raw Data'!F20))=0),_xlfn.REGEXEXTRACT(CELL("address",'Raw Data'!F20),"\$([A-Z]+)\$[0-9]+"),""),"")} | G20: C12 | H20: Check Empty | I20: TRUE
... F46: {=IFERROR(IF(OR('Raw Data'!F46="",LEN(TRIM('Raw Data'!F46))=0),_xlfn.REGEXEXTRACT(CELL("address",'Raw Data'!F46),"\$([A-Z]+)\$[0-9]+"),""),"")} | G46: C38 | H46: Check Empty | I46: TRUE
G47: C39 | H47: Check Empty | I47: FALSE
G48: C40 | H48: Check Empty | I48: FALSE
G49: C41 | H49: Check Empty | I49: FALSE
G50: C42 | H50: Check Empty | I50: FALSE
G51: C43 | H51: Check Empty | I51: FALSE
F52: {=IFERROR(IF(OR('Raw Data'!F52="",LEN(TRIM('Raw Data'!F52))=0),_xlfn.REGEXEXTRACT(CELL("address",'Raw Data'!F52),"\$([A-Z]+)\$[0-9]+"),""),"")} | G52: C44 | H52: Check Empty | I52: TRUE
F53: {=IFERROR(IF(OR('Raw Data'!F53="",LEN(TRIM('Raw Data'!F53))=0),_xlfn.REGEXEXTRACT(CELL("address",'Raw Data'!F53),"\$([A-Z]+)\$[0-9]+"),""),"")} | G53: C45 | H53: Check Empty | I53: TRUE
F54: {=IFERROR(IF(OR('Raw Data'!F54="",LEN(TRIM('Raw Data'!F54))=0),_xlfn.REGEXEXTRACT(CELL("address",'Raw Data'!F54),"\$([A-Z]+)\$[0-9]+"),""),"")} | G54: C46 | H54: Check Empty | I54: TRUE
F55: {=IFERROR(IF(OR('Raw Data'!F55="",LEN(TRIM('Raw Data'!F55))=0),_xlfn.REGEXEXTRACT(CELL("address",'Raw Data'!F55),"\$([A-Z]+)\$[0-9]+"),""),"")} | G55: C47 | H55: Check Empty | I55: TRUE
F56: {=IFERROR(IF(OR('Raw Data'!F56="",LEN(TRIM('Raw Data'!F56))=0),_xlfn.REGEXEXTRACT(CELL("address",'Raw Data'!F56),"\$([A-Z]+)\$[0-9]+"),""),"")} | G56: C48 | H56: Check Empty | I56: TRUE
F57: {=IFERROR(IF(OR('Raw Data'!F57="",LEN(TRIM('Raw Data'!F57))=0),_xlfn.REGEXEXTRACT(CELL("address",'Raw Data'!F57),"\$([A-Z]+)\$[0-9]+"),""),"")} | G57: C49 | H57: Check Empty | I57: TRUE
G58: C50 | H58: Check Empty | I58: FALSE
G59: C51 | H59: Check Empty | I59: FALSE
G60: C52 | H60: Check Empty | I60: FALSE
G61: C53 | H61: Check Empty | I61: FALSE
G62: C54 | H62: Check Empty | I62: FALSE
G63: C55 | H63: Check Empty | I63: FALSE
G64: C56 | H64: Check Empty | I64: FALSE
G65: C57 | H65: Check Empty | I65: FALSE
G66: C58 | H66: Check Empty | I66: FALSE

Sheet Validate_Value
B1: {=IF('Raw Data'!B1 = "","",IF(AND(LEN('Raw Data'!B1) < 255,LEN('Raw Data'!B1)> 0),"",_xlfn.REGEXEXTRACT(CELL("address",'Raw Data'!B1),"\$([A-Z]+)\$[0-9]+")))} | D1: {=IF('Raw Data'!C1 = "","",IF(AND(LEN('Raw Data'!C1) < 255,LEN('Raw Data'!C1)> 0),"",_xlfn.REGEXEXTRACT(CELL("address",'Raw Data'!C1),"\$([A-Z]+)\$[0-9]+")))} | E1: {=IF('Raw Data'!D1 = "","",IF(AND(LEN('Raw Data'!D1) < 255,LEN('Raw Data'!D1)> 0),"",_xlfn.REGEXEXTRACT(CELL("address",'Raw Data'!D1),"\$([A-Z]+)\$[0-9]+")))}
B2: {=IF('Raw Data'!B2 = "","",IF(AND(LEN('Raw Data'!B2) < 255,LEN('Raw Data'!B2)> 0),"",_xlfn.REGEXEXTRACT(CELL("address",'Raw Data'!B2),"\$([A-Z]+)\$[0-9]+")))} | D2: {=IF('Raw Data'!C2 = "","",IF(AND(LEN('Raw Data'!C2) < 255,LEN('Raw Data'!C2)> 0),"",_xlfn.REGEXEXTRACT(CELL("address",'Raw Data'!C2),"\$([A-Z]+)\$[0-9]+")))} | E2: {=IF('Raw Data'!D2 = "","",IF(AND(LEN('Raw Data'!D2) < 255,LEN('Raw Data'!D2)> 0),"",_xlfn.REGEXEXTRACT(CELL("address",'Raw Data'!D2),"\$([A-Z]+)\$[0-9]+")))}
B3: {=IF('Raw Data'!B3 = "","",IF(AND(LEN('Raw Data'!B3) < 255,LEN('Raw Data'!B3)> 0),"",_xlfn.REGEXEXTRACT(CELL("address",'Raw Data'!B3),"\$([A-Z]+)\$[0-9]+")))} | D3: {=IF('Raw Data'!C3 = "","",IF(AND(LEN('Raw Data'!C3) < 255,LEN('Raw Data'!C3)> 0),"",_xlfn.REGEXEXTRACT(CELL("address",'Raw Data'!C3),"\$([A-Z]+)\$[0-9]+")))} | E3: {=IF('Raw Data'!D3 = "","",IF(AND(LEN('Raw Data'!D3) < 255,LEN('Raw Data'!D3)> 0),"",_xlfn.REGEXEXTRACT(CELL("address",'Raw Data'!D3),"\$([A-Z]+)\$[0-9]+")))}
B4: {=IF('Raw Data'!B4 = "","",IF(AND(LEN('Raw Data'!B4) < 255,LEN('Raw Data'!B4)> 0),"",_xlfn.REGEXEXTRACT(CELL("address",'Raw Data'!B4),"\$([A-Z]+)\$[0-9]+")))} | D4: {=IF('Raw Data'!C4 = "","",IF(AND(LEN('Raw Data'!C4) < 255,LEN('Raw Data'!C4)> 0),"",_xlfn.REGEXEXTRACT(CELL("address",'Raw Data'!C4),"\$([A-Z]+)\$[0-9]+")))} | E4: {=IF('Raw Data'!D4 = "","",IF(AND(LEN('Raw Data'!D4) < 255,LEN('Raw Data'!D4)> 0),"",_xlfn.REGEXEXTRACT(CELL("address",'Raw Data'!D4),"\$([A-Z]+)\$[0-9]+")))}
B5: {=IF('Raw Data'!B5 = "","",IF(AND(LEN('Raw Data'!B5) < 255,LEN('Raw Data'!B5)> 0),"",_xlfn.REGEXEXTRACT(CELL("address",'Raw Data'!B5),"\$([A-Z]+)\$[0-9]+")))} | D5: {=IF('Raw Data'!C5 = "","",IF(AND(LEN('Raw Data'!C5) < 255,LEN('Raw Data'!C5)> 0),"",_xlfn.REGEXEXTRACT(CELL("address",'Raw Data'!C5),"\$([A-Z]+)\$[0-9]+")))} | E5: {=IF('Raw Data'!D5 = "","",IF(AND(LEN('Raw Data'!D5) < 255,LEN('Raw Data'!D5)> 0),"",_xlfn.REGEXEXTRACT(CELL("address",'Raw Data'!D5),"\$([A-Z]+)\$[0-9]+")))}
B6: {=IF('Raw Data'!B6 = "","",IF(AND(LEN('Raw Data'!B6) < 255,LEN('Raw Data'!B6)> 0),"",_xlfn.REGEXEXTRACT(CELL("address",'Raw Data'!B6),"\$([A-Z]+)\$[0-9]+")))} | D6: {=IF('Raw Data'!C6 = "","",IF(AND(LEN('Raw Data'!C6) < 255,LEN('Raw Data'!C6)> 0),"",_xlfn.REGEXEXTRACT(CELL("address",'Raw Data'!C6),"\$([A-Z]+)\$[0-9]+")))} | E6: {=IF('Raw Data'!D6 = "","",IF(AND(LEN('Raw Data'!D6) < 255,LEN('Raw Data'!D6)> 0),"",_xlfn.REGEXEXTRACT(CELL("address",'Raw Data'!D6),"\$([A-Z]+)\$[0-9]+")))}
B7: {=IF('Raw Data'!B7 = "","",IF(AND(LEN('Raw Data'!B7) < 255,LEN('Raw Data'!B7)> 0),"",_xlfn.REGEXEXTRACT(CELL("address",'Raw Data'!B7),"\$([A-Z]+)\$[0-9]+")))} | D7: {=IF('Raw Data'!C7 = "","",IF(AND(LEN('Raw Data'!C7) < 255,LEN('Raw Data'!C7)> 0),"",_xlfn.REGEXEXTRACT(CELL("address",'Raw Data'!C7),"\$([A-Z]+)\$[0-9]+")))} | E7: {=IF('Raw Data'!D7 = "","",IF(AND(LEN('Raw Data'!D7) < 255,LEN('Raw Data'!D7)> 0),"",_xlfn.REGEXEXTRACT(CELL("address",'Raw Data'!D7),"\$([A-Z]+)\$[0-9]+")))}
B8: {=IF('Raw Data'!B8 = "","",IF(AND(LEN('Raw Data'!B8) < 255,LEN('Raw Data'!B8)> 0),"",_xlfn.REGEXEXTRACT(CELL("address",'Raw Data'!B8),"\$([A-Z]+)\$[0-9]+")))} | D8: {=IF('Raw Data'!C8 = "","",IF(AND(LEN('Raw Data'!C8) < 255,LEN('Raw Data'!C8)> 0),"",_xlfn.REGEXEXTRACT(CELL("address",'Raw Data'!C8),"\$([A-Z]+)\$[0-9]+")))} | E8: {=IF('Raw Data'!D8 = "","",IF(AND(LEN('Raw Data'!D8) < 255,LEN('Raw Data'!D8)> 0),"",_xlfn.REGEXEXTRACT(CELL("address",'Raw Data'!D8),"\$([A-Z]+)\$[0-9]+")))}
B9: {=IF('Raw Data'!B9 = "","",IF(AND(LEN('Raw Data'!B9) < 255,LEN('Raw Data'!B9)> 0),"",_xlfn.REGEXEXTRACT(CELL("address",'Raw Data'!B9),"\$([A-Z]+)\$[0-9]+")))} | D9: {=IF('Raw Data'!C9 = "","",IF(AND(LEN('Raw Data'!C9) < 255,LEN('Raw Data'!C9)> 0),"",_xlfn.REGEXEXTRACT(CELL("address",'Raw Data'!C9),"\$([A-Z]+)\$[0-9]+")))} | E9: {=IF('Raw Data'!D9 = "","",IF(AND(LEN('Raw Data'!D9) < 255,LEN('Raw Data'!D9)> 0),"",_xlfn.REGEXEXTRACT(CELL("address",'Raw Data'!D9),"\$([A-Z]+)\$[0-9]+")))} | F9: {=IFERROR(IF(OR('Raw Data'!F9="",LEN(TRIM('Raw Data'!F9))=0),"",IF(AND(LEN('Raw Data'!F9) <= 255,LEN('Raw Data'!F9)> 0),"",_xlfn.REGEXEXTRACT(CELL("address",'Raw Data'!F9),"\$([A-Z]+)\$[0-9]+"))),_xlfn.REGEXEXTRACT(CELL("address",'Raw Data'!F9),"\$([A-Z]+)\$[0-9]+"))} | G9: C1 | H9: NVARCHAR(255)
B10: {=IF('Raw Data'!B10 = "","",IF(AND(LEN('Raw Data'!B10) < 255,LEN('Raw Data'!B10)> 0),"",_xlfn.REGEXEXTRACT(CELL("address",'Raw Data'!B10),"\$([A-Z]+)\$[0-9]+")))} | D10: {=IF('Raw Data'!C10 = "","",IF(AND(LEN('Raw Data'!C10) < 255,LEN('Raw Data'!C10)> 0),"",_xlfn.REGEXEXTRACT(CELL("address",'Raw Data'!C10),"\$([A-Z]+)\$[0-9]+")))} | E10: {=IF('Raw Data'!D10 = "","",IF(AND(LEN('Raw Data'!D10) < 255,LEN('Raw Data'!D10)> 0),"",_xlfn.REGEXEXTRACT(CELL("address",'Raw Data'!D10),"\$([A-Z]+)\$[0-9]+")))} | F10: {=IFERROR(IF(OR('Raw Data'!F10="",LEN(TRIM('Raw Data'!F10))=0),"",IF(AND(LEN('Raw Data'!F10) <= 255,LEN('Raw Data'!F10)> 0),"",_xlfn.REGEXEXTRACT(CELL("address",'Raw Data'!F10),"\$([A-Z]+)\$[0-9]+"))),_xlfn.REGEXEXTRACT(CELL("address",'Raw Data'!F10),"\$([A-Z]+)\$[0-9]+"))} | G10: C2 | H10: NVARCHAR(255)
B11: {=IF('Raw Data'!B11 = "","",IF(AND(LEN('Raw Data'!B11) < 255,LEN('Raw Data'!B11)> 0),"",_xlfn.REGEXEXTRACT(CELL("address",'Raw Data'!B11),"\$([A-Z]+)\$[0-9]+")))} | D11: {=IF('Raw Data'!C11 = "","",IF(AND(LEN('Raw Data'!C11) < 255,LEN('Raw Data'!C11)> 0),"",_xlfn.REGEXEXTRACT(CELL("address",'Raw Data'!C11),"\$([A-Z]+)\$[0-9]+")))} | E11: {=IF('Raw Data'!D11 = "","",IF(AND(LEN('Raw Data'!D11) < 255,LEN('Raw Data'!D11)> 0),"",_xlfn.REGEXEXTRACT(CELL("address",'Raw Data'!D11),"\$([A-Z]+)\$[0-9]+")))} | F11: {=IFERROR(IF(OR('Raw Data'!F11="",LEN(TRIM('Raw Data'!F11))=0),"",IF(AND(LEN('Raw Data'!F11) <= 255,LEN('Raw Data'!F11)> 0),"",_xlfn.REGEXEXTRACT(CELL("address",'Raw Data'!F11),"\$([A-Z]+)\$[0-9]+"))),_xlfn.REGEXEXTRACT(CELL("address",'Raw Data'!F11),"\$([A-Z]+)\$[0-9]+"))} | G11: C3 | H11: NVARCHAR(255)
B12: {=IF('Raw Data'!B12 = "","",IF(AND(LEN('Raw Data'!B12) < 255,LEN('Raw Data'!B12)> 0),"",_xlfn.REGEXEXTRACT(CELL("address",'Raw Data'!B12),"\$([A-Z]+)\$[0-9]+")))} | D12: {=IF('Raw Data'!C12 = "","",IF(AND(LEN('Raw Data'!C12) < 255,LEN('Raw Data'!C12)> 0),"",_xlfn.REGEXEXTRACT(CELL("address",'Raw Data'!C12),"\$([A-Z]+)\$[0-9]+")))} | E12: {=IF('Raw Data'!D12 = "","",IF(AND(LEN('Raw Data'!D12) < 255,LEN('Raw Data'!D12)> 0),"",_xlfn.REGEXEXTRACT(CELL("address",'Raw Data'!D12),"\$([A-Z]+)\$[0-9]+")))} | F12: {=IFERROR(IF(OR('Raw Data'!F12="",LEN(TRIM('Raw Data'!F12))=0),"",IF(AND(LEN('Raw Data'!F12) <= 255,LEN('Raw Data'!F12)> 0),"",_xlfn.REGEXEXTRACT(CELL("address",'Raw Data'!F12),"\$([A-Z]+)\$[0-9]+"))),_xlfn.REGEXEXTRACT(CELL("address",'Raw Data'!F12),"\$([A-Z]+)\$[0-9]+"))} | G12: C4 | H12: NVARCHAR(255)
B13: {=IF('Raw Data'!B13 = "","",IF(AND(LEN('Raw Data'!B13) < 255,LEN('Raw Data'!B13)> 0),"",_xlfn.REGEXEXTRACT(CELL("address",'Raw Data'!B13),"\$([A-Z]+)\$[0-9]+")))} | D13: {=IF('Raw Data'!C13 = "","",IF(AND(LEN('Raw Data'!C13) < 255,LEN('Raw Data'!C13)> 0),"",_xlfn.REGEXEXTRACT(CELL("address",'Raw Data'!C13),"\$([A-Z]+)\$[0-9]+")))} | E13: {=IF('Raw Data'!D13 = "","",IF(AND(LEN('Raw Data'!D13) < 255,LEN('Raw Data'!D13)> 0),"",_xlfn.REGEXEXTRACT(CELL("address",'Raw Data'!D13),"\$([A-Z]+)\$[0-9]+")))} | F13: {=IFERROR(IF(OR('Raw Data'!F13="",LEN(TRIM('Raw Data'!F13))=0),"",IF(AND(LEN('Raw Data'!F13) <= 255,LEN('Raw Data'!F13)> 0),"",_xlfn.REGEXEXTRACT(CELL("address",'Raw Data'!F13),"\$([A-Z]+)\$[0-9]+"))),_xlfn.REGEXEXTRACT(CELL("address",'Raw Data'!F13),"\$([A-Z]+)\$[0-9]+"))} | G13: C5 | H13: NVARCHAR(255)
B14: {=IF('Raw Data'!B14 = "","",IF(AND(LEN('Raw Data'!B14) < 255,LEN('Raw Data'!B14)> 0),"",_xlfn.REGEXEXTRACT(CELL("address",'Raw Data'!B14),"\$([A-Z]+)\$[0-9]+")))} | D14: {=IF('Raw Data'!C14 = "","",IF(AND(LEN('Raw Data'!C14) < 255,LEN('Raw Data'!C14)> 0),"",_xlfn.REGEXEXTRACT(CELL("address",'Raw Data'!C14),"\$([A-Z]+)\$[0-9]+")))} | E14: {=IF('Raw Data'!D14 = "","",IF(AND(LEN('Raw Data'!D14) < 255,LEN('Raw Data'!D14)> 0),"",_xlfn.REGEXEXTRACT(CELL("address",'Raw Data'!D14),"\$([A-Z]+)\$[0-9]+")))} | F14: {=IFERROR(IF(OR('Raw Data'!F14="",LEN(TRIM('Raw Data'!F14))=0),"",IF(AND(LEN('Raw Data'!F14) <= 255,LEN('Raw Data'!F14)> 0),"",_xlfn.REGEXEXTRACT(CELL("address",'Raw Data'!F14),"\$([A-Z]+)\$[0-9]+"))),_xlfn.REGEXEXTRACT(CELL("address",'Raw Data'!F14),"\$([A-Z]+)\$[0-9]+"))} | G14: C6 | H14: NVARCHAR(255)
B15: {=IF('Raw Data'!B15 = "","",IF(AND(LEN('Raw Data'!B15) < 255,LEN('Raw Data'!B15)> 0),"",_xlfn.REGEXEXTRACT(CELL("address",'Raw Data'!B15),"\$([A-Z]+)\$[0-9]+")))} | D15: {=IF('Raw Data'!C15 = "","",IF(AND(LEN('Raw Data'!C15) < 255,LEN('Raw Data'!C15)> 0),"",_xlfn.REGEXEXTRACT(CELL("address",'Raw Data'!C15),"\$([A-Z]+)\$[0-9]+")))} | E15: {=IF('Raw Data'!D15 = "","",IF(AND(LEN('Raw Data'!D15) < 255,LEN('Raw Data'!D15)> 0),"",_xlfn.REGEXEXTRACT(CELL("address",'Raw Data'!D15),"\$([A-Z]+)\$[0-9]+")))} | F15: {=IFERROR(IF(OR('Raw Data'!F15="",LEN(TRIM('Raw Data'!F15))=0),"",IF(AND(ISNUMBER('Raw Data'!F15),'Raw Data'!F15>=Configuration!$D$2),"",_xlfn.REGEXEXTRACT(CELL("address",'Raw Data'!F10),"\$([A-Z]+)\$[0-9]+"))),_xlfn.REGEXEXTRACT(CELL("address",'Raw Data'!F10),"\$([A-Z]+)\$[0-9]+"))} | G15: C7 | H15: DATE
B16: {=IF('Raw Data'!B16 = "","",IF(AND(LEN('Raw Data'!B16) < 255,LEN('Raw Data'!B16)> 0),"",_xlfn.REGEXEXTRACT(CELL("address",'Raw Data'!B16),"\$([A-Z]+)\$[0-9]+")))} | D16: {=IF('Raw Data'!C16 = "","",IF(AND(LEN('Raw Data'!C16) < 255,LEN('Raw Data'!C16)> 0),"",_xlfn.REGEXEXTRACT(CELL("address",'Raw Data'!C16),"\$([A-Z]+)\$[0-9]+")))} | E16: {=IF('Raw Data'!D16 = "","",IF(AND(LEN('Raw Data'!D16) < 255,LEN('Raw Data'!D16)> 0),"",_xlfn.REGEXEXTRACT(CELL("address",'Raw Data'!D16),"\$([A-Z]+)\$[0-9]+")))} | F16: {=IFERROR(IF(OR('Raw Data'!F16="",LEN(TRIM('Raw Data'!F16))=0),"",IF(AND(ISNUMBER('Raw Data'!F16),'Raw Data'!F16>=Configuration!$D$2),"",_xlfn.REGEXEXTRACT(CELL("address",'Raw Data'!F11),"\$([A-Z]+)\$[0-9]+"))),_xlfn.REGEXEXTRACT(CELL("address",'Raw Data'!F11),"\$([A-Z]+)\$[0-9]+"))} | G16: C8 | H16: DATE
B17: {=IF('Raw Data'!B17 = "","",IF(AND(LEN('Raw Data'!B17) < 255,LEN('Raw Data'!B17)> 0),"",_xlfn.REGEXEXTRACT(CELL("address",'Raw Data'!B17),"\$([A-Z]+)\$[0-9]+")))} | D17: {=IF('Raw Data'!C17 = "","",IF(AND(LEN('Raw Data'!C17) < 255,LEN('Raw Data'!C17)> 0),"",_xlfn.REGEXEXTRACT(CELL("address",'Raw Data'!C17),"\$([A-Z]+)\$[0-9]+")))} | E17: {=IF('Raw Data'!D17 = "","",IF(AND(LEN('Raw Data'!D17) < 255,LEN('Raw Data'!D17)> 0),"",_xlfn.REGEXEXTRACT(CELL("address",'Raw Data'!D17),"\$([A-Z]+)\$[0-9]+")))} | F17: {=IFERROR(IF(OR('Raw Data'!F17="",LEN(TRIM('Raw Data'!F17))=0),"",IF(AND(LEN('Raw Data'!F17) <= 255,LEN('Raw Data'!F17)> 0),"",_xlfn.REGEXEXTRACT(CELL("address",'Raw Data'!F17),"\$([A-Z]+)\$[0-9]+"))),_xlfn.REGEXEXTRACT(CELL("address",'Raw Data'!F17),"\$([A-Z]+)\$[0-9]+"))} | G17: C9 | H17: NVARCHAR(255)
B18: {=IF('Raw Data'!B18 = "","",IF(AND(LEN('Raw Data'!B18) < 255,LEN('Raw Data'!B18)> 0),"",_xlfn.REGEXEXTRACT(CELL("address",'Raw Data'!B18),"\$([A-Z]+)\$[0-9]+")))} | D18: {=IF('Raw Data'!C18 = "","",IF(AND(LEN('Raw Data'!C18) < 255,LEN('Raw Data'!C18)> 0),"",_xlfn.REGEXEXTRACT(CELL("address",'Raw Data'!C18),"\$([A-Z]+)\$[0-9]+")))} | E18: {=IF('Raw Data'!D18 = "","",IF(AND(LEN('Raw Data'!D18) < 255,LEN('Raw Data'!D18)> 0),"",_xlfn.REGEXEXTRACT(CELL("address",'Raw Data'!D18),"\$([A-Z]+)\$[0-9]+")))} | F18: {=IFERROR(IF(OR('Raw Data'!F18="",LEN(TRIM('Raw Data'!F18))=0),"",IF(AND(ISNUMBER('Raw Data'!F18),'Raw Data'!F18>=Configuration!$D$2),"",_xlfn.REGEXEXTRACT(CELL("address",'Raw Data'!F13),"\$([A-Z]+)\$[0-9]+"))),_xlfn.REGEXEXTRACT(CELL("address",'Raw Data'!F13),"\$([A-Z]+)\$[0-9]+"))} | G18: C10 | H18: DATE
B19: {=IF('Raw Data'!B19 = "","",IF(AND(LEN('Raw Data'!B19) < 255,LEN('Raw Data'!B19)> 0),"",_xlfn.REGEXEXTRACT(CELL("address",'Raw Data'!B19),"\$([A-Z]+)\$[0-9]+")))} | D19: {=IF('Raw Data'!C19 = "","",IF(AND(LEN('Raw Data'!C19) < 255,LEN('Raw Data'!C19)> 0),"",_xlfn.REGEXEXTRACT(CELL("address",'Raw Data'!C19),"\$([A-Z]+)\$[0-9]+")))} | E19: {=IF('Raw Data'!D19 = "","",IF(AND(LEN('Raw Data'!D19) < 255,LEN('Raw Data'!D19)> 0),"",_xlfn.REGEXEXTRACT(CELL("address",'Raw Data'!D19),"\$([A-Z]+)\$[0-9]+")))} | F19: {=IFERROR(IF(OR('Raw Data'!F19="",LEN(TRIM('Raw Data'!F19))=0),"",IF(AND(LEN('Raw Data'!F19) <= 255,LEN('Raw Data'!F19)> 0),"",_xlfn.REGEXEXTRACT(CELL("address",'Raw Data'!F19),"\$([A-Z]+)\$[0-9]+"))),_xlfn.REGEXEXTRACT(CELL("address",'Raw Data'!F19),"\$([A-Z]+)\$[0-9]+"))} | G19: C11 | H19: NVARCHAR(255)
B20: {=IF('Raw Data'!B20 = "","",IF(AND(LEN('Raw Data'!B20) < 255,LEN('Raw Data'!B20)> 0),"",_xlfn.REGEXEXTRACT(CELL("address",'Raw Data'!B20),"\$([A-Z]+)\$[0-9]+")))} | D20: {=IF('Raw Data'!C20 = "","",IF(AND(LEN('Raw Data'!C20) < 255,LEN('Raw Data'!C20)> 0),"",_xlfn.REGEXEXTRACT(CELL("address",'Raw Data'!C20),"\$([A-Z]+)\$[0-9]+")))} | E20: {=IF('Raw Data'!D20 = "","",IF(AND(LEN('Raw Data'!D20) < 255,LEN('Raw Data'!D20)> 0),"",_xlfn.REGEXEXTRACT(CELL("address",'Raw Data'!D20),"\$([A-Z]+)\$[0-9]+")))} | F20: {=IFERROR(IF(OR('Raw Data'!F20="",LEN(TRIM('Raw Data'!F20))=0),"",IF(AND(ISNUMBER('Raw Data'!F20),'Raw Data'!F20>=Configuration!$D$2),"",_xlfn.REGEXEXTRACT(CELL("address",'Raw Data'!F15),"\$([A-Z]+)\$[0-9]+"))),_xlfn.REGEXEXTRACT(CELL("address",'Raw Data'!F15),"\$([A-Z]+)\$[0-9]+"))} | G20: C12 | H20: DATE
B21: {=IF('Raw Data'!B21 = "","",IF(AND(LEN('Raw Data'!B21) < 255,LEN('Raw Data'!B21)> 0),"",_xlfn.REGEXEXTRACT(CELL("address",'Raw Data'!B21),"\$([A-Z]+)\$[0-9]+")))} | D21: {=IF('Raw Data'!C21 = "","",IF(AND(LEN('Raw Data'!C21) < 255,LEN('Raw Data'!C21)> 0),"",_xlfn.REGEXEXTRACT(CELL("address",'Raw Data'!C21),"\$([A-Z]+)\$[0-9]+")))} | E21: {=IF('Raw Data'!D21 = "","",IF(AND(LEN('Raw Data'!D21) < 255,LEN('Raw Data'!D21)> 0),"",_xlfn.REGEXEXTRACT(CELL("address",'Raw Data'!D21),"\$([A-Z]+)\$[0-9]+")))} | F21: {=IFERROR(IF(OR('Raw Data'!F21="",LEN(TRIM('Raw Data'!F21))=0),"",IF(AND(LEN('Raw Data'!F21) <= 255,LEN('Raw Data'!F21)> 0),"",_xlfn.REGEXEXTRACT(CELL("address",'Raw Data'!F21),"\$([A-Z]+)\$[0-9]+"))),_xlfn.REGEXEXTRACT(CELL("address",'Raw Data'!F21),"\$([A-Z]+)\$[0-9]+"))} | G21: C13 | H21: NVARCHAR(255)
B22: {=IF('Raw Data'!B22 = "","",IF(AND(LEN('Raw Data'!B22) < 255,LEN('Raw Data'!B22)> 0),"",_xlfn.REGEXEXTRACT(CELL("address",'Raw Data'!B22),"\$([A-Z]+)\$[0-9]+")))} | D22: {=IF('Raw Data'!C22 = "","",IF(AND(LEN('Raw Data'!C22) < 255,LEN('Raw Data'!C22)> 0),"",_xlfn.REGEXEXTRACT(CELL("address",'Raw Data'!C22),"\$([A-Z]+)\$[0-9]+")))} | E22: {=IF('Raw Data'!D22 = "","",IF(AND(LEN('Raw Data'!D22) < 255,LEN('Raw Data'!D22)> 0),"",_xlfn.REGEXEXTRACT(CELL("address",'Raw Data'!D22),"\$([A-Z]+)\$[0-9]+")))} | F22: {=IFERROR(IF(OR('Raw Data'!F22="",LEN(TRIM('Raw Data'!F22))=0),"",IF(AND(LEN('Raw Data'!F22) <= 255,LEN('Raw Data'!F22)> 0),"",_xlfn.REGEXEXTRACT(CELL("address",'Raw Data'!F22),"\$([A-Z]+)\$[0-9]+"))),_xlfn.REGEXEXTRACT(CELL("address",'Raw Data'!F22),"\$([A-Z]+)\$[0-9]+"))} | G22: C14 | H22: NVARCHAR(255)
B23: {=IF('Raw Data'!B23 = "","",IF(AND(LEN('Raw Data'!B23) < 255,LEN('Raw Data'!B23)> 0),"",_xlfn.REGEXEXTRACT(CELL("address",'Raw Data'!B23),"\$([A-Z]+)\$[0-9]+")))} | D23: {=IF('Raw Data'!C23 = "","",IF(AND(LEN('Raw Data'!C23) < 255,LEN('Raw Data'!C23)> 0),"",_xlfn.REGEXEXTRACT(CELL("address",'Raw Data'!C23),"\$([A-Z]+)\$[0-9]+")))} | E23: {=IF('Raw Data'!D23 = "","",IF(AND(LEN('Raw Data'!D23) < 255,LEN('Raw Data'!D23)> 0),"",_xlfn.REGEXEXTRACT(CELL("address",'Raw Data'!D23),"\$([A-Z]+)\$[0-9]+")))} | F23: {=IFERROR(IF(OR('Raw Data'!F23="",LEN(TRIM('Raw Data'!F23))=0),"",IF(AND(LEN('Raw Data'!F23) <= 255,LEN('Raw Data'!F23)> 0),"",_xlfn.REGEXEXTRACT(CELL("address",'Raw Data'!F23),"\$([A-Z]+)\$[0-9]+"))),_xlfn.REGEXEXTRACT(CELL("address",'Raw Data'!F23),"\$([A-Z]+)\$[0-9]+"))} | G23: C15 | H23: NVARCHAR(255)
B24: {=IF('Raw Data'!B24 = "","",IF(AND(LEN('Raw Data'!B24) < 255,LEN('Raw Data'!B24)> 0),"",_xlfn.REGEXEXTRACT(CELL("address",'Raw Data'!B24),"\$([A-Z]+)\$[0-9]+")))} | D24: {=IF('Raw Data'!C24 = "","",IF(AND(LEN('Raw Data'!C24) < 255,LEN('Raw Data'!C24)> 0),"",_xlfn.REGEXEXTRACT(CELL("address",'Raw Data'!C24),"\$([A-Z]+)\$[0-9]+")))} | E24: {=IF('Raw Data'!D24 = "","",IF(AND(LEN('Raw Data'!D24) < 255,LEN('Raw Data'!D24)> 0),"",_xlfn.REGEXEXTRACT(CELL("address",'Raw Data'!D24),"\$([A-Z]+)\$[0-9]+")))} | F24: {=IFERROR(IF(OR('Raw Data'!F24="",LEN(TRIM('Raw Data'!F24))=0),"",IF(AND(LEN('Raw Data'!F24) <= 255,LEN('Raw Data'!F24)> 0),"",_xlfn.REGEXEXTRACT(CELL("address",'Raw Data'!F24),"\$([A-Z]+)\$[0-9]+"))),_xlfn.REGEXEXTRACT(CELL("address",'Raw Data'!F24),"\$([A-Z]+)\$[0-9]+"))} | G24: C16 | H24: NVARCHAR(255)
B25: {=IF('Raw Data'!B25 = "","",IF(AND(LEN('Raw Data'!B25) < 255,LEN('Raw Data'!B25)> 0),"",_xlfn.REGEXEXTRACT(CELL("address",'Raw Data'!B25),"\$([A-Z]+)\$[0-9]+")))} | D25: {=IF('Raw Data'!C25 = "","",IF(AND(LEN('Raw Data'!C25) < 255,LEN('Raw Data'!C25)> 0),"",_xlfn.REGEXEXTRACT(CELL("address",'Raw Data'!C25),"\$([A-Z]+)\$[0-9]+")))} | E25: {=IF('Raw Data'!D25 = "","",IF(AND(LEN('Raw Data'!D25) < 255,LEN('Raw Data'!D25)> 0),"",_xlfn.REGEXEXTRACT(CELL("address",'Raw Data'!D25),"\$([A-Z]+)\$[0-9]+")))} | F25: {=IFERROR(IF(OR('Raw Data'!F25="",LEN(TRIM('Raw Data'!F25))=0),"",IF(AND(LEN('Raw Data'!F25) <= 255,LEN('Raw Data'!F25)> 0),"",_xlfn.REGEXEXTRACT(CELL("address",'Raw Data'!F25),"\$([A-Z]+)\$[0-9]+"))),_xlfn.REGEXEXTRACT(CELL("address",'Raw Data'!F25),"\$([A-Z]+)\$[0-9]+"))} | G25: C17 | H25: NVARCHAR(255)
B26: {=IF('Raw Data'!B26 = "","",IF(AND(LEN('Raw Data'!B26) < 255,LEN('Raw Data'!B26)> 0),"",_xlfn.REGEXEXTRACT(CELL("address",'Raw Data'!B26),"\$([A-Z]+)\$[0-9]+")))} | D26: {=IF('Raw Data'!C26 = "","",IF(AND(LEN('Raw Data'!C26) < 255,LEN('Raw Data'!C26)> 0),"",_xlfn.REGEXEXTRACT(CELL("address",'Raw Data'!C26),"\$([A-Z]+)\$[0-9]+")))} | E26: {=IF('Raw Data'!D26 = "","",IF(AND(LEN('Raw Data'!D26) < 255,LEN('Raw Data'!D26)> 0),"",_xlfn.REGEXEXTRACT(CELL("address",'Raw Data'!D26),"\$([A-Z]+)\$[0-9]+")))} | F26: {=IFERROR(IF(OR('Raw Data'!F26="",LEN(TRIM('Raw Data'!F26))=0),"",IF(AND(LEN('Raw Data'!F26) <= 255,LEN('Raw Data'!F26)> 0),"",_xlfn.REGEXEXTRACT(CELL("address",'Raw Data'!F26),"\$([A-Z]+)\$[0-9]+"))),_xlfn.REGEXEXTRACT(CELL("address",'Raw Data'!F26),"\$([A-Z]+)\$[0-9]+"))} | G26: C18 | H26: NVARCHAR(255)
B27: {=IF('Raw Data'!B27 = "","",IF(AND(LEN('Raw Data'!B27) < 255,LEN('Raw Data'!B27)> 0),"",_xlfn.REGEXEXTRACT(CELL("address",'Raw Data'!B27),"\$([A-Z]+)\$[0-9]+")))} | D27: {=IF('Raw Data'!C27 = "","",IF(AND(LEN('Raw Data'!C27) < 255,LEN('Raw Data'!C27)> 0),"",_xlfn.REGEXEXTRACT(CELL("address",'Raw Data'!C27),"\$([A-Z]+)\$[0-9]+")))} | E27: {=IF('Raw Data'!D27 = "","",IF(AND(LEN('Raw Data'!D27) < 255,LEN('Raw Data'!D27)> 0),"",_xlfn.REGEXEXTRACT(CELL("address",'Raw Data'!D27),"\$([A-Z]+)\$[0-9]+")))} | F27: {=IFERROR(IF(OR('Raw Data'!F27="",LEN(TRIM('Raw Data'!F27))=0),"",IF(AND(LEN('Raw Data'!F27) <= 255,LEN('Raw Data'!F27)> 0),"",_xlfn.REGEXEXTRACT(CELL("address",'Raw Data'!F27),"\$([A-Z]+)\$[0-9]+"))),_xlfn.REGEXEXTRACT(CELL("address",'Raw Data'!F27),"\$([A-Z]+)\$[0-9]+"))} | G27: C19 | H27: NVARCHAR(255)
B28: {=IF('Raw Data'!B28 = "","",IF(AND(LEN('Raw Data'!B28) < 255,LEN('Raw Data'!B28)> 0),"",_xlfn.REGEXEXTRACT(CELL("address",'Raw Data'!B28),"\$([A-Z]+)\$[0-9]+")))} | D28: {=IF('Raw Data'!C28 = "","",IF(AND(LEN('Raw Data'!C28) < 255,LEN('Raw Data'!C28)> 0),"",_xlfn.REGEXEXTRACT(CELL("address",'Raw Data'!C28),"\$([A-Z]+)\$[0-9]+")))} | E28: {=IF('Raw Data'!D28 = "","",IF(AND(LEN('Raw Data'!D28) < 255,LEN('Raw Data'!D28)> 0),"",_xlfn.REGEXEXTRACT(CELL("address",'Raw Data'!D28),"\$([A-Z]+)\$[0-9]+")))} | F28: {=IFERROR(IF(OR('Raw Data'!F28="",LEN(TRIM('Raw Data'!F28))=0),"",IF(AND(LEN('Raw Data'!F28) <= 255,LEN('Raw Data'!F28)> 0),"",_xlfn.REGEXEXTRACT(CELL("address",'Raw Data'!F28),"\$([A-Z]+)\$[0-9]+"))),_xlfn.REGEXEXTRACT(CELL("address",'Raw Data'!F28),"\$([A-Z]+)\$[0-9]+"))} | G28: C20 | H28: NVARCHAR(255)
B29: {=IF('Raw Data'!B29 = "","",IF(AND(LEN('Raw Data'!B29) < 255,LEN('Raw Data'!B29)> 0),"",_xlfn.REGEXEXTRACT(CELL("address",'Raw Data'!B29),"\$([A-Z]+)\$[0-9]+")))} | D29: {=IF('Raw Data'!C29 = "","",IF(AND(LEN('Raw Data'!C29) < 255,LEN('Raw Data'!C29)> 0),"",_xlfn.REGEXEXTRACT(CELL("address",'Raw Data'!C29),"\$([A-Z]+)\$[0-9]+")))} | E29: {=IF('Raw Data'!D29 = "","",IF(AND(LEN('Raw Data'!D29) < 255,LEN('Raw Data'!D29)> 0),"",_xlfn.REGEXEXTRACT(CELL("address",'Raw Data'!D29),"\$([A-Z]+)\$[0-9]+")))} | F29: {=IFERROR(IF(OR('Raw Data'!F29="",LEN(TRIM('Raw Data'!F29))=0),"",IF(AND(LEN('Raw Data'!F29) <= 255,LEN('Raw Data'!F29)> 0),"",_xlfn.REGEXEXTRACT(CELL("address",'Raw Data'!F29),"\$([A-Z]+)\$[0-9]+"))),_xlfn.REGEXEXTRACT(CELL("address",'Raw Data'!F29),"\$([A-Z]+)\$[0-9]+"))} | G29: C21 | H29: NVARCHAR(255)
B30: {=IF('Raw Data'!B30 = "","",IF(AND(LEN('Raw Data'!B30) < 255,LEN('Raw Data'!B30)> 0),"",_xlfn.REGEXEXTRACT(CELL("address",'Raw Data'!B30),"\$([A-Z]+)\$[0-9]+")))} | D30: {=IF('Raw Data'!C30 = "","",IF(AND(LEN('Raw Data'!C30) < 255,LEN('Raw Data'!C30)> 0),"",_xlfn.REGEXEXTRACT(CELL("address",'Raw Data'!C30),"\$([A-Z]+)\$[0-9]+")))} | E30: {=IF('Raw Data'!D30 = "","",IF(AND(LEN('Raw Data'!D30) < 255,LEN('Raw Data'!D30)> 0),"",_xlfn.REGEXEXTRACT(CELL("address",'Raw Data'!D30),"\$([A-Z]+)\$[0-9]+")))} | F30: {=IFERROR(IF(OR('Raw Data'!F30="",LEN(TRIM('Raw Data'!F30))=0),"",IF(AND(LEN('Raw Data'!F30) <= 255,LEN('Raw Data'!F30)> 0),"",_xlfn.REGEXEXTRACT(CELL("address",'Raw Data'!F30),"\$([A-Z]+)\$[0-9]+"))),_xlfn.REGEXEXTRACT(CELL("address",'Raw Data'!F30),"\$([A-Z]+)\$[0-9]+"))} | G30: C22 | H30: NVARCHAR(255)
B31: {=IF('Raw Data'!B31 = "","",IF(AND(LEN('Raw Data'!B31) < 255,LEN('Raw Data'!B31)> 0),"",_xlfn.REGEXEXTRACT(CELL("address",'Raw Data'!B31),"\$([A-Z]+)\$[0-9]+")))} | D31: {=IF('Raw Data'!C31 = "","",IF(AND(LEN('Raw Data'!C31) < 255,LEN('Raw Data'!C31)> 0),"",_xlfn.REGEXEXTRACT(CELL("address",'Raw Data'!C31),"\$([A-Z]+)\$[0-9]+")))} | E31: {=IF('Raw Data'!D31 = "","",IF(AND(LEN('Raw Data'!D31) < 255,LEN('Raw Data'!D31)> 0),"",_xlfn.REGEXEXTRACT(CELL("address",'Raw Data'!D31),"\$([A-Z]+)\$[0-9]+")))} | F31: {=IFERROR(IF(OR('Raw Data'!F31="",LEN(TRIM('Raw Data'!F31))=0),"",IF(AND(LEN('Raw Data'!F31) <= 255,LEN('Raw Data'!F31)> 0),"",_xlfn.REGEXEXTRACT(CELL("address",'Raw Data'!F31),"\$([A-Z]+)\$[0-9]+"))),_xlfn.REGEXEXTRACT(CELL("address",'Raw Data'!F31),"\$([A-Z]+)\$[0-9]+"))} | G31: C23 | H31: NVARCHAR(255)
B32: {=IF('Raw Data'!B32 = "","",IF(AND(LEN('Raw Data'!B32) < 255,LEN('Raw Data'!B32)> 0),"",_xlfn.REGEXEXTRACT(CELL("address",'Raw Data'!B32),"\$([A-Z]+)\$[0-9]+")))} | D32: {=IF('Raw Data'!C32 = "","",IF(AND(LEN('Raw Data'!C32) < 255,LEN('Raw Data'!C32)> 0),"",_xlfn.REGEXEXTRACT(CELL("address",'Raw Data'!C32),"\$([A-Z]+)\$[0-9]+")))} | E32: {=IF('Raw Data'!D32 = "","",IF(AND(LEN('Raw Data'!D32) < 255,LEN('Raw Data'!D32)> 0),"",_xlfn.REGEXEXTRACT(CELL("address",'Raw Data'!D32),"\$([A-Z]+)\$[0-9]+")))} | F32: {=IFERROR(IF(OR('Raw Data'!F32="",LEN(TRIM('Raw Data'!F32))=0),"",IF(AND(LEN('Raw Data'!F32) <= 255,LEN('Raw Data'!F32)> 0),"",_xlfn.REGEXEXTRACT(CELL("address",'Raw Data'!F32),"\$([A-Z]+)\$[0-9]+"))),_xlfn.REGEXEXTRACT(CELL("address",'Raw Data'!F32),"\$([A-Z]+)\$[0-9]+"))} | G32: C24 | H32: NVARCHAR(255)
... B43: {=IF('Raw Data'!B43 = "","",IF(AND(LEN('Raw Data'!B43) < 255,LEN('Raw Data'!B43)> 0),"",_xlfn.REGEXEXTRACT(CELL("address",'Raw Data'!B43),"\$([A-Z]+)\$[0-9]+")))} | D43: {=IF('Raw Data'!C43 = "","",IF(AND(LEN('Raw Data'!C43) < 255,LEN('Raw Data'!C43)> 0),"",_xlfn.REGEXEXTRACT(CELL("address",'Raw Data'!C43),"\$([A-Z]+)\$[0-9]+")))} | E43: {=IF('Raw Data'!D43 = "","",IF(AND(LEN('Raw Data'!D43) < 255,LEN('Raw Data'!D43)> 0),"",_xlfn.REGEXEXTRACT(CELL("address",'Raw Data'!D43),"\$([A-Z]+)\$[0-9]+")))} | F43: {=IFERROR(IF(OR('Raw Data'!F43="",LEN(TRIM('Raw Data'!F43))=0),"",IF(AND(LEN('Raw Data'!F43) <= 255,LEN('Raw Data'!F43)> 0),"",_xlfn.REGEXEXTRACT(CELL("address",'Raw Data'!F43),"\$([A-Z]+)\$[0-9]+"))),_xlfn.REGEXEXTRACT(CELL("address",'Raw Data'!F43),"\$([A-Z]+)\$[0-9]+"))} | G43: C35 | H43: NVARCHAR(255)
B44: {=IF('Raw Data'!B44 = "","",IF(AND(LEN('Raw Data'!B44) < 255,LEN('Raw Data'!B44)> 0),"",_xlfn.REGEXEXTRACT(CELL("address",'Raw Data'!B44),"\$([A-Z]+)\$[0-9]+")))} | D44: {=IF('Raw Data'!C44 = "","",IF(AND(LEN('Raw Data'!C44) < 255,LEN('Raw Data'!C44)> 0),"",_xlfn.REGEXEXTRACT(CELL("address",'Raw Data'!C44),"\$([A-Z]+)\$[0-9]+")))} | E44: {=IF('Raw Data'!D44 = "","",IF(AND(LEN('Raw Data'!D44) < 255,LEN('Raw Data'!D44)> 0),"",_xlfn.REGEXEXTRACT(CELL("address",'Raw Data'!D44),"\$([A-Z]+)\$[0-9]+")))} | F44: {=IFERROR(IF(OR('Raw Data'!F44="",LEN(TRIM('Raw Data'!F44))=0),"",IF(ISNUMBER('Raw Data'!F44),"",_xlfn.REGEXEXTRACT(CELL("address",B10), "\$([A-Z]+)\$[0-9]+"))),_xlfn.REGEXEXTRACT(CELL("address",B10), "\$([A-Z]+)\$[0-9]+"))} | G44: C36 | H44: INT
B45: {=IF('Raw Data'!B45 = "","",IF(AND(LEN('Raw Data'!B45) < 255,LEN('Raw Data'!B45)> 0),"",_xlfn.REGEXEXTRACT(CELL("address",'Raw Data'!B45),"\$([A-Z]+)\$[0-9]+")))} | D45: {=IF('Raw Data'!C45 = "","",IF(AND(LEN('Raw Data'!C45) < 255,LEN('Raw Data'!C45)> 0),"",_xlfn.REGEXEXTRACT(CELL("address",'Raw Data'!C45),"\$([A-Z]+)\$[0-9]+")))} | E45: {=IF('Raw Data'!D45 = "","",IF(AND(LEN('Raw Data'!D45) < 255,LEN('Raw Data'!D45)> 0),"",_xlfn.REGEXEXTRACT(CELL("address",'Raw Data'!D45),"\$([A-Z]+)\$[0-9]+")))} | F45: {=IFERROR(IF(OR('Raw Data'!F45="",LEN(TRIM('Raw Data'!F45))=0),"",IF(AND(LEN('Raw Data'!F45) <= 255,LEN('Raw Data'!F45)> 0),"",_xlfn.REGEXEXTRACT(CELL("address",'Raw Data'!F45),"\$([A-Z]+)\$[0-9]+"))),_xlfn.REGEXEXTRACT(CELL("address",'Raw Data'!F45),"\$([A-Z]+)\$[0-9]+"))} | G45: C37 | H45: NVARCHAR(255)
B46: {=IF('Raw Data'!B46 = "","",IF(AND(LEN('Raw Data'!B46) < 255,LEN('Raw Data'!B46)> 0),"",_xlfn.REGEXEXTRACT(CELL("address",'Raw Data'!B46),"\$([A-Z]+)\$[0-9]+")))} | D46: {=IF('Raw Data'!C46 = "","",IF(AND(LEN('Raw Data'!C46) < 255,LEN('Raw Data'!C46)> 0),"",_xlfn.REGEXEXTRACT(CELL("address",'Raw Data'!C46),"\$([A-Z]+)\$[0-9]+")))} | E46: {=IF('Raw Data'!D46 = "","",IF(AND(LEN('Raw Data'!D46) < 255,LEN('Raw Data'!D46)> 0),"",_xlfn.REGEXEXTRACT(CELL("address",'Raw Data'!D46),"\$([A-Z]+)\$[0-9]+")))} | F46: {=IFERROR(IF(OR('Raw Data'!F46="",LEN(TRIM('Raw Data'!F46))=0),"",IF(AND(LEN('Raw Data'!F46) <= 255,LEN('Raw Data'!F46)> 0),"",_xlfn.REGEXEXTRACT(CELL("address",'Raw Data'!F46),"\$([A-Z]+)\$[0-9]+"))),_xlfn.REGEXEXTRACT(CELL("address",'Raw Data'!F46),"\$([A-Z]+)\$[0-9]+"))} | G46: C38 | H46: NVARCHAR(255)
B47: {=IF('Raw Data'!B47 = "","",IF(AND(LEN('Raw Data'!B47) < 255,LEN('Raw Data'!B47)> 0),"",_xlfn.REGEXEXTRACT(CELL("address",'Raw Data'!B47),"\$([A-Z]+)\$[0-9]+")))} | D47: {=IF('Raw Data'!C47 = "","",IF(AND(LEN('Raw Data'!C47) < 255,LEN('Raw Data'!C47)> 0),"",_xlfn.REGEXEXTRACT(CELL("address",'Raw Data'!C47),"\$([A-Z]+)\$[0-9]+")))} | E47: {=IF('Raw Data'!D47 = "","",IF(AND(LEN('Raw Data'!D47) < 255,LEN('Raw Data'!D47)> 0),"",_xlfn.REGEXEXTRACT(CELL("address",'Raw Data'!D47),"\$([A-Z]+)\$[0-9]+")))} | F47: {=IFERROR(IF(OR('Raw Data'!F47="",LEN(TRIM('Raw Data'!F47))=0),"",IF(AND(ISNUMBER('Raw Data'!F47), IFERROR('Raw Data'!F47 = ROUND('Raw Data'!F47, 4),FALSE)),"",_xlfn.REGEXEXTRACT(CELL("address",F47), "\$([A-Z]+)\$[0-9]+"))),_xlfn.REGEXEXTRACT(CELL("address",E10), "\$([A-Z]+)\$[0-9]+"))} | G47: C39 | H47: DECIMAL(13,4) [Percentage]
B48: {=IF('Raw Data'!B48 = "","",IF(AND(LEN('Raw Data'!B48) < 255,LEN('Raw Data'!B48)> 0),"",_xlfn.REGEXEXTRACT(CELL("address",'Raw Data'!B48),"\$([A-Z]+)\$[0-9]+")))} | D48: {=IF('Raw Data'!C48 = "","",IF(AND(LEN('Raw Data'!C48) < 255,LEN('Raw Data'!C48)> 0),"",_xlfn.REGEXEXTRACT(CELL("address",'Raw Data'!C48),"\$([A-Z]+)\$[0-9]+")))} | E48: {=IF('Raw Data'!D48 = "","",IF(AND(LEN('Raw Data'!D48) < 255,LEN('Raw Data'!D48)> 0),"",_xlfn.REGEXEXTRACT(CELL("address",'Raw Data'!D48),"\$([A-Z]+)\$[0-9]+")))} | F48: {=IFERROR(IF(OR('Raw Data'!F48="",LEN(TRIM('Raw Data'!F48))=0),"",IF(AND(ISNUMBER('Raw Data'!F48), IFERROR('Raw Data'!F48 = ROUND('Raw Data'!F48, 4),FALSE)),"",_xlfn.REGEXEXTRACT(CELL("address",F48), "\$([A-Z]+)\$[0-9]+"))),_xlfn.REGEXEXTRACT(CELL("address",E11), "\$([A-Z]+)\$[0-9]+"))} | G48: C40 | H48: DECIMAL(13,4) [Percentage]
B49: {=IF('Raw Data'!B49 = "","",IF(AND(LEN('Raw Data'!B49) < 255,LEN('Raw Data'!B49)> 0),"",_xlfn.REGEXEXTRACT(CELL("address",'Raw Data'!B49),"\$([A-Z]+)\$[0-9]+")))} | D49: {=IF('Raw Data'!C49 = "","",IF(AND(LEN('Raw Data'!C49) < 255,LEN('Raw Data'!C49)> 0),"",_xlfn.REGEXEXTRACT(CELL("address",'Raw Data'!C49),"\$([A-Z]+)\$[0-9]+")))} | E49: {=IF('Raw Data'!D49 = "","",IF(AND(LEN('Raw Data'!D49) < 255,LEN('Raw Data'!D49)> 0),"",_xlfn.REGEXEXTRACT(CELL("address",'Raw Data'!D49),"\$([A-Z]+)\$[0-9]+")))} | F49: {=IFERROR(IF(OR('Raw Data'!F49="",LEN(TRIM('Raw Data'!F49))=0),"",IF(AND(ISNUMBER('Raw Data'!F49), IFERROR('Raw Data'!F49 = ROUND('Raw Data'!F49, 4),FALSE)),"",_xlfn.REGEXEXTRACT(CELL("address",F49), "\$([A-Z]+)\$[0-9]+"))),_xlfn.REGEXEXTRACT(CELL("address",E12), "\$([A-Z]+)\$[0-9]+"))} | G49: C41 | H49: DECIMAL(13,4) [Percentage]
B50: {=IF('Raw Data'!B50 = "","",IF(AND(LEN('Raw Data'!B50) < 255,LEN('Raw Data'!B50)> 0),"",_xlfn.REGEXEXTRACT(CELL("address",'Raw Data'!B50),"\$([A-Z]+)\$[0-9]+")))} | D50: {=IF('Raw Data'!C50 = "","",IF(AND(LEN('Raw Data'!C50) < 255,LEN('Raw Data'!C50)> 0),"",_xlfn.REGEXEXTRACT(CELL("address",'Raw Data'!C50),"\$([A-Z]+)\$[0-9]+")))} | E50: {=IF('Raw Data'!D50 = "","",IF(AND(LEN('Raw Data'!D50) < 255,LEN('Raw Data'!D50)> 0),"",_xlfn.REGEXEXTRACT(CELL("address",'Raw Data'!D50),"\$([A-Z]+)\$[0-9]+")))} | F50: {=IFERROR(IF(OR('Raw Data'!F50="",LEN(TRIM('Raw Data'!F50))=0),"",IF(AND(ISNUMBER('Raw Data'!F50), IFERROR('Raw Data'!F50 = ROUND('Raw Data'!F50, 4),FALSE)),"",_xlfn.REGEXEXTRACT(CELL("address",F50), "\$([A-Z]+)\$[0-9]+"))),_xlfn.REGEXEXTRACT(CELL("address",E13), "\$([A-Z]+)\$[0-9]+"))} | G50: C42 | H50: DECIMAL(13,4) [Percentage]
...

Sheet Validate_Condition
G9: C1 | H9: No
G10: C2 | H10: No
G11: C3 | H11: No
G12: C4 | H12: No
G13: C5 | H13: No
G14: C6 | H14: No
G15: C7 | H15: No
G16: C8 | H16: No
G17: C9 | H17: No
G18: C10 | H18: No
G19: C11 | H19: No
G20: C12 | H20: No
... G36: C28 | H36: No
F37: {=IFERROR(IF(OR('Raw Data'!F37="",LEN(TRIM('Raw Data'!F37))=0),_xlfn.REGEXEXTRACT(CELL("address",'Raw Data'!F37),"\$([A-Z]+)\$[0-9]+"),""),"")} | G37: C29 | H37: Just make sure it is clearly specified. If there is no Project Code, enter ‘None’.
F38: {=IFERROR(IF(OR('Raw Data'!F38="",LEN(TRIM('Raw Data'!F38))=0),_xlfn.REGEXEXTRACT(CELL("address",'Raw Data'!F38),"\$([A-Z]+)\$[0-9]+"),""),"")} | G38: C30 | H38: Just make sure it is clearly specified. If there is no Project Code, enter ‘None’.
F39: {=IFERROR(IF(OR('Raw Data'!F39="",LEN(TRIM('Raw Data'!F39))=0),_xlfn.REGEXEXTRACT(CELL("address",'Raw Data'!F39),"\$([A-Z]+)\$[0-9]+"),""),"")} | G39: C31 | H39: Just make sure it is clearly specified. If there is no Project Code, enter ‘None’.
F40: {=IFERROR(IF(OR('Raw Data'!F40="",LEN(TRIM('Raw Data'!F40))=0),_xlfn.REGEXEXTRACT(CELL("address",'Raw Data'!F40),"\$([A-Z]+)\$[0-9]+"),""),"")} | G40: C32 | H40: Just make sure it is clearly specified. If there is no Project Code, enter ‘None’.
F41: {=IFERROR(IF(OR('Raw Data'!F41="",LEN(TRIM('Raw Data'!F41))=0),_xlfn.REGEXEXTRACT(CELL("address",'Raw Data'!F41),"\$([A-Z]+)\$[0-9]+"),""),"")} | G41: C33 | H41: Just make sure it is clearly specified. If there is no Project Code, enter ‘None’.
G42: C34 | H42: No
G43: C35 | H43: No
G44: C36 | H44: No
G45: C37 | H45: No
G46: C38 | H46: No
G47: C39 | H47: No
G48: C40 | H48: No
G49: C41 | H49: No
G50: C42 | H50: No
G51: C43 | H51: No
G52: C44 | H52: No
G53: C45 | H53: No
... G66: C58 | H66: No

Sheet Condition
G9: C1 | H9: No
G10: C2 | H10: No
G11: C3 | H11: No
G12: C4 | H12: No
G13: C5 | H13: No
G14: C6 | H14: No
G15: C7 | H15: No
G16: C8 | H16: No
G17: C9 | H17: No
G18: C10 | H18: No
G19: C11 | H19: No
G20: C12 | H20: No
... G36: C28 | H36: No
F37: None | G37: C29 | H37: Yes
F38: None | G38: C30 | H38: Yes
F39: None | G39: C31 | H39: Yes
F40: None | G40: C32 | H40: Yes
F41: None | G41: C33 | H41: Yes
G42: C34 | H42: No
G43: C35 | H43: No
G44: C36 | H44: No
G45: C37 | H45: No
G46: C38 | H46: No
G47: C39 | H47: No
G48: C40 | H48: No
G49: C41 | H49: No
G50: C42 | H50: No
G51: C43 | H51: No
G52: C44 | H52: No
G53: C45 | H53: No
... G66: C58 | H66: No

Sheet Configuration
A1: col_number | B1: range_start | C1: range_stop | D1: project_active_Start | E1: project_inactive_end | F1: relate_document
A2: 6 | B2: F9 | C2: F66 | D2: 45292 | E2: 46388

Sheet Validate_Type
B1: C1 | C1: C2 | D1: C3 | E1: C4 | F1: C5 | G1: C6 | H1: C7 | I1: C8
B2: {=IF('Raw Data'!B1="",_xlfn.REGEXEXTRACT(CELL("address",'Raw Data'!B1),"\$([A-Z]+)\$[0-9]+"),"")} -> $B$1 | C2: {=IF('Raw Data'!C1="",_xlfn.REGEXEXTRACT(CELL("address",'Raw Data'!C1),"\$([A-Z]+)\$[0-9]+"),"")} -> $C$1 | D2: {=IF('Raw Data'!D1="",_xlfn.REGEXEXTRACT(CELL("address",'Raw Data'!D1),"\$([A-Z]+)\$[0-9]+"),"")} -> $D$1 | E2: {=IF('Raw Data'!E1="",_xlfn.REGEXEXTRACT(CELL("address",'Raw Data'!E1),"\$([A-Z]+)\$[0-9]+"),"")} -> $E$1 | F2: {=IF('Raw Data'!F1="",_xlfn.REGEXEXTRACT(CELL("address",'Raw Data'!F1),"\$([A-Z]+)\$[0-9]+"),"")} -> $F$1 | G2: {=IF('Raw Data'!G1="",_xlfn.REGEXEXTRACT(CELL("address",'Raw Data'!G1),"\$([A-Z]+)\$[0-9]+"),"")} -> $G$1 | H2: {=IF('Raw Data'!H1="",_xlfn.REGEXEXTRACT(CELL("address",'Raw Data'!H1),"\$([A-Z]+)\$[0-9]+"),"")} -> $H$1 | I2: {=IF('Raw Data'!I1="",_xlfn.REGEXEXTRACT(CELL("address",'Raw Data'!I1),"\$([A-Z]+)\$[0-9]+"),"")} -> $I$1
B3: {=IF('Raw Data'!B2="",_xlfn.REGEXEXTRACT(CELL("address",'Raw Data'!B2),"\$([A-Z]+)\$[0-9]+"),"")} -> $B$2 | C3: {=IF('Raw Data'!C2="",_xlfn.REGEXEXTRACT(CELL("address",'Raw Data'!C2),"\$([A-Z]+)\$[0-9]+"),"")} -> $C$2 | D3: {=IF('Raw Data'!D2="",_xlfn.REGEXEXTRACT(CELL("address",'Raw Data'!D2),"\$([A-Z]+)\$[0-9]+"),"")} -> $D$2 | E3: {=IF('Raw Data'!E2="",_xlfn.REGEXEXTRACT(CELL("address",'Raw Data'!E2),"\$([A-Z]+)\$[0-9]+"),"")} -> $E$2 | F3: {=IF('Raw Data'!F2="",_xlfn.REGEXEXTRACT(CELL("address",'Raw Data'!F2),"\$([A-Z]+)\$[0-9]+"),"")} -> $F$2 | G3: {=IF('Raw Data'!G2="",_xlfn.REGEXEXTRACT(CELL("address",'Raw Data'!G2),"\$([A-Z]+)\$[0-9]+"),"")} -> $G$2 | H3: {=IF('Raw Data'!H2="",_xlfn.REGEXEXTRACT(CELL("address",'Raw Data'!H2),"\$([A-Z]+)\$[0-9]+"),"")} -> $H$2 | I3: {=IF('Raw Data'!I2="",_xlfn.REGEXEXTRACT(CELL("address",'Raw Data'!I2),"\$([A-Z]+)\$[0-9]+"),"")} -> $I$2
B4: {=IF('Raw Data'!B3="",_xlfn.REGEXEXTRACT(CELL("address",'Raw Data'!B3),"\$([A-Z]+)\$[0-9]+"),"")} -> $B$3 | C4: {=IF('Raw Data'!C3="",_xlfn.REGEXEXTRACT(CELL("address",'Raw Data'!C3),"\$([A-Z]+)\$[0-9]+"),"")} -> $C$3 | D4: {=IF('Raw Data'!D3="",_xlfn.REGEXEXTRACT(CELL("address",'Raw Data'!D3),"\$([A-Z]+)\$[0-9]+"),"")} -> $D$3 | E4: {=IF('Raw Data'!E3="",_xlfn.REGEXEXTRACT(CELL("address",'Raw Data'!E3),"\$([A-Z]+)\$[0-9]+"),"")} -> $E$3 | F4: {=IF('Raw Data'!F3="",_xlfn.REGEXEXTRACT(CELL("address",'Raw Data'!F3),"\$([A-Z]+)\$[0-9]+"),"")} -> $F$3 | G4: {=IF('Raw Data'!G3="",_xlfn.REGEXEXTRACT(CELL("address",'Raw Data'!G3),"\$([A-Z]+)\$[0-9]+"),"")} -> $G$3 | H4: {=IF('Raw Data'!H3="",_xlfn.REGEXEXTRACT(CELL("address",'Raw Data'!H3),"\$([A-Z]+)\$[0-9]+"),"")} -> $H$3 | I4: {=IF('Raw Data'!I3="",_xlfn.REGEXEXTRACT(CELL("address",'Raw Data'!I3),"\$([A-Z]+)\$[0-9]+"),"")} -> $I$3
B5: {=IF('Raw Data'!B4="",_xlfn.REGEXEXTRACT(CELL("address",'Raw Data'!B4),"\$([A-Z]+)\$[0-9]+"),"")} -> $B$4 | C5: {=IF('Raw Data'!C4="",_xlfn.REGEXEXTRACT(CELL("address",'Raw Data'!C4),"\$([A-Z]+)\$[0-9]+"),"")} -> $C$4 | D5: {=IF('Raw Data'!D4="",_xlfn.REGEXEXTRACT(CELL("address",'Raw Data'!D4),"\$([A-Z]+)\$[0-9]+"),"")} -> $D$4 | E5: {=IF('Raw Data'!E4="",_xlfn.REGEXEXTRACT(CELL("address",'Raw Data'!E4),"\$([A-Z]+)\$[0-9]+"),"")} -> $E$4 | F5: {=IF('Raw Data'!F4="",_xlfn.REGEXEXTRACT(CELL("address",'Raw Data'!F4),"\$([A-Z]+)\$[0-9]+"),"")} -> $F$4 | G5: {=IF('Raw Data'!G4="",_xlfn.REGEXEXTRACT(CELL("address",'Raw Data'!G4),"\$([A-Z]+)\$[0-9]+"),"")} -> $G$4 | H5: {=IF('Raw Data'!H4="",_xlfn.REGEXEXTRACT(CELL("address",'Raw Data'!H4),"\$([A-Z]+)\$[0-9]+"),"")} -> $H$4 | I5: {=IF('Raw Data'!I4="",_xlfn.REGEXEXTRACT(CELL("address",'Raw Data'!I4),"\$([A-Z]+)\$[0-9]+"),"")} -> $I$4
B6: {=IF('Raw Data'!B5="",_xlfn.REGEXEXTRACT(CELL("address",'Raw Data'!B5),"\$([A-Z]+)\$[0-9]+"),"")} -> $B$5 | C6: {=IF('Raw Data'!C5="",_xlfn.REGEXEXTRACT(CELL("address",'Raw Data'!C5),"\$([A-Z]+)\$[0-9]+"),"")} -> $C$5 | D6: {=IF('Raw Data'!D5="",_xlfn.REGEXEXTRACT(CELL("address",'Raw Data'!D5),"\$([A-Z]+)\$[0-9]+"),"")} -> $D$5 | E6: {=IF('Raw Data'!E5="",_xlfn.REGEXEXTRACT(CELL("address",'Raw Data'!E5),"\$([A-Z]+)\$[0-9]+"),"")} -> $E$5 | F6: {=IF('Raw Data'!F5="",_xlfn.REGEXEXTRACT(CELL("address",'Raw Data'!F5),"\$([A-Z]+)\$[0-9]+"),"")} -> $F$5 | G6: {=IF('Raw Data'!G5="",_xlfn.REGEXEXTRACT(CELL("address",'Raw Data'!G5),"\$([A-Z]+)\$[0-9]+"),"")} -> $G$5 | H6: {=IF('Raw Data'!H5="",_xlfn.REGEXEXTRACT(CELL("address",'Raw Data'!H5),"\$([A-Z]+)\$[0-9]+"),"")} -> $H$5 | I6: {=IF('Raw Data'!I5="",_xlfn.REGEXEXTRACT(CELL("address",'Raw Data'!I5),"\$([A-Z]+)\$[0-9]+"),"")} -> $I$5
B7: {=IF('Raw Data'!B6="",_xlfn.REGEXEXTRACT(CELL("address",'Raw Data'!B6),"\$([A-Z]+)\$[0-9]+"),"")} -> $B$6 | C7: {=IF('Raw Data'!C6="",_xlfn.REGEXEXTRACT(CELL("address",'Raw Data'!C6),"\$([A-Z]+)\$[0-9]+"),"")} -> $C$6 | D7: {=IF('Raw Data'!D6="",_xlfn.REGEXEXTRACT(CELL("address",'Raw Data'!D6),"\$([A-Z]+)\$[0-9]+"),"")} -> $D$6 | E7: {=IF('Raw Data'!E6="",_xlfn.REGEXEXTRACT(CELL("address",'Raw Data'!E6),"\$([A-Z]+)\$[0-9]+"),"")} -> $E$6 | F7: {=IF('Raw Data'!F6="",_xlfn.REGEXEXTRACT(CELL("address",'Raw Data'!F6),"\$([A-Z]+)\$[0-9]+"),"")} -> $F$6 | G7: {=IF('Raw Data'!G6="",_xlfn.REGEXEXTRACT(CELL("address",'Raw Data'!G6),"\$([A-Z]+)\$[0-9]+"),"")} -> $G$6 | H7: {=IF('Raw Data'!H6="",_xlfn.REGEXEXTRACT(CELL("address",'Raw Data'!H6),"\$([A-Z]+)\$[0-9]+"),"")} -> $H$6 | I7: {=IF('Raw Data'!I6="",_xlfn.REGEXEXTRACT(CELL("address",'Raw Data'!I6),"\$([A-Z]+)\$[0-9]+"),"")} -> $I$6
B8: {=IF('Raw Data'!B7="",_xlfn.REGEXEXTRACT(CELL("address",'Raw Data'!B7),"\$([A-Z]+)\$[0-9]+"),"")} -> $B$7 | C8: {=IF('Raw Data'!C7="",_xlfn.REGEXEXTRACT(CELL("address",'Raw Data'!C7),"\$([A-Z]+)\$[0-9]+"),"")} -> $C$7 | D8: {=IF('Raw Data'!D7="",_xlfn.REGEXEXTRACT(CELL("address",'Raw Data'!D7),"\$([A-Z]+)\$[0-9]+"),"")} -> $D$7 | E8: {=IF('Raw Data'!E7="",_xlfn.REGEXEXTRACT(CELL("address",'Raw Data'!E7),"\$([A-Z]+)\$[0-9]+"),"")} -> $E$7 | F8: {=IF('Raw Data'!F7="",_xlfn.REGEXEXTRACT(CELL("address",'Raw Data'!F7),"\$([A-Z]+)\$[0-9]+"),"")} -> $F$7 | G8: {=IF('Raw Data'!G7="",_xlfn.REGEXEXTRACT(CELL("address",'Raw Data'!G7),"\$([A-Z]+)\$[0-9]+"),"")} -> $G$7 | H8: {=IF('Raw Data'!H7="",_xlfn.REGEXEXTRACT(CELL("address",'Raw Data'!H7),"\$([A-Z]+)\$[0-9]+"),"")} -> $H$7 | I8: {=IF('Raw Data'!I7="",_xlfn.REGEXEXTRACT(CELL("address",'Raw Data'!I7),"\$([A-Z]+)\$[0-9]+"),"")} -> $I$7
B9: {=IF('Raw Data'!B8="",_xlfn.REGEXEXTRACT(CELL("address",'Raw Data'!B8),"\$([A-Z]+)\$[0-9]+"),"")} -> $B$8 | C9: {=IF('Raw Data'!C8="",_xlfn.REGEXEXTRACT(CELL("address",'Raw Data'!C8),"\$([A-Z]+)\$[0-9]+"),"")} -> $C$8 | D9: {=IF('Raw Data'!D8="",_xlfn.REGEXEXTRACT(CELL("address",'Raw Data'!D8),"\$([A-Z]+)\$[0-9]+"),"")} -> $D$8 | E9: {=IF('Raw Data'!E8="",_xlfn.REGEXEXTRACT(CELL("address",'Raw Data'!E8),"\$([A-Z]+)\$[0-9]+"),"")} -> $E$8 | F9: {=IF('Raw Data'!F8="",_xlfn.REGEXEXTRACT(CELL("address",'Raw Data'!F8),"\$([A-Z]+)\$[0-9]+"),"")} -> $F$8 | G9: {=IF('Raw Data'!G8="",_xlfn.REGEXEXTRACT(CELL("address",'Raw Data'!G8),"\$([A-Z]+)\$[0-9]+"),"")} -> $G$8 | H9: {=IF('Raw Data'!H8="",_xlfn.REGEXEXTRACT(CELL("address",'Raw Data'!H8),"\$([A-Z]+)\$[0-9]+"),"")} -> $H$8 | I9: {=IF('Raw Data'!I8="",_xlfn.REGEXEXTRACT(CELL("address",'Raw Data'!I8),"\$([A-Z]+)\$[0-9]+"),"")} -> $I$8
B10: {=IF('Raw Data'!B9="",_xlfn.REGEXEXTRACT(CELL("address",'Raw Data'!B9),"\$([A-Z]+)\$[0-9]+"),"")} -> $B$9 | C10: {=IF('Raw Data'!C9="",_xlfn.REGEXEXTRACT(CELL("address",'Raw Data'!C9),"\$([A-Z]+)\$[0-9]+"),"")} -> $C$9 | D10: {=IF('Raw Data'!D9="",_xlfn.REGEXEXTRACT(CELL("address",'Raw Data'!D9),"\$([A-Z]+)\$[0-9]+"),"")} -> $D$9 | E10: {=IF('Raw Data'!E9="",_xlfn.REGEXEXTRACT(CELL("address",'Raw Data'!E9),"\$([A-Z]+)\$[0-9]+"),"")} -> $E$9 | F10: {=IF('Raw Data'!F9="",_xlfn.REGEXEXTRACT(CELL("address",'Raw Data'!F9),"\$([A-Z]+)\$[0-9]+"),"")} | G10: {=IF('Raw Data'!G9="",_xlfn.REGEXEXTRACT(CELL("address",'Raw Data'!G9),"\$([A-Z]+)\$[0-9]+"),"")} | H10: {=IF('Raw Data'!H9="",_xlfn.REGEXEXTRACT(CELL("address",'Raw Data'!H9),"\$([A-Z]+)\$[0-9]+"),"")} | I10: {=IF('Raw Data'!I9="",_xlfn.REGEXEXTRACT(CELL("address",'Raw Data'!I9),"\$([A-Z]+)\$[0-9]+"),"")} -> $I$9
B11: {=IF('Raw Data'!B10="",_xlfn.REGEXEXTRACT(CELL("address",'Raw Data'!B10),"\$([A-Z]+)\$[0-9]+"),"")} -> $B$10 | C11: {=IF('Raw Data'!C10="",_xlfn.REGEXEXTRACT(CELL("address",'Raw Data'!C10),"\$([A-Z]+)\$[0-9]+"),"")} -> $C$10 | D11: {=IF('Raw Data'!D10="",_xlfn.REGEXEXTRACT(CELL("address",'Raw Data'!D10),"\$([A-Z]+)\$[0-9]+"),"")} -> $D$10 | E11: {=IF('Raw Data'!E10="",_xlfn.REGEXEXTRACT(CELL("address",'Raw Data'!E10),"\$([A-Z]+)\$[0-9]+"),"")} -> $E$10 | F11: {=IF('Raw Data'!F10="",_xlfn.REGEXEXTRACT(CELL("address",'Raw Data'!F10),"\$([A-Z]+)\$[0-9]+"),"")} | G11: {=IF('Raw Data'!G10="",_xlfn.REGEXEXTRACT(CELL("address",'Raw Data'!G10),"\$([A-Z]+)\$[0-9]+"),"")} | H11: {=IF('Raw Data'!H10="",_xlfn.REGEXEXTRACT(CELL("address",'Raw Data'!H10),"\$([A-Z]+)\$[0-9]+"),"")} -> $H$10 | I11: {=IF('Raw Data'!I10="",_xlfn.REGEXEXTRACT(CELL("address",'Raw Data'!I10),"\$([A-Z]+)\$[0-9]+"),"")} -> $I$10
B12: {=IF('Raw Data'!B11="",_xlfn.REGEXEXTRACT(CELL("address",'Raw Data'!B11),"\$([A-Z]+)\$[0-9]+"),"")} -> $B$11 | C12: {=IF('Raw Data'!C11="",_xlfn.REGEXEXTRACT(CELL("address",'Raw Data'!C11),"\$([A-Z]+)\$[0-9]+"),"")} -> $C$11 | D12: {=IF('Raw Data'!D11="",_xlfn.REGEXEXTRACT(CELL("address",'Raw Data'!D11),"\$([A-Z]+)\$[0-9]+"),"")} -> $D$11 | E12: {=IF('Raw Data'!E11="",_xlfn.REGEXEXTRACT(CELL("address",'Raw Data'!E11),"\$([A-Z]+)\$[0-9]+"),"")} -> $E$11 | F12: {=IF('Raw Data'!F11="",_xlfn.REGEXEXTRACT(CELL("address",'Raw Data'!F11),"\$([A-Z]+)\$[0-9]+"),"")} | G12: {=IF('Raw Data'!G11="",_xlfn.REGEXEXTRACT(CELL("address",'Raw Data'!G11),"\$([A-Z]+)\$[0-9]+"),"")} | H12: {=IF('Raw Data'!#REF!="",_xlfn.REGEXEXTRACT(CELL("address",'Raw Data'!#REF!),"\$([A-Z]+)\$[0-9]+"),"")} -> #REF! | I12: {=IF('Raw Data'!H11="",_xlfn.REGEXEXTRACT(CELL("address",'Raw Data'!H11),"\$([A-Z]+)\$[0-9]+"),"")} -> $H$11
B13: {=IF('Raw Data'!B12="",_xlfn.REGEXEXTRACT(CELL("address",'Raw Data'!B12),"\$([A-Z]+)\$[0-9]+"),"")} -> $B$12 | C13: {=IF('Raw Data'!C12="",_xlfn.REGEXEXTRACT(CELL("address",'Raw Data'!C12),"\$([A-Z]+)\$[0-9]+"),"")} -> $C$12 | D13: {=IF('Raw Data'!D12="",_xlfn.REGEXEXTRACT(CELL("address",'Raw Data'!D12),"\$([A-Z]+)\$[0-9]+"),"")} -> $D$12 | E13: {=IF('Raw Data'!E12="",_xlfn.REGEXEXTRACT(CELL("address",'Raw Data'!E12),"\$([A-Z]+)\$[0-9]+"),"")} -> $E$12 | F13: {=IF('Raw Data'!F12="",_xlfn.REGEXEXTRACT(CELL("address",'Raw Data'!F12),"\$([A-Z]+)\$[0-9]+"),"")} | G13: {=IF('Raw Data'!G12="",_xlfn.REGEXEXTRACT(CELL("address",'Raw Data'!G12),"\$([A-Z]+)\$[0-9]+"),"")} | H13: {=IF('Raw Data'!#REF!="",_xlfn.REGEXEXTRACT(CELL("address",'Raw Data'!#REF!),"\$([A-Z]+)\$[0-9]+"),"")} -> #REF! | I13: {=IF('Raw Data'!H12="",_xlfn.REGEXEXTRACT(CELL("address",'Raw Data'!H12),"\$([A-Z]+)\$[0-9]+"),"")} -> $H$12
B14: {=IF('Raw Data'!B13="",_xlfn.REGEXEXTRACT(CELL("address",'Raw Data'!B13),"\$([A-Z]+)\$[0-9]+"),"")} -> $B$13 | C14: {=IF('Raw Data'!C13="",_xlfn.REGEXEXTRACT(CELL("address",'Raw Data'!C13),"\$([A-Z]+)\$[0-9]+"),"")} -> $C$13 | D14: {=IF('Raw Data'!D13="",_xlfn.REGEXEXTRACT(CELL("address",'Raw Data'!D13),"\$([A-Z]+)\$[0-9]+"),"")} -> $D$13 | E14: {=IF('Raw Data'!E13="",_xlfn.REGEXEXTRACT(CELL("address",'Raw Data'!E13),"\$([A-Z]+)\$[0-9]+"),"")} -> $E$13 | F14: {=IF('Raw Data'!F13="",_xlfn.REGEXEXTRACT(CELL("address",'Raw Data'!F13),"\$([A-Z]+)\$[0-9]+"),"")} | G14: {=IF('Raw Data'!G13="",_xlfn.REGEXEXTRACT(CELL("address",'Raw Data'!G13),"\$([A-Z]+)\$[0-9]+"),"")} | H14: {=IF('Raw Data'!#REF!="",_xlfn.REGEXEXTRACT(CELL("address",'Raw Data'!#REF!),"\$([A-Z]+)\$[0-9]+"),"")} -> #REF! | I14: {=IF('Raw Data'!H13="",_xlfn.REGEXEXTRACT(CELL("address",'Raw Data'!H13),"\$([A-Z]+)\$[0-9]+"),"")} -> $H$13
B15: {=IF('Raw Data'!B14="",_xlfn.REGEXEXTRACT(CELL("address",'Raw Data'!B14),"\$([A-Z]+)\$[0-9]+"),"")} -> $B$14 | C15: {=IF('Raw Data'!C14="",_xlfn.REGEXEXTRACT(CELL("address",'Raw Data'!C14),"\$([A-Z]+)\$[0-9]+"),"")} -> $C$14 | D15: {=IF('Raw Data'!D14="",_xlfn.REGEXEXTRACT(CELL("address",'Raw Data'!D14),"\$([A-Z]+)\$[0-9]+"),"")} -> $D$14 | E15: {=IF('Raw Data'!E14="",_xlfn.REGEXEXTRACT(CELL("address",'Raw Data'!E14),"\$([A-Z]+)\$[0-9]+"),"")} -> $E$14 | F15: {=IF('Raw Data'!F14="",_xlfn.REGEXEXTRACT(CELL("address",'Raw Data'!F14),"\$([A-Z]+)\$[0-9]+"),"")} | G15: {=IF('Raw Data'!G14="",_xlfn.REGEXEXTRACT(CELL("address",'Raw Data'!G14),"\$([A-Z]+)\$[0-9]+"),"")} | H15: {=IF('Raw Data'!#REF!="",_xlfn.REGEXEXTRACT(CELL("address",'Raw Data'!#REF!),"\$([A-Z]+)\$[0-9]+"),"")} -> #REF! | I15: {=IF('Raw Data'!H14="",_xlfn.REGEXEXTRACT(CELL("address",'Raw Data'!H14),"\$([A-Z]+)\$[0-9]+"),"")} -> $H$14
B16: {=IF('Raw Data'!B15="",_xlfn.REGEXEXTRACT(CELL("address",'Raw Data'!B15),"\$([A-Z]+)\$[0-9]+"),"")} -> $B$15 | C16: {=IF('Raw Data'!C15="",_xlfn.REGEXEXTRACT(CELL("address",'Raw Data'!C15),"\$([A-Z]+)\$[0-9]+"),"")} -> $C$15 | D16: {=IF('Raw Data'!D15="",_xlfn.REGEXEXTRACT(CELL("address",'Raw Data'!D15),"\$([A-Z]+)\$[0-9]+"),"")} -> $D$15 | E16: {=IF('Raw Data'!E15="",_xlfn.REGEXEXTRACT(CELL("address",'Raw Data'!E15),"\$([A-Z]+)\$[0-9]+"),"")} -> $E$15 | F16: {=IF('Raw Data'!F15="",_xlfn.REGEXEXTRACT(CELL("address",'Raw Data'!F15),"\$([A-Z]+)\$[0-9]+"),"")} | G16: {=IF('Raw Data'!G15="",_xlfn.REGEXEXTRACT(CELL("address",'Raw Data'!G15),"\$([A-Z]+)\$[0-9]+"),"")} | H16: {=IF('Raw Data'!#REF!="",_xlfn.REGEXEXTRACT(CELL("address",'Raw Data'!#REF!),"\$([A-Z]+)\$[0-9]+"),"")} -> #REF! | I16: {=IF('Raw Data'!H15="",_xlfn.REGEXEXTRACT(CELL("address",'Raw Data'!H15),"\$([A-Z]+)\$[0-9]+"),"")} -> $H$15
B17: {=IF('Raw Data'!B16="",_xlfn.REGEXEXTRACT(CELL("address",'Raw Data'!B16),"\$([A-Z]+)\$[0-9]+"),"")} -> $B$16 | C17: {=IF('Raw Data'!C16="",_xlfn.REGEXEXTRACT(CELL("address",'Raw Data'!C16),"\$([A-Z]+)\$[0-9]+"),"")} -> $C$16 | D17: {=IF('Raw Data'!D16="",_xlfn.REGEXEXTRACT(CELL("address",'Raw Data'!D16),"\$([A-Z]+)\$[0-9]+"),"")} -> $D$16 | E17: {=IF('Raw Data'!E16="",_xlfn.REGEXEXTRACT(CELL("address",'Raw Data'!E16),"\$([A-Z]+)\$[0-9]+"),"")} -> $E$16 | F17: {=IF('Raw Data'!F16="",_xlfn.REGEXEXTRACT(CELL("address",'Raw Data'!F16),"\$([A-Z]+)\$[0-9]+"),"")} | G17: {=IF('Raw Data'!G16="",_xlfn.REGEXEXTRACT(CELL("address",'Raw Data'!G16),"\$([A-Z]+)\$[0-9]+"),"")} | H17: {=IF('Raw Data'!#REF!="",_xlfn.REGEXEXTRACT(CELL("address",'Raw Data'!#REF!),"\$([A-Z]+)\$[0-9]+"),"")} -> #REF! | I17: {=IF('Raw Data'!H16="",_xlfn.REGEXEXTRACT(CELL("address",'Raw Data'!H16),"\$([A-Z]+)\$[0-9]+"),"")} -> $H$16
B18: {=IF('Raw Data'!B17="",_xlfn.REGEXEXTRACT(CELL("address",'Raw Data'!B17),"\$([A-Z]+)\$[0-9]+"),"")} -> $B$17 | C18: {=IF('Raw Data'!C17="",_xlfn.REGEXEXTRACT(CELL("address",'Raw Data'!C17),"\$([A-Z]+)\$[0-9]+"),"")} -> $C$17 | D18: {=IF('Raw Data'!D17="",_xlfn.REGEXEXTRACT(CELL("address",'Raw Data'!D17),"\$([A-Z]+)\$[0-9]+"),"")} -> $D$17 | E18: {=IF('Raw Data'!E17="",_xlfn.REGEXEXTRACT(CELL("address",'Raw Data'!E17),"\$([A-Z]+)\$[0-9]+"),"")} -> $E$17 | F18: {=IF('Raw Data'!F17="",_xlfn.REGEXEXTRACT(CELL("address",'Raw Data'!F17),"\$([A-Z]+)\$[0-9]+"),"")} | G18: {=IF('Raw Data'!G17="",_xlfn.REGEXEXTRACT(CELL("address",'Raw Data'!G17),"\$([A-Z]+)\$[0-9]+"),"")} | H18: {=IF('Raw Data'!#REF!="",_xlfn.REGEXEXTRACT(CELL("address",'Raw Data'!#REF!),"\$([A-Z]+)\$[0-9]+"),"")} -> #REF! | I18: {=IF('Raw Data'!H17="",_xlfn.REGEXEXTRACT(CELL("address",'Raw Data'!H17),"\$([A-Z]+)\$[0-9]+"),"")} -> $H$17
B19: {=IF('Raw Data'!B18="",_xlfn.REGEXEXTRACT(CELL("address",'Raw Data'!B18),"\$([A-Z]+)\$[0-9]+"),"")} -> $B$18 | C19: {=IF('Raw Data'!C18="",_xlfn.REGEXEXTRACT(CELL("address",'Raw Data'!C18),"\$([A-Z]+)\$[0-9]+"),"")} -> $C$18 | D19: {=IF('Raw Data'!D18="",_xlfn.REGEXEXTRACT(CELL("address",'Raw Data'!D18),"\$([A-Z]+)\$[0-9]+"),"")} -> $D$18 | E19: {=IF('Raw Data'!E18="",_xlfn.REGEXEXTRACT(CELL("address",'Raw Data'!E18),"\$([A-Z]+)\$[0-9]+"),"")} -> $E$18 | F19: {=IF('Raw Data'!F18="",_xlfn.REGEXEXTRACT(CELL("address",'Raw Data'!F18),"\$([A-Z]+)\$[0-9]+"),"")} | G19: {=IF('Raw Data'!G18="",_xlfn.REGEXEXTRACT(CELL("address",'Raw Data'!G18),"\$([A-Z]+)\$[0-9]+"),"")} | H19: {=IF('Raw Data'!#REF!="",_xlfn.REGEXEXTRACT(CELL("address",'Raw Data'!#REF!),"\$([A-Z]+)\$[0-9]+"),"")} -> #REF! | I19: {=IF('Raw Data'!H18="",_xlfn.REGEXEXTRACT(CELL("address",'Raw Data'!H18),"\$([A-Z]+)\$[0-9]+"),"")} -> $H$18
B20: {=IF('Raw Data'!B19="",_xlfn.REGEXEXTRACT(CELL("address",'Raw Data'!B19),"\$([A-Z]+)\$[0-9]+"),"")} -> $B$19 | C20: {=IF('Raw Data'!C19="",_xlfn.REGEXEXTRACT(CELL("address",'Raw Data'!C19),"\$([A-Z]+)\$[0-9]+"),"")} -> $C$19 | D20: {=IF('Raw Data'!D19="",_xlfn.REGEXEXTRACT(CELL("address",'Raw Data'!D19),"\$([A-Z]+)\$[0-9]+"),"")} -> $D$19 | E20: {=IF('Raw Data'!E19="",_xlfn.REGEXEXTRACT(CELL("address",'Raw Data'!E19),"\$([A-Z]+)\$[0-9]+"),"")} -> $E$19 | F20: {=IF('Raw Data'!F19="",_xlfn.REGEXEXTRACT(CELL("address",'Raw Data'!F19),"\$([A-Z]+)\$[0-9]+"),"")} | G20: {=IF('Raw Data'!G19="",_xlfn.REGEXEXTRACT(CELL("address",'Raw Data'!G19),"\$([A-Z]+)\$[0-9]+"),"")} | H20: {=IF('Raw Data'!#REF!="",_xlfn.REGEXEXTRACT(CELL("address",'Raw Data'!#REF!),"\$([A-Z]+)\$[0-9]+"),"")} -> #REF! | I20: {=IF('Raw Data'!H19="",_xlfn.REGEXEXTRACT(CELL("address",'Raw Data'!H19),"\$([A-Z]+)\$[0-9]+"),"")} -> $H$19
B21: {=IF('Raw Data'!B20="",_xlfn.REGEXEXTRACT(CELL("address",'Raw Data'!B20),"\$([A-Z]+)\$[0-9]+"),"")} -> $B$20 | C21: {=IF('Raw Data'!C20="",_xlfn.REGEXEXTRACT(CELL("address",'Raw Data'!C20),"\$([A-Z]+)\$[0-9]+"),"")} -> $C$20 | D21: {=IF('Raw Data'!D20="",_xlfn.REGEXEXTRACT(CELL("address",'Raw Data'!D20),"\$([A-Z]+)\$[0-9]+"),"")} -> $D$20 | E21: {=IF('Raw Data'!E20="",_xlfn.REGEXEXTRACT(CELL("address",'Raw Data'!E20),"\$([A-Z]+)\$[0-9]+"),"")} -> $E$20 | F21: {=IF('Raw Data'!F20="",_xlfn.REGEXEXTRACT(CELL("address",'Raw Data'!F20),"\$([A-Z]+)\$[0-9]+"),"")} | G21: {=IF('Raw Data'!G20="",_xlfn.REGEXEXTRACT(CELL("address",'Raw Data'!G20),"\$([A-Z]+)\$[0-9]+"),"")} | H21: {=IF('Raw Data'!#REF!="",_xlfn.REGEXEXTRACT(CELL("address",'Raw Data'!#REF!),"\$([A-Z]+)\$[0-9]+"),"")} -> #REF! | I21: {=IF('Raw Data'!H20="",_xlfn.REGEXEXTRACT(CELL("address",'Raw Data'!H20),"\$([A-Z]+)\$[0-9]+"),"")} -> $H$20
B22: {=IF('Raw Data'!B21="",_xlfn.REGEXEXTRACT(CELL("address",'Raw Data'!B21),"\$([A-Z]+)\$[0-9]+"),"")} -> $B$21 | C22: {=IF('Raw Data'!C21="",_xlfn.REGEXEXTRACT(CELL("address",'Raw Data'!C21),"\$([A-Z]+)\$[0-9]+"),"")} -> $C$21 | D22: {=IF('Raw Data'!D21="",_xlfn.REGEXEXTRACT(CELL("address",'Raw Data'!D21),"\$([A-Z]+)\$[0-9]+"),"")} -> $D$21 | E22: {=IF('Raw Data'!E21="",_xlfn.REGEXEXTRACT(CELL("address",'Raw Data'!E21),"\$([A-Z]+)\$[0-9]+"),"")} -> $E$21 | F22: {=IF('Raw Data'!F21="",_xlfn.REGEXEXTRACT(CELL("address",'Raw Data'!F21),"\$([A-Z]+)\$[0-9]+"),"")} | G22: {=IF('Raw Data'!G21="",_xlfn.REGEXEXTRACT(CELL("address",'Raw Data'!G21),"\$([A-Z]+)\$[0-9]+"),"")} | H22: {=IF('Raw Data'!H21="",_xlfn.REGEXEXTRACT(CELL("address",'Raw Data'!H21),"\$([A-Z]+)\$[0-9]+"),"")} -> $H$21 | I22: {=IF('Raw Data'!I21="",_xlfn.REGEXEXTRACT(CELL("address",'Raw Data'!I21),"\$([A-Z]+)\$[0-9]+"),"")} -> $I$21
B23: {=IF('Raw Data'!B22="",_xlfn.REGEXEXTRACT(CELL("address",'Raw Data'!B22),"\$([A-Z]+)\$[0-9]+"),"")} -> $B$22 | C23: {=IF('Raw Data'!C22="",_xlfn.REGEXEXTRACT(CELL("address",'Raw Data'!C22),"\$([A-Z]+)\$[0-9]+"),"")} -> $C$22 | D23: {=IF('Raw Data'!D22="",_xlfn.REGEXEXTRACT(CELL("address",'Raw Data'!D22),"\$([A-Z]+)\$[0-9]+"),"")} -> $D$22 | E23: {=IF('Raw Data'!E22="",_xlfn.REGEXEXTRACT(CELL("address",'Raw Data'!E22),"\$([A-Z]+)\$[0-9]+"),"")} -> $E$22 | F23: {=IF('Raw Data'!F22="",_xlfn.REGEXEXTRACT(CELL("address",'Raw Data'!F22),"\$([A-Z]+)\$[0-9]+"),"")} | G23: {=IF('Raw Data'!G22="",_xlfn.REGEXEXTRACT(CELL("address",'Raw Data'!G22),"\$([A-Z]+)\$[0-9]+"),"")} | H23: {=IF('Raw Data'!H22="",_xlfn.REGEXEXTRACT(CELL("address",'Raw Data'!H22),"\$([A-Z]+)\$[0-9]+"),"")} -> $H$22 | I23: {=IF('Raw Data'!I22="",_xlfn.REGEXEXTRACT(CELL("address",'Raw Data'!I22),"\$([A-Z]+)\$[0-9]+"),"")} -> $I$22
