Workbook

Sheet Raw Data
B11: C1 | C11: C2 | D11: C3 | E11: C4 | F11: C5 | G11: C6
B12: QAC001 | C12: Construction | D12: 47417565 | E12: 47417565 | F12: 0
B13: QAE001 | C13: Engineering | D13: 2851940.2 | E13: 2851940.2 | F13: 0
B14: QAP001 | C14: Procurement | D14: 36462971 | E14: 36462971 | F14: 0
B15: QAM001 | C15: Project Management | D15: 5526428.5 | E15: 5526428.5 | F15: 0
B16: N/A | C16: HUC | D16: 0 | E16: 0 | F16: 0
B17: N/A | C17: Construction | D17: 0 | E17: 0 | F17: 0
B18: N/A | C18: Engineering | D18: 0 | E18: 0 | F18: 0
B19: N/A | C19: Procurement | D19: 0 | E19: 0 | F19: 0
B20: N/A | C20: Project Management | D20: 0 | E20: 0 | F20: 0
B21: N/A | C21: HUC | D21: 0 | E21: 0 | F21: 0
B22: N/A | C22: Overall | D22: 0 | E22: 0 | F22: 0

Sheet Validate_Empty
B10: FALSE | C10: FALSE | D10: FALSE | E10: FALSE | F10: FALSE | G10: FALSE
B11: C1 | C11: C2 | D11: C3 | E11: C4 | F11: C5 | G11: C6

Sheet Validate_Value
B10: NVARCHAR(20) | C10: NVARCHAR(255) | D10: DECIMAL(13,2) | E10: DECIMAL(13,2) | F10: DECIMAL(13,2) | G10: NVARCHAR(MAX)
B11: C1 | C11: C2 | D11: C3 | E11: C4 | F11: C5 | G11: C6
B12: {=IFERROR(IF(OR('Raw Data'!B12="",LEN(TRIM('Raw Data'!B12))=0),"",IF(AND(LEN('Raw Data'!B12) <= 20,LEN('Raw Data'!B12)> 0),"",_xlfn.REGEXEXTRACT(CELL("address",'Raw Data'!B12),"\$([A-Z]+)\$[0-9]+"))),_xlfn.REGEXEXTRACT(CELL("address",'Raw Data'!B12),"\$([A-Z]+)\$[0-9]+"))} | C12: {=IFERROR(IF(OR('Raw Data'!C12="",LEN(TRIM('Raw Data'!C12))=0),"",IF(AND(LEN('Raw Data'!C12) <= 255,LEN('Raw Data'!C12)> 0),"",_xlfn.REGEXEXTRACT(CELL("address",'Raw Data'!C12),"\$([A-Z]+)\$[0-9]+"))),_xlfn.REGEXEXTRACT(CELL("address",'Raw Data'!C12),"\$([A-Z]+)\$[0-9]+"))} | D12: {=IFERROR(IF(OR('Raw Data'!D12="",LEN(TRIM('Raw Data'!D12))=0),"",IF(AND(ISNUMBER('Raw Data'!D12), IFERROR('Raw Data'!D12 = ROUND('Raw Data'!D12, 2),FALSE)),"",_xlfn.REGEXEXTRACT(CELL("address",D12), "\$([A-Z]+)\$[0-9]+"))),_xlfn.REGEXEXTRACT(CELL("address",D12), "\$([A-Z]+)\$[0-9]+"))} | E12: {=IFERROR(IF(OR('Raw Data'!E12="",LEN(TRIM('Raw Data'!E12))=0),"",IF(AND(ISNUMBER('Raw Data'!E12), IFERROR('Raw Data'!E12 = ROUND('Raw Data'!E12, 2),FALSE)),"",_xlfn.REGEXEXTRACT(CELL("address",E12), "\$([A-Z]+)\$[0-9]+"))),_xlfn.REGEXEXTRACT(CELL("address",E12), "\$([A-Z]+)\$[0-9]+"))} | F12: {=IFERROR(IF(OR('Raw Data'!F12="",LEN(TRIM('Raw Data'!F12))=0),"",IF(AND(ISNUMBER('Raw Data'!F12), IFERROR('Raw Data'!F12 = ROUND('Raw Data'!F12, 2),FALSE)),"",_xlfn.REGEXEXTRACT(CELL("address",F12), "\$([A-Z]+)\$[0-9]+"))),_xlfn.REGEXEXTRACT(CELL("address",F12), "\$([A-Z]+)\$[0-9]+"))} | G12: {=IFERROR(IF(OR('Raw Data'!G12="",LEN(TRIM('Raw Data'!G12))=0),"",IF(LEN('Raw Data'!G12)> 0,"",_xlfn.REGEXEXTRACT(CELL("address",'Raw Data'!G12),"\$([A-Z]+)\$[0-9]+"))),_xlfn.REGEXEXTRACT(CELL("address",'Raw Data'!G12),"\$([A-Z]+)\$[0-9]+"))}
B13: {=IFERROR(IF(OR('Raw Data'!B13="",LEN(TRIM('Raw Data'!B13))=0),"",IF(AND(LEN('Raw Data'!B13) <= 20,LEN('Raw Data'!B13)> 0),"",_xlfn.REGEXEXTRACT(CELL("address",'Raw Data'!B13),"\$([A-Z]+)\$[0-9]+"))),_xlfn.REGEXEXTRACT(CELL("address",'Raw Data'!B13),"\$([A-Z]+)\$[0-9]+"))} | C13: {=IFERROR(IF(OR('Raw Data'!C13="",LEN(TRIM('Raw Data'!C13))=0),"",IF(AND(LEN('Raw Data'!C13) <= 255,LEN('Raw Data'!C13)> 0),"",_xlfn.REGEXEXTRACT(CELL("address",'Raw Data'!C13),"\$([A-Z]+)\$[0-9]+"))),_xlfn.REGEXEXTRACT(CELL("address",'Raw Data'!C13),"\$([A-Z]+)\$[0-9]+"))} | D13: {=IFERROR(IF(OR('Raw Data'!D13="",LEN(TRIM('Raw Data'!D13))=0),"",IF(AND(ISNUMBER('Raw Data'!D13), IFERROR('Raw Data'!D13 = ROUND('Raw Data'!D13, 2),FALSE)),"",_xlfn.REGEXEXTRACT(CELL("address",D13), "\$([A-Z]+)\$[0-9]+"))),_xlfn.REGEXEXTRACT(CELL("address",D13), "\$([A-Z]+)\$[0-9]+"))} | E13: {=IFERROR(IF(OR('Raw Data'!E13="",LEN(TRIM('Raw Data'!E13))=0),"",IF(AND(ISNUMBER('Raw Data'!E13), IFERROR('Raw Data'!E13 = ROUND('Raw Data'!E13, 2),FALSE)),"",_xlfn.REGEXEXTRACT(CELL("address",E13), "\$([A-Z]+)\$[0-9]+"))),_xlfn.REGEXEXTRACT(CELL("address",E13), "\$([A-Z]+)\$[0-9]+"))} | F13: {=IFERROR(IF(OR('Raw Data'!F13="",LEN(TRIM('Raw Data'!F13))=0),"",IF(AND(ISNUMBER('Raw Data'!F13), IFERROR('Raw Data'!F13 = ROUND('Raw Data'!F13, 2),FALSE)),"",_xlfn.REGEXEXTRACT(CELL("address",F13), "\$([A-Z]+)\$[0-9]+"))),_xlfn.REGEXEXTRACT(CELL("address",F13), "\$([A-Z]+)\$[0-9]+"))} | G13: {=IFERROR(IF(OR('Raw Data'!G13="",LEN(TRIM('Raw Data'!G13))=0),"",IF(LEN('Raw Data'!G13)> 0,"",_xlfn.REGEXEXTRACT(CELL("address",'Raw Data'!G13),"\$([A-Z]+)\$[0-9]+"))),_xlfn.REGEXEXTRACT(CELL("address",'Raw Data'!G13),"\$([A-Z]+)\$[0-9]+"))}
B14: {=IFERROR(IF(OR('Raw Data'!B14="",LEN(TRIM('Raw Data'!B14))=0),"",IF(AND(LEN('Raw Data'!B14) <= 20,LEN('Raw Data'!B14)> 0),"",_xlfn.REGEXEXTRACT(CELL("address",'Raw Data'!B14),"\$([A-Z]+)\$[0-9]+"))),_xlfn.REGEXEXTRACT(CELL("address",'Raw Data'!B14),"\$([A-Z]+)\$[0-9]+"))} | C14: {=IFERROR(IF(OR('Raw Data'!C14="",LEN(TRIM('Raw Data'!C14))=0),"",IF(AND(LEN('Raw Data'!C14) <= 255,LEN('Raw Data'!C14)> 0),"",_xlfn.REGEXEXTRACT(CELL("address",'Raw Data'!C14),"\$([A-Z]+)\$[0-9]+"))),_xlfn.REGEXEXTRACT(CELL("address",'Raw Data'!C14),"\$([A-Z]+)\$[0-9]+"))} | D14: {=IFERROR(IF(OR('Raw Data'!D14="",LEN(TRIM('Raw Data'!D14))=0),"",IF(AND(ISNUMBER('Raw Data'!D14), IFERROR('Raw Data'!D14 = ROUND('Raw Data'!D14, 2),FALSE)),"",_xlfn.REGEXEXTRACT(CELL("address",D14), "\$([A-Z]+)\$[0-9]+"))),_xlfn.REGEXEXTRACT(CELL("address",D14), "\$([A-Z]+)\$[0-9]+"))} | E14: {=IFERROR(IF(OR('Raw Data'!E14="",LEN(TRIM('Raw Data'!E14))=0),"",IF(AND(ISNUMBER('Raw Data'!E14), IFERROR('Raw Data'!E14 = ROUND('Raw Data'!E14, 2),FALSE)),"",_xlfn.REGEXEXTRACT(CELL("address",E14), "\$([A-Z]+)\$[0-9]+"))),_xlfn.REGEXEXTRACT(CELL("address",E14), "\$([A-Z]+)\$[0-9]+"))} | F14: {=IFERROR(IF(OR('Raw Data'!F14="",LEN(TRIM('Raw Data'!F14))=0),"",IF(AND(ISNUMBER('Raw Data'!F14), IFERROR('Raw Data'!F14 = ROUND('Raw Data'!F14, 2),FALSE)),"",_xlfn.REGEXEXTRACT(CELL("address",F14), "\$([A-Z]+)\$[0-9]+"))),_xlfn.REGEXEXTRACT(CELL("address",F14), "\$([A-Z]+)\$[0-9]+"))} | G14: {=IFERROR(IF(OR('Raw Data'!G14="",LEN(TRIM('Raw Data'!G14))=0),"",IF(LEN('Raw Data'!G14)> 0,"",_xlfn.REGEXEXTRACT(CELL("address",'Raw Data'!G14),"\$([A-Z]+)\$[0-9]+"))),_xlfn.REGEXEXTRACT(CELL("address",'Raw Data'!G14),"\$([A-Z]+)\$[0-9]+"))}
B15: {=IFERROR(IF(OR('Raw Data'!B15="",LEN(TRIM('Raw Data'!B15))=0),"",IF(AND(LEN('Raw Data'!B15) <= 20,LEN('Raw Data'!B15)> 0),"",_xlfn.REGEXEXTRACT(CELL("address",'Raw Data'!B15),"\$([A-Z]+)\$[0-9]+"))),_xlfn.REGEXEXTRACT(CELL("address",'Raw Data'!B15),"\$([A-Z]+)\$[0-9]+"))} | C15: {=IFERROR(IF(OR('Raw Data'!C15="",LEN(TRIM('Raw Data'!C15))=0),"",IF(AND(LEN('Raw Data'!C15) <= 255,LEN('Raw Data'!C15)> 0),"",_xlfn.REGEXEXTRACT(CELL("address",'Raw Data'!C15),"\$([A-Z]+)\$[0-9]+"))),_xlfn.REGEXEXTRACT(CELL("address",'Raw Data'!C15),"\$([A-Z]+)\$[0-9]+"))} | D15: {=IFERROR(IF(OR('Raw Data'!D15="",LEN(TRIM('Raw Data'!D15))=0),"",IF(AND(ISNUMBER('Raw Data'!D15), IFERROR('Raw Data'!D15 = ROUND('Raw Data'!D15, 2),FALSE)),"",_xlfn.REGEXEXTRACT(CELL("address",D15), "\$([A-Z]+)\$[0-9]+"))),_xlfn.REGEXEXTRACT(CELL("address",D15), "\$([A-Z]+)\$[0-9]+"))} | E15: {=IFERROR(IF(OR('Raw Data'!E15="",LEN(TRIM('Raw Data'!E15))=0),"",IF(AND(ISNUMBER('Raw Data'!E15), IFERROR('Raw Data'!E15 = ROUND('Raw Data'!E15, 2),FALSE)),"",_xlfn.REGEXEXTRACT(CELL("address",E15), "\$([A-Z]+)\$[0-9]+"))),_xlfn.REGEXEXTRACT(CELL("address",E15), "\$([A-Z]+)\$[0-9]+"))} | F15: {=IFERROR(IF(OR('Raw Data'!F15="",LEN(TRIM('Raw Data'!F15))=0),"",IF(AND(ISNUMBER('Raw Data'!F15), IFERROR('Raw Data'!F15 = ROUND('Raw Data'!F15, 2),FALSE)),"",_xlfn.REGEXEXTRACT(CELL("address",F15), "\$([A-Z]+)\$[0-9]+"))),_xlfn.REGEXEXTRACT(CELL("address",F15), "\$([A-Z]+)\$[0-9]+"))} | G15: {=IFERROR(IF(OR('Raw Data'!G15="",LEN(TRIM('Raw Data'!G15))=0),"",IF(LEN('Raw Data'!G15)> 0,"",_xlfn.REGEXEXTRACT(CELL("address",'Raw Data'!G15),"\$([A-Z]+)\$[0-9]+"))),_xlfn.REGEXEXTRACT(CELL("address",'Raw Data'!G15),"\$([A-Z]+)\$[0-9]+"))}
B16: {=IFERROR(IF(OR('Raw Data'!B16="",LEN(TRIM('Raw Data'!B16))=0),"",IF(AND(LEN('Raw Data'!B16) <= 20,LEN('Raw Data'!B16)> 0),"",_xlfn.REGEXEXTRACT(CELL("address",'Raw Data'!B16),"\$([A-Z]+)\$[0-9]+"))),_xlfn.REGEXEXTRACT(CELL("address",'Raw Data'!B16),"\$([A-Z]+)\$[0-9]+"))} | C16: {=IFERROR(IF(OR('Raw Data'!C16="",LEN(TRIM('Raw Data'!C16))=0),"",IF(AND(LEN('Raw Data'!C16) <= 255,LEN('Raw Data'!C16)> 0),"",_xlfn.REGEXEXTRACT(CELL("address",'Raw Data'!C16),"\$([A-Z]+)\$[0-9]+"))),_xlfn.REGEXEXTRACT(CELL("address",'Raw Data'!C16),"\$([A-Z]+)\$[0-9]+"))} | D16: {=IFERROR(IF(OR('Raw Data'!D16="",LEN(TRIM('Raw Data'!D16))=0),"",IF(AND(ISNUMBER('Raw Data'!D16), IFERROR('Raw Data'!D16 = ROUND('Raw Data'!D16, 2),FALSE)),"",_xlfn.REGEXEXTRACT(CELL("address",D16), "\$([A-Z]+)\$[0-9]+"))),_xlfn.REGEXEXTRACT(CELL("address",D16), "\$([A-Z]+)\$[0-9]+"))} | E16: {=IFERROR(IF(OR('Raw Data'!E16="",LEN(TRIM('Raw Data'!E16))=0),"",IF(AND(ISNUMBER('Raw Data'!E16), IFERROR('Raw Data'!E16 = ROUND('Raw Data'!E16, 2),FALSE)),"",_xlfn.REGEXEXTRACT(CELL("address",E16), "\$([A-Z]+)\$[0-9]+"))),_xlfn.REGEXEXTRACT(CELL("address",E16), "\$([A-Z]+)\$[0-9]+"))} | F16: {=IFERROR(IF(OR('Raw Data'!F16="",LEN(TRIM('Raw Data'!F16))=0),"",IF(AND(ISNUMBER('Raw Data'!F16), IFERROR('Raw Data'!F16 = ROUND('Raw Data'!F16, 2),FALSE)),"",_xlfn.REGEXEXTRACT(CELL("address",F16), "\$([A-Z]+)\$[0-9]+"))),_xlfn.REGEXEXTRACT(CELL("address",F16), "\$([A-Z]+)\$[0-9]+"))} | G16: {=IFERROR(IF(OR('Raw Data'!G16="",LEN(TRIM('Raw Data'!G16))=0),"",IF(LEN('Raw Data'!G16)> 0,"",_xlfn.REGEXEXTRACT(CELL("address",'Raw Data'!G16),"\$([A-Z]+)\$[0-9]+"))),_xlfn.REGEXEXTRACT(CELL("address",'Raw Data'!G16),"\$([A-Z]+)\$[0-9]+"))}
B17: {=IFERROR(IF(OR('Raw Data'!B17="",LEN(TRIM('Raw Data'!B17))=0),"",IF(AND(LEN('Raw Data'!B17) <= 20,LEN('Raw Data'!B17)> 0),"",_xlfn.REGEXEXTRACT(CELL("address",'Raw Data'!B17),"\$([A-Z]+)\$[0-9]+"))),_xlfn.REGEXEXTRACT(CELL("address",'Raw Data'!B17),"\$([A-Z]+)\$[0-9]+"))} | C17: {=IFERROR(IF(OR('Raw Data'!C17="",LEN(TRIM('Raw Data'!C17))=0),"",IF(AND(LEN('Raw Data'!C17) <= 255,LEN('Raw Data'!C17)> 0),"",_xlfn.REGEXEXTRACT(CELL("address",'Raw Data'!C17),"\$([A-Z]+)\$[0-9]+"))),_xlfn.REGEXEXTRACT(CELL("address",'Raw Data'!C17),"\$([A-Z]+)\$[0-9]+"))} | D17: {=IFERROR(IF(OR('Raw Data'!D17="",LEN(TRIM('Raw Data'!D17))=0),"",IF(AND(ISNUMBER('Raw Data'!D17), IFERROR('Raw Data'!D17 = ROUND('Raw Data'!D17, 2),FALSE)),"",_xlfn.REGEXEXTRACT(CELL("address",D17), "\$([A-Z]+)\$[0-9]+"))),_xlfn.REGEXEXTRACT(CELL("address",D17), "\$([A-Z]+)\$[0-9]+"))} | E17: {=IFERROR(IF(OR('Raw Data'!E17="",LEN(TRIM('Raw Data'!E17))=0),"",IF(AND(ISNUMBER('Raw Data'!E17), IFERROR('Raw Data'!E17 = ROUND('Raw Data'!E17, 2),FALSE)),"",_xlfn.REGEXEXTRACT(CELL("address",E17), "\$([A-Z]+)\$[0-9]+"))),_xlfn.REGEXEXTRACT(CELL("address",E17), "\$([A-Z]+)\$[0-9]+"))} | F17: {=IFERROR(IF(OR('Raw Data'!F17="",LEN(TRIM('Raw Data'!F17))=0),"",IF(AND(ISNUMBER('Raw Data'!F17), IFERROR('Raw Data'!F17 = ROUND('Raw Data'!F17, 2),FALSE)),"",_xlfn.REGEXEXTRACT(CELL("address",F17), "\$([A-Z]+)\$[0-9]+"))),_xlfn.REGEXEXTRACT(CELL("address",F17), "\$([A-Z]+)\$[0-9]+"))} | G17: {=IFERROR(IF(OR('Raw Data'!G17="",LEN(TRIM('Raw Data'!G17))=0),"",IF(LEN('Raw Data'!G17)> 0,"",_xlfn.REGEXEXTRACT(CELL("address",'Raw Data'!G17),"\$([A-Z]+)\$[0-9]+"))),_xlfn.REGEXEXTRACT(CELL("address",'Raw Data'!G17),"\$([A-Z]+)\$[0-9]+"))}
B18: {=IFERROR(IF(OR('Raw Data'!B18="",LEN(TRIM('Raw Data'!B18))=0),"",IF(AND(LEN('Raw Data'!B18) <= 20,LEN('Raw Data'!B18)> 0),"",_xlfn.REGEXEXTRACT(CELL("address",'Raw Data'!B18),"\$([A-Z]+)\$[0-9]+"))),_xlfn.REGEXEXTRACT(CELL("address",'Raw Data'!B18),"\$([A-Z]+)\$[0-9]+"))} | C18: {=IFERROR(IF(OR('Raw Data'!C18="",LEN(TRIM('Raw Data'!C18))=0),"",IF(AND(LEN('Raw Data'!C18) <= 255,LEN('Raw Data'!C18)> 0),"",_xlfn.REGEXEXTRACT(CELL("address",'Raw Data'!C18),"\$([A-Z]+)\$[0-9]+"))),_xlfn.REGEXEXTRACT(CELL("address",'Raw Data'!C18),"\$([A-Z]+)\$[0-9]+"))} | D18: {=IFERROR(IF(OR('Raw Data'!D18="",LEN(TRIM('Raw Data'!D18))=0),"",IF(AND(ISNUMBER('Raw Data'!D18), IFERROR('Raw Data'!D18 = ROUND('Raw Data'!D18, 2),FALSE)),"",_xlfn.REGEXEXTRACT(CELL("address",D18), "\$([A-Z]+)\$[0-9]+"))),_xlfn.REGEXEXTRACT(CELL("address",D18), "\$([A-Z]+)\$[0-9]+"))} | E18: {=IFERROR(IF(OR('Raw Data'!E18="",LEN(TRIM('Raw Data'!E18))=0),"",IF(AND(ISNUMBER('Raw Data'!E18), IFERROR('Raw Data'!E18 = ROUND('Raw Data'!E18, 2),FALSE)),"",_xlfn.REGEXEXTRACT(CELL("address",E18), "\$([A-Z]+)\$[0-9]+"))),_xlfn.REGEXEXTRACT(CELL("address",E18), "\$([A-Z]+)\$[0-9]+"))} | F18: {=IFERROR(IF(OR('Raw Data'!F18="",LEN(TRIM('Raw Data'!F18))=0),"",IF(AND(ISNUMBER('Raw Data'!F18), IFERROR('Raw Data'!F18 = ROUND('Raw Data'!F18, 2),FALSE)),"",_xlfn.REGEXEXTRACT(CELL("address",F18), "\$([A-Z]+)\$[0-9]+"))),_xlfn.REGEXEXTRACT(CELL("address",F18), "\$([A-Z]+)\$[0-9]+"))} | G18: {=IFERROR(IF(OR('Raw Data'!G18="",LEN(TRIM('Raw Data'!G18))=0),"",IF(LEN('Raw Data'!G18)> 0,"",_xlfn.REGEXEXTRACT(CELL("address",'Raw Data'!G18),"\$([A-Z]+)\$[0-9]+"))),_xlfn.REGEXEXTRACT(CELL("address",'Raw Data'!G18),"\$([A-Z]+)\$[0-9]+"))}
B19: {=IFERROR(IF(OR('Raw Data'!B19="",LEN(TRIM('Raw Data'!B19))=0),"",IF(AND(LEN('Raw Data'!B19) <= 20,LEN('Raw Data'!B19)> 0),"",_xlfn.REGEXEXTRACT(CELL("address",'Raw Data'!B19),"\$([A-Z]+)\$[0-9]+"))),_xlfn.REGEXEXTRACT(CELL("address",'Raw Data'!B19),"\$([A-Z]+)\$[0-9]+"))} | C19: {=IFERROR(IF(OR('Raw Data'!C19="",LEN(TRIM('Raw Data'!C19))=0),"",IF(AND(LEN('Raw Data'!C19) <= 255,LEN('Raw Data'!C19)> 0),"",_xlfn.REGEXEXTRACT(CELL("address",'Raw Data'!C19),"\$([A-Z]+)\$[0-9]+"))),_xlfn.REGEXEXTRACT(CELL("address",'Raw Data'!C19),"\$([A-Z]+)\$[0-9]+"))} | D19: {=IFERROR(IF(OR('Raw Data'!D19="",LEN(TRIM('Raw Data'!D19))=0),"",IF(AND(ISNUMBER('Raw Data'!D19), IFERROR('Raw Data'!D19 = ROUND('Raw Data'!D19, 2),FALSE)),"",_xlfn.REGEXEXTRACT(CELL("address",D19), "\$([A-Z]+)\$[0-9]+"))),_xlfn.REGEXEXTRACT(CELL("address",D19), "\$([A-Z]+)\$[0-9]+"))} | E19: {=IFERROR(IF(OR('Raw Data'!E19="",LEN(TRIM('Raw Data'!E19))=0),"",IF(AND(ISNUMBER('Raw Data'!E19), IFERROR('Raw Data'!E19 = ROUND('Raw Data'!E19, 2),FALSE)),"",_xlfn.REGEXEXTRACT(CELL("address",E19), "\$([A-Z]+)\$[0-9]+"))),_xlfn.REGEXEXTRACT(CELL("address",E19), "\$([A-Z]+)\$[0-9]+"))} | F19: {=IFERROR(IF(OR('Raw Data'!F19="",LEN(TRIM('Raw Data'!F19))=0),"",IF(AND(ISNUMBER('Raw Data'!F19), IFERROR('Raw Data'!F19 = ROUND('Raw Data'!F19, 2),FALSE)),"",_xlfn.REGEXEXTRACT(CELL("address",F19), "\$([A-Z]+)\$[0-9]+"))),_xlfn.REGEXEXTRACT(CELL("address",F19), "\$([A-Z]+)\$[0-9]+"))} | G19: {=IFERROR(IF(OR('Raw Data'!G19="",LEN(TRIM('Raw Data'!G19))=0),"",IF(LEN('Raw Data'!G19)> 0,"",_xlfn.REGEXEXTRACT(CELL("address",'Raw Data'!G19),"\$([A-Z]+)\$[0-9]+"))),_xlfn.REGEXEXTRACT(CELL("address",'Raw Data'!G19),"\$([A-Z]+)\$[0-9]+"))}
B20: {=IFERROR(IF(OR('Raw Data'!B20="",LEN(TRIM('Raw Data'!B20))=0),"",IF(AND(LEN('Raw Data'!B20) <= 20,LEN('Raw Data'!B20)> 0),"",_xlfn.REGEXEXTRACT(CELL("address",'Raw Data'!B20),"\$([A-Z]+)\$[0-9]+"))),_xlfn.REGEXEXTRACT(CELL("address",'Raw Data'!B20),"\$([A-Z]+)\$[0-9]+"))} | C20: {=IFERROR(IF(OR('Raw Data'!C20="",LEN(TRIM('Raw Data'!C20))=0),"",IF(AND(LEN('Raw Data'!C20) <= 255,LEN('Raw Data'!C20)> 0),"",_xlfn.REGEXEXTRACT(CELL("address",'Raw Data'!C20),"\$([A-Z]+)\$[0-9]+"))),_xlfn.REGEXEXTRACT(CELL("address",'Raw Data'!C20),"\$([A-Z]+)\$[0-9]+"))} | D20: {=IFERROR(IF(OR('Raw Data'!D20="",LEN(TRIM('Raw Data'!D20))=0),"",IF(AND(ISNUMBER('Raw Data'!D20), IFERROR('Raw Data'!D20 = ROUND('Raw Data'!D20, 2),FALSE)),"",_xlfn.REGEXEXTRACT(CELL("address",D20), "\$([A-Z]+)\$[0-9]+"))),_xlfn.REGEXEXTRACT(CELL("address",D20), "\$([A-Z]+)\$[0-9]+"))} | E20: {=IFERROR(IF(OR('Raw Data'!E20="",LEN(TRIM('Raw Data'!E20))=0),"",IF(AND(ISNUMBER('Raw Data'!E20), IFERROR('Raw Data'!E20 = ROUND('Raw Data'!E20, 2),FALSE)),"",_xlfn.REGEXEXTRACT(CELL("address",E20), "\$([A-Z]+)\$[0-9]+"))),_xlfn.REGEXEXTRACT(CELL("address",E20), "\$([A-Z]+)\$[0-9]+"))} | F20: {=IFERROR(IF(OR('Raw Data'!F20="",LEN(TRIM('Raw Data'!F20))=0),"",IF(AND(ISNUMBER('Raw Data'!F20), IFERROR('Raw Data'!F20 = ROUND('Raw Data'!F20, 2),FALSE)),"",_xlfn.REGEXEXTRACT(CELL("address",F20), "\$([A-Z]+)\$[0-9]+"))),_xlfn.REGEXEXTRACT(CELL("address",F20), "\$([A-Z]+)\$[0-9]+"))} | G20: {=IFERROR(IF(OR('Raw Data'!G20="",LEN(TRIM('Raw Data'!G20))=0),"",IF(LEN('Raw Data'!G20)> 0,"",_xlfn.REGEXEXTRACT(CELL("address",'Raw Data'!G20),"\$([A-Z]+)\$[0-9]+"))),_xlfn.REGEXEXTRACT(CELL("address",'Raw Data'!G20),"\$([A-Z]+)\$[0-9]+"))}
B21: {=IFERROR(IF(OR('Raw Data'!B21="",LEN(TRIM('Raw Data'!B21))=0),"",IF(AND(LEN('Raw Data'!B21) <= 20,LEN('Raw Data'!B21)> 0),"",_xlfn.REGEXEXTRACT(CELL("address",'Raw Data'!B21),"\$([A-Z]+)\$[0-9]+"))),_xlfn.REGEXEXTRACT(CELL("address",'Raw Data'!B21),"\$([A-Z]+)\$[0-9]+"))} | C21: {=IFERROR(IF(OR('Raw Data'!C21="",LEN(TRIM('Raw Data'!C21))=0),"",IF(AND(LEN('Raw Data'!C21) <= 255,LEN('Raw Data'!C21)> 0),"",_xlfn.REGEXEXTRACT(CELL("address",'Raw Data'!C21),"\$([A-Z]+)\$[0-9]+"))),_xlfn.REGEXEXTRACT(CELL("address",'Raw Data'!C21),"\$([A-Z]+)\$[0-9]+"))} | D21: {=IFERROR(IF(OR('Raw Data'!D21="",LEN(TRIM('Raw Data'!D21))=0),"",IF(AND(ISNUMBER('Raw Data'!D21), IFERROR('Raw Data'!D21 = ROUND('Raw Data'!D21, 2),FALSE)),"",_xlfn.REGEXEXTRACT(CELL("address",D21), "\$([A-Z]+)\$[0-9]+"))),_xlfn.REGEXEXTRACT(CELL("address",D21), "\$([A-Z]+)\$[0-9]+"))} | E21: {=IFERROR(IF(OR('Raw Data'!E21="",LEN(TRIM('Raw Data'!E21))=0),"",IF(AND(ISNUMBER('Raw Data'!E21), IFERROR('Raw Data'!E21 = ROUND('Raw Data'!E21, 2),FALSE)),"",_xlfn.REGEXEXTRACT(CELL("address",E21), "\$([A-Z]+)\$[0-9]+"))),_xlfn.REGEXEXTRACT(CELL("address",E21), "\$([A-Z]+)\$[0-9]+"))} | F21: {=IFERROR(IF(OR('Raw Data'!F21="",LEN(TRIM('Raw Data'!F21))=0),"",IF(AND(ISNUMBER('Raw Data'!F21), IFERROR('Raw Data'!F21 = ROUND('Raw Data'!F21, 2),FALSE)),"",_xlfn.REGEXEXTRACT(CELL("address",F21), "\$([A-Z]+)\$[0-9]+"))),_xlfn.REGEXEXTRACT(CELL("address",F21), "\$([A-Z]+)\$[0-9]+"))} | G21: {=IFERROR(IF(OR('Raw Data'!G21="",LEN(TRIM('Raw Data'!G21))=0),"",IF(LEN('Raw Data'!G21)> 0,"",_xlfn.REGEXEXTRACT(CELL("address",'Raw Data'!G21),"\$([A-Z]+)\$[0-9]+"))),_xlfn.REGEXEXTRACT(CELL("address",'Raw Data'!G21),"\$([A-Z]+)\$[0-9]+"))}
B22: {=IFERROR(IF(OR('Raw Data'!B22="",LEN(TRIM('Raw Data'!B22))=0),"",IF(AND(LEN('Raw Data'!B22) <= 20,LEN('Raw Data'!B22)> 0),"",_xlfn.REGEXEXTRACT(CELL("address",'Raw Data'!B22),"\$([A-Z]+)\$[0-9]+"))),_xlfn.REGEXEXTRACT(CELL("address",'Raw Data'!B22),"\$([A-Z]+)\$[0-9]+"))} | C22: {=IFERROR(IF(OR('Raw Data'!C22="",LEN(TRIM('Raw Data'!C22))=0),"",IF(AND(LEN('Raw Data'!C22) <= 255,LEN('Raw Data'!C22)> 0),"",_xlfn.REGEXEXTRACT(CELL("address",'Raw Data'!C22),"\$([A-Z]+)\$[0-9]+"))),_xlfn.REGEXEXTRACT(CELL("address",'Raw Data'!C22),"\$([A-Z]+)\$[0-9]+"))} | D22: {=IFERROR(IF(OR('Raw Data'!D22="",LEN(TRIM('Raw Data'!D22))=0),"",IF(AND(ISNUMBER('Raw Data'!D22), IFERROR('Raw Data'!D22 = ROUND('Raw Data'!D22, 2),FALSE)),"",_xlfn.REGEXEXTRACT(CELL("address",D22), "\$([A-Z]+)\$[0-9]+"))),_xlfn.REGEXEXTRACT(CELL("address",D22), "\$([A-Z]+)\$[0-9]+"))} | E22: {=IFERROR(IF(OR('Raw Data'!E22="",LEN(TRIM('Raw Data'!E22))=0),"",IF(AND(ISNUMBER('Raw Data'!E22), IFERROR('Raw Data'!E22 = ROUND('Raw Data'!E22, 2),FALSE)),"",_xlfn.REGEXEXTRACT(CELL("address",E22), "\$([A-Z]+)\$[0-9]+"))),_xlfn.REGEXEXTRACT(CELL("address",E22), "\$([A-Z]+)\$[0-9]+"))} | F22: {=IFERROR(IF(OR('Raw Data'!F22="",LEN(TRIM('Raw Data'!F22))=0),"",IF(AND(ISNUMBER('Raw Data'!F22), IFERROR('Raw Data'!F22 = ROUND('Raw Data'!F22, 2),FALSE)),"",_xlfn.REGEXEXTRACT(CELL("address",F22), "\$([A-Z]+)\$[0-9]+"))),_xlfn.REGEXEXTRACT(CELL("address",F22), "\$([A-Z]+)\$[0-9]+"))} | G22: {=IFERROR(IF(OR('Raw Data'!G22="",LEN(TRIM('Raw Data'!G22))=0),"",IF(LEN('Raw Data'!G22)> 0,"",_xlfn.REGEXEXTRACT(CELL("address",'Raw Data'!G22),"\$([A-Z]+)\$[0-9]+"))),_xlfn.REGEXEXTRACT(CELL("address",'Raw Data'!G22),"\$([A-Z]+)\$[0-9]+"))}
B23: {=IFERROR(IF(OR('Raw Data'!B23="",LEN(TRIM('Raw Data'!B23))=0),"",IF(AND(LEN('Raw Data'!B23) <= 20,LEN('Raw Data'!B23)> 0),"",_xlfn.REGEXEXTRACT(CELL("address",'Raw Data'!B23),"\$([A-Z]+)\$[0-9]+"))),_xlfn.REGEXEXTRACT(CELL("address",'Raw Data'!B23),"\$([A-Z]+)\$[0-9]+"))} | C23: {=IFERROR(IF(OR('Raw Data'!C23="",LEN(TRIM('Raw Data'!C23))=0),"",IF(AND(LEN('Raw Data'!C23) <= 255,LEN('Raw Data'!C23)> 0),"",_xlfn.REGEXEXTRACT(CELL("address",'Raw Data'!C23),"\$([A-Z]+)\$[0-9]+"))),_xlfn.REGEXEXTRACT(CELL("address",'Raw Data'!C23),"\$([A-Z]+)\$[0-9]+"))} | D23: {=IFERROR(IF(OR('Raw Data'!D23="",LEN(TRIM('Raw Data'!D23))=0),"",IF(AND(ISNUMBER('Raw Data'!D23), IFERROR('Raw Data'!D23 = ROUND('Raw Data'!D23, 2),FALSE)),"",_xlfn.REGEXEXTRACT(CELL("address",D23), "\$([A-Z]+)\$[0-9]+"))),_xlfn.REGEXEXTRACT(CELL("address",D23), "\$([A-Z]+)\$[0-9]+"))} | E23: {=IFERROR(IF(OR('Raw Data'!E23="",LEN(TRIM('Raw Data'!E23))=0),"",IF(AND(ISNUMBER('Raw Data'!E23), IFERROR('Raw Data'!E23 = ROUND('Raw Data'!E23, 2),FALSE)),"",_xlfn.REGEXEXTRACT(CELL("address",E23), "\$([A-Z]+)\$[0-9]+"))),_xlfn.REGEXEXTRACT(CELL("address",E23), "\$([A-Z]+)\$[0-9]+"))} | F23: {=IFERROR(IF(OR('Raw Data'!F23="",LEN(TRIM('Raw Data'!F23))=0),"",IF(AND(ISNUMBER('Raw Data'!F23), IFERROR('Raw Data'!F23 = ROUND('Raw Data'!F23, 2),FALSE)),"",_xlfn.REGEXEXTRACT(CELL("address",F23), "\$([A-Z]+)\$[0-9]+"))),_xlfn.REGEXEXTRACT(CELL("address",F23), "\$([A-Z]+)\$[0-9]+"))} | G23: {=IFERROR(IF(OR('Raw Data'!G23="",LEN(TRIM('Raw Data'!G23))=0),"",IF(LEN('Raw Data'!G23)> 0,"",_xlfn.REGEXEXTRACT(CELL("address",'Raw Data'!G23),"\$([A-Z]+)\$[0-9]+"))),_xlfn.REGEXEXTRACT(CELL("address",'Raw Data'!G23),"\$([A-Z]+)\$[0-9]+"))}
... B251: {=IFERROR(IF(OR('Raw Data'!B251="",LEN(TRIM('Raw Data'!B251))=0),"",IF(AND(LEN('Raw Data'!B251) <= 20,LEN('Raw Data'!B251)> 0),"",_xlfn.REGEXEXTRACT(CELL("address",'Raw Data'!B251),"\$([A-Z]+)\$[0-9]+"))),_xlfn.REGEXEXTRACT(CELL("address",'Raw Data'!B251),"\$([A-Z]+)\$[0-9]+"))} | C251: {=IFERROR(IF(OR('Raw Data'!C251="",LEN(TRIM('Raw Data'!C251))=0),"",IF(AND(LEN('Raw Data'!C251) <= 255,LEN('Raw Data'!C251)> 0),"",_xlfn.REGEXEXTRACT(CELL("address",'Raw Data'!C251),"\$([A-Z]+)\$[0-9]+"))),_xlfn.REGEXEXTRACT(CELL("address",'Raw Data'!C251),"\$([A-Z]+)\$[0-9]+"))} | D251: {=IFERROR(IF(OR('Raw Data'!D251="",LEN(TRIM('Raw Data'!D251))=0),"",IF(AND(ISNUMBER('Raw Data'!D251), IFERROR('Raw Data'!D251 = ROUND('Raw Data'!D251, 2),FALSE)),"",_xlfn.REGEXEXTRACT(CELL("address",D251), "\$([A-Z]+)\$[0-9]+"))),_xlfn.REGEXEXTRACT(CELL("address",D251), "\$([A-Z]+)\$[0-9]+"))} | E251: {=IFERROR(IF(OR('Raw Data'!E251="",LEN(TRIM('Raw Data'!E251))=0),"",IF(AND(ISNUMBER('Raw Data'!E251), IFERROR('Raw Data'!E251 = ROUND('Raw Data'!E251, 2),FALSE)),"",_xlfn.REGEXEXTRACT(CELL("address",E251), "\$([A-Z]+)\$[0-9]+"))),_xlfn.REGEXEXTRACT(CELL("address",E251), "\$([A-Z]+)\$[0-9]+"))} | F251: {=IFERROR(IF(OR('Raw Data'!F251="",LEN(TRIM('Raw Data'!F251))=0),"",IF(AND(ISNUMBER('Raw Data'!F251), IFERROR('Raw Data'!F251 = ROUND('Raw Data'!F251, 2),FALSE)),"",_xlfn.REGEXEXTRACT(CELL("address",F251), "\$([A-Z]+)\$[0-9]+"))),_xlfn.REGEXEXTRACT(CELL("address",F251), "\$([A-Z]+)\$[0-9]+"))} | G251: {=IFERROR(IF(OR('Raw Data'!G251="",LEN(TRIM('Raw Data'!G251))=0),"",IF(LEN('Raw Data'!G251)> 0,"",_xlfn.REGEXEXTRACT(CELL("address",'Raw Data'!G251),"\$([A-Z]+)\$[0-9]+"))),_xlfn.REGEXEXTRACT(CELL("address",'Raw Data'!G251),"\$([A-Z]+)\$[0-9]+"))}

Sheet Validate_Condition
D10: Yes | E10: Yes
B11: C1 | C11: C2 | D11: C3 | E11: C4 | F11: C5 | G11: C6
D12: {=IF(OR('Raw Data'!D12="",LEN(TRIM('Raw Data'!D12))=0,Validate_Empty!D12<>"",Validate_Value!D12<>""),"",IF('Raw Data'!D12 = SUMIFS(Condition1!J:J,Condition1!B:B,TRIM('Raw Data'!B12),Condition1!C:C,TRIM('Raw Data'!C12)),"",_xlfn.REGEXEXTRACT(CELL("address",D12), "\$([A-Z]+)\$[0-9]+")))} | E12: {=IF(OR('Raw Data'!E12="",LEN(TRIM('Raw Data'!E12))=0,Validate_Empty!E12<>"",Validate_Value!E12<>""),"",IF('Raw Data'!E12 = SUMIFS(Condition2!K:K,Condition2!B:B,TRIM('Raw Data'!B12),Condition2!C:C,TRIM('Raw Data'!C12)),"",_xlfn.REGEXEXTRACT(CELL("address",E12), "\$([A-Z]+)\$[0-9]+")))}
D13: {=IF(OR('Raw Data'!D13="",LEN(TRIM('Raw Data'!D13))=0,Validate_Empty!D13<>"",Validate_Value!D13<>""),"",IF('Raw Data'!D13 = SUMIFS(Condition1!J:J,Condition1!B:B,TRIM('Raw Data'!B13),Condition1!C:C,TRIM('Raw Data'!C13)),"",_xlfn.REGEXEXTRACT(CELL("address",D13), "\$([A-Z]+)\$[0-9]+")))} | E13: {=IF(OR('Raw Data'!E13="",LEN(TRIM('Raw Data'!E13))=0,Validate_Empty!E13<>"",Validate_Value!E13<>""),"",IF('Raw Data'!E13 = SUMIFS(Condition2!K:K,Condition2!B:B,TRIM('Raw Data'!B13),Condition2!C:C,TRIM('Raw Data'!C13)),"",_xlfn.REGEXEXTRACT(CELL("address",E13), "\$([A-Z]+)\$[0-9]+")))}
D14: {=IF(OR('Raw Data'!D14="",LEN(TRIM('Raw Data'!D14))=0,Validate_Empty!D14<>"",Validate_Value!D14<>""),"",IF('Raw Data'!D14 = SUMIFS(Condition1!J:J,Condition1!B:B,TRIM('Raw Data'!B14),Condition1!C:C,TRIM('Raw Data'!C14)),"",_xlfn.REGEXEXTRACT(CELL("address",D14), "\$([A-Z]+)\$[0-9]+")))} | E14: {=IF(OR('Raw Data'!E14="",LEN(TRIM('Raw Data'!E14))=0,Validate_Empty!E14<>"",Validate_Value!E14<>""),"",IF('Raw Data'!E14 = SUMIFS(Condition2!K:K,Condition2!B:B,TRIM('Raw Data'!B14),Condition2!C:C,TRIM('Raw Data'!C14)),"",_xlfn.REGEXEXTRACT(CELL("address",E14), "\$([A-Z]+)\$[0-9]+")))}
D15: {=IF(OR('Raw Data'!D15="",LEN(TRIM('Raw Data'!D15))=0,Validate_Empty!D15<>"",Validate_Value!D15<>""),"",IF('Raw Data'!D15 = SUMIFS(Condition1!J:J,Condition1!B:B,TRIM('Raw Data'!B15),Condition1!C:C,TRIM('Raw Data'!C15)),"",_xlfn.REGEXEXTRACT(CELL("address",D15), "\$([A-Z]+)\$[0-9]+")))} | E15: {=IF(OR('Raw Data'!E15="",LEN(TRIM('Raw Data'!E15))=0,Validate_Empty!E15<>"",Validate_Value!E15<>""),"",IF('Raw Data'!E15 = SUMIFS(Condition2!K:K,Condition2!B:B,TRIM('Raw Data'!B15),Condition2!C:C,TRIM('Raw Data'!C15)),"",_xlfn.REGEXEXTRACT(CELL("address",E15), "\$([A-Z]+)\$[0-9]+")))}
D16: {=IF(OR('Raw Data'!D16="",LEN(TRIM('Raw Data'!D16))=0,Validate_Empty!D16<>"",Validate_Value!D16<>""),"",IF('Raw Data'!D16 = SUMIFS(Condition1!J:J,Condition1!B:B,TRIM('Raw Data'!B16),Condition1!C:C,TRIM('Raw Data'!C16)),"",_xlfn.REGEXEXTRACT(CELL("address",D16), "\$([A-Z]+)\$[0-9]+")))} | E16: {=IF(OR('Raw Data'!E16="",LEN(TRIM('Raw Data'!E16))=0,Validate_Empty!E16<>"",Validate_Value!E16<>""),"",IF('Raw Data'!E16 = SUMIFS(Condition2!K:K,Condition2!B:B,TRIM('Raw Data'!B16),Condition2!C:C,TRIM('Raw Data'!C16)),"",_xlfn.REGEXEXTRACT(CELL("address",E16), "\$([A-Z]+)\$[0-9]+")))}
D17: {=IF(OR('Raw Data'!D17="",LEN(TRIM('Raw Data'!D17))=0,Validate_Empty!D17<>"",Validate_Value!D17<>""),"",IF('Raw Data'!D17 = SUMIFS(Condition1!J:J,Condition1!B:B,TRIM('Raw Data'!B17),Condition1!C:C,TRIM('Raw Data'!C17)),"",_xlfn.REGEXEXTRACT(CELL("address",D17), "\$([A-Z]+)\$[0-9]+")))} | E17: {=IF(OR('Raw Data'!E17="",LEN(TRIM('Raw Data'!E17))=0,Validate_Empty!E17<>"",Validate_Value!E17<>""),"",IF('Raw Data'!E17 = SUMIFS(Condition2!K:K,Condition2!B:B,TRIM('Raw Data'!B17),Condition2!C:C,TRIM('Raw Data'!C17)),"",_xlfn.REGEXEXTRACT(CELL("address",E17), "\$([A-Z]+)\$[0-9]+")))}
D18: {=IF(OR('Raw Data'!D18="",LEN(TRIM('Raw Data'!D18))=0,Validate_Empty!D18<>"",Validate_Value!D18<>""),"",IF('Raw Data'!D18 = SUMIFS(Condition1!J:J,Condition1!B:B,TRIM('Raw Data'!B18),Condition1!C:C,TRIM('Raw Data'!C18)),"",_xlfn.REGEXEXTRACT(CELL("address",D18), "\$([A-Z]+)\$[0-9]+")))} | E18: {=IF(OR('Raw Data'!E18="",LEN(TRIM('Raw Data'!E18))=0,Validate_Empty!E18<>"",Validate_Value!E18<>""),"",IF('Raw Data'!E18 = SUMIFS(Condition2!K:K,Condition2!B:B,TRIM('Raw Data'!B18),Condition2!C:C,TRIM('Raw Data'!C18)),"",_xlfn.REGEXEXTRACT(CELL("address",E18), "\$([A-Z]+)\$[0-9]+")))}
D19: {=IF(OR('Raw Data'!D19="",LEN(TRIM('Raw Data'!D19))=0,Validate_Empty!D19<>"",Validate_Value!D19<>""),"",IF('Raw Data'!D19 = SUMIFS(Condition1!J:J,Condition1!B:B,TRIM('Raw Data'!B19),Condition1!C:C,TRIM('Raw Data'!C19)),"",_xlfn.REGEXEXTRACT(CELL("address",D19), "\$([A-Z]+)\$[0-9]+")))} | E19: {=IF(OR('Raw Data'!E19="",LEN(TRIM('Raw Data'!E19))=0,Validate_Empty!E19<>"",Validate_Value!E19<>""),"",IF('Raw Data'!E19 = SUMIFS(Condition2!K:K,Condition2!B:B,TRIM('Raw Data'!B19),Condition2!C:C,TRIM('Raw Data'!C19)),"",_xlfn.REGEXEXTRACT(CELL("address",E19), "\$([A-Z]+)\$[0-9]+")))}
D20: {=IF(OR('Raw Data'!D20="",LEN(TRIM('Raw Data'!D20))=0,Validate_Empty!D20<>"",Validate_Value!D20<>""),"",IF('Raw Data'!D20 = SUMIFS(Condition1!J:J,Condition1!B:B,TRIM('Raw Data'!B20),Condition1!C:C,TRIM('Raw Data'!C20)),"",_xlfn.REGEXEXTRACT(CELL("address",D20), "\$([A-Z]+)\$[0-9]+")))} | E20: {=IF(OR('Raw Data'!E20="",LEN(TRIM('Raw Data'!E20))=0,Validate_Empty!E20<>"",Validate_Value!E20<>""),"",IF('Raw Data'!E20 = SUMIFS(Condition2!K:K,Condition2!B:B,TRIM('Raw Data'!B20),Condition2!C:C,TRIM('Raw Data'!C20)),"",_xlfn.REGEXEXTRACT(CELL("address",E20), "\$([A-Z]+)\$[0-9]+")))}
D21: {=IF(OR('Raw Data'!D21="",LEN(TRIM('Raw Data'!D21))=0,Validate_Empty!D21<>"",Validate_Value!D21<>""),"",IF('Raw Data'!D21 = SUMIFS(Condition1!J:J,Condition1!B:B,TRIM('Raw Data'!B21),Condition1!C:C,TRIM('Raw Data'!C21)),"",_xlfn.REGEXEXTRACT(CELL("address",D21), "\$([A-Z]+)\$[0-9]+")))} | E21: {=IF(OR('Raw Data'!E21="",LEN(TRIM('Raw Data'!E21))=0,Validate_Empty!E21<>"",Validate_Value!E21<>""),"",IF('Raw Data'!E21 = SUMIFS(Condition2!K:K,Condition2!B:B,TRIM('Raw Data'!B21),Condition2!C:C,TRIM('Raw Data'!C21)),"",_xlfn.REGEXEXTRACT(CELL("address",E21), "\$([A-Z]+)\$[0-9]+")))}
D22: {=IF(OR('Raw Data'!D22="",LEN(TRIM('Raw Data'!D22))=0,Validate_Empty!D22<>"",Validate_Value!D22<>""),"",IF('Raw Data'!D22 = SUMIFS(Condition1!J:J,Condition1!B:B,TRIM('Raw Data'!B22),Condition1!C:C,TRIM('Raw Data'!C22)),"",_xlfn.REGEXEXTRACT(CELL("address",D22), "\$([A-Z]+)\$[0-9]+")))} | E22: {=IF(OR('Raw Data'!E22="",LEN(TRIM('Raw Data'!E22))=0,Validate_Empty!E22<>"",Validate_Value!E22<>""),"",IF('Raw Data'!E22 = SUMIFS(Condition2!K:K,Condition2!B:B,TRIM('Raw Data'!B22),Condition2!C:C,TRIM('Raw Data'!C22)),"",_xlfn.REGEXEXTRACT(CELL("address",E22), "\$([A-Z]+)\$[0-9]+")))}
D23: {=IF(OR('Raw Data'!D23="",LEN(TRIM('Raw Data'!D23))=0,Validate_Empty!D23<>"",Validate_Value!D23<>""),"",IF('Raw Data'!D23 = SUMIFS(Condition1!J:J,Condition1!B:B,TRIM('Raw Data'!B23),Condition1!C:C,TRIM('Raw Data'!C23)),"",_xlfn.REGEXEXTRACT(CELL("address",D23), "\$([A-Z]+)\$[0-9]+")))} | E23: {=IF(OR('Raw Data'!E23="",LEN(TRIM('Raw Data'!E23))=0,Validate_Empty!E23<>"",Validate_Value!E23<>""),"",IF('Raw Data'!E23 = SUMIFS(Condition2!K:K,Condition2!B:B,TRIM('Raw Data'!B23),Condition2!C:C,TRIM('Raw Data'!C23)),"",_xlfn.REGEXEXTRACT(CELL("address",E23), "\$([A-Z]+)\$[0-9]+")))}
... D100: {=IF(OR('Raw Data'!D100="",LEN(TRIM('Raw Data'!D100))=0,Validate_Empty!D100<>"",Validate_Value!D100<>""),"",IF('Raw Data'!D100 = SUMIFS(Condition1!J:J,Condition1!B:B,TRIM('Raw Data'!B100),Condition1!C:C,TRIM('Raw Data'!C100)),"",_xlfn.REGEXEXTRACT(CELL("address",D100), "\$([A-Z]+)\$[0-9]+")))} | E100: {=IF(OR('Raw Data'!E100="",LEN(TRIM('Raw Data'!E100))=0,Validate_Empty!E100<>"",Validate_Value!E100<>""),"",IF('Raw Data'!E100 = SUMIFS(Condition2!K:K,Condition2!B:B,TRIM('Raw Data'!B100),Condition2!C:C,TRIM('Raw Data'!C100)),"",_xlfn.REGEXEXTRACT(CELL("address",E100), "\$([A-Z]+)\$[0-9]+")))}

Sheet Condition1
B9: 11.3 EBAC & Current EAC
B10: C1 | C10: C2 | D10: C3 | E10: C4 | F10: C5 | G10: C6 | H10: C7 | I10: C8 | J10: C9
B11: QA001-Bidding | C11: Bidding Stage | D11: 703430 | E11: Insurance premium - Property (Project) | F11: Direct Cost | G11: Expense | H11: General Expense | J11: 0
B12: QA001-Bidding | C12: Bidding Stage | D12: 703852 | E12: Stamp Duty & BG | F12: Direct Cost | G12: Expense | H12: General Expense | J12: 0
B13: QA001-Bidding | C13: Bidding Stage | D13: 706700 | E13: Unit rate allocation (MH * Standard unit rate) provided by FA | F13: Indirect Cost | G13: TNS Labor | H13: TNS Labor Indirect | J13: 0
B14: QA001-Bidding | C14: Bidding Stage | D14: 706700-F/M&Below | E14: Unit rate allocation (Only Construction) | F14: Indirect Cost | G14: TNS Labor | H14: TNS Labor Direct | J14: 0
B15: QA001-Bidding | C15: Bidding Stage | D15: 706700-S/V&Above | E15: Unit rate allocation | F15: Indirect Cost | G15: TNS Labor | H15: TNS Labor Indirect | J15: 0
B16: QA001-Bidding | C16: Bidding Stage | D16: Allowance - Indirect | E16: Indirect Allowance | F16: Indirect Cost | G16: Allowance | H16: Allowance | J16: 0
B17: QA001-Bidding | C17: Bidding Stage | D17: Contingency - Direct | E17: Direct Contingency | F17: Direct Cost | G17: Contingency | H17: Contingency | J17: 0
B18: QA001-Bidding | C18: Bidding Stage | D18: Contingency - Indirect | E18: Indirect Contingency | F18: Indirect Cost | G18: Contingency | H18: Contingency | J18: 0
B19: QA001-Bidding | C19: Bidding Stage | D19: Cost Impact - Direct | E19: Direct Cost Impact | F19: Direct Cost | G19: Cost Impact | H19: Cost Impact | J19: 0
B20: QA001-Bidding | C20: Bidding Stage | D20: Cost Impact - Indirect | E20: Indirect Cost Impact | F20: Indirect Cost | G20: Cost Impact | H20: Cost Impact | J20: 0
B21: QA001-Bidding | C21: Bidding Stage | D21: Other - Indirect | E21: Indirect Other | F21: Indirect Cost | G21: Other | H21: Other | J21: 0
B22: QAC001 | C22: Construction | D22: 701000 | E22: Material Cost | F22: Direct Cost | G22: Materials | H22: Permanent Material | J22: 0
B23: QAC001 | C23: Construction | D23: 701008 | E23: Procurement contingency for Materials | F23: Direct Cost | G23: Materials | H23: Permanent Material | J23: 0
B24: QAC001 | C24: Construction | D24: 701009 | E24: Project Safety Equipment, Architectural per drawing | F24: Direct Cost | G24: Materials | H24: Permanent Material | J24: 0
B25: QAC001 | C25: Construction | D25: 701010 | E25: Seafastenning material, Skidding Support, Rigging P/F | F25: Direct Cost | G25: Materials | H25: Temporary Material | J25: 0
B26: QAC001 | C26: Construction | D26: 701011 | E26: Steel ( Not include NSC ) | F26: Direct Cost | G26: Materials | H26: Permanent Material | J26: 0
B27: QAC001 | C27: Construction | D27: 701012 | E27: Structure Procurement | F27: Direct Cost | G27: Materials | H27: Permanent Material | J27: 0
B28: QAC001 | C28: Construction | D28: 701013 | E28: Electrode for Structure | F28: Direct Cost | G28: Consumables | H28: Welding Electrode | J28: 0
B29: QAC001 | C29: Construction | D29: 701014 | E29: Painting material | F29: Direct Cost | G29: Consumables | H29: Painting Material | J29: 0
B30: QAC001 | C30: Construction | D30: 701015 | E30: Piping Procurement | F30: Direct Cost | G30: Materials | H30: Permanent Material | J30: 0
B31: QAC001 | C31: Construction | D31: 701016 | E31: Electrical Procurement | F31: Direct Cost | G31: Materials | H31: Permanent Material | J31: 0
B32: QAC001 | C32: Construction | D32: 701017 | E32: Packing Material & Pre rigging ( Tenchnical ) | F32: Direct Cost | G32: Consumables | H32: General Consumable | J32: 0
B33: QAC001 | C33: Construction | D33: 701018 | E33: Other Consumable for Structure | F33: Direct Cost | G33: Consumables | H33: General Consumable | J33: 0
... B75: QAC001 | C75: Construction | D75: 703016 | E75: Staff Insurance - Accident & Health | F75: Direct Cost | G75: Expense | H75: Staff Expense | J75: 0
B76: QAC001 | C76: Construction | D76: 703017 | E76: Apartment Rental & Service | F76: Direct Cost | G76: Expense | H76: Staff Expense | I76: X | J76: 235620
B77: QAC001 | C77: Construction | D77: 703018 | E77: Postage and Courier charges | F77: Direct Cost | G77: Expense | H77: Staff Expense | J77: 0
B78: QAC001 | C78: Construction | D78: 703019 | E78: Expenses - Others | F78: Direct Cost | G78: Expense | H78: Staff Expense | J78: 0
B79: QAC001 | C79: Construction | D79: 703210 | E79: Maintenance & Repairs - Building office | F79: Direct Cost | G79: Expense | H79: General Expense | J79: 0
B80: QAC001 | C80: Construction | D80: 703211 | E80: Maintenance Equipment | F80: Direct Cost | G80: Expense | H80: General Expense | J80: 0
B81: QAC001 | C81: Construction | D81: 703212 | E81: Maintenance Tool | F81: Direct Cost | G81: Expense | H81: General Expense | J81: 0
B82: QAC001 | C82: Construction | D82: 703213 | E82: Maintenance & Repairs - Car | F82: Direct Cost | G82: Expense | H82: General Expense | J82: 0
B83: QAC001 | C83: Construction | D83: 703214 | E83: Maintenance Yard Facility | F83: Direct Cost | G83: Expense | H83: General Expense | J83: 0
B84: QAC001 | C84: Construction | D84: 703215 | E84: Maintenance Blast Painting | F84: Direct Cost | G84: Expense | H84: General Expense | J84: 0
B85: QAC001 | C85: Construction | D85: 703216 | E85: Maintenance Yard Facility and Other Facility (Include Blast Painting and for all production yard facility) | F85: Direct Cost | G85: Expense | H85: General Expense | J85: 0
B86: QAC001 | C86: Construction | D86: 703217 | E86: Maintenance & Repairs - Computer & Software | F86: Direct Cost | G86: Expense | H86: General Expense | J86: 0
B87: QAC001 | C87: Construction | D87: 703219 | E87: Maintenance Others | F87: Direct Cost | G87: Expense | H87: General Expense | J87: 0
B88: QAC001 | C88: Construction | D88: 703220 | E88: WPQT WQT Production Test & SSCC Test | F88: Direct Cost | G88: Service Work & Supply | H88: For WPQT, WQT, Inspection & NDE3 | J88: 0
... B95: QAC001 | C95: Construction | D95: 703227 | E95: Manpower Supply for Structure Fitter & Other | F95: Direct Cost | G95: MPS Labor | H95: MPS Labor Direct | J95: 0
...

Sheet Condition2
B9: 11.4 Current EAC & VA
B10: C1 | C10: C2 | D10: C3 | E10: C4 | F10: C5 | G10: C6 | H10: C7 | I10: C8 | J10: C9 | K10: C10
B11: QA001-Bidding | C11: Bidding Stage | D11: 703430 | E11: Insurance premium - Property (Project) | F11: Direct Cost | G11: Expense | H11: General Expense | J11: 0 | K11: 0
B12: QA001-Bidding | C12: Bidding Stage | D12: 703852 | E12: Stamp Duty & BG | F12: Direct Cost | G12: Expense | H12: General Expense | J12: 0 | K12: 0
B13: QA001-Bidding | C13: Bidding Stage | D13: 706700 | E13: Unit rate allocation (MH * Standard unit rate) provided by FA | F13: Indirect Cost | G13: TNS Labor | H13: TNS Labor Indirect | J13: 0 | K13: 0
B14: QA001-Bidding | C14: Bidding Stage | D14: 706700-F/M&Below | E14: Unit rate allocation (Only Construction) | F14: Indirect Cost | G14: TNS Labor | H14: TNS Labor Direct | J14: 0 | K14: 0
B15: QA001-Bidding | C15: Bidding Stage | D15: 706700-S/V&Above | E15: Unit rate allocation | F15: Indirect Cost | G15: TNS Labor | H15: TNS Labor Indirect | J15: 0 | K15: 0
B16: QA001-Bidding | C16: Bidding Stage | D16: Allowance - Indirect | E16: Indirect Allowance | F16: Indirect Cost | G16: Allowance | H16: Allowance | J16: 0 | K16: 0
B17: QA001-Bidding | C17: Bidding Stage | D17: Contingency - Direct | E17: Direct Contingency | F17: Direct Cost | G17: Contingency | H17: Contingency | J17: 0 | K17: 0
B18: QA001-Bidding | C18: Bidding Stage | D18: Contingency - Indirect | E18: Indirect Contingency | F18: Indirect Cost | G18: Contingency | H18: Contingency | J18: 0 | K18: 0
B19: QA001-Bidding | C19: Bidding Stage | D19: Cost Impact - Direct | E19: Direct Cost Impact | F19: Direct Cost | G19: Cost Impact | H19: Cost Impact | J19: 0 | K19: 0
B20: QA001-Bidding | C20: Bidding Stage | D20: Cost Impact - Indirect | E20: Indirect Cost Impact | F20: Indirect Cost | G20: Cost Impact | H20: Cost Impact | J20: 0 | K20: 0
B21: QA001-Bidding | C21: Bidding Stage | D21: Other - Indirect | E21: Indirect Other | F21: Indirect Cost | G21: Other | H21: Other | J21: 0 | K21: 0
B22: QAC001 | C22: Construction | D22: 701000 | E22: Material Cost | F22: Direct Cost | G22: Materials | H22: Permanent Material | J22: 0 | K22: 0
B23: QAC001 | C23: Construction | D23: 701008 | E23: Procurement contingency for Materials | F23: Direct Cost | G23: Materials | H23: Permanent Material | J23: 0 | K23: 0
B24: QAC001 | C24: Construction | D24: 701009 | E24: Project Safety Equipment, Architectural per drawing | F24: Direct Cost | G24: Materials | H24: Permanent Material | J24: 0 | K24: 0
B25: QAC001 | C25: Construction | D25: 701010 | E25: Seafastenning material, Skidding Support, Rigging P/F | F25: Direct Cost | G25: Materials | H25: Temporary Material | J25: 0 | K25: 0
B26: QAC001 | C26: Construction | D26: 701011 | E26: Steel ( Not include NSC ) | F26: Direct Cost | G26: Materials | H26: Permanent Material | J26: 0 | K26: 0
B27: QAC001 | C27: Construction | D27: 701012 | E27: Structure Procurement | F27: Direct Cost | G27: Materials | H27: Permanent Material | J27: 0 | K27: 0
B28: QAC001 | C28: Construction | D28: 701013 | E28: Electrode for Structure | F28: Direct Cost | G28: Consumables | H28: Welding Electrode | J28: 0 | K28: 0
B29: QAC001 | C29: Construction | D29: 701014 | E29: Painting material | F29: Direct Cost | G29: Consumables | H29: Painting Material | J29: 0 | K29: 0
B30: QAC001 | C30: Construction | D30: 701015 | E30: Piping Procurement | F30: Direct Cost | G30: Materials | H30: Permanent Material | J30: 0 | K30: 0
B31: QAC001 | C31: Construction | D31: 701016 | E31: Electrical Procurement | F31: Direct Cost | G31: Materials | H31: Permanent Material | J31: 0 | K31: 0
B32: QAC001 | C32: Construction | D32: 701017 | E32: Packing Material & Pre rigging ( Tenchnical ) | F32: Direct Cost | G32: Consumables | H32: General Consumable | J32: 0 | K32: 0
B33: QAC001 | C33: Construction | D33: 701018 | E33: Other Consumable for Structure | F33: Direct Cost | G33: Consumables | H33: General Consumable | J33: 0 | K33: 0
... B75: QAC001 | C75: Construction | D75: 703016 | E75: Staff Insurance - Accident & Health | F75: Direct Cost | G75: Expense | H75: Staff Expense | J75: 0 | K75: 0
B76: QAC001 | C76: Construction | D76: 703017 | E76: Apartment Rental & Service | F76: Direct Cost | G76: Expense | H76: Staff Expense | I76: X | J76: 235620 | K76: 235620
B77: QAC001 | C77: Construction | D77: 703018 | E77: Postage and Courier charges | F77: Direct Cost | G77: Expense | H77: Staff Expense | J77: 0 | K77: 0
B78: QAC001 | C78: Construction | D78: 703019 | E78: Expenses - Others | F78: Direct Cost | G78: Expense | H78: Staff Expense | J78: 0 | K78: 0
B79: QAC001 | C79: Construction | D79: 703210 | E79: Maintenance & Repairs - Building office | F79: Direct Cost | G79: Expense | H79: General Expense | J79: 0 | K79: 0
B80: QAC001 | C80: Construction | D80: 703211 | E80: Maintenance Equipment | F80: Direct Cost | G80: Expense | H80: General Expense | J80: 0 | K80: 0
B81: QAC001 | C81: Construction | D81: 703212 | E81: Maintenance Tool | F81: Direct Cost | G81: Expense | H81: General Expense | J81: 0 | K81: 0
B82: QAC001 | C82: Construction | D82: 703213 | E82: Maintenance & Repairs - Car | F82: Direct Cost | G82: Expense | H82: General Expense | J82: 0 | K82: 0
B83: QAC001 | C83: Construction | D83: 703214 | E83: Maintenance Yard Facility | F83: Direct Cost | G83: Expense | H83: General Expense | J83: 0 | K83: 0
B84: QAC001 | C84: Construction | D84: 703215 | E84: Maintenance Blast Painting | F84: Direct Cost | G84: Expense | H84: General Expense | J84: 0 | K84: 0
B85: QAC001 | C85: Construction | D85: 703216 | E85: Maintenance Yard Facility and Other Facility (Include Blast Painting and for all production yard facility) | F85: Direct Cost | G85: Expense | H85: General Expense | J85: 0 | K85: 0
B86: QAC001 | C86: Construction | D86: 703217 | E86: Maintenance & Repairs - Computer & Software | F86: Direct Cost | G86: Expense | H86: General Expense | J86: 0 | K86: 0
B87: QAC001 | C87: Construction | D87: 703219 | E87: Maintenance Others | F87: Direct Cost | G87: Expense | H87: General Expense | J87: 0 | K87: 0
B88: QAC001 | C88: Construction | D88: 703220 | E88: WPQT WQT Production Test & SSCC Test | F88: Direct Cost | G88: Service Work & Supply | H88: For WPQT, WQT, Inspection & NDE3 | J88: 0 | K88: 0
... B95: QAC001 | C95: Construction | D95: 703227 | E95: Manpower Supply for Structure Fitter & Other | F95: Direct Cost | G95: MPS Labor | H95: MPS Labor Direct | J95: 0 | K95: 0
...

Sheet Configuration
A1: col_number | B1: range_start | C1: range_stop | D1: project_active_start | E1: project_inactive_end | F1: relate_document | G1: relate_range_start_11.3 | H1: relate_range_stop_11.3 | I1: relate_range_start_11.4 | J1: relate_range_stop_11.4
A2: 2 | B2: B12 | C2: G? | D2: 45292 | E2: 46388 | F2: 11. Budget & Variance Analysis | G2: B11 | H2: J? | I2: B11 | J2: K?
F3: 11.3 EBAC & Current EAC-Edited
F4: 11.4 LasCurrent EAC-Edtied

Sheet Validate_Type
B1: C1 | C1: C2 | D1: C3 | E1: C4 | F1: C5 | G1: C6 | H1: C7 | I1: C8
B2: {=IF('Raw Data'!B2="",_xlfn.REGEXEXTRACT(CELL("address",'Raw Data'!B2),"\$([A-Z]+)\$[0-9]+"),"")} -> $B$2 | C2: {=IF('Raw Data'!C2="",_xlfn.REGEXEXTRACT(CELL("address",'Raw Data'!C2),"\$([A-Z]+)\$[0-9]+"),"")} -> $C$2 | D2: {=IF('Raw Data'!D2="",_xlfn.REGEXEXTRACT(CELL("address",'Raw Data'!D2),"\$([A-Z]+)\$[0-9]+"),"")} -> $D$2 | E2: {=IF('Raw Data'!E2="",_xlfn.REGEXEXTRACT(CELL("address",'Raw Data'!E2),"\$([A-Z]+)\$[0-9]+"),"")} -> $E$2 | F2: {=IF('Raw Data'!F2="",_xlfn.REGEXEXTRACT(CELL("address",'Raw Data'!F2),"\$([A-Z]+)\$[0-9]+"),"")} -> $F$2 | G2: {=IF('Raw Data'!#REF!="",_xlfn.REGEXEXTRACT(CELL("address",'Raw Data'!#REF!),"\$([A-Z]+)\$[0-9]+"),"")} -> #REF! | H2: {=IF('Raw Data'!G2="",_xlfn.REGEXEXTRACT(CELL("address",'Raw Data'!G2),"\$([A-Z]+)\$[0-9]+"),"")} -> $G$2 | I2: {=IF('Raw Data'!#REF!="",_xlfn.REGEXEXTRACT(CELL("address",'Raw Data'!#REF!),"\$([A-Z]+)\$[0-9]+"),"")} -> #REF!
B3: {=IF('Raw Data'!B3="",_xlfn.REGEXEXTRACT(CELL("address",'Raw Data'!B3),"\$([A-Z]+)\$[0-9]+"),"")} -> $B$3 | C3: {=IF('Raw Data'!C3="",_xlfn.REGEXEXTRACT(CELL("address",'Raw Data'!C3),"\$([A-Z]+)\$[0-9]+"),"")} -> $C$3 | D3: {=IF('Raw Data'!D3="",_xlfn.REGEXEXTRACT(CELL("address",'Raw Data'!D3),"\$([A-Z]+)\$[0-9]+"),"")} -> $D$3 | E3: {=IF('Raw Data'!E3="",_xlfn.REGEXEXTRACT(CELL("address",'Raw Data'!E3),"\$([A-Z]+)\$[0-9]+"),"")} -> $E$3 | F3: {=IF('Raw Data'!F3="",_xlfn.REGEXEXTRACT(CELL("address",'Raw Data'!F3),"\$([A-Z]+)\$[0-9]+"),"")} -> $F$3 | G3: {=IF('Raw Data'!#REF!="",_xlfn.REGEXEXTRACT(CELL("address",'Raw Data'!#REF!),"\$([A-Z]+)\$[0-9]+"),"")} -> #REF! | H3: {=IF('Raw Data'!G3="",_xlfn.REGEXEXTRACT(CELL("address",'Raw Data'!G3),"\$([A-Z]+)\$[0-9]+"),"")} -> $G$3 | I3: {=IF('Raw Data'!#REF!="",_xlfn.REGEXEXTRACT(CELL("address",'Raw Data'!#REF!),"\$([A-Z]+)\$[0-9]+"),"")} -> #REF!
B4: {=IF('Raw Data'!B4="",_xlfn.REGEXEXTRACT(CELL("address",'Raw Data'!B4),"\$([A-Z]+)\$[0-9]+"),"")} -> $B$4 | C4: {=IF('Raw Data'!C4="",_xlfn.REGEXEXTRACT(CELL("address",'Raw Data'!C4),"\$([A-Z]+)\$[0-9]+"),"")} -> $C$4 | D4: {=IF('Raw Data'!D4="",_xlfn.REGEXEXTRACT(CELL("address",'Raw Data'!D4),"\$([A-Z]+)\$[0-9]+"),"")} -> $D$4 | E4: {=IF('Raw Data'!E4="",_xlfn.REGEXEXTRACT(CELL("address",'Raw Data'!E4),"\$([A-Z]+)\$[0-9]+"),"")} -> $E$4 | F4: {=IF('Raw Data'!F4="",_xlfn.REGEXEXTRACT(CELL("address",'Raw Data'!F4),"\$([A-Z]+)\$[0-9]+"),"")} -> $F$4 | G4: {=IF('Raw Data'!#REF!="",_xlfn.REGEXEXTRACT(CELL("address",'Raw Data'!#REF!),"\$([A-Z]+)\$[0-9]+"),"")} -> #REF! | H4: {=IF('Raw Data'!G4="",_xlfn.REGEXEXTRACT(CELL("address",'Raw Data'!G4),"\$([A-Z]+)\$[0-9]+"),"")} -> $G$4 | I4: {=IF('Raw Data'!#REF!="",_xlfn.REGEXEXTRACT(CELL("address",'Raw Data'!#REF!),"\$([A-Z]+)\$[0-9]+"),"")} -> #REF!
B5: {=IF('Raw Data'!B5="",_xlfn.REGEXEXTRACT(CELL("address",'Raw Data'!B5),"\$([A-Z]+)\$[0-9]+"),"")} -> $B$5 | C5: {=IF('Raw Data'!C5="",_xlfn.REGEXEXTRACT(CELL("address",'Raw Data'!C5),"\$([A-Z]+)\$[0-9]+"),"")} -> $C$5 | D5: {=IF('Raw Data'!D5="",_xlfn.REGEXEXTRACT(CELL("address",'Raw Data'!D5),"\$([A-Z]+)\$[0-9]+"),"")} -> $D$5 | E5: {=IF('Raw Data'!E5="",_xlfn.REGEXEXTRACT(CELL("address",'Raw Data'!E5),"\$([A-Z]+)\$[0-9]+"),"")} -> $E$5 | F5: {=IF('Raw Data'!F5="",_xlfn.REGEXEXTRACT(CELL("address",'Raw Data'!F5),"\$([A-Z]+)\$[0-9]+"),"")} -> $F$5 | G5: {=IF('Raw Data'!#REF!="",_xlfn.REGEXEXTRACT(CELL("address",'Raw Data'!#REF!),"\$([A-Z]+)\$[0-9]+"),"")} -> #REF! | H5: {=IF('Raw Data'!G5="",_xlfn.REGEXEXTRACT(CELL("address",'Raw Data'!G5),"\$([A-Z]+)\$[0-9]+"),"")} -> $G$5 | I5: {=IF('Raw Data'!#REF!="",_xlfn.REGEXEXTRACT(CELL("address",'Raw Data'!#REF!),"\$([A-Z]+)\$[0-9]+"),"")} -> #REF!
B6: {=IF('Raw Data'!B6="",_xlfn.REGEXEXTRACT(CELL("address",'Raw Data'!B6),"\$([A-Z]+)\$[0-9]+"),"")} -> $B$6 | C6: {=IF('Raw Data'!C6="",_xlfn.REGEXEXTRACT(CELL("address",'Raw Data'!C6),"\$([A-Z]+)\$[0-9]+"),"")} -> $C$6 | D6: {=IF('Raw Data'!D6="",_xlfn.REGEXEXTRACT(CELL("address",'Raw Data'!D6),"\$([A-Z]+)\$[0-9]+"),"")} -> $D$6 | E6: {=IF('Raw Data'!E6="",_xlfn.REGEXEXTRACT(CELL("address",'Raw Data'!E6),"\$([A-Z]+)\$[0-9]+"),"")} -> $E$6 | F6: {=IF('Raw Data'!F6="",_xlfn.REGEXEXTRACT(CELL("address",'Raw Data'!F6),"\$([A-Z]+)\$[0-9]+"),"")} -> $F$6 | G6: {=IF('Raw Data'!#REF!="",_xlfn.REGEXEXTRACT(CELL("address",'Raw Data'!#REF!),"\$([A-Z]+)\$[0-9]+"),"")} -> #REF! | H6: {=IF('Raw Data'!G6="",_xlfn.REGEXEXTRACT(CELL("address",'Raw Data'!G6),"\$([A-Z]+)\$[0-9]+"),"")} -> $G$6 | I6: {=IF('Raw Data'!#REF!="",_xlfn.REGEXEXTRACT(CELL("address",'Raw Data'!#REF!),"\$([A-Z]+)\$[0-9]+"),"")} -> #REF!
B7: {=IF('Raw Data'!B10="",_xlfn.REGEXEXTRACT(CELL("address",'Raw Data'!B10),"\$([A-Z]+)\$[0-9]+"),"")} -> $B$10 | C7: {=IF('Raw Data'!C10="",_xlfn.REGEXEXTRACT(CELL("address",'Raw Data'!C10),"\$([A-Z]+)\$[0-9]+"),"")} -> $C$10 | D7: {=IF('Raw Data'!D10="",_xlfn.REGEXEXTRACT(CELL("address",'Raw Data'!D10),"\$([A-Z]+)\$[0-9]+"),"")} -> $D$10 | E7: {=IF('Raw Data'!E10="",_xlfn.REGEXEXTRACT(CELL("address",'Raw Data'!E10),"\$([A-Z]+)\$[0-9]+"),"")} -> $E$10 | F7: {=IF('Raw Data'!F10="",_xlfn.REGEXEXTRACT(CELL("address",'Raw Data'!F10),"\$([A-Z]+)\$[0-9]+"),"")} -> $F$10 | G7: {=IF('Raw Data'!#REF!="",_xlfn.REGEXEXTRACT(CELL("address",'Raw Data'!#REF!),"\$([A-Z]+)\$[0-9]+"),"")} -> #REF! | H7: {=IF('Raw Data'!G10="",_xlfn.REGEXEXTRACT(CELL("address",'Raw Data'!G10),"\$([A-Z]+)\$[0-9]+"),"")} -> $G$10 | I7: {=IF('Raw Data'!#REF!="",_xlfn.REGEXEXTRACT(CELL("address",'Raw Data'!#REF!),"\$([A-Z]+)\$[0-9]+"),"")} -> #REF!
B8: {=IF('Raw Data'!#REF!="",_xlfn.REGEXEXTRACT(CELL("address",'Raw Data'!#REF!),"\$([A-Z]+)\$[0-9]+"),"")} -> #REF! | C8: {=IF('Raw Data'!#REF!="",_xlfn.REGEXEXTRACT(CELL("address",'Raw Data'!#REF!),"\$([A-Z]+)\$[0-9]+"),"")} -> #REF! | D8: {=IF('Raw Data'!#REF!="",_xlfn.REGEXEXTRACT(CELL("address",'Raw Data'!#REF!),"\$([A-Z]+)\$[0-9]+"),"")} -> #REF! | E8: {=IF('Raw Data'!#REF!="",_xlfn.REGEXEXTRACT(CELL("address",'Raw Data'!#REF!),"\$([A-Z]+)\$[0-9]+"),"")} -> #REF! | F8: {=IF('Raw Data'!#REF!="",_xlfn.REGEXEXTRACT(CELL("address",'Raw Data'!#REF!),"\$([A-Z]+)\$[0-9]+"),"")} -> #REF! | G8: {=IF('Raw Data'!#REF!="",_xlfn.REGEXEXTRACT(CELL("address",'Raw Data'!#REF!),"\$([A-Z]+)\$[0-9]+"),"")} -> #REF! | H8: {=IF('Raw Data'!#REF!="",_xlfn.REGEXEXTRACT(CELL("address",'Raw Data'!#REF!),"\$([A-Z]+)\$[0-9]+"),"")} -> #REF! | I8: {=IF('Raw Data'!#REF!="",_xlfn.REGEXEXTRACT(CELL("address",'Raw Data'!#REF!),"\$([A-Z]+)\$[0-9]+"),"")} -> #REF!
B9: {=IF('Raw Data'!#REF!="",_xlfn.REGEXEXTRACT(CELL("address",'Raw Data'!#REF!),"\$([A-Z]+)\$[0-9]+"),"")} -> #REF! | C9: {=IF('Raw Data'!#REF!="",_xlfn.REGEXEXTRACT(CELL("address",'Raw Data'!#REF!),"\$([A-Z]+)\$[0-9]+"),"")} -> #REF! | D9: {=IF('Raw Data'!#REF!="",_xlfn.REGEXEXTRACT(CELL("address",'Raw Data'!#REF!),"\$([A-Z]+)\$[0-9]+"),"")} -> #REF! | E9: {=IF('Raw Data'!#REF!="",_xlfn.REGEXEXTRACT(CELL("address",'Raw Data'!#REF!),"\$([A-Z]+)\$[0-9]+"),"")} -> #REF! | F9: {=IF('Raw Data'!#REF!="",_xlfn.REGEXEXTRACT(CELL("address",'Raw Data'!#REF!),"\$([A-Z]+)\$[0-9]+"),"")} -> #REF! | G9: {=IF('Raw Data'!#REF!="",_xlfn.REGEXEXTRACT(CELL("address",'Raw Data'!#REF!),"\$([A-Z]+)\$[0-9]+"),"")} -> #REF! | H9: {=IF('Raw Data'!G11="",_xlfn.REGEXEXTRACT(CELL("address",'Raw Data'!G11),"\$([A-Z]+)\$[0-9]+"),"")} | I9: {=IF('Raw Data'!#REF!="",_xlfn.REGEXEXTRACT(CELL("address",'Raw Data'!#REF!),"\$([A-Z]+)\$[0-9]+"),"")} -> #REF!
B10: {=IF('Raw Data'!B12="",_xlfn.REGEXEXTRACT(CELL("address",'Raw Data'!B12),"\$([A-Z]+)\$[0-9]+"),"")} | C10: {=IF('Raw Data'!C12="",_xlfn.REGEXEXTRACT(CELL("address",'Raw Data'!C12),"\$([A-Z]+)\$[0-9]+"),"")} | D10: {=IF('Raw Data'!D12="",_xlfn.REGEXEXTRACT(CELL("address",'Raw Data'!D12),"\$([A-Z]+)\$[0-9]+"),"")} | E10: {=IF('Raw Data'!E12="",_xlfn.REGEXEXTRACT(CELL("address",'Raw Data'!E12),"\$([A-Z]+)\$[0-9]+"),"")} | F10: {=IF('Raw Data'!F12="",_xlfn.REGEXEXTRACT(CELL("address",'Raw Data'!F12),"\$([A-Z]+)\$[0-9]+"),"")} | G10: {=IF('Raw Data'!#REF!="",_xlfn.REGEXEXTRACT(CELL("address",'Raw Data'!#REF!),"\$([A-Z]+)\$[0-9]+"),"")} -> #REF! | H10: {=IF('Raw Data'!G12="",_xlfn.REGEXEXTRACT(CELL("address",'Raw Data'!G12),"\$([A-Z]+)\$[0-9]+"),"")} -> $G$12 | I10: {=IF('Raw Data'!#REF!="",_xlfn.REGEXEXTRACT(CELL("address",'Raw Data'!#REF!),"\$([A-Z]+)\$[0-9]+"),"")} -> #REF!
B11: {=IF('Raw Data'!B13="",_xlfn.REGEXEXTRACT(CELL("address",'Raw Data'!B13),"\$([A-Z]+)\$[0-9]+"),"")} | C11: {=IF('Raw Data'!C13="",_xlfn.REGEXEXTRACT(CELL("address",'Raw Data'!C13),"\$([A-Z]+)\$[0-9]+"),"")} | D11: {=IF('Raw Data'!D13="",_xlfn.REGEXEXTRACT(CELL("address",'Raw Data'!D13),"\$([A-Z]+)\$[0-9]+"),"")} | E11: {=IF('Raw Data'!E13="",_xlfn.REGEXEXTRACT(CELL("address",'Raw Data'!E13),"\$([A-Z]+)\$[0-9]+"),"")} | F11: {=IF('Raw Data'!F13="",_xlfn.REGEXEXTRACT(CELL("address",'Raw Data'!F13),"\$([A-Z]+)\$[0-9]+"),"")} | G11: {=IF('Raw Data'!#REF!="",_xlfn.REGEXEXTRACT(CELL("address",'Raw Data'!#REF!),"\$([A-Z]+)\$[0-9]+"),"")} -> #REF! | H11: {=IF('Raw Data'!G13="",_xlfn.REGEXEXTRACT(CELL("address",'Raw Data'!G13),"\$([A-Z]+)\$[0-9]+"),"")} -> $G$13 | I11: {=IF('Raw Data'!#REF!="",_xlfn.REGEXEXTRACT(CELL("address",'Raw Data'!#REF!),"\$([A-Z]+)\$[0-9]+"),"")} -> #REF!
B12: {=IF('Raw Data'!B14="",_xlfn.REGEXEXTRACT(CELL("address",'Raw Data'!B14),"\$([A-Z]+)\$[0-9]+"),"")} | C12: {=IF('Raw Data'!C14="",_xlfn.REGEXEXTRACT(CELL("address",'Raw Data'!C14),"\$([A-Z]+)\$[0-9]+"),"")} | D12: {=IF('Raw Data'!D14="",_xlfn.REGEXEXTRACT(CELL("address",'Raw Data'!D14),"\$([A-Z]+)\$[0-9]+"),"")} | E12: {=IF('Raw Data'!E14="",_xlfn.REGEXEXTRACT(CELL("address",'Raw Data'!E14),"\$([A-Z]+)\$[0-9]+"),"")} | F12: {=IF('Raw Data'!F14="",_xlfn.REGEXEXTRACT(CELL("address",'Raw Data'!F14),"\$([A-Z]+)\$[0-9]+"),"")} | G12: {=IF('Raw Data'!#REF!="",_xlfn.REGEXEXTRACT(CELL("address",'Raw Data'!#REF!),"\$([A-Z]+)\$[0-9]+"),"")} -> #REF! | H12: {=IF('Raw Data'!G14="",_xlfn.REGEXEXTRACT(CELL("address",'Raw Data'!G14),"\$([A-Z]+)\$[0-9]+"),"")} -> $G$14 | I12: {=IF('Raw Data'!#REF!="",_xlfn.REGEXEXTRACT(CELL("address",'Raw Data'!#REF!),"\$([A-Z]+)\$[0-9]+"),"")} -> #REF!
B13: {=IF('Raw Data'!B15="",_xlfn.REGEXEXTRACT(CELL("address",'Raw Data'!B15),"\$([A-Z]+)\$[0-9]+"),"")} | C13: {=IF('Raw Data'!C15="",_xlfn.REGEXEXTRACT(CELL("address",'Raw Data'!C15),"\$([A-Z]+)\$[0-9]+"),"")} | D13: {=IF('Raw Data'!D15="",_xlfn.REGEXEXTRACT(CELL("address",'Raw Data'!D15),"\$([A-Z]+)\$[0-9]+"),"")} | E13: {=IF('Raw Data'!E15="",_xlfn.REGEXEXTRACT(CELL("address",'Raw Data'!E15),"\$([A-Z]+)\$[0-9]+"),"")} | F13: {=IF('Raw Data'!F15="",_xlfn.REGEXEXTRACT(CELL("address",'Raw Data'!F15),"\$([A-Z]+)\$[0-9]+"),"")} | G13: {=IF('Raw Data'!#REF!="",_xlfn.REGEXEXTRACT(CELL("address",'Raw Data'!#REF!),"\$([A-Z]+)\$[0-9]+"),"")} -> #REF! | H13: {=IF('Raw Data'!G15="",_xlfn.REGEXEXTRACT(CELL("address",'Raw Data'!G15),"\$([A-Z]+)\$[0-9]+"),"")} -> $G$15 | I13: {=IF('Raw Data'!#REF!="",_xlfn.REGEXEXTRACT(CELL("address",'Raw Data'!#REF!),"\$([A-Z]+)\$[0-9]+"),"")} -> #REF!
B14: {=IF('Raw Data'!B16="",_xlfn.REGEXEXTRACT(CELL("address",'Raw Data'!B16),"\$([A-Z]+)\$[0-9]+"),"")} | C14: {=IF('Raw Data'!C16="",_xlfn.REGEXEXTRACT(CELL("address",'Raw Data'!C16),"\$([A-Z]+)\$[0-9]+"),"")} | D14: {=IF('Raw Data'!D16="",_xlfn.REGEXEXTRACT(CELL("address",'Raw Data'!D16),"\$([A-Z]+)\$[0-9]+"),"")} | E14: {=IF('Raw Data'!E16="",_xlfn.REGEXEXTRACT(CELL("address",'Raw Data'!E16),"\$([A-Z]+)\$[0-9]+"),"")} | F14: {=IF('Raw Data'!F16="",_xlfn.REGEXEXTRACT(CELL("address",'Raw Data'!F16),"\$([A-Z]+)\$[0-9]+"),"")} | G14: {=IF('Raw Data'!#REF!="",_xlfn.REGEXEXTRACT(CELL("address",'Raw Data'!#REF!),"\$([A-Z]+)\$[0-9]+"),"")} -> #REF! | H14: {=IF('Raw Data'!G16="",_xlfn.REGEXEXTRACT(CELL("address",'Raw Data'!G16),"\$([A-Z]+)\$[0-9]+"),"")} -> $G$16 | I14: {=IF('Raw Data'!#REF!="",_xlfn.REGEXEXTRACT(CELL("address",'Raw Data'!#REF!),"\$([A-Z]+)\$[0-9]+"),"")} -> #REF!
B15: {=IF('Raw Data'!B17="",_xlfn.REGEXEXTRACT(CELL("address",'Raw Data'!B17),"\$([A-Z]+)\$[0-9]+"),"")} | C15: {=IF('Raw Data'!C17="",_xlfn.REGEXEXTRACT(CELL("address",'Raw Data'!C17),"\$([A-Z]+)\$[0-9]+"),"")} | D15: {=IF('Raw Data'!D17="",_xlfn.REGEXEXTRACT(CELL("address",'Raw Data'!D17),"\$([A-Z]+)\$[0-9]+"),"")} | E15: {=IF('Raw Data'!E17="",_xlfn.REGEXEXTRACT(CELL("address",'Raw Data'!E17),"\$([A-Z]+)\$[0-9]+"),"")} | F15: {=IF('Raw Data'!F17="",_xlfn.REGEXEXTRACT(CELL("address",'Raw Data'!F17),"\$([A-Z]+)\$[0-9]+"),"")} | G15: {=IF('Raw Data'!#REF!="",_xlfn.REGEXEXTRACT(CELL("address",'Raw Data'!#REF!),"\$([A-Z]+)\$[0-9]+"),"")} -> #REF! | H15: {=IF('Raw Data'!G17="",_xlfn.REGEXEXTRACT(CELL("address",'Raw Data'!G17),"\$([A-Z]+)\$[0-9]+"),"")} -> $G$17 | I15: {=IF('Raw Data'!#REF!="",_xlfn.REGEXEXTRACT(CELL("address",'Raw Data'!#REF!),"\$([A-Z]+)\$[0-9]+"),"")} -> #REF!
B16: {=IF('Raw Data'!B18="",_xlfn.REGEXEXTRACT(CELL("address",'Raw Data'!B18),"\$([A-Z]+)\$[0-9]+"),"")} | C16: {=IF('Raw Data'!C18="",_xlfn.REGEXEXTRACT(CELL("address",'Raw Data'!C18),"\$([A-Z]+)\$[0-9]+"),"")} | D16: {=IF('Raw Data'!D18="",_xlfn.REGEXEXTRACT(CELL("address",'Raw Data'!D18),"\$([A-Z]+)\$[0-9]+"),"")} | E16: {=IF('Raw Data'!E18="",_xlfn.REGEXEXTRACT(CELL("address",'Raw Data'!E18),"\$([A-Z]+)\$[0-9]+"),"")} | F16: {=IF('Raw Data'!F18="",_xlfn.REGEXEXTRACT(CELL("address",'Raw Data'!F18),"\$([A-Z]+)\$[0-9]+"),"")} | G16: {=IF('Raw Data'!#REF!="",_xlfn.REGEXEXTRACT(CELL("address",'Raw Data'!#REF!),"\$([A-Z]+)\$[0-9]+"),"")} -> #REF! | H16: {=IF('Raw Data'!G18="",_xlfn.REGEXEXTRACT(CELL("address",'Raw Data'!G18),"\$([A-Z]+)\$[0-9]+"),"")} -> $G$18 | I16: {=IF('Raw Data'!#REF!="",_xlfn.REGEXEXTRACT(CELL("address",'Raw Data'!#REF!),"\$([A-Z]+)\$[0-9]+"),"")} -> #REF!
B17: {=IF('Raw Data'!B19="",_xlfn.REGEXEXTRACT(CELL("address",'Raw Data'!B19),"\$([A-Z]+)\$[0-9]+"),"")} | C17: {=IF('Raw Data'!C19="",_xlfn.REGEXEXTRACT(CELL("address",'Raw Data'!C19),"\$([A-Z]+)\$[0-9]+"),"")} | D17: {=IF('Raw Data'!D19="",_xlfn.REGEXEXTRACT(CELL("address",'Raw Data'!D19),"\$([A-Z]+)\$[0-9]+"),"")} | E17: {=IF('Raw Data'!E19="",_xlfn.REGEXEXTRACT(CELL("address",'Raw Data'!E19),"\$([A-Z]+)\$[0-9]+"),"")} | F17: {=IF('Raw Data'!F19="",_xlfn.REGEXEXTRACT(CELL("address",'Raw Data'!F19),"\$([A-Z]+)\$[0-9]+"),"")} | G17: {=IF('Raw Data'!#REF!="",_xlfn.REGEXEXTRACT(CELL("address",'Raw Data'!#REF!),"\$([A-Z]+)\$[0-9]+"),"")} -> #REF! | H17: {=IF('Raw Data'!G19="",_xlfn.REGEXEXTRACT(CELL("address",'Raw Data'!G19),"\$([A-Z]+)\$[0-9]+"),"")} -> $G$19 | I17: {=IF('Raw Data'!#REF!="",_xlfn.REGEXEXTRACT(CELL("address",'Raw Data'!#REF!),"\$([A-Z]+)\$[0-9]+"),"")} -> #REF!
B18: {=IF('Raw Data'!B20="",_xlfn.REGEXEXTRACT(CELL("address",'Raw Data'!B20),"\$([A-Z]+)\$[0-9]+"),"")} | C18: {=IF('Raw Data'!C20="",_xlfn.REGEXEXTRACT(CELL("address",'Raw Data'!C20),"\$([A-Z]+)\$[0-9]+"),"")} | D18: {=IF('Raw Data'!D20="",_xlfn.REGEXEXTRACT(CELL("address",'Raw Data'!D20),"\$([A-Z]+)\$[0-9]+"),"")} | E18: {=IF('Raw Data'!E20="",_xlfn.REGEXEXTRACT(CELL("address",'Raw Data'!E20),"\$([A-Z]+)\$[0-9]+"),"")} | F18: {=IF('Raw Data'!F20="",_xlfn.REGEXEXTRACT(CELL("address",'Raw Data'!F20),"\$([A-Z]+)\$[0-9]+"),"")} | G18: {=IF('Raw Data'!#REF!="",_xlfn.REGEXEXTRACT(CELL("address",'Raw Data'!#REF!),"\$([A-Z]+)\$[0-9]+"),"")} -> #REF! | H18: {=IF('Raw Data'!G20="",_xlfn.REGEXEXTRACT(CELL("address",'Raw Data'!G20),"\$([A-Z]+)\$[0-9]+"),"")} -> $G$20 | I18: {=IF('Raw Data'!#REF!="",_xlfn.REGEXEXTRACT(CELL("address",'Raw Data'!#REF!),"\$([A-Z]+)\$[0-9]+"),"")} -> #REF!
