Workbook

Sheet Raw Data
B10: C1 | C10: C2 | D10: C3 | E10: C4 | F10: C5 | G10: C6 | H10: C7 | I10: C8 | J10: C9 | K10: C10 | L10: C11 | M10: C12 | N10: C13 | O10: C14 | P10: C15 | Q10: C16 | R10: C17 | S10: C18 | T10: C19 | U10: C20 | V10: C21 | W10: C22 | X10: C23 | Y10: C24 | Z10: C25 | AA10: C26 | AB10: C27 | AC10: C28 | AD10: C29 | AE10: C30 | AF10: C31 | AG10: C32 | AH10: C33 | AI10: C34 | AJ10: C35 | AK10: C36 | AL10: C37 | AM10: C38 | AN10: C39 | AO10: C40 | AP10: C41 | AQ10: C42 | AR10: C43 | AS10: C44 | AT10: C45 | AU10: C46 | AV10: C47 | AW10: C48 | AX10: C49 | AY10: C50 | AZ10: C51 | BA10: C52 | BB10: C53 | BC10: C54 | BD10: C55 | BE10: C56 | BF10: C57 | BG10: C58 | BH10: C59 | BI10: C60 | BJ10: C61 | BK10: C62 | BL10: C63 | BM10: C64 | BN10: C65 | BO10: C66 | BP10: C67 | BQ10: C68 | BR10: C69 | BS10: C70 | BT10: C71
B11: SL00042 | C11: Surapong Kidthook | E11: 03.Supervisor&Above | F11: 308 | G11: Engineering | H11: Process | I11: QAE001 | J11: Engineering | K11: Process | L11: 13.5 | M11: 13.5 | N11: 0 | O11: 0 | P11: 0 | Q11: 0 | R11: 0 | S11: 0 | T11: 0 | U11: 0 | V11: 0 | W11: 0 | X11: 0 | Y11: 0 | Z11: 0 | AA11: 0 | AB11: 0 | AC11: 0 | AD11: 0 | AE11: 0 | AF11: 0 | AG11: 0 | AH11: 0 | AI11: 0 | AJ11: 0 | AK11: 0 | AL11: 0 | AM11: 0 | AN11: 0 | AO11: 0 | AP11: 0 | AQ11: 0 | AR11: 0 | AS11: 0 | AT11: 0 | AU11: 0 | AV11: 0 | AW11: 0 | AX11: 0 | AY11: 0 | AZ11: 0 | BA11: 0 | BB11: 0 | BC11: 0 | BD11: 0 | BE11: 0 | BF11: 0 | BG11: 0 | BH11: 0 | BI11: 0 | BJ11: 0 | BK11: 0 | BL11: 0 | BM11: 0 | BN11: 0 | BO11: 0 | BP11: 0 | BQ11: 0 | BR11: 0 | BS11: 0 | BT11: 0
B12: ST04112 | C12: Jirapon Dangkham | E12: 03.Supervisor&Above | F12: 308 | G12: Engineering | H12: Process | I12: QAE001 | J12: Engineering | K12: Process | L12: 29.75 | M12: 16 | N12: 13.75 | O12: 0 | P12: 2 | Q12: 0 | R12: 0 | S12: 0 | T12: 0 | U12: 0 | V12: 0 | W12: 0 | X12: 0 | Y12: 0 | Z12: 0 | AA12: 0 | AB12: 0 | AC12: 0 | AD12: 0 | AE12: 0 | AF12: 0 | AG12: 0 | AH12: 0 | AI12: 0 | AJ12: 0 | AK12: 0 | AL12: 0 | AM12: 0 | AN12: 0 | AO12: 0 | AP12: 0 | AQ12: 0 | AR12: 0 | AS12: 0 | AT12: 0 | AU12: 0 | AV12: 0 | AW12: 0 | AX12: 0 | AY12: 0 | AZ12: 0 | BA12: 0 | BB12: 0 | BC12: 0 | BD12: 0 | BE12: 0 | BF12: 0 | BG12: 0 | BH12: 0 | BI12: 0 | BJ12: 0 | BK12: 0 | BL12: 0 | BM12: 0 | BN12: 0 | BO12: 0 | BP12: 0 | BQ12: 0 | BR12: 0 | BS12: 0 | BT12: 0
B13: ST04161 | C13: Phattasorn Jailuk | E13: 03.Supervisor&Above | F13: 312 | G13: Engineering | H13: Mechanical_Onshore | I13: QAE001 | J13: Engineering | K13: Mechanical | L13: 44.5 | M13: 0 | N13: 44.5 | O13: 13.75 | P13: 59.5 | Q13: 36.5 | R13: 47.75 | S13: 42.25 | T13: 20 | U13: 0 | V13: 0 | W13: 0 | X13: 0 | Y13: 0 | Z13: 0 | AA13: 30.18 | AB13: 0 | AC13: 0 | AD13: 0 | AE13: 0 | AF13: 0 | AG13: 0 | AH13: 0 | AI13: 0 | AJ13: 0 | AK13: 0 | AL13: 0 | AM13: 0 | AN13: 0 | AO13: 0 | AP13: 0 | AQ13: 0 | AR13: 0 | AS13: 0 | AT13: 0 | AU13: 0 | AV13: 0 | AW13: 0 | AX13: 0 | AY13: 0 | AZ13: 0 | BA13: 0 | BB13: 0 | BC13: 0 | BD13: 0 | BE13: 0 | BF13: 0 | BG13: 0 | BH13: 0 | BI13: 0 | BJ13: 0 | BK13: 0 | BL13: 0 | BM13: 0 | BN13: 0 | BO13: 0 | BP13: 0 | BQ13: 0 | BR13: 0 | BS13: 0 | BT13: 0
B14: ST04219 | C14: Thanadon Owartlarnporn | E14: 03.Supervisor&Above | F14: 312 | G14: Engineering | H14: Mechanical_Onshore | I14: QAE001 | J14: Engineering | K14: Mechanical | L14: 44.25 | M14: 36 | N14: 8.25 | O14: 44.5 | P14: 36.5 | Q14: 31.5 | R14: 30.5 | S14: 23 | T14: 3 | U14: 19.75 | V14: 1.5 | W14: 0 | X14: 0 | Y14: 0 | Z14: 8 | AA14: 1 | AB14: 0 | AC14: 0 | AD14: 0 | AE14: 0 | AF14: 0 | AG14: 0 | AH14: 0 | AI14: 0 | AJ14: 0 | AK14: 0 | AL14: 0 | AM14: 0 | AN14: 0 | AO14: 0 | AP14: 0 | AQ14: 0 | AR14: 0 | AS14: 0 | AT14: 0 | AU14: 0 | AV14: 0 | AW14: 0 | AX14: 0 | AY14: 0 | AZ14: 0 | BA14: 0 | BB14: 0 | BC14: 0 | BD14: 0 | BE14: 0 | BF14: 0 | BG14: 0 | BH14: 0 | BI14: 0 | BJ14: 0 | BK14: 0 | BL14: 0 | BM14: 0 | BN14: 0 | BO14: 0 | BP14: 0 | BQ14: 0 | BR14: 0 | BS14: 0 | BT14: 0
B15: PB00026 | C15: Ramon P. Alcontin | E15: 01.Expats | F15: 817 | G15: PMT | H15: PMT - Onshore | I15: QAM001 | J15: Project Management | K15: Project Manager | L15: 163.37 | M15: 107.12 | N15: 56.25 | O15: 8.25 | P15: 0 | Q15: 0 | R15: 0 | S15: 0 | T15: 0 | U15: 0 | V15: 0 | W15: 0 | X15: 0 | Y15: 0 | Z15: 0 | AA15: 0 | AB15: 0 | AC15: 0 | AD15: 0 | AE15: 0 | AF15: 0 | AG15: 0 | AH15: 0 | AI15: 0 | AJ15: 0 | AK15: 0 | AL15: 0 | AM15: 0 | AN15: 0 | AO15: 0 | AP15: 0 | AQ15: 0 | AR15: 0 | AS15: 0 | AT15: 0 | AU15: 0 | AV15: 0 | AW15: 0 | AX15: 0 | AY15: 0 | AZ15: 0 | BA15: 0 | BB15: 0 | BC15: 0 | BD15: 0 | BE15: 0 | BF15: 0 | BG15: 0 | BH15: 0 | BI15: 0 | BJ15: 0 | BK15: 0 | BL15: 0 | BM15: 0 | BN15: 0 | BO15: 0 | BP15: 0 | BQ15: 0 | BR15: 0 | BS15: 0 | BT15: 0
B16: ST04121 | C16: Kraiwich Srihapoach | E16: 03.Supervisor&Above | F16: 817 | G16: PMT | H16: PMT - Onshore | I16: QAM001 | J16: Project Management | K16: Project Control Engineer (Planner) | L16: 153.55 | M16: 101.83 | N16: 51.72 | O16: 66.25 | P16: 70 | Q16: 75.65 | R16: 72.37 | S16: 67.75 | T16: 89.5 | U16: 56.75 | V16: 71.98 | W16: 32.42 | X16: 38.75 | Y16: 22.86 | Z16: 35.67 | AA16: 16.75 | AB16: 3.77 | AC16: 3.77 | AD16: 0 | AE16: 0 | AF16: 0 | AG16: 0 | AH16: 0 | AI16: 0 | AJ16: 0 | AK16: 0 | AL16: 0 | AM16: 0 | AN16: 0 | AO16: 0 | AP16: 0 | AQ16: 0 | AR16: 0 | AS16: 0 | AT16: 0 | AU16: 0 | AV16: 0 | AW16: 0 | AX16: 0 | AY16: 0 | AZ16: 0 | BA16: 0 | BB16: 0 | BC16: 0 | BD16: 0 | BE16: 0 | BF16: 0 | BG16: 0 | BH16: 0 | BI16: 0 | BJ16: 0 | BK16: 0 | BL16: 0 | BM16: 0 | BN16: 0 | BO16: 0 | BP16: 0 | BQ16: 0 | BR16: 0 | BS16: 0 | BT16: 0
B17: ST03587 | C17: Radkao Saeli | E17: 03.Supervisor&Above | F17: 816 | G17: PMT | H17: PMT - Offshore | I17: QAM001 | J17: Project Management | K17: Document Control/Admin | L17: 57.75 | M17: 8 | N17: 49.75 | O17: 83.67 | P17: 60.81 | Q17: 81.1 | R17: 70.97 | S17: 63.58 | T17: 75.19 | U17: 74.4 | V17: 91.58 | W17: 31.75 | X17: 30.91 | Y17: 22.44 | Z17: 29.32 | AA17: 34.17 | AB17: 25.51 | AC17: 25.51 | AD17: 0 | AE17: 0 | AF17: 0 | AG17: 0 | AH17: 0 | AI17: 0 | AJ17: 0 | AK17: 0 | AL17: 0 | AM17: 0 | AN17: 0 | AO17: 0 | AP17: 0 | AQ17: 0 | AR17: 0 | AS17: 0 | AT17: 0 | AU17: 0 | AV17: 0 | AW17: 0 | AX17: 0 | AY17: 0 | AZ17: 0 | BA17: 0 | BB17: 0 | BC17: 0 | BD17: 0 | BE17: 0 | BF17: 0 | BG17: 0 | BH17: 0 | BI17: 0 | BJ17: 0 | BK17: 0 | BL17: 0 | BM17: 0 | BN17: 0 | BO17: 0 | BP17: 0 | BQ17: 0 | BR17: 0 | BS17: 0 | BT17: 0
B18: TT01573 | C18: Nathapol Rojjindangam | E18: 03.Supervisor&Above | F18: 816 | G18: PMT | H18: PMT - Offshore | I18: QAM001 | J18: Project Management | K18: Project Engineer | L18: 98.5 | M18: 56 | N18: 42.5 | O18: 59.75 | P18: 10 | Q18: 4 | R18: 6 | S18: 12 | T18: 10.75 | U18: 6 | V18: 0 | W18: 0 | X18: 0 | Y18: 0 | Z18: 0 | AA18: 0 | AB18: 0 | AC18: 0 | AD18: 0 | AE18: 0 | AF18: 0 | AG18: 0 | AH18: 0 | AI18: 0 | AJ18: 0 | AK18: 0 | AL18: 0 | AM18: 0 | AN18: 0 | AO18: 0 | AP18: 0 | AQ18: 0 | AR18: 0 | AS18: 0 | AT18: 0 | AU18: 0 | AV18: 0 | AW18: 0 | AX18: 0 | AY18: 0 | AZ18: 0 | BA18: 0 | BB18: 0 | BC18: 0 | BD18: 0 | BE18: 0 | BF18: 0 | BG18: 0 | BH18: 0 | BI18: 0 | BJ18: 0 | BK18: 0 | BL18: 0 | BM18: 0 | BN18: 0 | BO18: 0 | BP18: 0 | BQ18: 0 | BR18: 0 | BS18: 0 | BT18: 0
B19: ST04154 | C19: Chuleeporn Samranphit | E19: 03.Supervisor&Above | F19: 816 | G19: PMT | H19: PMT - Offshore | I19: QAM001 | J19: Project Management | K19: Cost Control | L19: 48.25 | M19: 31.75 | N19: 16.5 | O19: 58 | P19: 78.48 | Q19: 67.25 | R19: 98.5 | S19: 73.25 | T19: 56.5 | U19: 8.75 | V19: 18.92 | W19: 0 | X19: 0 | Y19: 0 | Z19: 0 | AA19: 0 | AB19: 0 | AC19: 0 | AD19: 0 | AE19: 0 | AF19: 0 | AG19: 0 | AH19: 0 | AI19: 0 | AJ19: 0 | AK19: 0 | AL19: 0 | AM19: 0 | AN19: 0 | AO19: 0 | AP19: 0 | AQ19: 0 | AR19: 0 | AS19: 0 | AT19: 0 | AU19: 0 | AV19: 0 | AW19: 0 | AX19: 0 | AY19: 0 | AZ19: 0 | BA19: 0 | BB19: 0 | BC19: 0 | BD19: 0 | BE19: 0 | BF19: 0 | BG19: 0 | BH19: 0 | BI19: 0 | BJ19: 0 | BK19: 0 | BL19: 0 | BM19: 0 | BN19: 0 | BO19: 0 | BP19: 0 | BQ19: 0 | BR19: 0 | BS19: 0 | BT19: 0
B20: ST03601 | C20: Chanchira Chuensirikun | E20: 03.Supervisor&Above | F20: 401 | G20: Procurement | H20: Purchasing | I20: QAP001 | J20: Procurement | K20: Purchasing | L20: 1.25 | M20: 1.25 | N20: 0 | O20: 32 | P20: 45 | Q20: 59.75 | R20: 78.25 | S20: 91 | T20: 95.25 | U20: 93 | V20: 93 | W20: 39 | X20: 38 | Y20: 37.5 | Z20: 60 | AA20: 38 | AB20: 30 | AC20: 30 | AD20: 0 | AE20: 0 | AF20: 0 | AG20: 0 | AH20: 0 | AI20: 0 | AJ20: 0 | AK20: 0 | AL20: 0 | AM20: 0 | AN20: 0 | AO20: 0 | AP20: 0 | AQ20: 0 | AR20: 0 | AS20: 0 | AT20: 0 | AU20: 0 | AV20: 0 | AW20: 0 | AX20: 0 | AY20: 0 | AZ20: 0 | BA20: 0 | BB20: 0 | BC20: 0 | BD20: 0 | BE20: 0 | BF20: 0 | BG20: 0 | BH20: 0 | BI20: 0 | BJ20: 0 | BK20: 0 | BL20: 0 | BM20: 0 | BN20: 0 | BO20: 0 | BP20: 0 | BQ20: 0 | BR20: 0 | BS20: 0 | BT20: 0
B21: ST04009 | C21: Chonnipa Chompu | E21: 03.Supervisor&Above | F21: 401 | G21: Procurement | H21: Purchasing | I21: QAP001 | J21: Procurement | K21: Purchasing | L21: 216.61 | M21: 121.31 | N21: 95.3 | O21: 0 | P21: 0 | Q21: 0 | R21: 0 | S21: 0 | T21: 0 | U21: 0 | V21: 0 | W21: 0 | X21: 0 | Y21: 0 | Z21: 0 | AA21: 0 | AB21: 0 | AC21: 0 | AD21: 0 | AE21: 0 | AF21: 0 | AG21: 0 | AH21: 0 | AI21: 0 | AJ21: 0 | AK21: 0 | AL21: 0 | AM21: 0 | AN21: 0 | AO21: 0 | AP21: 0 | AQ21: 0 | AR21: 0 | AS21: 0 | AT21: 0 | AU21: 0 | AV21: 0 | AW21: 0 | AX21: 0 | AY21: 0 | AZ21: 0 | BA21: 0 | BB21: 0 | BC21: 0 | BD21: 0 | BE21: 0 | BF21: 0 | BG21: 0 | BH21: 0 | BI21: 0 | BJ21: 0 | BK21: 0 | BL21: 0 | BM21: 0 | BN21: 0 | BO21: 0 | BP21: 0 | BQ21: 0 | BR21: 0 | BS21: 0 | BT21: 0
B22: ST04134 | C22: Chanchay Manphonsri | E22: 03.Supervisor&Above | F22: 401 | G22: Procurement | H22: Purchasing | I22: QAP001 | J22: Procurement | K22: Purchasing | L22: 118.31 | M22: 45.66 | N22: 72.65 | O22: 95.3 | P22: 36.32 | Q22: 16.33 | R22: 29.74 | S22: 30.66 | T22: 12.66 | U22: 20.24 | V22: 3.41 | W22: 3.17 | X22: 14.25 | Y22: 6.25 | Z22: 13.25 | AA22: 1 | AB22: 1.75 | AC22: 1.75 | AD22: 0 | AE22: 0 | AF22: 0 | AG22: 0 | AH22: 0 | AI22: 0 | AJ22: 0 | AK22: 0 | AL22: 0 | AM22: 0 | AN22: 0 | AO22: 0 | AP22: 0 | AQ22: 0 | AR22: 0 | AS22: 0 | AT22: 0 | AU22: 0 | AV22: 0 | AW22: 0 | AX22: 0 | AY22: 0 | AZ22: 0 | BA22: 0 | BB22: 0 | BC22: 0 | BD22: 0 | BE22: 0 | BF22: 0 | BG22: 0 | BH22: 0 | BI22: 0 | BJ22: 0 | BK22: 0 | BL22: 0 | BM22: 0 | BN22: 0 | BO22: 0 | BP22: 0 | BQ22: 0 | BR22: 0 | BS22: 0 | BT22: 0
... B70: ST04227 | C70: Peeranut Chomdech | E70: 03.Supervisor&Above | F70: 306 | G70: Engineering | H70: Instrumentation | I70: YYQCXXX | J70: Construction | K70: Engineering | L70: 93 | M70: 0 | N70: 0 | O70: 0 | P70: 0 | Q70: 0 | R70: 0 | S70: 0 | T70: 0 | U70: 0 | V70: 93 | W70: 0 | X70: 0 | Y70: 0 | Z70: 0 | AA70: 0 | AB70: 0 | AC70: 0 | AD70: 0 | AE70: 0 | AF70: 0 | AG70: 0 | AH70: 0 | AI70: 0 | AJ70: 0 | AK70: 0 | AL70: 0 | AM70: 0 | AN70: 0 | AO70: 0 | AP70: 0 | AQ70: 0 | AR70: 0 | AS70: 0 | AT70: 0 | AU70: 0 | AV70: 0 | AW70: 0 | AX70: 0 | AY70: 0 | AZ70: 0 | BA70: 0 | BB70: 0 | BC70: 0 | BD70: 0 | BE70: 0 | BF70: 0 | BG70: 0 | BH70: 0 | BI70: 0 | BJ70: 0 | BK70: 0 | BL70: 0 | BM70: 0 | BN70: 0 | BO70: 0 | BP70: 0 | BQ70: 0 | BR70: 0 | BS70: 0 | BT70: 0

Sheet Validate_Empty
B9: TRUE | C9: TRUE | D9: FALSE | E9: TRUE | F9: TRUE | G9: TRUE | H9: TRUE | I9: TRUE | J9: TRUE | K9: TRUE | L9: TRUE | M9: FALSE | N9: FALSE | O9: FALSE | P9: FALSE | Q9: FALSE | R9: FALSE | S9: FALSE | T9: FALSE | U9: FALSE | V9: FALSE | W9: FALSE | X9: FALSE | Y9: FALSE | Z9: FALSE | AA9: FALSE | AB9: FALSE | AC9: FALSE | AD9: FALSE | AE9: FALSE | AF9: FALSE | AG9: FALSE | AH9: FALSE | AI9: FALSE | AJ9: FALSE | AK9: FALSE | AL9: FALSE | AM9: FALSE | AN9: FALSE | AO9: FALSE | AP9: FALSE | AQ9: FALSE | AR9: FALSE | AS9: FALSE | AT9: FALSE | AU9: FALSE | AV9: FALSE | AW9: FALSE | AX9: FALSE | AY9: FALSE | AZ9: FALSE | BA9: FALSE | BB9: FALSE | BC9: FALSE | BD9: FALSE | BE9: FALSE | BF9: FALSE | BG9: FALSE | BH9: FALSE | BI9: FALSE | BJ9: FALSE | BK9: FALSE | BL9: FALSE | BM9: FALSE | BN9: FALSE | BO9: FALSE | BP9: FALSE | BQ9: FALSE | BR9: FALSE | BS9: FALSE | BT9: FALSE
B10: C1 | C10: C2 | D10: C3 | E10: C4 | F10: C5 | G10: C6 | H10: C7 | I10: C8 | J10: C9 | K10: C10 | L10: C11 | M10: C12 | N10: C13 | O10: C14 | P10: C15 | Q10: C16 | R10: C17 | S10: C18 | T10: C19 | U10: C20 | V10: C21 | W10: C22 | X10: C23 | Y10: C24 | Z10: C25 | AA10: C26 | AB10: C27 | AC10: C28 | AD10: C29 | AE10: C30 | AF10: C31 | AG10: C32 | AH10: C33 | AI10: C34 | AJ10: C35 | AK10: C36 | AL10: C37 | AM10: C38 | AN10: C39 | AO10: C40 | AP10: C41 | AQ10: C42 | AR10: C43 | AS10: C44 | AT10: C45 | AU10: C46 | AV10: C47 | AW10: C48 | AX10: C49 | AY10: C50 | AZ10: C51 | BA10: C52 | BB10: C53 | BC10: C54 | BD10: C55 | BE10: C56 | BF10: C57 | BG10: C58 | BH10: C59 | BI10: C60 | BJ10: C61 | BK10: C62 | BL10: C63 | BM10: C64 | BN10: C65 | BO10: C66 | BP10: C67 | BQ10: C68 | BR10: C69 | BS10: C70 | BT10: C71
B11: {=IFERROR(IF(OR('Raw Data'!B11="",LEN(TRIM('Raw Data'!B11))=0),_xlfn.REGEXEXTRACT(CELL("address",'Raw Data'!B11),"\$([A-Z]+)\$[0-9]+"),""),"")} | C11: {=IFERROR(IF(OR('Raw Data'!C11="",LEN(TRIM('Raw Data'!C11))=0),_xlfn.REGEXEXTRACT(CELL("address",'Raw Data'!C11),"\$([A-Z]+)\$[0-9]+"),""),"")} | E11: {=IFERROR(IF(OR('Raw Data'!E11="",LEN(TRIM('Raw Data'!E11))=0),_xlfn.REGEXEXTRACT(CELL("address",'Raw Data'!E11),"\$([A-Z]+)\$[0-9]+"),""),"")} | F11: {=IFERROR(IF(OR('Raw Data'!F11="",LEN(TRIM('Raw Data'!F11))=0),_xlfn.REGEXEXTRACT(CELL("address",'Raw Data'!F11),"\$([A-Z]+)\$[0-9]+"),""),"")} | G11: {=IFERROR(IF(OR('Raw Data'!G11="",LEN(TRIM('Raw Data'!G11))=0),_xlfn.REGEXEXTRACT(CELL("address",'Raw Data'!G11),"\$([A-Z]+)\$[0-9]+"),""),"")} | H11: {=IFERROR(IF(OR('Raw Data'!H11="",LEN(TRIM('Raw Data'!H11))=0),_xlfn.REGEXEXTRACT(CELL("address",'Raw Data'!H11),"\$([A-Z]+)\$[0-9]+"),""),"")} | I11: {=IFERROR(IF(OR('Raw Data'!I11="",LEN(TRIM('Raw Data'!I11))=0),_xlfn.REGEXEXTRACT(CELL("address",'Raw Data'!I11),"\$([A-Z]+)\$[0-9]+"),""),"")} | J11: {=IFERROR(IF(OR('Raw Data'!J11="",LEN(TRIM('Raw Data'!J11))=0),_xlfn.REGEXEXTRACT(CELL("address",'Raw Data'!J11),"\$([A-Z]+)\$[0-9]+"),""),"")} | K11: {=IFERROR(IF(OR('Raw Data'!K11="",LEN(TRIM('Raw Data'!K11))=0),_xlfn.REGEXEXTRACT(CELL("address",'Raw Data'!K11),"\$([A-Z]+)\$[0-9]+"),""),"")} | L11: {=IFERROR(IF(OR('Raw Data'!L11="",LEN(TRIM('Raw Data'!L11))=0),_xlfn.REGEXEXTRACT(CELL("address",'Raw Data'!L11),"\$([A-Z]+)\$[0-9]+"),""),"")}
B12: {=IFERROR(IF(OR('Raw Data'!B12="",LEN(TRIM('Raw Data'!B12))=0),_xlfn.REGEXEXTRACT(CELL("address",'Raw Data'!B12),"\$([A-Z]+)\$[0-9]+"),""),"")} | C12: {=IFERROR(IF(OR('Raw Data'!C12="",LEN(TRIM('Raw Data'!C12))=0),_xlfn.REGEXEXTRACT(CELL("address",'Raw Data'!C12),"\$([A-Z]+)\$[0-9]+"),""),"")} | E12: {=IFERROR(IF(OR('Raw Data'!E12="",LEN(TRIM('Raw Data'!E12))=0),_xlfn.REGEXEXTRACT(CELL("address",'Raw Data'!E12),"\$([A-Z]+)\$[0-9]+"),""),"")} | F12: {=IFERROR(IF(OR('Raw Data'!F12="",LEN(TRIM('Raw Data'!F12))=0),_xlfn.REGEXEXTRACT(CELL("address",'Raw Data'!F12),"\$([A-Z]+)\$[0-9]+"),""),"")} | G12: {=IFERROR(IF(OR('Raw Data'!G12="",LEN(TRIM('Raw Data'!G12))=0),_xlfn.REGEXEXTRACT(CELL("address",'Raw Data'!G12),"\$([A-Z]+)\$[0-9]+"),""),"")} | H12: {=IFERROR(IF(OR('Raw Data'!H12="",LEN(TRIM('Raw Data'!H12))=0),_xlfn.REGEXEXTRACT(CELL("address",'Raw Data'!H12),"\$([A-Z]+)\$[0-9]+"),""),"")} | I12: {=IFERROR(IF(OR('Raw Data'!I12="",LEN(TRIM('Raw Data'!I12))=0),_xlfn.REGEXEXTRACT(CELL("address",'Raw Data'!I12),"\$([A-Z]+)\$[0-9]+"),""),"")} | J12: {=IFERROR(IF(OR('Raw Data'!J12="",LEN(TRIM('Raw Data'!J12))=0),_xlfn.REGEXEXTRACT(CELL("address",'Raw Data'!J12),"\$([A-Z]+)\$[0-9]+"),""),"")} | K12: {=IFERROR(IF(OR('Raw Data'!K12="",LEN(TRIM('Raw Data'!K12))=0),_xlfn.REGEXEXTRACT(CELL("address",'Raw Data'!K12),"\$([A-Z]+)\$[0-9]+"),""),"")} | L12: {=IFERROR(IF(OR('Raw Data'!L12="",LEN(TRIM('Raw Data'!L12))=0),_xlfn.REGEXEXTRACT(CELL("address",'Raw Data'!L12),"\$([A-Z]+)\$[0-9]+"),""),"")}
B13: {=IFERROR(IF(OR('Raw Data'!B13="",LEN(TRIM('Raw Data'!B13))=0),_xlfn.REGEXEXTRACT(CELL("address",'Raw Data'!B13),"\$([A-Z]+)\$[0-9]+"),""),"")} | C13: {=IFERROR(IF(OR('Raw Data'!C13="",LEN(TRIM('Raw Data'!C13))=0),_xlfn.REGEXEXTRACT(CELL("address",'Raw Data'!C13),"\$([A-Z]+)\$[0-9]+"),""),"")} | E13: {=IFERROR(IF(OR('Raw Data'!E13="",LEN(TRIM('Raw Data'!E13))=0),_xlfn.REGEXEXTRACT(CELL("address",'Raw Data'!E13),"\$([A-Z]+)\$[0-9]+"),""),"")} | F13: {=IFERROR(IF(OR('Raw Data'!F13="",LEN(TRIM('Raw Data'!F13))=0),_xlfn.REGEXEXTRACT(CELL("address",'Raw Data'!F13),"\$([A-Z]+)\$[0-9]+"),""),"")} | G13: {=IFERROR(IF(OR('Raw Data'!G13="",LEN(TRIM('Raw Data'!G13))=0),_xlfn.REGEXEXTRACT(CELL("address",'Raw Data'!G13),"\$([A-Z]+)\$[0-9]+"),""),"")} | H13: {=IFERROR(IF(OR('Raw Data'!H13="",LEN(TRIM('Raw Data'!H13))=0),_xlfn.REGEXEXTRACT(CELL("address",'Raw Data'!H13),"\$([A-Z]+)\$[0-9]+"),""),"")} | I13: {=IFERROR(IF(OR('Raw Data'!I13="",LEN(TRIM('Raw Data'!I13))=0),_xlfn.REGEXEXTRACT(CELL("address",'Raw Data'!I13),"\$([A-Z]+)\$[0-9]+"),""),"")} | J13: {=IFERROR(IF(OR('Raw Data'!J13="",LEN(TRIM('Raw Data'!J13))=0),_xlfn.REGEXEXTRACT(CELL("address",'Raw Data'!J13),"\$([A-Z]+)\$[0-9]+"),""),"")} | K13: {=IFERROR(IF(OR('Raw Data'!K13="",LEN(TRIM('Raw Data'!K13))=0),_xlfn.REGEXEXTRACT(CELL("address",'Raw Data'!K13),"\$([A-Z]+)\$[0-9]+"),""),"")} | L13: {=IFERROR(IF(OR('Raw Data'!L13="",LEN(TRIM('Raw Data'!L13))=0),_xlfn.REGEXEXTRACT(CELL("address",'Raw Data'!L13),"\$([A-Z]+)\$[0-9]+"),""),"")}
B14: {=IFERROR(IF(OR('Raw Data'!B14="",LEN(TRIM('Raw Data'!B14))=0),_xlfn.REGEXEXTRACT(CELL("address",'Raw Data'!B14),"\$([A-Z]+)\$[0-9]+"),""),"")} | C14: {=IFERROR(IF(OR('Raw Data'!C14="",LEN(TRIM('Raw Data'!C14))=0),_xlfn.REGEXEXTRACT(CELL("address",'Raw Data'!C14),"\$([A-Z]+)\$[0-9]+"),""),"")} | E14: {=IFERROR(IF(OR('Raw Data'!E14="",LEN(TRIM('Raw Data'!E14))=0),_xlfn.REGEXEXTRACT(CELL("address",'Raw Data'!E14),"\$([A-Z]+)\$[0-9]+"),""),"")} | F14: {=IFERROR(IF(OR('Raw Data'!F14="",LEN(TRIM('Raw Data'!F14))=0),_xlfn.REGEXEXTRACT(CELL("address",'Raw Data'!F14),"\$([A-Z]+)\$[0-9]+"),""),"")} | G14: {=IFERROR(IF(OR('Raw Data'!G14="",LEN(TRIM('Raw Data'!G14))=0),_xlfn.REGEXEXTRACT(CELL("address",'Raw Data'!G14),"\$([A-Z]+)\$[0-9]+"),""),"")} | H14: {=IFERROR(IF(OR('Raw Data'!H14="",LEN(TRIM('Raw Data'!H14))=0),_xlfn.REGEXEXTRACT(CELL("address",'Raw Data'!H14),"\$([A-Z]+)\$[0-9]+"),""),"")} | I14: {=IFERROR(IF(OR('Raw Data'!I14="",LEN(TRIM('Raw Data'!I14))=0),_xlfn.REGEXEXTRACT(CELL("address",'Raw Data'!I14),"\$([A-Z]+)\$[0-9]+"),""),"")} | J14: {=IFERROR(IF(OR('Raw Data'!J14="",LEN(TRIM('Raw Data'!J14))=0),_xlfn.REGEXEXTRACT(CELL("address",'Raw Data'!J14),"\$([A-Z]+)\$[0-9]+"),""),"")} | K14: {=IFERROR(IF(OR('Raw Data'!K14="",LEN(TRIM('Raw Data'!K14))=0),_xlfn.REGEXEXTRACT(CELL("address",'Raw Data'!K14),"\$([A-Z]+)\$[0-9]+"),""),"")} | L14: {=IFERROR(IF(OR('Raw Data'!L14="",LEN(TRIM('Raw Data'!L14))=0),_xlfn.REGEXEXTRACT(CELL("address",'Raw Data'!L14),"\$([A-Z]+)\$[0-9]+"),""),"")}
B15: {=IFERROR(IF(OR('Raw Data'!B15="",LEN(TRIM('Raw Data'!B15))=0),_xlfn.REGEXEXTRACT(CELL("address",'Raw Data'!B15),"\$([A-Z]+)\$[0-9]+"),""),"")} | C15: {=IFERROR(IF(OR('Raw Data'!C15="",LEN(TRIM('Raw Data'!C15))=0),_xlfn.REGEXEXTRACT(CELL("address",'Raw Data'!C15),"\$([A-Z]+)\$[0-9]+"),""),"")} | E15: {=IFERROR(IF(OR('Raw Data'!E15="",LEN(TRIM('Raw Data'!E15))=0),_xlfn.REGEXEXTRACT(CELL("address",'Raw Data'!E15),"\$([A-Z]+)\$[0-9]+"),""),"")} | F15: {=IFERROR(IF(OR('Raw Data'!F15="",LEN(TRIM('Raw Data'!F15))=0),_xlfn.REGEXEXTRACT(CELL("address",'Raw Data'!F15),"\$([A-Z]+)\$[0-9]+"),""),"")} | G15: {=IFERROR(IF(OR('Raw Data'!G15="",LEN(TRIM('Raw Data'!G15))=0),_xlfn.REGEXEXTRACT(CELL("address",'Raw Data'!G15),"\$([A-Z]+)\$[0-9]+"),""),"")} | H15: {=IFERROR(IF(OR('Raw Data'!H15="",LEN(TRIM('Raw Data'!H15))=0),_xlfn.REGEXEXTRACT(CELL("address",'Raw Data'!H15),"\$([A-Z]+)\$[0-9]+"),""),"")} | I15: {=IFERROR(IF(OR('Raw Data'!I15="",LEN(TRIM('Raw Data'!I15))=0),_xlfn.REGEXEXTRACT(CELL("address",'Raw Data'!I15),"\$([A-Z]+)\$[0-9]+"),""),"")} | J15: {=IFERROR(IF(OR('Raw Data'!J15="",LEN(TRIM('Raw Data'!J15))=0),_xlfn.REGEXEXTRACT(CELL("address",'Raw Data'!J15),"\$([A-Z]+)\$[0-9]+"),""),"")} | K15: {=IFERROR(IF(OR('Raw Data'!K15="",LEN(TRIM('Raw Data'!K15))=0),_xlfn.REGEXEXTRACT(CELL("address",'Raw Data'!K15),"\$([A-Z]+)\$[0-9]+"),""),"")} | L15: {=IFERROR(IF(OR('Raw Data'!L15="",LEN(TRIM('Raw Data'!L15))=0),_xlfn.REGEXEXTRACT(CELL("address",'Raw Data'!L15),"\$([A-Z]+)\$[0-9]+"),""),"")}
B16: {=IFERROR(IF(OR('Raw Data'!B16="",LEN(TRIM('Raw Data'!B16))=0),_xlfn.REGEXEXTRACT(CELL("address",'Raw Data'!B16),"\$([A-Z]+)\$[0-9]+"),""),"")} | C16: {=IFERROR(IF(OR('Raw Data'!C16="",LEN(TRIM('Raw Data'!C16))=0),_xlfn.REGEXEXTRACT(CELL("address",'Raw Data'!C16),"\$([A-Z]+)\$[0-9]+"),""),"")} | E16: {=IFERROR(IF(OR('Raw Data'!E16="",LEN(TRIM('Raw Data'!E16))=0),_xlfn.REGEXEXTRACT(CELL("address",'Raw Data'!E16),"\$([A-Z]+)\$[0-9]+"),""),"")} | F16: {=IFERROR(IF(OR('Raw Data'!F16="",LEN(TRIM('Raw Data'!F16))=0),_xlfn.REGEXEXTRACT(CELL("address",'Raw Data'!F16),"\$([A-Z]+)\$[0-9]+"),""),"")} | G16: {=IFERROR(IF(OR('Raw Data'!G16="",LEN(TRIM('Raw Data'!G16))=0),_xlfn.REGEXEXTRACT(CELL("address",'Raw Data'!G16),"\$([A-Z]+)\$[0-9]+"),""),"")} | H16: {=IFERROR(IF(OR('Raw Data'!H16="",LEN(TRIM('Raw Data'!H16))=0),_xlfn.REGEXEXTRACT(CELL("address",'Raw Data'!H16),"\$([A-Z]+)\$[0-9]+"),""),"")} | I16: {=IFERROR(IF(OR('Raw Data'!I16="",LEN(TRIM('Raw Data'!I16))=0),_xlfn.REGEXEXTRACT(CELL("address",'Raw Data'!I16),"\$([A-Z]+)\$[0-9]+"),""),"")} | J16: {=IFERROR(IF(OR('Raw Data'!J16="",LEN(TRIM('Raw Data'!J16))=0),_xlfn.REGEXEXTRACT(CELL("address",'Raw Data'!J16),"\$([A-Z]+)\$[0-9]+"),""),"")} | K16: {=IFERROR(IF(OR('Raw Data'!K16="",LEN(TRIM('Raw Data'!K16))=0),_xlfn.REGEXEXTRACT(CELL("address",'Raw Data'!K16),"\$([A-Z]+)\$[0-9]+"),""),"")} | L16: {=IFERROR(IF(OR('Raw Data'!L16="",LEN(TRIM('Raw Data'!L16))=0),_xlfn.REGEXEXTRACT(CELL("address",'Raw Data'!L16),"\$([A-Z]+)\$[0-9]+"),""),"")}
B17: {=IFERROR(IF(OR('Raw Data'!B17="",LEN(TRIM('Raw Data'!B17))=0),_xlfn.REGEXEXTRACT(CELL("address",'Raw Data'!B17),"\$([A-Z]+)\$[0-9]+"),""),"")} | C17: {=IFERROR(IF(OR('Raw Data'!C17="",LEN(TRIM('Raw Data'!C17))=0),_xlfn.REGEXEXTRACT(CELL("address",'Raw Data'!C17),"\$([A-Z]+)\$[0-9]+"),""),"")} | E17: {=IFERROR(IF(OR('Raw Data'!E17="",LEN(TRIM('Raw Data'!E17))=0),_xlfn.REGEXEXTRACT(CELL("address",'Raw Data'!E17),"\$([A-Z]+)\$[0-9]+"),""),"")} | F17: {=IFERROR(IF(OR('Raw Data'!F17="",LEN(TRIM('Raw Data'!F17))=0),_xlfn.REGEXEXTRACT(CELL("address",'Raw Data'!F17),"\$([A-Z]+)\$[0-9]+"),""),"")} | G17: {=IFERROR(IF(OR('Raw Data'!G17="",LEN(TRIM('Raw Data'!G17))=0),_xlfn.REGEXEXTRACT(CELL("address",'Raw Data'!G17),"\$([A-Z]+)\$[0-9]+"),""),"")} | H17: {=IFERROR(IF(OR('Raw Data'!H17="",LEN(TRIM('Raw Data'!H17))=0),_xlfn.REGEXEXTRACT(CELL("address",'Raw Data'!H17),"\$([A-Z]+)\$[0-9]+"),""),"")} | I17: {=IFERROR(IF(OR('Raw Data'!I17="",LEN(TRIM('Raw Data'!I17))=0),_xlfn.REGEXEXTRACT(CELL("address",'Raw Data'!I17),"\$([A-Z]+)\$[0-9]+"),""),"")} | J17: {=IFERROR(IF(OR('Raw Data'!J17="",LEN(TRIM('Raw Data'!J17))=0),_xlfn.REGEXEXTRACT(CELL("address",'Raw Data'!J17),"\$([A-Z]+)\$[0-9]+"),""),"")} | K17: {=IFERROR(IF(OR('Raw Data'!K17="",LEN(TRIM('Raw Data'!K17))=0),_xlfn.REGEXEXTRACT(CELL("address",'Raw Data'!K17),"\$([A-Z]+)\$[0-9]+"),""),"")} | L17: {=IFERROR(IF(OR('Raw Data'!L17="",LEN(TRIM('Raw Data'!L17))=0),_xlfn.REGEXEXTRACT(CELL("address",'Raw Data'!L17),"\$([A-Z]+)\$[0-9]+"),""),"")}
B18: {=IFERROR(IF(OR('Raw Data'!B18="",LEN(TRIM('Raw Data'!B18))=0),_xlfn.REGEXEXTRACT(CELL("address",'Raw Data'!B18),"\$([A-Z]+)\$[0-9]+"),""),"")} | C18: {=IFERROR(IF(OR('Raw Data'!C18="",LEN(TRIM('Raw Data'!C18))=0),_xlfn.REGEXEXTRACT(CELL("address",'Raw Data'!C18),"\$([A-Z]+)\$[0-9]+"),""),"")} | E18: {=IFERROR(IF(OR('Raw Data'!E18="",LEN(TRIM('Raw Data'!E18))=0),_xlfn.REGEXEXTRACT(CELL("address",'Raw Data'!E18),"\$([A-Z]+)\$[0-9]+"),""),"")} | F18: {=IFERROR(IF(OR('Raw Data'!F18="",LEN(TRIM('Raw Data'!F18))=0),_xlfn.REGEXEXTRACT(CELL("address",'Raw Data'!F18),"\$([A-Z]+)\$[0-9]+"),""),"")} | G18: {=IFERROR(IF(OR('Raw Data'!G18="",LEN(TRIM('Raw Data'!G18))=0),_xlfn.REGEXEXTRACT(CELL("address",'Raw Data'!G18),"\$([A-Z]+)\$[0-9]+"),""),"")} | H18: {=IFERROR(IF(OR('Raw Data'!H18="",LEN(TRIM('Raw Data'!H18))=0),_xlfn.REGEXEXTRACT(CELL("address",'Raw Data'!H18),"\$([A-Z]+)\$[0-9]+"),""),"")} | I18: {=IFERROR(IF(OR('Raw Data'!I18="",LEN(TRIM('Raw Data'!I18))=0),_xlfn.REGEXEXTRACT(CELL("address",'Raw Data'!I18),"\$([A-Z]+)\$[0-9]+"),""),"")} | J18: {=IFERROR(IF(OR('Raw Data'!J18="",LEN(TRIM('Raw Data'!J18))=0),_xlfn.REGEXEXTRACT(CELL("address",'Raw Data'!J18),"\$([A-Z]+)\$[0-9]+"),""),"")} | K18: {=IFERROR(IF(OR('Raw Data'!K18="",LEN(TRIM('Raw Data'!K18))=0),_xlfn.REGEXEXTRACT(CELL("address",'Raw Data'!K18),"\$([A-Z]+)\$[0-9]+"),""),"")} | L18: {=IFERROR(IF(OR('Raw Data'!L18="",LEN(TRIM('Raw Data'!L18))=0),_xlfn.REGEXEXTRACT(CELL("address",'Raw Data'!L18),"\$([A-Z]+)\$[0-9]+"),""),"")}
B19: {=IFERROR(IF(OR('Raw Data'!B19="",LEN(TRIM('Raw Data'!B19))=0),_xlfn.REGEXEXTRACT(CELL("address",'Raw Data'!B19),"\$([A-Z]+)\$[0-9]+"),""),"")} | C19: {=IFERROR(IF(OR('Raw Data'!C19="",LEN(TRIM('Raw Data'!C19))=0),_xlfn.REGEXEXTRACT(CELL("address",'Raw Data'!C19),"\$([A-Z]+)\$[0-9]+"),""),"")} | E19: {=IFERROR(IF(OR('Raw Data'!E19="",LEN(TRIM('Raw Data'!E19))=0),_xlfn.REGEXEXTRACT(CELL("address",'Raw Data'!E19),"\$([A-Z]+)\$[0-9]+"),""),"")} | F19: {=IFERROR(IF(OR('Raw Data'!F19="",LEN(TRIM('Raw Data'!F19))=0),_xlfn.REGEXEXTRACT(CELL("address",'Raw Data'!F19),"\$([A-Z]+)\$[0-9]+"),""),"")} | G19: {=IFERROR(IF(OR('Raw Data'!G19="",LEN(TRIM('Raw Data'!G19))=0),_xlfn.REGEXEXTRACT(CELL("address",'Raw Data'!G19),"\$([A-Z]+)\$[0-9]+"),""),"")} | H19: {=IFERROR(IF(OR('Raw Data'!H19="",LEN(TRIM('Raw Data'!H19))=0),_xlfn.REGEXEXTRACT(CELL("address",'Raw Data'!H19),"\$([A-Z]+)\$[0-9]+"),""),"")} | I19: {=IFERROR(IF(OR('Raw Data'!I19="",LEN(TRIM('Raw Data'!I19))=0),_xlfn.REGEXEXTRACT(CELL("address",'Raw Data'!I19),"\$([A-Z]+)\$[0-9]+"),""),"")} | J19: {=IFERROR(IF(OR('Raw Data'!J19="",LEN(TRIM('Raw Data'!J19))=0),_xlfn.REGEXEXTRACT(CELL("address",'Raw Data'!J19),"\$([A-Z]+)\$[0-9]+"),""),"")} | K19: {=IFERROR(IF(OR('Raw Data'!K19="",LEN(TRIM('Raw Data'!K19))=0),_xlfn.REGEXEXTRACT(CELL("address",'Raw Data'!K19),"\$([A-Z]+)\$[0-9]+"),""),"")} | L19: {=IFERROR(IF(OR('Raw Data'!L19="",LEN(TRIM('Raw Data'!L19))=0),_xlfn.REGEXEXTRACT(CELL("address",'Raw Data'!L19),"\$([A-Z]+)\$[0-9]+"),""),"")}
B20: {=IFERROR(IF(OR('Raw Data'!B20="",LEN(TRIM('Raw Data'!B20))=0),_xlfn.REGEXEXTRACT(CELL("address",'Raw Data'!B20),"\$([A-Z]+)\$[0-9]+"),""),"")} | C20: {=IFERROR(IF(OR('Raw Data'!C20="",LEN(TRIM('Raw Data'!C20))=0),_xlfn.REGEXEXTRACT(CELL("address",'Raw Data'!C20),"\$([A-Z]+)\$[0-9]+"),""),"")} | E20: {=IFERROR(IF(OR('Raw Data'!E20="",LEN(TRIM('Raw Data'!E20))=0),_xlfn.REGEXEXTRACT(CELL("address",'Raw Data'!E20),"\$([A-Z]+)\$[0-9]+"),""),"")} | F20: {=IFERROR(IF(OR('Raw Data'!F20="",LEN(TRIM('Raw Data'!F20))=0),_xlfn.REGEXEXTRACT(CELL("address",'Raw Data'!F20),"\$([A-Z]+)\$[0-9]+"),""),"")} | G20: {=IFERROR(IF(OR('Raw Data'!G20="",LEN(TRIM('Raw Data'!G20))=0),_xlfn.REGEXEXTRACT(CELL("address",'Raw Data'!G20),"\$([A-Z]+)\$[0-9]+"),""),"")} | H20: {=IFERROR(IF(OR('Raw Data'!H20="",LEN(TRIM('Raw Data'!H20))=0),_xlfn.REGEXEXTRACT(CELL("address",'Raw Data'!H20),"\$([A-Z]+)\$[0-9]+"),""),"")} | I20: {=IFERROR(IF(OR('Raw Data'!I20="",LEN(TRIM('Raw Data'!I20))=0),_xlfn.REGEXEXTRACT(CELL("address",'Raw Data'!I20),"\$([A-Z]+)\$[0-9]+"),""),"")} | J20: {=IFERROR(IF(OR('Raw Data'!J20="",LEN(TRIM('Raw Data'!J20))=0),_xlfn.REGEXEXTRACT(CELL("address",'Raw Data'!J20),"\$([A-Z]+)\$[0-9]+"),""),"")} | K20: {=IFERROR(IF(OR('Raw Data'!K20="",LEN(TRIM('Raw Data'!K20))=0),_xlfn.REGEXEXTRACT(CELL("address",'Raw Data'!K20),"\$([A-Z]+)\$[0-9]+"),""),"")} | L20: {=IFERROR(IF(OR('Raw Data'!L20="",LEN(TRIM('Raw Data'!L20))=0),_xlfn.REGEXEXTRACT(CELL("address",'Raw Data'!L20),"\$([A-Z]+)\$[0-9]+"),""),"")}
B21: {=IFERROR(IF(OR('Raw Data'!B21="",LEN(TRIM('Raw Data'!B21))=0),_xlfn.REGEXEXTRACT(CELL("address",'Raw Data'!B21),"\$([A-Z]+)\$[0-9]+"),""),"")} | C21: {=IFERROR(IF(OR('Raw Data'!C21="",LEN(TRIM('Raw Data'!C21))=0),_xlfn.REGEXEXTRACT(CELL("address",'Raw Data'!C21),"\$([A-Z]+)\$[0-9]+"),""),"")} | E21: {=IFERROR(IF(OR('Raw Data'!E21="",LEN(TRIM('Raw Data'!E21))=0),_xlfn.REGEXEXTRACT(CELL("address",'Raw Data'!E21),"\$([A-Z]+)\$[0-9]+"),""),"")} | F21: {=IFERROR(IF(OR('Raw Data'!F21="",LEN(TRIM('Raw Data'!F21))=0),_xlfn.REGEXEXTRACT(CELL("address",'Raw Data'!F21),"\$([A-Z]+)\$[0-9]+"),""),"")} | G21: {=IFERROR(IF(OR('Raw Data'!G21="",LEN(TRIM('Raw Data'!G21))=0),_xlfn.REGEXEXTRACT(CELL("address",'Raw Data'!G21),"\$([A-Z]+)\$[0-9]+"),""),"")} | H21: {=IFERROR(IF(OR('Raw Data'!H21="",LEN(TRIM('Raw Data'!H21))=0),_xlfn.REGEXEXTRACT(CELL("address",'Raw Data'!H21),"\$([A-Z]+)\$[0-9]+"),""),"")} | I21: {=IFERROR(IF(OR('Raw Data'!I21="",LEN(TRIM('Raw Data'!I21))=0),_xlfn.REGEXEXTRACT(CELL("address",'Raw Data'!I21),"\$([A-Z]+)\$[0-9]+"),""),"")} | J21: {=IFERROR(IF(OR('Raw Data'!J21="",LEN(TRIM('Raw Data'!J21))=0),_xlfn.REGEXEXTRACT(CELL("address",'Raw Data'!J21),"\$([A-Z]+)\$[0-9]+"),""),"")} | K21: {=IFERROR(IF(OR('Raw Data'!K21="",LEN(TRIM('Raw Data'!K21))=0),_xlfn.REGEXEXTRACT(CELL("address",'Raw Data'!K21),"\$([A-Z]+)\$[0-9]+"),""),"")} | L21: {=IFERROR(IF(OR('Raw Data'!L21="",LEN(TRIM('Raw Data'!L21))=0),_xlfn.REGEXEXTRACT(CELL("address",'Raw Data'!L21),"\$([A-Z]+)\$[0-9]+"),""),"")}
B22: {=IFERROR(IF(OR('Raw Data'!B22="",LEN(TRIM('Raw Data'!B22))=0),_xlfn.REGEXEXTRACT(CELL("address",'Raw Data'!B22),"\$([A-Z]+)\$[0-9]+"),""),"")} | C22: {=IFERROR(IF(OR('Raw Data'!C22="",LEN(TRIM('Raw Data'!C22))=0),_xlfn.REGEXEXTRACT(CELL("address",'Raw Data'!C22),"\$([A-Z]+)\$[0-9]+"),""),"")} | E22: {=IFERROR(IF(OR('Raw Data'!E22="",LEN(TRIM('Raw Data'!E22))=0),_xlfn.REGEXEXTRACT(CELL("address",'Raw Data'!E22),"\$([A-Z]+)\$[0-9]+"),""),"")} | F22: {=IFERROR(IF(OR('Raw Data'!F22="",LEN(TRIM('Raw Data'!F22))=0),_xlfn.REGEXEXTRACT(CELL("address",'Raw Data'!F22),"\$([A-Z]+)\$[0-9]+"),""),"")} | G22: {=IFERROR(IF(OR('Raw Data'!G22="",LEN(TRIM('Raw Data'!G22))=0),_xlfn.REGEXEXTRACT(CELL("address",'Raw Data'!G22),"\$([A-Z]+)\$[0-9]+"),""),"")} | H22: {=IFERROR(IF(OR('Raw Data'!H22="",LEN(TRIM('Raw Data'!H22))=0),_xlfn.REGEXEXTRACT(CELL("address",'Raw Data'!H22),"\$([A-Z]+)\$[0-9]+"),""),"")} | I22: {=IFERROR(IF(OR('Raw Data'!I22="",LEN(TRIM('Raw Data'!I22))=0),_xlfn.REGEXEXTRACT(CELL("address",'Raw Data'!I22),"\$([A-Z]+)\$[0-9]+"),""),"")} | J22: {=IFERROR(IF(OR('Raw Data'!J22="",LEN(TRIM('Raw Data'!J22))=0),_xlfn.REGEXEXTRACT(CELL("address",'Raw Data'!J22),"\$([A-Z]+)\$[0-9]+"),""),"")} | K22: {=IFERROR(IF(OR('Raw Data'!K22="",LEN(TRIM('Raw Data'!K22))=0),_xlfn.REGEXEXTRACT(CELL("address",'Raw Data'!K22),"\$([A-Z]+)\$[0-9]+"),""),"")} | L22: {=IFERROR(IF(OR('Raw Data'!L22="",LEN(TRIM('Raw Data'!L22))=0),_xlfn.REGEXEXTRACT(CELL("address",'Raw Data'!L22),"\$([A-Z]+)\$[0-9]+"),""),"")}
... B296: {=IFERROR(IF(OR('Raw Data'!B296="",LEN(TRIM('Raw Data'!B296))=0),_xlfn.REGEXEXTRACT(CELL("address",'Raw Data'!B296),"\$([A-Z]+)\$[0-9]+"),""),"")} -> $B$296 | C296: {=IFERROR(IF(OR('Raw Data'!C296="",LEN(TRIM('Raw Data'!C296))=0),_xlfn.REGEXEXTRACT(CELL("address",'Raw Data'!C296),"\$([A-Z]+)\$[0-9]+"),""),"")} -> $C$296 | E296: {=IFERROR(IF(OR('Raw Data'!E296="",LEN(TRIM('Raw Data'!E296))=0),_xlfn.REGEXEXTRACT(CELL("address",'Raw Data'!E296),"\$([A-Z]+)\$[0-9]+"),""),"")} -> $E$296 | F296: {=IFERROR(IF(OR('Raw Data'!F296="",LEN(TRIM('Raw Data'!F296))=0),_xlfn.REGEXEXTRACT(CELL("address",'Raw Data'!F296),"\$([A-Z]+)\$[0-9]+"),""),"")} -> $F$296 | G296: {=IFERROR(IF(OR('Raw Data'!G296="",LEN(TRIM('Raw Data'!G296))=0),_xlfn.REGEXEXTRACT(CELL("address",'Raw Data'!G296),"\$([A-Z]+)\$[0-9]+"),""),"")} -> $G$296 | H296: {=IFERROR(IF(OR('Raw Data'!H296="",LEN(TRIM('Raw Data'!H296))=0),_xlfn.REGEXEXTRACT(CELL("address",'Raw Data'!H296),"\$([A-Z]+)\$[0-9]+"),""),"")} -> $H$296 | I296: {=IFERROR(IF(OR('Raw Data'!I296="",LEN(TRIM('Raw Data'!I296))=0),_xlfn.REGEXEXTRACT(CELL("address",'Raw Data'!I296),"\$([A-Z]+)\$[0-9]+"),""),"")} -> $I$296 | J296: {=IFERROR(IF(OR('Raw Data'!J296="",LEN(TRIM('Raw Data'!J296))=0),_xlfn.REGEXEXTRACT(CELL("address",'Raw Data'!J296),"\$([A-Z]+)\$[0-9]+"),""),"")} -> $J$296 | K296: {=IFERROR(IF(OR('Raw Data'!K296="",LEN(TRIM('Raw Data'!K296))=0),_xlfn.REGEXEXTRACT(CELL("address",'Raw Data'!K296),"\$([A-Z]+)\$[0-9]+"),""),"")} -> $K$296 | L296: {=IFERROR(IF(OR('Raw Data'!L296="",LEN(TRIM('Raw Data'!L296))=0),_xlfn.REGEXEXTRACT(CELL("address",'Raw Data'!L296),"\$([A-Z]+)\$[0-9]+"),""),"")} -> $L$296

Sheet Validate_Value
B9: NVARCHAR(255) | C9: NVARCHAR(255) | D9: NVARCHAR(255) | E9: NVARCHAR(255) | F9: NVARCHAR(20) | G9: NVARCHAR(255) | H9: NVARCHAR(255) | I9: NVARCHAR(50) | J9: NVARCHAR(255) | K9: NVARCHAR(255) | L9: DECIMAL(13,2) | M9: DECIMAL(13,2) | N9: DECIMAL(13,2) | O9: DECIMAL(13,2) | P9: DECIMAL(13,2) | Q9: DECIMAL(13,2) | R9: DECIMAL(13,2) | S9: DECIMAL(13,2) | T9: DECIMAL(13,2) | U9: DECIMAL(13,2) | V9: DECIMAL(13,2) | W9: DECIMAL(13,2) | X9: DECIMAL(13,2) | Y9: DECIMAL(13,2) | Z9: DECIMAL(13,2) | AA9: DECIMAL(13,2) | AB9: DECIMAL(13,2) | AC9: DECIMAL(13,2) | AD9: DECIMAL(13,2) | AE9: DECIMAL(13,2) | AF9: DECIMAL(13,2) | AG9: DECIMAL(13,2) | AH9: DECIMAL(13,2) | AI9: DECIMAL(13,2) | AJ9: DECIMAL(13,2) | AK9: DECIMAL(13,2) | AL9: DECIMAL(13,2) | AM9: DECIMAL(13,2) | AN9: DECIMAL(13,2) | AO9: DECIMAL(13,2) | AP9: DECIMAL(13,2) | AQ9: DECIMAL(13,2) | AR9: DECIMAL(13,2) | AS9: DECIMAL(13,2) | AT9: DECIMAL(13,2) | AU9: DECIMAL(13,2) | AV9: DECIMAL(13,2) | AW9: DECIMAL(13,2) | AX9: DECIMAL(13,2) | AY9: DECIMAL(13,2) | AZ9: DECIMAL(13,2) | BA9: DECIMAL(13,2) | BB9: DECIMAL(13,2) | BC9: DECIMAL(13,2) | BD9: DECIMAL(13,2) | BE9: DECIMAL(13,2) | BF9: DECIMAL(13,2) | BG9: DECIMAL(13,2) | BH9: DECIMAL(13,2) | BI9: DECIMAL(13,2) | BJ9: DECIMAL(13,2) | BK9: DECIMAL(13,2) | BL9: DECIMAL(13,2) | BM9: DECIMAL(13,2) | BN9: DECIMAL(13,2) | BO9: DECIMAL(13,2) | BP9: DECIMAL(13,2) | BQ9: DECIMAL(13,2) | BR9: DECIMAL(13,2) | BS9: DECIMAL(13,2) | BT9: DECIMAL(13,2)
B10: C1 | C10: C2 | D10: C3 | E10: C4 | F10: C5 | G10: C6 | H10: C7 | I10: C8 | J10: C9 | K10: C10 | L10: C11 | M10: C12 | N10: C13 | O10: C14 | P10: C15 | Q10: C16 | R10: C17 | S10: C18 | T10: C19 | U10: C20 | V10: C21 | W10: C22 | X10: C23 | Y10: C24 | Z10: C25 | AA10: C26 | AB10: C27 | AC10: C28 | AD10: C29 | AE10: C30 | AF10: C31 | AG10: C32 | AH10: C33 | AI10: C34 | AJ10: C35 | AK10: C36 | AL10: C37 | AM10: C38 | AN10: C39 | AO10: C40 | AP10: C41 | AQ10: C42 | AR10: C43 | AS10: C44 | AT10: C45 | AU10: C46 | AV10: C47 | AW10: C48 | AX10: C49 | AY10: C50 | AZ10: C51 | BA10: C52 | BB10: C53 | BC10: C54 | BD10: C55 | BE10: C56 | BF10: C57 | BG10: C58 | BH10: C59 | BI10: C60 | BJ10: C61 | BK10: C62 | BL10: C63 | BM10: C64 | BN10: C65 | BO10: C66 | BP10: C67 | BQ10: C68 | BR10: C69 | BS10: C70 | BT10: C71
B11: {=IFERROR(IF(OR('Raw Data'!B11="",LEN(TRIM('Raw Data'!B11))=0),"",IF(AND(LEN('Raw Data'!B11) <= 255,LEN('Raw Data'!B11)> 0),"",_xlfn.REGEXEXTRACT(CELL("address",'Raw Data'!B11),"\$([A-Z]+)\$[0-9]+"))),_xlfn.REGEXEXTRACT(CELL("address",'Raw Data'!B11),"\$([A-Z]+)\$[0-9]+"))} | C11: {=IFERROR(IF(OR('Raw Data'!C11="",LEN(TRIM('Raw Data'!C11))=0),"",IF(AND(LEN('Raw Data'!C11) <= 255,LEN('Raw Data'!C11)> 0),"",_xlfn.REGEXEXTRACT(CELL("address",'Raw Data'!C11),"\$([A-Z]+)\$[0-9]+"))),_xlfn.REGEXEXTRACT(CELL("address",'Raw Data'!C11),"\$([A-Z]+)\$[0-9]+"))} | D11: {=IFERROR(IF(OR('Raw Data'!D11="",LEN(TRIM('Raw Data'!D11))=0),"",IF(AND(LEN('Raw Data'!D11) <= 255,LEN('Raw Data'!D11)> 0),"",_xlfn.REGEXEXTRACT(CELL("address",'Raw Data'!D11),"\$([A-Z]+)\$[0-9]+"))),_xlfn.REGEXEXTRACT(CELL("address",'Raw Data'!D11),"\$([A-Z]+)\$[0-9]+"))} | E11: {=IFERROR(IF(OR('Raw Data'!E11="",LEN(TRIM('Raw Data'!E11))=0),"",IF(AND(LEN('Raw Data'!E11) <= 255,LEN('Raw Data'!E11)> 0),"",_xlfn.REGEXEXTRACT(CELL("address",'Raw Data'!E11),"\$([A-Z]+)\$[0-9]+"))),_xlfn.REGEXEXTRACT(CELL("address",'Raw Data'!E11),"\$([A-Z]+)\$[0-9]+"))} | F11: {=IFERROR(IF(OR('Raw Data'!F11="",LEN(TRIM('Raw Data'!F11))=0),"",IF(AND(LEN('Raw Data'!F11) <= 20,LEN('Raw Data'!F11)> 0),"",_xlfn.REGEXEXTRACT(CELL("address",'Raw Data'!F11),"\$([A-Z]+)\$[0-9]+"))),_xlfn.REGEXEXTRACT(CELL("address",'Raw Data'!F11),"\$([A-Z]+)\$[0-9]+"))} | G11: {=IFERROR(IF(OR('Raw Data'!G11="",LEN(TRIM('Raw Data'!G11))=0),"",IF(AND(LEN('Raw Data'!G11) <= 255,LEN('Raw Data'!G11)> 0),"",_xlfn.REGEXEXTRACT(CELL("address",'Raw Data'!G11),"\$([A-Z]+)\$[0-9]+"))),_xlfn.REGEXEXTRACT(CELL("address",'Raw Data'!G11),"\$([A-Z]+)\$[0-9]+"))} | H11: {=IFERROR(IF(OR('Raw Data'!H11="",LEN(TRIM('Raw Data'!H11))=0),"",IF(AND(LEN('Raw Data'!H11) <= 255,LEN('Raw Data'!H11)> 0),"",_xlfn.REGEXEXTRACT(CELL("address",'Raw Data'!H11),"\$([A-Z]+)\$[0-9]+"))),_xlfn.REGEXEXTRACT(CELL("address",'Raw Data'!H11),"\$([A-Z]+)\$[0-9]+"))} | I11: {=IFERROR(IF(OR('Raw Data'!I11="",LEN(TRIM('Raw Data'!I11))=0),"",IF(AND(LEN('Raw Data'!I11) <= 50,LEN('Raw Data'!I11)> 0),"",_xlfn.REGEXEXTRACT(CELL("address",'Raw Data'!I11),"\$([A-Z]+)\$[0-9]+"))),_xlfn.REGEXEXTRACT(CELL("address",'Raw Data'!I11),"\$([A-Z]+)\$[0-9]+"))} | J11: {=IFERROR(IF(OR('Raw Data'!J11="",LEN(TRIM('Raw Data'!J11))=0),"",IF(AND(LEN('Raw Data'!J11) <= 255,LEN('Raw Data'!J11)> 0),"",_xlfn.REGEXEXTRACT(CELL("address",'Raw Data'!J11),"\$([A-Z]+)\$[0-9]+"))),_xlfn.REGEXEXTRACT(CELL("address",'Raw Data'!J11),"\$([A-Z]+)\$[0-9]+"))} | K11: {=IFERROR(IF(OR('Raw Data'!K11="",LEN(TRIM('Raw Data'!K11))=0),"",IF(AND(LEN('Raw Data'!K11) <= 255,LEN('Raw Data'!K11)> 0),"",_xlfn.REGEXEXTRACT(CELL("address",'Raw Data'!K11),"\$([A-Z]+)\$[0-9]+"))),_xlfn.REGEXEXTRACT(CELL("address",'Raw Data'!K11),"\$([A-Z]+)\$[0-9]+"))} | L11: {=IFERROR(IF(OR('Raw Data'!L11="",LEN(TRIM('Raw Data'!L11))=0),"",IF(AND(ISNUMBER('Raw Data'!L11), IFERROR('Raw Data'!L11 = ROUND('Raw Data'!L11, 2),FALSE)),"",_xlfn.REGEXEXTRACT(CELL("address",L11), "\$([A-Z]+)\$[0-9]+"))),_xlfn.REGEXEXTRACT(CELL("address",L11), "\$([A-Z]+)\$[0-9]+"))} | M11: {=IFERROR(IF(OR('Raw Data'!M11="",LEN(TRIM('Raw Data'!M11))=0),"",IF(AND(ISNUMBER('Raw Data'!M11), IFERROR('Raw Data'!M11 = ROUND('Raw Data'!M11, 2),FALSE)),"",_xlfn.REGEXEXTRACT(CELL("address",M11), "\$([A-Z]+)\$[0-9]+"))),_xlfn.REGEXEXTRACT(CELL("address",M11), "\$([A-Z]+)\$[0-9]+"))} | N11: {=IFERROR(IF(OR('Raw Data'!N11="",LEN(TRIM('Raw Data'!N11))=0),"",IF(AND(ISNUMBER('Raw Data'!N11), IFERROR('Raw Data'!N11 = ROUND('Raw Data'!N11, 2),FALSE)),"",_xlfn.REGEXEXTRACT(CELL("address",N11), "\$([A-Z]+)\$[0-9]+"))),_xlfn.REGEXEXTRACT(CELL("address",N11), "\$([A-Z]+)\$[0-9]+"))} | O11: {=IFERROR(IF(OR('Raw Data'!O11="",LEN(TRIM('Raw Data'!O11))=0),"",IF(AND(ISNUMBER('Raw Data'!O11), IFERROR('Raw Data'!O11 = ROUND('Raw Data'!O11, 2),FALSE)),"",_xlfn.REGEXEXTRACT(CELL("address",O11), "\$([A-Z]+)\$[0-9]+"))),_xlfn.REGEXEXTRACT(CELL("address",O11), "\$([A-Z]+)\$[0-9]+"))} | P11: {=IFERROR(IF(OR('Raw Data'!P11="",LEN(TRIM('Raw Data'!P11))=0),"",IF(AND(ISNUMBER('Raw Data'!P11), IFERROR('Raw Data'!P11 = ROUND('Raw Data'!P11, 2),FALSE)),"",_xlfn.REGEXEXTRACT(CELL("address",P11), "\$([A-Z]+)\$[0-9]+"))),_xlfn.REGEXEXTRACT(CELL("address",P11), "\$([A-Z]+)\$[0-9]+"))} | Q11: {=IFERROR(IF(OR('Raw Data'!Q11="",LEN(TRIM('Raw Data'!Q11))=0),"",IF(AND(ISNUMBER('Raw Data'!Q11), IFERROR('Raw Data'!Q11 = ROUND('Raw Data'!Q11, 2),FALSE)),"",_xlfn.REGEXEXTRACT(CELL("address",Q11), "\$([A-Z]+)\$[0-9]+"))),_xlfn.REGEXEXTRACT(CELL("address",Q11), "\$([A-Z]+)\$[0-9]+"))} | R11: {=IFERROR(IF(OR('Raw Data'!R11="",LEN(TRIM('Raw Data'!R11))=0),"",IF(AND(ISNUMBER('Raw Data'!R11), IFERROR('Raw Data'!R11 = ROUND('Raw Data'!R11, 2),FALSE)),"",_xlfn.REGEXEXTRACT(CELL("address",R11), "\$([A-Z]+)\$[0-9]+"))),_xlfn.REGEXEXTRACT(CELL("address",R11), "\$([A-Z]+)\$[0-9]+"))} | S11: {=IFERROR(IF(OR('Raw Data'!S11="",LEN(TRIM('Raw Data'!S11))=0),"",IF(AND(ISNUMBER('Raw Data'!S11), IFERROR('Raw Data'!S11 = ROUND('Raw Data'!S11, 2),FALSE)),"",_xlfn.REGEXEXTRACT(CELL("address",S11), "\$([A-Z]+)\$[0-9]+"))),_xlfn.REGEXEXTRACT(CELL("address",S11), "\$([A-Z]+)\$[0-9]+"))} | ... BT11: {=IFERROR(IF(OR('Raw Data'!BT11="",LEN(TRIM('Raw Data'!BT11))=0),"",IF(AND(ISNUMBER('Raw Data'!BT11), IFERROR('Raw Data'!BT11 = ROUND('Raw Data'!BT11, 2),FALSE)),"",_xlfn.REGEXEXTRACT(CELL("address",BT11), "\$([A-Z]+)\$[0-9]+"))),_xlfn.REGEXEXTRACT(CELL("address",BT11), "\$([A-Z]+)\$[0-9]+"))}
B12: {=IFERROR(IF(OR('Raw Data'!B12="",LEN(TRIM('Raw Data'!B12))=0),"",IF(AND(LEN('Raw Data'!B12) <= 255,LEN('Raw Data'!B12)> 0),"",_xlfn.REGEXEXTRACT(CELL("address",'Raw Data'!B12),"\$([A-Z]+)\$[0-9]+"))),_xlfn.REGEXEXTRACT(CELL("address",'Raw Data'!B12),"\$([A-Z]+)\$[0-9]+"))} | C12: {=IFERROR(IF(OR('Raw Data'!C12="",LEN(TRIM('Raw Data'!C12))=0),"",IF(AND(LEN('Raw Data'!C12) <= 255,LEN('Raw Data'!C12)> 0),"",_xlfn.REGEXEXTRACT(CELL("address",'Raw Data'!C12),"\$([A-Z]+)\$[0-9]+"))),_xlfn.REGEXEXTRACT(CELL("address",'Raw Data'!C12),"\$([A-Z]+)\$[0-9]+"))} | D12: {=IFERROR(IF(OR('Raw Data'!D12="",LEN(TRIM('Raw Data'!D12))=0),"",IF(AND(LEN('Raw Data'!D12) <= 255,LEN('Raw Data'!D12)> 0),"",_xlfn.REGEXEXTRACT(CELL("address",'Raw Data'!D12),"\$([A-Z]+)\$[0-9]+"))),_xlfn.REGEXEXTRACT(CELL("address",'Raw Data'!D12),"\$([A-Z]+)\$[0-9]+"))} | E12: {=IFERROR(IF(OR('Raw Data'!E12="",LEN(TRIM('Raw Data'!E12))=0),"",IF(AND(LEN('Raw Data'!E12) <= 255,LEN('Raw Data'!E12)> 0),"",_xlfn.REGEXEXTRACT(CELL("address",'Raw Data'!E12),"\$([A-Z]+)\$[0-9]+"))),_xlfn.REGEXEXTRACT(CELL("address",'Raw Data'!E12),"\$([A-Z]+)\$[0-9]+"))} | F12: {=IFERROR(IF(OR('Raw Data'!F12="",LEN(TRIM('Raw Data'!F12))=0),"",IF(AND(LEN('Raw Data'!F12) <= 20,LEN('Raw Data'!F12)> 0),"",_xlfn.REGEXEXTRACT(CELL("address",'Raw Data'!F12),"\$([A-Z]+)\$[0-9]+"))),_xlfn.REGEXEXTRACT(CELL("address",'Raw Data'!F12),"\$([A-Z]+)\$[0-9]+"))} | G12: {=IFERROR(IF(OR('Raw Data'!G12="",LEN(TRIM('Raw Data'!G12))=0),"",IF(AND(LEN('Raw Data'!G12) <= 255,LEN('Raw Data'!G12)> 0),"",_xlfn.REGEXEXTRACT(CELL("address",'Raw Data'!G12),"\$([A-Z]+)\$[0-9]+"))),_xlfn.REGEXEXTRACT(CELL("address",'Raw Data'!G12),"\$([A-Z]+)\$[0-9]+"))} | H12: {=IFERROR(IF(OR('Raw Data'!H12="",LEN(TRIM('Raw Data'!H12))=0),"",IF(AND(LEN('Raw Data'!H12) <= 255,LEN('Raw Data'!H12)> 0),"",_xlfn.REGEXEXTRACT(CELL("address",'Raw Data'!H12),"\$([A-Z]+)\$[0-9]+"))),_xlfn.REGEXEXTRACT(CELL("address",'Raw Data'!H12),"\$([A-Z]+)\$[0-9]+"))} | I12: {=IFERROR(IF(OR('Raw Data'!I12="",LEN(TRIM('Raw Data'!I12))=0),"",IF(AND(LEN('Raw Data'!I12) <= 50,LEN('Raw Data'!I12)> 0),"",_xlfn.REGEXEXTRACT(CELL("address",'Raw Data'!I12),"\$([A-Z]+)\$[0-9]+"))),_xlfn.REGEXEXTRACT(CELL("address",'Raw Data'!I12),"\$([A-Z]+)\$[0-9]+"))} | J12: {=IFERROR(IF(OR('Raw Data'!J12="",LEN(TRIM('Raw Data'!J12))=0),"",IF(AND(LEN('Raw Data'!J12) <= 255,LEN('Raw Data'!J12)> 0),"",_xlfn.REGEXEXTRACT(CELL("address",'Raw Data'!J12),"\$([A-Z]+)\$[0-9]+"))),_xlfn.REGEXEXTRACT(CELL("address",'Raw Data'!J12),"\$([A-Z]+)\$[0-9]+"))} | K12: {=IFERROR(IF(OR('Raw Data'!K12="",LEN(TRIM('Raw Data'!K12))=0),"",IF(AND(LEN('Raw Data'!K12) <= 255,LEN('Raw Data'!K12)> 0),"",_xlfn.REGEXEXTRACT(CELL("address",'Raw Data'!K12),"\$([A-Z]+)\$[0-9]+"))),_xlfn.REGEXEXTRACT(CELL("address",'Raw Data'!K12),"\$([A-Z]+)\$[0-9]+"))} | L12: {=IFERROR(IF(OR('Raw Data'!L12="",LEN(TRIM('Raw Data'!L12))=0),"",IF(AND(ISNUMBER('Raw Data'!L12), IFERROR('Raw Data'!L12 = ROUND('Raw Data'!L12, 2),FALSE)),"",_xlfn.REGEXEXTRACT(CELL("address",L12), "\$([A-Z]+)\$[0-9]+"))),_xlfn.REGEXEXTRACT(CELL("address",L12), "\$([A-Z]+)\$[0-9]+"))} | M12: {=IFERROR(IF(OR('Raw Data'!M12="",LEN(TRIM('Raw Data'!M12))=0),"",IF(AND(ISNUMBER('Raw Data'!M12), IFERROR('Raw Data'!M12 = ROUND('Raw Data'!M12, 2),FALSE)),"",_xlfn.REGEXEXTRACT(CELL("address",M12), "\$([A-Z]+)\$[0-9]+"))),_xlfn.REGEXEXTRACT(CELL("address",M12), "\$([A-Z]+)\$[0-9]+"))} | N12: {=IFERROR(IF(OR('Raw Data'!N12="",LEN(TRIM('Raw Data'!N12))=0),"",IF(AND(ISNUMBER('Raw Data'!N12), IFERROR('Raw Data'!N12 = ROUND('Raw Data'!N12, 2),FALSE)),"",_xlfn.REGEXEXTRACT(CELL("address",N12), "\$([A-Z]+)\$[0-9]+"))),_xlfn.REGEXEXTRACT(CELL("address",N12), "\$([A-Z]+)\$[0-9]+"))} | O12: {=IFERROR(IF(OR('Raw Data'!O12="",LEN(TRIM('Raw Data'!O12))=0),"",IF(AND(ISNUMBER('Raw Data'!O12), IFERROR('Raw Data'!O12 = ROUND('Raw Data'!O12, 2),FALSE)),"",_xlfn.REGEXEXTRACT(CELL("address",O12), "\$([A-Z]+)\$[0-9]+"))),_xlfn.REGEXEXTRACT(CELL("address",O12), "\$([A-Z]+)\$[0-9]+"))} | P12: {=IFERROR(IF(OR('Raw Data'!P12="",LEN(TRIM('Raw Data'!P12))=0),"",IF(AND(ISNUMBER('Raw Data'!P12), IFERROR('Raw Data'!P12 = ROUND('Raw Data'!P12, 2),FALSE)),"",_xlfn.REGEXEXTRACT(CELL("address",P12), "\$([A-Z]+)\$[0-9]+"))),_xlfn.REGEXEXTRACT(CELL("address",P12), "\$([A-Z]+)\$[0-9]+"))} | Q12: {=IFERROR(IF(OR('Raw Data'!Q12="",LEN(TRIM('Raw Data'!Q12))=0),"",IF(AND(ISNUMBER('Raw Data'!Q12), IFERROR('Raw Data'!Q12 = ROUND('Raw Data'!Q12, 2),FALSE)),"",_xlfn.REGEXEXTRACT(CELL("address",Q12), "\$([A-Z]+)\$[0-9]+"))),_xlfn.REGEXEXTRACT(CELL("address",Q12), "\$([A-Z]+)\$[0-9]+"))} | R12: {=IFERROR(IF(OR('Raw Data'!R12="",LEN(TRIM('Raw Data'!R12))=0),"",IF(AND(ISNUMBER('Raw Data'!R12), IFERROR('Raw Data'!R12 = ROUND('Raw Data'!R12, 2),FALSE)),"",_xlfn.REGEXEXTRACT(CELL("address",R12), "\$([A-Z]+)\$[0-9]+"))),_xlfn.REGEXEXTRACT(CELL("address",R12), "\$([A-Z]+)\$[0-9]+"))} | S12: {=IFERROR(IF(OR('Raw Data'!S12="",LEN(TRIM('Raw Data'!S12))=0),"",IF(AND(ISNUMBER('Raw Data'!S12), IFERROR('Raw Data'!S12 = ROUND('Raw Data'!S12, 2),FALSE)),"",_xlfn.REGEXEXTRACT(CELL("address",S12), "\$([A-Z]+)\$[0-9]+"))),_xlfn.REGEXEXTRACT(CELL("address",S12), "\$([A-Z]+)\$[0-9]+"))} | ... BT12: {=IFERROR(IF(OR('Raw Data'!BT12="",LEN(TRIM('Raw Data'!BT12))=0),"",IF(AND(ISNUMBER('Raw Data'!BT12), IFERROR('Raw Data'!BT12 = ROUND('Raw Data'!BT12, 2),FALSE)),"",_xlfn.REGEXEXTRACT(CELL("address",BT12), "\$([A-Z]+)\$[0-9]+"))),_xlfn.REGEXEXTRACT(CELL("address",BT12), "\$([A-Z]+)\$[0-9]+"))}
B13: {=IFERROR(IF(OR('Raw Data'!B13="",LEN(TRIM('Raw Data'!B13))=0),"",IF(AND(LEN('Raw Data'!B13) <= 255,LEN('Raw Data'!B13)> 0),"",_xlfn.REGEXEXTRACT(CELL("address",'Raw Data'!B13),"\$([A-Z]+)\$[0-9]+"))),_xlfn.REGEXEXTRACT(CELL("address",'Raw Data'!B13),"\$([A-Z]+)\$[0-9]+"))} | C13: {=IFERROR(IF(OR('Raw Data'!C13="",LEN(TRIM('Raw Data'!C13))=0),"",IF(AND(LEN('Raw Data'!C13) <= 255,LEN('Raw Data'!C13)> 0),"",_xlfn.REGEXEXTRACT(CELL("address",'Raw Data'!C13),"\$([A-Z]+)\$[0-9]+"))),_xlfn.REGEXEXTRACT(CELL("address",'Raw Data'!C13),"\$([A-Z]+)\$[0-9]+"))} | D13: {=IFERROR(IF(OR('Raw Data'!D13="",LEN(TRIM('Raw Data'!D13))=0),"",IF(AND(LEN('Raw Data'!D13) <= 255,LEN('Raw Data'!D13)> 0),"",_xlfn.REGEXEXTRACT(CELL("address",'Raw Data'!D13),"\$([A-Z]+)\$[0-9]+"))),_xlfn.REGEXEXTRACT(CELL("address",'Raw Data'!D13),"\$([A-Z]+)\$[0-9]+"))} | E13: {=IFERROR(IF(OR('Raw Data'!E13="",LEN(TRIM('Raw Data'!E13))=0),"",IF(AND(LEN('Raw Data'!E13) <= 255,LEN('Raw Data'!E13)> 0),"",_xlfn.REGEXEXTRACT(CELL("address",'Raw Data'!E13),"\$([A-Z]+)\$[0-9]+"))),_xlfn.REGEXEXTRACT(CELL("address",'Raw Data'!E13),"\$([A-Z]+)\$[0-9]+"))} | F13: {=IFERROR(IF(OR('Raw Data'!F13="",LEN(TRIM('Raw Data'!F13))=0),"",IF(AND(LEN('Raw Data'!F13) <= 20,LEN('Raw Data'!F13)> 0),"",_xlfn.REGEXEXTRACT(CELL("address",'Raw Data'!F13),"\$([A-Z]+)\$[0-9]+"))),_xlfn.REGEXEXTRACT(CELL("address",'Raw Data'!F13),"\$([A-Z]+)\$[0-9]+"))} | G13: {=IFERROR(IF(OR('Raw Data'!G13="",LEN(TRIM('Raw Data'!G13))=0),"",IF(AND(LEN('Raw Data'!G13) <= 255,LEN('Raw Data'!G13)> 0),"",_xlfn.REGEXEXTRACT(CELL("address",'Raw Data'!G13),"\$([A-Z]+)\$[0-9]+"))),_xlfn.REGEXEXTRACT(CELL("address",'Raw Data'!G13),"\$([A-Z]+)\$[0-9]+"))} | H13: {=IFERROR(IF(OR('Raw Data'!H13="",LEN(TRIM('Raw Data'!H13))=0),"",IF(AND(LEN('Raw Data'!H13) <= 255,LEN('Raw Data'!H13)> 0),"",_xlfn.REGEXEXTRACT(CELL("address",'Raw Data'!H13),"\$([A-Z]+)\$[0-9]+"))),_xlfn.REGEXEXTRACT(CELL("address",'Raw Data'!H13),"\$([A-Z]+)\$[0-9]+"))} | I13: {=IFERROR(IF(OR('Raw Data'!I13="",LEN(TRIM('Raw Data'!I13))=0),"",IF(AND(LEN('Raw Data'!I13) <= 50,LEN('Raw Data'!I13)> 0),"",_xlfn.REGEXEXTRACT(CELL("address",'Raw Data'!I13),"\$([A-Z]+)\$[0-9]+"))),_xlfn.REGEXEXTRACT(CELL("address",'Raw Data'!I13),"\$([A-Z]+)\$[0-9]+"))} | J13: {=IFERROR(IF(OR('Raw Data'!J13="",LEN(TRIM('Raw Data'!J13))=0),"",IF(AND(LEN('Raw Data'!J13) <= 255,LEN('Raw Data'!J13)> 0),"",_xlfn.REGEXEXTRACT(CELL("address",'Raw Data'!J13),"\$([A-Z]+)\$[0-9]+"))),_xlfn.REGEXEXTRACT(CELL("address",'Raw Data'!J13),"\$([A-Z]+)\$[0-9]+"))} | K13: {=IFERROR(IF(OR('Raw Data'!K13="",LEN(TRIM('Raw Data'!K13))=0),"",IF(AND(LEN('Raw Data'!K13) <= 255,LEN('Raw Data'!K13)> 0),"",_xlfn.REGEXEXTRACT(CELL("address",'Raw Data'!K13),"\$([A-Z]+)\$[0-9]+"))),_xlfn.REGEXEXTRACT(CELL("address",'Raw Data'!K13),"\$([A-Z]+)\$[0-9]+"))} | L13: {=IFERROR(IF(OR('Raw Data'!L13="",LEN(TRIM('Raw Data'!L13))=0),"",IF(AND(ISNUMBER('Raw Data'!L13), IFERROR('Raw Data'!L13 = ROUND('Raw Data'!L13, 2),FALSE)),"",_xlfn.REGEXEXTRACT(CELL("address",L13), "\$([A-Z]+)\$[0-9]+"))),_xlfn.REGEXEXTRACT(CELL("address",L13), "\$([A-Z]+)\$[0-9]+"))} | M13: {=IFERROR(IF(OR('Raw Data'!M13="",LEN(TRIM('Raw Data'!M13))=0),"",IF(AND(ISNUMBER('Raw Data'!M13), IFERROR('Raw Data'!M13 = ROUND('Raw Data'!M13, 2),FALSE)),"",_xlfn.REGEXEXTRACT(CELL("address",M13), "\$([A-Z]+)\$[0-9]+"))),_xlfn.REGEXEXTRACT(CELL("address",M13), "\$([A-Z]+)\$[0-9]+"))} | N13: {=IFERROR(IF(OR('Raw Data'!N13="",LEN(TRIM('Raw Data'!N13))=0),"",IF(AND(ISNUMBER('Raw Data'!N13), IFERROR('Raw Data'!N13 = ROUND('Raw Data'!N13, 2),FALSE)),"",_xlfn.REGEXEXTRACT(CELL("address",N13), "\$([A-Z]+)\$[0-9]+"))),_xlfn.REGEXEXTRACT(CELL("address",N13), "\$([A-Z]+)\$[0-9]+"))} | O13: {=IFERROR(IF(OR('Raw Data'!O13="",LEN(TRIM('Raw Data'!O13))=0),"",IF(AND(ISNUMBER('Raw Data'!O13), IFERROR('Raw Data'!O13 = ROUND('Raw Data'!O13, 2),FALSE)),"",_xlfn.REGEXEXTRACT(CELL("address",O13), "\$([A-Z]+)\$[0-9]+"))),_xlfn.REGEXEXTRACT(CELL("address",O13), "\$([A-Z]+)\$[0-9]+"))} | P13: {=IFERROR(IF(OR('Raw Data'!P13="",LEN(TRIM('Raw Data'!P13))=0),"",IF(AND(ISNUMBER('Raw Data'!P13), IFERROR('Raw Data'!P13 = ROUND('Raw Data'!P13, 2),FALSE)),"",_xlfn.REGEXEXTRACT(CELL("address",P13), "\$([A-Z]+)\$[0-9]+"))),_xlfn.REGEXEXTRACT(CELL("address",P13), "\$([A-Z]+)\$[0-9]+"))} | Q13: {=IFERROR(IF(OR('Raw Data'!Q13="",LEN(TRIM('Raw Data'!Q13))=0),"",IF(AND(ISNUMBER('Raw Data'!Q13), IFERROR('Raw Data'!Q13 = ROUND('Raw Data'!Q13, 2),FALSE)),"",_xlfn.REGEXEXTRACT(CELL("address",Q13), "\$([A-Z]+)\$[0-9]+"))),_xlfn.REGEXEXTRACT(CELL("address",Q13), "\$([A-Z]+)\$[0-9]+"))} | R13: {=IFERROR(IF(OR('Raw Data'!R13="",LEN(TRIM('Raw Data'!R13))=0),"",IF(AND(ISNUMBER('Raw Data'!R13), IFERROR('Raw Data'!R13 = ROUND('Raw Data'!R13, 2),FALSE)),"",_xlfn.REGEXEXTRACT(CELL("address",R13), "\$([A-Z]+)\$[0-9]+"))),_xlfn.REGEXEXTRACT(CELL("address",R13), "\$([A-Z]+)\$[0-9]+"))} | S13: {=IFERROR(IF(OR('Raw Data'!S13="",LEN(TRIM('Raw Data'!S13))=0),"",IF(AND(ISNUMBER('Raw Data'!S13), IFERROR('Raw Data'!S13 = ROUND('Raw Data'!S13, 2),FALSE)),"",_xlfn.REGEXEXTRACT(CELL("address",S13), "\$([A-Z]+)\$[0-9]+"))),_xlfn.REGEXEXTRACT(CELL("address",S13), "\$([A-Z]+)\$[0-9]+"))} | ... BT13: {=IFERROR(IF(OR('Raw Data'!BT13="",LEN(TRIM('Raw Data'!BT13))=0),"",IF(AND(ISNUMBER('Raw Data'!BT13), IFERROR('Raw Data'!BT13 = ROUND('Raw Data'!BT13, 2),FALSE)),"",_xlfn.REGEXEXTRACT(CELL("address",BT13), "\$([A-Z]+)\$[0-9]+"))),_xlfn.REGEXEXTRACT(CELL("address",BT13), "\$([A-Z]+)\$[0-9]+"))}
B14: {=IFERROR(IF(OR('Raw Data'!B14="",LEN(TRIM('Raw Data'!B14))=0),"",IF(AND(LEN('Raw Data'!B14) <= 255,LEN('Raw Data'!B14)> 0),"",_xlfn.REGEXEXTRACT(CELL("address",'Raw Data'!B14),"\$([A-Z]+)\$[0-9]+"))),_xlfn.REGEXEXTRACT(CELL("address",'Raw Data'!B14),"\$([A-Z]+)\$[0-9]+"))} | C14: {=IFERROR(IF(OR('Raw Data'!C14="",LEN(TRIM('Raw Data'!C14))=0),"",IF(AND(LEN('Raw Data'!C14) <= 255,LEN('Raw Data'!C14)> 0),"",_xlfn.REGEXEXTRACT(CELL("address",'Raw Data'!C14),"\$([A-Z]+)\$[0-9]+"))),_xlfn.REGEXEXTRACT(CELL("address",'Raw Data'!C14),"\$([A-Z]+)\$[0-9]+"))} | D14: {=IFERROR(IF(OR('Raw Data'!D14="",LEN(TRIM('Raw Data'!D14))=0),"",IF(AND(LEN('Raw Data'!D14) <= 255,LEN('Raw Data'!D14)> 0),"",_xlfn.REGEXEXTRACT(CELL("address",'Raw Data'!D14),"\$([A-Z]+)\$[0-9]+"))),_xlfn.REGEXEXTRACT(CELL("address",'Raw Data'!D14),"\$([A-Z]+)\$[0-9]+"))} | E14: {=IFERROR(IF(OR('Raw Data'!E14="",LEN(TRIM('Raw Data'!E14))=0),"",IF(AND(LEN('Raw Data'!E14) <= 255,LEN('Raw Data'!E14)> 0),"",_xlfn.REGEXEXTRACT(CELL("address",'Raw Data'!E14),"\$([A-Z]+)\$[0-9]+"))),_xlfn.REGEXEXTRACT(CELL("address",'Raw Data'!E14),"\$([A-Z]+)\$[0-9]+"))} | F14: {=IFERROR(IF(OR('Raw Data'!F14="",LEN(TRIM('Raw Data'!F14))=0),"",IF(AND(LEN('Raw Data'!F14) <= 20,LEN('Raw Data'!F14)> 0),"",_xlfn.REGEXEXTRACT(CELL("address",'Raw Data'!F14),"\$([A-Z]+)\$[0-9]+"))),_xlfn.REGEXEXTRACT(CELL("address",'Raw Data'!F14),"\$([A-Z]+)\$[0-9]+"))} | G14: {=IFERROR(IF(OR('Raw Data'!G14="",LEN(TRIM('Raw Data'!G14))=0),"",IF(AND(LEN('Raw Data'!G14) <= 255,LEN('Raw Data'!G14)> 0),"",_xlfn.REGEXEXTRACT(CELL("address",'Raw Data'!G14),"\$([A-Z]+)\$[0-9]+"))),_xlfn.REGEXEXTRACT(CELL("address",'Raw Data'!G14),"\$([A-Z]+)\$[0-9]+"))} | H14: {=IFERROR(IF(OR('Raw Data'!H14="",LEN(TRIM('Raw Data'!H14))=0),"",IF(AND(LEN('Raw Data'!H14) <= 255,LEN('Raw Data'!H14)> 0),"",_xlfn.REGEXEXTRACT(CELL("address",'Raw Data'!H14),"\$([A-Z]+)\$[0-9]+"))),_xlfn.REGEXEXTRACT(CELL("address",'Raw Data'!H14),"\$([A-Z]+)\$[0-9]+"))} | I14: {=IFERROR(IF(OR('Raw Data'!I14="",LEN(TRIM('Raw Data'!I14))=0),"",IF(AND(LEN('Raw Data'!I14) <= 50,LEN('Raw Data'!I14)> 0),"",_xlfn.REGEXEXTRACT(CELL("address",'Raw Data'!I14),"\$([A-Z]+)\$[0-9]+"))),_xlfn.REGEXEXTRACT(CELL("address",'Raw Data'!I14),"\$([A-Z]+)\$[0-9]+"))} | J14: {=IFERROR(IF(OR('Raw Data'!J14="",LEN(TRIM('Raw Data'!J14))=0),"",IF(AND(LEN('Raw Data'!J14) <= 255,LEN('Raw Data'!J14)> 0),"",_xlfn.REGEXEXTRACT(CELL("address",'Raw Data'!J14),"\$([A-Z]+)\$[0-9]+"))),_xlfn.REGEXEXTRACT(CELL("address",'Raw Data'!J14),"\$([A-Z]+)\$[0-9]+"))} | K14: {=IFERROR(IF(OR('Raw Data'!K14="",LEN(TRIM('Raw Data'!K14))=0),"",IF(AND(LEN('Raw Data'!K14) <= 255,LEN('Raw Data'!K14)> 0),"",_xlfn.REGEXEXTRACT(CELL("address",'Raw Data'!K14),"\$([A-Z]+)\$[0-9]+"))),_xlfn.REGEXEXTRACT(CELL("address",'Raw Data'!K14),"\$([A-Z]+)\$[0-9]+"))} | L14: {=IFERROR(IF(OR('Raw Data'!L14="",LEN(TRIM('Raw Data'!L14))=0),"",IF(AND(ISNUMBER('Raw Data'!L14), IFERROR('Raw Data'!L14 = ROUND('Raw Data'!L14, 2),FALSE)),"",_xlfn.REGEXEXTRACT(CELL("address",L14), "\$([A-Z]+)\$[0-9]+"))),_xlfn.REGEXEXTRACT(CELL("address",L14), "\$([A-Z]+)\$[0-9]+"))} | M14: {=IFERROR(IF(OR('Raw Data'!M14="",LEN(TRIM('Raw Data'!M14))=0),"",IF(AND(ISNUMBER('Raw Data'!M14), IFERROR('Raw Data'!M14 = ROUND('Raw Data'!M14, 2),FALSE)),"",_xlfn.REGEXEXTRACT(CELL("address",M14), "\$([A-Z]+)\$[0-9]+"))),_xlfn.REGEXEXTRACT(CELL("address",M14), "\$([A-Z]+)\$[0-9]+"))} | N14: {=IFERROR(IF(OR('Raw Data'!N14="",LEN(TRIM('Raw Data'!N14))=0),"",IF(AND(ISNUMBER('Raw Data'!N14), IFERROR('Raw Data'!N14 = ROUND('Raw Data'!N14, 2),FALSE)),"",_xlfn.REGEXEXTRACT(CELL("address",N14), "\$([A-Z]+)\$[0-9]+"))),_xlfn.REGEXEXTRACT(CELL("address",N14), "\$([A-Z]+)\$[0-9]+"))} | O14: {=IFERROR(IF(OR('Raw Data'!O14="",LEN(TRIM('Raw Data'!O14))=0),"",IF(AND(ISNUMBER('Raw Data'!O14), IFERROR('Raw Data'!O14 = ROUND('Raw Data'!O14, 2),FALSE)),"",_xlfn.REGEXEXTRACT(CELL("address",O14), "\$([A-Z]+)\$[0-9]+"))),_xlfn.REGEXEXTRACT(CELL("address",O14), "\$([A-Z]+)\$[0-9]+"))} | P14: {=IFERROR(IF(OR('Raw Data'!P14="",LEN(TRIM('Raw Data'!P14))=0),"",IF(AND(ISNUMBER('Raw Data'!P14), IFERROR('Raw Data'!P14 = ROUND('Raw Data'!P14, 2),FALSE)),"",_xlfn.REGEXEXTRACT(CELL("address",P14), "\$([A-Z]+)\$[0-9]+"))),_xlfn.REGEXEXTRACT(CELL("address",P14), "\$([A-Z]+)\$[0-9]+"))} | Q14: {=IFERROR(IF(OR('Raw Data'!Q14="",LEN(TRIM('Raw Data'!Q14))=0),"",IF(AND(ISNUMBER('Raw Data'!Q14), IFERROR('Raw Data'!Q14 = ROUND('Raw Data'!Q14, 2),FALSE)),"",_xlfn.REGEXEXTRACT(CELL("address",Q14), "\$([A-Z]+)\$[0-9]+"))),_xlfn.REGEXEXTRACT(CELL("address",Q14), "\$([A-Z]+)\$[0-9]+"))} | R14: {=IFERROR(IF(OR('Raw Data'!R14="",LEN(TRIM('Raw Data'!R14))=0),"",IF(AND(ISNUMBER('Raw Data'!R14), IFERROR('Raw Data'!R14 = ROUND('Raw Data'!R14, 2),FALSE)),"",_xlfn.REGEXEXTRACT(CELL("address",R14), "\$([A-Z]+)\$[0-9]+"))),_xlfn.REGEXEXTRACT(CELL("address",R14), "\$([A-Z]+)\$[0-9]+"))} | S14: {=IFERROR(IF(OR('Raw Data'!S14="",LEN(TRIM('Raw Data'!S14))=0),"",IF(AND(ISNUMBER('Raw Data'!S14), IFERROR('Raw Data'!S14 = ROUND('Raw Data'!S14, 2),FALSE)),"",_xlfn.REGEXEXTRACT(CELL("address",S14), "\$([A-Z]+)\$[0-9]+"))),_xlfn.REGEXEXTRACT(CELL("address",S14), "\$([A-Z]+)\$[0-9]+"))} | ... BT14: {=IFERROR(IF(OR('Raw Data'!BT14="",LEN(TRIM('Raw Data'!BT14))=0),"",IF(AND(ISNUMBER('Raw Data'!BT14), IFERROR('Raw Data'!BT14 = ROUND('Raw Data'!BT14, 2),FALSE)),"",_xlfn.REGEXEXTRACT(CELL("address",BT14), "\$([A-Z]+)\$[0-9]+"))),_xlfn.REGEXEXTRACT(CELL("address",BT14), "\$([A-Z]+)\$[0-9]+"))}
